
#######################################################################
# +-----------------------------------------------------------------+ #
# |                            BO3 object                           | #
# +-----------------------------------------------------------------+ #
#######################################################################

Author: Unknown

Description: Converted version of the BO2 BirchForest5

Version: 3

SettingsMode: WriteWithoutComments


#######################################################################
# +-----------------------------------------------------------------+ #
# |                          Main settings                          | #
# +-----------------------------------------------------------------+ #
#######################################################################

Tree: true

Frequency: 1

Rarity: 10.0

RotateRandomly: true

SpawnHeight: highestSolidBlock

SpawnHeightOffset: 0

SpawnHeightVariance: 0

##############################
# Height Limits for the BO3. #
##############################

MinHeight: 62

MaxHeight: 239

######################
# Extrusion settings #
######################

ExtrudeMode: None

ExtrudeThroughBlocks: AIR

MaxBranchDepth: 10

ExcludedBiomes: All


#######################################################################
# +-----------------------------------------------------------------+ #
# |                      Source block settings                      | #
# +-----------------------------------------------------------------+ #
#######################################################################

SourceBlocks: STONE:1,STONE:3,STONE:5,DIRT:1,DIRT,SAND,GRASS,DIRT:2,STATIONARY_WATER,HARD_CLAY,STAINED_CLAY,CLAY,SANDSTONE,SAND:1,AIR,STONE,GRAVEL,LONG_GRASS,LONG_GRASS:1,LONG_GRASS:2,DEAD_BUSH,YELLOW_FLOWER,RED_ROSE,BROWN_MUSHROOM,RED_MUSHROOM,biomesoplenty:plant_0:1,biomesoplenty:plant_0:2,biomesoplenty:plant_0:3,biomesoplenty:plant_0:4,biomesoplenty:plant_0:5,biomesoplenty:plant_0:6,biomesoplenty:plant_0:7,biomesoplenty:plant_0:8,biomesoplenty:plant_0:9,biomesoplenty:plant_0:10,biomesoplenty:plant_0:11,biomesoplenty:plant_0:12,biomesoplenty:plant_0:13,biomesoplenty:plant_0:14,biomesoplenty:flower_0:1,biomesoplenty:flower_0:2,biomesoplenty:flower_0:3,biomesoplenty:flower_0:4,biomesoplenty:flower_0:5,biomesoplenty:flower_0:6,biomesoplenty:flower_0:7,biomesoplenty:flower_0:8,biomesoplenty:flower_0:9,biomesoplenty:flower_0:10,biomesoplenty:flower_0:11,biomesoplenty:flower_0:12,biomesoplenty:flower_0:13,biomesoplenty:flower_0:14,biomesoplenty:plant_1,biomesoplenty:grass:0,biomesoplenty:grass:1,biomesoplenty:grass,biomesoplenty:grass:3,biomesoplenty:grass:4,biomesoplenty:grass:5,biomesoplenty:grass:6,biomesoplenty:grass:7,UNKNOWN_BLOCK:0,UNKNOWN_BLOCK:1,UNKNOWN_BLOCK:2,UNKNOWN_BLOCK:8,UNKNOWN_BLOCK:9,UNKNOWN_BLOCK:10,biomesoplenty:dried_sand,biomesoplenty:hard_ice,biomesoplenty:white_sand,biomesoplenty:white_sandstone,biomesoplenty:mud,biomesoplenty:ash_block

MaxPercentageOutsideSourceBlock: 0

OutsideSourceBlock: placeAnyway

DoReplaceBlocks: true

IsOTGPlus: false


#######################################################################
# +-----------------------------------------------------------------+ #
# |                              Blocks                             | #
# +-----------------------------------------------------------------+ #
#######################################################################

Block(-4,9,2,LEAVES:2)
Block(-4,8,2,LEAVES:2)
Block(-4,7,2,LEAVES:2)
Block(-4,6,2,LEAVES:2)
Block(-4,5,2,LEAVES:2)
Block(-4,4,2,LEAVES:2)
Block(1,8,-4,LEAVES:2)
Block(1,9,-4,LEAVES:2)
Block(-3,7,4,LEAVES:2)
Block(-3,6,4,LEAVES:2)
Block(-3,9,4,LEAVES:2)
Block(-3,8,4,LEAVES:2)
Block(-3,5,4,LEAVES:2)
Block(-3,10,2,LEAVES:2)
Block(-3,11,2,LEAVES:2)
Block(-2,10,-3,LEAVES:2)
Block(1,10,1,LEAVES:2)
Block(1,11,1,LEAVES:2)
Block(-3,9,-2,LEAVES:2)
Block(-4,9,1,LEAVES:2)
Block(-4,8,1,LEAVES:2)
Block(-4,7,1,LEAVES:2)
Block(-4,6,1,LEAVES:2)
Block(-4,5,1,LEAVES:2)
Block(-4,4,1,LEAVES:2)
Block(1,9,-3,LEAVES:2)
Block(1,7,-3,LEAVES:2)
Block(1,8,-3,LEAVES:2)
Block(-3,8,3,LOG:2)
Block(1,10,2,LEAVES:2)
Block(1,6,-3,LEAVES:2)
Block(-3,7,3,LEAVES:2)
Block(1,11,2,LEAVES:2)
Block(-3,9,3,LEAVES:2)
Block(-3,4,3,LEAVES:2)
Block(-3,6,3,LEAVES:2)
Block(-3,5,3,LEAVES:2)
Block(1,10,-1,LEAVES:2)
Block(-4,10,5,LEAVES:2)
Block(-2,9,5,LEAVES:2)
Block(-3,4,-1,LEAVES:2)
Block(-3,5,-1,LEAVES:2)
Block(-3,9,-1,LEAVES:2)
Block(-3,11,3,LEAVES:2)
Block(-3,10,3,LEAVES:2)
Block(-4,8,4,LEAVES:2)
Block(-4,7,4,LEAVES:2)
Block(-4,6,4,LEAVES:2)
Block(-4,5,4,LEAVES:2)
Block(0,5,0,LEAVES:2)
Block(0,4,0,LOG:2)
Block(0,7,0,LEAVES:2)
Block(0,6,0,LOG:2)
Block(-4,9,4,LEAVES:2)
Block(-2,11,0,LEAVES:2)
Block(-2,10,0,LEAVES:2)
Block(1,8,-2,LEAVES:2)
Block(1,9,-2,LEAVES:2)
Block(1,6,-2,LEAVES:2)
Block(1,7,-2,LEAVES:2)
Block(1,5,-2,LEAVES:2)
Block(-4,10,3,LEAVES:2)
Block(-4,11,3,LEAVES:2)
Block(-5,8,1,LEAVES:2)
Block(-5,7,1,LEAVES:2)
Block(2,5,-1,LEAVES:2)
Block(2,4,-1,LEAVES:2)
Block(0,8,1,LEAVES:2)
Block(2,9,-1,LEAVES:2)
Block(0,7,1,LEAVES:2)
Block(2,8,-1,LEAVES:2)
Block(2,7,-1,LOG:2)
Block(2,6,-1,LEAVES:2)
Block(0,9,1,LEAVES:2)
Block(-5,6,1,LEAVES:2)
Block(-5,5,1,LEAVES:2)
Block(-4,9,3,LEAVES:2)
Block(-4,8,3,LEAVES:2)
Block(-4,7,3,LEAVES:2)
Block(-4,6,3,LEAVES:2)
Block(-4,10,4,LEAVES:2)
Block(-4,5,3,LEAVES:2)
Block(-3,9,5,LEAVES:2)
Block(1,9,-1,LEAVES:2)
Block(1,7,-1,LEAVES:2)
Block(1,8,-1,LEAVES:2)
Block(1,5,-1,LOG:2)
Block(1,6,-1,LEAVES:2)
Block(1,4,-1,LEAVES:2)
Block(-3,11,4,LEAVES:2)
Block(-3,10,4,LEAVES:2)
Block(-5,7,2,LEAVES:2)
Block(-5,6,2,LEAVES:2)
Block(-5,9,2,LEAVES:2)
Block(-5,8,2,LEAVES:2)
Block(2,8,-2,LEAVES:2)
Block(0,9,0,LEAVES:2)
Block(2,7,-2,LEAVES:2)
Block(0,8,0,LEAVES:2)
Block(2,6,-2,LEAVES:2)
Block(-5,5,2,LEAVES:2)
Block(2,9,-2,LEAVES:2)
Block(0,8,-4,LEAVES:2)
Block(0,7,-4,LEAVES:2)
Block(-4,10,2,LEAVES:2)
Block(-2,9,-3,LEAVES:2)
Block(-2,8,-3,LEAVES:2)
Block(0,12,1,LEAVES:2)
Block(0,9,-4,LEAVES:2)
Block(0,11,1,LEAVES:2)
Block(0,10,1,LEAVES:2)
Block(-5,6,3,LEAVES:2)
Block(-5,5,3,LEAVES:2)
Block(-5,8,3,LEAVES:2)
Block(-1,10,-2,LEAVES:2)
Block(-5,7,3,LEAVES:2)
Block(-1,11,-2,LEAVES:2)
Block(-5,9,3,LEAVES:2)
Block(2,7,-3,LEAVES:2)
Block(-3,10,5,LEAVES:2)
Block(2,6,-3,LEAVES:2)
Block(2,9,-3,LEAVES:2)
Block(2,8,-3,LEAVES:2)
Block(-4,9,5,LEAVES:2)
Block(-2,10,-1,LEAVES:2)
Block(-1,10,-1,LEAVES:2)
Block(-2,11,-1,LEAVES:2)
Block(-2,8,-4,LEAVES:2)
Block(-2,9,-4,LEAVES:2)
Block(0,9,-5,LEAVES:2)
Block(0,8,-5,LEAVES:2)
Block(-2,10,1,LEAVES:2)
Block(-1,11,-1,LEAVES:2)
Block(-2,12,1,LEAVES:2)
Block(-2,11,1,LEAVES:2)
Block(0,11,0,LEAVES:2)
Block(-5,9,4,LEAVES:2)
Block(-5,10,4,LEAVES:2)
Block(0,10,0,LEAVES:2)
Block(2,9,-4,LEAVES:2)
Block(2,8,-4,LEAVES:2)
Block(3,7,-1,LEAVES:2)
Block(3,8,-1,LEAVES:2)
Block(2,10,0,LEAVES:2)
Block(0,6,-2,LEAVES:2)
Block(3,9,-1,LEAVES:2)
Block(0,8,-2,LEAVES:2)
Block(0,7,-2,LOG:2)
Block(0,9,-2,LEAVES:2)
Block(-2,10,-2,LEAVES:2)
Block(3,6,-1,LEAVES:2)
Block(-1,10,-3,LEAVES:2)
Block(-2,10,3,LEAVES:2)
Block(-2,9,-1,LEAVES:2)
Block(-2,4,-1,LEAVES:2)
Block(-2,8,-1,LEAVES:2)
Block(-2,7,-1,LEAVES:2)
Block(-2,5,-1,LEAVES:2)
Block(-2,11,3,LEAVES:2)
Block(-3,10,-1,LEAVES:2)
Block(0,10,2,LEAVES:2)
Block(0,11,2,LEAVES:2)
Block(0,7,-3,LOG:2)
Block(0,6,-3,LEAVES:2)
Block(0,9,-3,LEAVES:2)
Block(0,8,-3,LEAVES:2)
Block(-2,10,2,LEAVES:2)
Block(-2,11,2,LEAVES:2)
Block(-2,9,-2,LEAVES:2)
Block(-2,8,-2,LEAVES:2)
Block(-4,10,1,LEAVES:2)
Block(3,8,-3,LEAVES:2)
Block(1,6,4,LEAVES:2)
Block(3,9,-3,LEAVES:2)
Block(1,5,4,LEAVES:2)
Block(2,5,2,LEAVES:2)
Block(2,4,2,LEAVES:2)
Block(2,7,2,LEAVES:2)
Block(2,6,2,LEAVES:2)
Block(-3,10,-2,LEAVES:2)
Block(-1,10,1,LEAVES:2)
Block(-1,11,1,LEAVES:2)
Block(-1,12,1,LEAVES:2)
Block(-1,5,0,LEAVES:2)
Block(3,8,0,LEAVES:2)
Block(-1,4,0,LEAVES:2)
Block(3,7,0,LEAVES:2)
Block(3,6,0,LEAVES:2)
Block(-1,7,0,LEAVES:2)
Block(3,5,0,LEAVES:2)
Block(-1,6,0,LOG:2)
Block(-1,9,0,LEAVES:2)
Block(-1,8,0,LOG:2)
Block(3,9,0,LEAVES:2)
Block(2,4,1,LEAVES:2)
Block(2,3,1,LEAVES:2)
Block(-1,9,-3,LEAVES:2)
Block(-1,8,-3,LEAVES:2)
Block(-1,7,-3,LEAVES:2)
Block(-5,10,2,LEAVES:2)
Block(0,5,-1,LEAVES:2)
Block(3,6,-2,LEAVES:2)
Block(0,4,-1,LEAVES:2)
Block(3,7,-2,LEAVES:2)
Block(0,7,-1,LEAVES:2)
Block(3,8,-2,LEAVES:2)
Block(0,6,-1,LOG:2)
Block(1,6,5,LEAVES:2)
Block(3,9,-2,LEAVES:2)
Block(1,5,5,LEAVES:2)
Block(0,9,-1,LEAVES:2)
Block(0,8,-1,LEAVES:2)
Block(2,4,3,LEAVES:2)
Block(2,6,3,LEAVES:2)
Block(2,5,3,LEAVES:2)
Block(0,10,3,LEAVES:2)
Block(0,11,3,LEAVES:2)
Block(3,4,0,LEAVES:2)
Block(-1,6,-2,LEAVES:2)
Block(3,5,1,LEAVES:2)
Block(3,4,1,LEAVES:2)
Block(3,9,1,LEAVES:2)
Block(3,8,1,LEAVES:2)
Block(-1,9,-2,LEAVES:2)
Block(-1,8,-2,LEAVES:2)
Block(-1,7,-2,LEAVES:2)
Block(-2,10,4,LEAVES:2)
Block(-1,10,2,LEAVES:2)
Block(0,10,-1,LEAVES:2)
Block(-1,12,2,LEAVES:2)
Block(-1,11,2,LEAVES:2)
Block(0,11,-1,LEAVES:2)
Block(2,6,4,LEAVES:2)
Block(2,5,4,LEAVES:2)
Block(3,5,2,LEAVES:2)
Block(3,4,2,LEAVES:2)
Block(-1,5,2,LEAVES:2)
Block(-1,4,2,LEAVES:2)
Block(-1,7,2,LEAVES:2)
Block(-1,6,2,LEAVES:2)
Block(-1,9,2,LEAVES:2)
Block(-1,8,2,LEAVES:2)
Block(-2,9,0,LEAVES:2)
Block(-2,8,0,LEAVES:2)
Block(-1,9,-5,LEAVES:2)
Block(-2,7,0,LEAVES:2)
Block(-1,8,-5,LEAVES:2)
Block(-2,6,0,LEAVES:2)
Block(-2,5,0,LEAVES:2)
Block(-2,4,0,LEAVES:2)
Block(-2,3,0,LEAVES:2)
Block(4,9,0,LEAVES:2)
Block(4,8,0,LEAVES:2)
Block(-1,10,0,LEAVES:2)
Block(-1,11,0,LEAVES:2)
Block(-1,12,0,LEAVES:2)
Block(-5,10,3,LEAVES:2)
Block(-2,10,5,LEAVES:2)
Block(-1,4,1,LOG:2)
Block(-1,3,1,LOG:2)
Block(-1,6,1,LOG:2)
Block(-1,5,1,LOG:2)
Block(-1,8,1,LOG:2)
Block(-1,7,1,LOG:2)
Block(-1,9,1,LOG:2)
Block(-1,9,-4,LEAVES:2)
Block(-1,8,-4,LEAVES:2)
Block(-1,0,1,LOG:2)
Block(-1,-1,1,LOG:2)
Block(-1,-2,1,LOG:2)
Block(-1,-3,1,LOG:2)
Block(-1,2,1,LOG:2)
Block(-1,1,1,LOG:2)
Block(1,9,0,LEAVES:2)
Block(-1,10,4,LEAVES:2)
Block(0,5,2,LEAVES:2)
Block(1,8,0,LEAVES:2)
Block(0,4,2,LOG:2)
Block(1,7,0,LEAVES:2)
Block(1,10,-3,LEAVES:2)
Block(2,10,-2,LEAVES:2)
Block(-3,7,0,LEAVES:2)
Block(-3,6,0,LEAVES:2)
Block(-3,9,0,LEAVES:2)
Block(0,10,-4,LEAVES:2)
Block(-3,8,0,LEAVES:2)
Block(-3,5,0,LEAVES:2)
Block(-3,4,0,LEAVES:2)
Block(-1,5,4,LEAVES:2)
Block(-1,6,4,LEAVES:2)
Block(-2,9,2,LEAVES:2)
Block(-2,8,2,LEAVES:2)
Block(-1,9,4,LEAVES:2)
Block(-2,7,2,LOG:2)
Block(-2,6,2,LOG:2)
Block(-2,5,2,LEAVES:2)
Block(-2,4,2,LOG:2)
Block(-2,3,2,LEAVES:2)
Block(0,6,3,LEAVES:2)
Block(0,5,3,LEAVES:2)
Block(0,7,3,LEAVES:2)
Block(0,4,1,LEAVES:2)
Block(1,9,1,LEAVES:2)
Block(0,3,1,LEAVES:2)
Block(1,8,1,LEAVES:2)
Block(0,6,1,LEAVES:2)
Block(1,7,1,LEAVES:2)
Block(0,5,1,LOG:2)
Block(1,6,1,LEAVES:2)
Block(4,8,-2,LEAVES:2)
Block(4,9,-2,LEAVES:2)
Block(-3,11,0,LEAVES:2)
Block(-1,4,3,LEAVES:2)
Block(-3,10,0,LEAVES:2)
Block(-1,6,3,LEAVES:2)
Block(-1,5,3,LEAVES:2)
Block(-1,8,3,LEAVES:2)
Block(-1,7,3,LEAVES:2)
Block(-2,9,1,LEAVES:2)
Block(-2,8,1,LEAVES:2)
Block(-1,9,3,LEAVES:2)
Block(-2,7,1,LEAVES:2)
Block(-2,6,1,LEAVES:2)
Block(-2,5,1,LEAVES:2)
Block(-2,4,1,LEAVES:2)
Block(-2,3,1,LEAVES:2)
Block(1,6,0,LOG:2)
Block(0,7,2,LEAVES:2)
Block(1,5,0,LEAVES:2)
Block(0,6,2,LEAVES:2)
Block(1,4,0,LEAVES:2)
Block(1,3,0,LEAVES:2)
Block(0,8,2,LEAVES:2)
Block(1,8,2,LEAVES:2)
Block(1,7,2,LEAVES:2)
Block(1,6,2,LEAVES:2)
Block(1,5,2,LEAVES:2)
Block(-4,4,0,LEAVES:2)
Block(-4,8,0,LEAVES:2)
Block(-4,7,0,LEAVES:2)
Block(-4,6,0,LEAVES:2)
Block(-4,5,0,LEAVES:2)
Block(2,7,0,LEAVES:2)
Block(4,9,-1,LEAVES:2)
Block(-3,9,2,LEAVES:2)
Block(2,6,0,LEAVES:2)
Block(4,8,-1,LEAVES:2)
Block(-3,8,2,LEAVES:2)
Block(2,9,0,LEAVES:2)
Block(2,8,0,LEAVES:2)
Block(-3,5,2,LEAVES:2)
Block(-3,4,2,LOG:2)
Block(-3,7,2,LEAVES:2)
Block(-3,6,2,LOG:2)
Block(-1,7,-1,LEAVES:2)
Block(-1,6,-1,LEAVES:2)
Block(-1,5,-1,LEAVES:2)
Block(-1,4,-1,LEAVES:2)
Block(-2,9,4,LEAVES:2)
Block(-2,8,4,LEAVES:2)
Block(-2,7,4,LEAVES:2)
Block(-2,6,4,LEAVES:2)
Block(1,11,0,LEAVES:2)
Block(-2,5,4,LEAVES:2)
Block(1,10,0,LEAVES:2)
Block(-1,9,-1,LEAVES:2)
Block(-1,8,-1,LOG:2)
Block(2,10,-1,LEAVES:2)
Block(1,5,1,LEAVES:2)
Block(1,4,1,LEAVES:2)
Block(1,3,1,LEAVES:2)
Block(0,6,5,LEAVES:2)
Block(0,5,5,LEAVES:2)
Block(0,10,-3,LEAVES:2)
Block(-3,10,1,LEAVES:2)
Block(-3,11,1,LEAVES:2)
Block(1,7,3,LEAVES:2)
Block(1,6,3,LEAVES:2)
Block(0,4,3,LOG:2)
Block(1,5,3,LEAVES:2)
Block(1,4,3,LEAVES:2)
Block(1,9,-5,LEAVES:2)
Block(1,8,-5,LEAVES:2)
Block(2,9,1,LEAVES:2)
Block(2,6,1,LEAVES:2)
Block(2,5,1,LEAVES:2)
Block(-3,9,1,LEAVES:2)
Block(2,8,1,LEAVES:2)
Block(2,7,1,LEAVES:2)
Block(-3,6,1,LEAVES:2)
Block(-1,11,3,LEAVES:2)
Block(-3,5,1,LEAVES:2)
Block(-1,10,3,LEAVES:2)
Block(-3,8,1,LEAVES:2)
Block(-3,7,1,LEAVES:2)
Block(0,10,-2,LEAVES:2)
Block(-3,4,1,LEAVES:2)
Block(-3,3,1,LEAVES:2)
Block(-1,6,5,LEAVES:2)
Block(-2,9,3,LEAVES:2)
Block(-1,5,5,LEAVES:2)
Block(-2,8,3,LEAVES:2)
Block(-2,7,3,LEAVES:2)
Block(-2,6,3,LEAVES:2)
Block(2,5,0,LEAVES:2)
Block(-2,5,3,LEAVES:2)
Block(3,10,-1,LEAVES:2)
Block(2,4,0,LEAVES:2)
Block(-2,4,3,LEAVES:2)
Block(1,10,-2,LEAVES:2)
Block(1,4,2,LEAVES:2)
Block(0,5,4,LEAVES:2)
Block(1,3,2,LEAVES:2)
Block(0,4,4,LEAVES:2)
Block(0,7,4,LEAVES:2)
Block(0,6,4,LEAVES:2)

#######################################################################
# +-----------------------------------------------------------------+ #
# |                            BO3 checks                           | #
# +-----------------------------------------------------------------+ #
#######################################################################

BlockCheck(0,-1,0,GRASS,DIRT:0,DIRT:1,DIRT:2,biomesoplenty:grass:0,biomesoplenty:grass:1,biomesoplenty:grass,biomesoplenty:grass:3,biomesoplenty:grass:4,biomesoplenty:grass:5,biomesoplenty:grass:6,biomesoplenty:grass:7,UNKNOWN_BLOCK:0,UNKNOWN_BLOCK:1,UNKNOWN_BLOCK:2,UNKNOWN_BLOCK:8,UNKNOWN_BLOCK:9,UNKNOWN_BLOCK:10,biomesoplenty:dried_sand,biomesoplenty:hard_ice,biomesoplenty:white_sand,biomesoplenty:white_sandstone,biomesoplenty:mud,biomesoplenty:ash_block)

#######################################################################
# +-----------------------------------------------------------------+ #
# |                             Branches                            | #
# +-----------------------------------------------------------------+ #
#######################################################################


#######################################################################
# +-----------------------------------------------------------------+ #
# |                             Entities                            | #
# +-----------------------------------------------------------------+ #
#######################################################################


#######################################################################
# +-----------------------------------------------------------------+ #
# |                            Particles                            | #
# +-----------------------------------------------------------------+ #
#######################################################################


#######################################################################
# +-----------------------------------------------------------------+ #
# |                             Spawners                            | #
# +-----------------------------------------------------------------+ #
#######################################################################


#######################################################################
# +-----------------------------------------------------------------+ #
# |                             ModData                             | #
# +-----------------------------------------------------------------+ #
#######################################################################

