
#######################################################################
# +-----------------------------------------------------------------+ #
# |                            BO3 object                           | #
# +-----------------------------------------------------------------+ #
#######################################################################

Author: LordSmellyPants

Description: No description given

Version: 3

SettingsMode: WriteWithoutComments


#######################################################################
# +-----------------------------------------------------------------+ #
# |                          Main settings                          | #
# +-----------------------------------------------------------------+ #
#######################################################################

Tree: false

Frequency: 1

Rarity: 30.0

RotateRandomly: true

SpawnHeight: highestSolidBlock

SpawnHeightOffset: 0

SpawnHeightVariance: 0

##############################
# Height Limits for the BO3. #
##############################

MinHeight: 55

MaxHeight: 111

######################
# Extrusion settings #
######################

ExtrudeMode: None

ExtrudeThroughBlocks: AIR

MaxBranchDepth: 10

ExcludedBiomes: All


#######################################################################
# +-----------------------------------------------------------------+ #
# |                      Source block settings                      | #
# +-----------------------------------------------------------------+ #
#######################################################################

SourceBlocks: STONE:1,STONE:3,STONE:5,DIRT:1,DIRT,SAND,GRASS,DIRT:2,STATIONARY_WATER,HARD_CLAY,STAINED_CLAY,CLAY,SANDSTONE,SAND:1,AIR,STONE,GRAVEL,LONG_GRASS,LONG_GRASS:1,LONG_GRASS:2,DEAD_BUSH,YELLOW_FLOWER,RED_ROSE,BROWN_MUSHROOM,RED_MUSHROOM,biomesoplenty:plant_0:1,biomesoplenty:plant_0:2,biomesoplenty:plant_0:3,biomesoplenty:plant_0:4,biomesoplenty:plant_0:5,biomesoplenty:plant_0:6,biomesoplenty:plant_0:7,biomesoplenty:plant_0:8,biomesoplenty:plant_0:9,biomesoplenty:plant_0:10,biomesoplenty:plant_0:11,biomesoplenty:plant_0:12,biomesoplenty:plant_0:13,biomesoplenty:plant_0:14,biomesoplenty:flower_0:1,biomesoplenty:flower_0:2,biomesoplenty:flower_0:3,biomesoplenty:flower_0:4,biomesoplenty:flower_0:5,biomesoplenty:flower_0:6,biomesoplenty:flower_0:7,biomesoplenty:flower_0:8,biomesoplenty:flower_0:9,biomesoplenty:flower_0:10,biomesoplenty:flower_0:11,biomesoplenty:flower_0:12,biomesoplenty:flower_0:13,biomesoplenty:flower_0:14,biomesoplenty:plant_1:0,biomesoplenty:grass:0,biomesoplenty:grass:1,biomesoplenty:grass,biomesoplenty:grass:3,biomesoplenty:grass:4,biomesoplenty:grass:5,biomesoplenty:grass:6,biomesoplenty:grass:7,biomesoplenty:dirt:0,biomesoplenty:dirt:1,biomesoplenty:dirt:2,biomesoplenty:dirt:8,biomesoplenty:dirt:9,biomesoplenty:dirt:10,biomesoplenty:dried_sand:0,biomesoplenty:hard_ice:0,biomesoplenty:white_sand:0,biomesoplenty:white_sandstone:0,biomesoplenty:mud:0,biomesoplenty:ash_block:0

MaxPercentageOutsideSourceBlock: 0

OutsideSourceBlock: placeAnyway

IsOTGPlus: false


#######################################################################
# +-----------------------------------------------------------------+ #
# |                              Blocks                             | #
# +-----------------------------------------------------------------+ #
#######################################################################

Block(-6,13,-3,biomesoplenty:leaves_4:3)
Block(-6,13,-2,biomesoplenty:leaves_4:3)
Block(-6,13,0,biomesoplenty:leaves_4:3)
Block(-5,13,-4,biomesoplenty:leaves_4:3)
Block(-5,13,-3,biomesoplenty:leaves_4:3)
Block(-5,13,-2,biomesoplenty:leaves_4:3)
Block(-5,13,-1,biomesoplenty:leaves_4:3)
Block(-5,13,0,biomesoplenty:leaves_4:3)
Block(-5,13,1,biomesoplenty:leaves_4:3)
Block(-5,13,3,biomesoplenty:leaves_4:3)
Block(-5,13,5,biomesoplenty:leaves_4:3)
Block(-5,14,-3,biomesoplenty:leaves_4:3)
Block(-5,14,-2,biomesoplenty:leaves_4:3)
Block(-5,14,-1,biomesoplenty:leaves_4:3)
Block(-5,14,0,biomesoplenty:leaves_4:3)
Block(-5,15,-1,biomesoplenty:leaves_4:3)
Block(-4,13,-5,biomesoplenty:leaves_4:3)
Block(-4,13,-4,biomesoplenty:leaves_4:3)
Block(-4,13,-3,biomesoplenty:leaves_4:3)
Block(-4,13,-2,biomesoplenty:leaves_4:3)
Block(-4,13,-1,biomesoplenty:leaves_4:3)
Block(-4,13,0,biomesoplenty:leaves_4:3)
Block(-4,13,1,biomesoplenty:leaves_4:3)
Block(-4,13,2,biomesoplenty:leaves_4:3)
Block(-4,13,3,biomesoplenty:leaves_4:3)
Block(-4,13,4,biomesoplenty:leaves_4:3)
Block(-4,13,5,biomesoplenty:leaves_4:3)
Block(-4,14,-4,biomesoplenty:leaves_4:3)
Block(-4,14,-3,biomesoplenty:leaves_4:3)
Block(-4,14,-2,biomesoplenty:leaves_4:3)
Block(-4,14,-1,biomesoplenty:leaves_4:3)
Block(-4,14,0,biomesoplenty:leaves_4:3)
Block(-4,14,2,biomesoplenty:leaves_4:3)
Block(-4,14,3,biomesoplenty:leaves_4:3)
Block(-4,14,4,biomesoplenty:leaves_4:3)
Block(-4,15,-2,biomesoplenty:leaves_4:3)
Block(-4,15,-1,biomesoplenty:leaves_4:3)
Block(-4,15,0,biomesoplenty:leaves_4:3)
Block(-3,12,4,biomesoplenty:log_2:5)
Block(-3,13,-6,biomesoplenty:leaves_4:3)
Block(-3,13,-5,biomesoplenty:leaves_4:3)
Block(-3,13,-4,biomesoplenty:leaves_4:3)
Block(-3,13,-3,biomesoplenty:leaves_4:3)
Block(-3,13,-2,biomesoplenty:leaves_4:3)
Block(-3,13,-1,biomesoplenty:leaves_4:3)
Block(-3,13,0,biomesoplenty:leaves_4:3)
Block(-3,13,1,biomesoplenty:leaves_4:3)
Block(-3,13,2,biomesoplenty:leaves_4:3)
Block(-3,13,3,biomesoplenty:leaves_4:3)
Block(-3,13,4,biomesoplenty:log_2:5)
Block(-3,13,5,biomesoplenty:leaves_4:3)
Block(-3,13,6,biomesoplenty:leaves_4:3)
Block(-3,14,-5,biomesoplenty:leaves_4:3)
Block(-3,14,-4,biomesoplenty:leaves_4:3)
Block(-3,14,-3,biomesoplenty:leaves_4:3)
Block(-3,14,-2,biomesoplenty:leaves_4:3)
Block(-3,14,-1,biomesoplenty:leaves_4:3)
Block(-3,14,0,biomesoplenty:leaves_4:3)
Block(-3,14,1,biomesoplenty:leaves_4:3)
Block(-3,14,2,biomesoplenty:leaves_4:3)
Block(-3,14,3,biomesoplenty:leaves_4:3)
Block(-3,14,4,biomesoplenty:log_2:5)
Block(-3,14,5,biomesoplenty:leaves_4:3)
Block(-3,15,-4,biomesoplenty:leaves_4:3)
Block(-3,15,-1,biomesoplenty:leaves_4:3)
Block(-3,15,0,biomesoplenty:leaves_4:3)
Block(-3,15,3,biomesoplenty:leaves_4:3)
Block(-3,15,4,biomesoplenty:leaves_4:3)
Block(-3,15,5,biomesoplenty:leaves_4:3)
Block(-2,-7,0,biomesoplenty:log_2:5)
Block(-2,-6,0,biomesoplenty:log_2:5)
Block(-2,-5,0,biomesoplenty:log_2:5)
Block(-2,-4,0,biomesoplenty:log_2:5)
Block(-2,-3,0,biomesoplenty:log_2:5)
Block(-2,-2,0,biomesoplenty:log_2:5)
Block(-2,-1,0,biomesoplenty:log_2:5)
Block(-2,0,0,biomesoplenty:log_2:5)
Block(-2,1,0,biomesoplenty:log_2:5)
Block(-2,11,-3,biomesoplenty:log_2:5)
Block(-2,11,3,biomesoplenty:log_2:5)
Block(-2,12,-4,biomesoplenty:log_2:5)
Block(-2,13,-5,biomesoplenty:leaves_4:3)
Block(-2,13,-4,biomesoplenty:log_2:5)
Block(-2,13,-3,biomesoplenty:leaves_4:3)
Block(-2,13,-2,biomesoplenty:leaves_4:3)
Block(-2,13,-1,biomesoplenty:leaves_4:3)
Block(-2,13,0,biomesoplenty:leaves_4:3)
Block(-2,13,1,biomesoplenty:leaves_4:3)
Block(-2,13,2,biomesoplenty:leaves_4:3)
Block(-2,13,3,biomesoplenty:leaves_4:3)
Block(-2,13,4,biomesoplenty:leaves_4:3)
Block(-2,13,5,biomesoplenty:leaves_4:3)
Block(-2,13,6,biomesoplenty:leaves_4:3)
Block(-2,14,-5,biomesoplenty:leaves_4:3)
Block(-2,14,-4,biomesoplenty:log_2:5)
Block(-2,14,-3,biomesoplenty:leaves_4:3)
Block(-2,14,-2,biomesoplenty:leaves_4:3)
Block(-2,14,-1,biomesoplenty:leaves_4:3)
Block(-2,14,0,biomesoplenty:leaves_4:3)
Block(-2,14,1,biomesoplenty:leaves_4:3)
Block(-2,14,2,biomesoplenty:leaves_4:3)
Block(-2,14,3,biomesoplenty:leaves_4:3)
Block(-2,14,4,biomesoplenty:leaves_4:3)
Block(-2,14,5,biomesoplenty:leaves_4:3)
Block(-2,15,-5,biomesoplenty:leaves_4:3)
Block(-2,15,-4,biomesoplenty:leaves_4:3)
Block(-2,15,-2,biomesoplenty:leaves_4:3)
Block(-2,15,-1,biomesoplenty:leaves_4:3)
Block(-2,15,0,biomesoplenty:leaves_4:3)
Block(-2,15,1,biomesoplenty:leaves_4:3)
Block(-2,15,2,biomesoplenty:leaves_4:3)
Block(-2,15,3,biomesoplenty:leaves_4:3)
Block(-1,-7,1,biomesoplenty:log_2:5)
Block(-1,-6,1,biomesoplenty:log_2:5)
Block(-1,-5,1,biomesoplenty:log_2:5)
Block(-1,-4,1,biomesoplenty:log_2:5)
Block(-1,-3,1,biomesoplenty:log_2:5)
Block(-1,-2,1,biomesoplenty:log_2:5)
Block(-1,-1,-1,biomesoplenty:log_2:5)
Block(-1,-1,1,biomesoplenty:log_2:5)
Block(-1,0,-1,biomesoplenty:log_2:5)
Block(-1,0,0,biomesoplenty:log_2:5)
Block(-1,0,1,biomesoplenty:log_2:5)
Block(-1,1,-1,biomesoplenty:log_2:5)
Block(-1,1,0,biomesoplenty:log_2:5)
Block(-1,1,1,biomesoplenty:log_2:5)
Block(-1,2,-1,biomesoplenty:log_2:5)
Block(-1,2,0,biomesoplenty:log_2:5)
Block(-1,2,1,biomesoplenty:log_2:5)
Block(-1,3,-1,biomesoplenty:log_2:5)
Block(-1,3,0,biomesoplenty:log_2:5)
Block(-1,4,0,biomesoplenty:log_2:5)
Block(-1,9,-1,biomesoplenty:log_2:5)
Block(-1,10,-2,biomesoplenty:log_2:5)
Block(-1,11,2,biomesoplenty:log_2:5)
Block(-1,13,-6,biomesoplenty:leaves_4:3)
Block(-1,13,-5,biomesoplenty:leaves_4:3)
Block(-1,13,-4,biomesoplenty:leaves_4:3)
Block(-1,13,-3,biomesoplenty:leaves_4:3)
Block(-1,13,-2,biomesoplenty:leaves_4:3)
Block(-1,13,-1,biomesoplenty:leaves_4:3)
Block(-1,13,0,biomesoplenty:leaves_4:3)
Block(-1,13,1,biomesoplenty:leaves_4:3)
Block(-1,13,2,biomesoplenty:leaves_4:3)
Block(-1,13,3,biomesoplenty:leaves_4:3)
Block(-1,13,4,biomesoplenty:leaves_4:3)
Block(-1,13,5,biomesoplenty:leaves_4:3)
Block(-1,14,-6,biomesoplenty:leaves_4:3)
Block(-1,14,-5,biomesoplenty:leaves_4:3)
Block(-1,14,-4,biomesoplenty:leaves_4:3)
Block(-1,14,-3,biomesoplenty:leaves_4:3)
Block(-1,14,-2,biomesoplenty:log_2:5)
Block(-1,14,-1,biomesoplenty:leaves_4:3)
Block(-1,14,0,biomesoplenty:log_2:5)
Block(-1,14,1,biomesoplenty:leaves_4:3)
Block(-1,14,2,biomesoplenty:leaves_4:3)
Block(-1,14,3,biomesoplenty:leaves_4:3)
Block(-1,14,4,biomesoplenty:leaves_4:3)
Block(-1,15,-4,biomesoplenty:leaves_4:3)
Block(-1,15,-3,biomesoplenty:leaves_4:3)
Block(-1,15,-2,biomesoplenty:leaves_4:3)
Block(-1,15,-1,biomesoplenty:leaves_4:3)
Block(-1,15,0,biomesoplenty:leaves_4:3)
Block(-1,15,1,biomesoplenty:leaves_4:3)
Block(0,-7,-2,biomesoplenty:log_2:5)
Block(0,-6,-2,biomesoplenty:log_2:5)
Block(0,-5,-2,biomesoplenty:log_2:5)
Block(0,-4,-2,biomesoplenty:log_2:5)
Block(0,-3,-2,biomesoplenty:log_2:5)
Block(0,-3,2,biomesoplenty:log_2:5)
Block(0,-2,-2,biomesoplenty:log_2:5)
Block(0,-2,2,biomesoplenty:log_2:5)
Block(0,-1,-2,biomesoplenty:log_2:5)
Block(0,-1,0,biomesoplenty:log_2:5)
Block(0,-1,2,biomesoplenty:log_2:5)
Block(0,0,-2,biomesoplenty:log_2:5)
Block(0,0,-1,biomesoplenty:log_2:5)
Block(0,0,0,biomesoplenty:log_2:5)
Block(0,0,1,biomesoplenty:log_2:5)
Block(0,0,2,biomesoplenty:log_2:5)
Block(0,1,-2,biomesoplenty:log_2:5)
Block(0,1,-1,biomesoplenty:log_2:5)
Block(0,1,0,biomesoplenty:log_2:5)
Block(0,1,1,biomesoplenty:log_2:5)
Block(0,1,2,biomesoplenty:log_2:5)
Block(0,2,-1,biomesoplenty:log_2:5)
Block(0,2,0,biomesoplenty:log_2:5)
Block(0,2,1,biomesoplenty:log_2:5)
Block(0,3,-1,biomesoplenty:log_2:5)
Block(0,3,0,biomesoplenty:log_2:5)
Block(0,3,1,biomesoplenty:log_2:5)
Block(0,4,-1,biomesoplenty:log_2:5)
Block(0,4,0,biomesoplenty:log_2:5)
Block(0,5,-1,biomesoplenty:log_2:5)
Block(0,5,0,biomesoplenty:log_2:5)
Block(0,6,-1,biomesoplenty:log_2:5)
Block(0,6,0,biomesoplenty:log_2:5)
Block(0,7,0,biomesoplenty:log_2:5)
Block(0,8,0,biomesoplenty:log_2:5)
Block(0,9,0,biomesoplenty:log_2:5)
Block(0,10,1,biomesoplenty:log_2:5)
Block(0,13,-6,biomesoplenty:leaves_4:3)
Block(0,13,-5,biomesoplenty:leaves_4:3)
Block(0,13,-4,biomesoplenty:leaves_4:3)
Block(0,13,-3,biomesoplenty:leaves_4:3)
Block(0,13,-2,biomesoplenty:leaves_4:3)
Block(0,13,-1,biomesoplenty:leaves_4:3)
Block(0,13,0,biomesoplenty:leaves_4:3)
Block(0,13,1,biomesoplenty:leaves_4:3)
Block(0,13,2,biomesoplenty:leaves_4:3)
Block(0,13,3,biomesoplenty:leaves_4:3)
Block(0,13,4,biomesoplenty:leaves_4:3)
Block(0,14,-6,biomesoplenty:leaves_4:3)
Block(0,14,-5,biomesoplenty:log_2:5)
Block(0,14,-4,biomesoplenty:leaves_4:3)
Block(0,14,-3,biomesoplenty:leaves_4:3)
Block(0,14,-2,biomesoplenty:leaves_4:3)
Block(0,14,-1,biomesoplenty:leaves_4:3)
Block(0,14,0,biomesoplenty:leaves_4:3)
Block(0,14,1,biomesoplenty:leaves_4:3)
Block(0,14,2,biomesoplenty:leaves_4:3)
Block(0,14,3,biomesoplenty:leaves_4:3)
Block(0,15,-5,biomesoplenty:leaves_4:3)
Block(0,15,-4,biomesoplenty:leaves_4:3)
Block(0,15,-3,biomesoplenty:leaves_4:3)
Block(0,15,-2,biomesoplenty:leaves_4:3)
Block(0,15,-1,biomesoplenty:leaves_4:3)
Block(0,15,0,biomesoplenty:leaves_4:3)
Block(0,15,1,biomesoplenty:leaves_4:3)
Block(0,15,2,biomesoplenty:leaves_4:3)
Block(1,-6,-1,biomesoplenty:log_2:5)
Block(1,-6,1,biomesoplenty:log_2:5)
Block(1,-5,-1,biomesoplenty:log_2:5)
Block(1,-5,1,biomesoplenty:log_2:5)
Block(1,-4,-1,biomesoplenty:log_2:5)
Block(1,-4,1,biomesoplenty:log_2:5)
Block(1,-3,-1,biomesoplenty:log_2:5)
Block(1,-3,1,biomesoplenty:log_2:5)
Block(1,-2,-1,biomesoplenty:log_2:5)
Block(1,-2,1,biomesoplenty:log_2:5)
Block(1,-1,-1,biomesoplenty:log_2:5)
Block(1,-1,1,biomesoplenty:log_2:5)
Block(1,0,-1,biomesoplenty:log_2:5)
Block(1,0,0,biomesoplenty:log_2:5)
Block(1,0,1,biomesoplenty:log_2:5)
Block(1,1,-1,biomesoplenty:log_2:5)
Block(1,1,0,biomesoplenty:log_2:5)
Block(1,1,1,biomesoplenty:log_2:5)
Block(1,2,-1,biomesoplenty:log_2:5)
Block(1,2,0,biomesoplenty:log_2:5)
Block(1,2,1,biomesoplenty:log_2:5)
Block(1,3,-1,biomesoplenty:log_2:5)
Block(1,3,0,biomesoplenty:log_2:5)
Block(1,3,1,biomesoplenty:log_2:5)
Block(1,4,-1,biomesoplenty:log_2:5)
Block(1,4,0,biomesoplenty:log_2:5)
Block(1,4,1,biomesoplenty:log_2:5)
Block(1,5,0,biomesoplenty:log_2:5)
Block(1,5,1,biomesoplenty:log_2:5)
Block(1,6,0,biomesoplenty:log_2:5)
Block(1,7,0,biomesoplenty:log_2:5)
Block(1,11,2,biomesoplenty:log_2:5)
Block(1,13,-5,biomesoplenty:leaves_4:3)
Block(1,13,-4,biomesoplenty:leaves_4:3)
Block(1,13,-3,biomesoplenty:leaves_4:3)
Block(1,13,-2,biomesoplenty:leaves_4:3)
Block(1,13,-1,biomesoplenty:leaves_4:3)
Block(1,13,0,biomesoplenty:leaves_4:3)
Block(1,13,1,biomesoplenty:leaves_4:3)
Block(1,13,2,biomesoplenty:leaves_4:3)
Block(1,13,3,biomesoplenty:leaves_4:3)
Block(1,13,4,biomesoplenty:leaves_4:3)
Block(1,13,5,biomesoplenty:leaves_4:3)
Block(1,14,-5,biomesoplenty:leaves_4:3)
Block(1,14,-4,biomesoplenty:leaves_4:3)
Block(1,14,-3,biomesoplenty:leaves_4:3)
Block(1,14,-2,biomesoplenty:leaves_4:3)
Block(1,14,-1,biomesoplenty:log_2:5)
Block(1,14,0,biomesoplenty:leaves_4:3)
Block(1,14,1,biomesoplenty:log_2:5)
Block(1,14,2,biomesoplenty:log_2:5)
Block(1,14,3,biomesoplenty:leaves_4:3)
Block(1,14,4,biomesoplenty:leaves_4:3)
Block(1,15,-3,biomesoplenty:leaves_4:3)
Block(1,15,-2,biomesoplenty:leaves_4:3)
Block(1,15,-1,biomesoplenty:leaves_4:3)
Block(1,15,0,biomesoplenty:leaves_4:3)
Block(1,15,1,biomesoplenty:leaves_4:3)
Block(1,15,2,biomesoplenty:leaves_4:3)
Block(1,15,3,biomesoplenty:leaves_4:3)
Block(2,-4,0,biomesoplenty:log_2:5)
Block(2,-3,0,biomesoplenty:log_2:5)
Block(2,-2,0,biomesoplenty:log_2:5)
Block(2,-1,0,biomesoplenty:log_2:5)
Block(2,0,0,biomesoplenty:log_2:5)
Block(2,1,0,biomesoplenty:log_2:5)
Block(2,2,0,biomesoplenty:log_2:5)
Block(2,3,0,biomesoplenty:log_2:5)
Block(2,12,3,biomesoplenty:log_2:5)
Block(2,13,-4,biomesoplenty:leaves_4:3)
Block(2,13,-3,biomesoplenty:leaves_4:3)
Block(2,13,-2,biomesoplenty:leaves_4:3)
Block(2,13,-1,biomesoplenty:leaves_4:3)
Block(2,13,0,biomesoplenty:leaves_4:3)
Block(2,13,1,biomesoplenty:leaves_4:3)
Block(2,13,2,biomesoplenty:leaves_4:3)
Block(2,13,3,biomesoplenty:leaves_4:3)
Block(2,13,4,biomesoplenty:leaves_4:3)
Block(2,13,5,biomesoplenty:leaves_4:3)
Block(2,14,-3,biomesoplenty:leaves_4:3)
Block(2,14,-2,biomesoplenty:leaves_4:3)
Block(2,14,-1,biomesoplenty:leaves_4:3)
Block(2,14,0,biomesoplenty:leaves_4:3)
Block(2,14,1,biomesoplenty:leaves_4:3)
Block(2,14,2,biomesoplenty:leaves_4:3)
Block(2,14,3,biomesoplenty:leaves_4:3)
Block(2,14,4,biomesoplenty:leaves_4:3)
Block(2,15,-1,biomesoplenty:leaves_4:3)
Block(2,15,0,biomesoplenty:leaves_4:3)
Block(2,15,2,biomesoplenty:leaves_4:3)
Block(2,15,3,biomesoplenty:leaves_4:3)
Block(3,13,-3,biomesoplenty:leaves_4:3)
Block(3,13,-2,biomesoplenty:leaves_4:3)
Block(3,13,-1,biomesoplenty:leaves_4:3)
Block(3,13,0,biomesoplenty:leaves_4:3)
Block(3,13,1,biomesoplenty:leaves_4:3)
Block(3,13,2,biomesoplenty:leaves_4:3)
Block(3,13,3,biomesoplenty:leaves_4:3)
Block(3,13,4,biomesoplenty:leaves_4:3)
Block(3,14,-1,biomesoplenty:leaves_4:3)
Block(3,14,0,biomesoplenty:leaves_4:3)
Block(3,14,1,biomesoplenty:leaves_4:3)
Block(3,14,2,biomesoplenty:leaves_4:3)
Block(3,14,3,biomesoplenty:leaves_4:3)
Block(3,15,0,biomesoplenty:leaves_4:3)
Block(3,15,2,biomesoplenty:leaves_4:3)
Block(4,13,-1,biomesoplenty:leaves_4:3)
Block(4,13,0,biomesoplenty:leaves_4:3)
Block(4,13,2,biomesoplenty:leaves_4:3)

#######################################################################
# +-----------------------------------------------------------------+ #
# |                            BO3 checks                           | #
# +-----------------------------------------------------------------+ #
#######################################################################

BlockCheck(0,-1,0,GRASS,DIRT,DIRT:2,DIRT:1,SAND,HARD_CLAY)

#######################################################################
# +-----------------------------------------------------------------+ #
# |                             Branches                            | #
# +-----------------------------------------------------------------+ #
#######################################################################


#######################################################################
# +-----------------------------------------------------------------+ #
# |                             Entities                            | #
# +-----------------------------------------------------------------+ #
#######################################################################


#######################################################################
# +-----------------------------------------------------------------+ #
# |                            Particles                            | #
# +-----------------------------------------------------------------+ #
#######################################################################


#######################################################################
# +-----------------------------------------------------------------+ #
# |                             Spawners                            | #
# +-----------------------------------------------------------------+ #
#######################################################################


#######################################################################
# +-----------------------------------------------------------------+ #
# |                             ModData                             | #
# +-----------------------------------------------------------------+ #
#######################################################################

