
#######################################################################
# +-----------------------------------------------------------------+ #
# |                            BO3 object                           | #
# +-----------------------------------------------------------------+ #
#######################################################################

Author: LordSmellyPants

Description: No description given

Version: 3

SettingsMode: WriteWithoutComments


#######################################################################
# +-----------------------------------------------------------------+ #
# |                          Main settings                          | #
# +-----------------------------------------------------------------+ #
#######################################################################

Tree: false

Frequency: 1

Rarity: 10.0

RotateRandomly: true

SpawnHeight: highestSolidBlock

SpawnHeightOffset: 0

SpawnHeightVariance: 0

##############################
# Height Limits for the BO3. #
##############################

MinHeight: 55

MaxHeight: 111

######################
# Extrusion settings #
######################

ExtrudeMode: None

ExtrudeThroughBlocks: AIR

MaxBranchDepth: 10

ExcludedBiomes: All


#######################################################################
# +-----------------------------------------------------------------+ #
# |                      Source block settings                      | #
# +-----------------------------------------------------------------+ #
#######################################################################

SourceBlocks: STONE:1,STONE:3,STONE:5,DIRT:1,DIRT,SAND,GRASS,DIRT:2,STATIONARY_WATER,HARD_CLAY,STAINED_CLAY,CLAY,SANDSTONE,SAND:1,AIR,STONE,GRAVEL,LONG_GRASS,LONG_GRASS:1,LONG_GRASS:2,DEAD_BUSH,YELLOW_FLOWER,RED_ROSE,BROWN_MUSHROOM,RED_MUSHROOM,biomesoplenty:plant_0:1,biomesoplenty:plant_0:2,biomesoplenty:plant_0:3,biomesoplenty:plant_0:4,biomesoplenty:plant_0:5,biomesoplenty:plant_0:6,biomesoplenty:plant_0:7,biomesoplenty:plant_0:8,biomesoplenty:plant_0:9,biomesoplenty:plant_0:10,biomesoplenty:plant_0:11,biomesoplenty:plant_0:12,biomesoplenty:plant_0:13,biomesoplenty:plant_0:14,biomesoplenty:flower_0:1,biomesoplenty:flower_0:2,biomesoplenty:flower_0:3,biomesoplenty:flower_0:4,biomesoplenty:flower_0:5,biomesoplenty:flower_0:6,biomesoplenty:flower_0:7,biomesoplenty:flower_0:8,biomesoplenty:flower_0:9,biomesoplenty:flower_0:10,biomesoplenty:flower_0:11,biomesoplenty:flower_0:12,biomesoplenty:flower_0:13,biomesoplenty:flower_0:14,biomesoplenty:plant_1:0,biomesoplenty:grass:0,biomesoplenty:grass:1,biomesoplenty:grass,biomesoplenty:grass:3,biomesoplenty:grass:4,biomesoplenty:grass:5,biomesoplenty:grass:6,biomesoplenty:grass:7,biomesoplenty:dirt:0,biomesoplenty:dirt:1,biomesoplenty:dirt:2,biomesoplenty:dirt:8,biomesoplenty:dirt:9,biomesoplenty:dirt:10,biomesoplenty:dried_sand:0,biomesoplenty:hard_ice:0,biomesoplenty:white_sand:0,biomesoplenty:white_sandstone:0,biomesoplenty:mud:0,biomesoplenty:ash_block:0

MaxPercentageOutsideSourceBlock: 0

OutsideSourceBlock: placeAnyway

IsOTGPlus: false


#######################################################################
# +-----------------------------------------------------------------+ #
# |                              Blocks                             | #
# +-----------------------------------------------------------------+ #
#######################################################################

Block(-12,27,-8,biomesoplenty:leaves_4:3)
Block(-12,27,-7,biomesoplenty:leaves_4:3)
Block(-12,27,-1,biomesoplenty:leaves_4:3)
Block(-12,27,0,biomesoplenty:leaves_4:3)
Block(-11,27,-9,biomesoplenty:leaves_4:3)
Block(-11,27,-8,biomesoplenty:leaves_4:3)
Block(-11,27,-7,biomesoplenty:leaves_4:3)
Block(-11,27,-6,biomesoplenty:leaves_4:3)
Block(-11,27,-4,biomesoplenty:leaves_4:3)
Block(-11,27,-2,biomesoplenty:leaves_4:3)
Block(-11,27,-1,biomesoplenty:leaves_4:3)
Block(-11,27,0,biomesoplenty:leaves_4:3)
Block(-11,27,1,biomesoplenty:leaves_4:3)
Block(-11,27,3,biomesoplenty:leaves_4:3)
Block(-11,28,-8,biomesoplenty:leaves_4:3)
Block(-11,28,-7,biomesoplenty:leaves_4:3)
Block(-11,28,-1,biomesoplenty:leaves_4:3)
Block(-11,28,0,biomesoplenty:leaves_4:3)
Block(-10,27,-10,biomesoplenty:leaves_4:3)
Block(-10,27,-9,biomesoplenty:leaves_4:3)
Block(-10,27,-8,biomesoplenty:log_2:5)
Block(-10,27,-7,biomesoplenty:leaves_4:3)
Block(-10,27,-6,biomesoplenty:leaves_4:3)
Block(-10,27,-5,biomesoplenty:leaves_4:3)
Block(-10,27,-4,biomesoplenty:leaves_4:3)
Block(-10,27,-3,biomesoplenty:leaves_4:3)
Block(-10,27,-2,biomesoplenty:leaves_4:3)
Block(-10,27,-1,biomesoplenty:leaves_4:3)
Block(-10,27,0,biomesoplenty:leaves_4:3)
Block(-10,27,1,biomesoplenty:leaves_4:3)
Block(-10,27,2,biomesoplenty:leaves_4:3)
Block(-10,27,3,biomesoplenty:leaves_4:3)
Block(-10,27,4,biomesoplenty:leaves_4:3)
Block(-10,27,6,biomesoplenty:leaves_4:3)
Block(-10,27,8,biomesoplenty:leaves_4:3)
Block(-10,27,9,biomesoplenty:leaves_4:3)
Block(-10,28,-9,biomesoplenty:leaves_4:3)
Block(-10,28,-8,biomesoplenty:log_2:5)
Block(-10,28,-7,biomesoplenty:leaves_4:3)
Block(-10,28,-6,biomesoplenty:leaves_4:3)
Block(-10,28,-5,biomesoplenty:leaves_4:3)
Block(-10,28,-3,biomesoplenty:leaves_4:3)
Block(-10,28,-2,biomesoplenty:leaves_4:3)
Block(-10,28,-1,biomesoplenty:leaves_4:3)
Block(-10,28,0,biomesoplenty:leaves_4:3)
Block(-10,28,1,biomesoplenty:leaves_4:3)
Block(-10,28,2,biomesoplenty:leaves_4:3)
Block(-10,29,-8,biomesoplenty:leaves_4:3)
Block(-10,29,-7,biomesoplenty:leaves_4:3)
Block(-10,29,-1,biomesoplenty:leaves_4:3)
Block(-10,29,0,biomesoplenty:leaves_4:3)
Block(-10,29,1,biomesoplenty:leaves_4:3)
Block(-9,27,-9,biomesoplenty:leaves_4:3)
Block(-9,27,-8,biomesoplenty:leaves_4:3)
Block(-9,27,-7,biomesoplenty:leaves_4:3)
Block(-9,27,-6,biomesoplenty:leaves_4:3)
Block(-9,27,-5,biomesoplenty:leaves_4:3)
Block(-9,27,-4,biomesoplenty:leaves_4:3)
Block(-9,27,-3,biomesoplenty:leaves_4:3)
Block(-9,27,-2,biomesoplenty:leaves_4:3)
Block(-9,27,-1,biomesoplenty:leaves_4:3)
Block(-9,27,0,biomesoplenty:log_2:5)
Block(-9,27,1,biomesoplenty:leaves_4:3)
Block(-9,27,2,biomesoplenty:leaves_4:3)
Block(-9,27,3,biomesoplenty:leaves_4:3)
Block(-9,27,4,biomesoplenty:leaves_4:3)
Block(-9,27,5,biomesoplenty:leaves_4:3)
Block(-9,27,6,biomesoplenty:leaves_4:3)
Block(-9,27,7,biomesoplenty:leaves_4:3)
Block(-9,27,8,biomesoplenty:leaves_4:3)
Block(-9,27,9,biomesoplenty:leaves_4:3)
Block(-9,27,10,biomesoplenty:leaves_4:3)
Block(-9,28,-9,biomesoplenty:leaves_4:3)
Block(-9,28,-8,biomesoplenty:leaves_4:3)
Block(-9,28,-7,biomesoplenty:leaves_4:3)
Block(-9,28,-6,biomesoplenty:leaves_4:3)
Block(-9,28,-5,biomesoplenty:leaves_4:3)
Block(-9,28,-4,biomesoplenty:leaves_4:3)
Block(-9,28,-3,biomesoplenty:leaves_4:3)
Block(-9,28,-2,biomesoplenty:leaves_4:3)
Block(-9,28,-1,biomesoplenty:leaves_4:3)
Block(-9,28,0,biomesoplenty:leaves_4:3)
Block(-9,28,1,biomesoplenty:leaves_4:3)
Block(-9,28,2,biomesoplenty:leaves_4:3)
Block(-9,28,3,biomesoplenty:leaves_4:3)
Block(-9,28,6,biomesoplenty:leaves_4:3)
Block(-9,28,8,biomesoplenty:leaves_4:3)
Block(-9,29,-8,biomesoplenty:leaves_4:3)
Block(-9,29,-7,biomesoplenty:leaves_4:3)
Block(-9,29,-6,biomesoplenty:leaves_4:3)
Block(-9,29,-5,biomesoplenty:leaves_4:3)
Block(-9,29,-3,biomesoplenty:leaves_4:3)
Block(-9,29,-2,biomesoplenty:leaves_4:3)
Block(-9,29,-1,biomesoplenty:leaves_4:3)
Block(-9,29,0,biomesoplenty:leaves_4:3)
Block(-9,29,1,biomesoplenty:leaves_4:3)
Block(-9,29,2,biomesoplenty:leaves_4:3)
Block(-9,29,3,biomesoplenty:leaves_4:3)
Block(-9,29,4,biomesoplenty:leaves_4:3)
Block(-9,30,-6,biomesoplenty:leaves_4:3)
Block(-8,26,-8,biomesoplenty:log_2:5)
Block(-8,26,3,biomesoplenty:log_2:5)
Block(-8,27,-11,biomesoplenty:leaves_4:3)
Block(-8,27,-10,biomesoplenty:leaves_4:3)
Block(-8,27,-9,biomesoplenty:leaves_4:3)
Block(-8,27,-8,biomesoplenty:leaves_4:3)
Block(-8,27,-7,biomesoplenty:leaves_4:3)
Block(-8,27,-6,biomesoplenty:log_2:5)
Block(-8,27,-5,biomesoplenty:leaves_4:3)
Block(-8,27,-4,biomesoplenty:leaves_4:3)
Block(-8,27,-3,biomesoplenty:leaves_4:3)
Block(-8,27,-2,biomesoplenty:leaves_4:3)
Block(-8,27,-1,biomesoplenty:leaves_4:3)
Block(-8,27,0,biomesoplenty:leaves_4:3)
Block(-8,27,1,biomesoplenty:leaves_4:3)
Block(-8,27,2,biomesoplenty:leaves_4:3)
Block(-8,27,3,biomesoplenty:log_2:5)
Block(-8,27,4,biomesoplenty:leaves_4:3)
Block(-8,27,5,biomesoplenty:leaves_4:3)
Block(-8,27,6,biomesoplenty:leaves_4:3)
Block(-8,27,7,biomesoplenty:leaves_4:3)
Block(-8,27,8,biomesoplenty:leaves_4:3)
Block(-8,27,9,biomesoplenty:leaves_4:3)
Block(-8,27,10,biomesoplenty:leaves_4:3)
Block(-8,27,11,biomesoplenty:leaves_4:3)
Block(-8,28,-10,biomesoplenty:leaves_4:3)
Block(-8,28,-9,biomesoplenty:log_2:5)
Block(-8,28,-8,biomesoplenty:leaves_4:3)
Block(-8,28,-7,biomesoplenty:leaves_4:3)
Block(-8,28,-6,biomesoplenty:log_2:5)
Block(-8,28,-5,biomesoplenty:leaves_4:3)
Block(-8,28,-4,biomesoplenty:leaves_4:3)
Block(-8,28,-3,biomesoplenty:leaves_4:3)
Block(-8,28,-2,biomesoplenty:leaves_4:3)
Block(-8,28,-1,biomesoplenty:leaves_4:3)
Block(-8,28,0,biomesoplenty:leaves_4:3)
Block(-8,28,1,biomesoplenty:leaves_4:3)
Block(-8,28,2,biomesoplenty:leaves_4:3)
Block(-8,28,3,biomesoplenty:leaves_4:3)
Block(-8,28,4,biomesoplenty:leaves_4:3)
Block(-8,28,5,biomesoplenty:leaves_4:3)
Block(-8,28,6,biomesoplenty:leaves_4:3)
Block(-8,28,7,biomesoplenty:leaves_4:3)
Block(-8,28,8,biomesoplenty:leaves_4:3)
Block(-8,28,9,biomesoplenty:leaves_4:3)
Block(-8,28,10,biomesoplenty:leaves_4:3)
Block(-8,29,-9,biomesoplenty:leaves_4:3)
Block(-8,29,-8,biomesoplenty:leaves_4:3)
Block(-8,29,-7,biomesoplenty:leaves_4:3)
Block(-8,29,-6,biomesoplenty:log_2:5)
Block(-8,29,-5,biomesoplenty:leaves_4:3)
Block(-8,29,-4,biomesoplenty:leaves_4:3)
Block(-8,29,-3,biomesoplenty:leaves_4:3)
Block(-8,29,-2,biomesoplenty:leaves_4:3)
Block(-8,29,-1,biomesoplenty:leaves_4:3)
Block(-8,29,0,biomesoplenty:leaves_4:3)
Block(-8,29,1,biomesoplenty:leaves_4:3)
Block(-8,29,2,biomesoplenty:leaves_4:3)
Block(-8,29,3,biomesoplenty:leaves_4:3)
Block(-8,29,4,biomesoplenty:leaves_4:3)
Block(-8,29,5,biomesoplenty:leaves_4:3)
Block(-8,29,7,biomesoplenty:leaves_4:3)
Block(-8,29,8,biomesoplenty:leaves_4:3)
Block(-8,30,-8,biomesoplenty:leaves_4:3)
Block(-8,30,-7,biomesoplenty:leaves_4:3)
Block(-8,30,-6,biomesoplenty:leaves_4:3)
Block(-8,30,-5,biomesoplenty:leaves_4:3)
Block(-8,30,-2,biomesoplenty:leaves_4:3)
Block(-8,30,-1,biomesoplenty:leaves_4:3)
Block(-8,30,1,biomesoplenty:leaves_4:3)
Block(-8,30,3,biomesoplenty:leaves_4:3)
Block(-8,30,4,biomesoplenty:leaves_4:3)
Block(-7,25,-7,biomesoplenty:log_2:5)
Block(-7,25,3,biomesoplenty:log_2:5)
Block(-7,26,-7,biomesoplenty:log_2:5)
Block(-7,27,-11,biomesoplenty:leaves_4:3)
Block(-7,27,-10,biomesoplenty:leaves_4:3)
Block(-7,27,-9,biomesoplenty:leaves_4:3)
Block(-7,27,-8,biomesoplenty:leaves_4:3)
Block(-7,27,-7,biomesoplenty:leaves_4:3)
Block(-7,27,-6,biomesoplenty:leaves_4:3)
Block(-7,27,-5,biomesoplenty:leaves_4:3)
Block(-7,27,-4,biomesoplenty:leaves_4:3)
Block(-7,27,-3,biomesoplenty:leaves_4:3)
Block(-7,27,-2,biomesoplenty:log_2:5)
Block(-7,27,-1,biomesoplenty:leaves_4:3)
Block(-7,27,0,biomesoplenty:leaves_4:3)
Block(-7,27,1,biomesoplenty:leaves_4:3)
Block(-7,27,2,biomesoplenty:leaves_4:3)
Block(-7,27,3,biomesoplenty:leaves_4:3)
Block(-7,27,4,biomesoplenty:leaves_4:3)
Block(-7,27,5,biomesoplenty:leaves_4:3)
Block(-7,27,6,biomesoplenty:leaves_4:3)
Block(-7,27,7,biomesoplenty:leaves_4:3)
Block(-7,27,8,biomesoplenty:leaves_4:3)
Block(-7,27,9,biomesoplenty:leaves_4:3)
Block(-7,27,10,biomesoplenty:leaves_4:3)
Block(-7,27,11,biomesoplenty:leaves_4:3)
Block(-7,28,-10,biomesoplenty:leaves_4:3)
Block(-7,28,-9,biomesoplenty:leaves_4:3)
Block(-7,28,-8,biomesoplenty:leaves_4:3)
Block(-7,28,-7,biomesoplenty:leaves_4:3)
Block(-7,28,-6,biomesoplenty:leaves_4:3)
Block(-7,28,-5,biomesoplenty:leaves_4:3)
Block(-7,28,-4,biomesoplenty:leaves_4:3)
Block(-7,28,-3,biomesoplenty:leaves_4:3)
Block(-7,28,-2,biomesoplenty:leaves_4:3)
Block(-7,28,-1,biomesoplenty:log_2:5)
Block(-7,28,0,biomesoplenty:leaves_4:3)
Block(-7,28,1,biomesoplenty:leaves_4:3)
Block(-7,28,2,biomesoplenty:leaves_4:3)
Block(-7,28,3,biomesoplenty:leaves_4:3)
Block(-7,28,4,biomesoplenty:leaves_4:3)
Block(-7,28,5,biomesoplenty:leaves_4:3)
Block(-7,28,6,biomesoplenty:leaves_4:3)
Block(-7,28,7,biomesoplenty:leaves_4:3)
Block(-7,28,8,biomesoplenty:leaves_4:3)
Block(-7,28,9,biomesoplenty:leaves_4:3)
Block(-7,28,10,biomesoplenty:leaves_4:3)
Block(-7,28,11,biomesoplenty:leaves_4:3)
Block(-7,29,-9,biomesoplenty:leaves_4:3)
Block(-7,29,-8,biomesoplenty:leaves_4:3)
Block(-7,29,-7,biomesoplenty:leaves_4:3)
Block(-7,29,-6,biomesoplenty:leaves_4:3)
Block(-7,29,-5,biomesoplenty:leaves_4:3)
Block(-7,29,-4,biomesoplenty:leaves_4:3)
Block(-7,29,-3,biomesoplenty:leaves_4:3)
Block(-7,29,-2,biomesoplenty:leaves_4:3)
Block(-7,29,-1,biomesoplenty:leaves_4:3)
Block(-7,29,0,biomesoplenty:leaves_4:3)
Block(-7,29,1,biomesoplenty:leaves_4:3)
Block(-7,29,2,biomesoplenty:leaves_4:3)
Block(-7,29,3,biomesoplenty:leaves_4:3)
Block(-7,29,4,biomesoplenty:leaves_4:3)
Block(-7,29,5,biomesoplenty:leaves_4:3)
Block(-7,29,6,biomesoplenty:leaves_4:3)
Block(-7,29,7,biomesoplenty:leaves_4:3)
Block(-7,29,8,biomesoplenty:leaves_4:3)
Block(-7,29,9,biomesoplenty:leaves_4:3)
Block(-7,29,10,biomesoplenty:leaves_4:3)
Block(-7,30,-7,biomesoplenty:leaves_4:3)
Block(-7,30,-6,biomesoplenty:leaves_4:3)
Block(-7,30,-5,biomesoplenty:leaves_4:3)
Block(-7,30,-4,biomesoplenty:leaves_4:3)
Block(-7,30,-3,biomesoplenty:leaves_4:3)
Block(-7,30,-2,biomesoplenty:leaves_4:3)
Block(-7,30,-1,biomesoplenty:leaves_4:3)
Block(-7,30,0,biomesoplenty:leaves_4:3)
Block(-7,30,1,biomesoplenty:leaves_4:3)
Block(-7,30,3,biomesoplenty:leaves_4:3)
Block(-7,30,4,biomesoplenty:leaves_4:3)
Block(-7,30,5,biomesoplenty:leaves_4:3)
Block(-7,30,6,biomesoplenty:leaves_4:3)
Block(-7,31,-1,biomesoplenty:leaves_4:3)
Block(-6,23,6,biomesoplenty:log_2:5)
Block(-6,24,-7,biomesoplenty:log_2:5)
Block(-6,24,6,biomesoplenty:log_2:5)
Block(-6,25,2,biomesoplenty:log_2:5)
Block(-6,25,7,biomesoplenty:log_2:5)
Block(-6,26,1,biomesoplenty:log_2:5)
Block(-6,27,-9,biomesoplenty:leaves_4:3)
Block(-6,27,-8,biomesoplenty:leaves_4:3)
Block(-6,27,-7,biomesoplenty:leaves_4:3)
Block(-6,27,-6,biomesoplenty:leaves_4:3)
Block(-6,27,-5,biomesoplenty:log_2:5)
Block(-6,27,-4,biomesoplenty:leaves_4:3)
Block(-6,27,-3,biomesoplenty:leaves_4:3)
Block(-6,27,-2,biomesoplenty:leaves_4:3)
Block(-6,27,-1,biomesoplenty:leaves_4:3)
Block(-6,27,0,biomesoplenty:leaves_4:3)
Block(-6,27,1,biomesoplenty:leaves_4:3)
Block(-6,27,2,biomesoplenty:leaves_4:3)
Block(-6,27,3,biomesoplenty:leaves_4:3)
Block(-6,27,4,biomesoplenty:leaves_4:3)
Block(-6,27,5,biomesoplenty:leaves_4:3)
Block(-6,27,6,biomesoplenty:leaves_4:3)
Block(-6,27,7,biomesoplenty:leaves_4:3)
Block(-6,27,8,biomesoplenty:leaves_4:3)
Block(-6,27,9,biomesoplenty:leaves_4:3)
Block(-6,27,10,biomesoplenty:leaves_4:3)
Block(-6,27,11,biomesoplenty:leaves_4:3)
Block(-6,28,-9,biomesoplenty:leaves_4:3)
Block(-6,28,-8,biomesoplenty:leaves_4:3)
Block(-6,28,-7,biomesoplenty:leaves_4:3)
Block(-6,28,-6,biomesoplenty:leaves_4:3)
Block(-6,28,-5,biomesoplenty:leaves_4:3)
Block(-6,28,-4,biomesoplenty:leaves_4:3)
Block(-6,28,-3,biomesoplenty:leaves_4:3)
Block(-6,28,-2,biomesoplenty:leaves_4:3)
Block(-6,28,-1,biomesoplenty:leaves_4:3)
Block(-6,28,0,biomesoplenty:leaves_4:3)
Block(-6,28,1,biomesoplenty:leaves_4:3)
Block(-6,28,2,biomesoplenty:leaves_4:3)
Block(-6,28,3,biomesoplenty:log_2:5)
Block(-6,28,4,biomesoplenty:leaves_4:3)
Block(-6,28,5,biomesoplenty:leaves_4:3)
Block(-6,28,6,biomesoplenty:leaves_4:3)
Block(-6,28,7,biomesoplenty:leaves_4:3)
Block(-6,28,8,biomesoplenty:leaves_4:3)
Block(-6,28,9,biomesoplenty:leaves_4:3)
Block(-6,28,10,biomesoplenty:leaves_4:3)
Block(-6,29,-8,biomesoplenty:leaves_4:3)
Block(-6,29,-7,biomesoplenty:leaves_4:3)
Block(-6,29,-6,biomesoplenty:leaves_4:3)
Block(-6,29,-5,biomesoplenty:leaves_4:3)
Block(-6,29,-4,biomesoplenty:leaves_4:3)
Block(-6,29,-3,biomesoplenty:leaves_4:3)
Block(-6,29,-2,biomesoplenty:leaves_4:3)
Block(-6,29,-1,biomesoplenty:leaves_4:3)
Block(-6,29,0,biomesoplenty:leaves_4:3)
Block(-6,29,1,biomesoplenty:leaves_4:3)
Block(-6,29,2,biomesoplenty:leaves_4:3)
Block(-6,29,3,biomesoplenty:leaves_4:3)
Block(-6,29,4,biomesoplenty:leaves_4:3)
Block(-6,29,5,biomesoplenty:leaves_4:3)
Block(-6,29,6,biomesoplenty:leaves_4:3)
Block(-6,29,7,biomesoplenty:leaves_4:3)
Block(-6,29,8,biomesoplenty:leaves_4:3)
Block(-6,29,9,biomesoplenty:leaves_4:3)
Block(-6,30,-6,biomesoplenty:leaves_4:3)
Block(-6,30,-5,biomesoplenty:leaves_4:3)
Block(-6,30,-4,biomesoplenty:leaves_4:3)
Block(-6,30,-3,biomesoplenty:leaves_4:3)
Block(-6,30,-2,biomesoplenty:leaves_4:3)
Block(-6,30,-1,biomesoplenty:leaves_4:3)
Block(-6,30,0,biomesoplenty:leaves_4:3)
Block(-6,30,1,biomesoplenty:leaves_4:3)
Block(-6,30,2,biomesoplenty:leaves_4:3)
Block(-6,30,3,biomesoplenty:leaves_4:3)
Block(-6,30,4,biomesoplenty:leaves_4:3)
Block(-6,30,5,biomesoplenty:leaves_4:3)
Block(-6,30,6,biomesoplenty:leaves_4:3)
Block(-6,30,7,biomesoplenty:leaves_4:3)
Block(-6,31,-3,biomesoplenty:leaves_4:3)
Block(-6,31,-2,biomesoplenty:leaves_4:3)
Block(-6,31,-1,biomesoplenty:leaves_4:3)
Block(-6,31,0,biomesoplenty:leaves_4:3)
Block(-6,31,4,biomesoplenty:leaves_4:3)
Block(-5,22,-5,biomesoplenty:log_2:5)
Block(-5,22,5,biomesoplenty:log_2:5)
Block(-5,23,-6,biomesoplenty:log_2:5)
Block(-5,23,3,biomesoplenty:log_2:5)
Block(-5,24,2,biomesoplenty:log_2:5)
Block(-5,24,4,biomesoplenty:log_2:5)
Block(-5,25,5,biomesoplenty:log_2:5)
Block(-5,26,6,biomesoplenty:log_2:5)
Block(-5,26,8,biomesoplenty:log_2:5)
Block(-5,27,-10,biomesoplenty:leaves_4:3)
Block(-5,27,-9,biomesoplenty:leaves_4:3)
Block(-5,27,-8,biomesoplenty:leaves_4:3)
Block(-5,27,-7,biomesoplenty:leaves_4:3)
Block(-5,27,-6,biomesoplenty:leaves_4:3)
Block(-5,27,-5,biomesoplenty:leaves_4:3)
Block(-5,27,-4,biomesoplenty:leaves_4:3)
Block(-5,27,-3,biomesoplenty:leaves_4:3)
Block(-5,27,-2,biomesoplenty:log_2:5)
Block(-5,27,-1,biomesoplenty:leaves_4:3)
Block(-5,27,0,biomesoplenty:leaves_4:3)
Block(-5,27,1,biomesoplenty:leaves_4:3)
Block(-5,27,2,biomesoplenty:leaves_4:3)
Block(-5,27,3,biomesoplenty:log_2:5)
Block(-5,27,4,biomesoplenty:leaves_4:3)
Block(-5,27,5,biomesoplenty:leaves_4:3)
Block(-5,27,6,biomesoplenty:leaves_4:3)
Block(-5,27,7,biomesoplenty:leaves_4:3)
Block(-5,27,8,biomesoplenty:log_2:5)
Block(-5,27,9,biomesoplenty:leaves_4:3)
Block(-5,27,10,biomesoplenty:leaves_4:3)
Block(-5,27,11,biomesoplenty:leaves_4:3)
Block(-5,27,12,biomesoplenty:leaves_4:3)
Block(-5,28,-9,biomesoplenty:leaves_4:3)
Block(-5,28,-8,biomesoplenty:leaves_4:3)
Block(-5,28,-7,biomesoplenty:leaves_4:3)
Block(-5,28,-6,biomesoplenty:leaves_4:3)
Block(-5,28,-5,biomesoplenty:leaves_4:3)
Block(-5,28,-4,biomesoplenty:leaves_4:3)
Block(-5,28,-3,biomesoplenty:leaves_4:3)
Block(-5,28,-2,biomesoplenty:leaves_4:3)
Block(-5,28,-1,biomesoplenty:leaves_4:3)
Block(-5,28,0,biomesoplenty:leaves_4:3)
Block(-5,28,1,biomesoplenty:leaves_4:3)
Block(-5,28,2,biomesoplenty:leaves_4:3)
Block(-5,28,3,biomesoplenty:leaves_4:3)
Block(-5,28,4,biomesoplenty:leaves_4:3)
Block(-5,28,5,biomesoplenty:leaves_4:3)
Block(-5,28,6,biomesoplenty:log_2:5)
Block(-5,28,7,biomesoplenty:leaves_4:3)
Block(-5,28,8,biomesoplenty:log_2:5)
Block(-5,28,9,biomesoplenty:leaves_4:3)
Block(-5,28,10,biomesoplenty:leaves_4:3)
Block(-5,28,11,biomesoplenty:leaves_4:3)
Block(-5,29,-7,biomesoplenty:leaves_4:3)
Block(-5,29,-6,biomesoplenty:leaves_4:3)
Block(-5,29,-5,biomesoplenty:leaves_4:3)
Block(-5,29,-4,biomesoplenty:leaves_4:3)
Block(-5,29,-3,biomesoplenty:leaves_4:3)
Block(-5,29,-2,biomesoplenty:leaves_4:3)
Block(-5,29,-1,biomesoplenty:leaves_4:3)
Block(-5,29,0,biomesoplenty:leaves_4:3)
Block(-5,29,1,biomesoplenty:leaves_4:3)
Block(-5,29,2,biomesoplenty:leaves_4:3)
Block(-5,29,3,biomesoplenty:leaves_4:3)
Block(-5,29,4,biomesoplenty:leaves_4:3)
Block(-5,29,5,biomesoplenty:leaves_4:3)
Block(-5,29,6,biomesoplenty:leaves_4:3)
Block(-5,29,7,biomesoplenty:leaves_4:3)
Block(-5,29,8,biomesoplenty:leaves_4:3)
Block(-5,29,9,biomesoplenty:leaves_4:3)
Block(-5,29,10,biomesoplenty:leaves_4:3)
Block(-5,30,-5,biomesoplenty:leaves_4:3)
Block(-5,30,-4,biomesoplenty:leaves_4:3)
Block(-5,30,-3,biomesoplenty:leaves_4:3)
Block(-5,30,-2,biomesoplenty:leaves_4:3)
Block(-5,30,-1,biomesoplenty:leaves_4:3)
Block(-5,30,0,biomesoplenty:leaves_4:3)
Block(-5,30,1,biomesoplenty:leaves_4:3)
Block(-5,30,2,biomesoplenty:leaves_4:3)
Block(-5,30,3,biomesoplenty:leaves_4:3)
Block(-5,30,4,biomesoplenty:leaves_4:3)
Block(-5,30,5,biomesoplenty:leaves_4:3)
Block(-5,30,6,biomesoplenty:leaves_4:3)
Block(-5,30,7,biomesoplenty:leaves_4:3)
Block(-5,31,-4,biomesoplenty:leaves_4:3)
Block(-5,31,-3,biomesoplenty:leaves_4:3)
Block(-5,31,-2,biomesoplenty:leaves_4:3)
Block(-5,31,-1,biomesoplenty:leaves_4:3)
Block(-5,31,0,biomesoplenty:leaves_4:3)
Block(-5,31,1,biomesoplenty:leaves_4:3)
Block(-5,31,4,biomesoplenty:leaves_4:3)
Block(-5,31,5,biomesoplenty:leaves_4:3)
Block(-4,21,-5,biomesoplenty:log_2:5)
Block(-4,21,4,biomesoplenty:log_2:5)
Block(-4,22,3,biomesoplenty:log_2:5)
Block(-4,27,-11,biomesoplenty:leaves_4:3)
Block(-4,27,-10,biomesoplenty:leaves_4:3)
Block(-4,27,-9,biomesoplenty:leaves_4:3)
Block(-4,27,-8,biomesoplenty:leaves_4:3)
Block(-4,27,-7,biomesoplenty:leaves_4:3)
Block(-4,27,-6,biomesoplenty:log_2:5)
Block(-4,27,-5,biomesoplenty:leaves_4:3)
Block(-4,27,-4,biomesoplenty:leaves_4:3)
Block(-4,27,-3,biomesoplenty:leaves_4:3)
Block(-4,27,-2,biomesoplenty:leaves_4:3)
Block(-4,27,-1,biomesoplenty:leaves_4:3)
Block(-4,27,0,biomesoplenty:leaves_4:3)
Block(-4,27,1,biomesoplenty:leaves_4:3)
Block(-4,27,2,biomesoplenty:leaves_4:3)
Block(-4,27,3,biomesoplenty:leaves_4:3)
Block(-4,27,4,biomesoplenty:leaves_4:3)
Block(-4,27,5,biomesoplenty:leaves_4:3)
Block(-4,27,6,biomesoplenty:leaves_4:3)
Block(-4,27,7,biomesoplenty:leaves_4:3)
Block(-4,27,8,biomesoplenty:leaves_4:3)
Block(-4,27,9,biomesoplenty:leaves_4:3)
Block(-4,27,10,biomesoplenty:leaves_4:3)
Block(-4,27,11,biomesoplenty:leaves_4:3)
Block(-4,27,12,biomesoplenty:leaves_4:3)
Block(-4,28,-10,biomesoplenty:leaves_4:3)
Block(-4,28,-9,biomesoplenty:leaves_4:3)
Block(-4,28,-8,biomesoplenty:leaves_4:3)
Block(-4,28,-7,biomesoplenty:leaves_4:3)
Block(-4,28,-6,biomesoplenty:log_2:5)
Block(-4,28,-5,biomesoplenty:leaves_4:3)
Block(-4,28,-4,biomesoplenty:leaves_4:3)
Block(-4,28,-3,biomesoplenty:leaves_4:3)
Block(-4,28,-2,biomesoplenty:log_2:5)
Block(-4,28,-1,biomesoplenty:leaves_4:3)
Block(-4,28,0,biomesoplenty:leaves_4:3)
Block(-4,28,1,biomesoplenty:leaves_4:3)
Block(-4,28,2,biomesoplenty:leaves_4:3)
Block(-4,28,3,biomesoplenty:log_2:5)
Block(-4,28,4,biomesoplenty:leaves_4:3)
Block(-4,28,5,biomesoplenty:leaves_4:3)
Block(-4,28,6,biomesoplenty:leaves_4:3)
Block(-4,28,7,biomesoplenty:leaves_4:3)
Block(-4,28,8,biomesoplenty:leaves_4:3)
Block(-4,28,9,biomesoplenty:leaves_4:3)
Block(-4,28,10,biomesoplenty:leaves_4:3)
Block(-4,28,11,biomesoplenty:leaves_4:3)
Block(-4,29,-8,biomesoplenty:leaves_4:3)
Block(-4,29,-7,biomesoplenty:leaves_4:3)
Block(-4,29,-6,biomesoplenty:leaves_4:3)
Block(-4,29,-5,biomesoplenty:leaves_4:3)
Block(-4,29,-4,biomesoplenty:leaves_4:3)
Block(-4,29,-3,biomesoplenty:leaves_4:3)
Block(-4,29,-2,biomesoplenty:log_2:5)
Block(-4,29,-1,biomesoplenty:leaves_4:3)
Block(-4,29,0,biomesoplenty:leaves_4:3)
Block(-4,29,1,biomesoplenty:leaves_4:3)
Block(-4,29,2,biomesoplenty:leaves_4:3)
Block(-4,29,3,biomesoplenty:leaves_4:3)
Block(-4,29,4,biomesoplenty:leaves_4:3)
Block(-4,29,5,biomesoplenty:leaves_4:3)
Block(-4,29,6,biomesoplenty:leaves_4:3)
Block(-4,29,7,biomesoplenty:leaves_4:3)
Block(-4,29,8,biomesoplenty:leaves_4:3)
Block(-4,29,9,biomesoplenty:leaves_4:3)
Block(-4,29,10,biomesoplenty:leaves_4:3)
Block(-4,30,-6,biomesoplenty:leaves_4:3)
Block(-4,30,-5,biomesoplenty:leaves_4:3)
Block(-4,30,-4,biomesoplenty:leaves_4:3)
Block(-4,30,-3,biomesoplenty:leaves_4:3)
Block(-4,30,-2,biomesoplenty:log_2:5)
Block(-4,30,-1,biomesoplenty:leaves_4:3)
Block(-4,30,0,biomesoplenty:leaves_4:3)
Block(-4,30,1,biomesoplenty:leaves_4:3)
Block(-4,30,2,biomesoplenty:leaves_4:3)
Block(-4,30,3,biomesoplenty:leaves_4:3)
Block(-4,30,4,biomesoplenty:leaves_4:3)
Block(-4,30,5,biomesoplenty:leaves_4:3)
Block(-4,30,6,biomesoplenty:leaves_4:3)
Block(-4,30,7,biomesoplenty:leaves_4:3)
Block(-4,30,8,biomesoplenty:leaves_4:3)
Block(-4,31,-5,biomesoplenty:leaves_4:3)
Block(-4,31,-4,biomesoplenty:leaves_4:3)
Block(-4,31,-3,biomesoplenty:leaves_4:3)
Block(-4,31,-2,biomesoplenty:leaves_4:3)
Block(-4,31,-1,biomesoplenty:leaves_4:3)
Block(-4,31,0,biomesoplenty:leaves_4:3)
Block(-4,31,1,biomesoplenty:leaves_4:3)
Block(-4,31,2,biomesoplenty:leaves_4:3)
Block(-4,31,4,biomesoplenty:leaves_4:3)
Block(-4,31,5,biomesoplenty:leaves_4:3)
Block(-4,31,6,biomesoplenty:leaves_4:3)
Block(-4,31,7,biomesoplenty:leaves_4:3)
Block(-4,32,0,biomesoplenty:leaves_4:3)
Block(-4,32,5,biomesoplenty:leaves_4:3)
Block(-3,19,-5,biomesoplenty:log_2:5)
Block(-3,20,-5,biomesoplenty:log_2:5)
Block(-3,21,3,biomesoplenty:log_2:5)
Block(-3,27,-11,biomesoplenty:leaves_4:3)
Block(-3,27,-10,biomesoplenty:leaves_4:3)
Block(-3,27,-9,biomesoplenty:leaves_4:3)
Block(-3,27,-8,biomesoplenty:log_2:5)
Block(-3,27,-7,biomesoplenty:leaves_4:3)
Block(-3,27,-6,biomesoplenty:leaves_4:3)
Block(-3,27,-5,biomesoplenty:leaves_4:3)
Block(-3,27,-4,biomesoplenty:leaves_4:3)
Block(-3,27,-3,biomesoplenty:leaves_4:3)
Block(-3,27,-2,biomesoplenty:leaves_4:3)
Block(-3,27,-1,biomesoplenty:leaves_4:3)
Block(-3,27,0,biomesoplenty:log_2:5)
Block(-3,27,1,biomesoplenty:leaves_4:3)
Block(-3,27,2,biomesoplenty:leaves_4:3)
Block(-3,27,3,biomesoplenty:leaves_4:3)
Block(-3,27,4,biomesoplenty:leaves_4:3)
Block(-3,27,5,biomesoplenty:leaves_4:3)
Block(-3,27,6,biomesoplenty:leaves_4:3)
Block(-3,27,7,biomesoplenty:leaves_4:3)
Block(-3,27,8,biomesoplenty:leaves_4:3)
Block(-3,27,9,biomesoplenty:leaves_4:3)
Block(-3,27,10,biomesoplenty:leaves_4:3)
Block(-3,28,-10,biomesoplenty:leaves_4:3)
Block(-3,28,-9,biomesoplenty:leaves_4:3)
Block(-3,28,-8,biomesoplenty:leaves_4:3)
Block(-3,28,-7,biomesoplenty:leaves_4:3)
Block(-3,28,-6,biomesoplenty:leaves_4:3)
Block(-3,28,-5,biomesoplenty:leaves_4:3)
Block(-3,28,-4,biomesoplenty:leaves_4:3)
Block(-3,28,-3,biomesoplenty:leaves_4:3)
Block(-3,28,-2,biomesoplenty:leaves_4:3)
Block(-3,28,-1,biomesoplenty:leaves_4:3)
Block(-3,28,0,biomesoplenty:leaves_4:3)
Block(-3,28,1,biomesoplenty:leaves_4:3)
Block(-3,28,2,biomesoplenty:leaves_4:3)
Block(-3,28,3,biomesoplenty:leaves_4:3)
Block(-3,28,4,biomesoplenty:leaves_4:3)
Block(-3,28,5,biomesoplenty:leaves_4:3)
Block(-3,28,6,biomesoplenty:leaves_4:3)
Block(-3,28,7,biomesoplenty:leaves_4:3)
Block(-3,28,8,biomesoplenty:leaves_4:3)
Block(-3,28,9,biomesoplenty:leaves_4:3)
Block(-3,28,10,biomesoplenty:leaves_4:3)
Block(-3,29,-9,biomesoplenty:leaves_4:3)
Block(-3,29,-8,biomesoplenty:leaves_4:3)
Block(-3,29,-7,biomesoplenty:leaves_4:3)
Block(-3,29,-6,biomesoplenty:leaves_4:3)
Block(-3,29,-5,biomesoplenty:leaves_4:3)
Block(-3,29,-4,biomesoplenty:leaves_4:3)
Block(-3,29,-3,biomesoplenty:leaves_4:3)
Block(-3,29,-2,biomesoplenty:leaves_4:3)
Block(-3,29,-1,biomesoplenty:leaves_4:3)
Block(-3,29,0,biomesoplenty:leaves_4:3)
Block(-3,29,1,biomesoplenty:leaves_4:3)
Block(-3,29,2,biomesoplenty:leaves_4:3)
Block(-3,29,3,biomesoplenty:leaves_4:3)
Block(-3,29,4,biomesoplenty:leaves_4:3)
Block(-3,29,5,biomesoplenty:leaves_4:3)
Block(-3,29,6,biomesoplenty:leaves_4:3)
Block(-3,29,7,biomesoplenty:leaves_4:3)
Block(-3,29,8,biomesoplenty:leaves_4:3)
Block(-3,29,9,biomesoplenty:leaves_4:3)
Block(-3,29,10,biomesoplenty:leaves_4:3)
Block(-3,30,-7,biomesoplenty:leaves_4:3)
Block(-3,30,-6,biomesoplenty:leaves_4:3)
Block(-3,30,-5,biomesoplenty:leaves_4:3)
Block(-3,30,-4,biomesoplenty:leaves_4:3)
Block(-3,30,-3,biomesoplenty:leaves_4:3)
Block(-3,30,-2,biomesoplenty:leaves_4:3)
Block(-3,30,-1,biomesoplenty:leaves_4:3)
Block(-3,30,0,biomesoplenty:leaves_4:3)
Block(-3,30,1,biomesoplenty:leaves_4:3)
Block(-3,30,2,biomesoplenty:leaves_4:3)
Block(-3,30,3,biomesoplenty:leaves_4:3)
Block(-3,30,4,biomesoplenty:leaves_4:3)
Block(-3,30,5,biomesoplenty:leaves_4:3)
Block(-3,30,6,biomesoplenty:leaves_4:3)
Block(-3,30,7,biomesoplenty:leaves_4:3)
Block(-3,30,8,biomesoplenty:leaves_4:3)
Block(-3,31,-5,biomesoplenty:leaves_4:3)
Block(-3,31,-4,biomesoplenty:leaves_4:3)
Block(-3,31,-3,biomesoplenty:leaves_4:3)
Block(-3,31,-2,biomesoplenty:leaves_4:3)
Block(-3,31,-1,biomesoplenty:leaves_4:3)
Block(-3,31,0,biomesoplenty:leaves_4:3)
Block(-3,31,1,biomesoplenty:leaves_4:3)
Block(-3,31,2,biomesoplenty:leaves_4:3)
Block(-3,31,3,biomesoplenty:leaves_4:3)
Block(-3,31,4,biomesoplenty:leaves_4:3)
Block(-3,31,5,biomesoplenty:leaves_4:3)
Block(-3,31,6,biomesoplenty:leaves_4:3)
Block(-3,31,7,biomesoplenty:leaves_4:3)
Block(-3,32,0,biomesoplenty:leaves_4:3)
Block(-3,32,1,biomesoplenty:leaves_4:3)
Block(-3,32,4,biomesoplenty:leaves_4:3)
Block(-3,32,5,biomesoplenty:leaves_4:3)
Block(-3,32,6,biomesoplenty:leaves_4:3)
Block(-2,-7,0,biomesoplenty:log_2:5)
Block(-2,-6,0,biomesoplenty:log_2:5)
Block(-2,-5,0,biomesoplenty:log_2:5)
Block(-2,-4,0,biomesoplenty:log_2:5)
Block(-2,-3,0,biomesoplenty:log_2:5)
Block(-2,-2,0,biomesoplenty:log_2:5)
Block(-2,-1,0,biomesoplenty:log_2:5)
Block(-2,0,0,biomesoplenty:log_2:5)
Block(-2,18,-4,biomesoplenty:log_2:5)
Block(-2,20,2,biomesoplenty:log_2:5)
Block(-2,26,-3,biomesoplenty:log_2:5)
Block(-2,27,-10,biomesoplenty:leaves_4:3)
Block(-2,27,-9,biomesoplenty:leaves_4:3)
Block(-2,27,-8,biomesoplenty:leaves_4:3)
Block(-2,27,-7,biomesoplenty:leaves_4:3)
Block(-2,27,-6,biomesoplenty:leaves_4:3)
Block(-2,27,-5,biomesoplenty:leaves_4:3)
Block(-2,27,-4,biomesoplenty:leaves_4:3)
Block(-2,27,-3,biomesoplenty:log_2:5)
Block(-2,27,-2,biomesoplenty:leaves_4:3)
Block(-2,27,-1,biomesoplenty:leaves_4:3)
Block(-2,27,0,biomesoplenty:leaves_4:3)
Block(-2,27,1,biomesoplenty:leaves_4:3)
Block(-2,27,2,biomesoplenty:leaves_4:3)
Block(-2,27,3,biomesoplenty:leaves_4:3)
Block(-2,27,4,biomesoplenty:log_2:5)
Block(-2,27,5,biomesoplenty:leaves_4:3)
Block(-2,27,6,biomesoplenty:leaves_4:3)
Block(-2,27,7,biomesoplenty:leaves_4:3)
Block(-2,27,8,biomesoplenty:leaves_4:3)
Block(-2,27,9,biomesoplenty:leaves_4:3)
Block(-2,27,10,biomesoplenty:leaves_4:3)
Block(-2,27,11,biomesoplenty:leaves_4:3)
Block(-2,28,-9,biomesoplenty:leaves_4:3)
Block(-2,28,-8,biomesoplenty:leaves_4:3)
Block(-2,28,-7,biomesoplenty:leaves_4:3)
Block(-2,28,-6,biomesoplenty:leaves_4:3)
Block(-2,28,-5,biomesoplenty:leaves_4:3)
Block(-2,28,-4,biomesoplenty:leaves_4:3)
Block(-2,28,-3,biomesoplenty:log_2:5)
Block(-2,28,-2,biomesoplenty:leaves_4:3)
Block(-2,28,-1,biomesoplenty:leaves_4:3)
Block(-2,28,0,biomesoplenty:leaves_4:3)
Block(-2,28,1,biomesoplenty:leaves_4:3)
Block(-2,28,2,biomesoplenty:leaves_4:3)
Block(-2,28,3,biomesoplenty:leaves_4:3)
Block(-2,28,4,biomesoplenty:leaves_4:3)
Block(-2,28,5,biomesoplenty:leaves_4:3)
Block(-2,28,6,biomesoplenty:leaves_4:3)
Block(-2,28,7,biomesoplenty:leaves_4:3)
Block(-2,28,8,biomesoplenty:leaves_4:3)
Block(-2,28,9,biomesoplenty:leaves_4:3)
Block(-2,28,10,biomesoplenty:leaves_4:3)
Block(-2,29,-8,biomesoplenty:leaves_4:3)
Block(-2,29,-7,biomesoplenty:leaves_4:3)
Block(-2,29,-6,biomesoplenty:leaves_4:3)
Block(-2,29,-5,biomesoplenty:leaves_4:3)
Block(-2,29,-4,biomesoplenty:leaves_4:3)
Block(-2,29,-3,biomesoplenty:leaves_4:3)
Block(-2,29,-2,biomesoplenty:leaves_4:3)
Block(-2,29,-1,biomesoplenty:leaves_4:3)
Block(-2,29,0,biomesoplenty:leaves_4:3)
Block(-2,29,1,biomesoplenty:leaves_4:3)
Block(-2,29,2,biomesoplenty:leaves_4:3)
Block(-2,29,3,biomesoplenty:leaves_4:3)
Block(-2,29,4,biomesoplenty:leaves_4:3)
Block(-2,29,5,biomesoplenty:leaves_4:3)
Block(-2,29,6,biomesoplenty:leaves_4:3)
Block(-2,29,7,biomesoplenty:leaves_4:3)
Block(-2,29,8,biomesoplenty:leaves_4:3)
Block(-2,29,9,biomesoplenty:leaves_4:3)
Block(-2,30,-5,biomesoplenty:leaves_4:3)
Block(-2,30,-4,biomesoplenty:leaves_4:3)
Block(-2,30,-3,biomesoplenty:leaves_4:3)
Block(-2,30,-2,biomesoplenty:leaves_4:3)
Block(-2,30,-1,biomesoplenty:leaves_4:3)
Block(-2,30,0,biomesoplenty:leaves_4:3)
Block(-2,30,1,biomesoplenty:leaves_4:3)
Block(-2,30,2,biomesoplenty:leaves_4:3)
Block(-2,30,3,biomesoplenty:leaves_4:3)
Block(-2,30,4,biomesoplenty:leaves_4:3)
Block(-2,30,5,biomesoplenty:leaves_4:3)
Block(-2,30,6,biomesoplenty:leaves_4:3)
Block(-2,30,7,biomesoplenty:leaves_4:3)
Block(-2,31,-4,biomesoplenty:leaves_4:3)
Block(-2,31,-3,biomesoplenty:leaves_4:3)
Block(-2,31,-2,biomesoplenty:leaves_4:3)
Block(-2,31,-1,biomesoplenty:leaves_4:3)
Block(-2,31,0,biomesoplenty:leaves_4:3)
Block(-2,31,1,biomesoplenty:leaves_4:3)
Block(-2,31,2,biomesoplenty:leaves_4:3)
Block(-2,31,3,biomesoplenty:leaves_4:3)
Block(-2,31,4,biomesoplenty:leaves_4:3)
Block(-2,31,5,biomesoplenty:leaves_4:3)
Block(-2,31,6,biomesoplenty:leaves_4:3)
Block(-2,32,-2,biomesoplenty:leaves_4:3)
Block(-2,32,-1,biomesoplenty:leaves_4:3)
Block(-2,32,0,biomesoplenty:leaves_4:3)
Block(-2,32,1,biomesoplenty:leaves_4:3)
Block(-2,32,2,biomesoplenty:leaves_4:3)
Block(-2,32,3,biomesoplenty:leaves_4:3)
Block(-2,32,4,biomesoplenty:leaves_4:3)
Block(-2,32,5,biomesoplenty:leaves_4:3)
Block(-1,-7,-1,biomesoplenty:log_2:5)
Block(-1,-7,0,biomesoplenty:log_2:5)
Block(-1,-7,1,biomesoplenty:log_2:5)
Block(-1,-6,-1,biomesoplenty:log_2:5)
Block(-1,-6,0,biomesoplenty:log_2:5)
Block(-1,-6,1,biomesoplenty:log_2:5)
Block(-1,-5,-1,biomesoplenty:log_2:5)
Block(-1,-5,0,biomesoplenty:log_2:5)
Block(-1,-5,1,biomesoplenty:log_2:5)
Block(-1,-4,-1,biomesoplenty:log_2:5)
Block(-1,-4,0,biomesoplenty:log_2:5)
Block(-1,-4,1,biomesoplenty:log_2:5)
Block(-1,-3,-1,biomesoplenty:log_2:5)
Block(-1,-3,0,biomesoplenty:log_2:5)
Block(-1,-3,1,biomesoplenty:log_2:5)
Block(-1,-2,-1,biomesoplenty:log_2:5)
Block(-1,-2,0,biomesoplenty:log_2:5)
Block(-1,-2,1,biomesoplenty:log_2:5)
Block(-1,-1,-1,biomesoplenty:log_2:5)
Block(-1,-1,0,biomesoplenty:log_2:5)
Block(-1,-1,1,biomesoplenty:log_2:5)
Block(-1,0,-1,biomesoplenty:log_2:5)
Block(-1,0,0,biomesoplenty:log_2:5)
Block(-1,0,1,biomesoplenty:log_2:5)
Block(-1,1,-1,biomesoplenty:log_2:5)
Block(-1,1,0,biomesoplenty:log_2:5)
Block(-1,1,1,biomesoplenty:log_2:5)
Block(-1,2,-1,biomesoplenty:log_2:5)
Block(-1,2,0,biomesoplenty:log_2:5)
Block(-1,2,1,biomesoplenty:log_2:5)
Block(-1,3,-1,biomesoplenty:log_2:5)
Block(-1,3,0,biomesoplenty:log_2:5)
Block(-1,3,1,biomesoplenty:log_2:5)
Block(-1,4,0,biomesoplenty:log_2:5)
Block(-1,5,0,biomesoplenty:log_2:5)
Block(-1,6,0,biomesoplenty:log_2:5)
Block(-1,7,0,biomesoplenty:log_2:5)
Block(-1,8,0,biomesoplenty:log_2:5)
Block(-1,9,0,biomesoplenty:log_2:5)
Block(-1,16,-2,biomesoplenty:log_2:5)
Block(-1,17,-3,biomesoplenty:log_2:5)
Block(-1,19,1,biomesoplenty:log_2:5)
Block(-1,20,3,biomesoplenty:log_2:5)
Block(-1,21,-1,biomesoplenty:log_2:5)
Block(-1,25,-7,biomesoplenty:log_2:5)
Block(-1,25,-2,biomesoplenty:log_2:5)
Block(-1,26,-7,biomesoplenty:log_2:5)
Block(-1,27,-9,biomesoplenty:leaves_4:3)
Block(-1,27,-8,biomesoplenty:leaves_4:3)
Block(-1,27,-7,biomesoplenty:log_2:5)
Block(-1,27,-6,biomesoplenty:leaves_4:3)
Block(-1,27,-5,biomesoplenty:leaves_4:3)
Block(-1,27,-4,biomesoplenty:leaves_4:3)
Block(-1,27,-3,biomesoplenty:leaves_4:3)
Block(-1,27,-2,biomesoplenty:leaves_4:3)
Block(-1,27,-1,biomesoplenty:leaves_4:3)
Block(-1,27,0,biomesoplenty:leaves_4:3)
Block(-1,27,1,biomesoplenty:leaves_4:3)
Block(-1,27,2,biomesoplenty:leaves_4:3)
Block(-1,27,3,biomesoplenty:leaves_4:3)
Block(-1,27,4,biomesoplenty:leaves_4:3)
Block(-1,27,5,biomesoplenty:leaves_4:3)
Block(-1,27,6,biomesoplenty:leaves_4:3)
Block(-1,27,7,biomesoplenty:leaves_4:3)
Block(-1,27,8,biomesoplenty:leaves_4:3)
Block(-1,27,9,biomesoplenty:log_2:5)
Block(-1,27,10,biomesoplenty:leaves_4:3)
Block(-1,27,11,biomesoplenty:leaves_4:3)
Block(-1,27,12,biomesoplenty:leaves_4:3)
Block(-1,28,-9,biomesoplenty:leaves_4:3)
Block(-1,28,-8,biomesoplenty:leaves_4:3)
Block(-1,28,-7,biomesoplenty:log_2:5)
Block(-1,28,-6,biomesoplenty:leaves_4:3)
Block(-1,28,-5,biomesoplenty:leaves_4:3)
Block(-1,28,-4,biomesoplenty:leaves_4:3)
Block(-1,28,-3,biomesoplenty:leaves_4:3)
Block(-1,28,-2,biomesoplenty:leaves_4:3)
Block(-1,28,-1,biomesoplenty:leaves_4:3)
Block(-1,28,0,biomesoplenty:leaves_4:3)
Block(-1,28,1,biomesoplenty:leaves_4:3)
Block(-1,28,2,biomesoplenty:leaves_4:3)
Block(-1,28,3,biomesoplenty:leaves_4:3)
Block(-1,28,4,biomesoplenty:leaves_4:3)
Block(-1,28,5,biomesoplenty:leaves_4:3)
Block(-1,28,6,biomesoplenty:leaves_4:3)
Block(-1,28,7,biomesoplenty:leaves_4:3)
Block(-1,28,8,biomesoplenty:leaves_4:3)
Block(-1,28,9,biomesoplenty:leaves_4:3)
Block(-1,28,10,biomesoplenty:leaves_4:3)
Block(-1,28,11,biomesoplenty:leaves_4:3)
Block(-1,29,-8,biomesoplenty:leaves_4:3)
Block(-1,29,-7,biomesoplenty:leaves_4:3)
Block(-1,29,-6,biomesoplenty:leaves_4:3)
Block(-1,29,-5,biomesoplenty:leaves_4:3)
Block(-1,29,-4,biomesoplenty:leaves_4:3)
Block(-1,29,-3,biomesoplenty:leaves_4:3)
Block(-1,29,-2,biomesoplenty:leaves_4:3)
Block(-1,29,-1,biomesoplenty:leaves_4:3)
Block(-1,29,0,biomesoplenty:leaves_4:3)
Block(-1,29,1,biomesoplenty:leaves_4:3)
Block(-1,29,2,biomesoplenty:leaves_4:3)
Block(-1,29,3,biomesoplenty:leaves_4:3)
Block(-1,29,4,biomesoplenty:leaves_4:3)
Block(-1,29,5,biomesoplenty:leaves_4:3)
Block(-1,29,6,biomesoplenty:leaves_4:3)
Block(-1,29,7,biomesoplenty:leaves_4:3)
Block(-1,29,8,biomesoplenty:leaves_4:3)
Block(-1,29,9,biomesoplenty:leaves_4:3)
Block(-1,29,10,biomesoplenty:leaves_4:3)
Block(-1,30,-6,biomesoplenty:leaves_4:3)
Block(-1,30,-5,biomesoplenty:leaves_4:3)
Block(-1,30,-4,biomesoplenty:leaves_4:3)
Block(-1,30,-3,biomesoplenty:leaves_4:3)
Block(-1,30,-2,biomesoplenty:leaves_4:3)
Block(-1,30,-1,biomesoplenty:leaves_4:3)
Block(-1,30,0,biomesoplenty:leaves_4:3)
Block(-1,30,1,biomesoplenty:leaves_4:3)
Block(-1,30,2,biomesoplenty:leaves_4:3)
Block(-1,30,3,biomesoplenty:leaves_4:3)
Block(-1,30,4,biomesoplenty:leaves_4:3)
Block(-1,30,5,biomesoplenty:leaves_4:3)
Block(-1,30,6,biomesoplenty:leaves_4:3)
Block(-1,30,7,biomesoplenty:leaves_4:3)
Block(-1,30,8,biomesoplenty:leaves_4:3)
Block(-1,31,-3,biomesoplenty:leaves_4:3)
Block(-1,31,-2,biomesoplenty:leaves_4:3)
Block(-1,31,-1,biomesoplenty:leaves_4:3)
Block(-1,31,0,biomesoplenty:leaves_4:3)
Block(-1,31,1,biomesoplenty:leaves_4:3)
Block(-1,31,2,biomesoplenty:leaves_4:3)
Block(-1,31,3,biomesoplenty:leaves_4:3)
Block(-1,31,4,biomesoplenty:leaves_4:3)
Block(-1,31,5,biomesoplenty:leaves_4:3)
Block(-1,31,6,biomesoplenty:leaves_4:3)
Block(-1,32,-1,biomesoplenty:leaves_4:3)
Block(-1,32,0,biomesoplenty:leaves_4:3)
Block(-1,32,1,biomesoplenty:leaves_4:3)
Block(-1,32,2,biomesoplenty:leaves_4:3)
Block(-1,32,3,biomesoplenty:leaves_4:3)
Block(0,-7,-2,biomesoplenty:log_2:5)
Block(0,-7,-1,biomesoplenty:log_2:5)
Block(0,-7,0,biomesoplenty:log_2:5)
Block(0,-7,1,biomesoplenty:log_2:5)
Block(0,-7,2,biomesoplenty:log_2:5)
Block(0,-6,-2,biomesoplenty:log_2:5)
Block(0,-6,-1,biomesoplenty:log_2:5)
Block(0,-6,0,biomesoplenty:log_2:5)
Block(0,-6,1,biomesoplenty:log_2:5)
Block(0,-6,2,biomesoplenty:log_2:5)
Block(0,-5,-2,biomesoplenty:log_2:5)
Block(0,-5,-1,biomesoplenty:log_2:5)
Block(0,-5,0,biomesoplenty:log_2:5)
Block(0,-5,1,biomesoplenty:log_2:5)
Block(0,-5,2,biomesoplenty:log_2:5)
Block(0,-4,-2,biomesoplenty:log_2:5)
Block(0,-4,-1,biomesoplenty:log_2:5)
Block(0,-4,0,biomesoplenty:log_2:5)
Block(0,-4,1,biomesoplenty:log_2:5)
Block(0,-4,2,biomesoplenty:log_2:5)
Block(0,-3,-2,biomesoplenty:log_2:5)
Block(0,-3,-1,biomesoplenty:log_2:5)
Block(0,-3,0,biomesoplenty:log_2:5)
Block(0,-3,1,biomesoplenty:log_2:5)
Block(0,-3,2,biomesoplenty:log_2:5)
Block(0,-2,-2,biomesoplenty:log_2:5)
Block(0,-2,-1,biomesoplenty:log_2:5)
Block(0,-2,0,biomesoplenty:log_2:5)
Block(0,-2,1,biomesoplenty:log_2:5)
Block(0,-2,2,biomesoplenty:log_2:5)
Block(0,-1,-2,biomesoplenty:log_2:5)
Block(0,-1,-1,biomesoplenty:log_2:5)
Block(0,-1,0,biomesoplenty:log_2:5)
Block(0,-1,1,biomesoplenty:log_2:5)
Block(0,-1,2,biomesoplenty:log_2:5)
Block(0,0,-2,biomesoplenty:log_2:5)
Block(0,0,-1,biomesoplenty:log_2:5)
Block(0,0,0,biomesoplenty:log_2:5)
Block(0,0,1,biomesoplenty:log_2:5)
Block(0,0,2,biomesoplenty:log_2:5)
Block(0,1,-1,biomesoplenty:log_2:5)
Block(0,1,0,biomesoplenty:log_2:5)
Block(0,1,1,biomesoplenty:log_2:5)
Block(0,2,-1,biomesoplenty:log_2:5)
Block(0,2,0,biomesoplenty:log_2:5)
Block(0,2,1,biomesoplenty:log_2:5)
Block(0,3,-1,biomesoplenty:log_2:5)
Block(0,3,0,biomesoplenty:log_2:5)
Block(0,3,1,biomesoplenty:log_2:5)
Block(0,4,-1,biomesoplenty:log_2:5)
Block(0,4,0,biomesoplenty:log_2:5)
Block(0,4,1,biomesoplenty:log_2:5)
Block(0,5,-1,biomesoplenty:log_2:5)
Block(0,5,0,biomesoplenty:log_2:5)
Block(0,5,1,biomesoplenty:log_2:5)
Block(0,6,-1,biomesoplenty:log_2:5)
Block(0,6,0,biomesoplenty:log_2:5)
Block(0,6,1,biomesoplenty:log_2:5)
Block(0,7,-1,biomesoplenty:log_2:5)
Block(0,7,0,biomesoplenty:log_2:5)
Block(0,7,1,biomesoplenty:log_2:5)
Block(0,8,-1,biomesoplenty:log_2:5)
Block(0,8,0,biomesoplenty:log_2:5)
Block(0,8,1,biomesoplenty:log_2:5)
Block(0,9,0,biomesoplenty:log_2:5)
Block(0,9,1,biomesoplenty:log_2:5)
Block(0,10,0,biomesoplenty:log_2:5)
Block(0,10,1,biomesoplenty:log_2:5)
Block(0,11,0,biomesoplenty:log_2:5)
Block(0,12,0,biomesoplenty:log_2:5)
Block(0,13,0,biomesoplenty:log_2:5)
Block(0,14,-1,biomesoplenty:log_2:5)
Block(0,14,0,biomesoplenty:log_2:5)
Block(0,15,-1,biomesoplenty:log_2:5)
Block(0,15,0,biomesoplenty:log_2:5)
Block(0,16,0,biomesoplenty:log_2:5)
Block(0,17,0,biomesoplenty:log_2:5)
Block(0,18,0,biomesoplenty:log_2:5)
Block(0,19,0,biomesoplenty:log_2:5)
Block(0,20,0,biomesoplenty:log_2:5)
Block(0,21,0,biomesoplenty:log_2:5)
Block(0,21,3,biomesoplenty:log_2:5)
Block(0,22,-2,biomesoplenty:log_2:5)
Block(0,22,0,biomesoplenty:log_2:5)
Block(0,22,4,biomesoplenty:log_2:5)
Block(0,23,-6,biomesoplenty:log_2:5)
Block(0,23,0,biomesoplenty:log_2:5)
Block(0,23,5,biomesoplenty:log_2:5)
Block(0,24,-7,biomesoplenty:log_2:5)
Block(0,24,-1,biomesoplenty:log_2:5)
Block(0,24,0,biomesoplenty:log_2:5)
Block(0,25,0,biomesoplenty:log_2:5)
Block(0,25,1,biomesoplenty:log_2:5)
Block(0,26,0,biomesoplenty:log_2:5)
Block(0,26,2,biomesoplenty:log_2:5)
Block(0,27,-10,biomesoplenty:leaves_4:3)
Block(0,27,-9,biomesoplenty:leaves_4:3)
Block(0,27,-8,biomesoplenty:leaves_4:3)
Block(0,27,-7,biomesoplenty:leaves_4:3)
Block(0,27,-6,biomesoplenty:leaves_4:3)
Block(0,27,-5,biomesoplenty:log_2:5)
Block(0,27,-4,biomesoplenty:leaves_4:3)
Block(0,27,-3,biomesoplenty:leaves_4:3)
Block(0,27,-2,biomesoplenty:leaves_4:3)
Block(0,27,-1,biomesoplenty:leaves_4:3)
Block(0,27,0,biomesoplenty:leaves_4:3)
Block(0,27,1,biomesoplenty:log_2:5)
Block(0,27,2,biomesoplenty:leaves_4:3)
Block(0,27,3,biomesoplenty:leaves_4:3)
Block(0,27,4,biomesoplenty:leaves_4:3)
Block(0,27,5,biomesoplenty:leaves_4:3)
Block(0,27,6,biomesoplenty:leaves_4:3)
Block(0,27,7,biomesoplenty:leaves_4:3)
Block(0,27,8,biomesoplenty:leaves_4:3)
Block(0,27,9,biomesoplenty:leaves_4:3)
Block(0,27,10,biomesoplenty:leaves_4:3)
Block(0,27,11,biomesoplenty:leaves_4:3)
Block(0,28,-8,biomesoplenty:leaves_4:3)
Block(0,28,-7,biomesoplenty:leaves_4:3)
Block(0,28,-6,biomesoplenty:leaves_4:3)
Block(0,28,-5,biomesoplenty:leaves_4:3)
Block(0,28,-4,biomesoplenty:leaves_4:3)
Block(0,28,-3,biomesoplenty:leaves_4:3)
Block(0,28,-2,biomesoplenty:leaves_4:3)
Block(0,28,-1,biomesoplenty:leaves_4:3)
Block(0,28,0,biomesoplenty:leaves_4:3)
Block(0,28,1,biomesoplenty:log_2:5)
Block(0,28,2,biomesoplenty:leaves_4:3)
Block(0,28,3,biomesoplenty:leaves_4:3)
Block(0,28,4,biomesoplenty:leaves_4:3)
Block(0,28,5,biomesoplenty:leaves_4:3)
Block(0,28,6,biomesoplenty:leaves_4:3)
Block(0,28,7,biomesoplenty:leaves_4:3)
Block(0,28,8,biomesoplenty:leaves_4:3)
Block(0,28,9,biomesoplenty:leaves_4:3)
Block(0,28,10,biomesoplenty:leaves_4:3)
Block(0,28,11,biomesoplenty:leaves_4:3)
Block(0,29,-7,biomesoplenty:leaves_4:3)
Block(0,29,-6,biomesoplenty:leaves_4:3)
Block(0,29,-5,biomesoplenty:leaves_4:3)
Block(0,29,-4,biomesoplenty:leaves_4:3)
Block(0,29,-3,biomesoplenty:leaves_4:3)
Block(0,29,-2,biomesoplenty:leaves_4:3)
Block(0,29,-1,biomesoplenty:leaves_4:3)
Block(0,29,0,biomesoplenty:leaves_4:3)
Block(0,29,1,biomesoplenty:leaves_4:3)
Block(0,29,2,biomesoplenty:leaves_4:3)
Block(0,29,3,biomesoplenty:leaves_4:3)
Block(0,29,4,biomesoplenty:leaves_4:3)
Block(0,29,5,biomesoplenty:leaves_4:3)
Block(0,29,6,biomesoplenty:leaves_4:3)
Block(0,29,7,biomesoplenty:leaves_4:3)
Block(0,29,8,biomesoplenty:leaves_4:3)
Block(0,29,9,biomesoplenty:leaves_4:3)
Block(0,29,10,biomesoplenty:leaves_4:3)
Block(0,29,11,biomesoplenty:leaves_4:3)
Block(0,30,-4,biomesoplenty:leaves_4:3)
Block(0,30,-3,biomesoplenty:leaves_4:3)
Block(0,30,-2,biomesoplenty:leaves_4:3)
Block(0,30,-1,biomesoplenty:leaves_4:3)
Block(0,30,0,biomesoplenty:leaves_4:3)
Block(0,30,1,biomesoplenty:leaves_4:3)
Block(0,30,2,biomesoplenty:leaves_4:3)
Block(0,30,3,biomesoplenty:leaves_4:3)
Block(0,30,4,biomesoplenty:leaves_4:3)
Block(0,30,5,biomesoplenty:leaves_4:3)
Block(0,30,6,biomesoplenty:leaves_4:3)
Block(0,31,-3,biomesoplenty:leaves_4:3)
Block(0,31,-2,biomesoplenty:leaves_4:3)
Block(0,31,-1,biomesoplenty:leaves_4:3)
Block(0,31,0,biomesoplenty:leaves_4:3)
Block(0,31,1,biomesoplenty:leaves_4:3)
Block(0,31,2,biomesoplenty:leaves_4:3)
Block(0,31,3,biomesoplenty:leaves_4:3)
Block(0,31,4,biomesoplenty:leaves_4:3)
Block(0,31,5,biomesoplenty:leaves_4:3)
Block(0,32,-3,biomesoplenty:leaves_4:3)
Block(0,32,-2,biomesoplenty:leaves_4:3)
Block(0,32,-1,biomesoplenty:leaves_4:3)
Block(0,32,0,biomesoplenty:leaves_4:3)
Block(0,32,1,biomesoplenty:leaves_4:3)
Block(0,32,2,biomesoplenty:leaves_4:3)
Block(0,32,3,biomesoplenty:leaves_4:3)
Block(0,32,4,biomesoplenty:leaves_4:3)
Block(1,-7,-1,biomesoplenty:log_2:5)
Block(1,-7,0,biomesoplenty:log_2:5)
Block(1,-7,1,biomesoplenty:log_2:5)
Block(1,-6,-1,biomesoplenty:log_2:5)
Block(1,-6,0,biomesoplenty:log_2:5)
Block(1,-6,1,biomesoplenty:log_2:5)
Block(1,-5,-1,biomesoplenty:log_2:5)
Block(1,-5,0,biomesoplenty:log_2:5)
Block(1,-5,1,biomesoplenty:log_2:5)
Block(1,-4,-1,biomesoplenty:log_2:5)
Block(1,-4,0,biomesoplenty:log_2:5)
Block(1,-4,1,biomesoplenty:log_2:5)
Block(1,-3,-1,biomesoplenty:log_2:5)
Block(1,-3,0,biomesoplenty:log_2:5)
Block(1,-3,1,biomesoplenty:log_2:5)
Block(1,-2,-1,biomesoplenty:log_2:5)
Block(1,-2,0,biomesoplenty:log_2:5)
Block(1,-2,1,biomesoplenty:log_2:5)
Block(1,-1,-1,biomesoplenty:log_2:5)
Block(1,-1,0,biomesoplenty:log_2:5)
Block(1,-1,1,biomesoplenty:log_2:5)
Block(1,0,-1,biomesoplenty:log_2:5)
Block(1,0,0,biomesoplenty:log_2:5)
Block(1,0,1,biomesoplenty:log_2:5)
Block(1,1,-1,biomesoplenty:log_2:5)
Block(1,1,0,biomesoplenty:log_2:5)
Block(1,1,1,biomesoplenty:log_2:5)
Block(1,2,-1,biomesoplenty:log_2:5)
Block(1,2,0,biomesoplenty:log_2:5)
Block(1,2,1,biomesoplenty:log_2:5)
Block(1,3,-1,biomesoplenty:log_2:5)
Block(1,3,0,biomesoplenty:log_2:5)
Block(1,3,1,biomesoplenty:log_2:5)
Block(1,4,0,biomesoplenty:log_2:5)
Block(1,5,0,biomesoplenty:log_2:5)
Block(1,6,0,biomesoplenty:log_2:5)
Block(1,7,0,biomesoplenty:log_2:5)
Block(1,8,0,biomesoplenty:log_2:5)
Block(1,9,0,biomesoplenty:log_2:5)
Block(1,17,0,biomesoplenty:log_2:5)
Block(1,18,-2,biomesoplenty:log_2:5)
Block(1,18,1,biomesoplenty:log_2:5)
Block(1,19,-3,biomesoplenty:log_2:5)
Block(1,19,-1,biomesoplenty:log_2:5)
Block(1,20,-4,biomesoplenty:log_2:5)
Block(1,21,-5,biomesoplenty:log_2:5)
Block(1,22,-6,biomesoplenty:log_2:5)
Block(1,23,-3,biomesoplenty:log_2:5)
Block(1,24,0,biomesoplenty:log_2:5)
Block(1,24,6,biomesoplenty:log_2:5)
Block(1,25,7,biomesoplenty:log_2:5)
Block(1,26,8,biomesoplenty:log_2:5)
Block(1,27,-9,biomesoplenty:leaves_4:3)
Block(1,27,-8,biomesoplenty:leaves_4:3)
Block(1,27,-7,biomesoplenty:leaves_4:3)
Block(1,27,-6,biomesoplenty:leaves_4:3)
Block(1,27,-5,biomesoplenty:leaves_4:3)
Block(1,27,-4,biomesoplenty:leaves_4:3)
Block(1,27,-3,biomesoplenty:leaves_4:3)
Block(1,27,-2,biomesoplenty:leaves_4:3)
Block(1,27,-1,biomesoplenty:leaves_4:3)
Block(1,27,0,biomesoplenty:leaves_4:3)
Block(1,27,1,biomesoplenty:leaves_4:3)
Block(1,27,2,biomesoplenty:leaves_4:3)
Block(1,27,3,biomesoplenty:leaves_4:3)
Block(1,27,4,biomesoplenty:leaves_4:3)
Block(1,27,5,biomesoplenty:log_2:5)
Block(1,27,6,biomesoplenty:leaves_4:3)
Block(1,27,7,biomesoplenty:leaves_4:3)
Block(1,27,8,biomesoplenty:leaves_4:3)
Block(1,27,9,biomesoplenty:leaves_4:3)
Block(1,27,10,biomesoplenty:leaves_4:3)
Block(1,27,11,biomesoplenty:leaves_4:3)
Block(1,27,12,biomesoplenty:leaves_4:3)
Block(1,28,-8,biomesoplenty:leaves_4:3)
Block(1,28,-7,biomesoplenty:leaves_4:3)
Block(1,28,-6,biomesoplenty:leaves_4:3)
Block(1,28,-5,biomesoplenty:leaves_4:3)
Block(1,28,-4,biomesoplenty:leaves_4:3)
Block(1,28,-3,biomesoplenty:leaves_4:3)
Block(1,28,-2,biomesoplenty:leaves_4:3)
Block(1,28,-1,biomesoplenty:leaves_4:3)
Block(1,28,0,biomesoplenty:leaves_4:3)
Block(1,28,1,biomesoplenty:leaves_4:3)
Block(1,28,2,biomesoplenty:leaves_4:3)
Block(1,28,3,biomesoplenty:leaves_4:3)
Block(1,28,4,biomesoplenty:leaves_4:3)
Block(1,28,5,biomesoplenty:leaves_4:3)
Block(1,28,6,biomesoplenty:leaves_4:3)
Block(1,28,7,biomesoplenty:leaves_4:3)
Block(1,28,8,biomesoplenty:leaves_4:3)
Block(1,28,9,biomesoplenty:leaves_4:3)
Block(1,28,10,biomesoplenty:leaves_4:3)
Block(1,28,11,biomesoplenty:leaves_4:3)
Block(1,29,-6,biomesoplenty:leaves_4:3)
Block(1,29,-5,biomesoplenty:leaves_4:3)
Block(1,29,-4,biomesoplenty:leaves_4:3)
Block(1,29,-3,biomesoplenty:leaves_4:3)
Block(1,29,-2,biomesoplenty:leaves_4:3)
Block(1,29,-1,biomesoplenty:leaves_4:3)
Block(1,29,0,biomesoplenty:leaves_4:3)
Block(1,29,1,biomesoplenty:leaves_4:3)
Block(1,29,2,biomesoplenty:leaves_4:3)
Block(1,29,3,biomesoplenty:leaves_4:3)
Block(1,29,4,biomesoplenty:leaves_4:3)
Block(1,29,5,biomesoplenty:leaves_4:3)
Block(1,29,6,biomesoplenty:leaves_4:3)
Block(1,29,7,biomesoplenty:leaves_4:3)
Block(1,29,8,biomesoplenty:leaves_4:3)
Block(1,29,9,biomesoplenty:leaves_4:3)
Block(1,29,10,biomesoplenty:leaves_4:3)
Block(1,29,11,biomesoplenty:leaves_4:3)
Block(1,30,-4,biomesoplenty:leaves_4:3)
Block(1,30,-3,biomesoplenty:leaves_4:3)
Block(1,30,-2,biomesoplenty:leaves_4:3)
Block(1,30,-1,biomesoplenty:leaves_4:3)
Block(1,30,0,biomesoplenty:leaves_4:3)
Block(1,30,1,biomesoplenty:leaves_4:3)
Block(1,30,2,biomesoplenty:leaves_4:3)
Block(1,30,3,biomesoplenty:leaves_4:3)
Block(1,30,4,biomesoplenty:leaves_4:3)
Block(1,30,5,biomesoplenty:leaves_4:3)
Block(1,30,6,biomesoplenty:leaves_4:3)
Block(1,30,7,biomesoplenty:leaves_4:3)
Block(1,31,-3,biomesoplenty:leaves_4:3)
Block(1,31,-2,biomesoplenty:leaves_4:3)
Block(1,31,-1,biomesoplenty:leaves_4:3)
Block(1,31,0,biomesoplenty:leaves_4:3)
Block(1,31,1,biomesoplenty:leaves_4:3)
Block(1,31,2,biomesoplenty:leaves_4:3)
Block(1,31,3,biomesoplenty:leaves_4:3)
Block(1,31,4,biomesoplenty:leaves_4:3)
Block(1,31,5,biomesoplenty:leaves_4:3)
Block(1,31,6,biomesoplenty:leaves_4:3)
Block(1,32,-3,biomesoplenty:leaves_4:3)
Block(1,32,-2,biomesoplenty:leaves_4:3)
Block(1,32,-1,biomesoplenty:leaves_4:3)
Block(1,32,0,biomesoplenty:leaves_4:3)
Block(1,32,1,biomesoplenty:leaves_4:3)
Block(1,32,2,biomesoplenty:leaves_4:3)
Block(1,32,3,biomesoplenty:leaves_4:3)
Block(1,32,4,biomesoplenty:leaves_4:3)
Block(1,32,5,biomesoplenty:leaves_4:3)
Block(2,-7,0,biomesoplenty:log_2:5)
Block(2,-6,0,biomesoplenty:log_2:5)
Block(2,-5,0,biomesoplenty:log_2:5)
Block(2,-4,0,biomesoplenty:log_2:5)
Block(2,-3,0,biomesoplenty:log_2:5)
Block(2,-2,0,biomesoplenty:log_2:5)
Block(2,-1,0,biomesoplenty:log_2:5)
Block(2,0,0,biomesoplenty:log_2:5)
Block(2,18,-1,biomesoplenty:log_2:5)
Block(2,19,-2,biomesoplenty:log_2:5)
Block(2,19,1,biomesoplenty:log_2:5)
Block(2,24,-4,biomesoplenty:log_2:5)
Block(2,25,-5,biomesoplenty:log_2:5)
Block(2,25,0,biomesoplenty:log_2:5)
Block(2,26,-5,biomesoplenty:log_2:5)
Block(2,27,-10,biomesoplenty:leaves_4:3)
Block(2,27,-9,biomesoplenty:leaves_4:3)
Block(2,27,-8,biomesoplenty:leaves_4:3)
Block(2,27,-7,biomesoplenty:leaves_4:3)
Block(2,27,-6,biomesoplenty:leaves_4:3)
Block(2,27,-5,biomesoplenty:leaves_4:3)
Block(2,27,-4,biomesoplenty:leaves_4:3)
Block(2,27,-3,biomesoplenty:leaves_4:3)
Block(2,27,-2,biomesoplenty:leaves_4:3)
Block(2,27,-1,biomesoplenty:leaves_4:3)
Block(2,27,0,biomesoplenty:leaves_4:3)
Block(2,27,1,biomesoplenty:leaves_4:3)
Block(2,27,2,biomesoplenty:leaves_4:3)
Block(2,27,3,biomesoplenty:leaves_4:3)
Block(2,27,4,biomesoplenty:leaves_4:3)
Block(2,27,5,biomesoplenty:leaves_4:3)
Block(2,27,6,biomesoplenty:leaves_4:3)
Block(2,27,7,biomesoplenty:leaves_4:3)
Block(2,27,8,biomesoplenty:leaves_4:3)
Block(2,27,9,biomesoplenty:leaves_4:3)
Block(2,27,10,biomesoplenty:log_2:5)
Block(2,27,11,biomesoplenty:leaves_4:3)
Block(2,27,12,biomesoplenty:leaves_4:3)
Block(2,27,13,biomesoplenty:leaves_4:3)
Block(2,28,-9,biomesoplenty:leaves_4:3)
Block(2,28,-8,biomesoplenty:leaves_4:3)
Block(2,28,-7,biomesoplenty:leaves_4:3)
Block(2,28,-6,biomesoplenty:leaves_4:3)
Block(2,28,-5,biomesoplenty:log_2:5)
Block(2,28,-4,biomesoplenty:leaves_4:3)
Block(2,28,-3,biomesoplenty:leaves_4:3)
Block(2,28,-2,biomesoplenty:leaves_4:3)
Block(2,28,-1,biomesoplenty:leaves_4:3)
Block(2,28,0,biomesoplenty:leaves_4:3)
Block(2,28,1,biomesoplenty:leaves_4:3)
Block(2,28,2,biomesoplenty:leaves_4:3)
Block(2,28,3,biomesoplenty:leaves_4:3)
Block(2,28,4,biomesoplenty:leaves_4:3)
Block(2,28,5,biomesoplenty:leaves_4:3)
Block(2,28,6,biomesoplenty:leaves_4:3)
Block(2,28,7,biomesoplenty:leaves_4:3)
Block(2,28,8,biomesoplenty:leaves_4:3)
Block(2,28,9,biomesoplenty:leaves_4:3)
Block(2,28,10,biomesoplenty:leaves_4:3)
Block(2,28,11,biomesoplenty:leaves_4:3)
Block(2,29,-7,biomesoplenty:leaves_4:3)
Block(2,29,-6,biomesoplenty:leaves_4:3)
Block(2,29,-5,biomesoplenty:leaves_4:3)
Block(2,29,-4,biomesoplenty:leaves_4:3)
Block(2,29,-3,biomesoplenty:leaves_4:3)
Block(2,29,-2,biomesoplenty:leaves_4:3)
Block(2,29,-1,biomesoplenty:leaves_4:3)
Block(2,29,0,biomesoplenty:leaves_4:3)
Block(2,29,1,biomesoplenty:leaves_4:3)
Block(2,29,2,biomesoplenty:leaves_4:3)
Block(2,29,3,biomesoplenty:leaves_4:3)
Block(2,29,4,biomesoplenty:leaves_4:3)
Block(2,29,5,biomesoplenty:log_2:5)
Block(2,29,6,biomesoplenty:leaves_4:3)
Block(2,29,7,biomesoplenty:leaves_4:3)
Block(2,29,8,biomesoplenty:leaves_4:3)
Block(2,29,9,biomesoplenty:leaves_4:3)
Block(2,29,10,biomesoplenty:leaves_4:3)
Block(2,30,-5,biomesoplenty:leaves_4:3)
Block(2,30,-4,biomesoplenty:leaves_4:3)
Block(2,30,-3,biomesoplenty:leaves_4:3)
Block(2,30,-2,biomesoplenty:leaves_4:3)
Block(2,30,-1,biomesoplenty:leaves_4:3)
Block(2,30,0,biomesoplenty:leaves_4:3)
Block(2,30,1,biomesoplenty:leaves_4:3)
Block(2,30,2,biomesoplenty:leaves_4:3)
Block(2,30,3,biomesoplenty:leaves_4:3)
Block(2,30,4,biomesoplenty:leaves_4:3)
Block(2,30,5,biomesoplenty:leaves_4:3)
Block(2,30,6,biomesoplenty:leaves_4:3)
Block(2,30,7,biomesoplenty:leaves_4:3)
Block(2,30,8,biomesoplenty:leaves_4:3)
Block(2,30,9,biomesoplenty:leaves_4:3)
Block(2,31,-3,biomesoplenty:leaves_4:3)
Block(2,31,-2,biomesoplenty:leaves_4:3)
Block(2,31,-1,biomesoplenty:leaves_4:3)
Block(2,31,0,biomesoplenty:leaves_4:3)
Block(2,31,1,biomesoplenty:leaves_4:3)
Block(2,31,2,biomesoplenty:leaves_4:3)
Block(2,31,3,biomesoplenty:leaves_4:3)
Block(2,31,4,biomesoplenty:leaves_4:3)
Block(2,31,5,biomesoplenty:log_2:5)
Block(2,31,6,biomesoplenty:leaves_4:3)
Block(2,32,-2,biomesoplenty:leaves_4:3)
Block(2,32,-1,biomesoplenty:leaves_4:3)
Block(2,32,0,biomesoplenty:leaves_4:3)
Block(2,32,1,biomesoplenty:leaves_4:3)
Block(2,32,2,biomesoplenty:leaves_4:3)
Block(2,32,3,biomesoplenty:leaves_4:3)
Block(2,32,4,biomesoplenty:leaves_4:3)
Block(2,32,5,biomesoplenty:leaves_4:3)
Block(2,32,6,biomesoplenty:leaves_4:3)
Block(3,20,-3,biomesoplenty:log_2:5)
Block(3,20,2,biomesoplenty:log_2:5)
Block(3,26,0,biomesoplenty:log_2:5)
Block(3,27,-10,biomesoplenty:leaves_4:3)
Block(3,27,-9,biomesoplenty:leaves_4:3)
Block(3,27,-8,biomesoplenty:log_2:5)
Block(3,27,-7,biomesoplenty:leaves_4:3)
Block(3,27,-6,biomesoplenty:leaves_4:3)
Block(3,27,-5,biomesoplenty:leaves_4:3)
Block(3,27,-4,biomesoplenty:leaves_4:3)
Block(3,27,-3,biomesoplenty:leaves_4:3)
Block(3,27,-2,biomesoplenty:leaves_4:3)
Block(3,27,-1,biomesoplenty:leaves_4:3)
Block(3,27,0,biomesoplenty:leaves_4:3)
Block(3,27,1,biomesoplenty:leaves_4:3)
Block(3,27,2,biomesoplenty:leaves_4:3)
Block(3,27,3,biomesoplenty:leaves_4:3)
Block(3,27,4,biomesoplenty:leaves_4:3)
Block(3,27,5,biomesoplenty:leaves_4:3)
Block(3,27,6,biomesoplenty:leaves_4:3)
Block(3,27,7,biomesoplenty:leaves_4:3)
Block(3,27,8,biomesoplenty:leaves_4:3)
Block(3,27,9,biomesoplenty:leaves_4:3)
Block(3,27,10,biomesoplenty:leaves_4:3)
Block(3,27,11,biomesoplenty:leaves_4:3)
Block(3,27,12,biomesoplenty:leaves_4:3)
Block(3,28,-9,biomesoplenty:leaves_4:3)
Block(3,28,-8,biomesoplenty:leaves_4:3)
Block(3,28,-7,biomesoplenty:leaves_4:3)
Block(3,28,-6,biomesoplenty:leaves_4:3)
Block(3,28,-5,biomesoplenty:leaves_4:3)
Block(3,28,-4,biomesoplenty:leaves_4:3)
Block(3,28,-3,biomesoplenty:leaves_4:3)
Block(3,28,-2,biomesoplenty:leaves_4:3)
Block(3,28,-1,biomesoplenty:leaves_4:3)
Block(3,28,0,biomesoplenty:leaves_4:3)
Block(3,28,1,biomesoplenty:leaves_4:3)
Block(3,28,2,biomesoplenty:leaves_4:3)
Block(3,28,3,biomesoplenty:leaves_4:3)
Block(3,28,4,biomesoplenty:leaves_4:3)
Block(3,28,5,biomesoplenty:leaves_4:3)
Block(3,28,6,biomesoplenty:leaves_4:3)
Block(3,28,7,biomesoplenty:leaves_4:3)
Block(3,28,8,biomesoplenty:leaves_4:3)
Block(3,28,9,biomesoplenty:leaves_4:3)
Block(3,28,10,biomesoplenty:leaves_4:3)
Block(3,28,11,biomesoplenty:leaves_4:3)
Block(3,28,12,biomesoplenty:leaves_4:3)
Block(3,29,-8,biomesoplenty:leaves_4:3)
Block(3,29,-7,biomesoplenty:leaves_4:3)
Block(3,29,-6,biomesoplenty:leaves_4:3)
Block(3,29,-5,biomesoplenty:leaves_4:3)
Block(3,29,-4,biomesoplenty:leaves_4:3)
Block(3,29,-3,biomesoplenty:leaves_4:3)
Block(3,29,-2,biomesoplenty:leaves_4:3)
Block(3,29,-1,biomesoplenty:leaves_4:3)
Block(3,29,2,biomesoplenty:leaves_4:3)
Block(3,29,3,biomesoplenty:leaves_4:3)
Block(3,29,4,biomesoplenty:leaves_4:3)
Block(3,29,5,biomesoplenty:leaves_4:3)
Block(3,29,6,biomesoplenty:leaves_4:3)
Block(3,29,7,biomesoplenty:leaves_4:3)
Block(3,29,8,biomesoplenty:leaves_4:3)
Block(3,29,9,biomesoplenty:leaves_4:3)
Block(3,29,10,biomesoplenty:leaves_4:3)
Block(3,29,11,biomesoplenty:leaves_4:3)
Block(3,30,-4,biomesoplenty:leaves_4:3)
Block(3,30,-3,biomesoplenty:leaves_4:3)
Block(3,30,-2,biomesoplenty:leaves_4:3)
Block(3,30,-1,biomesoplenty:leaves_4:3)
Block(3,30,0,biomesoplenty:leaves_4:3)
Block(3,30,1,biomesoplenty:leaves_4:3)
Block(3,30,2,biomesoplenty:leaves_4:3)
Block(3,30,3,biomesoplenty:leaves_4:3)
Block(3,30,4,biomesoplenty:leaves_4:3)
Block(3,30,5,biomesoplenty:leaves_4:3)
Block(3,30,6,biomesoplenty:leaves_4:3)
Block(3,30,7,biomesoplenty:leaves_4:3)
Block(3,30,8,biomesoplenty:leaves_4:3)
Block(3,31,-3,biomesoplenty:leaves_4:3)
Block(3,31,-2,biomesoplenty:leaves_4:3)
Block(3,31,-1,biomesoplenty:leaves_4:3)
Block(3,31,0,biomesoplenty:leaves_4:3)
Block(3,31,1,biomesoplenty:leaves_4:3)
Block(3,31,2,biomesoplenty:leaves_4:3)
Block(3,31,3,biomesoplenty:leaves_4:3)
Block(3,31,4,biomesoplenty:leaves_4:3)
Block(3,31,5,biomesoplenty:leaves_4:3)
Block(3,31,6,biomesoplenty:leaves_4:3)
Block(3,31,7,biomesoplenty:leaves_4:3)
Block(3,32,-2,biomesoplenty:leaves_4:3)
Block(3,32,0,biomesoplenty:leaves_4:3)
Block(3,32,1,biomesoplenty:leaves_4:3)
Block(3,32,2,biomesoplenty:leaves_4:3)
Block(3,32,3,biomesoplenty:leaves_4:3)
Block(3,32,4,biomesoplenty:leaves_4:3)
Block(3,32,5,biomesoplenty:leaves_4:3)
Block(3,32,6,biomesoplenty:leaves_4:3)
Block(4,21,-4,biomesoplenty:log_2:5)
Block(4,21,3,biomesoplenty:log_2:5)
Block(4,27,-9,biomesoplenty:leaves_4:3)
Block(4,27,-8,biomesoplenty:leaves_4:3)
Block(4,27,-7,biomesoplenty:leaves_4:3)
Block(4,27,-6,biomesoplenty:leaves_4:3)
Block(4,27,-5,biomesoplenty:leaves_4:3)
Block(4,27,-4,biomesoplenty:leaves_4:3)
Block(4,27,-3,biomesoplenty:leaves_4:3)
Block(4,27,-2,biomesoplenty:leaves_4:3)
Block(4,27,-1,biomesoplenty:leaves_4:3)
Block(4,27,0,biomesoplenty:leaves_4:3)
Block(4,27,1,biomesoplenty:log_2:5)
Block(4,27,2,biomesoplenty:leaves_4:3)
Block(4,27,3,biomesoplenty:leaves_4:3)
Block(4,27,4,biomesoplenty:leaves_4:3)
Block(4,27,5,biomesoplenty:log_2:5)
Block(4,27,6,biomesoplenty:leaves_4:3)
Block(4,27,7,biomesoplenty:leaves_4:3)
Block(4,27,8,biomesoplenty:leaves_4:3)
Block(4,27,9,biomesoplenty:leaves_4:3)
Block(4,27,10,biomesoplenty:leaves_4:3)
Block(4,27,11,biomesoplenty:leaves_4:3)
Block(4,27,12,biomesoplenty:leaves_4:3)
Block(4,27,13,biomesoplenty:leaves_4:3)
Block(4,28,-8,biomesoplenty:leaves_4:3)
Block(4,28,-7,biomesoplenty:leaves_4:3)
Block(4,28,-6,biomesoplenty:leaves_4:3)
Block(4,28,-5,biomesoplenty:leaves_4:3)
Block(4,28,-4,biomesoplenty:leaves_4:3)
Block(4,28,-3,biomesoplenty:leaves_4:3)
Block(4,28,-2,biomesoplenty:leaves_4:3)
Block(4,28,-1,biomesoplenty:leaves_4:3)
Block(4,28,0,biomesoplenty:leaves_4:3)
Block(4,28,1,biomesoplenty:leaves_4:3)
Block(4,28,2,biomesoplenty:leaves_4:3)
Block(4,28,3,biomesoplenty:leaves_4:3)
Block(4,28,4,biomesoplenty:leaves_4:3)
Block(4,28,5,biomesoplenty:log_2:5)
Block(4,28,6,biomesoplenty:leaves_4:3)
Block(4,28,7,biomesoplenty:leaves_4:3)
Block(4,28,8,biomesoplenty:leaves_4:3)
Block(4,28,9,biomesoplenty:leaves_4:3)
Block(4,28,10,biomesoplenty:leaves_4:3)
Block(4,28,11,biomesoplenty:leaves_4:3)
Block(4,29,-7,biomesoplenty:leaves_4:3)
Block(4,29,-6,biomesoplenty:leaves_4:3)
Block(4,29,-5,biomesoplenty:leaves_4:3)
Block(4,29,-4,biomesoplenty:leaves_4:3)
Block(4,29,-3,biomesoplenty:leaves_4:3)
Block(4,29,-2,biomesoplenty:leaves_4:3)
Block(4,29,-1,biomesoplenty:leaves_4:3)
Block(4,29,0,biomesoplenty:leaves_4:3)
Block(4,29,1,biomesoplenty:leaves_4:3)
Block(4,29,2,biomesoplenty:leaves_4:3)
Block(4,29,3,biomesoplenty:leaves_4:3)
Block(4,29,4,biomesoplenty:log_2:5)
Block(4,29,5,biomesoplenty:log_2:5)
Block(4,29,6,biomesoplenty:log_2:5)
Block(4,29,7,biomesoplenty:leaves_4:3)
Block(4,29,8,biomesoplenty:leaves_4:3)
Block(4,29,9,biomesoplenty:leaves_4:3)
Block(4,29,10,biomesoplenty:leaves_4:3)
Block(4,29,11,biomesoplenty:leaves_4:3)
Block(4,30,-5,biomesoplenty:leaves_4:3)
Block(4,30,-4,biomesoplenty:leaves_4:3)
Block(4,30,-3,biomesoplenty:leaves_4:3)
Block(4,30,-2,biomesoplenty:leaves_4:3)
Block(4,30,-1,biomesoplenty:leaves_4:3)
Block(4,30,0,biomesoplenty:leaves_4:3)
Block(4,30,1,biomesoplenty:leaves_4:3)
Block(4,30,2,biomesoplenty:leaves_4:3)
Block(4,30,3,biomesoplenty:leaves_4:3)
Block(4,30,4,biomesoplenty:leaves_4:3)
Block(4,30,5,biomesoplenty:leaves_4:3)
Block(4,30,6,biomesoplenty:log_2:5)
Block(4,30,7,biomesoplenty:leaves_4:3)
Block(4,30,8,biomesoplenty:leaves_4:3)
Block(4,30,9,biomesoplenty:leaves_4:3)
Block(4,31,-2,biomesoplenty:leaves_4:3)
Block(4,31,-1,biomesoplenty:leaves_4:3)
Block(4,31,0,biomesoplenty:leaves_4:3)
Block(4,31,1,biomesoplenty:leaves_4:3)
Block(4,31,2,biomesoplenty:leaves_4:3)
Block(4,31,3,biomesoplenty:leaves_4:3)
Block(4,31,4,biomesoplenty:log_2:5)
Block(4,31,5,biomesoplenty:leaves_4:3)
Block(4,31,6,biomesoplenty:log_2:5)
Block(4,31,7,biomesoplenty:leaves_4:3)
Block(4,31,8,biomesoplenty:leaves_4:3)
Block(4,32,0,biomesoplenty:leaves_4:3)
Block(4,32,1,biomesoplenty:leaves_4:3)
Block(4,32,3,biomesoplenty:leaves_4:3)
Block(4,32,4,biomesoplenty:leaves_4:3)
Block(4,32,5,biomesoplenty:leaves_4:3)
Block(4,32,6,biomesoplenty:leaves_4:3)
Block(4,32,7,biomesoplenty:leaves_4:3)
Block(5,22,-4,biomesoplenty:log_2:5)
Block(5,22,4,biomesoplenty:log_2:5)
Block(5,27,-8,biomesoplenty:leaves_4:3)
Block(5,27,-7,biomesoplenty:leaves_4:3)
Block(5,27,-6,biomesoplenty:log_2:5)
Block(5,27,-5,biomesoplenty:leaves_4:3)
Block(5,27,-4,biomesoplenty:leaves_4:3)
Block(5,27,-3,biomesoplenty:leaves_4:3)
Block(5,27,-2,biomesoplenty:leaves_4:3)
Block(5,27,-1,biomesoplenty:leaves_4:3)
Block(5,27,0,biomesoplenty:leaves_4:3)
Block(5,27,1,biomesoplenty:leaves_4:3)
Block(5,27,2,biomesoplenty:leaves_4:3)
Block(5,27,3,biomesoplenty:leaves_4:3)
Block(5,27,4,biomesoplenty:leaves_4:3)
Block(5,27,5,biomesoplenty:log_2:5)
Block(5,27,6,biomesoplenty:leaves_4:3)
Block(5,27,7,biomesoplenty:leaves_4:3)
Block(5,27,8,biomesoplenty:leaves_4:3)
Block(5,27,9,biomesoplenty:log_2:5)
Block(5,27,10,biomesoplenty:leaves_4:3)
Block(5,27,11,biomesoplenty:leaves_4:3)
Block(5,27,12,biomesoplenty:leaves_4:3)
Block(5,28,-8,biomesoplenty:leaves_4:3)
Block(5,28,-7,biomesoplenty:leaves_4:3)
Block(5,28,-6,biomesoplenty:leaves_4:3)
Block(5,28,-5,biomesoplenty:leaves_4:3)
Block(5,28,-4,biomesoplenty:leaves_4:3)
Block(5,28,-3,biomesoplenty:leaves_4:3)
Block(5,28,-2,biomesoplenty:leaves_4:3)
Block(5,28,-1,biomesoplenty:leaves_4:3)
Block(5,28,0,biomesoplenty:leaves_4:3)
Block(5,28,1,biomesoplenty:leaves_4:3)
Block(5,28,2,biomesoplenty:leaves_4:3)
Block(5,28,3,biomesoplenty:leaves_4:3)
Block(5,28,4,biomesoplenty:leaves_4:3)
Block(5,28,5,biomesoplenty:leaves_4:3)
Block(5,28,6,biomesoplenty:leaves_4:3)
Block(5,28,7,biomesoplenty:leaves_4:3)
Block(5,28,8,biomesoplenty:leaves_4:3)
Block(5,28,9,biomesoplenty:log_2:5)
Block(5,28,10,biomesoplenty:leaves_4:3)
Block(5,28,11,biomesoplenty:leaves_4:3)
Block(5,29,-5,biomesoplenty:leaves_4:3)
Block(5,29,-4,biomesoplenty:leaves_4:3)
Block(5,29,-3,biomesoplenty:leaves_4:3)
Block(5,29,-2,biomesoplenty:leaves_4:3)
Block(5,29,-1,biomesoplenty:leaves_4:3)
Block(5,29,0,biomesoplenty:leaves_4:3)
Block(5,29,1,biomesoplenty:leaves_4:3)
Block(5,29,2,biomesoplenty:leaves_4:3)
Block(5,29,3,biomesoplenty:leaves_4:3)
Block(5,29,4,biomesoplenty:leaves_4:3)
Block(5,29,5,biomesoplenty:leaves_4:3)
Block(5,29,6,biomesoplenty:leaves_4:3)
Block(5,29,7,biomesoplenty:leaves_4:3)
Block(5,29,8,biomesoplenty:leaves_4:3)
Block(5,29,9,biomesoplenty:leaves_4:3)
Block(5,29,10,biomesoplenty:leaves_4:3)
Block(5,30,-4,biomesoplenty:leaves_4:3)
Block(5,30,-3,biomesoplenty:leaves_4:3)
Block(5,30,-2,biomesoplenty:leaves_4:3)
Block(5,30,-1,biomesoplenty:leaves_4:3)
Block(5,30,0,biomesoplenty:leaves_4:3)
Block(5,30,1,biomesoplenty:leaves_4:3)
Block(5,30,2,biomesoplenty:leaves_4:3)
Block(5,30,3,biomesoplenty:leaves_4:3)
Block(5,30,4,biomesoplenty:leaves_4:3)
Block(5,30,5,biomesoplenty:leaves_4:3)
Block(5,30,6,biomesoplenty:leaves_4:3)
Block(5,30,7,biomesoplenty:leaves_4:3)
Block(5,30,8,biomesoplenty:leaves_4:3)
Block(5,30,9,biomesoplenty:leaves_4:3)
Block(5,31,0,biomesoplenty:leaves_4:3)
Block(5,31,1,biomesoplenty:leaves_4:3)
Block(5,31,3,biomesoplenty:leaves_4:3)
Block(5,31,4,biomesoplenty:leaves_4:3)
Block(5,31,5,biomesoplenty:leaves_4:3)
Block(5,31,6,biomesoplenty:leaves_4:3)
Block(5,31,7,biomesoplenty:leaves_4:3)
Block(5,32,4,biomesoplenty:leaves_4:3)
Block(5,32,6,biomesoplenty:leaves_4:3)
Block(6,23,-4,biomesoplenty:log_2:5)
Block(6,23,5,biomesoplenty:log_2:5)
Block(6,25,-3,biomesoplenty:log_2:5)
Block(6,26,-2,biomesoplenty:log_2:5)
Block(6,27,-9,biomesoplenty:leaves_4:3)
Block(6,27,-8,biomesoplenty:leaves_4:3)
Block(6,27,-7,biomesoplenty:leaves_4:3)
Block(6,27,-6,biomesoplenty:leaves_4:3)
Block(6,27,-5,biomesoplenty:leaves_4:3)
Block(6,27,-4,biomesoplenty:leaves_4:3)
Block(6,27,-3,biomesoplenty:leaves_4:3)
Block(6,27,-2,biomesoplenty:log_2:5)
Block(6,27,-1,biomesoplenty:leaves_4:3)
Block(6,27,0,biomesoplenty:leaves_4:3)
Block(6,27,1,biomesoplenty:leaves_4:3)
Block(6,27,2,biomesoplenty:leaves_4:3)
Block(6,27,3,biomesoplenty:leaves_4:3)
Block(6,27,4,biomesoplenty:leaves_4:3)
Block(6,27,5,biomesoplenty:leaves_4:3)
Block(6,27,6,biomesoplenty:leaves_4:3)
Block(6,27,7,biomesoplenty:log_2:5)
Block(6,27,8,biomesoplenty:leaves_4:3)
Block(6,27,9,biomesoplenty:leaves_4:3)
Block(6,27,10,biomesoplenty:leaves_4:3)
Block(6,27,11,biomesoplenty:leaves_4:3)
Block(6,28,-7,biomesoplenty:leaves_4:3)
Block(6,28,-6,biomesoplenty:leaves_4:3)
Block(6,28,-5,biomesoplenty:leaves_4:3)
Block(6,28,-4,biomesoplenty:leaves_4:3)
Block(6,28,-3,biomesoplenty:leaves_4:3)
Block(6,28,-2,biomesoplenty:log_2:5)
Block(6,28,-1,biomesoplenty:leaves_4:3)
Block(6,28,0,biomesoplenty:leaves_4:3)
Block(6,28,1,biomesoplenty:leaves_4:3)
Block(6,28,2,biomesoplenty:leaves_4:3)
Block(6,28,3,biomesoplenty:leaves_4:3)
Block(6,28,4,biomesoplenty:leaves_4:3)
Block(6,28,5,biomesoplenty:leaves_4:3)
Block(6,28,6,biomesoplenty:leaves_4:3)
Block(6,28,7,biomesoplenty:leaves_4:3)
Block(6,28,8,biomesoplenty:leaves_4:3)
Block(6,28,9,biomesoplenty:leaves_4:3)
Block(6,28,10,biomesoplenty:leaves_4:3)
Block(6,29,-5,biomesoplenty:leaves_4:3)
Block(6,29,-4,biomesoplenty:leaves_4:3)
Block(6,29,-3,biomesoplenty:leaves_4:3)
Block(6,29,-2,biomesoplenty:leaves_4:3)
Block(6,29,-1,biomesoplenty:leaves_4:3)
Block(6,29,0,biomesoplenty:leaves_4:3)
Block(6,29,1,biomesoplenty:leaves_4:3)
Block(6,29,2,biomesoplenty:leaves_4:3)
Block(6,29,3,biomesoplenty:leaves_4:3)
Block(6,29,4,biomesoplenty:leaves_4:3)
Block(6,29,5,biomesoplenty:leaves_4:3)
Block(6,29,6,biomesoplenty:leaves_4:3)
Block(6,29,7,biomesoplenty:leaves_4:3)
Block(6,29,8,biomesoplenty:leaves_4:3)
Block(6,29,9,biomesoplenty:leaves_4:3)
Block(6,30,-3,biomesoplenty:leaves_4:3)
Block(6,30,-1,biomesoplenty:leaves_4:3)
Block(6,30,0,biomesoplenty:leaves_4:3)
Block(6,30,1,biomesoplenty:leaves_4:3)
Block(6,30,2,biomesoplenty:leaves_4:3)
Block(6,30,3,biomesoplenty:leaves_4:3)
Block(6,30,4,biomesoplenty:leaves_4:3)
Block(6,30,5,biomesoplenty:leaves_4:3)
Block(6,30,6,biomesoplenty:leaves_4:3)
Block(6,30,7,biomesoplenty:leaves_4:3)
Block(6,30,8,biomesoplenty:leaves_4:3)
Block(6,31,4,biomesoplenty:leaves_4:3)
Block(6,31,5,biomesoplenty:leaves_4:3)
Block(6,31,6,biomesoplenty:leaves_4:3)
Block(7,23,-4,biomesoplenty:log_2:5)
Block(7,24,-4,biomesoplenty:log_2:5)
Block(7,24,5,biomesoplenty:log_2:5)
Block(7,27,-8,biomesoplenty:leaves_4:3)
Block(7,27,-7,biomesoplenty:leaves_4:3)
Block(7,27,-6,biomesoplenty:leaves_4:3)
Block(7,27,-5,biomesoplenty:leaves_4:3)
Block(7,27,-4,biomesoplenty:leaves_4:3)
Block(7,27,-3,biomesoplenty:leaves_4:3)
Block(7,27,-2,biomesoplenty:leaves_4:3)
Block(7,27,-1,biomesoplenty:leaves_4:3)
Block(7,27,0,biomesoplenty:leaves_4:3)
Block(7,27,1,biomesoplenty:leaves_4:3)
Block(7,27,2,biomesoplenty:log_2:5)
Block(7,27,3,biomesoplenty:leaves_4:3)
Block(7,27,4,biomesoplenty:leaves_4:3)
Block(7,27,5,biomesoplenty:leaves_4:3)
Block(7,27,6,biomesoplenty:leaves_4:3)
Block(7,27,7,biomesoplenty:leaves_4:3)
Block(7,27,8,biomesoplenty:leaves_4:3)
Block(7,27,9,biomesoplenty:leaves_4:3)
Block(7,27,10,biomesoplenty:leaves_4:3)
Block(7,28,-6,biomesoplenty:leaves_4:3)
Block(7,28,-5,biomesoplenty:leaves_4:3)
Block(7,28,-4,biomesoplenty:leaves_4:3)
Block(7,28,-3,biomesoplenty:leaves_4:3)
Block(7,28,-2,biomesoplenty:leaves_4:3)
Block(7,28,-1,biomesoplenty:leaves_4:3)
Block(7,28,0,biomesoplenty:leaves_4:3)
Block(7,28,1,biomesoplenty:leaves_4:3)
Block(7,28,2,biomesoplenty:log_2:5)
Block(7,28,3,biomesoplenty:leaves_4:3)
Block(7,28,4,biomesoplenty:leaves_4:3)
Block(7,28,5,biomesoplenty:leaves_4:3)
Block(7,28,6,biomesoplenty:leaves_4:3)
Block(7,28,7,biomesoplenty:leaves_4:3)
Block(7,28,8,biomesoplenty:leaves_4:3)
Block(7,28,9,biomesoplenty:leaves_4:3)
Block(7,28,10,biomesoplenty:leaves_4:3)
Block(7,29,-4,biomesoplenty:leaves_4:3)
Block(7,29,-3,biomesoplenty:leaves_4:3)
Block(7,29,-2,biomesoplenty:leaves_4:3)
Block(7,29,-1,biomesoplenty:leaves_4:3)
Block(7,29,0,biomesoplenty:leaves_4:3)
Block(7,29,1,biomesoplenty:leaves_4:3)
Block(7,29,2,biomesoplenty:leaves_4:3)
Block(7,29,3,biomesoplenty:leaves_4:3)
Block(7,29,4,biomesoplenty:leaves_4:3)
Block(7,29,5,biomesoplenty:leaves_4:3)
Block(7,29,6,biomesoplenty:leaves_4:3)
Block(7,29,7,biomesoplenty:leaves_4:3)
Block(7,29,8,biomesoplenty:leaves_4:3)
Block(7,29,9,biomesoplenty:leaves_4:3)
Block(7,30,-1,biomesoplenty:leaves_4:3)
Block(7,30,0,biomesoplenty:leaves_4:3)
Block(7,30,1,biomesoplenty:leaves_4:3)
Block(7,30,3,biomesoplenty:leaves_4:3)
Block(7,30,4,biomesoplenty:leaves_4:3)
Block(7,30,5,biomesoplenty:leaves_4:3)
Block(7,30,6,biomesoplenty:leaves_4:3)
Block(7,30,7,biomesoplenty:leaves_4:3)
Block(7,30,8,biomesoplenty:leaves_4:3)
Block(7,31,6,biomesoplenty:leaves_4:3)
Block(8,24,-5,biomesoplenty:log_2:5)
Block(8,24,-3,biomesoplenty:log_2:5)
Block(8,25,6,biomesoplenty:log_2:5)
Block(8,27,-9,biomesoplenty:leaves_4:3)
Block(8,27,-8,biomesoplenty:leaves_4:3)
Block(8,27,-7,biomesoplenty:leaves_4:3)
Block(8,27,-6,biomesoplenty:leaves_4:3)
Block(8,27,-5,biomesoplenty:log_2:5)
Block(8,27,-4,biomesoplenty:leaves_4:3)
Block(8,27,-3,biomesoplenty:leaves_4:3)
Block(8,27,-2,biomesoplenty:leaves_4:3)
Block(8,27,-1,biomesoplenty:leaves_4:3)
Block(8,27,0,biomesoplenty:leaves_4:3)
Block(8,27,1,biomesoplenty:leaves_4:3)
Block(8,27,2,biomesoplenty:leaves_4:3)
Block(8,27,3,biomesoplenty:leaves_4:3)
Block(8,27,4,biomesoplenty:leaves_4:3)
Block(8,27,5,biomesoplenty:leaves_4:3)
Block(8,27,6,biomesoplenty:leaves_4:3)
Block(8,27,7,biomesoplenty:leaves_4:3)
Block(8,27,8,biomesoplenty:leaves_4:3)
Block(8,27,9,biomesoplenty:leaves_4:3)
Block(8,27,10,biomesoplenty:leaves_4:3)
Block(8,27,11,biomesoplenty:leaves_4:3)
Block(8,28,-7,biomesoplenty:leaves_4:3)
Block(8,28,-6,biomesoplenty:leaves_4:3)
Block(8,28,-5,biomesoplenty:leaves_4:3)
Block(8,28,-4,biomesoplenty:leaves_4:3)
Block(8,28,-3,biomesoplenty:leaves_4:3)
Block(8,28,-2,biomesoplenty:leaves_4:3)
Block(8,28,-1,biomesoplenty:leaves_4:3)
Block(8,28,0,biomesoplenty:leaves_4:3)
Block(8,28,1,biomesoplenty:leaves_4:3)
Block(8,28,2,biomesoplenty:leaves_4:3)
Block(8,28,3,biomesoplenty:leaves_4:3)
Block(8,28,4,biomesoplenty:leaves_4:3)
Block(8,28,5,biomesoplenty:leaves_4:3)
Block(8,28,6,biomesoplenty:leaves_4:3)
Block(8,28,7,biomesoplenty:leaves_4:3)
Block(8,28,8,biomesoplenty:leaves_4:3)
Block(8,28,9,biomesoplenty:leaves_4:3)
Block(8,29,-5,biomesoplenty:leaves_4:3)
Block(8,29,-4,biomesoplenty:leaves_4:3)
Block(8,29,-3,biomesoplenty:leaves_4:3)
Block(8,29,-2,biomesoplenty:leaves_4:3)
Block(8,29,-1,biomesoplenty:leaves_4:3)
Block(8,29,0,biomesoplenty:leaves_4:3)
Block(8,29,1,biomesoplenty:leaves_4:3)
Block(8,29,2,biomesoplenty:leaves_4:3)
Block(8,29,3,biomesoplenty:leaves_4:3)
Block(8,29,4,biomesoplenty:leaves_4:3)
Block(8,29,5,biomesoplenty:leaves_4:3)
Block(8,29,6,biomesoplenty:leaves_4:3)
Block(8,29,7,biomesoplenty:leaves_4:3)
Block(8,29,8,biomesoplenty:leaves_4:3)
Block(8,30,0,biomesoplenty:leaves_4:3)
Block(8,30,3,biomesoplenty:leaves_4:3)
Block(8,30,5,biomesoplenty:leaves_4:3)
Block(8,30,6,biomesoplenty:leaves_4:3)
Block(9,25,-5,biomesoplenty:log_2:5)
Block(9,25,-3,biomesoplenty:log_2:5)
Block(9,25,7,biomesoplenty:log_2:5)
Block(9,26,-2,biomesoplenty:log_2:5)
Block(9,26,7,biomesoplenty:log_2:5)
Block(9,27,-10,biomesoplenty:leaves_4:3)
Block(9,27,-9,biomesoplenty:leaves_4:3)
Block(9,27,-8,biomesoplenty:leaves_4:3)
Block(9,27,-7,biomesoplenty:leaves_4:3)
Block(9,27,-6,biomesoplenty:leaves_4:3)
Block(9,27,-5,biomesoplenty:leaves_4:3)
Block(9,27,-4,biomesoplenty:leaves_4:3)
Block(9,27,-3,biomesoplenty:leaves_4:3)
Block(9,27,-2,biomesoplenty:log_2:5)
Block(9,27,-1,biomesoplenty:leaves_4:3)
Block(9,27,0,biomesoplenty:leaves_4:3)
Block(9,27,1,biomesoplenty:leaves_4:3)
Block(9,27,2,biomesoplenty:leaves_4:3)
Block(9,27,3,biomesoplenty:log_2:5)
Block(9,27,4,biomesoplenty:leaves_4:3)
Block(9,27,5,biomesoplenty:leaves_4:3)
Block(9,27,6,biomesoplenty:leaves_4:3)
Block(9,27,7,biomesoplenty:log_2:5)
Block(9,27,8,biomesoplenty:leaves_4:3)
Block(9,27,9,biomesoplenty:leaves_4:3)
Block(9,28,-9,biomesoplenty:leaves_4:3)
Block(9,28,-8,biomesoplenty:leaves_4:3)
Block(9,28,-7,biomesoplenty:leaves_4:3)
Block(9,28,-6,biomesoplenty:leaves_4:3)
Block(9,28,-5,biomesoplenty:leaves_4:3)
Block(9,28,-4,biomesoplenty:leaves_4:3)
Block(9,28,-3,biomesoplenty:leaves_4:3)
Block(9,28,-2,biomesoplenty:log_2:5)
Block(9,28,-1,biomesoplenty:leaves_4:3)
Block(9,28,0,biomesoplenty:leaves_4:3)
Block(9,28,1,biomesoplenty:leaves_4:3)
Block(9,28,2,biomesoplenty:leaves_4:3)
Block(9,28,3,biomesoplenty:leaves_4:3)
Block(9,28,4,biomesoplenty:leaves_4:3)
Block(9,28,5,biomesoplenty:leaves_4:3)
Block(9,28,6,biomesoplenty:leaves_4:3)
Block(9,28,7,biomesoplenty:log_2:5)
Block(9,28,8,biomesoplenty:leaves_4:3)
Block(9,29,-8,biomesoplenty:leaves_4:3)
Block(9,29,-6,biomesoplenty:leaves_4:3)
Block(9,29,-5,biomesoplenty:leaves_4:3)
Block(9,29,-4,biomesoplenty:leaves_4:3)
Block(9,29,-2,biomesoplenty:leaves_4:3)
Block(9,29,-1,biomesoplenty:leaves_4:3)
Block(9,29,0,biomesoplenty:leaves_4:3)
Block(9,29,1,biomesoplenty:leaves_4:3)
Block(9,29,3,biomesoplenty:leaves_4:3)
Block(9,29,4,biomesoplenty:leaves_4:3)
Block(9,29,5,biomesoplenty:leaves_4:3)
Block(9,29,6,biomesoplenty:leaves_4:3)
Block(9,29,7,biomesoplenty:leaves_4:3)
Block(9,29,8,biomesoplenty:leaves_4:3)
Block(9,30,5,biomesoplenty:leaves_4:3)
Block(10,25,-6,biomesoplenty:log_2:5)
Block(10,26,-6,biomesoplenty:log_2:5)
Block(10,27,-9,biomesoplenty:leaves_4:3)
Block(10,27,-8,biomesoplenty:leaves_4:3)
Block(10,27,-7,biomesoplenty:leaves_4:3)
Block(10,27,-6,biomesoplenty:leaves_4:3)
Block(10,27,-5,biomesoplenty:leaves_4:3)
Block(10,27,-4,biomesoplenty:leaves_4:3)
Block(10,27,-3,biomesoplenty:leaves_4:3)
Block(10,27,-2,biomesoplenty:leaves_4:3)
Block(10,27,-1,biomesoplenty:leaves_4:3)
Block(10,27,0,biomesoplenty:leaves_4:3)
Block(10,27,1,biomesoplenty:leaves_4:3)
Block(10,27,2,biomesoplenty:leaves_4:3)
Block(10,27,3,biomesoplenty:leaves_4:3)
Block(10,27,4,biomesoplenty:leaves_4:3)
Block(10,27,5,biomesoplenty:leaves_4:3)
Block(10,27,6,biomesoplenty:leaves_4:3)
Block(10,27,7,biomesoplenty:leaves_4:3)
Block(10,27,8,biomesoplenty:leaves_4:3)
Block(10,28,-9,biomesoplenty:leaves_4:3)
Block(10,28,-8,biomesoplenty:leaves_4:3)
Block(10,28,-7,biomesoplenty:leaves_4:3)
Block(10,28,-6,biomesoplenty:leaves_4:3)
Block(10,28,-5,biomesoplenty:leaves_4:3)
Block(10,28,-4,biomesoplenty:leaves_4:3)
Block(10,28,-3,biomesoplenty:leaves_4:3)
Block(10,28,-2,biomesoplenty:leaves_4:3)
Block(10,28,-1,biomesoplenty:leaves_4:3)
Block(10,28,0,biomesoplenty:leaves_4:3)
Block(10,28,1,biomesoplenty:leaves_4:3)
Block(10,28,3,biomesoplenty:leaves_4:3)
Block(10,28,4,biomesoplenty:leaves_4:3)
Block(10,28,5,biomesoplenty:leaves_4:3)
Block(10,28,6,biomesoplenty:leaves_4:3)
Block(10,28,7,biomesoplenty:leaves_4:3)
Block(10,28,8,biomesoplenty:leaves_4:3)
Block(10,29,-9,biomesoplenty:leaves_4:3)
Block(10,29,-8,biomesoplenty:leaves_4:3)
Block(10,29,-7,biomesoplenty:leaves_4:3)
Block(10,29,-6,biomesoplenty:leaves_4:3)
Block(10,29,-5,biomesoplenty:leaves_4:3)
Block(10,29,-2,biomesoplenty:leaves_4:3)
Block(10,29,-1,biomesoplenty:leaves_4:3)
Block(10,29,4,biomesoplenty:leaves_4:3)
Block(10,29,5,biomesoplenty:leaves_4:3)
Block(10,29,7,biomesoplenty:leaves_4:3)
Block(11,26,-7,biomesoplenty:log_2:5)
Block(11,27,-10,biomesoplenty:leaves_4:3)
Block(11,27,-9,biomesoplenty:leaves_4:3)
Block(11,27,-8,biomesoplenty:leaves_4:3)
Block(11,27,-7,biomesoplenty:log_2:5)
Block(11,27,-6,biomesoplenty:leaves_4:3)
Block(11,27,-5,biomesoplenty:leaves_4:3)
Block(11,27,-4,biomesoplenty:leaves_4:3)
Block(11,27,-3,biomesoplenty:leaves_4:3)
Block(11,27,-2,biomesoplenty:leaves_4:3)
Block(11,27,-1,biomesoplenty:leaves_4:3)
Block(11,27,0,biomesoplenty:leaves_4:3)
Block(11,27,3,biomesoplenty:leaves_4:3)
Block(11,27,4,biomesoplenty:leaves_4:3)
Block(11,27,5,biomesoplenty:leaves_4:3)
Block(11,27,6,biomesoplenty:leaves_4:3)
Block(11,27,8,biomesoplenty:leaves_4:3)
Block(11,28,-9,biomesoplenty:leaves_4:3)
Block(11,28,-8,biomesoplenty:leaves_4:3)
Block(11,28,-7,biomesoplenty:log_2:5)
Block(11,28,-6,biomesoplenty:leaves_4:3)
Block(11,28,-5,biomesoplenty:leaves_4:3)
Block(11,28,-2,biomesoplenty:leaves_4:3)
Block(11,28,-1,biomesoplenty:leaves_4:3)
Block(11,28,4,biomesoplenty:leaves_4:3)
Block(11,28,5,biomesoplenty:leaves_4:3)
Block(11,29,-8,biomesoplenty:leaves_4:3)
Block(11,29,-7,biomesoplenty:leaves_4:3)
Block(11,29,-6,biomesoplenty:leaves_4:3)
Block(12,27,-9,biomesoplenty:leaves_4:3)
Block(12,27,-8,biomesoplenty:leaves_4:3)
Block(12,27,-7,biomesoplenty:leaves_4:3)
Block(12,27,-6,biomesoplenty:leaves_4:3)
Block(12,27,-5,biomesoplenty:leaves_4:3)
Block(12,27,-4,biomesoplenty:leaves_4:3)
Block(12,27,-2,biomesoplenty:leaves_4:3)
Block(12,27,-1,biomesoplenty:leaves_4:3)
Block(12,27,4,biomesoplenty:leaves_4:3)
Block(12,27,5,biomesoplenty:leaves_4:3)
Block(12,28,-8,biomesoplenty:leaves_4:3)
Block(12,28,-7,biomesoplenty:leaves_4:3)
Block(12,28,-6,biomesoplenty:leaves_4:3)
Block(12,29,-7,biomesoplenty:leaves_4:3)
Block(13,27,-8,biomesoplenty:leaves_4:3)
Block(13,27,-6,biomesoplenty:leaves_4:3)
Block(13,27,-5,biomesoplenty:leaves_4:3)

#######################################################################
# +-----------------------------------------------------------------+ #
# |                            BO3 checks                           | #
# +-----------------------------------------------------------------+ #
#######################################################################

BlockCheck(0,-1,0,GRASS,DIRT,DIRT:2,DIRT:1,SAND,HARD_CLAY)

#######################################################################
# +-----------------------------------------------------------------+ #
# |                             Branches                            | #
# +-----------------------------------------------------------------+ #
#######################################################################


#######################################################################
# +-----------------------------------------------------------------+ #
# |                             Entities                            | #
# +-----------------------------------------------------------------+ #
#######################################################################


#######################################################################
# +-----------------------------------------------------------------+ #
# |                            Particles                            | #
# +-----------------------------------------------------------------+ #
#######################################################################


#######################################################################
# +-----------------------------------------------------------------+ #
# |                             Spawners                            | #
# +-----------------------------------------------------------------+ #
#######################################################################


#######################################################################
# +-----------------------------------------------------------------+ #
# |                             ModData                             | #
# +-----------------------------------------------------------------+ #
#######################################################################

