
#######################################################################
# +-----------------------------------------------------------------+ #
# |                            BO3 object                           | #
# +-----------------------------------------------------------------+ #
#######################################################################

Author: Unknown

Description: Converted version of the BO2 WaterJungleTree

Version: 3

SettingsMode: WriteWithoutComments


#######################################################################
# +-----------------------------------------------------------------+ #
# |                          Main settings                          | #
# +-----------------------------------------------------------------+ #
#######################################################################

Tree: true

Frequency: 1

Rarity: 5.0

RotateRandomly: true

SpawnHeight: highestSolidBlock

SpawnHeightOffset: 0

SpawnHeightVariance: 0

##############################
# Height Limits for the BO3. #
##############################

MinHeight: 51

MaxHeight: 62

######################
# Extrusion settings #
######################

ExtrudeMode: None

ExtrudeThroughBlocks: AIR

MaxBranchDepth: 10

ExcludedBiomes: All


#######################################################################
# +-----------------------------------------------------------------+ #
# |                      Source block settings                      | #
# +-----------------------------------------------------------------+ #
#######################################################################

SourceBlocks: STONE:1,STONE:3,STONE:5,DIRT:1,DIRT,SAND,GRASS,DIRT:2,STATIONARY_WATER,HARD_CLAY,STAINED_CLAY,CLAY,SANDSTONE,SAND:1,AIR,STONE,GRAVEL,LONG_GRASS,LONG_GRASS:1,LONG_GRASS:2,DEAD_BUSH,YELLOW_FLOWER,RED_ROSE,BROWN_MUSHROOM,RED_MUSHROOM,biomesoplenty:plant_0:1,biomesoplenty:plant_0:2,biomesoplenty:plant_0:3,biomesoplenty:plant_0:4,biomesoplenty:plant_0:5,biomesoplenty:plant_0:6,biomesoplenty:plant_0:7,biomesoplenty:plant_0:8,biomesoplenty:plant_0:9,biomesoplenty:plant_0:10,biomesoplenty:plant_0:11,biomesoplenty:plant_0:12,biomesoplenty:plant_0:13,biomesoplenty:plant_0:14,biomesoplenty:flower_0:1,biomesoplenty:flower_0:2,biomesoplenty:flower_0:3,biomesoplenty:flower_0:4,biomesoplenty:flower_0:5,biomesoplenty:flower_0:6,biomesoplenty:flower_0:7,biomesoplenty:flower_0:8,biomesoplenty:flower_0:9,biomesoplenty:flower_0:10,biomesoplenty:flower_0:11,biomesoplenty:flower_0:12,biomesoplenty:flower_0:13,biomesoplenty:flower_0:14,biomesoplenty:plant_1:0,biomesoplenty:grass:0,biomesoplenty:grass:1,biomesoplenty:grass:2,biomesoplenty:grass:3,biomesoplenty:grass:4,biomesoplenty:grass:5,biomesoplenty:grass:6,biomesoplenty:grass:7,biomesoplenty:dirt:0,biomesoplenty:dirt:1,biomesoplenty:dirt:2,biomesoplenty:dirt:3,biomesoplenty:dirt:4,biomesoplenty:dirt:5,biomesoplenty:dirt:6,biomesoplenty:dirt:7,biomesoplenty:dirt:8,biomesoplenty:dirt:9,biomesoplenty:dirt:10,biomesoplenty:dried_sand:0,biomesoplenty:hard_ice:0,biomesoplenty:white_sand:0,biomesoplenty:white_sandstone:0,biomesoplenty:mud:0,biomesoplenty:ash_block:0
MaxPercentageOutsideSourceBlock: 0

OutsideSourceBlock: placeAnyway

IsOTGPlus: false


#######################################################################
# +-----------------------------------------------------------------+ #
# |                              Blocks                             | #
# +-----------------------------------------------------------------+ #
#######################################################################

Block(4,40,-2,biomesoplenty:leaves_4:3)
Block(4,43,-2,biomesoplenty:leaves_4:3)
Block(4,44,-2,biomesoplenty:leaves_4:3)
Block(4,41,-2,biomesoplenty:leaves_4:3)
Block(-11,49,0,biomesoplenty:leaves_4:3)
Block(4,42,-2,biomesoplenty:leaves_4:3)
Block(15,40,-22,biomesoplenty:leaves_4:3)
Block(15,41,-22,biomesoplenty:leaves_4:3)
Block(-2,41,-16,biomesoplenty:leaves_4:3)
Block(-2,42,-16,biomesoplenty:leaves_4:3)
Block(-2,40,-16,biomesoplenty:leaves_4:3)
Block(-8,45,-7,biomesoplenty:leaves_4:3)
Block(4,47,-2,biomesoplenty:leaves_4:3)
Block(-8,46,-7,biomesoplenty:leaves_4:3)
Block(4,48,-2,biomesoplenty:leaves_4:3)
Block(-8,43,-7,biomesoplenty:leaves_4:3)
Block(4,45,-2,biomesoplenty:leaves_4:3)
Block(-8,44,-7,biomesoplenty:leaves_4:3)
Block(4,46,-2,biomesoplenty:leaves_4:3)
Block(-8,49,-7,biomesoplenty:leaves_4:3)
Block(-8,47,-7,biomesoplenty:leaves_4:3)
Block(4,49,-2,biomesoplenty:log_2:5)
Block(-8,48,-7,biomesoplenty:leaves_4:3)
Block(-1,41,6,biomesoplenty:leaves_4:3)
Block(-1,40,6,biomesoplenty:leaves_4:3)
Block(-1,45,6,biomesoplenty:leaves_4:3)
Block(-1,44,6,biomesoplenty:leaves_4:3)
Block(-1,42,6,biomesoplenty:leaves_4:3)
Block(14,40,-1,biomesoplenty:leaves_4:3)
Block(-16,45,-1,biomesoplenty:leaves_4:3)
Block(-1,37,6,biomesoplenty:log_2:5)
Block(-16,44,-1,biomesoplenty:leaves_4:3)
Block(-16,43,-1,biomesoplenty:leaves_4:3)
Block(-16,42,-1,biomesoplenty:leaves_4:3)
Block(14,44,-1,biomesoplenty:leaves_4:3)
Block(14,43,-1,biomesoplenty:leaves_4:3)
Block(14,42,-1,biomesoplenty:leaves_4:3)
Block(14,41,-1,biomesoplenty:leaves_4:3)
Block(-15,40,13,biomesoplenty:leaves_4:3)
Block(14,47,-1,biomesoplenty:leaves_4:3)
Block(-1,51,6,biomesoplenty:leaves_4:3)
Block(14,46,-1,biomesoplenty:leaves_4:3)
Block(-1,50,6,biomesoplenty:leaves_4:3)
Block(0,50,7,biomesoplenty:leaves_4:3)
Block(14,45,-1,biomesoplenty:leaves_4:3)
Block(0,51,7,biomesoplenty:leaves_4:3)
Block(-2,40,8,biomesoplenty:leaves_4:3)
Block(-2,41,8,biomesoplenty:leaves_4:3)
Block(-2,42,8,biomesoplenty:leaves_4:3)
Block(-2,43,8,biomesoplenty:leaves_4:3)
Block(-2,44,8,biomesoplenty:leaves_4:3)
Block(-2,45,8,biomesoplenty:leaves_4:3)
Block(3,45,14,biomesoplenty:leaves_4:3)
Block(3,44,14,biomesoplenty:leaves_4:3)
Block(-2,46,8,biomesoplenty:leaves_4:3)
Block(-2,47,8,biomesoplenty:log_2:5)
Block(-2,48,8,biomesoplenty:leaves_4:3)
Block(3,41,14,biomesoplenty:leaves_4:3)
Block(3,40,14,biomesoplenty:leaves_4:3)
Block(2,41,20,biomesoplenty:leaves_4:3)
Block(3,43,14,biomesoplenty:leaves_4:3)
Block(2,40,20,biomesoplenty:leaves_4:3)
Block(3,42,14,biomesoplenty:leaves_4:3)
Block(-1,49,6,biomesoplenty:log_2:5)
Block(-1,48,6,biomesoplenty:leaves_4:3)
Block(-1,47,6,biomesoplenty:leaves_4:3)
Block(-1,46,6,biomesoplenty:leaves_4:3)
Block(2,41,19,biomesoplenty:leaves_4:3)
Block(2,40,19,biomesoplenty:log_2:5)
Block(0,41,7,biomesoplenty:log_2:5)
Block(-10,46,9,biomesoplenty:leaves_4:3)
Block(-12,47,2,biomesoplenty:leaves_4:3)
Block(0,42,7,biomesoplenty:leaves_4:3)
Block(-10,45,9,biomesoplenty:leaves_4:3)
Block(-12,45,2,biomesoplenty:leaves_4:3)
Block(0,40,7,biomesoplenty:log_2:5)
Block(-10,42,9,biomesoplenty:leaves_4:3)
Block(-2,50,8,biomesoplenty:leaves_4:3)
Block(-10,43,9,biomesoplenty:leaves_4:3)
Block(4,42,-18,biomesoplenty:leaves_4:3)
Block(4,43,-18,biomesoplenty:leaves_4:3)
Block(-2,46,-16,biomesoplenty:leaves_4:3)
Block(-2,43,-16,biomesoplenty:leaves_4:3)
Block(4,41,-18,biomesoplenty:log_2:5)
Block(-12,42,2,biomesoplenty:leaves_4:3)
Block(-12,41,2,biomesoplenty:leaves_4:3)
Block(-12,40,2,biomesoplenty:leaves_4:3)
Block(-2,49,8,biomesoplenty:leaves_4:3)
Block(3,40,-12,biomesoplenty:leaves_4:3)
Block(-11,40,0,biomesoplenty:leaves_4:3)
Block(3,43,-12,biomesoplenty:leaves_4:3)
Block(-15,43,-6,biomesoplenty:leaves_4:3)
Block(15,44,-10,biomesoplenty:leaves_4:3)
Block(-15,42,-6,biomesoplenty:leaves_4:3)
Block(3,44,-12,biomesoplenty:leaves_4:3)
Block(3,41,-12,biomesoplenty:leaves_4:3)
Block(-15,41,-6,biomesoplenty:leaves_4:3)
Block(4,44,-18,biomesoplenty:leaves_4:3)
Block(-15,40,-6,biomesoplenty:leaves_4:3)
Block(3,42,-12,biomesoplenty:leaves_4:3)
Block(3,47,-12,biomesoplenty:leaves_4:3)
Block(-11,47,0,biomesoplenty:log_2:5)
Block(0,49,7,biomesoplenty:leaves_4:3)
Block(-11,48,0,biomesoplenty:leaves_4:3)
Block(-10,40,9,biomesoplenty:leaves_4:3)
Block(0,47,7,biomesoplenty:leaves_4:3)
Block(15,43,-10,biomesoplenty:leaves_4:3)
Block(3,46,-12,biomesoplenty:leaves_4:3)
Block(-11,46,0,biomesoplenty:leaves_4:3)
Block(0,48,7,biomesoplenty:leaves_4:3)
Block(0,45,7,biomesoplenty:leaves_4:3)
Block(-11,44,0,biomesoplenty:leaves_4:3)
Block(0,46,7,biomesoplenty:leaves_4:3)
Block(-11,41,0,biomesoplenty:leaves_4:3)
Block(-11,42,0,biomesoplenty:leaves_4:3)
Block(0,44,7,biomesoplenty:log_2:5)
Block(3,41,-7,biomesoplenty:log_2:5)
Block(3,42,-7,biomesoplenty:leaves_4:3)
Block(3,40,-7,biomesoplenty:leaves_4:3)
Block(3,49,-7,biomesoplenty:leaves_4:3)
Block(3,47,-7,biomesoplenty:log_2:5)
Block(3,48,-7,biomesoplenty:leaves_4:3)
Block(3,45,-7,biomesoplenty:leaves_4:3)
Block(3,46,-7,biomesoplenty:leaves_4:3)
Block(3,43,-7,biomesoplenty:log_2:5)
Block(3,44,-7,biomesoplenty:leaves_4:3)
Block(-7,50,-1,biomesoplenty:leaves_4:3)
Block(-9,49,-2,biomesoplenty:leaves_4:3)
Block(-7,51,-1,biomesoplenty:leaves_4:3)
Block(5,30,-8,biomesoplenty:log_2:5)
Block(-9,47,-2,biomesoplenty:leaves_4:3)
Block(-9,48,-2,biomesoplenty:log_2:5)
Block(-9,45,-2,biomesoplenty:leaves_4:3)
Block(-9,46,-2,biomesoplenty:leaves_4:3)
Block(-9,43,-2,biomesoplenty:log_2:5)
Block(-9,44,-2,biomesoplenty:leaves_4:3)
Block(-9,41,-2,biomesoplenty:leaves_4:3)
Block(-9,42,-2,biomesoplenty:leaves_4:3)
Block(-9,40,-2,biomesoplenty:log_2:5)
Block(3,50,-7,biomesoplenty:log_2:5)
Block(3,51,-7,biomesoplenty:leaves_4:3)
Block(-17,40,-7,biomesoplenty:leaves_4:3)
Block(-17,41,-7,biomesoplenty:leaves_4:3)
Block(-7,41,-1,biomesoplenty:leaves_4:3)
Block(-7,40,-1,biomesoplenty:log_2:5)
Block(5,41,-8,biomesoplenty:leaves_4:3)
Block(-7,43,-1,biomesoplenty:log_2:5)
Block(5,40,-8,biomesoplenty:leaves_4:3)
Block(-7,42,-1,biomesoplenty:leaves_4:3)
Block(-7,45,-1,biomesoplenty:log_2:5)
Block(-7,44,-1,biomesoplenty:leaves_4:3)
Block(5,45,-8,biomesoplenty:log_2:5)
Block(-7,47,-1,biomesoplenty:leaves_4:3)
Block(5,44,-8,biomesoplenty:log_2:5)
Block(-7,46,-1,biomesoplenty:leaves_4:3)
Block(5,43,-8,biomesoplenty:leaves_4:3)
Block(-7,49,-1,biomesoplenty:leaves_4:3)
Block(5,42,-8,biomesoplenty:leaves_4:3)
Block(-7,48,-1,biomesoplenty:leaves_4:3)
Block(5,49,-8,biomesoplenty:leaves_4:3)
Block(5,48,-8,biomesoplenty:leaves_4:3)
Block(5,47,-8,biomesoplenty:leaves_4:3)
Block(5,46,-8,biomesoplenty:leaves_4:3)
Block(13,49,-6,biomesoplenty:leaves_4:3)
Block(13,48,-6,biomesoplenty:leaves_4:3)
Block(13,45,-6,biomesoplenty:leaves_4:3)
Block(13,44,-6,biomesoplenty:leaves_4:3)
Block(13,43,-6,biomesoplenty:leaves_4:3)
Block(13,42,-6,biomesoplenty:leaves_4:3)
Block(13,41,-6,biomesoplenty:leaves_4:3)
Block(13,40,-6,biomesoplenty:leaves_4:3)
Block(-13,40,12,biomesoplenty:leaves_4:3)
Block(-13,41,12,biomesoplenty:leaves_4:3)
Block(15,44,5,biomesoplenty:leaves_4:3)
Block(15,41,5,biomesoplenty:leaves_4:3)
Block(-18,41,-10,biomesoplenty:leaves_4:3)
Block(-18,40,-10,biomesoplenty:leaves_4:3)
Block(15,40,5,biomesoplenty:leaves_4:3)
Block(1,45,13,biomesoplenty:leaves_4:3)
Block(4,50,-2,biomesoplenty:leaves_4:3)
Block(4,51,-2,biomesoplenty:leaves_4:3)
Block(19,41,2,biomesoplenty:leaves_4:3)
Block(1,48,13,biomesoplenty:leaves_4:3)
Block(-8,41,-7,biomesoplenty:leaves_4:3)
Block(19,43,2,biomesoplenty:leaves_4:3)
Block(15,47,5,biomesoplenty:leaves_4:3)
Block(-8,42,-7,biomesoplenty:leaves_4:3)
Block(17,42,9,biomesoplenty:leaves_4:3)
Block(15,45,5,biomesoplenty:leaves_4:3)
Block(-8,40,-7,biomesoplenty:leaves_4:3)
Block(17,40,9,biomesoplenty:leaves_4:3)
Block(19,44,2,biomesoplenty:leaves_4:3)
Block(15,46,5,biomesoplenty:leaves_4:3)
Block(17,43,9,biomesoplenty:leaves_4:3)
Block(1,40,13,biomesoplenty:leaves_4:3)
Block(1,41,13,biomesoplenty:leaves_4:3)
Block(1,42,13,biomesoplenty:leaves_4:3)
Block(1,43,13,biomesoplenty:leaves_4:3)
Block(1,44,13,biomesoplenty:leaves_4:3)
Block(2,50,0,biomesoplenty:log_2:5)
Block(2,51,0,biomesoplenty:leaves_4:3)
Block(-4,43,1,biomesoplenty:leaves_4:3)
Block(-4,42,1,biomesoplenty:log_2:5)
Block(-4,40,1,biomesoplenty:leaves_4:3)
Block(-8,46,-13,biomesoplenty:leaves_4:3)
Block(-1,-4,-3,biomesoplenty:log_2:5)
Block(-1,-3,-3,biomesoplenty:log_2:5)
Block(-8,43,-13,biomesoplenty:leaves_4:3)
Block(-8,42,-13,biomesoplenty:leaves_4:3)
Block(-8,41,-13,biomesoplenty:leaves_4:3)
Block(-14,45,6,biomesoplenty:leaves_4:3)
Block(-8,40,-13,biomesoplenty:leaves_4:3)
Block(-14,44,6,biomesoplenty:leaves_4:3)
Block(-14,43,6,biomesoplenty:leaves_4:3)
Block(-14,42,6,biomesoplenty:leaves_4:3)
Block(-3,48,-11,biomesoplenty:leaves_4:3)
Block(-3,47,-11,biomesoplenty:leaves_4:3)
Block(-3,40,-11,biomesoplenty:leaves_4:3)
Block(-3,42,-11,biomesoplenty:leaves_4:3)
Block(-3,41,-11,biomesoplenty:leaves_4:3)
Block(2,35,0,biomesoplenty:log_2:5)
Block(-3,44,-11,biomesoplenty:leaves_4:3)
Block(-5,48,3,biomesoplenty:leaves_4:3)
Block(-5,47,3,biomesoplenty:leaves_4:3)
Block(-3,46,-11,biomesoplenty:leaves_4:3)
Block(-3,45,-11,biomesoplenty:leaves_4:3)
Block(-5,49,3,biomesoplenty:leaves_4:3)
Block(-5,51,3,biomesoplenty:leaves_4:3)
Block(-5,50,3,biomesoplenty:log_2:5)
Block(6,51,-3,biomesoplenty:leaves_4:3)
Block(6,50,-3,biomesoplenty:leaves_4:3)
Block(2,43,0,biomesoplenty:leaves_4:3)
Block(2,44,0,biomesoplenty:leaves_4:3)
Block(6,49,-3,biomesoplenty:leaves_4:3)
Block(2,45,0,biomesoplenty:leaves_4:3)
Block(6,48,-3,biomesoplenty:log_2:5)
Block(6,47,-3,biomesoplenty:leaves_4:3)
Block(6,46,-3,biomesoplenty:leaves_4:3)
Block(2,40,0,biomesoplenty:leaves_4:3)
Block(6,45,-3,biomesoplenty:log_2:5)
Block(2,41,0,biomesoplenty:leaves_4:3)
Block(6,44,-3,biomesoplenty:leaves_4:3)
Block(-18,42,-2,biomesoplenty:leaves_4:3)
Block(-18,43,-2,biomesoplenty:leaves_4:3)
Block(-18,44,-2,biomesoplenty:leaves_4:3)
Block(-4,51,1,biomesoplenty:leaves_4:3)
Block(2,46,0,biomesoplenty:leaves_4:3)
Block(-4,50,1,biomesoplenty:log_2:5)
Block(2,47,0,biomesoplenty:leaves_4:3)
Block(2,48,0,biomesoplenty:leaves_4:3)
Block(2,49,0,biomesoplenty:leaves_4:3)
Block(-5,44,3,biomesoplenty:leaves_4:3)
Block(-5,43,3,biomesoplenty:log_2:5)
Block(-5,46,3,biomesoplenty:log_2:5)
Block(-4,49,1,biomesoplenty:log_2:5)
Block(-5,45,3,biomesoplenty:leaves_4:3)
Block(-4,48,1,biomesoplenty:leaves_4:3)
Block(-5,40,3,biomesoplenty:leaves_4:3)
Block(-18,45,-2,biomesoplenty:leaves_4:3)
Block(-4,47,1,biomesoplenty:leaves_4:3)
Block(-4,46,1,biomesoplenty:leaves_4:3)
Block(-5,42,3,biomesoplenty:log_2:5)
Block(-4,45,1,biomesoplenty:log_2:5)
Block(-5,41,3,biomesoplenty:leaves_4:3)
Block(-4,44,1,biomesoplenty:leaves_4:3)
Block(6,43,-3,biomesoplenty:leaves_4:3)
Block(6,42,-3,biomesoplenty:leaves_4:3)
Block(6,41,-3,biomesoplenty:leaves_4:3)
Block(6,40,-3,biomesoplenty:leaves_4:3)
Block(-6,41,13,biomesoplenty:leaves_4:3)
Block(-13,44,-5,biomesoplenty:leaves_4:3)
Block(-6,42,13,biomesoplenty:leaves_4:3)
Block(-13,43,-5,biomesoplenty:leaves_4:3)
Block(-13,42,-5,biomesoplenty:leaves_4:3)
Block(-6,43,13,biomesoplenty:leaves_4:3)
Block(16,46,7,biomesoplenty:leaves_4:3)
Block(-13,41,-5,biomesoplenty:leaves_4:3)
Block(-6,44,13,biomesoplenty:leaves_4:3)
Block(16,40,7,biomesoplenty:log_2:5)
Block(3,40,2,biomesoplenty:leaves_4:3)
Block(16,41,7,biomesoplenty:leaves_4:3)
Block(9,41,-21,biomesoplenty:leaves_4:3)
Block(16,42,7,biomesoplenty:leaves_4:3)
Block(-6,40,13,biomesoplenty:leaves_4:3)
Block(9,42,-21,biomesoplenty:leaves_4:3)
Block(-6,46,13,biomesoplenty:leaves_4:3)
Block(-13,46,-5,biomesoplenty:leaves_4:3)
Block(-6,47,13,biomesoplenty:leaves_4:3)
Block(-13,45,-5,biomesoplenty:leaves_4:3)
Block(1,45,-6,biomesoplenty:leaves_4:3)
Block(1,44,-6,biomesoplenty:log_2:5)
Block(1,47,-6,biomesoplenty:leaves_4:3)
Block(3,49,2,biomesoplenty:leaves_4:3)
Block(1,46,-6,biomesoplenty:log_2:5)
Block(1,49,-6,biomesoplenty:log_2:5)
Block(1,48,-6,biomesoplenty:log_2:5)
Block(3,43,2,biomesoplenty:leaves_4:3)
Block(3,44,2,biomesoplenty:leaves_4:3)
Block(3,41,2,biomesoplenty:leaves_4:3)
Block(3,42,2,biomesoplenty:leaves_4:3)
Block(1,41,-6,biomesoplenty:leaves_4:3)
Block(3,47,2,biomesoplenty:leaves_4:3)
Block(1,40,-6,biomesoplenty:leaves_4:3)
Block(3,48,2,biomesoplenty:leaves_4:3)
Block(1,43,-6,biomesoplenty:leaves_4:3)
Block(3,45,2,biomesoplenty:leaves_4:3)
Block(1,42,-6,biomesoplenty:leaves_4:3)
Block(3,46,2,biomesoplenty:leaves_4:3)
Block(11,43,-5,biomesoplenty:leaves_4:3)
Block(3,50,2,biomesoplenty:leaves_4:3)
Block(11,42,-5,biomesoplenty:leaves_4:3)
Block(3,51,2,biomesoplenty:leaves_4:3)
Block(11,41,-5,biomesoplenty:log_2:5)
Block(11,40,-5,biomesoplenty:leaves_4:3)
Block(11,47,-5,biomesoplenty:leaves_4:3)
Block(11,44,-5,biomesoplenty:leaves_4:3)
Block(11,49,-5,biomesoplenty:leaves_4:3)
Block(11,48,-5,biomesoplenty:leaves_4:3)
Block(-8,41,14,biomesoplenty:leaves_4:3)
Block(-8,40,14,biomesoplenty:log_2:5)
Block(-8,43,14,biomesoplenty:leaves_4:3)
Block(-12,42,-13,biomesoplenty:leaves_4:3)
Block(-12,41,-13,biomesoplenty:leaves_4:3)
Block(16,40,-2,biomesoplenty:leaves_4:3)
Block(16,42,-2,biomesoplenty:leaves_4:3)
Block(16,43,-2,biomesoplenty:leaves_4:3)
Block(13,40,-21,biomesoplenty:leaves_4:3)
Block(16,44,-2,biomesoplenty:leaves_4:3)
Block(16,45,-2,biomesoplenty:leaves_4:3)
Block(1,50,-6,biomesoplenty:log_2:5)
Block(1,51,-6,biomesoplenty:leaves_4:3)
Block(2,-3,0,biomesoplenty:log_2:5)
Block(2,-4,0,biomesoplenty:log_2:5)
Block(-1,47,-3,biomesoplenty:leaves_4:3)
Block(-1,46,-3,biomesoplenty:leaves_4:3)
Block(2,-1,0,biomesoplenty:log_2:5)
Block(-1,49,-3,biomesoplenty:leaves_4:3)
Block(2,-2,0,biomesoplenty:log_2:5)
Block(-1,48,-3,biomesoplenty:leaves_4:3)
Block(-1,50,-3,biomesoplenty:log_2:5)
Block(-1,51,-3,biomesoplenty:leaves_4:3)
Block(17,43,-8,biomesoplenty:leaves_4:3)
Block(2,-4,-1,biomesoplenty:log_2:5)
Block(2,-3,-1,biomesoplenty:log_2:5)
Block(8,40,-4,biomesoplenty:leaves_4:3)
Block(8,41,-4,biomesoplenty:leaves_4:3)
Block(8,42,-4,biomesoplenty:log_2:5)
Block(4,40,4,biomesoplenty:leaves_4:3)
Block(4,41,4,biomesoplenty:leaves_4:3)
Block(2,-2,-1,biomesoplenty:log_2:5)
Block(4,42,4,biomesoplenty:leaves_4:3)
Block(2,-1,-1,biomesoplenty:log_2:5)
Block(4,43,4,biomesoplenty:leaves_4:3)
Block(4,44,4,biomesoplenty:leaves_4:3)
Block(8,47,-4,biomesoplenty:leaves_4:3)
Block(4,45,4,biomesoplenty:leaves_4:3)
Block(8,48,-4,biomesoplenty:leaves_4:3)
Block(4,46,4,biomesoplenty:leaves_4:3)
Block(8,49,-4,biomesoplenty:log_2:5)
Block(4,47,4,biomesoplenty:leaves_4:3)
Block(8,43,-4,biomesoplenty:leaves_4:3)
Block(4,48,4,biomesoplenty:leaves_4:3)
Block(8,44,-4,biomesoplenty:leaves_4:3)
Block(4,49,4,biomesoplenty:leaves_4:3)
Block(8,45,-4,biomesoplenty:leaves_4:3)
Block(8,46,-4,biomesoplenty:leaves_4:3)
Block(-1,29,-3,biomesoplenty:log_2:5)
Block(8,50,-4,biomesoplenty:leaves_4:3)
Block(-1,28,-3,biomesoplenty:log_2:5)
Block(10,42,-20,biomesoplenty:leaves_4:3)
Block(10,41,-20,biomesoplenty:log_2:5)
Block(-14,42,-14,biomesoplenty:leaves_4:3)
Block(-1,34,-3,biomesoplenty:log_2:5)
Block(-14,41,-14,biomesoplenty:leaves_4:3)
Block(-6,40,5,biomesoplenty:leaves_4:3)
Block(-6,41,5,biomesoplenty:leaves_4:3)
Block(-6,44,5,biomesoplenty:leaves_4:3)
Block(-6,45,5,biomesoplenty:leaves_4:3)
Block(-6,42,5,biomesoplenty:leaves_4:3)
Block(-6,43,5,biomesoplenty:leaves_4:3)
Block(-6,48,5,biomesoplenty:leaves_4:3)
Block(-6,49,5,biomesoplenty:leaves_4:3)
Block(-6,46,5,biomesoplenty:leaves_4:3)
Block(-6,47,5,biomesoplenty:log_2:5)
Block(1,49,-11,biomesoplenty:leaves_4:3)
Block(1,48,-11,biomesoplenty:leaves_4:3)
Block(1,47,-11,biomesoplenty:log_2:5)
Block(1,46,-11,biomesoplenty:leaves_4:3)
Block(1,45,-11,biomesoplenty:leaves_4:3)
Block(1,44,-11,biomesoplenty:log_2:5)
Block(1,43,-11,biomesoplenty:log_2:5)
Block(1,42,-11,biomesoplenty:log_2:5)
Block(-3,40,17,biomesoplenty:leaves_4:3)
Block(1,41,-11,biomesoplenty:leaves_4:3)
Block(1,40,-11,biomesoplenty:leaves_4:3)
Block(-1,35,-3,biomesoplenty:log_2:5)
Block(-1,38,-3,biomesoplenty:log_2:5)
Block(-1,43,-3,biomesoplenty:log_2:5)
Block(-1,42,-3,biomesoplenty:leaves_4:3)
Block(-1,45,-3,biomesoplenty:leaves_4:3)
Block(-1,44,-3,biomesoplenty:leaves_4:3)
Block(-1,41,-3,biomesoplenty:leaves_4:3)
Block(-1,40,-3,biomesoplenty:leaves_4:3)
Block(-2,41,-9,biomesoplenty:leaves_4:3)
Block(6,45,8,biomesoplenty:leaves_4:3)
Block(-2,42,-9,biomesoplenty:leaves_4:3)
Block(6,44,8,biomesoplenty:leaves_4:3)
Block(6,43,8,biomesoplenty:leaves_4:3)
Block(-2,40,-9,biomesoplenty:leaves_4:3)
Block(6,42,8,biomesoplenty:leaves_4:3)
Block(6,48,8,biomesoplenty:leaves_4:3)
Block(6,47,8,biomesoplenty:leaves_4:3)
Block(6,46,8,biomesoplenty:leaves_4:3)
Block(-2,49,-9,biomesoplenty:leaves_4:3)
Block(-2,47,-9,biomesoplenty:leaves_4:3)
Block(-2,48,-9,biomesoplenty:log_2:5)
Block(6,41,8,biomesoplenty:leaves_4:3)
Block(-2,46,-9,biomesoplenty:leaves_4:3)
Block(-2,43,-9,biomesoplenty:leaves_4:3)
Block(-2,44,-9,biomesoplenty:leaves_4:3)
Block(-4,46,12,biomesoplenty:leaves_4:3)
Block(-4,47,12,biomesoplenty:leaves_4:3)
Block(-4,48,12,biomesoplenty:leaves_4:3)
Block(-11,47,-4,biomesoplenty:leaves_4:3)
Block(-11,41,-4,biomesoplenty:leaves_4:3)
Block(-4,41,12,biomesoplenty:leaves_4:3)
Block(-4,42,12,biomesoplenty:leaves_4:3)
Block(-11,44,-4,biomesoplenty:leaves_4:3)
Block(-4,43,12,biomesoplenty:leaves_4:3)
Block(-11,45,-4,biomesoplenty:leaves_4:3)
Block(-11,42,-4,biomesoplenty:log_2:5)
Block(-11,43,-4,biomesoplenty:leaves_4:3)
Block(-4,45,12,biomesoplenty:leaves_4:3)
Block(13,47,1,biomesoplenty:leaves_4:3)
Block(-6,50,5,biomesoplenty:leaves_4:3)
Block(13,42,1,biomesoplenty:leaves_4:3)
Block(-8,46,9,biomesoplenty:leaves_4:3)
Block(13,41,1,biomesoplenty:leaves_4:3)
Block(13,40,1,biomesoplenty:leaves_4:3)
Block(-8,44,9,biomesoplenty:leaves_4:3)
Block(-8,45,9,biomesoplenty:log_2:5)
Block(-8,42,9,biomesoplenty:leaves_4:3)
Block(13,46,1,biomesoplenty:leaves_4:3)
Block(-8,43,9,biomesoplenty:leaves_4:3)
Block(13,45,1,biomesoplenty:leaves_4:3)
Block(13,44,1,biomesoplenty:leaves_4:3)
Block(-8,41,9,biomesoplenty:leaves_4:3)
Block(13,43,1,biomesoplenty:log_2:5)
Block(4,50,4,biomesoplenty:leaves_4:3)
Block(4,51,4,biomesoplenty:leaves_4:3)
Block(10,42,-19,biomesoplenty:leaves_4:3)
Block(10,41,-19,biomesoplenty:leaves_4:3)
Block(-2,50,-9,biomesoplenty:leaves_4:3)
Block(-2,51,-9,biomesoplenty:leaves_4:3)
Block(8,41,-14,biomesoplenty:log_2:5)
Block(8,42,-14,biomesoplenty:leaves_4:3)
Block(8,43,-14,biomesoplenty:leaves_4:3)
Block(6,51,8,biomesoplenty:leaves_4:3)
Block(6,50,8,biomesoplenty:leaves_4:3)
Block(8,44,-14,biomesoplenty:leaves_4:3)
Block(8,45,-14,biomesoplenty:log_2:5)
Block(8,46,-14,biomesoplenty:leaves_4:3)
Block(7,43,-19,biomesoplenty:leaves_4:3)
Block(-1,51,-10,biomesoplenty:leaves_4:3)
Block(7,42,-19,biomesoplenty:leaves_4:3)
Block(-1,50,-10,biomesoplenty:leaves_4:3)
Block(2,47,-1,biomesoplenty:leaves_4:3)
Block(7,49,4,biomesoplenty:log_2:5)
Block(2,46,-1,biomesoplenty:leaves_4:3)
Block(7,47,4,biomesoplenty:leaves_4:3)
Block(2,49,-1,biomesoplenty:leaves_4:3)
Block(2,48,-1,biomesoplenty:leaves_4:3)
Block(7,48,4,biomesoplenty:leaves_4:3)
Block(2,43,-1,biomesoplenty:log_2:5)
Block(7,45,4,biomesoplenty:leaves_4:3)
Block(7,46,4,biomesoplenty:leaves_4:3)
Block(-9,40,5,biomesoplenty:leaves_4:3)
Block(7,43,4,biomesoplenty:leaves_4:3)
Block(2,45,-1,biomesoplenty:leaves_4:3)
Block(7,44,4,biomesoplenty:leaves_4:3)
Block(7,41,4,biomesoplenty:leaves_4:3)
Block(-9,42,5,biomesoplenty:leaves_4:3)
Block(7,42,4,biomesoplenty:leaves_4:3)
Block(-9,44,5,biomesoplenty:leaves_4:3)
Block(2,40,-1,biomesoplenty:log_2:5)
Block(7,40,4,biomesoplenty:leaves_4:3)
Block(-9,43,5,biomesoplenty:leaves_4:3)
Block(-9,46,5,biomesoplenty:leaves_4:3)
Block(-9,45,5,biomesoplenty:leaves_4:3)
Block(-22,41,-10,biomesoplenty:leaves_4:3)
Block(-22,40,-10,biomesoplenty:leaves_4:3)
Block(-9,49,5,biomesoplenty:leaves_4:3)
Block(8,47,11,biomesoplenty:leaves_4:3)
Block(8,46,11,biomesoplenty:leaves_4:3)
Block(8,45,11,biomesoplenty:leaves_4:3)
Block(8,44,11,biomesoplenty:log_2:5)
Block(7,43,-20,biomesoplenty:leaves_4:3)
Block(7,42,-20,biomesoplenty:log_2:5)
Block(8,48,11,biomesoplenty:leaves_4:3)
Block(8,43,11,biomesoplenty:leaves_4:3)
Block(8,42,11,biomesoplenty:leaves_4:3)
Block(8,41,11,biomesoplenty:leaves_4:3)
Block(8,40,11,biomesoplenty:leaves_4:3)
Block(-9,50,5,biomesoplenty:leaves_4:3)
Block(2,50,-1,biomesoplenty:leaves_4:3)
Block(7,50,4,biomesoplenty:leaves_4:3)
Block(2,51,-1,biomesoplenty:leaves_4:3)
Block(5,42,15,biomesoplenty:leaves_4:3)
Block(1,42,9,biomesoplenty:leaves_4:3)
Block(1,43,9,biomesoplenty:leaves_4:3)
Block(5,-3,0,biomesoplenty:log_2:5)
Block(1,44,9,biomesoplenty:leaves_4:3)
Block(1,45,9,biomesoplenty:leaves_4:3)
Block(2,40,-17,biomesoplenty:leaves_4:3)
Block(1,40,9,biomesoplenty:leaves_4:3)
Block(1,41,9,biomesoplenty:leaves_4:3)
Block(2,44,-17,biomesoplenty:leaves_4:3)
Block(2,43,-17,biomesoplenty:leaves_4:3)
Block(2,42,-17,biomesoplenty:leaves_4:3)
Block(2,41,-17,biomesoplenty:leaves_4:3)
Block(1,46,9,biomesoplenty:leaves_4:3)
Block(1,47,9,biomesoplenty:leaves_4:3)
Block(1,48,9,biomesoplenty:leaves_4:3)
Block(5,50,-8,biomesoplenty:leaves_4:3)
Block(10,49,6,biomesoplenty:leaves_4:3)
Block(1,49,9,biomesoplenty:leaves_4:3)
Block(5,45,15,biomesoplenty:leaves_4:3)
Block(10,48,6,biomesoplenty:leaves_4:3)
Block(10,47,6,biomesoplenty:leaves_4:3)
Block(5,43,15,biomesoplenty:leaves_4:3)
Block(10,46,6,biomesoplenty:leaves_4:3)
Block(5,44,15,biomesoplenty:leaves_4:3)
Block(10,45,6,biomesoplenty:leaves_4:3)
Block(14,41,-15,biomesoplenty:leaves_4:3)
Block(10,44,6,biomesoplenty:leaves_4:3)
Block(14,40,-15,biomesoplenty:leaves_4:3)
Block(10,43,6,biomesoplenty:log_2:5)
Block(10,42,6,biomesoplenty:leaves_4:3)
Block(10,41,6,biomesoplenty:log_2:5)
Block(-1,42,-10,biomesoplenty:leaves_4:3)
Block(-1,43,-10,biomesoplenty:leaves_4:3)
Block(-1,40,-10,biomesoplenty:log_2:5)
Block(-1,41,-10,biomesoplenty:leaves_4:3)
Block(-1,48,-10,biomesoplenty:leaves_4:3)
Block(-1,49,-10,biomesoplenty:leaves_4:3)
Block(-1,46,-10,biomesoplenty:leaves_4:3)
Block(-1,47,-10,biomesoplenty:leaves_4:3)
Block(-1,44,-10,biomesoplenty:leaves_4:3)
Block(-1,45,-10,biomesoplenty:leaves_4:3)
Block(1,39,9,biomesoplenty:log_2:5)
Block(9,51,3,biomesoplenty:leaves_4:3)
Block(9,50,3,biomesoplenty:leaves_4:3)
Block(-6,40,-12,biomesoplenty:leaves_4:3)
Block(-6,42,-12,biomesoplenty:leaves_4:3)
Block(-6,41,-12,biomesoplenty:leaves_4:3)
Block(-1,43,10,biomesoplenty:leaves_4:3)
Block(-1,44,10,biomesoplenty:leaves_4:3)
Block(-1,45,10,biomesoplenty:leaves_4:3)
Block(-4,39,-5,biomesoplenty:log_2:5)
Block(-1,40,10,biomesoplenty:leaves_4:3)
Block(-1,41,10,biomesoplenty:log_2:5)
Block(-1,42,10,biomesoplenty:leaves_4:3)
Block(2,17,-1,biomesoplenty:log_2:5)
Block(2,14,-1,biomesoplenty:log_2:5)
Block(-1,47,10,biomesoplenty:leaves_4:3)
Block(2,13,-1,biomesoplenty:log_2:5)
Block(-1,48,10,biomesoplenty:leaves_4:3)
Block(1,50,9,biomesoplenty:leaves_4:3)
Block(2,16,-1,biomesoplenty:log_2:5)
Block(-1,49,10,biomesoplenty:leaves_4:3)
Block(2,15,-1,biomesoplenty:log_2:5)
Block(2,10,-1,biomesoplenty:log_2:5)
Block(2,12,-1,biomesoplenty:log_2:5)
Block(2,11,-1,biomesoplenty:log_2:5)
Block(-4,40,-5,biomesoplenty:log_2:5)
Block(-4,42,-5,biomesoplenty:leaves_4:3)
Block(-4,41,-5,biomesoplenty:leaves_4:3)
Block(-4,44,-5,biomesoplenty:leaves_4:3)
Block(-4,43,-5,biomesoplenty:leaves_4:3)
Block(-4,46,-5,biomesoplenty:leaves_4:3)
Block(-4,45,-5,biomesoplenty:leaves_4:3)
Block(18,44,0,biomesoplenty:leaves_4:3)
Block(-4,48,-5,biomesoplenty:leaves_4:3)
Block(18,43,0,biomesoplenty:leaves_4:3)
Block(-4,47,-5,biomesoplenty:leaves_4:3)
Block(-1,50,10,biomesoplenty:leaves_4:3)
Block(-4,49,-5,biomesoplenty:leaves_4:3)
Block(2,22,-1,biomesoplenty:log_2:5)
Block(-17,45,1,biomesoplenty:leaves_4:3)
Block(-17,44,1,biomesoplenty:leaves_4:3)
Block(-4,51,-5,biomesoplenty:leaves_4:3)
Block(-4,50,-5,biomesoplenty:leaves_4:3)
Block(9,40,3,biomesoplenty:leaves_4:3)
Block(9,41,3,biomesoplenty:log_2:5)
Block(9,42,3,biomesoplenty:leaves_4:3)
Block(9,43,3,biomesoplenty:leaves_4:3)
Block(9,44,3,biomesoplenty:leaves_4:3)
Block(9,45,3,biomesoplenty:log_2:5)
Block(9,46,3,biomesoplenty:leaves_4:3)
Block(9,47,3,biomesoplenty:log_2:5)
Block(13,42,13,biomesoplenty:leaves_4:3)
Block(12,43,5,biomesoplenty:leaves_4:3)
Block(-6,47,-12,biomesoplenty:leaves_4:3)
Block(12,44,5,biomesoplenty:leaves_4:3)
Block(13,41,13,biomesoplenty:leaves_4:3)
Block(12,45,5,biomesoplenty:leaves_4:3)
Block(12,46,5,biomesoplenty:leaves_4:3)
Block(12,47,5,biomesoplenty:leaves_4:3)
Block(12,48,5,biomesoplenty:leaves_4:3)
Block(2,37,-1,biomesoplenty:log_2:5)
Block(2,32,-1,biomesoplenty:log_2:5)
Block(2,30,-1,biomesoplenty:log_2:5)
Block(9,48,3,biomesoplenty:leaves_4:3)
Block(9,49,3,biomesoplenty:leaves_4:3)
Block(18,42,0,biomesoplenty:leaves_4:3)
Block(18,41,0,biomesoplenty:leaves_4:3)
Block(18,40,0,biomesoplenty:leaves_4:3)
Block(-16,43,4,biomesoplenty:leaves_4:3)
Block(-16,44,4,biomesoplenty:leaves_4:3)
Block(4,43,9,biomesoplenty:leaves_4:3)
Block(17,42,-3,biomesoplenty:leaves_4:3)
Block(4,44,9,biomesoplenty:log_2:5)
Block(4,41,9,biomesoplenty:leaves_4:3)
Block(17,40,-3,biomesoplenty:leaves_4:3)
Block(4,47,9,biomesoplenty:leaves_4:3)
Block(4,48,9,biomesoplenty:leaves_4:3)
Block(4,45,9,biomesoplenty:leaves_4:3)
Block(4,46,9,biomesoplenty:leaves_4:3)
Block(10,42,-13,biomesoplenty:leaves_4:3)
Block(10,43,-13,biomesoplenty:leaves_4:3)
Block(10,44,-13,biomesoplenty:leaves_4:3)
Block(4,49,9,biomesoplenty:leaves_4:3)
Block(10,45,-13,biomesoplenty:leaves_4:3)
Block(12,41,5,biomesoplenty:leaves_4:3)
Block(-5,43,-5,biomesoplenty:leaves_4:3)
Block(-5,42,-5,biomesoplenty:leaves_4:3)
Block(-5,41,-5,biomesoplenty:leaves_4:3)
Block(-5,40,-5,biomesoplenty:leaves_4:3)
Block(6,42,16,biomesoplenty:leaves_4:3)
Block(10,41,-13,biomesoplenty:leaves_4:3)
Block(10,50,-4,biomesoplenty:leaves_4:3)
Block(10,48,-4,biomesoplenty:leaves_4:3)
Block(10,49,-4,biomesoplenty:leaves_4:3)
Block(10,44,-4,biomesoplenty:leaves_4:3)
Block(10,45,-4,biomesoplenty:leaves_4:3)
Block(10,46,-4,biomesoplenty:leaves_4:3)
Block(10,47,-4,biomesoplenty:leaves_4:3)
Block(10,40,-4,biomesoplenty:leaves_4:3)
Block(10,41,-4,biomesoplenty:leaves_4:3)
Block(10,42,-4,biomesoplenty:leaves_4:3)
Block(10,43,-4,biomesoplenty:leaves_4:3)
Block(-3,41,11,biomesoplenty:leaves_4:3)
Block(0,43,-5,biomesoplenty:leaves_4:3)
Block(-3,43,11,biomesoplenty:leaves_4:3)
Block(0,42,-5,biomesoplenty:leaves_4:3)
Block(-3,42,11,biomesoplenty:leaves_4:3)
Block(0,41,-5,biomesoplenty:leaves_4:3)
Block(-3,45,11,biomesoplenty:leaves_4:3)
Block(0,40,-5,biomesoplenty:leaves_4:3)
Block(-3,44,11,biomesoplenty:leaves_4:3)
Block(0,47,-5,biomesoplenty:leaves_4:3)
Block(-3,47,11,biomesoplenty:log_2:5)
Block(0,46,-5,biomesoplenty:leaves_4:3)
Block(0,45,-5,biomesoplenty:leaves_4:3)
Block(0,44,-5,biomesoplenty:leaves_4:3)
Block(-3,48,11,biomesoplenty:leaves_4:3)
Block(0,49,-5,biomesoplenty:log_2:5)
Block(0,48,-5,biomesoplenty:leaves_4:3)
Block(3,42,7,biomesoplenty:leaves_4:3)
Block(0,40,12,biomesoplenty:leaves_4:3)
Block(3,43,7,biomesoplenty:log_2:5)
Block(3,44,7,biomesoplenty:leaves_4:3)
Block(3,45,7,biomesoplenty:leaves_4:3)
Block(0,43,12,biomesoplenty:leaves_4:3)
Block(0,44,12,biomesoplenty:leaves_4:3)
Block(0,41,12,biomesoplenty:log_2:5)
Block(3,41,7,biomesoplenty:leaves_4:3)
Block(0,42,12,biomesoplenty:leaves_4:3)
Block(0,50,-5,biomesoplenty:log_2:5)
Block(-13,41,-13,biomesoplenty:leaves_4:3)
Block(17,45,-3,biomesoplenty:leaves_4:3)
Block(17,44,-3,biomesoplenty:leaves_4:3)
Block(0,51,-5,biomesoplenty:leaves_4:3)
Block(0,48,12,biomesoplenty:leaves_4:3)
Block(0,45,12,biomesoplenty:leaves_4:3)
Block(-13,42,-13,biomesoplenty:leaves_4:3)
Block(3,46,7,biomesoplenty:leaves_4:3)
Block(3,47,7,biomesoplenty:leaves_4:3)
Block(3,48,7,biomesoplenty:leaves_4:3)
Block(0,49,12,biomesoplenty:leaves_4:3)
Block(3,49,7,biomesoplenty:leaves_4:3)
Block(-2,30,-4,biomesoplenty:log_2:5)
Block(-19,40,10,biomesoplenty:leaves_4:3)
Block(11,41,3,biomesoplenty:leaves_4:3)
Block(-19,41,10,biomesoplenty:leaves_4:3)
Block(11,42,3,biomesoplenty:leaves_4:3)
Block(-5,49,8,biomesoplenty:leaves_4:3)
Block(11,40,3,biomesoplenty:leaves_4:3)
Block(-5,48,8,biomesoplenty:leaves_4:3)
Block(11,45,3,biomesoplenty:leaves_4:3)
Block(-5,47,8,biomesoplenty:leaves_4:3)
Block(11,46,3,biomesoplenty:log_2:5)
Block(-5,46,8,biomesoplenty:leaves_4:3)
Block(-5,45,8,biomesoplenty:leaves_4:3)
Block(-5,44,8,biomesoplenty:leaves_4:3)
Block(10,40,11,biomesoplenty:leaves_4:3)
Block(-5,43,8,biomesoplenty:leaves_4:3)
Block(11,49,3,biomesoplenty:leaves_4:3)
Block(-5,42,8,biomesoplenty:leaves_4:3)
Block(-5,41,8,biomesoplenty:leaves_4:3)
Block(11,47,3,biomesoplenty:leaves_4:3)
Block(-5,40,8,biomesoplenty:leaves_4:3)
Block(11,48,3,biomesoplenty:leaves_4:3)
Block(10,44,11,biomesoplenty:leaves_4:3)
Block(10,43,11,biomesoplenty:leaves_4:3)
Block(10,42,11,biomesoplenty:leaves_4:3)
Block(10,41,11,biomesoplenty:leaves_4:3)
Block(-9,40,15,biomesoplenty:leaves_4:3)
Block(-9,41,15,biomesoplenty:leaves_4:3)
Block(0,37,-5,biomesoplenty:log_2:5)
Block(-2,50,-4,biomesoplenty:leaves_4:3)
Block(-2,51,-4,biomesoplenty:leaves_4:3)
Block(6,45,-13,biomesoplenty:leaves_4:3)
Block(6,43,-13,biomesoplenty:leaves_4:3)
Block(-2,46,-4,biomesoplenty:leaves_4:3)
Block(6,44,-13,biomesoplenty:leaves_4:3)
Block(-2,47,-4,biomesoplenty:log_2:5)
Block(6,41,-13,biomesoplenty:log_2:5)
Block(-2,48,-4,biomesoplenty:leaves_4:3)
Block(6,42,-13,biomesoplenty:leaves_4:3)
Block(-2,49,-4,biomesoplenty:log_2:5)
Block(10,47,11,biomesoplenty:leaves_4:3)
Block(10,46,11,biomesoplenty:leaves_4:3)
Block(10,45,11,biomesoplenty:leaves_4:3)
Block(-2,42,-4,biomesoplenty:leaves_4:3)
Block(-2,43,-4,biomesoplenty:leaves_4:3)
Block(-2,44,-4,biomesoplenty:leaves_4:3)
Block(-2,45,-4,biomesoplenty:leaves_4:3)
Block(-2,40,-4,biomesoplenty:log_2:5)
Block(-2,41,-4,biomesoplenty:leaves_4:3)
Block(-2,39,-4,biomesoplenty:log_2:5)
Block(11,50,3,biomesoplenty:leaves_4:3)
Block(-5,41,-17,biomesoplenty:leaves_4:3)
Block(-2,36,-4,biomesoplenty:log_2:5)
Block(-5,42,-17,biomesoplenty:leaves_4:3)
Block(-5,40,-17,biomesoplenty:leaves_4:3)
Block(15,44,0,biomesoplenty:leaves_4:3)
Block(15,46,0,biomesoplenty:leaves_4:3)
Block(15,47,0,biomesoplenty:leaves_4:3)
Block(15,40,0,biomesoplenty:leaves_4:3)
Block(15,41,0,biomesoplenty:leaves_4:3)
Block(15,42,0,biomesoplenty:leaves_4:3)
Block(15,43,0,biomesoplenty:leaves_4:3)
Block(9,50,-5,biomesoplenty:leaves_4:3)
Block(10,51,1,biomesoplenty:leaves_4:3)
Block(10,50,1,biomesoplenty:leaves_4:3)
Block(18,40,-11,biomesoplenty:leaves_4:3)
Block(18,41,-11,biomesoplenty:leaves_4:3)
Block(18,43,-11,biomesoplenty:leaves_4:3)
Block(9,42,-5,biomesoplenty:leaves_4:3)
Block(2,50,-6,biomesoplenty:leaves_4:3)
Block(9,41,-5,biomesoplenty:leaves_4:3)
Block(2,51,-6,biomesoplenty:leaves_4:3)
Block(9,40,-5,biomesoplenty:leaves_4:3)
Block(-17,44,-2,biomesoplenty:leaves_4:3)
Block(10,48,1,biomesoplenty:leaves_4:3)
Block(-1,-2,0,biomesoplenty:log_2:5)
Block(-17,45,-2,biomesoplenty:leaves_4:3)
Block(10,49,1,biomesoplenty:leaves_4:3)
Block(-1,-3,0,biomesoplenty:log_2:5)
Block(0,40,-16,biomesoplenty:leaves_4:3)
Block(-17,42,-2,biomesoplenty:leaves_4:3)
Block(-1,-4,0,biomesoplenty:log_2:5)
Block(0,41,-16,biomesoplenty:leaves_4:3)
Block(-17,43,-2,biomesoplenty:leaves_4:3)
Block(0,42,-16,biomesoplenty:log_2:5)
Block(10,44,1,biomesoplenty:leaves_4:3)
Block(0,43,-16,biomesoplenty:leaves_4:3)
Block(10,45,1,biomesoplenty:leaves_4:3)
Block(10,46,1,biomesoplenty:leaves_4:3)
Block(10,47,1,biomesoplenty:leaves_4:3)
Block(10,40,1,biomesoplenty:leaves_4:3)
Block(9,46,-5,biomesoplenty:leaves_4:3)
Block(10,41,1,biomesoplenty:leaves_4:3)
Block(9,45,-5,biomesoplenty:leaves_4:3)
Block(10,42,1,biomesoplenty:leaves_4:3)
Block(9,44,-5,biomesoplenty:leaves_4:3)
Block(9,43,-5,biomesoplenty:leaves_4:3)
Block(10,43,1,biomesoplenty:leaves_4:3)
Block(9,49,-5,biomesoplenty:leaves_4:3)
Block(9,48,-5,biomesoplenty:leaves_4:3)
Block(9,47,-5,biomesoplenty:leaves_4:3)
Block(10,38,1,biomesoplenty:log_2:5)
Block(-12,43,7,biomesoplenty:log_2:5)
Block(-12,44,7,biomesoplenty:leaves_4:3)
Block(-12,41,7,biomesoplenty:leaves_4:3)
Block(-12,42,7,biomesoplenty:leaves_4:3)
Block(-12,40,7,biomesoplenty:leaves_4:3)
Block(3,40,21,biomesoplenty:leaves_4:3)
Block(-9,40,-8,biomesoplenty:leaves_4:3)
Block(18,41,5,biomesoplenty:leaves_4:3)
Block(-9,42,-8,biomesoplenty:log_2:5)
Block(-9,41,-8,biomesoplenty:log_2:5)
Block(18,42,5,biomesoplenty:leaves_4:3)
Block(-9,44,-8,biomesoplenty:leaves_4:3)
Block(-10,42,10,biomesoplenty:leaves_4:3)
Block(-9,43,-8,biomesoplenty:leaves_4:3)
Block(-9,46,-8,biomesoplenty:leaves_4:3)
Block(-9,45,-8,biomesoplenty:leaves_4:3)
Block(-10,45,10,biomesoplenty:leaves_4:3)
Block(-9,48,-8,biomesoplenty:leaves_4:3)
Block(-9,47,-8,biomesoplenty:leaves_4:3)
Block(-10,43,10,biomesoplenty:leaves_4:3)
Block(-10,44,10,biomesoplenty:leaves_4:3)
Block(-17,43,6,biomesoplenty:leaves_4:3)
Block(5,44,-18,biomesoplenty:leaves_4:3)
Block(5,43,-18,biomesoplenty:leaves_4:3)
Block(5,42,-18,biomesoplenty:leaves_4:3)
Block(5,41,-18,biomesoplenty:leaves_4:3)
Block(9,47,8,biomesoplenty:leaves_4:3)
Block(9,48,8,biomesoplenty:log_2:5)
Block(-7,46,14,biomesoplenty:leaves_4:3)
Block(-4,48,-11,biomesoplenty:leaves_4:3)
Block(9,46,8,biomesoplenty:leaves_4:3)
Block(2,40,-6,biomesoplenty:leaves_4:3)
Block(2,41,-6,biomesoplenty:leaves_4:3)
Block(9,49,8,biomesoplenty:leaves_4:3)
Block(2,42,-6,biomesoplenty:leaves_4:3)
Block(-7,40,14,biomesoplenty:leaves_4:3)
Block(2,43,-6,biomesoplenty:log_2:5)
Block(9,40,8,biomesoplenty:leaves_4:3)
Block(2,44,-6,biomesoplenty:leaves_4:3)
Block(-4,40,-11,biomesoplenty:leaves_4:3)
Block(2,45,-6,biomesoplenty:leaves_4:3)
Block(-4,41,-11,biomesoplenty:leaves_4:3)
Block(2,46,-6,biomesoplenty:leaves_4:3)
Block(9,43,8,biomesoplenty:leaves_4:3)
Block(-4,46,-11,biomesoplenty:leaves_4:3)
Block(2,47,-6,biomesoplenty:leaves_4:3)
Block(9,44,8,biomesoplenty:leaves_4:3)
Block(-4,47,-11,biomesoplenty:leaves_4:3)
Block(2,48,-6,biomesoplenty:leaves_4:3)
Block(9,41,8,biomesoplenty:leaves_4:3)
Block(-4,44,-11,biomesoplenty:leaves_4:3)
Block(2,49,-6,biomesoplenty:leaves_4:3)
Block(-7,41,14,biomesoplenty:leaves_4:3)
Block(9,42,8,biomesoplenty:leaves_4:3)
Block(-4,45,-11,biomesoplenty:leaves_4:3)
Block(-19,40,-10,biomesoplenty:leaves_4:3)
Block(-19,41,-10,biomesoplenty:leaves_4:3)
Block(20,44,1,biomesoplenty:leaves_4:3)
Block(20,43,1,biomesoplenty:leaves_4:3)
Block(-7,45,7,biomesoplenty:leaves_4:3)
Block(-7,46,7,biomesoplenty:leaves_4:3)
Block(-7,47,7,biomesoplenty:leaves_4:3)
Block(-2,51,-10,biomesoplenty:leaves_4:3)
Block(-2,50,-10,biomesoplenty:leaves_4:3)
Block(-7,40,7,biomesoplenty:leaves_4:3)
Block(-7,41,7,biomesoplenty:leaves_4:3)
Block(-7,42,7,biomesoplenty:leaves_4:3)
Block(-7,43,7,biomesoplenty:leaves_4:3)
Block(17,46,3,biomesoplenty:leaves_4:3)
Block(-7,44,7,biomesoplenty:leaves_4:3)
Block(17,45,3,biomesoplenty:leaves_4:3)
Block(-9,47,-13,biomesoplenty:leaves_4:3)
Block(-16,41,-6,biomesoplenty:leaves_4:3)
Block(-16,42,-6,biomesoplenty:leaves_4:3)
Block(5,50,6,biomesoplenty:leaves_4:3)
Block(-16,40,-6,biomesoplenty:log_2:5)
Block(5,51,6,biomesoplenty:leaves_4:3)
Block(-2,44,-10,biomesoplenty:leaves_4:3)
Block(-2,42,-10,biomesoplenty:log_2:5)
Block(-2,41,-10,biomesoplenty:leaves_4:3)
Block(-2,40,-10,biomesoplenty:leaves_4:3)
Block(5,49,6,biomesoplenty:leaves_4:3)
Block(5,47,6,biomesoplenty:log_2:5)
Block(5,48,6,biomesoplenty:leaves_4:3)
Block(-2,49,-10,biomesoplenty:leaves_4:3)
Block(-2,48,-10,biomesoplenty:leaves_4:3)
Block(-2,47,-10,biomesoplenty:leaves_4:3)
Block(-2,46,-10,biomesoplenty:leaves_4:3)
Block(17,42,3,biomesoplenty:leaves_4:3)
Block(17,41,3,biomesoplenty:leaves_4:3)
Block(17,40,3,biomesoplenty:leaves_4:3)
Block(5,45,6,biomesoplenty:leaves_4:3)
Block(5,46,6,biomesoplenty:leaves_4:3)
Block(5,43,6,biomesoplenty:leaves_4:3)
Block(5,44,6,biomesoplenty:log_2:5)
Block(5,41,6,biomesoplenty:leaves_4:3)
Block(5,42,6,biomesoplenty:leaves_4:3)
Block(5,40,6,biomesoplenty:leaves_4:3)
Block(3,41,-17,biomesoplenty:leaves_4:3)
Block(3,42,-17,biomesoplenty:leaves_4:3)
Block(3,43,-17,biomesoplenty:leaves_4:3)
Block(3,44,-17,biomesoplenty:leaves_4:3)
Block(-11,42,5,biomesoplenty:leaves_4:3)
Block(-11,43,5,biomesoplenty:leaves_4:3)
Block(-11,45,5,biomesoplenty:leaves_4:3)
Block(18,40,-3,biomesoplenty:leaves_4:3)
Block(18,41,-3,biomesoplenty:leaves_4:3)
Block(-9,40,-13,biomesoplenty:leaves_4:3)
Block(-9,42,-13,biomesoplenty:leaves_4:3)
Block(-9,41,-13,biomesoplenty:leaves_4:3)
Block(-20,41,-9,biomesoplenty:leaves_4:3)
Block(-20,40,-9,biomesoplenty:leaves_4:3)
Block(-9,43,-13,biomesoplenty:leaves_4:3)
Block(-14,40,13,biomesoplenty:leaves_4:3)
Block(-9,46,-13,biomesoplenty:leaves_4:3)
Block(-14,41,13,biomesoplenty:leaves_4:3)
Block(14,42,-7,biomesoplenty:leaves_4:3)
Block(14,48,-7,biomesoplenty:leaves_4:3)
Block(14,45,-7,biomesoplenty:leaves_4:3)
Block(14,43,-7,biomesoplenty:leaves_4:3)
Block(14,44,-7,biomesoplenty:leaves_4:3)
Block(-10,43,4,biomesoplenty:leaves_4:3)
Block(-10,42,4,biomesoplenty:leaves_4:3)
Block(-10,47,4,biomesoplenty:leaves_4:3)
Block(-10,46,4,biomesoplenty:leaves_4:3)
Block(-10,45,4,biomesoplenty:leaves_4:3)
Block(-10,49,4,biomesoplenty:leaves_4:3)
Block(3,39,-2,biomesoplenty:log_2:5)
Block(5,50,-2,biomesoplenty:leaves_4:3)
Block(18,44,-3,biomesoplenty:leaves_4:3)
Block(5,51,-2,biomesoplenty:leaves_4:3)
Block(15,40,-15,biomesoplenty:leaves_4:3)
Block(-10,50,4,biomesoplenty:leaves_4:3)
Block(3,42,-2,biomesoplenty:leaves_4:3)
Block(3,44,-2,biomesoplenty:leaves_4:3)
Block(3,45,-2,biomesoplenty:leaves_4:3)
Block(-4,50,7,biomesoplenty:leaves_4:3)
Block(4,41,-12,biomesoplenty:leaves_4:3)
Block(8,40,6,biomesoplenty:leaves_4:3)
Block(8,41,6,biomesoplenty:leaves_4:3)
Block(3,46,-2,biomesoplenty:leaves_4:3)
Block(4,44,-12,biomesoplenty:leaves_4:3)
Block(3,47,-2,biomesoplenty:leaves_4:3)
Block(4,43,-12,biomesoplenty:log_2:5)
Block(3,48,-2,biomesoplenty:leaves_4:3)
Block(-1,40,-15,biomesoplenty:leaves_4:3)
Block(4,42,-12,biomesoplenty:leaves_4:3)
Block(3,49,-2,biomesoplenty:leaves_4:3)
Block(12,40,-14,biomesoplenty:leaves_4:3)
Block(8,46,6,biomesoplenty:leaves_4:3)
Block(8,47,6,biomesoplenty:leaves_4:3)
Block(4,48,-12,biomesoplenty:leaves_4:3)
Block(4,47,-12,biomesoplenty:leaves_4:3)
Block(8,48,6,biomesoplenty:leaves_4:3)
Block(4,46,-12,biomesoplenty:leaves_4:3)
Block(8,49,6,biomesoplenty:leaves_4:3)
Block(8,42,6,biomesoplenty:leaves_4:3)
Block(15,42,14,biomesoplenty:leaves_4:3)
Block(12,44,-14,biomesoplenty:leaves_4:3)
Block(15,41,14,biomesoplenty:leaves_4:3)
Block(12,43,-14,biomesoplenty:leaves_4:3)
Block(8,43,6,biomesoplenty:leaves_4:3)
Block(8,44,6,biomesoplenty:log_2:5)
Block(12,41,-14,biomesoplenty:leaves_4:3)
Block(8,45,6,biomesoplenty:leaves_4:3)
Block(3,50,-2,biomesoplenty:log_2:5)
Block(3,51,-2,biomesoplenty:leaves_4:3)
Block(8,50,6,biomesoplenty:leaves_4:3)
Block(8,51,6,biomesoplenty:leaves_4:3)
Block(2,51,6,biomesoplenty:leaves_4:3)
Block(2,50,6,biomesoplenty:leaves_4:3)
Block(5,45,-2,biomesoplenty:leaves_4:3)
Block(5,44,-2,biomesoplenty:leaves_4:3)
Block(5,47,-2,biomesoplenty:log_2:5)
Block(5,46,-2,biomesoplenty:leaves_4:3)
Block(5,49,-2,biomesoplenty:log_2:5)
Block(5,48,-2,biomesoplenty:leaves_4:3)
Block(5,41,-2,biomesoplenty:leaves_4:3)
Block(5,40,-2,biomesoplenty:leaves_4:3)
Block(5,43,-2,biomesoplenty:leaves_4:3)
Block(5,42,-2,biomesoplenty:leaves_4:3)
Block(-3,40,-4,biomesoplenty:leaves_4:3)
Block(-3,43,-4,biomesoplenty:leaves_4:3)
Block(-3,44,-4,biomesoplenty:log_2:5)
Block(-3,41,-4,biomesoplenty:log_2:5)
Block(-3,42,-4,biomesoplenty:log_2:5)
Block(16,40,-22,biomesoplenty:leaves_4:3)
Block(-3,43,-16,biomesoplenty:leaves_4:3)
Block(-3,42,-16,biomesoplenty:leaves_4:3)
Block(-3,41,-16,biomesoplenty:leaves_4:3)
Block(-3,40,-16,biomesoplenty:leaves_4:3)
Block(-3,37,-4,biomesoplenty:log_2:5)
Block(-10,40,-12,biomesoplenty:leaves_4:3)
Block(-10,41,-12,biomesoplenty:leaves_4:3)
Block(-10,42,-12,biomesoplenty:leaves_4:3)
Block(9,38,-14,biomesoplenty:log_2:5)
Block(-3,50,-4,biomesoplenty:log_2:5)
Block(-3,51,-4,biomesoplenty:leaves_4:3)
Block(2,49,6,biomesoplenty:leaves_4:3)
Block(2,48,6,biomesoplenty:log_2:5)
Block(9,43,-14,biomesoplenty:leaves_4:3)
Block(2,47,6,biomesoplenty:leaves_4:3)
Block(9,44,-14,biomesoplenty:leaves_4:3)
Block(2,46,6,biomesoplenty:leaves_4:3)
Block(9,41,-14,biomesoplenty:leaves_4:3)
Block(2,45,6,biomesoplenty:log_2:5)
Block(9,42,-14,biomesoplenty:leaves_4:3)
Block(2,44,6,biomesoplenty:log_2:5)
Block(16,44,-7,biomesoplenty:leaves_4:3)
Block(-3,47,-16,biomesoplenty:leaves_4:3)
Block(16,43,-7,biomesoplenty:leaves_4:3)
Block(-3,46,-16,biomesoplenty:leaves_4:3)
Block(16,42,-7,biomesoplenty:leaves_4:3)
Block(-3,45,-16,biomesoplenty:leaves_4:3)
Block(14,41,3,biomesoplenty:leaves_4:3)
Block(14,40,3,biomesoplenty:leaves_4:3)
Block(2,43,6,biomesoplenty:leaves_4:3)
Block(-3,47,-4,biomesoplenty:leaves_4:3)
Block(2,42,6,biomesoplenty:leaves_4:3)
Block(-3,48,-4,biomesoplenty:leaves_4:3)
Block(2,41,6,biomesoplenty:leaves_4:3)
Block(16,44,-10,biomesoplenty:leaves_4:3)
Block(9,45,-14,biomesoplenty:leaves_4:3)
Block(-3,45,-4,biomesoplenty:log_2:5)
Block(2,40,6,biomesoplenty:leaves_4:3)
Block(16,43,-10,biomesoplenty:log_2:5)
Block(9,46,-14,biomesoplenty:leaves_4:3)
Block(-3,46,-4,biomesoplenty:leaves_4:3)
Block(-3,49,-4,biomesoplenty:leaves_4:3)
Block(-4,44,7,biomesoplenty:leaves_4:3)
Block(-4,45,7,biomesoplenty:leaves_4:3)
Block(-13,42,4,biomesoplenty:leaves_4:3)
Block(-4,42,7,biomesoplenty:leaves_4:3)
Block(-4,43,7,biomesoplenty:leaves_4:3)
Block(-4,48,7,biomesoplenty:leaves_4:3)
Block(-13,43,4,biomesoplenty:leaves_4:3)
Block(-4,49,7,biomesoplenty:leaves_4:3)
Block(-13,46,4,biomesoplenty:leaves_4:3)
Block(-4,46,7,biomesoplenty:leaves_4:3)
Block(-13,45,4,biomesoplenty:log_2:5)
Block(-4,47,7,biomesoplenty:log_2:5)
Block(17,42,10,biomesoplenty:leaves_4:3)
Block(-4,40,7,biomesoplenty:leaves_4:3)
Block(-4,41,7,biomesoplenty:leaves_4:3)
Block(-10,41,-3,biomesoplenty:leaves_4:3)
Block(-10,40,-3,biomesoplenty:leaves_4:3)
Block(6,31,-9,biomesoplenty:log_2:5)
Block(6,32,-9,biomesoplenty:log_2:5)
Block(15,42,-7,biomesoplenty:leaves_4:3)
Block(15,43,-7,biomesoplenty:leaves_4:3)
Block(-10,44,-3,biomesoplenty:leaves_4:3)
Block(-10,43,-3,biomesoplenty:leaves_4:3)
Block(15,44,-7,biomesoplenty:leaves_4:3)
Block(-10,42,-3,biomesoplenty:leaves_4:3)
Block(15,45,-7,biomesoplenty:leaves_4:3)
Block(-10,49,-3,biomesoplenty:leaves_4:3)
Block(-10,48,-3,biomesoplenty:leaves_4:3)
Block(-10,47,-3,biomesoplenty:leaves_4:3)
Block(-10,46,-3,biomesoplenty:leaves_4:3)
Block(14,41,14,biomesoplenty:log_2:5)
Block(14,42,14,biomesoplenty:leaves_4:3)
Block(3,50,7,biomesoplenty:leaves_4:3)
Block(5,-4,-2,biomesoplenty:log_2:5)
Block(5,-3,-2,biomesoplenty:log_2:5)
Block(9,42,12,biomesoplenty:leaves_4:3)
Block(9,43,12,biomesoplenty:leaves_4:3)
Block(9,40,12,biomesoplenty:leaves_4:3)
Block(9,41,12,biomesoplenty:leaves_4:3)
Block(0,39,7,biomesoplenty:log_2:5)
Block(9,47,12,biomesoplenty:leaves_4:3)
Block(9,44,12,biomesoplenty:leaves_4:3)
Block(9,45,12,biomesoplenty:leaves_4:3)
Block(6,50,-9,biomesoplenty:leaves_4:3)
Block(-2,49,11,biomesoplenty:leaves_4:3)
Block(-2,48,11,biomesoplenty:leaves_4:3)
Block(-2,47,11,biomesoplenty:leaves_4:3)
Block(-2,42,11,biomesoplenty:leaves_4:3)
Block(-2,41,11,biomesoplenty:leaves_4:3)
Block(-2,46,11,biomesoplenty:leaves_4:3)
Block(-2,45,11,biomesoplenty:leaves_4:3)
Block(-2,44,11,biomesoplenty:leaves_4:3)
Block(-2,43,11,biomesoplenty:leaves_4:3)
Block(6,44,-9,biomesoplenty:log_2:5)
Block(6,45,-9,biomesoplenty:leaves_4:3)
Block(6,42,-9,biomesoplenty:leaves_4:3)
Block(6,43,-9,biomesoplenty:leaves_4:3)
Block(6,48,-9,biomesoplenty:leaves_4:3)
Block(6,49,-9,biomesoplenty:leaves_4:3)
Block(6,46,-9,biomesoplenty:leaves_4:3)
Block(6,47,-9,biomesoplenty:leaves_4:3)
Block(6,40,-9,biomesoplenty:leaves_4:3)
Block(6,41,-9,biomesoplenty:leaves_4:3)
Block(7,50,-9,biomesoplenty:leaves_4:3)
Block(-15,43,3,biomesoplenty:leaves_4:3)
Block(11,41,-20,biomesoplenty:leaves_4:3)
Block(11,42,-20,biomesoplenty:leaves_4:3)
Block(-15,44,3,biomesoplenty:leaves_4:3)
Block(-15,45,3,biomesoplenty:leaves_4:3)
Block(3,-3,-2,biomesoplenty:log_2:5)
Block(14,43,3,biomesoplenty:leaves_4:3)
Block(3,-4,-2,biomesoplenty:log_2:5)
Block(14,42,3,biomesoplenty:leaves_4:3)
Block(14,45,3,biomesoplenty:leaves_4:3)
Block(14,44,3,biomesoplenty:leaves_4:3)
Block(14,46,3,biomesoplenty:leaves_4:3)
Block(3,-2,-2,biomesoplenty:log_2:5)
Block(16,45,2,biomesoplenty:leaves_4:3)
Block(16,46,2,biomesoplenty:leaves_4:3)
Block(16,43,2,biomesoplenty:leaves_4:3)
Block(11,41,-19,biomesoplenty:leaves_4:3)
Block(11,42,-19,biomesoplenty:leaves_4:3)
Block(-10,46,-12,biomesoplenty:leaves_4:3)
Block(-10,47,-12,biomesoplenty:leaves_4:3)
Block(16,41,2,biomesoplenty:leaves_4:3)
Block(16,42,2,biomesoplenty:leaves_4:3)
Block(7,40,-9,biomesoplenty:log_2:5)
Block(16,40,2,biomesoplenty:leaves_4:3)
Block(7,41,-9,biomesoplenty:leaves_4:3)
Block(7,42,-9,biomesoplenty:leaves_4:3)
Block(7,43,-9,biomesoplenty:leaves_4:3)
Block(7,44,-9,biomesoplenty:leaves_4:3)
Block(7,45,-9,biomesoplenty:leaves_4:3)
Block(7,46,-9,biomesoplenty:leaves_4:3)
Block(7,47,-9,biomesoplenty:leaves_4:3)
Block(7,48,-9,biomesoplenty:leaves_4:3)
Block(7,49,-9,biomesoplenty:leaves_4:3)
Block(4,-4,-2,biomesoplenty:log_2:5)
Block(4,-3,-2,biomesoplenty:log_2:5)
Block(5,45,1,biomesoplenty:leaves_4:3)
Block(8,43,-19,biomesoplenty:leaves_4:3)
Block(5,44,1,biomesoplenty:leaves_4:3)
Block(8,42,-19,biomesoplenty:leaves_4:3)
Block(5,43,1,biomesoplenty:leaves_4:3)
Block(8,41,-19,biomesoplenty:leaves_4:3)
Block(5,42,1,biomesoplenty:log_2:5)
Block(5,49,1,biomesoplenty:leaves_4:3)
Block(5,48,1,biomesoplenty:leaves_4:3)
Block(5,47,1,biomesoplenty:log_2:5)
Block(5,46,1,biomesoplenty:leaves_4:3)
Block(8,46,-9,biomesoplenty:leaves_4:3)
Block(9,46,2,biomesoplenty:leaves_4:3)
Block(9,45,2,biomesoplenty:leaves_4:3)
Block(8,47,-9,biomesoplenty:leaves_4:3)
Block(8,44,-9,biomesoplenty:leaves_4:3)
Block(9,44,2,biomesoplenty:leaves_4:3)
Block(9,43,2,biomesoplenty:leaves_4:3)
Block(8,45,-9,biomesoplenty:log_2:5)
Block(8,42,-9,biomesoplenty:leaves_4:3)
Block(9,42,2,biomesoplenty:leaves_4:3)
Block(9,41,2,biomesoplenty:leaves_4:3)
Block(8,43,-9,biomesoplenty:leaves_4:3)
Block(8,40,-9,biomesoplenty:leaves_4:3)
Block(9,40,2,biomesoplenty:leaves_4:3)
Block(8,41,-9,biomesoplenty:leaves_4:3)
Block(9,49,2,biomesoplenty:leaves_4:3)
Block(8,48,-9,biomesoplenty:leaves_4:3)
Block(9,48,2,biomesoplenty:leaves_4:3)
Block(9,47,2,biomesoplenty:leaves_4:3)
Block(8,49,-9,biomesoplenty:leaves_4:3)
Block(0,37,-6,biomesoplenty:log_2:5)
Block(-21,41,-10,biomesoplenty:leaves_4:3)
Block(-21,40,-10,biomesoplenty:leaves_4:3)
Block(5,41,1,biomesoplenty:log_2:5)
Block(5,40,1,biomesoplenty:log_2:5)
Block(-7,46,2,biomesoplenty:leaves_4:3)
Block(-7,47,2,biomesoplenty:leaves_4:3)
Block(-7,44,2,biomesoplenty:log_2:5)
Block(-7,45,2,biomesoplenty:leaves_4:3)
Block(-7,42,2,biomesoplenty:leaves_4:3)
Block(-7,43,2,biomesoplenty:leaves_4:3)
Block(-7,40,2,biomesoplenty:leaves_4:3)
Block(9,51,2,biomesoplenty:leaves_4:3)
Block(-7,41,2,biomesoplenty:leaves_4:3)
Block(9,50,2,biomesoplenty:log_2:5)
Block(0,40,-6,biomesoplenty:leaves_4:3)
Block(-3,41,12,biomesoplenty:leaves_4:3)
Block(0,44,-6,biomesoplenty:leaves_4:3)
Block(0,43,-6,biomesoplenty:leaves_4:3)
Block(-3,43,12,biomesoplenty:leaves_4:3)
Block(0,42,-6,biomesoplenty:leaves_4:3)
Block(-3,46,12,biomesoplenty:leaves_4:3)
Block(0,41,-6,biomesoplenty:leaves_4:3)
Block(-3,45,12,biomesoplenty:leaves_4:3)
Block(0,48,-6,biomesoplenty:leaves_4:3)
Block(-3,48,12,biomesoplenty:leaves_4:3)
Block(0,47,-6,biomesoplenty:leaves_4:3)
Block(-3,47,12,biomesoplenty:leaves_4:3)
Block(0,46,-6,biomesoplenty:leaves_4:3)
Block(0,45,-6,biomesoplenty:leaves_4:3)
Block(0,49,-6,biomesoplenty:leaves_4:3)
Block(-21,41,-9,biomesoplenty:leaves_4:3)
Block(12,48,4,biomesoplenty:leaves_4:3)
Block(-21,40,-9,biomesoplenty:leaves_4:3)
Block(12,47,4,biomesoplenty:leaves_4:3)
Block(1,19,-1,biomesoplenty:log_2:5)
Block(12,46,4,biomesoplenty:leaves_4:3)
Block(1,18,-1,biomesoplenty:log_2:5)
Block(12,45,4,biomesoplenty:leaves_4:3)
Block(1,17,-1,biomesoplenty:log_2:5)
Block(12,44,4,biomesoplenty:leaves_4:3)
Block(1,16,-1,biomesoplenty:log_2:5)
Block(1,15,-1,biomesoplenty:log_2:5)
Block(1,14,-1,biomesoplenty:log_2:5)
Block(12,41,4,biomesoplenty:leaves_4:3)
Block(-2,40,-3,biomesoplenty:leaves_4:3)
Block(-2,44,-3,biomesoplenty:leaves_4:3)
Block(-2,43,-3,biomesoplenty:leaves_4:3)
Block(-2,42,-3,biomesoplenty:leaves_4:3)
Block(-2,41,-3,biomesoplenty:leaves_4:3)
Block(12,49,4,biomesoplenty:leaves_4:3)
Block(11,51,2,biomesoplenty:leaves_4:3)
Block(-1,49,-8,biomesoplenty:leaves_4:3)
Block(-1,48,-8,biomesoplenty:log_2:5)
Block(-1,47,-8,biomesoplenty:leaves_4:3)
Block(11,50,2,biomesoplenty:leaves_4:3)
Block(-5,42,-18,biomesoplenty:leaves_4:3)
Block(-1,46,-8,biomesoplenty:leaves_4:3)
Block(-1,45,-8,biomesoplenty:leaves_4:3)
Block(-5,40,-18,biomesoplenty:leaves_4:3)
Block(-1,44,-8,biomesoplenty:leaves_4:3)
Block(-5,41,-18,biomesoplenty:leaves_4:3)
Block(-1,43,-8,biomesoplenty:leaves_4:3)
Block(1,13,-1,biomesoplenty:log_2:5)
Block(-1,42,-8,biomesoplenty:leaves_4:3)
Block(1,12,-1,biomesoplenty:log_2:5)
Block(-1,41,-8,biomesoplenty:leaves_4:3)
Block(1,11,-1,biomesoplenty:log_2:5)
Block(-1,40,-8,biomesoplenty:log_2:5)
Block(1,10,-1,biomesoplenty:log_2:5)
Block(6,42,15,biomesoplenty:leaves_4:3)
Block(8,45,0,biomesoplenty:leaves_4:3)
Block(6,43,15,biomesoplenty:leaves_4:3)
Block(8,44,0,biomesoplenty:leaves_4:3)
Block(12,41,-19,biomesoplenty:leaves_4:3)
Block(6,44,15,biomesoplenty:leaves_4:3)
Block(8,47,0,biomesoplenty:leaves_4:3)
Block(-20,40,10,biomesoplenty:leaves_4:3)
Block(8,46,0,biomesoplenty:leaves_4:3)
Block(8,49,0,biomesoplenty:leaves_4:3)
Block(8,48,0,biomesoplenty:leaves_4:3)
Block(11,42,-21,biomesoplenty:leaves_4:3)
Block(11,41,-21,biomesoplenty:leaves_4:3)
Block(11,40,2,biomesoplenty:leaves_4:3)
Block(11,41,2,biomesoplenty:leaves_4:3)
Block(11,45,2,biomesoplenty:leaves_4:3)
Block(11,42,2,biomesoplenty:leaves_4:3)
Block(11,43,2,biomesoplenty:leaves_4:3)
Block(12,40,4,biomesoplenty:leaves_4:3)
Block(11,48,2,biomesoplenty:leaves_4:3)
Block(-1,40,15,biomesoplenty:leaves_4:3)
Block(11,46,2,biomesoplenty:leaves_4:3)
Block(-1,51,-8,biomesoplenty:leaves_4:3)
Block(-1,41,15,biomesoplenty:leaves_4:3)
Block(11,47,2,biomesoplenty:leaves_4:3)
Block(-1,50,-8,biomesoplenty:log_2:5)
Block(8,41,0,biomesoplenty:leaves_4:3)
Block(8,40,0,biomesoplenty:leaves_4:3)
Block(8,43,0,biomesoplenty:leaves_4:3)
Block(8,42,0,biomesoplenty:leaves_4:3)
Block(7,43,-21,biomesoplenty:leaves_4:3)
Block(-6,45,0,biomesoplenty:log_2:5)
Block(-6,46,0,biomesoplenty:log_2:5)
Block(-6,47,0,biomesoplenty:log_2:5)
Block(-6,48,0,biomesoplenty:leaves_4:3)
Block(-6,49,0,biomesoplenty:leaves_4:3)
Block(7,42,-21,biomesoplenty:leaves_4:3)
Block(10,47,0,biomesoplenty:leaves_4:3)
Block(10,48,0,biomesoplenty:leaves_4:3)
Block(10,49,0,biomesoplenty:leaves_4:3)
Block(10,43,0,biomesoplenty:leaves_4:3)
Block(10,44,0,biomesoplenty:leaves_4:3)
Block(10,45,0,biomesoplenty:leaves_4:3)
Block(10,46,0,biomesoplenty:log_2:5)
Block(10,40,0,biomesoplenty:leaves_4:3)
Block(10,41,0,biomesoplenty:log_2:5)
Block(-6,50,0,biomesoplenty:leaves_4:3)
Block(8,50,0,biomesoplenty:leaves_4:3)
Block(10,42,0,biomesoplenty:leaves_4:3)
Block(-6,51,0,biomesoplenty:leaves_4:3)
Block(8,51,0,biomesoplenty:leaves_4:3)
Block(-2,51,-3,biomesoplenty:leaves_4:3)
Block(-2,50,-3,biomesoplenty:log_2:5)
Block(-2,48,-3,biomesoplenty:leaves_4:3)
Block(-2,47,-3,biomesoplenty:leaves_4:3)
Block(-2,46,-3,biomesoplenty:log_2:5)
Block(-2,45,-3,biomesoplenty:leaves_4:3)
Block(-2,49,-3,biomesoplenty:log_2:5)
Block(-6,40,0,biomesoplenty:leaves_4:3)
Block(-6,41,0,biomesoplenty:leaves_4:3)
Block(19,40,-3,biomesoplenty:leaves_4:3)
Block(-6,42,0,biomesoplenty:leaves_4:3)
Block(-6,43,0,biomesoplenty:leaves_4:3)
Block(-6,44,0,biomesoplenty:leaves_4:3)
Block(0,41,13,biomesoplenty:leaves_4:3)
Block(6,51,3,biomesoplenty:leaves_4:3)
Block(1,-4,-1,biomesoplenty:log_2:5)
Block(6,50,3,biomesoplenty:leaves_4:3)
Block(1,-3,-1,biomesoplenty:log_2:5)
Block(0,44,13,biomesoplenty:leaves_4:3)
Block(1,-2,-1,biomesoplenty:log_2:5)
Block(0,45,13,biomesoplenty:leaves_4:3)
Block(1,-1,-1,biomesoplenty:log_2:5)
Block(0,42,13,biomesoplenty:leaves_4:3)
Block(0,43,13,biomesoplenty:leaves_4:3)
Block(12,42,-20,biomesoplenty:leaves_4:3)
Block(12,41,-20,biomesoplenty:leaves_4:3)
Block(-8,47,4,biomesoplenty:leaves_4:3)
Block(-8,48,4,biomesoplenty:leaves_4:3)
Block(-13,42,-14,biomesoplenty:leaves_4:3)
Block(-8,49,4,biomesoplenty:log_2:5)
Block(-13,41,-14,biomesoplenty:leaves_4:3)
Block(-8,43,4,biomesoplenty:leaves_4:3)
Block(-8,44,4,biomesoplenty:leaves_4:3)
Block(-8,45,4,biomesoplenty:leaves_4:3)
Block(-8,46,4,biomesoplenty:leaves_4:3)
Block(0,48,13,biomesoplenty:leaves_4:3)
Block(-8,40,4,biomesoplenty:leaves_4:3)
Block(0,49,13,biomesoplenty:leaves_4:3)
Block(0,46,13,biomesoplenty:leaves_4:3)
Block(8,43,-20,biomesoplenty:leaves_4:3)
Block(6,40,3,biomesoplenty:log_2:5)
Block(6,42,3,biomesoplenty:log_2:5)
Block(6,41,3,biomesoplenty:leaves_4:3)
Block(8,42,-20,biomesoplenty:leaves_4:3)
Block(6,44,3,biomesoplenty:leaves_4:3)
Block(8,41,-20,biomesoplenty:leaves_4:3)
Block(6,43,3,biomesoplenty:leaves_4:3)
Block(-10,42,-4,biomesoplenty:leaves_4:3)
Block(-10,41,-4,biomesoplenty:leaves_4:3)
Block(-10,40,-4,biomesoplenty:leaves_4:3)
Block(-10,46,-4,biomesoplenty:leaves_4:3)
Block(-10,45,-4,biomesoplenty:leaves_4:3)
Block(-10,44,-4,biomesoplenty:leaves_4:3)
Block(-10,43,-4,biomesoplenty:leaves_4:3)
Block(6,46,3,biomesoplenty:leaves_4:3)
Block(-8,50,4,biomesoplenty:leaves_4:3)
Block(6,45,3,biomesoplenty:leaves_4:3)
Block(-10,48,-4,biomesoplenty:leaves_4:3)
Block(6,48,3,biomesoplenty:leaves_4:3)
Block(-10,47,-4,biomesoplenty:leaves_4:3)
Block(6,47,3,biomesoplenty:leaves_4:3)
Block(6,49,3,biomesoplenty:leaves_4:3)
Block(-6,49,-1,biomesoplenty:leaves_4:3)
Block(-6,48,-1,biomesoplenty:leaves_4:3)
Block(-6,47,-1,biomesoplenty:leaves_4:3)
Block(-6,42,-1,biomesoplenty:leaves_4:3)
Block(-6,41,-1,biomesoplenty:leaves_4:3)
Block(-6,40,-1,biomesoplenty:log_2:5)
Block(5,43,-19,biomesoplenty:leaves_4:3)
Block(5,42,-19,biomesoplenty:leaves_4:3)
Block(5,41,-19,biomesoplenty:leaves_4:3)
Block(-6,46,-1,biomesoplenty:leaves_4:3)
Block(-6,45,-1,biomesoplenty:log_2:5)
Block(-6,44,-1,biomesoplenty:leaves_4:3)
Block(-6,43,-1,biomesoplenty:leaves_4:3)
Block(-9,43,14,biomesoplenty:leaves_4:3)
Block(-9,44,14,biomesoplenty:leaves_4:3)
Block(2,40,-11,biomesoplenty:leaves_4:3)
Block(2,41,-11,biomesoplenty:leaves_4:3)
Block(2,42,-11,biomesoplenty:log_2:5)
Block(2,43,-11,biomesoplenty:leaves_4:3)
Block(2,44,-11,biomesoplenty:leaves_4:3)
Block(2,45,-11,biomesoplenty:leaves_4:3)
Block(2,46,-11,biomesoplenty:leaves_4:3)
Block(2,47,-11,biomesoplenty:leaves_4:3)
Block(-9,40,14,biomesoplenty:leaves_4:3)
Block(2,48,-11,biomesoplenty:leaves_4:3)
Block(-9,41,14,biomesoplenty:leaves_4:3)
Block(2,49,-11,biomesoplenty:leaves_4:3)
Block(5,41,-20,biomesoplenty:leaves_4:3)
Block(5,43,-20,biomesoplenty:leaves_4:3)
Block(5,42,-20,biomesoplenty:leaves_4:3)
Block(-6,51,-1,biomesoplenty:leaves_4:3)
Block(-6,50,-1,biomesoplenty:log_2:5)
Block(7,41,9,biomesoplenty:leaves_4:3)
Block(-14,45,-6,biomesoplenty:leaves_4:3)
Block(7,43,9,biomesoplenty:leaves_4:3)
Block(7,42,9,biomesoplenty:leaves_4:3)
Block(-14,42,-6,biomesoplenty:leaves_4:3)
Block(7,45,9,biomesoplenty:leaves_4:3)
Block(-14,41,-6,biomesoplenty:leaves_4:3)
Block(7,44,9,biomesoplenty:leaves_4:3)
Block(-14,44,-6,biomesoplenty:leaves_4:3)
Block(7,47,9,biomesoplenty:leaves_4:3)
Block(-14,43,-6,biomesoplenty:leaves_4:3)
Block(7,46,9,biomesoplenty:leaves_4:3)
Block(7,48,9,biomesoplenty:leaves_4:3)
Block(-14,40,-6,biomesoplenty:leaves_4:3)
Block(21,41,4,biomesoplenty:leaves_4:3)
Block(9,50,-4,biomesoplenty:leaves_4:3)
Block(15,46,-1,biomesoplenty:leaves_4:3)
Block(15,44,-1,biomesoplenty:leaves_4:3)
Block(15,45,-1,biomesoplenty:leaves_4:3)
Block(2,50,-11,biomesoplenty:leaves_4:3)
Block(10,50,0,biomesoplenty:leaves_4:3)
Block(0,4,-2,biomesoplenty:log_2:5)
Block(0,3,-2,biomesoplenty:log_2:5)
Block(0,6,-2,biomesoplenty:log_2:5)
Block(0,5,-2,biomesoplenty:log_2:5)
Block(0,8,-2,biomesoplenty:log_2:5)
Block(9,40,-4,biomesoplenty:leaves_4:3)
Block(20,43,2,biomesoplenty:leaves_4:3)
Block(0,7,-2,biomesoplenty:log_2:5)
Block(9,41,-4,biomesoplenty:leaves_4:3)
Block(-1,45,15,biomesoplenty:leaves_4:3)
Block(0,0,-2,biomesoplenty:log_2:5)
Block(0,2,-2,biomesoplenty:log_2:5)
Block(0,1,-2,biomesoplenty:log_2:5)
Block(-2,-4,-3,biomesoplenty:log_2:5)
Block(-2,-3,-3,biomesoplenty:log_2:5)
Block(9,44,-4,biomesoplenty:log_2:5)
Block(9,45,-4,biomesoplenty:leaves_4:3)
Block(9,42,-4,biomesoplenty:leaves_4:3)
Block(9,43,-4,biomesoplenty:leaves_4:3)
Block(-19,44,-2,biomesoplenty:leaves_4:3)
Block(9,49,-4,biomesoplenty:leaves_4:3)
Block(9,46,-4,biomesoplenty:leaves_4:3)
Block(9,47,-4,biomesoplenty:leaves_4:3)
Block(-6,43,-17,biomesoplenty:leaves_4:3)
Block(-6,42,-17,biomesoplenty:leaves_4:3)
Block(-6,40,-17,biomesoplenty:leaves_4:3)
Block(-19,40,-11,biomesoplenty:leaves_4:3)
Block(-19,41,-11,biomesoplenty:leaves_4:3)
Block(-10,42,11,biomesoplenty:leaves_4:3)
Block(-10,43,11,biomesoplenty:leaves_4:3)
Block(-7,50,2,biomesoplenty:leaves_4:3)
Block(-10,44,11,biomesoplenty:leaves_4:3)
Block(-7,51,2,biomesoplenty:leaves_4:3)
Block(10,49,-5,biomesoplenty:leaves_4:3)
Block(0,51,-6,biomesoplenty:leaves_4:3)
Block(0,50,-6,biomesoplenty:leaves_4:3)
Block(10,45,-5,biomesoplenty:leaves_4:3)
Block(10,46,-5,biomesoplenty:leaves_4:3)
Block(10,47,-5,biomesoplenty:leaves_4:3)
Block(-7,48,2,biomesoplenty:leaves_4:3)
Block(10,48,-5,biomesoplenty:leaves_4:3)
Block(-7,49,2,biomesoplenty:leaves_4:3)
Block(10,41,-5,biomesoplenty:leaves_4:3)
Block(10,42,-5,biomesoplenty:leaves_4:3)
Block(-11,40,10,biomesoplenty:leaves_4:3)
Block(10,43,-5,biomesoplenty:log_2:5)
Block(10,44,-5,biomesoplenty:leaves_4:3)
Block(-11,42,10,biomesoplenty:leaves_4:3)
Block(-11,43,10,biomesoplenty:leaves_4:3)
Block(10,40,-5,biomesoplenty:leaves_4:3)
Block(5,51,1,biomesoplenty:leaves_4:3)
Block(5,50,1,biomesoplenty:leaves_4:3)
Block(13,50,-1,biomesoplenty:leaves_4:3)
Block(3,40,19,biomesoplenty:leaves_4:3)
Block(-1,50,0,biomesoplenty:log_2:5)
Block(3,41,19,biomesoplenty:leaves_4:3)
Block(-4,41,-16,biomesoplenty:leaves_4:3)
Block(-1,48,0,biomesoplenty:log_2:5)
Block(-4,42,-16,biomesoplenty:leaves_4:3)
Block(-1,49,0,biomesoplenty:leaves_4:3)
Block(-4,43,-16,biomesoplenty:leaves_4:3)
Block(-4,40,-16,biomesoplenty:log_2:5)
Block(-1,42,0,biomesoplenty:leaves_4:3)
Block(-1,43,0,biomesoplenty:leaves_4:3)
Block(-1,44,0,biomesoplenty:log_2:5)
Block(13,47,-1,biomesoplenty:leaves_4:3)
Block(-1,45,0,biomesoplenty:leaves_4:3)
Block(13,46,-1,biomesoplenty:leaves_4:3)
Block(-1,46,0,biomesoplenty:leaves_4:3)
Block(13,49,-1,biomesoplenty:leaves_4:3)
Block(-1,47,0,biomesoplenty:log_2:5)
Block(13,48,-1,biomesoplenty:leaves_4:3)
Block(-10,42,3,biomesoplenty:leaves_4:3)
Block(-10,40,3,biomesoplenty:leaves_4:3)
Block(-10,45,3,biomesoplenty:leaves_4:3)
Block(-10,46,3,biomesoplenty:leaves_4:3)
Block(-10,43,3,biomesoplenty:leaves_4:3)
Block(-10,44,3,biomesoplenty:leaves_4:3)
Block(-10,49,3,biomesoplenty:leaves_4:3)
Block(-10,47,3,biomesoplenty:leaves_4:3)
Block(-10,48,3,biomesoplenty:leaves_4:3)
Block(3,41,20,biomesoplenty:leaves_4:3)
Block(-1,51,0,biomesoplenty:leaves_4:3)
Block(-11,40,6,biomesoplenty:leaves_4:3)
Block(3,40,20,biomesoplenty:leaves_4:3)
Block(-11,42,6,biomesoplenty:leaves_4:3)
Block(-11,43,6,biomesoplenty:leaves_4:3)
Block(-11,44,6,biomesoplenty:leaves_4:3)
Block(-9,41,-7,biomesoplenty:leaves_4:3)
Block(-9,40,-7,biomesoplenty:leaves_4:3)
Block(-9,43,-7,biomesoplenty:leaves_4:3)
Block(-9,42,-7,biomesoplenty:leaves_4:3)
Block(-9,45,-7,biomesoplenty:leaves_4:3)
Block(-9,44,-7,biomesoplenty:leaves_4:3)
Block(-9,47,-7,biomesoplenty:leaves_4:3)
Block(-9,46,-7,biomesoplenty:leaves_4:3)
Block(-9,48,-7,biomesoplenty:leaves_4:3)
Block(2,45,13,biomesoplenty:leaves_4:3)
Block(2,44,13,biomesoplenty:leaves_4:3)
Block(-7,40,-7,biomesoplenty:leaves_4:3)
Block(-7,41,-7,biomesoplenty:leaves_4:3)
Block(-7,42,-7,biomesoplenty:leaves_4:3)
Block(-7,43,-7,biomesoplenty:leaves_4:3)
Block(1,41,20,biomesoplenty:leaves_4:3)
Block(1,40,20,biomesoplenty:leaves_4:3)
Block(15,42,-1,biomesoplenty:leaves_4:3)
Block(15,43,-1,biomesoplenty:leaves_4:3)
Block(15,40,-1,biomesoplenty:leaves_4:3)
Block(15,41,-1,biomesoplenty:leaves_4:3)
Block(2,43,13,biomesoplenty:leaves_4:3)
Block(2,42,13,biomesoplenty:leaves_4:3)
Block(2,41,13,biomesoplenty:leaves_4:3)
Block(2,40,13,biomesoplenty:leaves_4:3)
Block(-12,40,-9,biomesoplenty:leaves_4:3)
Block(-12,41,-9,biomesoplenty:leaves_4:3)
Block(-12,42,-9,biomesoplenty:leaves_4:3)
Block(-12,43,-9,biomesoplenty:leaves_4:3)
Block(4,51,-8,biomesoplenty:leaves_4:3)
Block(4,50,-8,biomesoplenty:leaves_4:3)
Block(3,41,-18,biomesoplenty:log_2:5)
Block(3,42,-18,biomesoplenty:leaves_4:3)
Block(14,41,-21,biomesoplenty:leaves_4:3)
Block(14,40,-21,biomesoplenty:leaves_4:3)
Block(3,43,-18,biomesoplenty:log_2:5)
Block(1,41,19,biomesoplenty:leaves_4:3)
Block(3,44,-18,biomesoplenty:leaves_4:3)
Block(1,40,19,biomesoplenty:leaves_4:3)
Block(4,48,-8,biomesoplenty:leaves_4:3)
Block(4,47,-8,biomesoplenty:leaves_4:3)
Block(4,49,-8,biomesoplenty:leaves_4:3)
Block(4,44,-8,biomesoplenty:leaves_4:3)
Block(4,43,-8,biomesoplenty:leaves_4:3)
Block(4,46,-8,biomesoplenty:log_2:5)
Block(4,45,-8,biomesoplenty:leaves_4:3)
Block(4,40,-8,biomesoplenty:leaves_4:3)
Block(-9,40,-14,biomesoplenty:leaves_4:3)
Block(4,42,-8,biomesoplenty:leaves_4:3)
Block(-9,43,-14,biomesoplenty:leaves_4:3)
Block(4,41,-8,biomesoplenty:leaves_4:3)
Block(-9,42,-14,biomesoplenty:log_2:5)
Block(19,42,7,biomesoplenty:leaves_4:3)
Block(19,41,7,biomesoplenty:leaves_4:3)
Block(-8,45,-1,biomesoplenty:log_2:5)
Block(-8,46,-1,biomesoplenty:leaves_4:3)
Block(-8,47,-1,biomesoplenty:leaves_4:3)
Block(-8,48,-1,biomesoplenty:log_2:5)
Block(-8,49,-1,biomesoplenty:leaves_4:3)
Block(-8,40,-1,biomesoplenty:leaves_4:3)
Block(-8,41,-1,biomesoplenty:log_2:5)
Block(-8,42,-1,biomesoplenty:leaves_4:3)
Block(-8,43,-1,biomesoplenty:log_2:5)
Block(-8,44,-1,biomesoplenty:log_2:5)
Block(13,43,-1,biomesoplenty:leaves_4:3)
Block(13,42,-1,biomesoplenty:leaves_4:3)
Block(13,45,-1,biomesoplenty:leaves_4:3)
Block(6,41,-18,biomesoplenty:leaves_4:3)
Block(13,44,-1,biomesoplenty:log_2:5)
Block(6,42,-18,biomesoplenty:leaves_4:3)
Block(13,41,-1,biomesoplenty:leaves_4:3)
Block(13,40,-1,biomesoplenty:log_2:5)
Block(-7,51,-7,biomesoplenty:leaves_4:3)
Block(-7,50,-7,biomesoplenty:leaves_4:3)
Block(-1,37,0,biomesoplenty:log_2:5)
Block(-7,48,-7,biomesoplenty:leaves_4:3)
Block(-7,49,-7,biomesoplenty:leaves_4:3)
Block(-1,39,0,biomesoplenty:log_2:5)
Block(-7,44,-7,biomesoplenty:leaves_4:3)
Block(11,40,11,biomesoplenty:leaves_4:3)
Block(-7,45,-7,biomesoplenty:leaves_4:3)
Block(11,43,11,biomesoplenty:log_2:5)
Block(-7,46,-7,biomesoplenty:log_2:5)
Block(11,42,11,biomesoplenty:log_2:5)
Block(-7,47,-7,biomesoplenty:leaves_4:3)
Block(-8,50,-1,biomesoplenty:leaves_4:3)
Block(-8,51,-1,biomesoplenty:leaves_4:3)
Block(-16,42,-7,biomesoplenty:leaves_4:3)
Block(-16,43,-7,biomesoplenty:leaves_4:3)
Block(-16,40,-7,biomesoplenty:leaves_4:3)
Block(-16,41,-7,biomesoplenty:leaves_4:3)
Block(-2,48,10,biomesoplenty:leaves_4:3)
Block(-18,40,-7,biomesoplenty:leaves_4:3)
Block(-2,49,10,biomesoplenty:leaves_4:3)
Block(-2,47,10,biomesoplenty:leaves_4:3)
Block(-2,40,10,biomesoplenty:leaves_4:3)
Block(-2,41,10,biomesoplenty:leaves_4:3)
Block(11,44,11,biomesoplenty:leaves_4:3)
Block(6,49,-8,biomesoplenty:log_2:5)
Block(-2,44,10,biomesoplenty:leaves_4:3)
Block(-2,42,10,biomesoplenty:leaves_4:3)
Block(-4,51,6,biomesoplenty:leaves_4:3)
Block(-2,43,10,biomesoplenty:log_2:5)
Block(-4,50,6,biomesoplenty:leaves_4:3)
Block(6,42,-8,biomesoplenty:log_2:5)
Block(-14,42,1,biomesoplenty:leaves_4:3)
Block(6,41,-8,biomesoplenty:log_2:5)
Block(-14,41,1,biomesoplenty:leaves_4:3)
Block(6,44,-8,biomesoplenty:leaves_4:3)
Block(6,43,-8,biomesoplenty:leaves_4:3)
Block(6,46,-8,biomesoplenty:leaves_4:3)
Block(6,45,-8,biomesoplenty:leaves_4:3)
Block(-14,40,1,biomesoplenty:leaves_4:3)
Block(6,48,-8,biomesoplenty:leaves_4:3)
Block(6,47,-8,biomesoplenty:leaves_4:3)
Block(-4,49,6,biomesoplenty:leaves_4:3)
Block(-14,46,1,biomesoplenty:leaves_4:3)
Block(6,40,-8,biomesoplenty:leaves_4:3)
Block(-4,42,6,biomesoplenty:leaves_4:3)
Block(-4,41,6,biomesoplenty:leaves_4:3)
Block(-4,44,6,biomesoplenty:leaves_4:3)
Block(-4,43,6,biomesoplenty:leaves_4:3)
Block(-4,45,6,biomesoplenty:leaves_4:3)
Block(-4,48,6,biomesoplenty:leaves_4:3)
Block(-4,47,6,biomesoplenty:leaves_4:3)
Block(3,31,-1,biomesoplenty:log_2:5)
Block(4,42,15,biomesoplenty:leaves_4:3)
Block(3,33,-1,biomesoplenty:log_2:5)
Block(4,43,15,biomesoplenty:leaves_4:3)
Block(-4,40,6,biomesoplenty:leaves_4:3)
Block(-5,49,9,biomesoplenty:leaves_4:3)
Block(4,44,15,biomesoplenty:leaves_4:3)
Block(-5,48,9,biomesoplenty:leaves_4:3)
Block(-5,47,9,biomesoplenty:leaves_4:3)
Block(-5,46,9,biomesoplenty:leaves_4:3)
Block(-5,45,9,biomesoplenty:leaves_4:3)
Block(-5,44,9,biomesoplenty:leaves_4:3)
Block(-5,43,9,biomesoplenty:leaves_4:3)
Block(-5,42,9,biomesoplenty:leaves_4:3)
Block(-5,41,9,biomesoplenty:leaves_4:3)
Block(0,45,-10,biomesoplenty:leaves_4:3)
Block(0,44,-10,biomesoplenty:leaves_4:3)
Block(2,49,5,biomesoplenty:log_2:5)
Block(0,47,-10,biomesoplenty:leaves_4:3)
Block(2,48,5,biomesoplenty:leaves_4:3)
Block(0,46,-10,biomesoplenty:leaves_4:3)
Block(2,47,5,biomesoplenty:leaves_4:3)
Block(0,41,-10,biomesoplenty:leaves_4:3)
Block(2,46,5,biomesoplenty:leaves_4:3)
Block(0,40,-10,biomesoplenty:leaves_4:3)
Block(2,45,5,biomesoplenty:leaves_4:3)
Block(-3,31,-5,biomesoplenty:log_2:5)
Block(0,43,-10,biomesoplenty:leaves_4:3)
Block(2,44,5,biomesoplenty:log_2:5)
Block(-3,32,-5,biomesoplenty:log_2:5)
Block(0,42,-10,biomesoplenty:leaves_4:3)
Block(2,43,5,biomesoplenty:log_2:5)
Block(3,41,-1,biomesoplenty:log_2:5)
Block(3,42,-1,biomesoplenty:leaves_4:3)
Block(3,43,-1,biomesoplenty:leaves_4:3)
Block(3,44,-1,biomesoplenty:log_2:5)
Block(3,49,-1,biomesoplenty:log_2:5)
Block(3,45,-1,biomesoplenty:leaves_4:3)
Block(3,46,-1,biomesoplenty:leaves_4:3)
Block(3,47,-1,biomesoplenty:leaves_4:3)
Block(3,48,-1,biomesoplenty:leaves_4:3)
Block(2,42,5,biomesoplenty:leaves_4:3)
Block(2,41,5,biomesoplenty:leaves_4:3)
Block(2,40,5,biomesoplenty:leaves_4:3)
Block(-3,40,-5,biomesoplenty:leaves_4:3)
Block(-3,41,-5,biomesoplenty:log_2:5)
Block(-3,44,-5,biomesoplenty:leaves_4:3)
Block(-3,45,-5,biomesoplenty:leaves_4:3)
Block(0,51,-10,biomesoplenty:leaves_4:3)
Block(-3,42,-5,biomesoplenty:leaves_4:3)
Block(-3,43,-5,biomesoplenty:leaves_4:3)
Block(0,50,-10,biomesoplenty:leaves_4:3)
Block(3,50,-1,biomesoplenty:log_2:5)
Block(3,51,-1,biomesoplenty:leaves_4:3)
Block(-3,40,-17,biomesoplenty:leaves_4:3)
Block(9,40,11,biomesoplenty:leaves_4:3)
Block(-3,42,-17,biomesoplenty:leaves_4:3)
Block(9,42,11,biomesoplenty:leaves_4:3)
Block(-3,41,-17,biomesoplenty:leaves_4:3)
Block(9,44,11,biomesoplenty:leaves_4:3)
Block(-3,38,-5,biomesoplenty:log_2:5)
Block(9,43,11,biomesoplenty:leaves_4:3)
Block(9,46,11,biomesoplenty:leaves_4:3)
Block(2,51,5,biomesoplenty:leaves_4:3)
Block(9,45,11,biomesoplenty:leaves_4:3)
Block(2,50,5,biomesoplenty:leaves_4:3)
Block(9,48,11,biomesoplenty:leaves_4:3)
Block(0,49,-10,biomesoplenty:leaves_4:3)
Block(9,47,11,biomesoplenty:leaves_4:3)
Block(0,48,-10,biomesoplenty:leaves_4:3)
Block(6,50,-8,biomesoplenty:leaves_4:3)
Block(-3,51,-5,biomesoplenty:leaves_4:3)
Block(9,41,-15,biomesoplenty:leaves_4:3)
Block(-3,50,-5,biomesoplenty:leaves_4:3)
Block(1,39,-1,biomesoplenty:log_2:5)
Block(9,44,-15,biomesoplenty:leaves_4:3)
Block(1,38,-1,biomesoplenty:log_2:5)
Block(9,45,-15,biomesoplenty:leaves_4:3)
Block(1,37,-1,biomesoplenty:log_2:5)
Block(9,42,-15,biomesoplenty:leaves_4:3)
Block(1,36,-1,biomesoplenty:log_2:5)
Block(9,43,-15,biomesoplenty:leaves_4:3)
Block(-2,50,7,biomesoplenty:leaves_4:3)
Block(16,44,-8,biomesoplenty:leaves_4:3)
Block(16,43,-8,biomesoplenty:leaves_4:3)
Block(16,42,-8,biomesoplenty:leaves_4:3)
Block(14,40,4,biomesoplenty:leaves_4:3)
Block(14,41,4,biomesoplenty:leaves_4:3)
Block(-2,48,7,biomesoplenty:leaves_4:3)
Block(-2,49,7,biomesoplenty:leaves_4:3)
Block(1,35,-1,biomesoplenty:log_2:5)
Block(-3,48,-5,biomesoplenty:leaves_4:3)
Block(1,34,-1,biomesoplenty:log_2:5)
Block(-3,49,-5,biomesoplenty:leaves_4:3)
Block(1,33,-1,biomesoplenty:log_2:5)
Block(9,46,-15,biomesoplenty:leaves_4:3)
Block(-3,46,-5,biomesoplenty:leaves_4:3)
Block(1,32,-1,biomesoplenty:log_2:5)
Block(-3,47,-5,biomesoplenty:leaves_4:3)
Block(1,31,-1,biomesoplenty:log_2:5)
Block(1,30,-1,biomesoplenty:log_2:5)
Block(0,50,6,biomesoplenty:leaves_4:3)
Block(1,29,-1,biomesoplenty:log_2:5)
Block(0,51,6,biomesoplenty:leaves_4:3)
Block(1,28,-1,biomesoplenty:log_2:5)
Block(1,27,-1,biomesoplenty:log_2:5)
Block(1,26,-1,biomesoplenty:log_2:5)
Block(1,25,-1,biomesoplenty:log_2:5)
Block(14,44,4,biomesoplenty:leaves_4:3)
Block(14,46,4,biomesoplenty:leaves_4:3)
Block(14,45,4,biomesoplenty:leaves_4:3)
Block(14,47,4,biomesoplenty:leaves_4:3)
Block(1,24,-1,biomesoplenty:log_2:5)
Block(1,23,-1,biomesoplenty:log_2:5)
Block(1,22,-1,biomesoplenty:log_2:5)
Block(1,21,-1,biomesoplenty:log_2:5)
Block(1,20,-1,biomesoplenty:log_2:5)
Block(3,44,8,biomesoplenty:leaves_4:3)
Block(3,43,8,biomesoplenty:leaves_4:3)
Block(0,41,6,biomesoplenty:log_2:5)
Block(3,46,8,biomesoplenty:leaves_4:3)
Block(0,40,6,biomesoplenty:log_2:5)
Block(3,45,8,biomesoplenty:leaves_4:3)
Block(3,41,8,biomesoplenty:leaves_4:3)
Block(0,47,6,biomesoplenty:leaves_4:3)
Block(0,46,6,biomesoplenty:leaves_4:3)
Block(0,49,6,biomesoplenty:leaves_4:3)
Block(0,48,6,biomesoplenty:leaves_4:3)
Block(0,43,6,biomesoplenty:leaves_4:3)
Block(3,48,8,biomesoplenty:log_2:5)
Block(0,42,6,biomesoplenty:leaves_4:3)
Block(3,47,8,biomesoplenty:leaves_4:3)
Block(0,45,6,biomesoplenty:leaves_4:3)
Block(1,51,-1,biomesoplenty:leaves_4:3)
Block(0,44,6,biomesoplenty:leaves_4:3)
Block(3,49,8,biomesoplenty:leaves_4:3)
Block(1,50,-1,biomesoplenty:leaves_4:3)
Block(-5,49,-5,biomesoplenty:leaves_4:3)
Block(-5,48,-5,biomesoplenty:leaves_4:3)
Block(-5,47,-5,biomesoplenty:leaves_4:3)
Block(-5,46,-5,biomesoplenty:leaves_4:3)
Block(1,49,-1,biomesoplenty:leaves_4:3)
Block(3,50,8,biomesoplenty:leaves_4:3)
Block(-5,45,-5,biomesoplenty:log_2:5)
Block(1,48,-1,biomesoplenty:leaves_4:3)
Block(-5,44,-5,biomesoplenty:log_2:5)
Block(1,47,-1,biomesoplenty:leaves_4:3)
Block(-2,40,7,biomesoplenty:leaves_4:3)
Block(-2,41,7,biomesoplenty:leaves_4:3)
Block(-2,42,7,biomesoplenty:leaves_4:3)
Block(-2,43,7,biomesoplenty:leaves_4:3)
Block(-2,50,10,biomesoplenty:leaves_4:3)
Block(-2,44,7,biomesoplenty:leaves_4:3)
Block(-4,45,-16,biomesoplenty:leaves_4:3)
Block(-2,45,7,biomesoplenty:log_2:5)
Block(-4,46,-16,biomesoplenty:leaves_4:3)
Block(-2,46,7,biomesoplenty:leaves_4:3)
Block(-2,47,7,biomesoplenty:leaves_4:3)
Block(0,39,6,biomesoplenty:log_2:5)
Block(1,46,-1,biomesoplenty:leaves_4:3)
Block(1,45,-1,biomesoplenty:log_2:5)
Block(0,38,6,biomesoplenty:log_2:5)
Block(1,44,-1,biomesoplenty:log_2:5)
Block(1,43,-1,biomesoplenty:log_2:5)
Block(-5,51,-5,biomesoplenty:leaves_4:3)
Block(1,42,-1,biomesoplenty:log_2:5)
Block(-5,50,-5,biomesoplenty:leaves_4:3)
Block(1,41,-1,biomesoplenty:log_2:5)
Block(1,40,-1,biomesoplenty:log_2:5)
Block(5,29,-7,biomesoplenty:log_2:5)
Block(7,51,-4,biomesoplenty:leaves_4:3)
Block(7,50,-4,biomesoplenty:leaves_4:3)
Block(-15,40,12,biomesoplenty:leaves_4:3)
Block(-15,41,12,biomesoplenty:leaves_4:3)
Block(-7,50,-2,biomesoplenty:leaves_4:3)
Block(-7,51,-2,biomesoplenty:leaves_4:3)
Block(16,41,15,biomesoplenty:leaves_4:3)
Block(17,40,8,biomesoplenty:leaves_4:3)
Block(17,41,8,biomesoplenty:leaves_4:3)
Block(-12,42,-4,biomesoplenty:leaves_4:3)
Block(-12,43,-4,biomesoplenty:leaves_4:3)
Block(-12,44,-4,biomesoplenty:log_2:5)
Block(-12,45,-4,biomesoplenty:leaves_4:3)
Block(-12,46,-4,biomesoplenty:leaves_4:3)
Block(17,42,8,biomesoplenty:leaves_4:3)
Block(3,-2,-1,biomesoplenty:log_2:5)
Block(3,-3,-1,biomesoplenty:log_2:5)
Block(3,-4,-1,biomesoplenty:log_2:5)
Block(3,-1,-1,biomesoplenty:log_2:5)
Block(1,-2,3,biomesoplenty:log_2:5)
Block(1,-4,3,biomesoplenty:log_2:5)
Block(1,-3,3,biomesoplenty:log_2:5)
Block(7,42,11,biomesoplenty:leaves_4:3)
Block(7,41,11,biomesoplenty:leaves_4:3)
Block(4,51,-3,biomesoplenty:leaves_4:3)
Block(7,44,11,biomesoplenty:leaves_4:3)
Block(4,50,-3,biomesoplenty:log_2:5)
Block(-8,41,-6,biomesoplenty:log_2:5)
Block(7,40,11,biomesoplenty:leaves_4:3)
Block(7,46,11,biomesoplenty:leaves_4:3)
Block(7,45,11,biomesoplenty:leaves_4:3)
Block(7,48,11,biomesoplenty:leaves_4:3)
Block(7,47,11,biomesoplenty:leaves_4:3)
Block(-8,42,-12,biomesoplenty:leaves_4:3)
Block(-8,41,-12,biomesoplenty:leaves_4:3)
Block(-8,40,-12,biomesoplenty:log_2:5)
Block(0,-4,1,biomesoplenty:log_2:5)
Block(0,-3,1,biomesoplenty:log_2:5)
Block(0,-2,1,biomesoplenty:log_2:5)
Block(1,41,14,biomesoplenty:leaves_4:3)
Block(1,40,14,biomesoplenty:leaves_4:3)
Block(1,43,14,biomesoplenty:leaves_4:3)
Block(1,42,14,biomesoplenty:leaves_4:3)
Block(1,45,14,biomesoplenty:leaves_4:3)
Block(1,44,14,biomesoplenty:leaves_4:3)
Block(4,40,-3,biomesoplenty:log_2:5)
Block(4,45,-3,biomesoplenty:log_2:5)
Block(4,44,-3,biomesoplenty:leaves_4:3)
Block(4,42,-3,biomesoplenty:leaves_4:3)
Block(15,45,-6,biomesoplenty:leaves_4:3)
Block(-18,41,8,biomesoplenty:leaves_4:3)
Block(-18,40,8,biomesoplenty:leaves_4:3)
Block(15,48,-6,biomesoplenty:leaves_4:3)
Block(15,42,-6,biomesoplenty:log_2:5)
Block(15,43,-6,biomesoplenty:leaves_4:3)
Block(15,44,-6,biomesoplenty:leaves_4:3)
Block(-8,44,-6,biomesoplenty:leaves_4:3)
Block(4,49,-3,biomesoplenty:log_2:5)
Block(-8,45,-6,biomesoplenty:leaves_4:3)
Block(4,48,-3,biomesoplenty:leaves_4:3)
Block(-8,42,-6,biomesoplenty:leaves_4:3)
Block(4,47,-3,biomesoplenty:log_2:5)
Block(15,40,-6,biomesoplenty:leaves_4:3)
Block(-8,43,-6,biomesoplenty:leaves_4:3)
Block(4,46,-3,biomesoplenty:leaves_4:3)
Block(19,40,-12,biomesoplenty:leaves_4:3)
Block(-8,48,-6,biomesoplenty:leaves_4:3)
Block(19,41,-12,biomesoplenty:leaves_4:3)
Block(-8,49,-6,biomesoplenty:leaves_4:3)
Block(-8,46,-6,biomesoplenty:leaves_4:3)
Block(-8,47,-6,biomesoplenty:leaves_4:3)
Block(-1,40,5,biomesoplenty:leaves_4:3)
Block(13,44,7,biomesoplenty:leaves_4:3)
Block(5,49,-7,biomesoplenty:leaves_4:3)
Block(-1,44,5,biomesoplenty:leaves_4:3)
Block(-1,41,5,biomesoplenty:leaves_4:3)
Block(-1,42,5,biomesoplenty:leaves_4:3)
Block(-14,42,7,biomesoplenty:leaves_4:3)
Block(-14,40,7,biomesoplenty:leaves_4:3)
Block(4,42,-17,biomesoplenty:leaves_4:3)
Block(-18,42,-1,biomesoplenty:leaves_4:3)
Block(4,41,-17,biomesoplenty:leaves_4:3)
Block(-7,41,-2,biomesoplenty:leaves_4:3)
Block(1,42,-17,biomesoplenty:leaves_4:3)
Block(-7,42,-2,biomesoplenty:leaves_4:3)
Block(1,43,-17,biomesoplenty:leaves_4:3)
Block(1,40,-17,biomesoplenty:leaves_4:3)
Block(-7,40,-2,biomesoplenty:leaves_4:3)
Block(1,41,-17,biomesoplenty:leaves_4:3)
Block(5,40,-7,biomesoplenty:log_2:5)
Block(4,44,-17,biomesoplenty:leaves_4:3)
Block(-18,44,-1,biomesoplenty:leaves_4:3)
Block(-7,45,-2,biomesoplenty:leaves_4:3)
Block(4,43,-17,biomesoplenty:leaves_4:3)
Block(-18,45,-1,biomesoplenty:leaves_4:3)
Block(-7,46,-2,biomesoplenty:leaves_4:3)
Block(-7,43,-2,biomesoplenty:leaves_4:3)
Block(-14,44,7,biomesoplenty:leaves_4:3)
Block(-14,43,7,biomesoplenty:leaves_4:3)
Block(-7,44,-2,biomesoplenty:leaves_4:3)
Block(-1,36,5,biomesoplenty:log_2:5)
Block(5,44,-7,biomesoplenty:leaves_4:3)
Block(-7,49,-2,biomesoplenty:log_2:5)
Block(5,43,-7,biomesoplenty:log_2:5)
Block(5,42,-7,biomesoplenty:leaves_4:3)
Block(-7,47,-2,biomesoplenty:leaves_4:3)
Block(5,41,-7,biomesoplenty:leaves_4:3)
Block(-7,48,-2,biomesoplenty:leaves_4:3)
Block(5,48,-7,biomesoplenty:leaves_4:3)
Block(5,47,-7,biomesoplenty:leaves_4:3)
Block(5,46,-7,biomesoplenty:log_2:5)
Block(5,45,-7,biomesoplenty:leaves_4:3)
Block(-1,50,5,biomesoplenty:leaves_4:3)
Block(-1,51,5,biomesoplenty:leaves_4:3)
Block(2,41,18,biomesoplenty:leaves_4:3)
Block(-7,41,-13,biomesoplenty:leaves_4:3)
Block(-7,42,-13,biomesoplenty:leaves_4:3)
Block(-5,47,12,biomesoplenty:leaves_4:3)
Block(5,51,-7,biomesoplenty:leaves_4:3)
Block(-7,40,-13,biomesoplenty:leaves_4:3)
Block(-5,48,12,biomesoplenty:leaves_4:3)
Block(5,50,-7,biomesoplenty:leaves_4:3)
Block(-5,46,12,biomesoplenty:leaves_4:3)
Block(-5,43,12,biomesoplenty:leaves_4:3)
Block(-1,47,5,biomesoplenty:leaves_4:3)
Block(-5,44,12,biomesoplenty:leaves_4:3)
Block(-1,48,5,biomesoplenty:leaves_4:3)
Block(-5,41,12,biomesoplenty:leaves_4:3)
Block(-1,45,5,biomesoplenty:leaves_4:3)
Block(-5,42,12,biomesoplenty:leaves_4:3)
Block(-1,46,5,biomesoplenty:leaves_4:3)
Block(13,47,7,biomesoplenty:leaves_4:3)
Block(-5,40,12,biomesoplenty:leaves_4:3)
Block(2,40,18,biomesoplenty:leaves_4:3)
Block(-1,49,5,biomesoplenty:leaves_4:3)
Block(13,46,7,biomesoplenty:leaves_4:3)
Block(11,40,-6,biomesoplenty:log_2:5)
Block(12,44,-5,biomesoplenty:leaves_4:3)
Block(12,43,-5,biomesoplenty:leaves_4:3)
Block(12,46,-5,biomesoplenty:leaves_4:3)
Block(19,40,1,biomesoplenty:leaves_4:3)
Block(19,41,1,biomesoplenty:leaves_4:3)
Block(11,44,-6,biomesoplenty:leaves_4:3)
Block(12,48,-5,biomesoplenty:leaves_4:3)
Block(19,42,1,biomesoplenty:leaves_4:3)
Block(11,43,-6,biomesoplenty:leaves_4:3)
Block(12,47,-5,biomesoplenty:leaves_4:3)
Block(11,42,-6,biomesoplenty:leaves_4:3)
Block(19,43,1,biomesoplenty:leaves_4:3)
Block(11,41,-6,biomesoplenty:leaves_4:3)
Block(19,44,1,biomesoplenty:leaves_4:3)
Block(12,49,-5,biomesoplenty:leaves_4:3)
Block(11,48,-6,biomesoplenty:leaves_4:3)
Block(11,46,-6,biomesoplenty:leaves_4:3)
Block(12,40,-5,biomesoplenty:leaves_4:3)
Block(12,42,-5,biomesoplenty:leaves_4:3)
Block(12,41,-5,biomesoplenty:leaves_4:3)
Block(1,41,3,biomesoplenty:leaves_4:3)
Block(4,41,10,biomesoplenty:leaves_4:3)
Block(1,40,3,biomesoplenty:leaves_4:3)
Block(4,42,10,biomesoplenty:leaves_4:3)
Block(1,43,3,biomesoplenty:log_2:5)
Block(-10,48,-9,biomesoplenty:leaves_4:3)
Block(4,40,10,biomesoplenty:leaves_4:3)
Block(1,42,3,biomesoplenty:leaves_4:3)
Block(1,45,3,biomesoplenty:leaves_4:3)
Block(4,45,10,biomesoplenty:leaves_4:3)
Block(-10,46,-9,biomesoplenty:leaves_4:3)
Block(1,44,3,biomesoplenty:leaves_4:3)
Block(4,46,10,biomesoplenty:leaves_4:3)
Block(-10,47,-9,biomesoplenty:leaves_4:3)
Block(-1,41,-16,biomesoplenty:leaves_4:3)
Block(4,43,10,biomesoplenty:leaves_4:3)
Block(-10,44,-9,biomesoplenty:leaves_4:3)
Block(1,47,3,biomesoplenty:leaves_4:3)
Block(-1,40,-16,biomesoplenty:leaves_4:3)
Block(-15,40,9,biomesoplenty:leaves_4:3)
Block(4,44,10,biomesoplenty:leaves_4:3)
Block(1,46,3,biomesoplenty:leaves_4:3)
Block(1,49,3,biomesoplenty:log_2:5)
Block(1,50,-7,biomesoplenty:log_2:5)
Block(-12,42,-12,biomesoplenty:leaves_4:3)
Block(1,48,3,biomesoplenty:log_2:5)
Block(1,51,-7,biomesoplenty:leaves_4:3)
Block(-12,41,-12,biomesoplenty:leaves_4:3)
Block(4,47,10,biomesoplenty:leaves_4:3)
Block(-12,40,-12,biomesoplenty:leaves_4:3)
Block(4,48,10,biomesoplenty:leaves_4:3)
Block(16,42,8,biomesoplenty:leaves_4:3)
Block(16,41,8,biomesoplenty:leaves_4:3)
Block(16,43,8,biomesoplenty:leaves_4:3)
Block(7,42,-14,biomesoplenty:leaves_4:3)
Block(-10,42,-9,biomesoplenty:log_2:5)
Block(-1,43,-16,biomesoplenty:leaves_4:3)
Block(7,41,-14,biomesoplenty:leaves_4:3)
Block(-1,42,-16,biomesoplenty:leaves_4:3)
Block(-10,43,-9,biomesoplenty:leaves_4:3)
Block(-10,40,-9,biomesoplenty:leaves_4:3)
Block(16,40,8,biomesoplenty:leaves_4:3)
Block(-10,41,-9,biomesoplenty:leaves_4:3)
Block(1,47,-7,biomesoplenty:log_2:5)
Block(-4,47,13,biomesoplenty:leaves_4:3)
Block(1,48,-7,biomesoplenty:leaves_4:3)
Block(-4,48,13,biomesoplenty:leaves_4:3)
Block(1,45,-7,biomesoplenty:log_2:5)
Block(1,46,-7,biomesoplenty:leaves_4:3)
Block(7,46,-14,biomesoplenty:leaves_4:3)
Block(1,33,3,biomesoplenty:log_2:5)
Block(7,45,-14,biomesoplenty:leaves_4:3)
Block(7,44,-14,biomesoplenty:leaves_4:3)
Block(1,49,-7,biomesoplenty:leaves_4:3)
Block(7,43,-14,biomesoplenty:leaves_4:3)
Block(-3,41,4,biomesoplenty:leaves_4:3)
Block(1,40,-7,biomesoplenty:leaves_4:3)
Block(-3,40,4,biomesoplenty:leaves_4:3)
Block(1,43,-7,biomesoplenty:leaves_4:3)
Block(-3,45,4,biomesoplenty:log_2:5)
Block(1,44,-7,biomesoplenty:leaves_4:3)
Block(-3,44,4,biomesoplenty:leaves_4:3)
Block(1,41,-7,biomesoplenty:leaves_4:3)
Block(-3,43,4,biomesoplenty:leaves_4:3)
Block(-4,45,13,biomesoplenty:leaves_4:3)
Block(1,42,-7,biomesoplenty:leaves_4:3)
Block(-3,42,4,biomesoplenty:leaves_4:3)
Block(-4,46,13,biomesoplenty:leaves_4:3)
Block(-3,49,4,biomesoplenty:leaves_4:3)
Block(-3,48,4,biomesoplenty:leaves_4:3)
Block(-3,47,4,biomesoplenty:leaves_4:3)
Block(-3,46,4,biomesoplenty:leaves_4:3)
Block(-1,-2,-2,biomesoplenty:log_2:5)
Block(-1,-3,-2,biomesoplenty:log_2:5)
Block(-1,-4,-2,biomesoplenty:log_2:5)
Block(-3,51,4,biomesoplenty:leaves_4:3)
Block(-3,50,4,biomesoplenty:log_2:5)
Block(-8,47,-12,biomesoplenty:leaves_4:3)
Block(-8,46,-12,biomesoplenty:leaves_4:3)
Block(1,50,3,biomesoplenty:leaves_4:3)
Block(1,51,3,biomesoplenty:leaves_4:3)
Block(-1,42,-2,biomesoplenty:leaves_4:3)
Block(-2,42,2,biomesoplenty:leaves_4:3)
Block(-1,43,-2,biomesoplenty:leaves_4:3)
Block(-1,44,-2,biomesoplenty:leaves_4:3)
Block(-1,40,-2,biomesoplenty:leaves_4:3)
Block(14,42,-2,biomesoplenty:leaves_4:3)
Block(0,51,1,biomesoplenty:leaves_4:3)
Block(14,43,-2,biomesoplenty:leaves_4:3)
Block(0,50,1,biomesoplenty:leaves_4:3)
Block(14,44,-2,biomesoplenty:log_2:5)
Block(-12,42,11,biomesoplenty:leaves_4:3)
Block(14,45,-2,biomesoplenty:leaves_4:3)
Block(-12,41,11,biomesoplenty:leaves_4:3)
Block(-12,40,11,biomesoplenty:leaves_4:3)
Block(14,40,-2,biomesoplenty:leaves_4:3)
Block(14,41,-2,biomesoplenty:leaves_4:3)
Block(14,46,-2,biomesoplenty:leaves_4:3)
Block(14,47,-2,biomesoplenty:leaves_4:3)
Block(-1,49,-2,biomesoplenty:leaves_4:3)
Block(-2,49,2,biomesoplenty:leaves_4:3)
Block(-2,47,2,biomesoplenty:leaves_4:3)
Block(-2,48,2,biomesoplenty:leaves_4:3)
Block(-1,45,-2,biomesoplenty:log_2:5)
Block(-2,45,2,biomesoplenty:leaves_4:3)
Block(-1,46,-2,biomesoplenty:leaves_4:3)
Block(-2,46,2,biomesoplenty:leaves_4:3)
Block(-2,43,2,biomesoplenty:leaves_4:3)
Block(-1,47,-2,biomesoplenty:leaves_4:3)
Block(-2,44,2,biomesoplenty:leaves_4:3)
Block(-1,48,-2,biomesoplenty:leaves_4:3)
Block(0,48,1,biomesoplenty:leaves_4:3)
Block(0,47,1,biomesoplenty:leaves_4:3)
Block(0,46,1,biomesoplenty:leaves_4:3)
Block(-2,50,2,biomesoplenty:leaves_4:3)
Block(0,45,1,biomesoplenty:leaves_4:3)
Block(-2,51,2,biomesoplenty:leaves_4:3)
Block(-1,50,-2,biomesoplenty:log_2:5)
Block(0,49,1,biomesoplenty:log_2:5)
Block(-1,51,-2,biomesoplenty:leaves_4:3)
Block(0,40,1,biomesoplenty:leaves_4:3)
Block(0,44,1,biomesoplenty:leaves_4:3)
Block(0,43,1,biomesoplenty:log_2:5)
Block(0,42,1,biomesoplenty:leaves_4:3)
Block(-2,43,-15,biomesoplenty:leaves_4:3)
Block(-2,42,-15,biomesoplenty:leaves_4:3)
Block(8,40,-3,biomesoplenty:leaves_4:3)
Block(-2,45,-15,biomesoplenty:leaves_4:3)
Block(8,41,-3,biomesoplenty:leaves_4:3)
Block(-2,47,-15,biomesoplenty:leaves_4:3)
Block(-2,46,-15,biomesoplenty:leaves_4:3)
Block(8,46,-3,biomesoplenty:leaves_4:3)
Block(8,47,-3,biomesoplenty:leaves_4:3)
Block(0,35,1,biomesoplenty:log_2:5)
Block(8,48,-3,biomesoplenty:leaves_4:3)
Block(0,34,1,biomesoplenty:log_2:5)
Block(8,49,-3,biomesoplenty:leaves_4:3)
Block(-8,40,13,biomesoplenty:leaves_4:3)
Block(-15,42,-5,biomesoplenty:leaves_4:3)
Block(8,42,-3,biomesoplenty:leaves_4:3)
Block(-15,41,-5,biomesoplenty:leaves_4:3)
Block(8,43,-3,biomesoplenty:leaves_4:3)
Block(-15,40,-5,biomesoplenty:leaves_4:3)
Block(-8,42,13,biomesoplenty:leaves_4:3)
Block(8,44,-3,biomesoplenty:leaves_4:3)
Block(-8,41,13,biomesoplenty:leaves_4:3)
Block(8,45,-3,biomesoplenty:leaves_4:3)
Block(-8,44,13,biomesoplenty:leaves_4:3)
Block(-15,46,-5,biomesoplenty:leaves_4:3)
Block(-8,43,13,biomesoplenty:leaves_4:3)
Block(-15,43,-5,biomesoplenty:leaves_4:3)
Block(0,32,1,biomesoplenty:log_2:5)
Block(0,31,1,biomesoplenty:log_2:5)
Block(14,43,9,biomesoplenty:leaves_4:3)
Block(14,42,9,biomesoplenty:leaves_4:3)
Block(8,50,-3,biomesoplenty:leaves_4:3)
Block(14,41,9,biomesoplenty:leaves_4:3)
Block(7,48,-4,biomesoplenty:leaves_4:3)
Block(7,49,-4,biomesoplenty:leaves_4:3)
Block(7,46,-4,biomesoplenty:leaves_4:3)
Block(7,47,-4,biomesoplenty:leaves_4:3)
Block(7,44,-4,biomesoplenty:leaves_4:3)
Block(7,45,-4,biomesoplenty:leaves_4:3)
Block(-2,41,16,biomesoplenty:leaves_4:3)
Block(7,42,-4,biomesoplenty:leaves_4:3)
Block(-2,40,16,biomesoplenty:leaves_4:3)
Block(7,43,-4,biomesoplenty:leaves_4:3)
Block(11,44,-14,biomesoplenty:leaves_4:3)
Block(7,40,-4,biomesoplenty:leaves_4:3)
Block(7,41,-4,biomesoplenty:leaves_4:3)
Block(-2,41,-15,biomesoplenty:leaves_4:3)
Block(-2,40,-15,biomesoplenty:leaves_4:3)
Block(11,41,-14,biomesoplenty:leaves_4:3)
Block(11,40,-14,biomesoplenty:leaves_4:3)
Block(11,43,-14,biomesoplenty:leaves_4:3)
Block(11,42,-14,biomesoplenty:leaves_4:3)
Block(-4,41,-6,biomesoplenty:leaves_4:3)
Block(-4,40,-6,biomesoplenty:leaves_4:3)
Block(-4,43,-6,biomesoplenty:log_2:5)
Block(-4,42,-6,biomesoplenty:log_2:5)
Block(-4,45,-6,biomesoplenty:log_2:5)
Block(-4,44,-6,biomesoplenty:leaves_4:3)
Block(-4,47,-6,biomesoplenty:leaves_4:3)
Block(6,47,9,biomesoplenty:leaves_4:3)
Block(-4,46,-6,biomesoplenty:leaves_4:3)
Block(-4,49,-6,biomesoplenty:leaves_4:3)
Block(-4,48,-6,biomesoplenty:leaves_4:3)
Block(6,43,9,biomesoplenty:leaves_4:3)
Block(6,44,9,biomesoplenty:leaves_4:3)
Block(6,45,9,biomesoplenty:leaves_4:3)
Block(6,41,9,biomesoplenty:leaves_4:3)
Block(6,42,9,biomesoplenty:leaves_4:3)
Block(-12,44,8,biomesoplenty:leaves_4:3)
Block(-12,42,8,biomesoplenty:log_2:5)
Block(-12,43,8,biomesoplenty:leaves_4:3)
Block(-12,40,8,biomesoplenty:log_2:5)
Block(-12,41,8,biomesoplenty:leaves_4:3)
Block(10,41,-18,biomesoplenty:leaves_4:3)
Block(-4,50,-6,biomesoplenty:leaves_4:3)
Block(10,42,-18,biomesoplenty:leaves_4:3)
Block(-4,51,-6,biomesoplenty:leaves_4:3)
Block(0,5,-1,biomesoplenty:log_2:5)
Block(17,44,-9,biomesoplenty:leaves_4:3)
Block(0,4,-1,biomesoplenty:log_2:5)
Block(0,7,-1,biomesoplenty:log_2:5)
Block(0,6,-1,biomesoplenty:log_2:5)
Block(17,43,-9,biomesoplenty:leaves_4:3)
Block(0,9,-1,biomesoplenty:log_2:5)
Block(0,8,-1,biomesoplenty:log_2:5)
Block(8,41,-13,biomesoplenty:leaves_4:3)
Block(8,42,-13,biomesoplenty:leaves_4:3)
Block(11,40,8,biomesoplenty:leaves_4:3)
Block(-6,46,-11,biomesoplenty:leaves_4:3)
Block(11,41,8,biomesoplenty:leaves_4:3)
Block(11,42,8,biomesoplenty:leaves_4:3)
Block(11,43,8,biomesoplenty:leaves_4:3)
Block(0,1,-1,biomesoplenty:log_2:5)
Block(-6,42,-11,biomesoplenty:leaves_4:3)
Block(0,0,-1,biomesoplenty:log_2:5)
Block(-6,43,-11,biomesoplenty:leaves_4:3)
Block(0,3,-1,biomesoplenty:log_2:5)
Block(0,2,-1,biomesoplenty:log_2:5)
Block(12,44,12,biomesoplenty:leaves_4:3)
Block(6,47,10,biomesoplenty:leaves_4:3)
Block(6,48,10,biomesoplenty:leaves_4:3)
Block(6,45,10,biomesoplenty:leaves_4:3)
Block(6,46,10,biomesoplenty:leaves_4:3)
Block(8,43,-13,biomesoplenty:leaves_4:3)
Block(6,43,10,biomesoplenty:leaves_4:3)
Block(8,44,-13,biomesoplenty:log_2:5)
Block(6,44,10,biomesoplenty:leaves_4:3)
Block(6,41,10,biomesoplenty:leaves_4:3)
Block(17,44,-11,biomesoplenty:leaves_4:3)
Block(8,45,-13,biomesoplenty:leaves_4:3)
Block(6,42,10,biomesoplenty:leaves_4:3)
Block(17,43,-11,biomesoplenty:leaves_4:3)
Block(8,46,-13,biomesoplenty:leaves_4:3)
Block(6,40,10,biomesoplenty:leaves_4:3)
Block(17,41,-11,biomesoplenty:leaves_4:3)
Block(17,40,-11,biomesoplenty:leaves_4:3)
Block(12,42,12,biomesoplenty:leaves_4:3)
Block(12,43,12,biomesoplenty:leaves_4:3)
Block(-6,40,-11,biomesoplenty:leaves_4:3)
Block(-11,47,-5,biomesoplenty:leaves_4:3)
Block(-11,48,-5,biomesoplenty:leaves_4:3)
Block(-11,41,-5,biomesoplenty:leaves_4:3)
Block(-11,42,-5,biomesoplenty:leaves_4:3)
Block(-11,40,-5,biomesoplenty:leaves_4:3)
Block(8,36,-13,biomesoplenty:log_2:5)
Block(-11,45,-5,biomesoplenty:leaves_4:3)
Block(-11,46,-5,biomesoplenty:leaves_4:3)
Block(-11,43,-5,biomesoplenty:leaves_4:3)
Block(-11,44,-5,biomesoplenty:leaves_4:3)
Block(8,46,10,biomesoplenty:leaves_4:3)
Block(8,45,10,biomesoplenty:leaves_4:3)
Block(8,44,10,biomesoplenty:leaves_4:3)
Block(8,43,10,biomesoplenty:leaves_4:3)
Block(8,48,10,biomesoplenty:leaves_4:3)
Block(8,47,10,biomesoplenty:log_2:5)
Block(8,42,10,biomesoplenty:leaves_4:3)
Block(8,40,10,biomesoplenty:leaves_4:3)
Block(-5,45,-12,biomesoplenty:leaves_4:3)
Block(0,40,18,biomesoplenty:leaves_4:3)
Block(0,43,-15,biomesoplenty:leaves_4:3)
Block(-5,44,-12,biomesoplenty:leaves_4:3)
Block(0,42,-15,biomesoplenty:leaves_4:3)
Block(-5,43,-12,biomesoplenty:leaves_4:3)
Block(0,41,-15,biomesoplenty:leaves_4:3)
Block(-5,42,-12,biomesoplenty:leaves_4:3)
Block(0,40,-15,biomesoplenty:leaves_4:3)
Block(7,48,3,biomesoplenty:leaves_4:3)
Block(-5,48,-12,biomesoplenty:leaves_4:3)
Block(7,49,3,biomesoplenty:leaves_4:3)
Block(7,46,3,biomesoplenty:log_2:5)
Block(-5,47,-12,biomesoplenty:leaves_4:3)
Block(7,47,3,biomesoplenty:leaves_4:3)
Block(7,44,3,biomesoplenty:leaves_4:3)
Block(11,48,8,biomesoplenty:leaves_4:3)
Block(7,45,3,biomesoplenty:leaves_4:3)
Block(11,49,8,biomesoplenty:leaves_4:3)
Block(3,-2,2,biomesoplenty:log_2:5)
Block(7,42,3,biomesoplenty:log_2:5)
Block(3,-3,2,biomesoplenty:log_2:5)
Block(-14,41,-13,biomesoplenty:leaves_4:3)
Block(7,43,3,biomesoplenty:leaves_4:3)
Block(7,40,3,biomesoplenty:leaves_4:3)
Block(7,41,3,biomesoplenty:leaves_4:3)
Block(-9,42,4,biomesoplenty:leaves_4:3)
Block(11,46,8,biomesoplenty:leaves_4:3)
Block(-9,43,4,biomesoplenty:leaves_4:3)
Block(-9,44,4,biomesoplenty:leaves_4:3)
Block(-9,45,4,biomesoplenty:log_2:5)
Block(-9,46,4,biomesoplenty:leaves_4:3)
Block(-9,47,4,biomesoplenty:leaves_4:3)
Block(-9,48,4,biomesoplenty:leaves_4:3)
Block(-9,49,4,biomesoplenty:leaves_4:3)
Block(-11,42,-13,biomesoplenty:leaves_4:3)
Block(-11,41,-13,biomesoplenty:leaves_4:3)
Block(-17,40,-8,biomesoplenty:leaves_4:3)
Block(-17,43,-8,biomesoplenty:leaves_4:3)
Block(2,42,-16,biomesoplenty:leaves_4:3)
Block(2,43,-16,biomesoplenty:leaves_4:3)
Block(2,40,-16,biomesoplenty:leaves_4:3)
Block(2,41,-16,biomesoplenty:leaves_4:3)
Block(15,45,6,biomesoplenty:leaves_4:3)
Block(15,44,6,biomesoplenty:leaves_4:3)
Block(15,41,6,biomesoplenty:leaves_4:3)
Block(15,40,6,biomesoplenty:leaves_4:3)
Block(10,44,12,biomesoplenty:leaves_4:3)
Block(-21,40,7,biomesoplenty:leaves_4:3)
Block(10,43,12,biomesoplenty:log_2:5)
Block(10,42,12,biomesoplenty:leaves_4:3)
Block(15,47,6,biomesoplenty:leaves_4:3)
Block(15,46,6,biomesoplenty:leaves_4:3)
Block(-6,41,-6,biomesoplenty:log_2:5)
Block(-17,43,-10,biomesoplenty:leaves_4:3)
Block(5,44,-13,biomesoplenty:leaves_4:3)
Block(-6,40,-6,biomesoplenty:leaves_4:3)
Block(-6,43,-6,biomesoplenty:leaves_4:3)
Block(-6,42,-6,biomesoplenty:leaves_4:3)
Block(-9,50,4,biomesoplenty:leaves_4:3)
Block(5,41,-13,biomesoplenty:leaves_4:3)
Block(5,42,-13,biomesoplenty:leaves_4:3)
Block(5,43,-13,biomesoplenty:leaves_4:3)
Block(7,50,3,biomesoplenty:leaves_4:3)
Block(-14,42,-1,biomesoplenty:leaves_4:3)
Block(-14,41,-1,biomesoplenty:leaves_4:3)
Block(-14,40,-1,biomesoplenty:leaves_4:3)
Block(-14,47,-1,biomesoplenty:leaves_4:3)
Block(-14,46,-1,biomesoplenty:leaves_4:3)
Block(-6,49,-6,biomesoplenty:leaves_4:3)
Block(-6,48,-6,biomesoplenty:log_2:5)
Block(-6,45,-6,biomesoplenty:leaves_4:3)
Block(-6,44,-6,biomesoplenty:leaves_4:3)
Block(-6,47,-6,biomesoplenty:leaves_4:3)
Block(-6,46,-6,biomesoplenty:leaves_4:3)
Block(-17,42,0,biomesoplenty:leaves_4:3)
Block(-6,51,-6,biomesoplenty:leaves_4:3)
Block(-17,45,0,biomesoplenty:leaves_4:3)
Block(-17,44,0,biomesoplenty:leaves_4:3)
Block(-6,50,-6,biomesoplenty:leaves_4:3)
Block(-9,50,-2,biomesoplenty:leaves_4:3)
Block(20,41,7,biomesoplenty:leaves_4:3)
Block(14,40,-14,biomesoplenty:leaves_4:3)
Block(14,41,-14,biomesoplenty:leaves_4:3)
Block(-19,40,-8,biomesoplenty:leaves_4:3)
Block(13,40,-15,biomesoplenty:leaves_4:3)
Block(13,41,-15,biomesoplenty:leaves_4:3)
Block(5,44,14,biomesoplenty:leaves_4:3)
Block(5,45,14,biomesoplenty:leaves_4:3)
Block(5,42,14,biomesoplenty:log_2:5)
Block(5,43,14,biomesoplenty:leaves_4:3)
Block(-4,33,-6,biomesoplenty:log_2:5)
Block(-13,41,-9,biomesoplenty:leaves_4:3)
Block(-13,42,-9,biomesoplenty:leaves_4:3)
Block(-13,43,-9,biomesoplenty:leaves_4:3)
Block(-13,44,-9,biomesoplenty:leaves_4:3)
Block(-13,40,-12,biomesoplenty:leaves_4:3)
Block(-13,41,-12,biomesoplenty:leaves_4:3)
Block(11,45,-9,biomesoplenty:leaves_4:3)
Block(13,42,8,biomesoplenty:leaves_4:3)
Block(11,46,-9,biomesoplenty:leaves_4:3)
Block(11,41,-9,biomesoplenty:leaves_4:3)
Block(13,41,8,biomesoplenty:leaves_4:3)
Block(11,42,-9,biomesoplenty:leaves_4:3)
Block(-4,40,16,biomesoplenty:leaves_4:3)
Block(11,43,-9,biomesoplenty:leaves_4:3)
Block(-13,40,-9,biomesoplenty:leaves_4:3)
Block(13,41,-16,biomesoplenty:leaves_4:3)
Block(13,40,-16,biomesoplenty:leaves_4:3)
Block(13,42,-16,biomesoplenty:leaves_4:3)
Block(-5,49,-4,biomesoplenty:log_2:5)
Block(-5,47,-4,biomesoplenty:leaves_4:3)
Block(-5,48,-4,biomesoplenty:leaves_4:3)
Block(-5,45,-4,biomesoplenty:leaves_4:3)
Block(-5,46,-4,biomesoplenty:leaves_4:3)
Block(-5,43,-4,biomesoplenty:leaves_4:3)
Block(-5,44,-4,biomesoplenty:leaves_4:3)
Block(-5,50,-4,biomesoplenty:leaves_4:3)
Block(-5,51,-4,biomesoplenty:leaves_4:3)
Block(13,46,8,biomesoplenty:leaves_4:3)
Block(16,43,-9,biomesoplenty:leaves_4:3)
Block(16,44,-9,biomesoplenty:leaves_4:3)
Block(-5,41,-4,biomesoplenty:leaves_4:3)
Block(-5,42,-4,biomesoplenty:leaves_4:3)
Block(-5,40,-4,biomesoplenty:leaves_4:3)
Block(10,45,-12,biomesoplenty:leaves_4:3)
Block(10,44,-12,biomesoplenty:leaves_4:3)
Block(10,43,-12,biomesoplenty:leaves_4:3)
Block(10,42,-12,biomesoplenty:leaves_4:3)
Block(10,41,-12,biomesoplenty:leaves_4:3)
Block(-7,50,0,biomesoplenty:leaves_4:3)
Block(-7,51,0,biomesoplenty:leaves_4:3)
Block(-5,48,11,biomesoplenty:leaves_4:3)
Block(-7,47,0,biomesoplenty:leaves_4:3)
Block(-5,44,11,biomesoplenty:leaves_4:3)
Block(-7,46,0,biomesoplenty:log_2:5)
Block(-5,47,11,biomesoplenty:leaves_4:3)
Block(-7,49,0,biomesoplenty:leaves_4:3)
Block(-5,46,11,biomesoplenty:leaves_4:3)
Block(-7,48,0,biomesoplenty:leaves_4:3)
Block(-5,41,11,biomesoplenty:leaves_4:3)
Block(-5,40,11,biomesoplenty:leaves_4:3)
Block(-5,43,11,biomesoplenty:leaves_4:3)
Block(-5,42,11,biomesoplenty:leaves_4:3)
Block(-3,41,-15,biomesoplenty:leaves_4:3)
Block(-3,42,-15,biomesoplenty:leaves_4:3)
Block(-3,40,-15,biomesoplenty:leaves_4:3)
Block(-3,45,-15,biomesoplenty:leaves_4:3)
Block(-3,46,-15,biomesoplenty:leaves_4:3)
Block(-3,43,-15,biomesoplenty:leaves_4:3)
Block(-3,47,-15,biomesoplenty:leaves_4:3)
Block(-3,40,3,biomesoplenty:leaves_4:3)
Block(-9,40,16,biomesoplenty:leaves_4:3)
Block(-5,50,7,biomesoplenty:leaves_4:3)
Block(-3,44,3,biomesoplenty:log_2:5)
Block(-3,43,3,biomesoplenty:leaves_4:3)
Block(-3,42,3,biomesoplenty:leaves_4:3)
Block(-3,41,3,biomesoplenty:leaves_4:3)
Block(-3,48,3,biomesoplenty:leaves_4:3)
Block(-3,47,3,biomesoplenty:leaves_4:3)
Block(-3,46,3,biomesoplenty:leaves_4:3)
Block(-3,45,3,biomesoplenty:log_2:5)
Block(-3,49,3,biomesoplenty:leaves_4:3)
Block(-7,43,0,biomesoplenty:leaves_4:3)
Block(-7,42,0,biomesoplenty:leaves_4:3)
Block(-7,45,0,biomesoplenty:leaves_4:3)
Block(-7,44,0,biomesoplenty:leaves_4:3)
Block(-7,41,0,biomesoplenty:log_2:5)
Block(-7,40,0,biomesoplenty:leaves_4:3)
Block(-5,49,7,biomesoplenty:leaves_4:3)
Block(-5,47,7,biomesoplenty:leaves_4:3)
Block(-5,48,7,biomesoplenty:leaves_4:3)
Block(-5,45,7,biomesoplenty:leaves_4:3)
Block(-5,46,7,biomesoplenty:leaves_4:3)
Block(-5,43,7,biomesoplenty:leaves_4:3)
Block(-5,44,7,biomesoplenty:log_2:5)
Block(-5,41,7,biomesoplenty:leaves_4:3)
Block(-3,51,3,biomesoplenty:leaves_4:3)
Block(-5,42,7,biomesoplenty:leaves_4:3)
Block(-3,50,3,biomesoplenty:leaves_4:3)
Block(-5,40,7,biomesoplenty:leaves_4:3)
Block(-9,46,-9,biomesoplenty:leaves_4:3)
Block(-9,47,-9,biomesoplenty:leaves_4:3)
Block(-9,44,-9,biomesoplenty:leaves_4:3)
Block(-9,48,-9,biomesoplenty:leaves_4:3)
Block(3,41,-19,biomesoplenty:leaves_4:3)
Block(3,43,-19,biomesoplenty:leaves_4:3)
Block(3,42,-19,biomesoplenty:leaves_4:3)
Block(4,40,-11,biomesoplenty:leaves_4:3)
Block(4,43,-11,biomesoplenty:leaves_4:3)
Block(3,44,-19,biomesoplenty:leaves_4:3)
Block(4,44,-11,biomesoplenty:leaves_4:3)
Block(4,42,-11,biomesoplenty:leaves_4:3)
Block(4,47,-11,biomesoplenty:leaves_4:3)
Block(4,48,-11,biomesoplenty:leaves_4:3)
Block(4,45,-11,biomesoplenty:leaves_4:3)
Block(4,46,-11,biomesoplenty:leaves_4:3)
Block(4,49,-11,biomesoplenty:leaves_4:3)
Block(2,47,12,biomesoplenty:leaves_4:3)
Block(2,48,12,biomesoplenty:leaves_4:3)
Block(2,45,12,biomesoplenty:leaves_4:3)
Block(2,46,12,biomesoplenty:leaves_4:3)
Block(2,43,12,biomesoplenty:leaves_4:3)
Block(2,44,12,biomesoplenty:leaves_4:3)
Block(-2,45,15,biomesoplenty:leaves_4:3)
Block(-2,46,15,biomesoplenty:leaves_4:3)
Block(12,42,-10,biomesoplenty:leaves_4:3)
Block(11,43,4,biomesoplenty:leaves_4:3)
Block(11,42,4,biomesoplenty:leaves_4:3)
Block(11,41,4,biomesoplenty:leaves_4:3)
Block(11,40,4,biomesoplenty:leaves_4:3)
Block(12,43,-10,biomesoplenty:leaves_4:3)
Block(11,47,4,biomesoplenty:log_2:5)
Block(3,44,-20,biomesoplenty:leaves_4:3)
Block(12,45,-10,biomesoplenty:leaves_4:3)
Block(11,46,4,biomesoplenty:leaves_4:3)
Block(3,43,-20,biomesoplenty:leaves_4:3)
Block(11,45,4,biomesoplenty:leaves_4:3)
