
#######################################################################
# +-----------------------------------------------------------------+ #
# |                            BO3 object                           | #
# +-----------------------------------------------------------------+ #
#######################################################################

Author: LordSmellyPants

Description: No description given

Version: 3

SettingsMode: WriteWithoutComments


#######################################################################
# +-----------------------------------------------------------------+ #
# |                          Main settings                          | #
# +-----------------------------------------------------------------+ #
#######################################################################

Tree: true

Frequency: 1

Rarity: 10.0

RotateRandomly: true

SpawnHeight: highestSolidBlock

SpawnHeightOffset: 0

SpawnHeightVariance: 0

##############################
# Height Limits for the BO3. #
##############################

MinHeight: 66

MaxHeight: 89

######################
# Extrusion settings #
######################

ExtrudeMode: None

ExtrudeThroughBlocks: AIR

MaxBranchDepth: 10

ExcludedBiomes: All


#######################################################################
# +-----------------------------------------------------------------+ #
# |                      Source block settings                      | #
# +-----------------------------------------------------------------+ #
#######################################################################

SourceBlocks: STONE:1,STONE:3,STONE:5,DIRT:1,DIRT,SAND,GRASS,DIRT:2,STATIONARY_WATER,HARD_CLAY,STAINED_CLAY,CLAY,SANDSTONE,SAND:1,AIR,STONE,GRAVEL,LONG_GRASS,LONG_GRASS:1,LONG_GRASS:2,DEAD_BUSH,YELLOW_FLOWER,RED_ROSE,BROWN_MUSHROOM,RED_MUSHROOM,biomesoplenty:plant_0:1,biomesoplenty:plant_0:2,biomesoplenty:plant_0:3,biomesoplenty:plant_0:4,biomesoplenty:plant_0:5,biomesoplenty:plant_0:6,biomesoplenty:plant_0:7,biomesoplenty:plant_0:8,biomesoplenty:plant_0:9,biomesoplenty:plant_0:10,biomesoplenty:plant_0:11,biomesoplenty:plant_0:12,biomesoplenty:plant_0:13,biomesoplenty:plant_0:14,biomesoplenty:flower_0:1,biomesoplenty:flower_0:2,biomesoplenty:flower_0:3,biomesoplenty:flower_0:4,biomesoplenty:flower_0:5,biomesoplenty:flower_0:6,biomesoplenty:flower_0:7,biomesoplenty:flower_0:8,biomesoplenty:flower_0:9,biomesoplenty:flower_0:10,biomesoplenty:flower_0:11,biomesoplenty:flower_0:12,biomesoplenty:flower_0:13,biomesoplenty:flower_0:14,biomesoplenty:plant_1:0,biomesoplenty:grass:0,biomesoplenty:grass:1,biomesoplenty:grass,biomesoplenty:grass:3,biomesoplenty:grass:4,biomesoplenty:grass:5,biomesoplenty:grass:6,biomesoplenty:grass:7,biomesoplenty:dirt:0,biomesoplenty:dirt:1,biomesoplenty:dirt:2,biomesoplenty:dirt:8,biomesoplenty:dirt:9,biomesoplenty:dirt:10,biomesoplenty:dried_sand:0,biomesoplenty:hard_ice:0,biomesoplenty:white_sand:0,biomesoplenty:white_sandstone:0,biomesoplenty:mud:0,biomesoplenty:ash_block:0

MaxPercentageOutsideSourceBlock: 0

OutsideSourceBlock: placeAnyway

IsOTGPlus: false


#######################################################################
# +-----------------------------------------------------------------+ #
# |                              Blocks                             | #
# +-----------------------------------------------------------------+ #
#######################################################################

Block(-19,9,-1,LEAVES_2:1)
Block(-19,10,-1,LEAVES_2:1)
Block(-19,11,-2,LEAVES_2:1)
Block(-19,11,-1,LEAVES_2:1)
Block(-19,12,-2,LEAVES_2:1)
Block(-19,12,-1,LEAVES_2:1)
Block(-19,13,-2,LEAVES_2:1)
Block(-19,13,-1,LEAVES_2:1)
Block(-19,13,0,LEAVES_2:1)
Block(-19,14,-3,LEAVES_2:1)
Block(-19,14,-2,LEAVES_2:1)
Block(-19,14,-1,LEAVES_2:1)
Block(-19,14,0,LEAVES_2:1)
Block(-19,15,-2,LEAVES_2:1)
Block(-19,15,-1,LEAVES_2:1)
Block(-19,15,0,LEAVES_2:1)
Block(-19,16,-1,LEAVES_2:1)
Block(-19,16,0,LEAVES_2:1)
Block(-19,16,1,LEAVES_2:1)
Block(-19,17,0,LEAVES_2:1)
Block(-19,17,1,LEAVES_2:1)
Block(-19,17,2,LEAVES_2:1)
Block(-19,18,1,LEAVES_2:1)
Block(-18,13,-1,LEAVES_2:1)
Block(-18,14,-2,LEAVES_2:1)
Block(-18,14,-1,LEAVES_2:1)
Block(-18,15,-3,LEAVES_2:1)
Block(-18,15,-2,LEAVES_2:1)
Block(-18,15,-1,LOG_2:1)
Block(-18,15,0,LEAVES_2:1)
Block(-18,15,1,LEAVES_2:1)
Block(-18,15,4,LEAVES_2:1)
Block(-18,15,5,LEAVES_2:1)
Block(-18,16,-2,LEAVES_2:1)
Block(-18,16,-1,LOG_2:1)
Block(-18,16,0,LOG_2:1)
Block(-18,16,1,LEAVES_2:1)
Block(-18,16,2,LEAVES_2:1)
Block(-18,16,3,LEAVES_2:1)
Block(-18,16,4,LEAVES_2:1)
Block(-18,17,-2,LEAVES_2:1)
Block(-18,17,-1,LEAVES_2:1)
Block(-18,17,0,LOG_2:1)
Block(-18,17,1,LEAVES_2:1)
Block(-18,17,2,LEAVES_2:1)
Block(-18,17,3,LEAVES_2:1)
Block(-18,18,0,LEAVES_2:1)
Block(-18,18,1,LEAVES_2:1)
Block(-18,18,2,LEAVES_2:1)
Block(-17,14,4,LEAVES_2:1)
Block(-17,14,5,LEAVES_2:1)
Block(-17,14,6,LEAVES_2:1)
Block(-17,15,-3,LEAVES_2:1)
Block(-17,15,-2,LEAVES_2:1)
Block(-17,15,-1,LEAVES_2:1)
Block(-17,15,3,LEAVES_2:1)
Block(-17,15,4,LEAVES_2:1)
Block(-17,15,5,LEAVES_2:1)
Block(-17,15,6,LEAVES_2:1)
Block(-17,16,-4,LEAVES_2:1)
Block(-17,16,-3,LEAVES_2:1)
Block(-17,16,-2,LEAVES_2:1)
Block(-17,16,0,LEAVES_2:1)
Block(-17,16,1,LEAVES_2:1)
Block(-17,16,2,LEAVES_2:1)
Block(-17,16,3,LEAVES_2:1)
Block(-17,16,4,LEAVES_2:1)
Block(-17,16,5,LEAVES_2:1)
Block(-17,17,-3,LEAVES_2:1)
Block(-17,17,-2,LEAVES_2:1)
Block(-17,17,-1,LEAVES_2:1)
Block(-17,17,0,LOG_2:1)
Block(-17,17,1,LOG_2:1)
Block(-17,17,2,LEAVES_2:1)
Block(-17,17,3,LEAVES_2:1)
Block(-17,17,4,LEAVES_2:1)
Block(-17,18,-2,LEAVES_2:1)
Block(-17,18,-1,LEAVES_2:1)
Block(-17,18,0,LOG_2:1)
Block(-17,18,1,LEAVES_2:1)
Block(-17,18,2,LEAVES_2:1)
Block(-17,18,3,LEAVES_2:1)
Block(-17,19,-1,LEAVES_2:1)
Block(-17,19,0,LEAVES_2:1)
Block(-17,19,1,LEAVES_2:1)
Block(-17,19,2,LEAVES_2:1)
Block(-16,13,5,LEAVES_2:1)
Block(-16,13,6,LEAVES_2:1)
Block(-16,13,8,LEAVES_2:1)
Block(-16,13,9,LEAVES_2:1)
Block(-16,14,4,LEAVES_2:1)
Block(-16,14,5,LEAVES_2:1)
Block(-16,14,6,LEAVES_2:1)
Block(-16,14,7,LEAVES_2:1)
Block(-16,14,8,LEAVES_2:1)
Block(-16,15,-4,LEAVES_2:1)
Block(-16,15,4,LEAVES_2:1)
Block(-16,15,5,LEAVES_2:1)
Block(-16,15,6,LEAVES_2:1)
Block(-16,15,7,LEAVES_2:1)
Block(-16,15,8,LEAVES_2:1)
Block(-16,16,-7,LEAVES_2:1)
Block(-16,16,-6,LEAVES_2:1)
Block(-16,16,-5,LEAVES_2:1)
Block(-16,16,-4,LEAVES_2:1)
Block(-16,16,-3,LEAVES_2:1)
Block(-16,16,-2,LEAVES_2:1)
Block(-16,16,-1,LEAVES_2:1)
Block(-16,16,3,LEAVES_2:1)
Block(-16,16,4,LEAVES_2:1)
Block(-16,16,5,LEAVES_2:1)
Block(-16,16,6,LEAVES_2:1)
Block(-16,17,-6,LEAVES_2:1)
Block(-16,17,-5,LEAVES_2:1)
Block(-16,17,-4,LEAVES_2:1)
Block(-16,17,-3,LEAVES_2:1)
Block(-16,17,-2,LEAVES_2:1)
Block(-16,17,-1,LEAVES_2:1)
Block(-16,17,0,LEAVES_2:1)
Block(-16,17,1,LOG_2:1)
Block(-16,17,2,LOG_2:1)
Block(-16,17,3,LEAVES_2:1)
Block(-16,17,4,LEAVES_2:1)
Block(-16,17,5,LEAVES_2:1)
Block(-16,18,-3,LEAVES_2:1)
Block(-16,18,-2,LEAVES_2:1)
Block(-16,18,-1,LEAVES_2:1)
Block(-16,18,0,LOG_2:1)
Block(-16,18,1,LOG_2:1)
Block(-16,18,2,LEAVES_2:1)
Block(-16,18,3,LEAVES_2:1)
Block(-16,18,4,LEAVES_2:1)
Block(-16,19,-2,LEAVES_2:1)
Block(-16,19,-1,LEAVES_2:1)
Block(-16,19,0,LEAVES_2:1)
Block(-16,19,1,LEAVES_2:1)
Block(-16,19,2,LEAVES_2:1)
Block(-16,19,3,LEAVES_2:1)
Block(-16,20,-1,LEAVES_2:1)
Block(-16,20,0,LEAVES_2:1)
Block(-16,20,1,LEAVES_2:1)
Block(-15,11,-10,LEAVES_2:1)
Block(-15,12,-10,LEAVES_2:1)
Block(-15,12,8,LEAVES_2:1)
Block(-15,12,9,LEAVES_2:1)
Block(-15,12,10,LEAVES_2:1)
Block(-15,12,11,LEAVES_2:1)
Block(-15,13,-10,LEAVES_2:1)
Block(-15,13,6,LEAVES_2:1)
Block(-15,13,7,LEAVES_2:1)
Block(-15,13,8,LEAVES_2:1)
Block(-15,13,9,LEAVES_2:1)
Block(-15,13,10,LEAVES_2:1)
Block(-15,14,-10,LEAVES_2:1)
Block(-15,14,-9,LEAVES_2:1)
Block(-15,14,5,LEAVES_2:1)
Block(-15,14,6,LEAVES_2:1)
Block(-15,14,7,LEAVES_2:1)
Block(-15,14,8,LEAVES_2:1)
Block(-15,14,9,LEAVES_2:1)
Block(-15,15,-10,LEAVES_2:1)
Block(-15,15,-9,LEAVES_2:1)
Block(-15,15,-8,LEAVES_2:1)
Block(-15,15,-7,LEAVES_2:1)
Block(-15,15,4,LEAVES_2:1)
Block(-15,15,5,LEAVES_2:1)
Block(-15,15,6,LEAVES_2:1)
Block(-15,15,7,LEAVES_2:1)
Block(-15,15,8,LEAVES_2:1)
Block(-15,15,9,LEAVES_2:1)
Block(-15,16,-9,LEAVES_2:1)
Block(-15,16,-8,LEAVES_2:1)
Block(-15,16,-7,LEAVES_2:1)
Block(-15,16,-6,LEAVES_2:1)
Block(-15,16,-5,LEAVES_2:1)
Block(-15,16,-4,LEAVES_2:1)
Block(-15,16,-3,LEAVES_2:1)
Block(-15,16,3,LEAVES_2:1)
Block(-15,16,4,LEAVES_2:1)
Block(-15,16,5,LEAVES_2:1)
Block(-15,16,7,LEAVES_2:1)
Block(-15,16,8,LEAVES_2:1)
Block(-15,17,-7,LEAVES_2:1)
Block(-15,17,-6,LEAVES_2:1)
Block(-15,17,-5,LEAVES_2:1)
Block(-15,17,-4,LEAVES_2:1)
Block(-15,17,-3,LEAVES_2:1)
Block(-15,17,-2,LEAVES_2:1)
Block(-15,17,-1,LEAVES_2:1)
Block(-15,17,1,LOG_2:1)
Block(-15,17,2,LOG_2:1)
Block(-15,17,3,LEAVES_2:1)
Block(-15,17,4,LEAVES_2:1)
Block(-15,17,5,LEAVES_2:1)
Block(-15,17,6,LEAVES_2:1)
Block(-15,17,7,LEAVES_2:1)
Block(-15,18,-6,LEAVES_2:1)
Block(-15,18,-5,LEAVES_2:1)
Block(-15,18,-4,LEAVES_2:1)
Block(-15,18,-3,LEAVES_2:1)
Block(-15,18,-2,LEAVES_2:1)
Block(-15,18,-1,LEAVES_2:1)
Block(-15,18,0,LEAVES_2:1)
Block(-15,18,1,LOG_2:1)
Block(-15,18,2,LOG_2:1)
Block(-15,18,3,LEAVES_2:1)
Block(-15,18,4,LEAVES_2:1)
Block(-15,18,5,LEAVES_2:1)
Block(-15,19,-3,LEAVES_2:1)
Block(-15,19,-2,LEAVES_2:1)
Block(-15,19,-1,LEAVES_2:1)
Block(-15,19,0,LEAVES_2:1)
Block(-15,19,1,LEAVES_2:1)
Block(-15,19,2,LEAVES_2:1)
Block(-15,19,3,LEAVES_2:1)
Block(-15,19,4,LEAVES_2:1)
Block(-15,19,5,LEAVES_2:1)
Block(-15,20,-2,LEAVES_2:1)
Block(-15,20,-1,LEAVES_2:1)
Block(-15,20,0,LEAVES_2:1)
Block(-15,20,1,LEAVES_2:1)
Block(-15,20,2,LEAVES_2:1)
Block(-14,8,16,LEAVES_2:1)
Block(-14,9,-10,LEAVES_2:1)
Block(-14,9,15,LEAVES_2:1)
Block(-14,9,16,LEAVES_2:1)
Block(-14,10,-10,LEAVES_2:1)
Block(-14,10,15,LEAVES_2:1)
Block(-14,10,16,LEAVES_2:1)
Block(-14,11,-10,LEAVES_2:1)
Block(-14,11,10,LEAVES_2:1)
Block(-14,11,11,LEAVES_2:1)
Block(-14,11,12,LEAVES_2:1)
Block(-14,11,13,LEAVES_2:1)
Block(-14,11,14,LEAVES_2:1)
Block(-14,11,15,LEAVES_2:1)
Block(-14,12,-11,LEAVES_2:1)
Block(-14,12,-10,LEAVES_2:1)
Block(-14,12,9,LEAVES_2:1)
Block(-14,12,10,LEAVES_2:1)
Block(-14,12,11,LEAVES_2:1)
Block(-14,12,12,LEAVES_2:1)
Block(-14,12,13,LEAVES_2:1)
Block(-14,13,-11,LEAVES_2:1)
Block(-14,13,-10,LEAVES_2:1)
Block(-14,13,-9,LEAVES_2:1)
Block(-14,13,7,LEAVES_2:1)
Block(-14,13,8,LEAVES_2:1)
Block(-14,13,9,LEAVES_2:1)
Block(-14,13,10,LEAVES_2:1)
Block(-14,13,11,LEAVES_2:1)
Block(-14,13,12,LEAVES_2:1)
Block(-14,14,-11,LEAVES_2:1)
Block(-14,14,-10,LEAVES_2:1)
Block(-14,14,-9,LEAVES_2:1)
Block(-14,14,-8,LEAVES_2:1)
Block(-14,14,5,LEAVES_2:1)
Block(-14,14,6,LEAVES_2:1)
Block(-14,14,7,LEAVES_2:1)
Block(-14,14,8,LEAVES_2:1)
Block(-14,14,9,LEAVES_2:1)
Block(-14,14,10,LEAVES_2:1)
Block(-14,14,11,LEAVES_2:1)
Block(-14,15,-10,LEAVES_2:1)
Block(-14,15,-9,LEAVES_2:1)
Block(-14,15,-8,LEAVES_2:1)
Block(-14,15,-7,LEAVES_2:1)
Block(-14,15,4,LEAVES_2:1)
Block(-14,15,5,LEAVES_2:1)
Block(-14,15,6,LEAVES_2:1)
Block(-14,15,7,LEAVES_2:1)
Block(-14,15,8,LEAVES_2:1)
Block(-14,15,9,LEAVES_2:1)
Block(-14,15,10,LEAVES_2:1)
Block(-14,16,-10,LEAVES_2:1)
Block(-14,16,-9,LEAVES_2:1)
Block(-14,16,-8,LEAVES_2:1)
Block(-14,16,-7,LEAVES_2:1)
Block(-14,16,-6,LEAVES_2:1)
Block(-14,16,-3,LEAVES_2:1)
Block(-14,16,3,LOG_2:1)
Block(-14,16,4,LEAVES_2:1)
Block(-14,16,5,LEAVES_2:1)
Block(-14,16,6,LEAVES_2:1)
Block(-14,16,7,LEAVES_2:1)
Block(-14,16,8,LEAVES_2:1)
Block(-14,16,9,LEAVES_2:1)
Block(-14,16,10,LEAVES_2:1)
Block(-14,17,-9,LEAVES_2:1)
Block(-14,17,-8,LEAVES_2:1)
Block(-14,17,-7,LEAVES_2:1)
Block(-14,17,-6,LEAVES_2:1)
Block(-14,17,-5,LEAVES_2:1)
Block(-14,17,-4,LEAVES_2:1)
Block(-14,17,-3,LEAVES_2:1)
Block(-14,17,-2,LEAVES_2:1)
Block(-14,17,2,LOG_2:1)
Block(-14,17,3,LOG_2:1)
Block(-14,17,5,LEAVES_2:1)
Block(-14,17,6,LEAVES_2:1)
Block(-14,17,7,LEAVES_2:1)
Block(-14,17,8,LEAVES_2:1)
Block(-14,18,-8,LEAVES_2:1)
Block(-14,18,-7,LEAVES_2:1)
Block(-14,18,-6,LEAVES_2:1)
Block(-14,18,-5,LEAVES_2:1)
Block(-14,18,-4,LEAVES_2:1)
Block(-14,18,-3,LEAVES_2:1)
Block(-14,18,-2,LEAVES_2:1)
Block(-14,18,1,LOG_2:1)
Block(-14,18,2,LOG_2:1)
Block(-14,18,3,LOG_2:1)
Block(-14,18,4,LEAVES_2:1)
Block(-14,18,5,LEAVES_2:1)
Block(-14,18,6,LEAVES_2:1)
Block(-14,18,7,LEAVES_2:1)
Block(-14,19,-6,LEAVES_2:1)
Block(-14,19,-5,LEAVES_2:1)
Block(-14,19,-4,LEAVES_2:1)
Block(-14,19,-3,LEAVES_2:1)
Block(-14,19,-2,LEAVES_2:1)
Block(-14,19,-1,LEAVES_2:1)
Block(-14,19,0,LEAVES_2:1)
Block(-14,19,1,LEAVES_2:1)
Block(-14,19,2,LEAVES_2:1)
Block(-14,19,3,LEAVES_2:1)
Block(-14,19,4,LEAVES_2:1)
Block(-14,19,5,LEAVES_2:1)
Block(-14,19,6,LEAVES_2:1)
Block(-14,19,7,LEAVES_2:1)
Block(-14,20,-4,LEAVES_2:1)
Block(-14,20,-3,LEAVES_2:1)
Block(-14,20,-2,LEAVES_2:1)
Block(-14,20,-1,LEAVES_2:1)
Block(-14,20,0,LEAVES_2:1)
Block(-14,20,1,LEAVES_2:1)
Block(-14,20,2,LEAVES_2:1)
Block(-14,20,3,LEAVES_2:1)
Block(-14,20,4,LEAVES_2:1)
Block(-14,20,5,LEAVES_2:1)
Block(-14,21,-1,LEAVES_2:1)
Block(-14,21,0,LEAVES_2:1)
Block(-13,7,16,LEAVES_2:1)
Block(-13,8,15,LOG_2:1)
Block(-13,8,16,LEAVES_2:1)
Block(-13,9,14,LEAVES_2:1)
Block(-13,9,15,LOG_2:1)
Block(-13,9,16,LEAVES_2:1)
Block(-13,9,17,LEAVES_2:1)
Block(-13,10,14,LEAVES_2:1)
Block(-13,10,15,LEAVES_2:1)
Block(-13,10,16,LEAVES_2:1)
Block(-13,10,17,LEAVES_2:1)
Block(-13,11,11,LEAVES_2:1)
Block(-13,11,12,LEAVES_2:1)
Block(-13,11,13,LEAVES_2:1)
Block(-13,11,14,LEAVES_2:1)
Block(-13,11,15,LEAVES_2:1)
Block(-13,11,16,LEAVES_2:1)
Block(-13,12,10,LEAVES_2:1)
Block(-13,12,11,LEAVES_2:1)
Block(-13,12,12,LEAVES_2:1)
Block(-13,12,13,LEAVES_2:1)
Block(-13,12,14,LEAVES_2:1)
Block(-13,12,15,LEAVES_2:1)
Block(-13,13,-10,LEAVES_2:1)
Block(-13,13,9,LEAVES_2:1)
Block(-13,13,10,LEAVES_2:1)
Block(-13,13,11,LEAVES_2:1)
Block(-13,13,12,LEAVES_2:1)
Block(-13,13,13,LEAVES_2:1)
Block(-13,13,14,LEAVES_2:1)
Block(-13,14,-11,LEAVES_2:1)
Block(-13,14,-10,LEAVES_2:1)
Block(-13,14,-9,LEAVES_2:1)
Block(-13,14,7,LEAVES_2:1)
Block(-13,14,8,LEAVES_2:1)
Block(-13,14,9,LEAVES_2:1)
Block(-13,14,10,LEAVES_2:1)
Block(-13,14,11,LEAVES_2:1)
Block(-13,14,12,LEAVES_2:1)
Block(-13,14,13,LEAVES_2:1)
Block(-13,15,-11,LEAVES_2:1)
Block(-13,15,-10,LEAVES_2:1)
Block(-13,15,-9,LEAVES_2:1)
Block(-13,15,5,LEAVES_2:1)
Block(-13,15,7,LEAVES_2:1)
Block(-13,15,8,LEAVES_2:1)
Block(-13,15,9,LEAVES_2:1)
Block(-13,15,10,LEAVES_2:1)
Block(-13,15,11,LEAVES_2:1)
Block(-13,15,12,LEAVES_2:1)
Block(-13,16,-10,LEAVES_2:1)
Block(-13,16,-9,LEAVES_2:1)
Block(-13,16,-8,LEAVES_2:1)
Block(-13,16,-7,LEAVES_2:1)
Block(-13,16,3,LOG_2:1)
Block(-13,16,4,LOG_2:1)
Block(-13,16,5,LEAVES_2:1)
Block(-13,16,7,LEAVES_2:1)
Block(-13,16,9,LEAVES_2:1)
Block(-13,16,10,LEAVES_2:1)
Block(-13,16,11,LEAVES_2:1)
Block(-13,17,-10,LEAVES_2:1)
Block(-13,17,-9,LEAVES_2:1)
Block(-13,17,-8,LEAVES_2:1)
Block(-13,17,-7,LEAVES_2:1)
Block(-13,17,-6,LEAVES_2:1)
Block(-13,17,-5,LEAVES_2:1)
Block(-13,17,-4,LEAVES_2:1)
Block(-13,17,-3,LEAVES_2:1)
Block(-13,17,2,LOG_2:1)
Block(-13,17,3,LOG_2:1)
Block(-13,17,4,LOG_2:1)
Block(-13,17,6,LEAVES_2:1)
Block(-13,17,7,LEAVES_2:1)
Block(-13,17,9,LEAVES_2:1)
Block(-13,17,10,LEAVES_2:1)
Block(-13,17,11,LEAVES_2:1)
Block(-13,18,-9,LEAVES_2:1)
Block(-13,18,-8,LEAVES_2:1)
Block(-13,18,-7,LEAVES_2:1)
Block(-13,18,-6,LEAVES_2:1)
Block(-13,18,-5,LEAVES_2:1)
Block(-13,18,-4,LEAVES_2:1)
Block(-13,18,-3,LEAVES_2:1)
Block(-13,18,-2,LEAVES_2:1)
Block(-13,18,-1,LEAVES_2:1)
Block(-13,18,1,LEAVES_2:1)
Block(-13,18,2,LOG_2:1)
Block(-13,18,3,LEAVES_2:1)
Block(-13,18,5,LEAVES_2:1)
Block(-13,18,6,LEAVES_2:1)
Block(-13,18,7,LEAVES_2:1)
Block(-13,18,8,LEAVES_2:1)
Block(-13,18,9,LEAVES_2:1)
Block(-13,19,-7,LEAVES_2:1)
Block(-13,19,-6,LEAVES_2:1)
Block(-13,19,-5,LEAVES_2:1)
Block(-13,19,-4,LEAVES_2:1)
Block(-13,19,-3,LEAVES_2:1)
Block(-13,19,-2,LEAVES_2:1)
Block(-13,19,-1,LEAVES_2:1)
Block(-13,19,0,LEAVES_2:1)
Block(-13,19,1,LEAVES_2:1)
Block(-13,19,2,LEAVES_2:1)
Block(-13,19,3,LEAVES_2:1)
Block(-13,19,4,LEAVES_2:1)
Block(-13,19,5,LEAVES_2:1)
Block(-13,19,6,LEAVES_2:1)
Block(-13,19,7,LEAVES_2:1)
Block(-13,19,8,LEAVES_2:1)
Block(-13,20,-5,LEAVES_2:1)
Block(-13,20,-4,LEAVES_2:1)
Block(-13,20,-3,LEAVES_2:1)
Block(-13,20,-2,LEAVES_2:1)
Block(-13,20,-1,LEAVES_2:1)
Block(-13,20,0,LEAVES_2:1)
Block(-13,20,1,LEAVES_2:1)
Block(-13,20,2,LEAVES_2:1)
Block(-13,20,5,LEAVES_2:1)
Block(-13,20,6,LEAVES_2:1)
Block(-13,20,7,LEAVES_2:1)
Block(-13,21,-2,LEAVES_2:1)
Block(-13,21,-1,LEAVES_2:1)
Block(-13,21,0,LEAVES_2:1)
Block(-13,21,1,LEAVES_2:1)
Block(-13,21,2,LEAVES_2:1)
Block(-13,21,3,LEAVES_2:1)
Block(-13,21,4,LEAVES_2:1)
Block(-13,21,5,LEAVES_2:1)
Block(-13,21,6,LEAVES_2:1)
Block(-12,9,15,LOG_2:1)
Block(-12,9,16,LEAVES_2:1)
Block(-12,10,13,LOG_2:1)
Block(-12,10,14,LOG_2:1)
Block(-12,10,15,LOG_2:1)
Block(-12,10,16,LEAVES_2:1)
Block(-12,10,17,LEAVES_2:1)
Block(-12,11,13,LEAVES_2:1)
Block(-12,11,14,LOG_2:1)
Block(-12,11,15,LEAVES_2:1)
Block(-12,11,16,LEAVES_2:1)
Block(-12,12,11,LEAVES_2:1)
Block(-12,12,12,LEAVES_2:1)
Block(-12,12,13,LEAVES_2:1)
Block(-12,12,14,LEAVES_2:1)
Block(-12,12,15,LEAVES_2:1)
Block(-12,12,16,LEAVES_2:1)
Block(-12,13,10,LEAVES_2:1)
Block(-12,13,11,LEAVES_2:1)
Block(-12,13,12,LEAVES_2:1)
Block(-12,13,13,LEAVES_2:1)
Block(-12,13,14,LEAVES_2:1)
Block(-12,13,15,LEAVES_2:1)
Block(-12,14,-9,LEAVES_2:1)
Block(-12,14,9,LEAVES_2:1)
Block(-12,14,10,LEAVES_2:1)
Block(-12,14,11,LEAVES_2:1)
Block(-12,14,12,LEAVES_2:1)
Block(-12,14,13,LEAVES_2:1)
Block(-12,14,14,LEAVES_2:1)
Block(-12,14,15,LEAVES_2:1)
Block(-12,15,-10,LEAVES_2:1)
Block(-12,15,-9,LEAVES_2:1)
Block(-12,15,4,LOG_2:1)
Block(-12,15,5,LOG_2:1)
Block(-12,15,10,LEAVES_2:1)
Block(-12,15,11,LEAVES_2:1)
Block(-12,15,12,LEAVES_2:1)
Block(-12,15,13,LEAVES_2:1)
Block(-12,15,14,LEAVES_2:1)
Block(-12,16,-10,LEAVES_2:1)
Block(-12,16,-9,LEAVES_2:1)
Block(-12,16,-8,LEAVES_2:1)
Block(-12,16,3,LOG_2:1)
Block(-12,16,4,LOG_2:1)
Block(-12,16,5,LOG_2:1)
Block(-12,16,9,LEAVES_2:1)
Block(-12,16,10,LEAVES_2:1)
Block(-12,16,11,LEAVES_2:1)
Block(-12,16,12,LEAVES_2:1)
Block(-12,16,13,LEAVES_2:1)
Block(-12,17,-10,LEAVES_2:1)
Block(-12,17,-9,LEAVES_2:1)
Block(-12,17,-8,LEAVES_2:1)
Block(-12,17,-7,LEAVES_2:1)
Block(-12,17,3,LOG_2:1)
Block(-12,17,4,LOG_2:1)
Block(-12,17,8,LEAVES_2:1)
Block(-12,17,9,LEAVES_2:1)
Block(-12,17,10,LEAVES_2:1)
Block(-12,17,11,LEAVES_2:1)
Block(-12,17,12,LEAVES_2:1)
Block(-12,18,-10,LEAVES_2:1)
Block(-12,18,-9,LEAVES_2:1)
Block(-12,18,-8,LEAVES_2:1)
Block(-12,18,-7,LEAVES_2:1)
Block(-12,18,-6,LEAVES_2:1)
Block(-12,18,-5,LEAVES_2:1)
Block(-12,18,-4,LEAVES_2:1)
Block(-12,18,-3,LEAVES_2:1)
Block(-12,18,-2,LEAVES_2:1)
Block(-12,18,-1,LEAVES_2:1)
Block(-12,18,7,LEAVES_2:1)
Block(-12,18,8,LEAVES_2:1)
Block(-12,18,9,LEAVES_2:1)
Block(-12,18,10,LEAVES_2:1)
Block(-12,18,11,LEAVES_2:1)
Block(-12,19,-8,LEAVES_2:1)
Block(-12,19,-7,LEAVES_2:1)
Block(-12,19,-6,LEAVES_2:1)
Block(-12,19,-5,LEAVES_2:1)
Block(-12,19,-4,LEAVES_2:1)
Block(-12,19,-3,LEAVES_2:1)
Block(-12,19,-2,LEAVES_2:1)
Block(-12,19,-1,LEAVES_2:1)
Block(-12,19,0,LEAVES_2:1)
Block(-12,19,1,LEAVES_2:1)
Block(-12,19,2,LEAVES_2:1)
Block(-12,19,5,LEAVES_2:1)
Block(-12,19,6,LEAVES_2:1)
Block(-12,19,7,LEAVES_2:1)
Block(-12,19,9,LEAVES_2:1)
Block(-12,20,-6,LEAVES_2:1)
Block(-12,20,-5,LEAVES_2:1)
Block(-12,20,-4,LEAVES_2:1)
Block(-12,20,-3,LEAVES_2:1)
Block(-12,20,-2,LEAVES_2:1)
Block(-12,20,-1,LEAVES_2:1)
Block(-12,20,0,LEAVES_2:1)
Block(-12,20,1,LEAVES_2:1)
Block(-12,20,2,LEAVES_2:1)
Block(-12,20,3,LEAVES_2:1)
Block(-12,20,4,LEAVES_2:1)
Block(-12,20,5,LEAVES_2:1)
Block(-12,20,6,LEAVES_2:1)
Block(-12,20,7,LEAVES_2:1)
Block(-12,20,8,LEAVES_2:1)
Block(-12,21,-5,LEAVES_2:1)
Block(-12,21,-4,LEAVES_2:1)
Block(-12,21,-3,LEAVES_2:1)
Block(-12,21,-2,LEAVES_2:1)
Block(-12,21,-1,LEAVES_2:1)
Block(-12,21,0,LEAVES_2:1)
Block(-12,21,1,LEAVES_2:1)
Block(-12,21,2,LEAVES_2:1)
Block(-12,21,3,LEAVES_2:1)
Block(-12,21,4,LEAVES_2:1)
Block(-12,21,5,LEAVES_2:1)
Block(-12,21,6,LEAVES_2:1)
Block(-12,21,7,LEAVES_2:1)
Block(-12,22,4,LEAVES_2:1)
Block(-12,22,5,LEAVES_2:1)
Block(-11,10,13,LOG_2:1)
Block(-11,10,14,LOG_2:1)
Block(-11,11,12,LOG_2:1)
Block(-11,11,13,LOG_2:1)
Block(-11,11,14,LOG_2:1)
Block(-11,11,15,LEAVES_2:1)
Block(-11,12,13,LEAVES_2:1)
Block(-11,12,14,LEAVES_2:1)
Block(-11,12,15,LEAVES_2:1)
Block(-11,12,16,LEAVES_2:1)
Block(-11,13,11,LEAVES_2:1)
Block(-11,13,13,LEAVES_2:1)
Block(-11,13,14,LEAVES_2:1)
Block(-11,13,15,LEAVES_2:1)
Block(-11,13,16,LEAVES_2:1)
Block(-11,14,5,LOG_2:1)
Block(-11,14,11,LEAVES_2:1)
Block(-11,14,13,LEAVES_2:1)
Block(-11,14,14,LEAVES_2:1)
Block(-11,14,15,LEAVES_2:1)
Block(-11,14,16,LEAVES_2:1)
Block(-11,15,-9,LEAVES_2:1)
Block(-11,15,4,LOG_2:1)
Block(-11,15,5,LOG_2:1)
Block(-11,15,6,LOG_2:1)
Block(-11,15,11,LEAVES_2:1)
Block(-11,15,13,LEAVES_2:1)
Block(-11,15,14,LEAVES_2:1)
Block(-11,15,15,LEAVES_2:1)
Block(-11,16,-10,LEAVES_2:1)
Block(-11,16,-9,LEAVES_2:1)
Block(-11,16,3,LOG_2:1)
Block(-11,16,4,LOG_2:1)
Block(-11,16,5,LOG_2:1)
Block(-11,16,6,LOG_2:1)
Block(-11,16,10,LEAVES_2:1)
Block(-11,16,11,LEAVES_2:1)
Block(-11,16,12,LEAVES_2:1)
Block(-11,16,13,LEAVES_2:1)
Block(-11,16,14,LEAVES_2:1)
Block(-11,17,-10,LEAVES_2:1)
Block(-11,17,-9,LEAVES_2:1)
Block(-11,17,-8,LEAVES_2:1)
Block(-11,17,4,LOG_2:1)
Block(-11,17,5,LOG_2:1)
Block(-11,17,9,LEAVES_2:1)
Block(-11,17,10,LEAVES_2:1)
Block(-11,17,11,LEAVES_2:1)
Block(-11,17,13,LEAVES_2:1)
Block(-11,18,-10,LEAVES_2:1)
Block(-11,18,-9,LEAVES_2:1)
Block(-11,18,-8,LEAVES_2:1)
Block(-11,18,-7,LEAVES_2:1)
Block(-11,18,-6,LEAVES_2:1)
Block(-11,18,9,LEAVES_2:1)
Block(-11,18,10,LEAVES_2:1)
Block(-11,18,12,LEAVES_2:1)
Block(-11,19,-9,LEAVES_2:1)
Block(-11,19,-8,LEAVES_2:1)
Block(-11,19,-7,LEAVES_2:1)
Block(-11,19,-6,LEAVES_2:1)
Block(-11,19,-5,LEAVES_2:1)
Block(-11,19,-4,LEAVES_2:1)
Block(-11,19,-3,LEAVES_2:1)
Block(-11,19,-2,LEAVES_2:1)
Block(-11,19,-1,LEAVES_2:1)
Block(-11,19,0,LEAVES_2:1)
Block(-11,19,1,LEAVES_2:1)
Block(-11,19,2,LEAVES_2:1)
Block(-11,19,7,LEAVES_2:1)
Block(-11,19,8,LEAVES_2:1)
Block(-11,19,9,LEAVES_2:1)
Block(-11,19,10,LEAVES_2:1)
Block(-11,19,11,LEAVES_2:1)
Block(-11,19,12,LEAVES_2:1)
Block(-11,20,-7,LEAVES_2:1)
Block(-11,20,-6,LEAVES_2:1)
Block(-11,20,-5,LEAVES_2:1)
Block(-11,20,-4,LEAVES_2:1)
Block(-11,20,-3,LEAVES_2:1)
Block(-11,20,-2,LEAVES_2:1)
Block(-11,20,-1,LEAVES_2:1)
Block(-11,20,0,LEAVES_2:1)
Block(-11,20,1,LEAVES_2:1)
Block(-11,20,2,LEAVES_2:1)
Block(-11,20,3,LEAVES_2:1)
Block(-11,20,6,LEAVES_2:1)
Block(-11,20,7,LEAVES_2:1)
Block(-11,20,8,LEAVES_2:1)
Block(-11,20,9,LEAVES_2:1)
Block(-11,21,-6,LEAVES_2:1)
Block(-11,21,-5,LEAVES_2:1)
Block(-11,21,-4,LEAVES_2:1)
Block(-11,21,-3,LEAVES_2:1)
Block(-11,21,-2,LEAVES_2:1)
Block(-11,21,-1,LEAVES_2:1)
Block(-11,21,0,LEAVES_2:1)
Block(-11,21,1,LEAVES_2:1)
Block(-11,21,2,LEAVES_2:1)
Block(-11,21,3,LEAVES_2:1)
Block(-11,21,4,LEAVES_2:1)
Block(-11,21,5,LEAVES_2:1)
Block(-11,21,6,LEAVES_2:1)
Block(-11,21,7,LEAVES_2:1)
Block(-11,21,8,LEAVES_2:1)
Block(-11,22,0,LEAVES_2:1)
Block(-11,22,1,LEAVES_2:1)
Block(-11,22,2,LEAVES_2:1)
Block(-11,22,3,LEAVES_2:1)
Block(-11,22,4,LEAVES_2:1)
Block(-11,22,5,LEAVES_2:1)
Block(-11,22,6,LEAVES_2:1)
Block(-10,10,11,LOG_2:1)
Block(-10,10,12,LOG_2:1)
Block(-10,10,13,LOG_2:1)
Block(-10,11,11,LOG_2:1)
Block(-10,11,12,LOG_2:1)
Block(-10,11,13,LOG_2:1)
Block(-10,11,14,LEAVES_2:1)
Block(-10,12,12,LOG_2:1)
Block(-10,12,13,LEAVES_2:1)
Block(-10,12,14,LEAVES_2:1)
Block(-10,12,15,LEAVES_2:1)
Block(-10,13,13,LEAVES_2:1)
Block(-10,13,14,LEAVES_2:1)
Block(-10,13,15,LEAVES_2:1)
Block(-10,14,5,LOG_2:1)
Block(-10,14,6,LOG_2:1)
Block(-10,14,14,LEAVES_2:1)
Block(-10,14,15,LEAVES_2:1)
Block(-10,14,16,LEAVES_2:1)
Block(-10,15,4,LOG_2:1)
Block(-10,15,5,LOG_2:1)
Block(-10,15,6,LOG_2:1)
Block(-10,15,13,LEAVES_2:1)
Block(-10,15,14,LEAVES_2:1)
Block(-10,15,15,LEAVES_2:1)
Block(-10,15,16,LEAVES_2:1)
Block(-10,16,-9,LEAVES_2:1)
Block(-10,16,4,LOG_2:1)
Block(-10,16,5,LOG_2:1)
Block(-10,16,6,LOG_2:1)
Block(-10,16,12,LEAVES_2:1)
Block(-10,16,13,LEAVES_2:1)
Block(-10,16,14,LEAVES_2:1)
Block(-10,16,15,LEAVES_2:1)
Block(-10,17,-10,LEAVES_2:1)
Block(-10,17,-9,LEAVES_2:1)
Block(-10,17,10,LEAVES_2:1)
Block(-10,17,12,LEAVES_2:1)
Block(-10,17,13,LEAVES_2:1)
Block(-10,17,14,LEAVES_2:1)
Block(-10,18,-11,LEAVES_2:1)
Block(-10,18,-10,LEAVES_2:1)
Block(-10,18,-9,LEAVES_2:1)
Block(-10,18,-8,LEAVES_2:1)
Block(-10,18,-7,LEAVES_2:1)
Block(-10,18,9,LEAVES_2:1)
Block(-10,18,10,LEAVES_2:1)
Block(-10,18,11,LEAVES_2:1)
Block(-10,18,12,LEAVES_2:1)
Block(-10,18,13,LEAVES_2:1)
Block(-10,19,-9,LEAVES_2:1)
Block(-10,19,-8,LEAVES_2:1)
Block(-10,19,-7,LEAVES_2:1)
Block(-10,19,-6,LEAVES_2:1)
Block(-10,19,-5,LEAVES_2:1)
Block(-10,19,8,LEAVES_2:1)
Block(-10,19,9,LEAVES_2:1)
Block(-10,19,10,LEAVES_2:1)
Block(-10,19,11,LEAVES_2:1)
Block(-10,19,12,LEAVES_2:1)
Block(-10,19,13,LEAVES_2:1)
Block(-10,20,-8,LEAVES_2:1)
Block(-10,20,-7,LEAVES_2:1)
Block(-10,20,-6,LEAVES_2:1)
Block(-10,20,-5,LEAVES_2:1)
Block(-10,20,-4,LEAVES_2:1)
Block(-10,20,-3,LEAVES_2:1)
Block(-10,20,-2,LEAVES_2:1)
Block(-10,20,-1,LEAVES_2:1)
Block(-10,20,0,LEAVES_2:1)
Block(-10,20,1,LEAVES_2:1)
Block(-10,20,2,LEAVES_2:1)
Block(-10,20,3,LEAVES_2:1)
Block(-10,20,6,LEAVES_2:1)
Block(-10,20,7,LEAVES_2:1)
Block(-10,20,8,LEAVES_2:1)
Block(-10,20,9,LEAVES_2:1)
Block(-10,20,10,LEAVES_2:1)
Block(-10,20,11,LEAVES_2:1)
Block(-10,20,12,LEAVES_2:1)
Block(-10,21,-7,LEAVES_2:1)
Block(-10,21,-6,LEAVES_2:1)
Block(-10,21,-5,LEAVES_2:1)
Block(-10,21,-4,LEAVES_2:1)
Block(-10,21,-3,LEAVES_2:1)
Block(-10,21,-2,LEAVES_2:1)
Block(-10,21,-1,LEAVES_2:1)
Block(-10,21,0,LEAVES_2:1)
Block(-10,21,1,LEAVES_2:1)
Block(-10,21,2,LEAVES_2:1)
Block(-10,21,3,LEAVES_2:1)
Block(-10,21,4,LEAVES_2:1)
Block(-10,21,5,LEAVES_2:1)
Block(-10,21,6,LEAVES_2:1)
Block(-10,21,7,LEAVES_2:1)
Block(-10,21,8,LEAVES_2:1)
Block(-10,21,9,LEAVES_2:1)
Block(-10,21,10,LEAVES_2:1)
Block(-10,22,-3,LEAVES_2:1)
Block(-10,22,-2,LEAVES_2:1)
Block(-10,22,-1,LEAVES_2:1)
Block(-10,22,0,LEAVES_2:1)
Block(-10,22,1,LEAVES_2:1)
Block(-10,22,2,LEAVES_2:1)
Block(-10,22,3,LEAVES_2:1)
Block(-10,22,4,LEAVES_2:1)
Block(-10,22,5,LEAVES_2:1)
Block(-10,22,6,LEAVES_2:1)
Block(-10,22,7,LEAVES_2:1)
Block(-10,23,3,LEAVES_2:1)
Block(-10,23,4,LEAVES_2:1)
Block(-9,9,11,LOG_2:1)
Block(-9,9,12,LOG_2:1)
Block(-9,10,10,LOG_2:1)
Block(-9,10,11,LOG_2:1)
Block(-9,10,12,LOG_2:1)
Block(-9,10,13,LOG_2:1)
Block(-9,11,11,LOG_2:1)
Block(-9,11,12,LOG_2:1)
Block(-9,12,6,LOG_2:1)
Block(-9,12,7,LOG_2:1)
Block(-9,12,11,LOG_2:1)
Block(-9,12,14,LEAVES_2:1)
Block(-9,13,5,LOG_2:1)
Block(-9,13,6,LOG_2:1)
Block(-9,13,7,LOG_2:1)
Block(-9,13,8,LOG_2:1)
Block(-9,13,14,LEAVES_2:1)
Block(-9,14,5,LOG_2:1)
Block(-9,14,6,LOG_2:1)
Block(-9,14,7,LOG_2:1)
Block(-9,14,8,LOG_2:1)
Block(-9,14,15,LEAVES_2:1)
Block(-9,15,5,LOG_2:1)
Block(-9,15,6,LOG_2:1)
Block(-9,15,7,LOG_2:1)
Block(-9,15,13,LEAVES_2:1)
Block(-9,15,14,LEAVES_2:1)
Block(-9,15,15,LEAVES_2:1)
Block(-9,15,16,LEAVES_2:1)
Block(-9,16,-9,LEAVES_2:1)
Block(-9,16,5,LOG_2:1)
Block(-9,16,6,LOG_2:1)
Block(-9,16,12,LEAVES_2:1)
Block(-9,16,13,LEAVES_2:1)
Block(-9,16,14,LEAVES_2:1)
Block(-9,16,15,LEAVES_2:1)
Block(-9,17,-11,LEAVES_2:1)
Block(-9,17,-10,LEAVES_2:1)
Block(-9,17,-9,LEAVES_2:1)
Block(-9,17,12,LEAVES_2:1)
Block(-9,17,13,LEAVES_2:1)
Block(-9,17,14,LEAVES_2:1)
Block(-9,17,15,LEAVES_2:1)
Block(-9,18,-11,LEAVES_2:1)
Block(-9,18,-10,LEAVES_2:1)
Block(-9,18,-9,LEAVES_2:1)
Block(-9,18,-8,LEAVES_2:1)
Block(-9,18,11,LEAVES_2:1)
Block(-9,18,12,LEAVES_2:1)
Block(-9,18,13,LEAVES_2:1)
Block(-9,18,14,LEAVES_2:1)
Block(-9,19,-10,LEAVES_2:1)
Block(-9,19,-9,LEAVES_2:1)
Block(-9,19,-8,LEAVES_2:1)
Block(-9,19,-7,LEAVES_2:1)
Block(-9,19,-6,LEAVES_2:1)
Block(-9,19,9,LEAVES_2:1)
Block(-9,19,10,LEAVES_2:1)
Block(-9,19,11,LEAVES_2:1)
Block(-9,19,12,LEAVES_2:1)
Block(-9,19,13,LEAVES_2:1)
Block(-9,20,-10,LEAVES_2:1)
Block(-9,20,-9,LEAVES_2:1)
Block(-9,20,-8,LEAVES_2:1)
Block(-9,20,-7,LEAVES_2:1)
Block(-9,20,-6,LEAVES_2:1)
Block(-9,20,-5,LEAVES_2:1)
Block(-9,20,-3,LEAVES_2:1)
Block(-9,20,-2,LEAVES_2:1)
Block(-9,20,3,LEAVES_2:1)
Block(-9,20,8,LEAVES_2:1)
Block(-9,20,9,LEAVES_2:1)
Block(-9,20,10,LEAVES_2:1)
Block(-9,20,12,LEAVES_2:1)
Block(-9,21,-8,LEAVES_2:1)
Block(-9,21,-7,LEAVES_2:1)
Block(-9,21,-6,LEAVES_2:1)
Block(-9,21,-5,LEAVES_2:1)
Block(-9,21,-4,LEAVES_2:1)
Block(-9,21,-3,LEAVES_2:1)
Block(-9,21,-2,LEAVES_2:1)
Block(-9,21,-1,LEAVES_2:1)
Block(-9,21,0,LEAVES_2:1)
Block(-9,21,1,LEAVES_2:1)
Block(-9,21,2,LEAVES_2:1)
Block(-9,21,3,LEAVES_2:1)
Block(-9,21,4,LEAVES_2:1)
Block(-9,21,5,LEAVES_2:1)
Block(-9,21,6,LEAVES_2:1)
Block(-9,21,7,LEAVES_2:1)
Block(-9,21,8,LEAVES_2:1)
Block(-9,21,9,LEAVES_2:1)
Block(-9,21,10,LEAVES_2:1)
Block(-9,21,11,LEAVES_2:1)
Block(-9,22,-6,LEAVES_2:1)
Block(-9,22,-5,LEAVES_2:1)
Block(-9,22,-4,LEAVES_2:1)
Block(-9,22,-3,LEAVES_2:1)
Block(-9,22,-2,LEAVES_2:1)
Block(-9,22,-1,LEAVES_2:1)
Block(-9,22,0,LEAVES_2:1)
Block(-9,22,1,LEAVES_2:1)
Block(-9,22,2,LEAVES_2:1)
Block(-9,22,3,LEAVES_2:1)
Block(-9,22,4,LEAVES_2:1)
Block(-9,22,5,LEAVES_2:1)
Block(-9,22,6,LEAVES_2:1)
Block(-9,22,7,LEAVES_2:1)
Block(-9,22,8,LEAVES_2:1)
Block(-9,22,9,LEAVES_2:1)
Block(-9,22,10,LEAVES_2:1)
Block(-9,23,-1,LEAVES_2:1)
Block(-9,23,0,LEAVES_2:1)
Block(-9,23,1,LEAVES_2:1)
Block(-9,23,2,LEAVES_2:1)
Block(-9,23,3,LEAVES_2:1)
Block(-9,23,4,LEAVES_2:1)
Block(-9,23,5,LEAVES_2:1)
Block(-8,9,11,LOG_2:1)
Block(-8,10,8,LOG_2:1)
Block(-8,10,9,LOG_2:1)
Block(-8,10,10,LOG_2:1)
Block(-8,10,11,LOG_2:1)
Block(-8,10,12,LOG_2:1)
Block(-8,11,7,LOG_2:1)
Block(-8,11,8,LOG_2:1)
Block(-8,11,9,LOG_2:1)
Block(-8,11,10,LOG_2:1)
Block(-8,11,11,LOG_2:1)
Block(-8,12,6,LOG_2:1)
Block(-8,12,7,LOG_2:1)
Block(-8,12,8,LOG_2:1)
Block(-8,12,9,LOG_2:1)
Block(-8,13,5,LOG_2:1)
Block(-8,13,6,LOG_2:1)
Block(-8,13,7,LOG_2:1)
Block(-8,13,8,LOG_2:1)
Block(-8,13,9,LOG_2:1)
Block(-8,14,5,LOG_2:1)
Block(-8,14,6,LOG_2:1)
Block(-8,14,7,LOG_2:1)
Block(-8,14,8,LOG_2:1)
Block(-8,15,-9,LEAVES_2:1)
Block(-8,15,6,LOG_2:1)
Block(-8,15,7,LOG_2:1)
Block(-8,15,8,LOG_2:1)
Block(-8,15,15,LEAVES_2:1)
Block(-8,16,-10,LEAVES_2:1)
Block(-8,16,13,LEAVES_2:1)
Block(-8,16,14,LEAVES_2:1)
Block(-8,16,15,LEAVES_2:1)
Block(-8,17,-11,LEAVES_2:1)
Block(-8,17,-10,LEAVES_2:1)
Block(-8,17,13,LEAVES_2:1)
Block(-8,17,14,LEAVES_2:1)
Block(-8,17,15,LEAVES_2:1)
Block(-8,18,-11,LEAVES_2:1)
Block(-8,18,-10,LEAVES_2:1)
Block(-8,18,-9,LEAVES_2:1)
Block(-8,18,12,LEAVES_2:1)
Block(-8,18,13,LEAVES_2:1)
Block(-8,18,14,LEAVES_2:1)
Block(-8,19,-11,LEAVES_2:1)
Block(-8,19,-10,LEAVES_2:1)
Block(-8,19,-9,LEAVES_2:1)
Block(-8,19,-8,LEAVES_2:1)
Block(-8,19,11,LEAVES_2:1)
Block(-8,19,12,LEAVES_2:1)
Block(-8,19,13,LEAVES_2:1)
Block(-8,19,14,LEAVES_2:1)
Block(-8,20,-10,LEAVES_2:1)
Block(-8,20,-9,LEAVES_2:1)
Block(-8,20,-8,LEAVES_2:1)
Block(-8,20,-7,LEAVES_2:1)
Block(-8,20,-6,LEAVES_2:1)
Block(-8,20,2,LEAVES_2:1)
Block(-8,20,3,LEAVES_2:1)
Block(-8,20,5,LEAVES_2:1)
Block(-8,20,6,LEAVES_2:1)
Block(-8,20,7,LEAVES_2:1)
Block(-8,20,8,LEAVES_2:1)
Block(-8,20,9,LEAVES_2:1)
Block(-8,20,10,LEAVES_2:1)
Block(-8,20,12,LEAVES_2:1)
Block(-8,20,13,LEAVES_2:1)
Block(-8,21,-10,LEAVES_2:1)
Block(-8,21,-9,LEAVES_2:1)
Block(-8,21,-8,LEAVES_2:1)
Block(-8,21,-7,LEAVES_2:1)
Block(-8,21,-6,LEAVES_2:1)
Block(-8,21,-4,LEAVES_2:1)
Block(-8,21,-3,LEAVES_2:1)
Block(-8,21,-2,LEAVES_2:1)
Block(-8,21,0,LEAVES_2:1)
Block(-8,21,1,LEAVES_2:1)
Block(-8,21,2,LEAVES_2:1)
Block(-8,21,3,LEAVES_2:1)
Block(-8,21,4,LEAVES_2:1)
Block(-8,21,5,LEAVES_2:1)
Block(-8,21,6,LEAVES_2:1)
Block(-8,21,7,LEAVES_2:1)
Block(-8,21,8,LEAVES_2:1)
Block(-8,21,9,LEAVES_2:1)
Block(-8,21,10,LEAVES_2:1)
Block(-8,21,11,LEAVES_2:1)
Block(-8,21,12,LEAVES_2:1)
Block(-8,22,-7,LEAVES_2:1)
Block(-8,22,-6,LEAVES_2:1)
Block(-8,22,-5,LEAVES_2:1)
Block(-8,22,-4,LEAVES_2:1)
Block(-8,22,-3,LEAVES_2:1)
Block(-8,22,-2,LEAVES_2:1)
Block(-8,22,-1,LEAVES_2:1)
Block(-8,22,0,LEAVES_2:1)
Block(-8,22,1,LEAVES_2:1)
Block(-8,22,2,LEAVES_2:1)
Block(-8,22,3,LEAVES_2:1)
Block(-8,22,4,LEAVES_2:1)
Block(-8,22,5,LEAVES_2:1)
Block(-8,22,6,LEAVES_2:1)
Block(-8,22,7,LEAVES_2:1)
Block(-8,22,8,LEAVES_2:1)
Block(-8,22,9,LEAVES_2:1)
Block(-8,22,10,LEAVES_2:1)
Block(-8,22,11,LEAVES_2:1)
Block(-8,23,-4,LEAVES_2:1)
Block(-8,23,-3,LEAVES_2:1)
Block(-8,23,-2,LEAVES_2:1)
Block(-8,23,-1,LEAVES_2:1)
Block(-8,23,0,LEAVES_2:1)
Block(-8,23,1,LEAVES_2:1)
Block(-8,23,2,LEAVES_2:1)
Block(-8,23,3,LEAVES_2:1)
Block(-8,23,4,LEAVES_2:1)
Block(-8,23,5,LEAVES_2:1)
Block(-8,23,6,LEAVES_2:1)
Block(-8,23,7,LEAVES_2:1)
Block(-8,23,8,LEAVES_2:1)
Block(-8,23,9,LEAVES_2:1)
Block(-8,24,1,LEAVES_2:1)
Block(-8,24,2,LEAVES_2:1)
Block(-8,24,3,LEAVES_2:1)
Block(-7,9,8,LOG_2:1)
Block(-7,9,9,LOG_2:1)
Block(-7,9,10,LOG_2:1)
Block(-7,10,7,LOG_2:1)
Block(-7,10,8,LOG_2:1)
Block(-7,10,9,LOG_2:1)
Block(-7,10,10,LOG_2:1)
Block(-7,10,11,LOG_2:1)
Block(-7,11,6,LOG_2:1)
Block(-7,11,7,LOG_2:1)
Block(-7,11,8,LOG_2:1)
Block(-7,11,9,LOG_2:1)
Block(-7,11,10,LOG_2:1)
Block(-7,12,6,LOG_2:1)
Block(-7,12,7,LOG_2:1)
Block(-7,12,8,LOG_2:1)
Block(-7,12,9,LOG_2:1)
Block(-7,12,10,LOG_2:1)
Block(-7,13,6,LOG_2:1)
Block(-7,13,7,LOG_2:1)
Block(-7,13,8,LOG_2:1)
Block(-7,13,9,LOG_2:1)
Block(-7,13,10,LOG_2:1)
Block(-7,14,7,LOG_2:1)
Block(-7,14,8,LOG_2:1)
Block(-7,14,9,LOG_2:1)
Block(-7,15,-10,LEAVES_2:1)
Block(-7,15,7,LOG_2:1)
Block(-7,15,8,LOG_2:1)
Block(-7,15,9,LOG_2:1)
Block(-7,15,14,LEAVES_2:1)
Block(-7,16,-10,LEAVES_2:1)
Block(-7,16,9,LOG_2:1)
Block(-7,16,13,LEAVES_2:1)
Block(-7,16,14,LEAVES_2:1)
Block(-7,16,15,LEAVES_2:1)
Block(-7,17,-11,LEAVES_2:1)
Block(-7,17,-10,LEAVES_2:1)
Block(-7,17,13,LEAVES_2:1)
Block(-7,17,14,LEAVES_2:1)
Block(-7,17,15,LEAVES_2:1)
Block(-7,18,-12,LEAVES_2:1)
Block(-7,18,-11,LEAVES_2:1)
Block(-7,18,-10,LEAVES_2:1)
Block(-7,18,12,LEAVES_2:1)
Block(-7,18,13,LEAVES_2:1)
Block(-7,18,14,LEAVES_2:1)
Block(-7,18,15,LEAVES_2:1)
Block(-7,19,-11,LEAVES_2:1)
Block(-7,19,-10,LEAVES_2:1)
Block(-7,19,12,LEAVES_2:1)
Block(-7,19,13,LEAVES_2:1)
Block(-7,19,14,LEAVES_2:1)
Block(-7,20,-11,LEAVES_2:1)
Block(-7,20,-10,LEAVES_2:1)
Block(-7,20,-9,LEAVES_2:1)
Block(-7,20,-8,LEAVES_2:1)
Block(-7,20,11,LEAVES_2:1)
Block(-7,20,12,LEAVES_2:1)
Block(-7,20,13,LEAVES_2:1)
Block(-7,20,14,LEAVES_2:1)
Block(-7,21,-10,LEAVES_2:1)
Block(-7,21,-9,LEAVES_2:1)
Block(-7,21,-8,LEAVES_2:1)
Block(-7,21,-7,LEAVES_2:1)
Block(-7,21,-4,LEAVES_2:1)
Block(-7,21,-3,LEAVES_2:1)
Block(-7,21,0,LEAVES_2:1)
Block(-7,21,1,LEAVES_2:1)
Block(-7,21,2,LEAVES_2:1)
Block(-7,21,3,LEAVES_2:1)
Block(-7,21,5,LEAVES_2:1)
Block(-7,21,6,LEAVES_2:1)
Block(-7,21,7,LEAVES_2:1)
Block(-7,21,8,LEAVES_2:1)
Block(-7,21,9,LEAVES_2:1)
Block(-7,21,10,LEAVES_2:1)
Block(-7,21,11,LEAVES_2:1)
Block(-7,21,12,LEAVES_2:1)
Block(-7,21,13,LEAVES_2:1)
Block(-7,22,-9,LEAVES_2:1)
Block(-7,22,-8,LEAVES_2:1)
Block(-7,22,-7,LEAVES_2:1)
Block(-7,22,-6,LEAVES_2:1)
Block(-7,22,-5,LEAVES_2:1)
Block(-7,22,-4,LEAVES_2:1)
Block(-7,22,-3,LEAVES_2:1)
Block(-7,22,-2,LEAVES_2:1)
Block(-7,22,-1,LEAVES_2:1)
Block(-7,22,0,LEAVES_2:1)
Block(-7,22,1,LEAVES_2:1)
Block(-7,22,2,LEAVES_2:1)
Block(-7,22,3,LEAVES_2:1)
Block(-7,22,4,LEAVES_2:1)
Block(-7,22,5,LEAVES_2:1)
Block(-7,22,6,LEAVES_2:1)
Block(-7,22,7,LEAVES_2:1)
Block(-7,22,8,LEAVES_2:1)
Block(-7,22,9,LEAVES_2:1)
Block(-7,22,10,LEAVES_2:1)
Block(-7,22,11,LEAVES_2:1)
Block(-7,22,12,LEAVES_2:1)
Block(-7,23,-6,LEAVES_2:1)
Block(-7,23,-5,LEAVES_2:1)
Block(-7,23,-4,LEAVES_2:1)
Block(-7,23,-3,LEAVES_2:1)
Block(-7,23,-2,LEAVES_2:1)
Block(-7,23,-1,LEAVES_2:1)
Block(-7,23,0,LEAVES_2:1)
Block(-7,23,1,LEAVES_2:1)
Block(-7,23,2,LEAVES_2:1)
Block(-7,23,3,LEAVES_2:1)
Block(-7,23,4,LEAVES_2:1)
Block(-7,23,5,LEAVES_2:1)
Block(-7,23,6,LEAVES_2:1)
Block(-7,23,7,LEAVES_2:1)
Block(-7,23,8,LEAVES_2:1)
Block(-7,23,9,LEAVES_2:1)
Block(-7,23,10,LEAVES_2:1)
Block(-7,24,-1,LEAVES_2:1)
Block(-7,24,0,LEAVES_2:1)
Block(-7,24,1,LEAVES_2:1)
Block(-7,24,2,LEAVES_2:1)
Block(-7,24,3,LEAVES_2:1)
Block(-7,24,4,LEAVES_2:1)
Block(-7,24,5,LEAVES_2:1)
Block(-7,24,6,LEAVES_2:1)
Block(-6,8,8,LOG_2:1)
Block(-6,8,9,LOG_2:1)
Block(-6,9,7,LOG_2:1)
Block(-6,9,8,LOG_2:1)
Block(-6,9,9,LOG_2:1)
Block(-6,9,10,LOG_2:1)
Block(-6,10,6,LOG_2:1)
Block(-6,10,7,LOG_2:1)
Block(-6,10,8,LOG_2:1)
Block(-6,10,9,LOG_2:1)
Block(-6,10,10,LOG_2:1)
Block(-6,11,6,LOG_2:1)
Block(-6,11,7,LOG_2:1)
Block(-6,11,8,LOG_2:1)
Block(-6,11,9,LOG_2:1)
Block(-6,11,10,LOG_2:1)
Block(-6,12,7,LOG_2:1)
Block(-6,12,8,LOG_2:1)
Block(-6,12,9,LOG_2:1)
Block(-6,13,8,LOG_2:1)
Block(-6,14,8,LOG_2:1)
Block(-6,14,9,LOG_2:1)
Block(-6,15,-10,LEAVES_2:1)
Block(-6,15,8,LOG_2:1)
Block(-6,15,9,LOG_2:1)
Block(-6,15,14,LEAVES_2:1)
Block(-6,16,-11,LEAVES_2:1)
Block(-6,16,-10,LEAVES_2:1)
Block(-6,16,8,LOG_2:1)
Block(-6,16,9,LOG_2:1)
Block(-6,16,14,LEAVES_2:1)
Block(-6,17,-12,LEAVES_2:1)
Block(-6,17,-11,LEAVES_2:1)
Block(-6,17,-10,LEAVES_2:1)
Block(-6,17,9,LOG_2:1)
Block(-6,17,10,LOG_2:1)
Block(-6,17,13,LEAVES_2:1)
Block(-6,17,14,LEAVES_2:1)
Block(-6,17,15,LEAVES_2:1)
Block(-6,18,-12,LEAVES_2:1)
Block(-6,18,-11,LEAVES_2:1)
Block(-6,18,-10,LEAVES_2:1)
Block(-6,18,-8,LOG_2:1)
Block(-6,18,10,LOG_2:1)
Block(-6,18,12,LEAVES_2:1)
Block(-6,18,13,LEAVES_2:1)
Block(-6,18,14,LEAVES_2:1)
Block(-6,18,15,LEAVES_2:1)
Block(-6,19,-11,LEAVES_2:1)
Block(-6,19,-10,LEAVES_2:1)
Block(-6,19,-9,LOG_2:1)
Block(-6,19,-8,LOG_2:1)
Block(-6,19,12,LEAVES_2:1)
Block(-6,19,13,LEAVES_2:1)
Block(-6,19,14,LEAVES_2:1)
Block(-6,20,-11,LEAVES_2:1)
Block(-6,20,-10,LEAVES_2:1)
Block(-6,20,-9,LOG_2:1)
Block(-6,20,-8,LEAVES_2:1)
Block(-6,20,-3,LEAVES_2:1)
Block(-6,20,3,LEAVES_2:1)
Block(-6,20,11,LEAVES_2:1)
Block(-6,20,12,LEAVES_2:1)
Block(-6,20,13,LEAVES_2:1)
Block(-6,20,14,LEAVES_2:1)
Block(-6,21,-10,LEAVES_2:1)
Block(-6,21,-9,LOG_2:1)
Block(-6,21,-8,LEAVES_2:1)
Block(-6,21,-4,LEAVES_2:1)
Block(-6,21,-3,LEAVES_2:1)
Block(-6,21,-2,LEAVES_2:1)
Block(-6,21,0,LEAVES_2:1)
Block(-6,21,2,LEAVES_2:1)
Block(-6,21,3,LEAVES_2:1)
Block(-6,21,4,LEAVES_2:1)
Block(-6,21,9,LEAVES_2:1)
Block(-6,21,10,LEAVES_2:1)
Block(-6,21,11,LEAVES_2:1)
Block(-6,21,12,LEAVES_2:1)
Block(-6,21,13,LEAVES_2:1)
Block(-6,22,-10,LEAVES_2:1)
Block(-6,22,-9,LEAVES_2:1)
Block(-6,22,-8,LEAVES_2:1)
Block(-6,22,-7,LEAVES_2:1)
Block(-6,22,-6,LEAVES_2:1)
Block(-6,22,-5,LEAVES_2:1)
Block(-6,22,-4,LEAVES_2:1)
Block(-6,22,-3,LEAVES_2:1)
Block(-6,22,-2,LEAVES_2:1)
Block(-6,22,-1,LEAVES_2:1)
Block(-6,22,0,LEAVES_2:1)
Block(-6,22,1,LEAVES_2:1)
Block(-6,22,2,LEAVES_2:1)
Block(-6,22,3,LEAVES_2:1)
Block(-6,22,4,LEAVES_2:1)
Block(-6,22,6,LEAVES_2:1)
Block(-6,22,8,LEAVES_2:1)
Block(-6,22,9,LEAVES_2:1)
Block(-6,22,10,LEAVES_2:1)
Block(-6,22,11,LEAVES_2:1)
Block(-6,22,12,LEAVES_2:1)
Block(-6,23,-8,LEAVES_2:1)
Block(-6,23,-7,LEAVES_2:1)
Block(-6,23,-6,LEAVES_2:1)
Block(-6,23,-5,LEAVES_2:1)
Block(-6,23,-4,LEAVES_2:1)
Block(-6,23,-3,LEAVES_2:1)
Block(-6,23,-2,LEAVES_2:1)
Block(-6,23,-1,LEAVES_2:1)
Block(-6,23,0,LEAVES_2:1)
Block(-6,23,1,LEAVES_2:1)
Block(-6,23,2,LEAVES_2:1)
Block(-6,23,3,LEAVES_2:1)
Block(-6,23,4,LEAVES_2:1)
Block(-6,23,5,LEAVES_2:1)
Block(-6,23,6,LEAVES_2:1)
Block(-6,23,7,LEAVES_2:1)
Block(-6,23,8,LEAVES_2:1)
Block(-6,23,9,LEAVES_2:1)
Block(-6,23,10,LEAVES_2:1)
Block(-6,23,11,LEAVES_2:1)
Block(-6,24,-2,LEAVES_2:1)
Block(-6,24,-1,LEAVES_2:1)
Block(-6,24,0,LEAVES_2:1)
Block(-6,24,1,LEAVES_2:1)
Block(-6,24,2,LEAVES_2:1)
Block(-6,24,3,LEAVES_2:1)
Block(-6,24,4,LEAVES_2:1)
Block(-6,24,5,LEAVES_2:1)
Block(-6,24,6,LEAVES_2:1)
Block(-6,24,7,LEAVES_2:1)
Block(-6,24,8,LEAVES_2:1)
Block(-6,24,9,LEAVES_2:1)
Block(-6,25,1,LEAVES_2:1)
Block(-6,25,2,LEAVES_2:1)
Block(-6,25,3,LEAVES_2:1)
Block(-5,7,8,LOG_2:1)
Block(-5,7,9,LOG_2:1)
Block(-5,8,7,LOG_2:1)
Block(-5,8,8,LOG_2:1)
Block(-5,8,9,LOG_2:1)
Block(-5,8,10,LOG_2:1)
Block(-5,9,7,LOG_2:1)
Block(-5,9,8,LOG_2:1)
Block(-5,9,9,LOG_2:1)
Block(-5,9,10,LOG_2:1)
Block(-5,10,7,LOG_2:1)
Block(-5,10,8,LOG_2:1)
Block(-5,10,9,LOG_2:1)
Block(-5,11,7,LOG_2:1)
Block(-5,11,8,LOG_2:1)
Block(-5,12,8,LOG_2:1)
Block(-5,14,-7,LOG_2:1)
Block(-5,15,-11,LEAVES_2:1)
Block(-5,15,-7,LOG_2:1)
Block(-5,15,9,LOG_2:1)
Block(-5,16,-12,LEAVES_2:1)
Block(-5,16,-11,LEAVES_2:1)
Block(-5,16,-8,LOG_2:1)
Block(-5,16,-7,LOG_2:1)
Block(-5,16,9,LOG_2:1)
Block(-5,16,10,LOG_2:1)
Block(-5,16,14,LEAVES_2:1)
Block(-5,17,-12,LEAVES_2:1)
Block(-5,17,-11,LEAVES_2:1)
Block(-5,17,-10,LEAVES_2:1)
Block(-5,17,-9,LOG_2:1)
Block(-5,17,-8,LOG_2:1)
Block(-5,17,-7,LOG_2:1)
Block(-5,17,9,LOG_2:1)
Block(-5,17,10,LOG_2:1)
Block(-5,17,11,LOG_2:1)
Block(-5,17,13,LEAVES_2:1)
Block(-5,17,14,LEAVES_2:1)
Block(-5,17,15,LEAVES_2:1)
Block(-5,18,-12,LEAVES_2:1)
Block(-5,18,-11,LEAVES_2:1)
Block(-5,18,-10,LEAVES_2:1)
Block(-5,18,-9,LOG_2:1)
Block(-5,18,-8,LOG_2:1)
Block(-5,18,-7,LOG_2:1)
Block(-5,18,9,LOG_2:1)
Block(-5,18,10,LOG_2:1)
Block(-5,18,11,LOG_2:1)
Block(-5,18,13,LEAVES_2:1)
Block(-5,18,14,LEAVES_2:1)
Block(-5,18,15,LEAVES_2:1)
Block(-5,18,16,LEAVES_2:1)
Block(-5,19,-11,LEAVES_2:1)
Block(-5,19,-10,LEAVES_2:1)
Block(-5,19,-9,LOG_2:1)
Block(-5,19,-8,LOG_2:1)
Block(-5,19,-7,LOG_2:1)
Block(-5,19,10,LOG_2:1)
Block(-5,19,13,LEAVES_2:1)
Block(-5,19,14,LEAVES_2:1)
Block(-5,19,15,LEAVES_2:1)
Block(-5,20,-10,LEAVES_2:1)
Block(-5,20,-9,LOG_2:1)
Block(-5,20,-8,LOG_2:1)
Block(-5,20,12,LEAVES_2:1)
Block(-5,20,13,LEAVES_2:1)
Block(-5,20,14,LEAVES_2:1)
Block(-5,21,-10,LEAVES_2:1)
Block(-5,21,-9,LOG_2:1)
Block(-5,21,-8,LEAVES_2:1)
Block(-5,21,-7,LEAVES_2:1)
Block(-5,21,-6,LEAVES_2:1)
Block(-5,21,-5,LEAVES_2:1)
Block(-5,21,-4,LEAVES_2:1)
Block(-5,21,-3,LEAVES_2:1)
Block(-5,21,-1,LEAVES_2:1)
Block(-5,21,0,LEAVES_2:1)
Block(-5,21,3,LEAVES_2:1)
Block(-5,21,11,LEAVES_2:1)
Block(-5,21,12,LEAVES_2:1)
Block(-5,21,13,LEAVES_2:1)
Block(-5,21,14,LEAVES_2:1)
Block(-5,22,-9,LEAVES_2:1)
Block(-5,22,-8,LEAVES_2:1)
Block(-5,22,-7,LEAVES_2:1)
Block(-5,22,-6,LEAVES_2:1)
Block(-5,22,-5,LEAVES_2:1)
Block(-5,22,-4,LEAVES_2:1)
Block(-5,22,-3,LEAVES_2:1)
Block(-5,22,-2,LEAVES_2:1)
Block(-5,22,-1,LEAVES_2:1)
Block(-5,22,0,LEAVES_2:1)
Block(-5,22,1,LEAVES_2:1)
Block(-5,22,2,LEAVES_2:1)
Block(-5,22,3,LEAVES_2:1)
Block(-5,22,4,LEAVES_2:1)
Block(-5,22,7,LEAVES_2:1)
Block(-5,22,8,LEAVES_2:1)
Block(-5,22,9,LEAVES_2:1)
Block(-5,22,10,LEAVES_2:1)
Block(-5,22,11,LEAVES_2:1)
Block(-5,22,12,LEAVES_2:1)
Block(-5,22,13,LEAVES_2:1)
Block(-5,23,-7,LEAVES_2:1)
Block(-5,23,-6,LEAVES_2:1)
Block(-5,23,-5,LEAVES_2:1)
Block(-5,23,-4,LEAVES_2:1)
Block(-5,23,-3,LEAVES_2:1)
Block(-5,23,-2,LEAVES_2:1)
Block(-5,23,-1,LEAVES_2:1)
Block(-5,23,0,LEAVES_2:1)
Block(-5,23,1,LEAVES_2:1)
Block(-5,23,2,LEAVES_2:1)
Block(-5,23,3,LEAVES_2:1)
Block(-5,23,4,LEAVES_2:1)
Block(-5,23,5,LEAVES_2:1)
Block(-5,23,6,LEAVES_2:1)
Block(-5,23,7,LEAVES_2:1)
Block(-5,23,8,LEAVES_2:1)
Block(-5,23,9,LEAVES_2:1)
Block(-5,23,10,LEAVES_2:1)
Block(-5,23,11,LEAVES_2:1)
Block(-5,23,12,LEAVES_2:1)
Block(-5,24,-3,LEAVES_2:1)
Block(-5,24,-2,LEAVES_2:1)
Block(-5,24,-1,LEAVES_2:1)
Block(-5,24,0,LEAVES_2:1)
Block(-5,24,1,LEAVES_2:1)
Block(-5,24,2,LEAVES_2:1)
Block(-5,24,3,LEAVES_2:1)
Block(-5,24,4,LEAVES_2:1)
Block(-5,24,5,LEAVES_2:1)
Block(-5,24,6,LEAVES_2:1)
Block(-5,24,7,LEAVES_2:1)
Block(-5,24,8,LEAVES_2:1)
Block(-5,24,9,LEAVES_2:1)
Block(-5,24,10,LEAVES_2:1)
Block(-5,24,11,LEAVES_2:1)
Block(-5,25,1,LEAVES_2:1)
Block(-5,25,2,LEAVES_2:1)
Block(-5,25,3,LEAVES_2:1)
Block(-5,25,4,LEAVES_2:1)
Block(-5,25,5,LEAVES_2:1)
Block(-5,25,6,LEAVES_2:1)
Block(-4,-9,0,LOG_2:1)
Block(-4,-9,1,LOG_2:1)
Block(-4,-8,1,LOG_2:1)
Block(-4,-7,1,LOG_2:1)
Block(-4,-6,1,LOG_2:1)
Block(-4,6,7,LOG_2:1)
Block(-4,7,6,LOG_2:1)
Block(-4,7,7,LOG_2:1)
Block(-4,7,8,LOG_2:1)
Block(-4,8,6,LOG_2:1)
Block(-4,8,7,LOG_2:1)
Block(-4,8,8,LOG_2:1)
Block(-4,8,9,LOG_2:1)
Block(-4,9,7,LOG_2:1)
Block(-4,9,8,LOG_2:1)
Block(-4,10,8,LOG_2:1)
Block(-4,11,-6,LOG_2:1)
Block(-4,12,-7,LOG_2:1)
Block(-4,12,-6,LOG_2:1)
Block(-4,13,-8,LOG_2:1)
Block(-4,13,-7,LOG_2:1)
Block(-4,13,-6,LOG_2:1)
Block(-4,14,-12,LEAVES_2:1)
Block(-4,14,-8,LOG_2:1)
Block(-4,14,-7,LOG_2:1)
Block(-4,14,-6,LOG_2:1)
Block(-4,15,-12,LEAVES_2:1)
Block(-4,15,-11,LEAVES_2:1)
Block(-4,15,-8,LOG_2:1)
Block(-4,15,-7,LOG_2:1)
Block(-4,15,-6,LOG_2:1)
Block(-4,16,-12,LEAVES_2:1)
Block(-4,16,-11,LEAVES_2:1)
Block(-4,16,-10,LEAVES_2:1)
Block(-4,16,-9,LOG_2:1)
Block(-4,16,-8,LOG_2:1)
Block(-4,16,-7,LOG_2:1)
Block(-4,16,1,LOG_2:1)
Block(-4,16,14,LEAVES_2:1)
Block(-4,17,-12,LEAVES_2:1)
Block(-4,17,-11,LEAVES_2:1)
Block(-4,17,-10,LEAVES_2:1)
Block(-4,17,-9,LOG_2:1)
Block(-4,17,-8,LOG_2:1)
Block(-4,17,-7,LOG_2:1)
Block(-4,17,2,LOG_2:1)
Block(-4,17,10,LOG_2:1)
Block(-4,17,12,LEAVES_2:1)
Block(-4,17,13,LEAVES_2:1)
Block(-4,17,14,LEAVES_2:1)
Block(-4,17,15,LEAVES_2:1)
Block(-4,18,-11,LEAVES_2:1)
Block(-4,18,-10,LEAVES_2:1)
Block(-4,18,-9,LOG_2:1)
Block(-4,18,-8,LOG_2:1)
Block(-4,18,2,LOG_2:1)
Block(-4,18,9,LOG_2:1)
Block(-4,18,10,LOG_2:1)
Block(-4,18,11,LOG_2:1)
Block(-4,18,12,LEAVES_2:1)
Block(-4,18,13,LEAVES_2:1)
Block(-4,18,14,LEAVES_2:1)
Block(-4,18,15,LEAVES_2:1)
Block(-4,18,16,LEAVES_2:1)
Block(-4,19,-10,LEAVES_2:1)
Block(-4,19,-9,LEAVES_2:1)
Block(-4,19,-8,LOG_2:1)
Block(-4,19,9,LOG_2:1)
Block(-4,19,10,LOG_2:1)
Block(-4,19,11,LOG_2:1)
Block(-4,19,12,LEAVES_2:1)
Block(-4,19,13,LEAVES_2:1)
Block(-4,19,14,LEAVES_2:1)
Block(-4,19,15,LEAVES_2:1)
Block(-4,19,16,LEAVES_2:1)
Block(-4,20,-10,LEAVES_2:1)
Block(-4,20,-9,LEAVES_2:1)
Block(-4,20,-8,LEAVES_2:1)
Block(-4,20,-5,LEAVES_2:1)
Block(-4,20,-3,LEAVES_2:1)
Block(-4,20,-1,LEAVES_2:1)
Block(-4,20,0,LEAVES_2:1)
Block(-4,20,10,LOG_2:1)
Block(-4,20,11,LOG_2:1)
Block(-4,20,12,LEAVES_2:1)
Block(-4,20,13,LEAVES_2:1)
Block(-4,20,14,LEAVES_2:1)
Block(-4,20,15,LEAVES_2:1)
Block(-4,21,-9,LEAVES_2:1)
Block(-4,21,-8,LEAVES_2:1)
Block(-4,21,-7,LEAVES_2:1)
Block(-4,21,-6,LEAVES_2:1)
Block(-4,21,-5,LEAVES_2:1)
Block(-4,21,-4,LEAVES_2:1)
Block(-4,21,-3,LEAVES_2:1)
Block(-4,21,-2,LEAVES_2:1)
Block(-4,21,-1,LEAVES_2:1)
Block(-4,21,0,LEAVES_2:1)
Block(-4,21,1,LEAVES_2:1)
Block(-4,21,2,LEAVES_2:1)
Block(-4,21,3,LEAVES_2:1)
Block(-4,21,11,LEAVES_2:1)
Block(-4,21,12,LEAVES_2:1)
Block(-4,21,13,LEAVES_2:1)
Block(-4,21,14,LEAVES_2:1)
Block(-4,22,-8,LEAVES_2:1)
Block(-4,22,-7,LEAVES_2:1)
Block(-4,22,-6,LEAVES_2:1)
Block(-4,22,-5,LEAVES_2:1)
Block(-4,22,-4,LEAVES_2:1)
Block(-4,22,-3,LEAVES_2:1)
Block(-4,22,-2,LEAVES_2:1)
Block(-4,22,-1,LEAVES_2:1)
Block(-4,22,0,LEAVES_2:1)
Block(-4,22,1,LEAVES_2:1)
Block(-4,22,2,LEAVES_2:1)
Block(-4,22,3,LEAVES_2:1)
Block(-4,22,4,LEAVES_2:1)
Block(-4,22,5,LEAVES_2:1)
Block(-4,22,8,LEAVES_2:1)
Block(-4,22,9,LEAVES_2:1)
Block(-4,22,10,LEAVES_2:1)
Block(-4,22,11,LEAVES_2:1)
Block(-4,22,12,LEAVES_2:1)
Block(-4,22,13,LEAVES_2:1)
Block(-4,23,-6,LEAVES_2:1)
Block(-4,23,-5,LEAVES_2:1)
Block(-4,23,-4,LEAVES_2:1)
Block(-4,23,-3,LEAVES_2:1)
Block(-4,23,-2,LEAVES_2:1)
Block(-4,23,-1,LEAVES_2:1)
Block(-4,23,0,LEAVES_2:1)
Block(-4,23,1,LEAVES_2:1)
Block(-4,23,2,LEAVES_2:1)
Block(-4,23,3,LEAVES_2:1)
Block(-4,23,4,LEAVES_2:1)
Block(-4,23,5,LEAVES_2:1)
Block(-4,23,6,LEAVES_2:1)
Block(-4,23,7,LEAVES_2:1)
Block(-4,23,8,LEAVES_2:1)
Block(-4,23,9,LEAVES_2:1)
Block(-4,23,10,LEAVES_2:1)
Block(-4,23,11,LEAVES_2:1)
Block(-4,23,12,LEAVES_2:1)
Block(-4,23,13,LEAVES_2:1)
Block(-4,24,-1,LEAVES_2:1)
Block(-4,24,0,LEAVES_2:1)
Block(-4,24,1,LEAVES_2:1)
Block(-4,24,2,LEAVES_2:1)
Block(-4,24,3,LEAVES_2:1)
Block(-4,24,4,LEAVES_2:1)
Block(-4,24,5,LEAVES_2:1)
Block(-4,24,6,LEAVES_2:1)
Block(-4,24,7,LEAVES_2:1)
Block(-4,24,8,LEAVES_2:1)
Block(-4,24,9,LEAVES_2:1)
Block(-4,24,10,LEAVES_2:1)
Block(-4,24,11,LEAVES_2:1)
Block(-4,24,12,LEAVES_2:1)
Block(-4,25,2,LEAVES_2:1)
Block(-4,25,3,LEAVES_2:1)
Block(-4,25,4,LEAVES_2:1)
Block(-4,25,5,LEAVES_2:1)
Block(-4,25,6,LEAVES_2:1)
Block(-4,25,7,LEAVES_2:1)
Block(-4,25,8,LEAVES_2:1)
Block(-4,25,9,LEAVES_2:1)
Block(-3,-10,1,LOG_2:1)
Block(-3,-9,0,LOG_2:1)
Block(-3,-9,1,LOG_2:1)
Block(-3,-9,2,LOG_2:1)
Block(-3,-8,0,LOG_2:1)
Block(-3,-8,1,LOG_2:1)
Block(-3,-8,2,LOG_2:1)
Block(-3,-7,0,LOG_2:1)
Block(-3,-7,1,LOG_2:1)
Block(-3,-7,2,LOG_2:1)
Block(-3,-6,0,LOG_2:1)
Block(-3,-6,1,LOG_2:1)
Block(-3,-6,2,LOG_2:1)
Block(-3,-5,0,LOG_2:1)
Block(-3,-5,1,LOG_2:1)
Block(-3,-4,1,LOG_2:1)
Block(-3,-3,1,LOG_2:1)
Block(-3,5,6,LOG_2:1)
Block(-3,6,5,LOG_2:1)
Block(-3,6,6,LOG_2:1)
Block(-3,6,7,LOG_2:1)
Block(-3,7,5,LOG_2:1)
Block(-3,7,6,LOG_2:1)
Block(-3,7,7,LOG_2:1)
Block(-3,7,8,LOG_2:1)
Block(-3,8,-4,LOG_2:1)
Block(-3,8,6,LOG_2:1)
Block(-3,8,7,LOG_2:1)
Block(-3,8,8,LOG_2:1)
Block(-3,9,-5,LOG_2:1)
Block(-3,9,-4,LOG_2:1)
Block(-3,9,6,LOG_2:1)
Block(-3,9,7,LOG_2:1)
Block(-3,9,8,LOG_2:1)
Block(-3,10,-12,LEAVES_2:1)
Block(-3,10,-6,LOG_2:1)
Block(-3,10,-5,LOG_2:1)
Block(-3,10,7,LOG_2:1)
Block(-3,11,-12,LEAVES_2:1)
Block(-3,11,-7,LOG_2:1)
Block(-3,11,-6,LOG_2:1)
Block(-3,11,-5,LOG_2:1)
Block(-3,12,-12,LEAVES_2:1)
Block(-3,12,-7,LOG_2:1)
Block(-3,12,-6,LOG_2:1)
Block(-3,12,-5,LOG_2:1)
Block(-3,12,0,LOG_2:1)
Block(-3,13,-13,LEAVES_2:1)
Block(-3,13,-12,LEAVES_2:1)
Block(-3,13,-11,LEAVES_2:1)
Block(-3,13,-7,LOG_2:1)
Block(-3,13,-6,LOG_2:1)
Block(-3,13,0,LOG_2:1)
Block(-3,14,-13,LEAVES_2:1)
Block(-3,14,-12,LEAVES_2:1)
Block(-3,14,-11,LEAVES_2:1)
Block(-3,14,-7,LOG_2:1)
Block(-3,14,0,LOG_2:1)
Block(-3,14,1,LOG_2:1)
Block(-3,15,-13,LEAVES_2:1)
Block(-3,15,-12,LEAVES_2:1)
Block(-3,15,-11,LEAVES_2:1)
Block(-3,15,-10,LEAVES_2:1)
Block(-3,15,-8,LOG_2:1)
Block(-3,15,-7,LOG_2:1)
Block(-3,15,0,LOG_2:1)
Block(-3,15,1,LOG_2:1)
Block(-3,15,2,LOG_2:1)
Block(-3,16,-12,LEAVES_2:1)
Block(-3,16,-11,LEAVES_2:1)
Block(-3,16,-10,LEAVES_2:1)
Block(-3,16,-9,LEAVES_2:1)
Block(-3,16,-8,LOG_2:1)
Block(-3,16,1,LOG_2:1)
Block(-3,16,2,LOG_2:1)
Block(-3,16,14,LEAVES_2:1)
Block(-3,17,-11,LEAVES_2:1)
Block(-3,17,-10,LEAVES_2:1)
Block(-3,17,-9,LEAVES_2:1)
Block(-3,17,-8,LOG_2:1)
Block(-3,17,1,LOG_2:1)
Block(-3,17,2,LOG_2:1)
Block(-3,17,3,LOG_2:1)
Block(-3,17,13,LEAVES_2:1)
Block(-3,17,14,LEAVES_2:1)
Block(-3,18,-10,LEAVES_2:1)
Block(-3,18,-9,LEAVES_2:1)
Block(-3,18,-8,LEAVES_2:1)
Block(-3,18,-5,LEAVES_2:1)
Block(-3,18,1,LOG_2:1)
Block(-3,18,2,LOG_2:1)
Block(-3,18,3,LOG_2:1)
Block(-3,18,10,LOG_2:1)
Block(-3,18,13,LEAVES_2:1)
Block(-3,18,14,LEAVES_2:1)
Block(-3,18,15,LEAVES_2:1)
Block(-3,19,-10,LEAVES_2:1)
Block(-3,19,-9,LEAVES_2:1)
Block(-3,19,-8,LEAVES_2:1)
Block(-3,19,-7,LEAVES_2:1)
Block(-3,19,-6,LEAVES_2:1)
Block(-3,19,-5,LEAVES_2:1)
Block(-3,19,-4,LEAVES_2:1)
Block(-3,19,-3,LEAVES_2:1)
Block(-3,19,-2,LEAVES_2:1)
Block(-3,19,2,LOG_2:1)
Block(-3,19,3,LOG_2:1)
Block(-3,19,10,LOG_2:1)
Block(-3,19,12,LEAVES_2:1)
Block(-3,19,13,LEAVES_2:1)
Block(-3,19,14,LEAVES_2:1)
Block(-3,19,15,LEAVES_2:1)
Block(-3,19,16,LEAVES_2:1)
Block(-3,20,-9,LEAVES_2:1)
Block(-3,20,-8,LEAVES_2:1)
Block(-3,20,-7,LEAVES_2:1)
Block(-3,20,-6,LEAVES_2:1)
Block(-3,20,-5,LEAVES_2:1)
Block(-3,20,-4,LEAVES_2:1)
Block(-3,20,-3,LEAVES_2:1)
Block(-3,20,-2,LEAVES_2:1)
Block(-3,20,-1,LEAVES_2:1)
Block(-3,20,0,LEAVES_2:1)
Block(-3,20,1,LEAVES_2:1)
Block(-3,20,2,LOG_2:1)
Block(-3,20,3,LEAVES_2:1)
Block(-3,20,10,LOG_2:1)
Block(-3,20,11,LOG_2:1)
Block(-3,20,12,LEAVES_2:1)
Block(-3,20,13,LEAVES_2:1)
Block(-3,20,14,LEAVES_2:1)
Block(-3,20,15,LEAVES_2:1)
Block(-3,21,-7,LEAVES_2:1)
Block(-3,21,-6,LEAVES_2:1)
Block(-3,21,-5,LEAVES_2:1)
Block(-3,21,-4,LEAVES_2:1)
Block(-3,21,-3,LEAVES_2:1)
Block(-3,21,-2,LEAVES_2:1)
Block(-3,21,-1,LEAVES_2:1)
Block(-3,21,0,LEAVES_2:1)
Block(-3,21,1,LEAVES_2:1)
Block(-3,21,2,LOG_2:1)
Block(-3,21,3,LEAVES_2:1)
Block(-3,21,4,LEAVES_2:1)
Block(-3,21,10,LOG_2:1)
Block(-3,21,11,LOG_2:1)
Block(-3,21,12,LEAVES_2:1)
Block(-3,21,13,LEAVES_2:1)
Block(-3,21,14,LEAVES_2:1)
Block(-3,22,-5,LEAVES_2:1)
Block(-3,22,-4,LEAVES_2:1)
Block(-3,22,-3,LEAVES_2:1)
Block(-3,22,-2,LEAVES_2:1)
Block(-3,22,-1,LEAVES_2:1)
Block(-3,22,0,LEAVES_2:1)
Block(-3,22,1,LEAVES_2:1)
Block(-3,22,2,LEAVES_2:1)
Block(-3,22,3,LEAVES_2:1)
Block(-3,22,4,LEAVES_2:1)
Block(-3,22,5,LEAVES_2:1)
Block(-3,22,10,LOG_2:1)
Block(-3,22,11,LEAVES_2:1)
Block(-3,22,12,LEAVES_2:1)
Block(-3,22,13,LEAVES_2:1)
Block(-3,23,-2,LEAVES_2:1)
Block(-3,23,-1,LEAVES_2:1)
Block(-3,23,0,LEAVES_2:1)
Block(-3,23,1,LEAVES_2:1)
Block(-3,23,2,LEAVES_2:1)
Block(-3,23,3,LEAVES_2:1)
Block(-3,23,4,LEAVES_2:1)
Block(-3,23,5,LEAVES_2:1)
Block(-3,23,6,LEAVES_2:1)
Block(-3,23,8,LEAVES_2:1)
Block(-3,23,9,LEAVES_2:1)
Block(-3,23,10,LEAVES_2:1)
Block(-3,23,11,LEAVES_2:1)
Block(-3,23,12,LEAVES_2:1)
Block(-3,23,13,LEAVES_2:1)
Block(-3,24,0,LEAVES_2:1)
Block(-3,24,1,LEAVES_2:1)
Block(-3,24,2,LEAVES_2:1)
Block(-3,24,3,LEAVES_2:1)
Block(-3,24,4,LEAVES_2:1)
Block(-3,24,5,LEAVES_2:1)
Block(-3,24,6,LEAVES_2:1)
Block(-3,24,7,LEAVES_2:1)
Block(-3,24,8,LEAVES_2:1)
Block(-3,24,9,LEAVES_2:1)
Block(-3,24,10,LEAVES_2:1)
Block(-3,24,11,LEAVES_2:1)
Block(-3,24,12,LEAVES_2:1)
Block(-3,25,3,LEAVES_2:1)
Block(-3,25,4,LEAVES_2:1)
Block(-3,25,5,LEAVES_2:1)
Block(-3,25,6,LEAVES_2:1)
Block(-3,25,7,LEAVES_2:1)
Block(-3,25,8,LEAVES_2:1)
Block(-3,25,9,LEAVES_2:1)
Block(-3,25,10,LEAVES_2:1)
Block(-3,25,11,LEAVES_2:1)
Block(-2,-9,1,LOG_2:1)
Block(-2,-8,1,LOG_2:1)
Block(-2,-7,0,LOG_2:1)
Block(-2,-7,1,LOG_2:1)
Block(-2,-6,-1,LOG_2:1)
Block(-2,-6,0,LOG_2:1)
Block(-2,-6,1,LOG_2:1)
Block(-2,-6,2,LOG_2:1)
Block(-2,-5,-1,LOG_2:1)
Block(-2,-5,0,LOG_2:1)
Block(-2,-5,1,LOG_2:1)
Block(-2,-5,2,LOG_2:1)
Block(-2,-4,0,LOG_2:1)
Block(-2,-4,1,LOG_2:1)
Block(-2,-4,2,LOG_2:1)
Block(-2,-3,0,LOG_2:1)
Block(-2,-3,1,LOG_2:1)
Block(-2,-2,1,LOG_2:1)
Block(-2,-1,1,LOG_2:1)
Block(-2,2,3,LOG_2:1)
Block(-2,3,3,LOG_2:1)
Block(-2,3,4,LOG_2:1)
Block(-2,4,3,LOG_2:1)
Block(-2,4,4,LOG_2:1)
Block(-2,4,5,LOG_2:1)
Block(-2,5,4,LOG_2:1)
Block(-2,5,5,LOG_2:1)
Block(-2,6,-3,LOG_2:1)
Block(-2,6,4,LOG_2:1)
Block(-2,6,5,LOG_2:1)
Block(-2,7,-4,LOG_2:1)
Block(-2,7,-3,LOG_2:1)
Block(-2,7,5,LOG_2:1)
Block(-2,7,6,LOG_2:1)
Block(-2,8,-5,LOG_2:1)
Block(-2,8,-4,LOG_2:1)
Block(-2,8,-3,LOG_2:1)
Block(-2,8,-2,LOG_2:1)
Block(-2,8,5,LOG_2:1)
Block(-2,8,6,LOG_2:1)
Block(-2,8,7,LOG_2:1)
Block(-2,8,8,LOG_2:1)
Block(-2,9,-5,LOG_2:1)
Block(-2,9,-4,LOG_2:1)
Block(-2,9,-3,LOG_2:1)
Block(-2,9,-2,LOG_2:1)
Block(-2,9,7,LOG_2:1)
Block(-2,9,8,LOG_2:1)
Block(-2,10,-6,LOG_2:1)
Block(-2,10,-5,LOG_2:1)
Block(-2,10,-4,LOG_2:1)
Block(-2,10,-3,LOG_2:1)
Block(-2,10,-2,LOG_2:1)
Block(-2,10,-1,LOG_2:1)
Block(-2,11,-6,LOG_2:1)
Block(-2,11,-5,LOG_2:1)
Block(-2,11,-2,LOG_2:1)
Block(-2,11,-1,LOG_2:1)
Block(-2,11,0,LOG_2:1)
Block(-2,12,-12,LEAVES_2:1)
Block(-2,12,-6,LOG_2:1)
Block(-2,12,-1,LOG_2:1)
Block(-2,12,0,LOG_2:1)
Block(-2,13,-12,LEAVES_2:1)
Block(-2,13,-1,LOG_2:1)
Block(-2,13,0,LOG_2:1)
Block(-2,13,1,LOG_2:1)
Block(-2,14,-12,LEAVES_2:1)
Block(-2,14,-11,LEAVES_2:1)
Block(-2,14,-1,LOG_2:1)
Block(-2,14,0,LOG_2:1)
Block(-2,14,1,LOG_2:1)
Block(-2,15,-12,LEAVES_2:1)
Block(-2,15,-11,LEAVES_2:1)
Block(-2,15,-10,LEAVES_2:1)
Block(-2,15,0,LOG_2:1)
Block(-2,15,1,LOG_2:1)
Block(-2,16,-11,LEAVES_2:1)
Block(-2,16,-10,LEAVES_2:1)
Block(-2,16,-9,LEAVES_2:1)
Block(-2,16,-8,LEAVES_2:1)
Block(-2,16,-7,LEAVES_2:1)
Block(-2,16,1,LOG_2:1)
Block(-2,16,2,LOG_2:1)
Block(-2,17,-10,LEAVES_2:1)
Block(-2,17,-9,LEAVES_2:1)
Block(-2,17,-8,LEAVES_2:1)
Block(-2,17,-7,LEAVES_2:1)
Block(-2,17,-5,LEAVES_2:1)
Block(-2,17,2,LOG_2:1)
Block(-2,17,14,LEAVES_2:1)
Block(-2,18,-9,LEAVES_2:1)
Block(-2,18,-8,LEAVES_2:1)
Block(-2,18,-7,LEAVES_2:1)
Block(-2,18,-6,LEAVES_2:1)
Block(-2,18,-5,LEAVES_2:1)
Block(-2,18,-4,LEAVES_2:1)
Block(-2,18,-3,LEAVES_2:1)
Block(-2,18,-2,LEAVES_2:1)
Block(-2,18,13,LEAVES_2:1)
Block(-2,18,14,LEAVES_2:1)
Block(-2,18,15,LEAVES_2:1)
Block(-2,19,-8,LEAVES_2:1)
Block(-2,19,-7,LEAVES_2:1)
Block(-2,19,-6,LEAVES_2:1)
Block(-2,19,-5,LEAVES_2:1)
Block(-2,19,-4,LEAVES_2:1)
Block(-2,19,-3,LEAVES_2:1)
Block(-2,19,-2,LEAVES_2:1)
Block(-2,19,-1,LEAVES_2:1)
Block(-2,19,12,LEAVES_2:1)
Block(-2,19,13,LEAVES_2:1)
Block(-2,19,14,LEAVES_2:1)
Block(-2,19,15,LEAVES_2:1)
Block(-2,20,-6,LEAVES_2:1)
Block(-2,20,-5,LEAVES_2:1)
Block(-2,20,-4,LEAVES_2:1)
Block(-2,20,-3,LEAVES_2:1)
Block(-2,20,-2,LEAVES_2:1)
Block(-2,20,-1,LEAVES_2:1)
Block(-2,20,0,LEAVES_2:1)
Block(-2,20,1,LEAVES_2:1)
Block(-2,20,2,LEAVES_2:1)
Block(-2,20,3,LEAVES_2:1)
Block(-2,20,11,LOG_2:1)
Block(-2,20,12,LEAVES_2:1)
Block(-2,20,13,LEAVES_2:1)
Block(-2,20,14,LEAVES_2:1)
Block(-2,20,15,LEAVES_2:1)
Block(-2,21,-5,LEAVES_2:1)
Block(-2,21,-4,LEAVES_2:1)
Block(-2,21,-3,LEAVES_2:1)
Block(-2,21,-2,LEAVES_2:1)
Block(-2,21,-1,LEAVES_2:1)
Block(-2,21,0,LEAVES_2:1)
Block(-2,21,1,LEAVES_2:1)
Block(-2,21,2,LEAVES_2:1)
Block(-2,21,3,LEAVES_2:1)
Block(-2,21,4,LEAVES_2:1)
Block(-2,21,5,LEAVES_2:1)
Block(-2,21,10,LOG_2:1)
Block(-2,21,11,LOG_2:1)
Block(-2,21,12,LEAVES_2:1)
Block(-2,21,13,LEAVES_2:1)
Block(-2,21,14,LEAVES_2:1)
Block(-2,22,-3,LEAVES_2:1)
Block(-2,22,-2,LEAVES_2:1)
Block(-2,22,-1,LEAVES_2:1)
Block(-2,22,0,LEAVES_2:1)
Block(-2,22,1,LEAVES_2:1)
Block(-2,22,2,LEAVES_2:1)
Block(-2,22,3,LEAVES_2:1)
Block(-2,22,4,LEAVES_2:1)
Block(-2,22,5,LEAVES_2:1)
Block(-2,22,6,LEAVES_2:1)
Block(-2,22,8,LEAVES_2:1)
Block(-2,22,10,LOG_2:1)
Block(-2,22,11,LOG_2:1)
Block(-2,22,12,LEAVES_2:1)
Block(-2,22,13,LEAVES_2:1)
Block(-2,22,14,LEAVES_2:1)
Block(-2,23,-1,LEAVES_2:1)
Block(-2,23,0,LEAVES_2:1)
Block(-2,23,1,LEAVES_2:1)
Block(-2,23,2,LEAVES_2:1)
Block(-2,23,3,LEAVES_2:1)
Block(-2,23,4,LEAVES_2:1)
Block(-2,23,5,LEAVES_2:1)
Block(-2,23,6,LEAVES_2:1)
Block(-2,23,7,LEAVES_2:1)
Block(-2,23,8,LEAVES_2:1)
Block(-2,23,9,LEAVES_2:1)
Block(-2,23,10,LOG_2:1)
Block(-2,23,11,LOG_2:1)
Block(-2,23,12,LEAVES_2:1)
Block(-2,23,13,LEAVES_2:1)
Block(-2,24,1,LEAVES_2:1)
Block(-2,24,2,LEAVES_2:1)
Block(-2,24,3,LEAVES_2:1)
Block(-2,24,4,LEAVES_2:1)
Block(-2,24,5,LEAVES_2:1)
Block(-2,24,6,LEAVES_2:1)
Block(-2,24,7,LEAVES_2:1)
Block(-2,24,8,LEAVES_2:1)
Block(-2,24,9,LEAVES_2:1)
Block(-2,24,10,LOG_2:1)
Block(-2,24,11,LEAVES_2:1)
Block(-2,24,12,LEAVES_2:1)
Block(-2,24,13,LEAVES_2:1)
Block(-2,25,3,LEAVES_2:1)
Block(-2,25,4,LEAVES_2:1)
Block(-2,25,5,LEAVES_2:1)
Block(-2,25,6,LEAVES_2:1)
Block(-2,25,7,LEAVES_2:1)
Block(-2,25,8,LEAVES_2:1)
Block(-2,25,9,LEAVES_2:1)
Block(-2,25,10,LEAVES_2:1)
Block(-2,25,11,LEAVES_2:1)
Block(-2,26,7,LEAVES_2:1)
Block(-2,26,8,LEAVES_2:1)
Block(-2,26,9,LEAVES_2:1)
Block(-1,-6,0,LOG_2:1)
Block(-1,-6,1,LOG_2:1)
Block(-1,-5,-1,LOG_2:1)
Block(-1,-5,0,LOG_2:1)
Block(-1,-5,1,LOG_2:1)
Block(-1,-4,-1,LOG_2:1)
Block(-1,-4,0,LOG_2:1)
Block(-1,-4,1,LOG_2:1)
Block(-1,-4,2,LOG_2:1)
Block(-1,-3,-1,LOG_2:1)
Block(-1,-3,0,LOG_2:1)
Block(-1,-3,1,LOG_2:1)
Block(-1,-3,2,LOG_2:1)
Block(-1,-2,-1,LOG_2:1)
Block(-1,-2,0,LOG_2:1)
Block(-1,-2,1,LOG_2:1)
Block(-1,-2,2,LOG_2:1)
Block(-1,-1,0,LOG_2:1)
Block(-1,-1,1,LOG_2:1)
Block(-1,-1,2,LOG_2:1)
Block(-1,-1,3,LOG_2:1)
Block(-1,0,1,LOG_2:1)
Block(-1,0,2,LOG_2:1)
Block(-1,0,3,LOG_2:1)
Block(-1,1,2,LOG_2:1)
Block(-1,1,3,LOG_2:1)
Block(-1,2,2,LOG_2:1)
Block(-1,2,3,LOG_2:1)
Block(-1,2,4,LOG_2:1)
Block(-1,3,3,LOG_2:1)
Block(-1,3,4,LOG_2:1)
Block(-1,3,5,LOG_2:1)
Block(-1,4,-3,LOG_2:1)
Block(-1,4,3,LOG_2:1)
Block(-1,4,4,LOG_2:1)
Block(-1,4,5,LOG_2:1)
Block(-1,5,-4,LOG_2:1)
Block(-1,5,-3,LOG_2:1)
Block(-1,5,3,LOG_2:1)
Block(-1,5,4,LOG_2:1)
Block(-1,5,5,LOG_2:1)
Block(-1,6,-4,LOG_2:1)
Block(-1,6,-3,LOG_2:1)
Block(-1,6,4,LOG_2:1)
Block(-1,6,5,LOG_2:1)
Block(-1,7,-4,LOG_2:1)
Block(-1,7,-3,LOG_2:1)
Block(-1,7,-2,LOG_2:1)
Block(-1,7,5,LOG_2:1)
Block(-1,8,-4,LOG_2:1)
Block(-1,8,-3,LOG_2:1)
Block(-1,8,-2,LOG_2:1)
Block(-1,8,6,LOG_2:1)
Block(-1,9,-4,LOG_2:1)
Block(-1,9,-3,LOG_2:1)
Block(-1,9,-2,LOG_2:1)
Block(-1,9,5,LOG_2:1)
Block(-1,9,6,LOG_2:1)
Block(-1,9,7,LOG_2:1)
Block(-1,10,-3,LOG_2:1)
Block(-1,10,-2,LOG_2:1)
Block(-1,10,6,LOG_2:1)
Block(-1,10,7,LOG_2:1)
Block(-1,11,-3,LOG_2:1)
Block(-1,11,-2,LOG_2:1)
Block(-1,12,-2,LOG_2:1)
Block(-1,12,-1,LOG_2:1)
Block(-1,13,-1,LOG_2:1)
Block(-1,13,0,LOG_2:1)
Block(-1,14,0,LOG_2:1)
Block(-1,15,-7,LEAVES_2:1)
Block(-1,15,-6,LEAVES_2:1)
Block(-1,16,-8,LEAVES_2:1)
Block(-1,16,-7,LEAVES_2:1)
Block(-1,16,-6,LEAVES_2:1)
Block(-1,16,-5,LEAVES_2:1)
Block(-1,17,-9,LEAVES_2:1)
Block(-1,17,-8,LEAVES_2:1)
Block(-1,17,-7,LEAVES_2:1)
Block(-1,17,-6,LEAVES_2:1)
Block(-1,17,-5,LEAVES_2:1)
Block(-1,17,-4,LEAVES_2:1)
Block(-1,17,14,LEAVES_2:1)
Block(-1,18,-8,LEAVES_2:1)
Block(-1,18,-7,LEAVES_2:1)
Block(-1,18,-6,LEAVES_2:1)
Block(-1,18,-5,LEAVES_2:1)
Block(-1,18,-4,LEAVES_2:1)
Block(-1,18,13,LEAVES_2:1)
Block(-1,18,14,LEAVES_2:1)
Block(-1,18,15,LEAVES_2:1)
Block(-1,19,-6,LEAVES_2:1)
Block(-1,19,-5,LEAVES_2:1)
Block(-1,19,-4,LEAVES_2:1)
Block(-1,19,-3,LEAVES_2:1)
Block(-1,19,-2,LEAVES_2:1)
Block(-1,19,-1,LEAVES_2:1)
Block(-1,19,12,LEAVES_2:1)
Block(-1,19,13,LEAVES_2:1)
Block(-1,19,14,LEAVES_2:1)
Block(-1,19,15,LEAVES_2:1)
Block(-1,20,-4,LEAVES_2:1)
Block(-1,20,-3,LEAVES_2:1)
Block(-1,20,-2,LEAVES_2:1)
Block(-1,20,-1,LEAVES_2:1)
Block(-1,20,0,LEAVES_2:1)
Block(-1,20,2,LEAVES_2:1)
Block(-1,20,12,LEAVES_2:1)
Block(-1,20,13,LEAVES_2:1)
Block(-1,20,14,LEAVES_2:1)
Block(-1,21,-3,LEAVES_2:1)
Block(-1,21,-2,LEAVES_2:1)
Block(-1,21,-1,LEAVES_2:1)
Block(-1,21,0,LEAVES_2:1)
Block(-1,21,1,LEAVES_2:1)
Block(-1,21,2,LEAVES_2:1)
Block(-1,21,3,LEAVES_2:1)
Block(-1,21,12,LEAVES_2:1)
Block(-1,21,13,LEAVES_2:1)
Block(-1,21,14,LEAVES_2:1)
Block(-1,22,-2,LEAVES_2:1)
Block(-1,22,-1,LEAVES_2:1)
Block(-1,22,0,LEAVES_2:1)
Block(-1,22,1,LEAVES_2:1)
Block(-1,22,2,LEAVES_2:1)
Block(-1,22,3,LEAVES_2:1)
Block(-1,22,4,LEAVES_2:1)
Block(-1,22,5,LEAVES_2:1)
Block(-1,22,6,LEAVES_2:1)
Block(-1,22,7,LEAVES_2:1)
Block(-1,22,8,LEAVES_2:1)
Block(-1,22,10,LOG_2:1)
Block(-1,22,11,LEAVES_2:1)
Block(-1,22,12,LEAVES_2:1)
Block(-1,22,13,LEAVES_2:1)
Block(-1,22,14,LEAVES_2:1)
Block(-1,23,0,LEAVES_2:1)
Block(-1,23,1,LEAVES_2:1)
Block(-1,23,2,LEAVES_2:1)
Block(-1,23,3,LEAVES_2:1)
Block(-1,23,4,LEAVES_2:1)
Block(-1,23,5,LEAVES_2:1)
Block(-1,23,6,LEAVES_2:1)
Block(-1,23,7,LEAVES_2:1)
Block(-1,23,8,LEAVES_2:1)
Block(-1,23,9,LOG_2:1)
Block(-1,23,10,LOG_2:1)
Block(-1,23,11,LOG_2:1)
Block(-1,23,12,LEAVES_2:1)
Block(-1,23,13,LEAVES_2:1)
Block(-1,24,2,LEAVES_2:1)
Block(-1,24,3,LEAVES_2:1)
Block(-1,24,4,LEAVES_2:1)
Block(-1,24,5,LEAVES_2:1)
Block(-1,24,6,LEAVES_2:1)
Block(-1,24,7,LEAVES_2:1)
Block(-1,24,8,LEAVES_2:1)
Block(-1,24,9,LOG_2:1)
Block(-1,24,10,LOG_2:1)
Block(-1,24,11,LOG_2:1)
Block(-1,24,12,LEAVES_2:1)
Block(-1,24,13,LEAVES_2:1)
Block(-1,25,3,LEAVES_2:1)
Block(-1,25,4,LEAVES_2:1)
Block(-1,25,5,LEAVES_2:1)
Block(-1,25,6,LEAVES_2:1)
Block(-1,25,7,LEAVES_2:1)
Block(-1,25,8,LEAVES_2:1)
Block(-1,25,9,LOG_2:1)
Block(-1,25,10,LOG_2:1)
Block(-1,25,11,LEAVES_2:1)
Block(-1,25,12,LEAVES_2:1)
Block(-1,26,6,LEAVES_2:1)
Block(-1,26,7,LEAVES_2:1)
Block(-1,26,8,LEAVES_2:1)
Block(-1,26,9,LEAVES_2:1)
Block(-1,26,10,LEAVES_2:1)
Block(0,-5,0,LOG_2:1)
Block(0,-4,0,LOG_2:1)
Block(0,-4,1,LOG_2:1)
Block(0,-3,0,LOG_2:1)
Block(0,-3,1,LOG_2:1)
Block(0,-3,2,LOG_2:1)
Block(0,-2,0,LOG_2:1)
Block(0,-2,1,LOG_2:1)
Block(0,-2,2,LOG_2:1)
Block(0,-1,-1,LOG_2:1)
Block(0,-1,0,LOG_2:1)
Block(0,-1,1,LOG_2:1)
Block(0,-1,2,LOG_2:1)
Block(0,0,-1,LOG_2:1)
Block(0,0,0,LOG_2:1)
Block(0,0,1,LOG_2:1)
Block(0,0,2,LOG_2:1)
Block(0,1,-2,LOG_2:1)
Block(0,1,-1,LOG_2:1)
Block(0,1,1,LOG_2:1)
Block(0,1,2,LOG_2:1)
Block(0,1,3,LOG_2:1)
Block(0,2,-3,LOG_2:1)
Block(0,2,-2,LOG_2:1)
Block(0,2,2,LOG_2:1)
Block(0,2,3,LOG_2:1)
Block(0,2,4,LOG_2:1)
Block(0,3,-3,LOG_2:1)
Block(0,3,-2,LOG_2:1)
Block(0,3,2,LOG_2:1)
Block(0,3,3,LOG_2:1)
Block(0,3,4,LOG_2:1)
Block(0,4,-4,LOG_2:1)
Block(0,4,-3,LOG_2:1)
Block(0,4,-2,LOG_2:1)
Block(0,4,3,LOG_2:1)
Block(0,4,4,LOG_2:1)
Block(0,5,-4,LOG_2:1)
Block(0,5,-3,LOG_2:1)
Block(0,5,-2,LOG_2:1)
Block(0,5,4,LOG_2:1)
Block(0,6,-4,LOG_2:1)
Block(0,6,-3,LOG_2:1)
Block(0,6,-2,LOG_2:1)
Block(0,7,-3,LOG_2:1)
Block(0,7,-2,LOG_2:1)
Block(0,8,-3,LOG_2:1)
Block(0,8,-2,LOG_2:1)
Block(0,9,-2,LOG_2:1)
Block(0,9,6,LOG_2:1)
Block(0,10,5,LOG_2:1)
Block(0,10,6,LOG_2:1)
Block(0,10,7,LOG_2:1)
Block(0,11,5,LOG_2:1)
Block(0,11,6,LOG_2:1)
Block(0,11,7,LOG_2:1)
Block(0,12,5,LOG_2:1)
Block(0,12,6,LOG_2:1)
Block(0,13,5,LOG_2:1)
Block(0,16,-7,LEAVES_2:1)
Block(0,16,-5,LEAVES_2:1)
Block(0,16,-4,LEAVES_2:1)
Block(0,17,-7,LEAVES_2:1)
Block(0,17,-6,LEAVES_2:1)
Block(0,17,-5,LEAVES_2:1)
Block(0,17,-4,LEAVES_2:1)
Block(0,17,-3,LEAVES_2:1)
Block(0,17,14,LEAVES_2:1)
Block(0,18,-6,LEAVES_2:1)
Block(0,18,-5,LEAVES_2:1)
Block(0,18,-4,LEAVES_2:1)
Block(0,18,13,LEAVES_2:1)
Block(0,18,14,LEAVES_2:1)
Block(0,18,15,LEAVES_2:1)
Block(0,19,-5,LEAVES_2:1)
Block(0,19,-3,LEAVES_2:1)
Block(0,19,12,LEAVES_2:1)
Block(0,19,13,LEAVES_2:1)
Block(0,19,14,LEAVES_2:1)
Block(0,20,-4,LEAVES_2:1)
Block(0,20,-3,LEAVES_2:1)
Block(0,20,-2,LEAVES_2:1)
Block(0,20,-1,LEAVES_2:1)
Block(0,20,0,LEAVES_2:1)
Block(0,20,2,LEAVES_2:1)
Block(0,20,12,LEAVES_2:1)
Block(0,20,13,LEAVES_2:1)
Block(0,20,14,LEAVES_2:1)
Block(0,21,-3,LEAVES_2:1)
Block(0,21,-2,LEAVES_2:1)
Block(0,21,-1,LEAVES_2:1)
Block(0,21,0,LEAVES_2:1)
Block(0,21,1,LEAVES_2:1)
Block(0,21,2,LEAVES_2:1)
Block(0,21,3,LEAVES_2:1)
Block(0,21,11,LEAVES_2:1)
Block(0,21,12,LEAVES_2:1)
Block(0,21,13,LEAVES_2:1)
Block(0,21,14,LEAVES_2:1)
Block(0,22,-1,LEAVES_2:1)
Block(0,22,0,LEAVES_2:1)
Block(0,22,1,LEAVES_2:1)
Block(0,22,2,LEAVES_2:1)
Block(0,22,3,LEAVES_2:1)
Block(0,22,4,LEAVES_2:1)
Block(0,22,5,LEAVES_2:1)
Block(0,22,10,LEAVES_2:1)
Block(0,22,11,LEAVES_2:1)
Block(0,22,12,LEAVES_2:1)
Block(0,22,13,LEAVES_2:1)
Block(0,23,0,LEAVES_2:1)
Block(0,23,1,LEAVES_2:1)
Block(0,23,2,LEAVES_2:1)
Block(0,23,3,LEAVES_2:1)
Block(0,23,4,LEAVES_2:1)
Block(0,23,5,LEAVES_2:1)
Block(0,23,6,LEAVES_2:1)
Block(0,23,8,LEAVES_2:1)
Block(0,23,9,LEAVES_2:1)
Block(0,23,10,LEAVES_2:1)
Block(0,23,11,LEAVES_2:1)
Block(0,23,12,LEAVES_2:1)
Block(0,23,13,LEAVES_2:1)
Block(0,24,2,LEAVES_2:1)
Block(0,24,3,LEAVES_2:1)
Block(0,24,4,LEAVES_2:1)
Block(0,24,5,LEAVES_2:1)
Block(0,24,7,LEAVES_2:1)
Block(0,24,8,LEAVES_2:1)
Block(0,24,9,LEAVES_2:1)
Block(0,24,10,LOG_2:1)
Block(0,24,11,LEAVES_2:1)
Block(0,24,12,LEAVES_2:1)
Block(0,25,4,LEAVES_2:1)
Block(0,25,5,LEAVES_2:1)
Block(0,25,6,LEAVES_2:1)
Block(0,25,7,LEAVES_2:1)
Block(0,25,8,LEAVES_2:1)
Block(0,25,9,LOG_2:1)
Block(0,25,10,LOG_2:1)
Block(0,25,11,LEAVES_2:1)
Block(0,25,12,LEAVES_2:1)
Block(0,26,6,LEAVES_2:1)
Block(0,26,7,LEAVES_2:1)
Block(0,26,8,LEAVES_2:1)
Block(0,26,9,LEAVES_2:1)
Block(0,26,10,LEAVES_2:1)
Block(1,-3,0,LOG_2:1)
Block(1,-2,0,LOG_2:1)
Block(1,-1,0,LOG_2:1)
Block(1,-1,1,LOG_2:1)
Block(1,0,-1,LOG_2:1)
Block(1,0,0,LOG_2:1)
Block(1,0,1,LOG_2:1)
Block(1,0,2,LOG_2:1)
Block(1,1,-1,LOG_2:1)
Block(1,1,0,LOG_2:1)
Block(1,1,1,LOG_2:1)
Block(1,1,2,LOG_2:1)
Block(1,2,-2,LOG_2:1)
Block(1,2,-1,LOG_2:1)
Block(1,2,0,LOG_2:1)
Block(1,2,1,LOG_2:1)
Block(1,2,2,LOG_2:1)
Block(1,2,3,LOG_2:1)
Block(1,3,-3,LOG_2:1)
Block(1,3,-2,LOG_2:1)
Block(1,3,-1,LOG_2:1)
Block(1,3,3,LOG_2:1)
Block(1,4,-3,LOG_2:1)
Block(1,4,-2,LOG_2:1)
Block(1,4,-1,LOG_2:1)
Block(1,5,-3,LOG_2:1)
Block(1,5,-2,LOG_2:1)
Block(1,5,-1,LOG_2:1)
Block(1,6,-2,LOG_2:1)
Block(1,7,-2,LOG_2:1)
Block(1,10,6,LOG_2:1)
Block(1,11,5,LOG_2:1)
Block(1,11,6,LOG_2:1)
Block(1,11,7,LOG_2:1)
Block(1,12,5,LOG_2:1)
Block(1,12,6,LOG_2:1)
Block(1,12,7,LOG_2:1)
Block(1,13,4,LOG_2:1)
Block(1,13,5,LOG_2:1)
Block(1,13,6,LOG_2:1)
Block(1,14,4,LOG_2:1)
Block(1,14,5,LOG_2:1)
Block(1,15,5,LOG_2:1)
Block(1,16,-4,LEAVES_2:1)
Block(1,17,-5,LEAVES_2:1)
Block(1,17,-4,LEAVES_2:1)
Block(1,17,-3,LEAVES_2:1)
Block(1,17,13,LEAVES_2:1)
Block(1,17,14,LEAVES_2:1)
Block(1,18,-5,LEAVES_2:1)
Block(1,18,-4,LEAVES_2:1)
Block(1,18,-3,LEAVES_2:1)
Block(1,18,12,LEAVES_2:1)
Block(1,18,13,LEAVES_2:1)
Block(1,18,14,LEAVES_2:1)
Block(1,19,-4,LEAVES_2:1)
Block(1,19,-3,LEAVES_2:1)
Block(1,19,12,LEAVES_2:1)
Block(1,19,13,LEAVES_2:1)
Block(1,19,14,LEAVES_2:1)
Block(1,20,-3,LEAVES_2:1)
Block(1,20,-1,LEAVES_2:1)
Block(1,20,0,LEAVES_2:1)
Block(1,20,1,LEAVES_2:1)
Block(1,20,2,LEAVES_2:1)
Block(1,20,12,LEAVES_2:1)
Block(1,20,13,LEAVES_2:1)
Block(1,21,-2,LEAVES_2:1)
Block(1,21,-1,LEAVES_2:1)
Block(1,21,0,LEAVES_2:1)
Block(1,21,1,LEAVES_2:1)
Block(1,21,2,LEAVES_2:1)
Block(1,21,3,LEAVES_2:1)
Block(1,21,10,LEAVES_2:1)
Block(1,21,11,LEAVES_2:1)
Block(1,21,12,LEAVES_2:1)
Block(1,21,13,LEAVES_2:1)
Block(1,22,-1,LEAVES_2:1)
Block(1,22,0,LEAVES_2:1)
Block(1,22,1,LEAVES_2:1)
Block(1,22,2,LEAVES_2:1)
Block(1,22,3,LEAVES_2:1)
Block(1,22,8,LEAVES_2:1)
Block(1,22,9,LEAVES_2:1)
Block(1,22,10,LEAVES_2:1)
Block(1,22,11,LEAVES_2:1)
Block(1,22,12,LEAVES_2:1)
Block(1,22,13,LEAVES_2:1)
Block(1,23,1,LEAVES_2:1)
Block(1,23,2,LEAVES_2:1)
Block(1,23,3,LEAVES_2:1)
Block(1,23,4,LEAVES_2:1)
Block(1,23,5,LEAVES_2:1)
Block(1,23,7,LEAVES_2:1)
Block(1,23,8,LEAVES_2:1)
Block(1,23,9,LEAVES_2:1)
Block(1,23,10,LEAVES_2:1)
Block(1,23,11,LEAVES_2:1)
Block(1,23,12,LEAVES_2:1)
Block(1,24,2,LEAVES_2:1)
Block(1,24,3,LEAVES_2:1)
Block(1,24,4,LEAVES_2:1)
Block(1,24,5,LEAVES_2:1)
Block(1,24,6,LEAVES_2:1)
Block(1,24,7,LEAVES_2:1)
Block(1,24,8,LEAVES_2:1)
Block(1,24,9,LEAVES_2:1)
Block(1,24,10,LEAVES_2:1)
Block(1,24,11,LEAVES_2:1)
Block(1,24,12,LEAVES_2:1)
Block(1,25,4,LEAVES_2:1)
Block(1,25,5,LEAVES_2:1)
Block(1,25,6,LEAVES_2:1)
Block(1,25,7,LEAVES_2:1)
Block(1,25,8,LEAVES_2:1)
Block(1,25,9,LEAVES_2:1)
Block(1,25,10,LEAVES_2:1)
Block(1,25,11,LEAVES_2:1)
Block(1,26,7,LEAVES_2:1)
Block(1,26,8,LEAVES_2:1)
Block(1,26,9,LEAVES_2:1)
Block(2,-1,0,LOG_2:1)
Block(2,0,0,LOG_2:1)
Block(2,1,0,LOG_2:1)
Block(2,1,1,LOG_2:1)
Block(2,2,-1,LOG_2:1)
Block(2,2,0,LOG_2:1)
Block(2,3,-2,LOG_2:1)
Block(2,3,-1,LOG_2:1)
Block(2,4,-2,LOG_2:1)
Block(2,11,6,LOG_2:1)
Block(2,12,5,LOG_2:1)
Block(2,12,6,LOG_2:1)
Block(2,13,4,LOG_2:1)
Block(2,13,5,LOG_2:1)
Block(2,13,6,LOG_2:1)
Block(2,14,4,LOG_2:1)
Block(2,14,5,LOG_2:1)
Block(2,14,6,LOG_2:1)
Block(2,15,4,LOG_2:1)
Block(2,15,5,LOG_2:1)
Block(2,15,6,LOG_2:1)
Block(2,16,4,LOG_2:1)
Block(2,16,5,LOG_2:1)
Block(2,16,13,LEAVES_2:1)
Block(2,16,14,LEAVES_2:1)
Block(2,17,-5,LEAVES_2:1)
Block(2,17,-4,LEAVES_2:1)
Block(2,17,-3,LEAVES_2:1)
Block(2,17,12,LEAVES_2:1)
Block(2,17,13,LEAVES_2:1)
Block(2,17,14,LEAVES_2:1)
Block(2,18,-5,LEAVES_2:1)
Block(2,18,-4,LEAVES_2:1)
Block(2,18,-3,LEAVES_2:1)
Block(2,18,-2,LEAVES_2:1)
Block(2,18,12,LEAVES_2:1)
Block(2,18,13,LEAVES_2:1)
Block(2,18,14,LEAVES_2:1)
Block(2,19,-4,LEAVES_2:1)
Block(2,19,-3,LEAVES_2:1)
Block(2,19,-2,LEAVES_2:1)
Block(2,19,11,LEAVES_2:1)
Block(2,19,12,LEAVES_2:1)
Block(2,19,13,LEAVES_2:1)
Block(2,20,-3,LEAVES_2:1)
Block(2,20,-2,LEAVES_2:1)
Block(2,20,-1,LEAVES_2:1)
Block(2,20,11,LEAVES_2:1)
Block(2,20,12,LEAVES_2:1)
Block(2,20,13,LEAVES_2:1)
Block(2,21,-2,LEAVES_2:1)
Block(2,21,-1,LEAVES_2:1)
Block(2,21,0,LEAVES_2:1)
Block(2,21,1,LEAVES_2:1)
Block(2,21,2,LEAVES_2:1)
Block(2,21,9,LEAVES_2:1)
Block(2,21,10,LEAVES_2:1)
Block(2,21,11,LEAVES_2:1)
Block(2,21,12,LEAVES_2:1)
Block(2,21,13,LEAVES_2:1)
Block(2,22,-1,LEAVES_2:1)
Block(2,22,0,LEAVES_2:1)
Block(2,22,1,LEAVES_2:1)
Block(2,22,2,LEAVES_2:1)
Block(2,22,3,LEAVES_2:1)
Block(2,22,4,LEAVES_2:1)
Block(2,22,8,LEAVES_2:1)
Block(2,22,9,LEAVES_2:1)
Block(2,22,10,LEAVES_2:1)
Block(2,22,11,LEAVES_2:1)
Block(2,22,12,LEAVES_2:1)
Block(2,23,1,LEAVES_2:1)
Block(2,23,2,LEAVES_2:1)
Block(2,23,3,LEAVES_2:1)
Block(2,23,4,LEAVES_2:1)
Block(2,23,5,LEAVES_2:1)
Block(2,23,6,LEAVES_2:1)
Block(2,23,7,LEAVES_2:1)
Block(2,23,8,LEAVES_2:1)
Block(2,23,9,LEAVES_2:1)
Block(2,23,10,LEAVES_2:1)
Block(2,23,11,LEAVES_2:1)
Block(2,24,2,LEAVES_2:1)
Block(2,24,3,LEAVES_2:1)
Block(2,24,4,LEAVES_2:1)
Block(2,24,5,LEAVES_2:1)
Block(2,24,6,LEAVES_2:1)
Block(2,24,7,LEAVES_2:1)
Block(2,24,8,LEAVES_2:1)
Block(2,24,9,LEAVES_2:1)
Block(2,24,10,LEAVES_2:1)
Block(2,25,4,LEAVES_2:1)
Block(2,25,5,LEAVES_2:1)
Block(2,25,6,LEAVES_2:1)
Block(2,25,7,LEAVES_2:1)
Block(2,25,8,LEAVES_2:1)
Block(2,25,9,LEAVES_2:1)
Block(3,12,13,LEAVES_2:1)
Block(3,13,5,LOG_2:1)
Block(3,13,13,LEAVES_2:1)
Block(3,14,4,LOG_2:1)
Block(3,14,5,LOG_2:1)
Block(3,14,13,LEAVES_2:1)
Block(3,14,14,LEAVES_2:1)
Block(3,15,3,LOG_2:1)
Block(3,15,4,LOG_2:1)
Block(3,15,5,LOG_2:1)
Block(3,15,13,LEAVES_2:1)
Block(3,15,14,LEAVES_2:1)
Block(3,16,-3,LEAVES_2:1)
Block(3,16,3,LOG_2:1)
Block(3,16,4,LOG_2:1)
Block(3,16,5,LOG_2:1)
Block(3,16,12,LEAVES_2:1)
Block(3,16,13,LEAVES_2:1)
Block(3,16,14,LEAVES_2:1)
Block(3,17,-4,LEAVES_2:1)
Block(3,17,-3,LEAVES_2:1)
Block(3,17,-2,LEAVES_2:1)
Block(3,17,3,LOG_2:1)
Block(3,17,4,LOG_2:1)
Block(3,17,12,LEAVES_2:1)
Block(3,17,13,LEAVES_2:1)
Block(3,18,-5,LEAVES_2:1)
Block(3,18,-4,LEAVES_2:1)
Block(3,18,-3,LEAVES_2:1)
Block(3,18,-2,LEAVES_2:1)
Block(3,18,3,LOG_2:1)
Block(3,18,11,LEAVES_2:1)
Block(3,18,12,LEAVES_2:1)
Block(3,18,13,LEAVES_2:1)
Block(3,19,-4,LEAVES_2:1)
Block(3,19,-3,LEAVES_2:1)
Block(3,19,-2,LEAVES_2:1)
Block(3,19,-1,LEAVES_2:1)
Block(3,19,9,LEAVES_2:1)
Block(3,19,10,LEAVES_2:1)
Block(3,19,11,LEAVES_2:1)
Block(3,19,12,LEAVES_2:1)
Block(3,19,13,LEAVES_2:1)
Block(3,20,-3,LEAVES_2:1)
Block(3,20,-2,LEAVES_2:1)
Block(3,20,-1,LEAVES_2:1)
Block(3,20,0,LEAVES_2:1)
Block(3,20,8,LEAVES_2:1)
Block(3,20,9,LEAVES_2:1)
Block(3,20,10,LEAVES_2:1)
Block(3,20,11,LEAVES_2:1)
Block(3,20,12,LEAVES_2:1)
Block(3,21,-2,LEAVES_2:1)
Block(3,21,-1,LEAVES_2:1)
Block(3,21,0,LEAVES_2:1)
Block(3,21,2,LEAVES_2:1)
Block(3,21,8,LEAVES_2:1)
Block(3,21,9,LEAVES_2:1)
Block(3,21,10,LEAVES_2:1)
Block(3,21,11,LEAVES_2:1)
Block(3,21,12,LEAVES_2:1)
Block(3,22,-1,LEAVES_2:1)
Block(3,22,0,LEAVES_2:1)
Block(3,22,1,LEAVES_2:1)
Block(3,22,2,LEAVES_2:1)
Block(3,22,3,LEAVES_2:1)
Block(3,22,4,LEAVES_2:1)
Block(3,22,7,LEAVES_2:1)
Block(3,22,8,LEAVES_2:1)
Block(3,22,9,LEAVES_2:1)
Block(3,22,10,LEAVES_2:1)
Block(3,23,1,LEAVES_2:1)
Block(3,23,2,LEAVES_2:1)
Block(3,23,3,LEAVES_2:1)
Block(3,23,4,LEAVES_2:1)
Block(3,23,5,LEAVES_2:1)
Block(3,23,6,LEAVES_2:1)
Block(3,23,7,LEAVES_2:1)
Block(3,23,8,LEAVES_2:1)
Block(3,23,9,LEAVES_2:1)
Block(3,24,2,LEAVES_2:1)
Block(3,24,3,LEAVES_2:1)
Block(3,24,4,LEAVES_2:1)
Block(3,24,5,LEAVES_2:1)
Block(3,24,6,LEAVES_2:1)
Block(3,24,7,LEAVES_2:1)
Block(3,24,8,LEAVES_2:1)
Block(3,25,4,LEAVES_2:1)
Block(3,25,5,LEAVES_2:1)
Block(3,25,6,LEAVES_2:1)
Block(3,25,7,LEAVES_2:1)
Block(4,14,13,LEAVES_2:1)
Block(4,15,4,LOG_2:1)
Block(4,15,13,LEAVES_2:1)
Block(4,15,14,LEAVES_2:1)
Block(4,16,-3,LEAVES_2:1)
Block(4,16,-2,LEAVES_2:1)
Block(4,16,3,LOG_2:1)
Block(4,16,4,LOG_2:1)
Block(4,16,5,LOG_2:1)
Block(4,16,13,LEAVES_2:1)
Block(4,17,-4,LEAVES_2:1)
Block(4,17,-3,LEAVES_2:1)
Block(4,17,-2,LEAVES_2:1)
Block(4,17,3,LOG_2:1)
Block(4,17,4,LOG_2:1)
Block(4,17,5,LOG_2:1)
Block(4,17,12,LEAVES_2:1)
Block(4,17,13,LEAVES_2:1)
Block(4,18,-4,LEAVES_2:1)
Block(4,18,-3,LEAVES_2:1)
Block(4,18,-2,LEAVES_2:1)
Block(4,18,-1,LEAVES_2:1)
Block(4,18,2,LOG_2:1)
Block(4,18,3,LOG_2:1)
Block(4,18,4,LOG_2:1)
Block(4,18,9,LEAVES_2:1)
Block(4,18,10,LEAVES_2:1)
Block(4,18,11,LEAVES_2:1)
Block(4,18,12,LEAVES_2:1)
Block(4,19,-3,LEAVES_2:1)
Block(4,19,-2,LEAVES_2:1)
Block(4,19,-1,LEAVES_2:1)
Block(4,19,2,LOG_2:1)
Block(4,19,3,LOG_2:1)
Block(4,19,8,LEAVES_2:1)
Block(4,19,9,LEAVES_2:1)
Block(4,19,10,LEAVES_2:1)
Block(4,19,11,LEAVES_2:1)
Block(4,19,12,LEAVES_2:1)
Block(4,20,-2,LEAVES_2:1)
Block(4,20,-1,LEAVES_2:1)
Block(4,20,0,LEAVES_2:1)
Block(4,20,2,LOG_2:1)
Block(4,20,7,LEAVES_2:1)
Block(4,20,8,LEAVES_2:1)
Block(4,20,9,LEAVES_2:1)
Block(4,20,10,LEAVES_2:1)
Block(4,20,11,LEAVES_2:1)
Block(4,21,-2,LEAVES_2:1)
Block(4,21,-1,LEAVES_2:1)
Block(4,21,0,LEAVES_2:1)
Block(4,21,1,LEAVES_2:1)
Block(4,21,8,LEAVES_2:1)
Block(4,21,9,LEAVES_2:1)
Block(4,21,10,LEAVES_2:1)
Block(4,22,0,LEAVES_2:1)
Block(4,22,1,LEAVES_2:1)
Block(4,22,2,LEAVES_2:1)
Block(4,22,4,LEAVES_2:1)
Block(4,22,5,LEAVES_2:1)
Block(4,22,6,LEAVES_2:1)
Block(4,22,7,LEAVES_2:1)
Block(4,22,8,LEAVES_2:1)
Block(4,23,1,LEAVES_2:1)
Block(4,23,2,LEAVES_2:1)
Block(4,23,3,LEAVES_2:1)
Block(4,23,4,LEAVES_2:1)
Block(4,23,5,LEAVES_2:1)
Block(4,23,6,LEAVES_2:1)
Block(4,23,7,LEAVES_2:1)
Block(4,23,8,LEAVES_2:1)
Block(4,24,3,LEAVES_2:1)
Block(4,24,4,LEAVES_2:1)
Block(4,24,5,LEAVES_2:1)
Block(4,24,6,LEAVES_2:1)
Block(4,24,7,LEAVES_2:1)
Block(4,25,5,LEAVES_2:1)
Block(5,15,-2,LEAVES_2:1)
Block(5,16,-3,LEAVES_2:1)
Block(5,16,-2,LEAVES_2:1)
Block(5,16,-1,LEAVES_2:1)
Block(5,16,4,LOG_2:1)
Block(5,17,-4,LEAVES_2:1)
Block(5,17,-3,LEAVES_2:1)
Block(5,17,-2,LEAVES_2:1)
Block(5,17,-1,LEAVES_2:1)
Block(5,17,3,LOG_2:1)
Block(5,17,4,LOG_2:1)
Block(5,18,-3,LEAVES_2:1)
Block(5,18,-2,LEAVES_2:1)
Block(5,18,-1,LEAVES_2:1)
Block(5,18,3,LOG_2:1)
Block(5,18,4,LOG_2:1)
Block(5,18,8,LEAVES_2:1)
Block(5,18,9,LEAVES_2:1)
Block(5,19,-2,LEAVES_2:1)
Block(5,19,-1,LEAVES_2:1)
Block(5,19,0,LEAVES_2:1)
Block(5,19,2,LOG_2:1)
Block(5,19,3,LOG_2:1)
Block(5,19,4,LOG_2:1)
Block(5,19,8,LEAVES_2:1)
Block(5,19,9,LEAVES_2:1)
Block(5,19,10,LEAVES_2:1)
Block(5,19,11,LEAVES_2:1)
Block(5,20,-2,LEAVES_2:1)
Block(5,20,-1,LEAVES_2:1)
Block(5,20,0,LEAVES_2:1)
Block(5,20,2,LOG_2:1)
Block(5,20,3,LOG_2:1)
Block(5,20,5,LEAVES_2:1)
Block(5,20,7,LEAVES_2:1)
Block(5,20,8,LEAVES_2:1)
Block(5,20,9,LEAVES_2:1)
Block(5,20,10,LEAVES_2:1)
Block(5,20,11,LEAVES_2:1)
Block(5,21,-1,LEAVES_2:1)
Block(5,21,0,LEAVES_2:1)
Block(5,21,1,LEAVES_2:1)
Block(5,21,2,LOG_2:1)
Block(5,21,3,LOG_2:1)
Block(5,21,5,LEAVES_2:1)
Block(5,21,6,LEAVES_2:1)
Block(5,21,7,LEAVES_2:1)
Block(5,21,8,LEAVES_2:1)
Block(5,21,9,LEAVES_2:1)
Block(5,21,10,LEAVES_2:1)
Block(5,22,0,LEAVES_2:1)
Block(5,22,1,LEAVES_2:1)
Block(5,22,2,LEAVES_2:1)
Block(5,22,5,LEAVES_2:1)
Block(5,22,6,LEAVES_2:1)
Block(5,22,7,LEAVES_2:1)
Block(5,22,8,LEAVES_2:1)
Block(5,22,9,LEAVES_2:1)
Block(5,23,1,LEAVES_2:1)
Block(5,23,2,LEAVES_2:1)
Block(5,23,3,LEAVES_2:1)
Block(5,23,4,LEAVES_2:1)
Block(5,23,5,LEAVES_2:1)
Block(5,23,6,LEAVES_2:1)
Block(5,23,7,LEAVES_2:1)
Block(5,23,8,LEAVES_2:1)
Block(5,24,3,LEAVES_2:1)
Block(5,24,4,LEAVES_2:1)
Block(5,24,5,LEAVES_2:1)
Block(5,24,6,LEAVES_2:1)
Block(5,24,7,LEAVES_2:1)
Block(6,14,-2,LEAVES_2:1)
Block(6,15,-3,LEAVES_2:1)
Block(6,15,-2,LEAVES_2:1)
Block(6,16,-3,LEAVES_2:1)
Block(6,16,-2,LEAVES_2:1)
Block(6,16,-1,LEAVES_2:1)
Block(6,16,0,LEAVES_2:1)
Block(6,17,-3,LEAVES_2:1)
Block(6,17,-2,LEAVES_2:1)
Block(6,17,-1,LEAVES_2:1)
Block(6,17,0,LEAVES_2:1)
Block(6,18,-2,LEAVES_2:1)
Block(6,18,-1,LEAVES_2:1)
Block(6,18,0,LEAVES_2:1)
Block(6,18,3,LOG_2:1)
Block(6,18,8,LEAVES_2:1)
Block(6,19,-2,LEAVES_2:1)
Block(6,19,-1,LEAVES_2:1)
Block(6,19,0,LEAVES_2:1)
Block(6,19,3,LOG_2:1)
Block(6,19,5,LEAVES_2:1)
Block(6,19,7,LEAVES_2:1)
Block(6,19,8,LEAVES_2:1)
Block(6,19,9,LEAVES_2:1)
Block(6,20,-1,LEAVES_2:1)
Block(6,20,0,LEAVES_2:1)
Block(6,20,1,LEAVES_2:1)
Block(6,20,2,LOG_2:1)
Block(6,20,3,LOG_2:1)
Block(6,20,4,LEAVES_2:1)
Block(6,20,5,LEAVES_2:1)
Block(6,20,6,LEAVES_2:1)
Block(6,20,7,LEAVES_2:1)
Block(6,20,8,LEAVES_2:1)
Block(6,20,9,LEAVES_2:1)
Block(6,20,10,LEAVES_2:1)
Block(6,21,0,LEAVES_2:1)
Block(6,21,1,LEAVES_2:1)
Block(6,21,2,LOG_2:1)
Block(6,21,3,LEAVES_2:1)
Block(6,21,4,LEAVES_2:1)
Block(6,21,5,LEAVES_2:1)
Block(6,21,6,LEAVES_2:1)
Block(6,21,7,LEAVES_2:1)
Block(6,21,8,LEAVES_2:1)
Block(6,22,0,LEAVES_2:1)
Block(6,22,1,LEAVES_2:1)
Block(6,22,2,LOG_2:1)
Block(6,22,3,LEAVES_2:1)
Block(6,22,4,LEAVES_2:1)
Block(6,22,5,LEAVES_2:1)
Block(6,22,6,LEAVES_2:1)
Block(6,22,7,LEAVES_2:1)
Block(6,23,1,LEAVES_2:1)
Block(6,23,2,LEAVES_2:1)
Block(6,23,3,LEAVES_2:1)
Block(6,23,4,LEAVES_2:1)
Block(6,23,5,LEAVES_2:1)
Block(6,23,6,LEAVES_2:1)
Block(6,23,7,LEAVES_2:1)
Block(6,24,5,LEAVES_2:1)
Block(6,24,6,LEAVES_2:1)
Block(7,12,-2,LEAVES_2:1)
Block(7,13,-2,LEAVES_2:1)
Block(7,13,-1,LEAVES_2:1)
Block(7,14,-3,LEAVES_2:1)
Block(7,14,-2,LEAVES_2:1)
Block(7,14,-1,LEAVES_2:1)
Block(7,15,-3,LEAVES_2:1)
Block(7,15,-2,LEAVES_2:1)
Block(7,15,-1,LEAVES_2:1)
Block(7,15,0,LEAVES_2:1)
Block(7,16,-2,LEAVES_2:1)
Block(7,16,-1,LEAVES_2:1)
Block(7,16,0,LEAVES_2:1)
Block(7,16,1,LEAVES_2:1)
Block(7,17,-2,LEAVES_2:1)
Block(7,17,-1,LEAVES_2:1)
Block(7,17,0,LEAVES_2:1)
Block(7,17,1,LEAVES_2:1)
Block(7,17,3,LEAVES_2:1)
Block(7,18,-1,LEAVES_2:1)
Block(7,18,0,LEAVES_2:1)
Block(7,18,1,LEAVES_2:1)
Block(7,18,2,LEAVES_2:1)
Block(7,18,3,LEAVES_2:1)
Block(7,18,7,LEAVES_2:1)
Block(7,19,-1,LEAVES_2:1)
Block(7,19,0,LEAVES_2:1)
Block(7,19,1,LEAVES_2:1)
Block(7,19,2,LEAVES_2:1)
Block(7,19,3,LEAVES_2:1)
Block(7,19,4,LEAVES_2:1)
Block(7,19,5,LEAVES_2:1)
Block(7,19,6,LEAVES_2:1)
Block(7,19,7,LEAVES_2:1)
Block(7,20,0,LEAVES_2:1)
Block(7,20,1,LEAVES_2:1)
Block(7,20,2,LEAVES_2:1)
Block(7,20,3,LEAVES_2:1)
Block(7,20,4,LEAVES_2:1)
Block(7,20,5,LEAVES_2:1)
Block(7,20,6,LEAVES_2:1)
Block(7,20,7,LEAVES_2:1)
Block(7,21,0,LEAVES_2:1)
Block(7,21,1,LEAVES_2:1)
Block(7,21,2,LEAVES_2:1)
Block(7,21,3,LEAVES_2:1)
Block(7,21,4,LEAVES_2:1)
Block(7,21,5,LEAVES_2:1)
Block(7,21,6,LEAVES_2:1)
Block(7,21,7,LEAVES_2:1)
Block(7,22,1,LEAVES_2:1)
Block(7,22,2,LEAVES_2:1)
Block(7,22,3,LEAVES_2:1)
Block(7,22,4,LEAVES_2:1)
Block(7,22,5,LEAVES_2:1)
Block(7,22,6,LEAVES_2:1)
Block(7,23,2,LEAVES_2:1)
Block(7,23,3,LEAVES_2:1)
Block(7,23,4,LEAVES_2:1)
Block(7,23,5,LEAVES_2:1)
Block(8,10,-2,LEAVES_2:1)
Block(8,11,-2,LEAVES_2:1)
Block(8,12,-3,LEAVES_2:1)
Block(8,12,-2,LEAVES_2:1)
Block(8,12,-1,LEAVES_2:1)
Block(8,13,-3,LEAVES_2:1)
Block(8,13,-2,LEAVES_2:1)
Block(8,13,-1,LEAVES_2:1)
Block(8,13,0,LEAVES_2:1)
Block(8,14,-2,LEAVES_2:1)
Block(8,14,-1,LEAVES_2:1)
Block(8,14,0,LEAVES_2:1)
Block(8,14,1,LEAVES_2:1)
Block(8,15,-2,LEAVES_2:1)
Block(8,15,-1,LEAVES_2:1)
Block(8,15,0,LEAVES_2:1)
Block(8,15,1,LEAVES_2:1)
Block(8,15,2,LEAVES_2:1)
Block(8,16,-1,LEAVES_2:1)
Block(8,16,0,LEAVES_2:1)
Block(8,16,1,LEAVES_2:1)
Block(8,16,3,LEAVES_2:1)
Block(8,17,-1,LEAVES_2:1)
Block(8,17,0,LEAVES_2:1)
Block(8,17,1,LEAVES_2:1)
Block(8,17,2,LEAVES_2:1)
Block(8,17,3,LEAVES_2:1)
Block(8,17,4,LEAVES_2:1)
Block(8,18,0,LEAVES_2:1)
Block(8,18,1,LEAVES_2:1)
Block(8,18,2,LEAVES_2:1)
Block(8,18,3,LEAVES_2:1)
Block(8,18,4,LEAVES_2:1)
Block(8,18,5,LEAVES_2:1)
Block(8,18,6,LEAVES_2:1)
Block(8,19,0,LEAVES_2:1)
Block(8,19,1,LEAVES_2:1)
Block(8,19,2,LEAVES_2:1)
Block(8,19,3,LEAVES_2:1)
Block(8,19,4,LEAVES_2:1)
Block(8,19,5,LEAVES_2:1)
Block(8,19,6,LEAVES_2:1)
Block(8,19,7,LEAVES_2:1)
Block(8,20,0,LEAVES_2:1)
Block(8,20,1,LEAVES_2:1)
Block(8,20,2,LEAVES_2:1)
Block(8,20,3,LEAVES_2:1)
Block(8,20,4,LEAVES_2:1)
Block(8,20,5,LEAVES_2:1)
Block(8,20,6,LEAVES_2:1)
Block(8,21,1,LEAVES_2:1)
Block(8,21,2,LEAVES_2:1)
Block(8,21,3,LEAVES_2:1)
Block(8,21,4,LEAVES_2:1)
Block(8,21,5,LEAVES_2:1)
Block(8,22,2,LEAVES_2:1)
Block(8,22,3,LEAVES_2:1)
Block(9,11,-2,LEAVES_2:1)
Block(9,12,-2,LEAVES_2:1)
Block(9,13,-2,LEAVES_2:1)
Block(9,13,-1,LEAVES_2:1)
Block(9,13,0,LEAVES_2:1)
Block(9,14,-1,LEAVES_2:1)
Block(9,14,0,LEAVES_2:1)
Block(9,14,1,LEAVES_2:1)
Block(9,15,0,LEAVES_2:1)
Block(9,15,1,LEAVES_2:1)
Block(9,15,2,LEAVES_2:1)
Block(9,16,0,LEAVES_2:1)
Block(9,16,1,LEAVES_2:1)
Block(9,16,2,LEAVES_2:1)
Block(9,17,0,LEAVES_2:1)
Block(9,17,1,LEAVES_2:1)
Block(9,17,2,LEAVES_2:1)
Block(9,17,3,LEAVES_2:1)
Block(9,18,0,LEAVES_2:1)
Block(9,18,1,LEAVES_2:1)
Block(9,18,2,LEAVES_2:1)
Block(9,18,3,LEAVES_2:1)
Block(9,18,4,LEAVES_2:1)
Block(9,19,1,LEAVES_2:1)
Block(9,19,2,LEAVES_2:1)
Block(9,19,3,LEAVES_2:1)
Block(9,19,4,LEAVES_2:1)
Block(9,19,5,LEAVES_2:1)
Block(9,20,2,LEAVES_2:1)
Block(9,20,3,LEAVES_2:1)
Block(9,21,2,LEAVES_2:1)
Block(10,16,1,LEAVES_2:1)
Block(10,16,2,LEAVES_2:1)
Block(10,17,1,LEAVES_2:1)
Block(10,17,2,LEAVES_2:1)
Block(10,18,1,LEAVES_2:1)

#######################################################################
# +-----------------------------------------------------------------+ #
# |                            BO3 checks                           | #
# +-----------------------------------------------------------------+ #
#######################################################################

BlockCheck(0,-1,0,GRASS,DIRT:0,DIRT:1,DIRT:2,biomesoplenty:grass:0,biomesoplenty:grass:1,biomesoplenty:grass:2,biomesoplenty:grass:3,biomesoplenty:grass:4,biomesoplenty:grass:5,biomesoplenty:grass:6,biomesoplenty:grass:7,biomesoplenty:dirt:0,biomesoplenty:dirt:1,biomesoplenty:dirt:2,biomesoplenty:dirt:3,biomesoplenty:dirt:4,biomesoplenty:dirt:5,biomesoplenty:dirt:6,biomesoplenty:dirt:7,biomesoplenty:dirt:8,biomesoplenty:dirt:9,biomesoplenty:dirt:10,biomesoplenty:dried_sand:0,biomesoplenty:hard_ice:0,biomesoplenty:white_sand:0,biomesoplenty:white_sandstone:0,biomesoplenty:mud:0,biomesoplenty:ash_block:0)

#######################################################################
# +-----------------------------------------------------------------+ #
# |                             Branches                            | #
# +-----------------------------------------------------------------+ #
#######################################################################


#######################################################################
# +-----------------------------------------------------------------+ #
# |                             Entities                            | #
# +-----------------------------------------------------------------+ #
#######################################################################


#######################################################################
# +-----------------------------------------------------------------+ #
# |                            Particles                            | #
# +-----------------------------------------------------------------+ #
#######################################################################


#######################################################################
# +-----------------------------------------------------------------+ #
# |                             Spawners                            | #
# +-----------------------------------------------------------------+ #
#######################################################################


#######################################################################
# +-----------------------------------------------------------------+ #
# |                             ModData                             | #
# +-----------------------------------------------------------------+ #
#######################################################################

