
#######################################################################
# +-----------------------------------------------------------------+ #
# |                            BO3 object                           | #
# +-----------------------------------------------------------------+ #
#######################################################################

Author: Unknown

Description: Converted version of the BO2 GrandFir5

Version: 3

SettingsMode: WriteWithoutComments


#######################################################################
# +-----------------------------------------------------------------+ #
# |                          Main settings                          | #
# +-----------------------------------------------------------------+ #
#######################################################################

Tree: true

Frequency: 1

Rarity: 5.0

RotateRandomly: true

SpawnHeight: highestSolidBlock

SpawnHeightOffset: 0

SpawnHeightVariance: 0

##############################
# Height Limits for the BO3. #
##############################

MinHeight: 63

MaxHeight: 210

######################
# Extrusion settings #
######################

ExtrudeMode: None

ExtrudeThroughBlocks: AIR

MaxBranchDepth: 10

ExcludedBiomes: All


#######################################################################
# +-----------------------------------------------------------------+ #
# |                      Source block settings                      | #
# +-----------------------------------------------------------------+ #
#######################################################################

SourceBlocks: AIR

MaxPercentageOutsideSourceBlock: 0

OutsideSourceBlock: placeAnyway

DoReplaceBlocks: true

IsOTGPlus: false


#######################################################################
# +-----------------------------------------------------------------+ #
# |                              Blocks                             | #
# +-----------------------------------------------------------------+ #
#######################################################################

Block(3,5,-3,LEAVES:1)
Block(3,6,-3,LEAVES:1)
Block(5,15,2,LEAVES:1)
Block(3,7,-3,LEAVES:1)
Block(4,12,-3,LEAVES:1)
Block(4,11,-3,LEAVES:1)
Block(4,10,-3,LEAVES:1)
Block(3,12,-4,LEAVES:1)
Block(3,11,-4,LEAVES:1)
Block(3,10,-4,LEAVES:1)
Block(1,8,-4,LEAVES:1)
Block(1,6,-4,LEAVES:1)
Block(1,7,-4,LEAVES:1)
Block(1,5,-4,LEAVES:1)
Block(2,7,2,LEAVES:1)
Block(3,18,-4,LEAVES:1)
Block(4,18,-3,LEAVES:1)
Block(3,8,0,LEAVES:1)
Block(-1,4,-3,LEAVES:1)
Block(3,7,0,LEAVES:1)
Block(0,-3,-3,LOG:1)
Block(3,6,0,LEAVES:1)
Block(3,5,0,LEAVES:1)
Block(3,9,0,LEAVES:1)
Block(2,-3,-1,LOG:1)
Block(-1,9,-3,LEAVES:1)
Block(-1,8,-3,LEAVES:1)
Block(2,-2,-1,LOG:1)
Block(2,-1,-1,LOG:1)
Block(5,5,-3,LEAVES:1)
Block(5,6,-3,LEAVES:1)
Block(5,3,-3,LEAVES:1)
Block(5,4,-3,LEAVES:1)
Block(1,13,1,LEAVES:1)
Block(1,14,1,LEAVES:1)
Block(3,6,-2,LEAVES:1)
Block(0,-2,-2,LOG:1)
Block(3,7,-2,LEAVES:1)
Block(3,8,-2,LEAVES:1)
Block(1,19,-1,LEAVES:1)
Block(1,18,-1,LEAVES:1)
Block(1,17,-1,LEAVES:1)
Block(1,16,-1,LEAVES:1)
Block(1,15,-1,LEAVES:1)
Block(1,14,-1,LEAVES:1)
Block(3,3,-2,LEAVES:1)
Block(0,3,-1,LEAVES:1)
Block(3,4,-2,LEAVES:1)
Block(0,2,-1,LEAVES:1)
Block(3,5,-2,LEAVES:1)
Block(1,7,-3,LEAVES:1)
Block(1,8,-3,LEAVES:1)
Block(1,5,-3,LEAVES:1)
Block(1,6,-3,LEAVES:1)
Block(1,3,-3,LEAVES:1)
Block(1,4,-3,LEAVES:1)
Block(1,13,-1,LEAVES:1)
Block(1,2,-3,LEAVES:1)
Block(1,12,-1,LEAVES:1)
Block(1,11,-1,LEAVES:1)
Block(3,7,1,LEAVES:1)
Block(0,16,-1,LEAVES:1)
Block(0,15,-1,LEAVES:1)
Block(-1,3,-2,LEAVES:1)
Block(0,17,-1,LEAVES:1)
Block(-1,2,-2,LEAVES:1)
Block(5,16,1,LEAVES:1)
Block(4,11,-2,LEAVES:1)
Block(5,15,1,LEAVES:1)
Block(3,8,1,LEAVES:1)
Block(1,-1,-2,LOG:1)
Block(5,17,1,LEAVES:1)
Block(-1,9,-2,LEAVES:1)
Block(5,4,-4,LEAVES:1)
Block(3,-1,-1,LOG:1)
Block(-3,9,-1,LEAVES:1)
Block(0,10,-1,LEAVES:1)
Block(0,12,-1,LEAVES:1)
Block(0,11,-1,LEAVES:1)
Block(0,13,-1,LEAVES:1)
Block(-2,11,0,LEAVES:1)
Block(-2,10,0,LOG:1)
Block(1,8,-2,LEAVES:1)
Block(1,6,-2,LEAVES:1)
Block(2,20,-3,LEAVES:1)
Block(1,7,-2,LEAVES:1)
Block(1,4,-2,LEAVES:1)
Block(1,5,-2,LEAVES:1)
Block(1,3,-2,LEAVES:1)
Block(1,0,-2,LOG:1)
Block(-4,9,-1,LEAVES:1)
Block(4,17,0,LEAVES:1)
Block(4,11,-4,LEAVES:1)
Block(4,15,0,LEAVES:1)
Block(4,16,0,LEAVES:1)
Block(3,11,-3,LEAVES:1)
Block(4,13,0,LEAVES:1)
Block(-2,9,0,LEAVES:1)
Block(3,10,-3,LEAVES:1)
Block(4,14,0,LEAVES:1)
Block(3,12,-3,LEAVES:1)
Block(2,-3,-5,LOG:1)
Block(4,5,0,LEAVES:1)
Block(-1,15,0,LEAVES:1)
Block(4,4,0,LEAVES:1)
Block(-1,16,0,LEAVES:1)
Block(3,18,-3,LEAVES:1)
Block(4,7,0,LEAVES:1)
Block(4,6,0,LEAVES:1)
Block(2,4,-1,LEAVES:1)
Block(2,9,-1,LEAVES:1)
Block(2,8,-1,LEAVES:1)
Block(2,7,-1,LEAVES:1)
Block(2,6,-1,LEAVES:1)
Block(-1,10,0,LEAVES:1)
Block(-1,11,0,LEAVES:1)
Block(-1,12,0,LEAVES:1)
Block(3,7,-4,LEAVES:1)
Block(4,18,1,LEAVES:1)
Block(1,-2,-1,LOG:1)
Block(4,16,1,LOG:1)
Block(4,17,1,LEAVES:1)
Block(4,15,1,LEAVES:1)
Block(3,15,1,LEAVES:1)
Block(2,12,-4,LEAVES:1)
Block(3,16,1,LEAVES:1)
Block(4,6,-4,LEAVES:1)
Block(1,7,-1,LEAVES:1)
Block(2,11,-4,LEAVES:1)
Block(4,5,-4,LEAVES:1)
Block(1,3,-1,LEAVES:1)
Block(1,4,-1,LEAVES:1)
Block(3,13,1,LEAVES:1)
Block(3,14,1,LEAVES:1)
Block(0,-3,-1,LOG:1)
Block(2,0,-2,LOG:1)
Block(2,4,-2,LOG:1)
Block(2,3,-2,LOG:1)
Block(2,2,-2,LOG:1)
Block(2,1,-2,LOG:1)
Block(2,8,-2,LOG:1)
Block(2,7,-2,LOG:1)
Block(2,6,-2,LOG:1)
Block(2,5,-2,LOG:1)
Block(2,9,-2,LOG:1)
Block(0,4,-4,LEAVES:1)
Block(6,6,-2,LEAVES:1)
Block(2,20,1,LEAVES:1)
Block(0,7,-4,LEAVES:1)
Block(3,20,-1,LEAVES:1)
Block(2,18,-2,LEAVES:1)
Block(2,19,-2,LEAVES:1)
Block(3,22,-1,LEAVES:1)
Block(2,16,-2,LEAVES:1)
Block(2,17,-2,LEAVES:1)
Block(2,14,-2,LEAVES:1)
Block(2,12,-2,LEAVES:1)
Block(2,13,-2,LEAVES:1)
Block(1,10,-3,LEAVES:1)
Block(2,10,-2,LOG:1)
Block(2,11,-2,LOG:1)
Block(4,7,-3,LEAVES:1)
Block(1,12,-3,LEAVES:1)
Block(4,6,-3,LEAVES:1)
Block(1,13,-3,LEAVES:1)
Block(1,14,-3,LEAVES:1)
Block(4,5,-3,LEAVES:1)
Block(4,4,-3,LEAVES:1)
Block(2,23,-2,LEAVES:1)
Block(-1,10,-2,LEAVES:1)
Block(2,21,-2,LEAVES:1)
Block(-1,11,-2,LEAVES:1)
Block(3,-1,-3,LOG:1)
Block(2,20,-2,LEAVES:1)
Block(3,-3,-3,LOG:1)
Block(1,-2,-4,LOG:1)
Block(2,1,-3,LOG:1)
Block(3,-2,-3,LOG:1)
Block(2,0,-3,LOG:1)
Block(2,7,-3,LEAVES:1)
Block(2,6,-3,LEAVES:1)
Block(2,5,-3,LEAVES:1)
Block(2,4,-3,LEAVES:1)
Block(5,5,0,LEAVES:1)
Block(2,8,-3,LEAVES:1)
Block(6,5,-1,LEAVES:1)
Block(3,10,-2,LEAVES:1)
Block(3,11,-2,LEAVES:1)
Block(3,12,-2,LEAVES:1)
Block(2,-1,-4,LOG:1)
Block(3,17,-2,LEAVES:1)
Block(3,18,-2,LEAVES:1)
Block(-1,10,-1,LEAVES:1)
Block(-2,11,-1,LEAVES:1)
Block(-2,16,-1,LEAVES:1)
Block(4,7,-2,LEAVES:1)
Block(-2,15,-1,LEAVES:1)
Block(4,4,-2,LEAVES:1)
Block(4,3,-2,LEAVES:1)
Block(4,6,-2,LEAVES:1)
Block(4,5,-2,LEAVES:1)
Block(-3,10,0,LEAVES:1)
Block(-2,9,1,LEAVES:1)
Block(-1,15,-1,LEAVES:1)
Block(4,16,2,LEAVES:1)
Block(2,19,1,LEAVES:1)
Block(3,20,-2,LEAVES:1)
Block(4,15,2,LEAVES:1)
Block(-1,16,-1,LEAVES:1)
Block(-2,10,1,LEAVES:1)
Block(-1,11,-1,LOG:1)
Block(2,15,1,LEAVES:1)
Block(-1,12,-1,LEAVES:1)
Block(2,14,1,LEAVES:1)
Block(2,18,-3,LEAVES:1)
Block(2,13,-3,LEAVES:1)
Block(3,15,0,LEAVES:1)
Block(3,14,0,LEAVES:1)
Block(2,11,-3,LEAVES:1)
Block(3,17,0,LOG:1)
Block(2,12,-3,LEAVES:1)
Block(3,16,0,LEAVES:1)
Block(3,19,0,LEAVES:1)
Block(2,10,-3,LEAVES:1)
Block(3,18,0,LEAVES:1)
Block(2,0,-4,LOG:1)
Block(3,13,0,LEAVES:1)
Block(2,7,-4,LEAVES:1)
Block(0,4,-2,LEAVES:1)
Block(3,7,-1,LEAVES:1)
Block(0,3,-2,LEAVES:1)
Block(3,8,-1,LEAVES:1)
Block(2,12,0,LEAVES:1)
Block(0,7,-2,LEAVES:1)
Block(0,9,-2,LEAVES:1)
Block(2,17,0,LEAVES:1)
Block(3,0,-1,LOG:1)
Block(2,18,0,LEAVES:1)
Block(4,15,3,LEAVES:1)
Block(4,14,3,LEAVES:1)
Block(3,3,-1,LEAVES:1)
Block(-2,10,-2,LEAVES:1)
Block(2,13,0,LEAVES:1)
Block(3,4,-1,LEAVES:1)
Block(2,14,0,LEAVES:1)
Block(3,5,-1,LEAVES:1)
Block(2,15,0,LEAVES:1)
Block(2,-1,-2,LOG:1)
Block(3,6,-1,LEAVES:1)
Block(2,16,0,LEAVES:1)
Block(-1,10,-3,LEAVES:1)
Block(2,7,0,LEAVES:1)
Block(2,8,0,LEAVES:1)
Block(4,5,-1,LEAVES:1)
Block(4,4,-1,LEAVES:1)
Block(4,7,-1,LEAVES:1)
Block(4,6,-1,LEAVES:1)
Block(6,14,1,LEAVES:1)
Block(6,15,1,LEAVES:1)
Block(6,16,1,LEAVES:1)
Block(2,20,0,LEAVES:1)
Block(2,22,0,LEAVES:1)
Block(1,16,0,LEAVES:1)
Block(2,18,-1,LOG:1)
Block(2,17,-1,LOG:1)
Block(2,19,-1,LOG:1)
Block(2,14,-1,LOG:1)
Block(2,13,-1,LEAVES:1)
Block(-1,9,-1,LEAVES:1)
Block(2,16,-1,LOG:1)
Block(2,15,-1,LOG:1)
Block(5,4,-1,LEAVES:1)
Block(2,11,-1,LEAVES:1)
Block(5,5,-1,LOG:1)
Block(5,6,-1,LEAVES:1)
Block(0,11,-3,LEAVES:1)
Block(-3,10,-1,LEAVES:1)
Block(1,22,-1,LEAVES:1)
Block(0,10,-3,LEAVES:1)
Block(1,21,-1,LEAVES:1)
Block(2,8,-5,LEAVES:1)
Block(0,16,-3,LEAVES:1)
Block(2,7,-5,LEAVES:1)
Block(2,6,-5,LEAVES:1)
Block(0,3,-3,LEAVES:1)
Block(0,17,-2,LEAVES:1)
Block(0,16,-2,LEAVES:1)
Block(6,4,-3,LEAVES:1)
Block(0,5,-3,LEAVES:1)
Block(0,4,-3,LEAVES:1)
Block(0,7,-3,LEAVES:1)
Block(0,6,-3,LEAVES:1)
Block(0,9,-3,LEAVES:1)
Block(0,8,-3,LEAVES:1)
Block(-1,16,-2,LEAVES:1)
Block(1,20,0,LEAVES:1)
Block(2,24,-1,LEAVES:1)
Block(-1,15,-2,LEAVES:1)
Block(1,7,-5,LEAVES:1)
Block(2,21,-1,LOG:1)
Block(2,20,-1,LOG:1)
Block(4,19,-1,LEAVES:1)
Block(2,23,-1,LEAVES:1)
Block(1,6,-5,LEAVES:1)
Block(2,22,-1,LEAVES:1)
Block(-3,9,1,LEAVES:1)
Block(2,7,1,LEAVES:1)
Block(4,13,-1,LEAVES:1)
Block(-3,8,1,LEAVES:1)
Block(0,11,-2,LEAVES:1)
Block(0,10,-2,LEAVES:1)
Block(0,13,-2,LEAVES:1)
Block(0,12,-2,LEAVES:1)
Block(0,15,-2,LEAVES:1)
Block(0,14,-2,LEAVES:1)
Block(4,16,-1,LEAVES:1)
Block(1,15,-2,LEAVES:1)
Block(1,16,-2,LEAVES:1)
Block(1,17,-2,LEAVES:1)
Block(2,-3,-3,LOG:1)
Block(2,-1,-3,LOG:1)
Block(2,-2,-3,LOG:1)
Block(3,-3,0,LOG:1)
Block(3,-2,0,LOG:1)
Block(1,10,-2,LEAVES:1)
Block(3,19,-1,LOG:1)
Block(5,6,-2,LEAVES:1)
Block(1,11,-2,LOG:1)
Block(3,12,-1,LEAVES:1)
Block(5,7,-2,LEAVES:1)
Block(1,12,-2,LOG:1)
Block(3,13,-1,LEAVES:1)
Block(5,4,-2,LEAVES:1)
Block(1,13,-2,LEAVES:1)
Block(3,14,-1,LEAVES:1)
Block(5,5,-2,LEAVES:1)
Block(1,14,-2,LEAVES:1)
Block(3,15,-1,LEAVES:1)
Block(2,7,-6,LEAVES:1)
Block(4,-3,-2,LOG:1)

#######################################################################
# +-----------------------------------------------------------------+ #
# |                            BO3 checks                           | #
# +-----------------------------------------------------------------+ #
#######################################################################

BlockCheck(0,-1,0,GRASS,DIRT:0,DIRT:1,DIRT:2,biomesoplenty:grass:0,biomesoplenty:grass:1,biomesoplenty:grass,biomesoplenty:grass:3,biomesoplenty:grass:4,biomesoplenty:grass:5,biomesoplenty:grass:6,biomesoplenty:grass:7,UNKNOWN_BLOCK:0,UNKNOWN_BLOCK:1,UNKNOWN_BLOCK:2,UNKNOWN_BLOCK:8,UNKNOWN_BLOCK:9,UNKNOWN_BLOCK:10,biomesoplenty:dried_sand,biomesoplenty:hard_ice,biomesoplenty:white_sand,biomesoplenty:white_sandstone,biomesoplenty:mud,biomesoplenty:ash_block)

#######################################################################
# +-----------------------------------------------------------------+ #
# |                             Branches                            | #
# +-----------------------------------------------------------------+ #
#######################################################################


#######################################################################
# +-----------------------------------------------------------------+ #
# |                             Entities                            | #
# +-----------------------------------------------------------------+ #
#######################################################################


#######################################################################
# +-----------------------------------------------------------------+ #
# |                            Particles                            | #
# +-----------------------------------------------------------------+ #
#######################################################################


#######################################################################
# +-----------------------------------------------------------------+ #
# |                             Spawners                            | #
# +-----------------------------------------------------------------+ #
#######################################################################


#######################################################################
# +-----------------------------------------------------------------+ #
# |                             ModData                             | #
# +-----------------------------------------------------------------+ #
#######################################################################

