
#######################################################################
# +-----------------------------------------------------------------+ #
# |                            BO3 object                           | #
# +-----------------------------------------------------------------+ #
#######################################################################

Author: Unknown

Description: Converted version of the BO2 GrandFir6

Version: 3

SettingsMode: WriteWithoutComments


#######################################################################
# +-----------------------------------------------------------------+ #
# |                          Main settings                          | #
# +-----------------------------------------------------------------+ #
#######################################################################

Tree: true

Frequency: 1

Rarity: 5.0

RotateRandomly: true

SpawnHeight: highestSolidBlock

SpawnHeightOffset: 0

SpawnHeightVariance: 0

##############################
# Height Limits for the BO3. #
##############################

MinHeight: 63

MaxHeight: 210

######################
# Extrusion settings #
######################

ExtrudeMode: None

ExtrudeThroughBlocks: AIR

MaxBranchDepth: 10

ExcludedBiomes: All


#######################################################################
# +-----------------------------------------------------------------+ #
# |                      Source block settings                      | #
# +-----------------------------------------------------------------+ #
#######################################################################

SourceBlocks: AIR

MaxPercentageOutsideSourceBlock: 0

OutsideSourceBlock: placeAnyway

IsOTGPlus: false


#######################################################################
# +-----------------------------------------------------------------+ #
# |                              Blocks                             | #
# +-----------------------------------------------------------------+ #
#######################################################################

Block(-4,8,2,LEAVES:1)
Block(-2,-3,0,LOG:1)
Block(-2,-2,0,LOG:1)
Block(-2,-1,0,LOG:1)
Block(1,8,-4,LEAVES:1)
Block(1,6,-4,LEAVES:1)
Block(-2,13,-3,LEAVES:1)
Block(1,7,-4,LEAVES:1)
Block(-2,12,-3,LEAVES:1)
Block(-4,19,-1,LEAVES:1)
Block(-2,18,-3,LEAVES:1)
Block(-4,18,-1,LEAVES:1)
Block(-2,17,-3,LEAVES:1)
Block(-4,17,-1,LEAVES:1)
Block(-2,16,-3,LEAVES:1)
Block(-4,10,-1,LEAVES:1)
Block(-3,14,2,LEAVES:1)
Block(-3,18,2,LEAVES:1)
Block(-3,17,2,LEAVES:1)
Block(-3,19,2,LEAVES:1)
Block(-2,11,-3,LEAVES:1)
Block(-3,5,-2,LEAVES:1)
Block(-3,6,-2,LEAVES:1)
Block(1,12,1,LEAVES:1)
Block(1,13,1,LEAVES:1)
Block(-6,23,0,LEAVES:1)
Block(-4,9,1,LEAVES:1)
Block(1,19,-1,LEAVES:1)
Block(-3,23,2,LEAVES:1)
Block(-4,8,1,LEAVES:1)
Block(1,18,-1,LOG:1)
Block(1,17,-1,LEAVES:1)
Block(-4,7,1,LEAVES:1)
Block(1,9,-3,LEAVES:1)
Block(1,7,-3,LEAVES:1)
Block(1,8,-3,LOG:1)
Block(-3,7,3,LEAVES:1)
Block(1,13,-1,LEAVES:1)
Block(1,12,-1,LEAVES:1)
Block(-3,6,3,LEAVES:1)
Block(1,10,-1,LEAVES:1)
Block(-6,16,0,LEAVES:1)
Block(-6,17,0,LEAVES:1)
Block(-5,9,0,LEAVES:1)
Block(-5,8,0,LEAVES:1)
Block(-2,24,-3,LEAVES:1)
Block(-2,23,-3,LEAVES:1)
Block(-3,7,-1,LEAVES:1)
Block(-3,8,-1,LEAVES:1)
Block(-3,9,-1,LEAVES:1)
Block(4,15,-2,LEAVES:1)
Block(-6,21,0,LEAVES:1)
Block(-6,22,0,LEAVES:1)
Block(0,5,0,LOG:1)
Block(-2,17,0,LOG:1)
Block(0,4,0,LEAVES:1)
Block(-2,16,0,LOG:1)
Block(0,7,0,LEAVES:1)
Block(-2,19,0,LOG:1)
Block(0,6,0,LEAVES:1)
Block(-2,18,0,LOG:1)
Block(-2,13,0,LOG:1)
Block(-2,12,0,LOG:1)
Block(-2,15,0,LOG:1)
Block(-2,14,0,LOG:1)
Block(-2,11,0,LOG:1)
Block(-2,10,0,LOG:1)
Block(1,8,-2,LEAVES:1)
Block(1,9,-2,LEAVES:1)
Block(-4,-3,-1,LOG:1)
Block(-4,-2,-1,LOG:1)
Block(-4,13,3,LEAVES:1)
Block(-1,16,5,LEAVES:1)
Block(-6,23,1,LEAVES:1)
Block(-4,8,-1,LEAVES:1)
Block(-4,10,-3,LEAVES:1)
Block(-4,11,-3,LEAVES:1)
Block(-5,17,-4,LEAVES:1)
Block(-4,12,-3,LEAVES:1)
Block(-4,9,-1,LEAVES:1)
Block(-2,28,0,LEAVES:1)
Block(-2,27,0,LOG:1)
Block(-5,10,-4,LEAVES:1)
Block(-4,16,-3,LEAVES:1)
Block(-5,11,-4,LEAVES:1)
Block(-4,12,3,LEAVES:1)
Block(-4,17,-3,LEAVES:1)
Block(-2,29,0,LEAVES:1)
Block(-4,18,-3,LEAVES:1)
Block(-2,24,0,LOG:1)
Block(-4,19,-3,LEAVES:1)
Block(-2,23,0,LOG:1)
Block(-2,26,0,LOG:1)
Block(-2,25,0,LOG:1)
Block(-2,20,0,LOG:1)
Block(-5,18,-4,LEAVES:1)
Block(-2,22,0,LOG:1)
Block(-2,21,0,LOG:1)
Block(-5,8,1,LEAVES:1)
Block(-2,17,-4,LEAVES:1)
Block(-5,7,1,LEAVES:1)
Block(-5,9,1,LEAVES:1)
Block(-7,16,-2,LEAVES:1)
Block(-7,15,-2,LEAVES:1)
Block(2,12,2,LEAVES:1)
Block(-4,12,4,LEAVES:1)
Block(1,9,-1,LEAVES:1)
Block(-6,13,2,LEAVES:1)
Block(-6,12,2,LEAVES:1)
Block(-1,-1,-1,LOG:1)
Block(-2,10,-5,LEAVES:1)
Block(-1,-3,-1,LOG:1)
Block(-2,-2,1,LOG:1)
Block(0,9,0,LEAVES:1)
Block(1,16,3,LEAVES:1)
Block(0,8,0,LEAVES:1)
Block(-4,10,-4,LEAVES:1)
Block(-5,11,-3,LEAVES:1)
Block(-2,29,1,LEAVES:1)
Block(-6,16,-2,LEAVES:1)
Block(-6,17,-2,LEAVES:1)
Block(-2,25,1,LEAVES:1)
Block(-2,24,1,LEAVES:1)
Block(-2,27,1,LEAVES:1)
Block(-2,26,1,LOG:1)
Block(-1,22,-1,LEAVES:1)
Block(-2,20,1,LEAVES:1)
Block(-1,23,-1,LEAVES:1)
Block(-2,23,1,LOG:1)
Block(-1,24,-1,LEAVES:1)
Block(-5,18,-3,LEAVES:1)
Block(-2,22,1,LEAVES:1)
Block(0,14,1,LEAVES:1)
Block(0,13,1,LEAVES:1)
Block(-2,7,-3,LEAVES:1)
Block(1,15,4,LEAVES:1)
Block(0,9,-4,LEAVES:1)
Block(1,16,4,LEAVES:1)
Block(-7,16,-1,LEAVES:1)
Block(-2,6,-3,LEAVES:1)
Block(-2,5,-3,LEAVES:1)
Block(-7,17,-1,LEAVES:1)
Block(-6,22,-2,LEAVES:1)
Block(-1,10,-2,LEAVES:1)
Block(-1,11,-2,LEAVES:1)
Block(-4,23,1,LEAVES:1)
Block(-4,22,1,LEAVES:1)
Block(2,7,-3,LEAVES:1)
Block(2,6,-3,LEAVES:1)
Block(2,8,-3,LEAVES:1)
Block(-5,22,-2,LEAVES:1)
Block(-2,-3,2,LOG:1)
Block(0,19,0,LEAVES:1)
Block(-2,31,0,LEAVES:1)
Block(-2,20,-1,LEAVES:1)
Block(-2,30,0,LEAVES:1)
Block(-2,12,-1,LEAVES:1)
Block(-2,13,-1,LOG:1)
Block(0,24,0,LEAVES:1)
Block(-2,10,-1,LEAVES:1)
Block(0,23,0,LEAVES:1)
Block(-1,10,-1,LEAVES:1)
Block(-2,11,-1,LEAVES:1)
Block(0,22,0,LEAVES:1)
Block(-2,17,-1,LOG:1)
Block(-2,14,-1,LEAVES:1)
Block(-2,4,-4,LEAVES:1)
Block(-2,18,-1,LEAVES:1)
Block(-2,5,-4,LEAVES:1)
Block(-2,19,-1,LEAVES:1)
Block(0,21,0,LEAVES:1)
Block(2,13,1,LEAVES:1)
Block(2,12,1,LEAVES:1)
Block(-2,18,1,LEAVES:1)
Block(-1,19,-1,LEAVES:1)
Block(-2,17,1,LOG:1)
Block(-4,5,-2,LEAVES:1)
Block(-4,4,-2,LEAVES:1)
Block(-2,19,1,LEAVES:1)
Block(-1,17,-1,LEAVES:1)
Block(-2,15,1,LOG:1)
Block(-1,18,-1,LEAVES:1)
Block(-2,10,1,LEAVES:1)
Block(-5,17,-2,LEAVES:1)
Block(-1,12,-1,LEAVES:1)
Block(-1,14,-1,LEAVES:1)
Block(0,14,0,LOG:1)
Block(0,13,0,LEAVES:1)
Block(0,12,0,LEAVES:1)
Block(-1,20,-1,LEAVES:1)
Block(0,11,0,LEAVES:1)
Block(-1,21,-1,LOG:1)
Block(-4,15,2,LEAVES:1)
Block(0,18,0,LEAVES:1)
Block(-2,-3,-2,LOG:1)
Block(-4,14,2,LEAVES:1)
Block(-2,-2,-2,LOG:1)
Block(-4,13,2,LEAVES:1)
Block(0,16,0,LEAVES:1)
Block(-4,12,2,LEAVES:1)
Block(0,15,0,LEAVES:1)
Block(2,6,-4,LEAVES:1)
Block(0,10,0,LEAVES:1)
Block(2,11,0,LEAVES:1)
Block(2,12,0,LEAVES:1)
Block(-2,0,-1,LOG:1)
Block(0,8,-2,LOG:1)
Block(0,7,-2,LEAVES:1)
Block(0,9,-2,LEAVES:1)
Block(-2,10,-2,LEAVES:1)
Block(2,13,0,LEAVES:1)
Block(2,14,0,LEAVES:1)
Block(-2,10,3,LEAVES:1)
Block(-1,12,-3,LEAVES:1)
Block(-4,25,0,LEAVES:1)
Block(-2,9,-1,LEAVES:1)
Block(-4,23,0,LEAVES:1)
Block(-4,24,0,LEAVES:1)
Block(-4,21,0,LEAVES:1)
Block(-4,22,0,LOG:1)
Block(-2,2,-1,LOG:1)
Block(-2,1,-1,LOG:1)
Block(-2,8,-1,LEAVES:1)
Block(-2,7,-1,LOG:1)
Block(-2,6,-1,LEAVES:1)
Block(-6,17,-1,LOG:1)
Block(-5,23,-1,LEAVES:1)
Block(-6,16,-1,LEAVES:1)
Block(-5,22,-1,LEAVES:1)
Block(-2,19,3,LEAVES:1)
Block(-6,18,-1,LEAVES:1)
Block(-2,17,3,LEAVES:1)
Block(-2,18,3,LEAVES:1)
Block(-2,16,3,LEAVES:1)
Block(-2,30,-1,LEAVES:1)
Block(0,17,2,LEAVES:1)
Block(-1,21,-3,LEAVES:1)
Block(-2,23,-1,LEAVES:1)
Block(-4,17,0,LEAVES:1)
Block(-3,18,-1,LEAVES:1)
Block(-2,24,-1,LEAVES:1)
Block(-4,14,0,LEAVES:1)
Block(-2,21,-1,LEAVES:1)
Block(-4,15,0,LEAVES:1)
Block(-2,22,-1,LOG:1)
Block(0,13,2,LEAVES:1)
Block(-2,27,-1,LEAVES:1)
Block(-2,28,-1,LEAVES:1)
Block(-4,10,0,LEAVES:1)
Block(-2,25,-1,LEAVES:1)
Block(-4,11,0,LEAVES:1)
Block(-4,17,-2,LEAVES:1)
Block(-2,26,-1,LEAVES:1)
Block(-3,10,-1,LEAVES:1)
Block(-3,11,-1,LEAVES:1)
Block(-3,12,-1,LEAVES:1)
Block(0,12,2,LEAVES:1)
Block(-4,18,0,LOG:1)
Block(-4,19,0,LEAVES:1)
Block(0,7,-3,LEAVES:1)
Block(0,9,-3,LEAVES:1)
Block(-5,10,-1,LEAVES:1)
Block(-2,18,2,LOG:1)
Block(0,8,-3,LEAVES:1)
Block(-2,19,2,LEAVES:1)
Block(-4,21,1,LEAVES:1)
Block(-2,17,2,LEAVES:1)
Block(-5,19,-1,LEAVES:1)
Block(-1,18,-2,LEAVES:1)
Block(-1,19,-2,LEAVES:1)
Block(-1,12,-2,LEAVES:1)
Block(-5,16,-1,LEAVES:1)
Block(-1,13,-2,LEAVES:1)
Block(-5,18,-1,LOG:1)
Block(-5,17,-1,LEAVES:1)
Block(-4,18,1,LEAVES:1)
Block(-2,25,-2,LEAVES:1)
Block(-1,20,-2,LEAVES:1)
Block(-2,20,2,LEAVES:1)
Block(-2,24,-2,LEAVES:1)
Block(-1,21,-2,LEAVES:1)
Block(-2,8,-2,LEAVES:1)
Block(-4,15,1,LEAVES:1)
Block(-1,22,-2,LEAVES:1)
Block(-4,14,1,LOG:1)
Block(-4,13,1,LEAVES:1)
Block(-3,22,-1,LEAVES:1)
Block(-3,23,-1,LEAVES:1)
Block(-2,7,-2,LEAVES:1)
Block(-3,24,-1,LEAVES:1)
Block(-2,6,-2,LOG:1)
Block(-3,26,-1,LEAVES:1)
Block(-4,19,1,LEAVES:1)
Block(-4,10,1,LEAVES:1)
Block(-2,26,2,LEAVES:1)
Block(-2,21,-2,LEAVES:1)
Block(-2,23,2,LEAVES:1)
Block(-2,22,2,LEAVES:1)
Block(-2,13,-2,LEAVES:1)
Block(-4,-3,2,LOG:1)
Block(-2,12,-2,LOG:1)
Block(-2,11,-2,LEAVES:1)
Block(0,23,1,LEAVES:1)
Block(-2,18,-2,LEAVES:1)
Block(-2,17,-2,LOG:1)
Block(-4,23,-1,LEAVES:1)
Block(-4,22,-1,LEAVES:1)
Block(3,6,-3,LEAVES:1)
Block(-2,17,4,LEAVES:1)
Block(-2,16,4,LEAVES:1)
Block(-5,13,2,LOG:1)
Block(-2,15,4,LEAVES:1)
Block(-5,14,2,LEAVES:1)
Block(-2,14,4,LEAVES:1)
Block(-1,16,1,LEAVES:1)
Block(-3,18,-2,LEAVES:1)
Block(-5,21,2,LEAVES:1)
Block(-1,18,1,LEAVES:1)
Block(-5,22,2,LEAVES:1)
Block(3,16,-4,LEAVES:1)
Block(-3,11,-2,LEAVES:1)
Block(0,21,-1,LEAVES:1)
Block(-3,12,-2,LEAVES:1)
Block(0,20,-1,LEAVES:1)
Block(-1,12,1,LEAVES:1)
Block(-1,13,1,LEAVES:1)
Block(0,22,-1,LEAVES:1)
Block(-5,7,-2,LEAVES:1)
Block(-1,14,1,LEAVES:1)
Block(-3,17,-2,LEAVES:1)
Block(-5,8,-2,LEAVES:1)
Block(-1,15,1,LEAVES:1)
Block(-3,16,-2,LEAVES:1)
Block(-1,5,0,LEAVES:1)
Block(-1,4,0,LEAVES:1)
Block(-1,7,0,LEAVES:1)
Block(-1,6,0,LOG:1)
Block(-1,9,0,LOG:1)
Block(-5,11,2,LEAVES:1)
Block(-4,-1,0,LOG:1)
Block(-5,12,2,LEAVES:1)
Block(-1,22,1,LEAVES:1)
Block(-3,23,-2,LEAVES:1)
Block(-1,23,1,LEAVES:1)
Block(-1,24,1,LEAVES:1)
Block(0,5,-1,LEAVES:1)
Block(0,4,-1,LEAVES:1)
Block(0,7,-1,LEAVES:1)
Block(0,6,-1,LEAVES:1)
Block(0,9,-1,LOG:1)
Block(0,8,-1,LEAVES:1)
Block(-5,23,1,LEAVES:1)
Block(-5,24,1,LEAVES:1)
Block(0,3,-1,LEAVES:1)
Block(0,18,3,LEAVES:1)
Block(-4,-2,1,LOG:1)
Block(0,15,3,LEAVES:1)
Block(0,16,3,LEAVES:1)
Block(0,17,3,LEAVES:1)
Block(0,10,3,LEAVES:1)
Block(0,15,-1,LEAVES:1)
Block(0,18,-1,LOG:1)
Block(0,17,-1,LEAVES:1)
Block(0,19,-1,LEAVES:1)
Block(-1,9,-2,LEAVES:1)
Block(-5,13,1,LEAVES:1)
Block(-1,8,-2,LEAVES:1)
Block(-4,9,-6,LEAVES:1)
Block(-5,14,1,LEAVES:1)
Block(-5,15,1,LEAVES:1)
Block(-2,11,4,LEAVES:1)
Block(-1,18,2,LEAVES:1)
Block(-2,10,4,LEAVES:1)
Block(-1,17,2,LEAVES:1)
Block(-5,22,1,LEAVES:1)
Block(-3,12,-3,LOG:1)
Block(-3,11,-3,LEAVES:1)
Block(0,10,-1,LEAVES:1)
Block(-3,13,-3,LEAVES:1)
Block(-3,16,-3,LEAVES:1)
Block(0,14,-1,LEAVES:1)
Block(-1,16,2,LEAVES:1)
Block(-3,18,-3,LEAVES:1)
Block(0,13,-1,LEAVES:1)
Block(-3,17,-3,LOG:1)
Block(1,20,-4,LEAVES:1)
Block(0,16,5,LEAVES:1)
Block(0,15,5,LEAVES:1)
Block(0,14,5,LEAVES:1)
Block(-1,-1,1,LOG:1)
Block(-1,5,2,LEAVES:1)
Block(-1,4,2,LEAVES:1)
Block(-1,7,2,LEAVES:1)
Block(-3,10,-4,LEAVES:1)
Block(-3,11,-4,LEAVES:1)
Block(-1,9,2,LEAVES:1)
Block(-1,8,2,LEAVES:1)
Block(-2,9,0,LOG:1)
Block(-2,8,0,LOG:1)
Block(-2,7,0,LOG:1)
Block(-2,6,0,LOG:1)
Block(-2,5,0,LOG:1)
Block(-2,4,0,LOG:1)
Block(-2,3,0,LOG:1)
Block(-2,2,0,LOG:1)
Block(-1,15,0,LEAVES:1)
Block(-2,1,0,LOG:1)
Block(-1,16,0,LEAVES:1)
Block(-2,0,0,LOG:1)
Block(-1,18,0,LOG:1)
Block(3,15,-3,LEAVES:1)
Block(-1,19,0,LEAVES:1)
Block(3,17,-3,LEAVES:1)
Block(3,16,-3,LEAVES:1)
Block(-1,10,0,LEAVES:1)
Block(-1,11,0,LOG:1)
Block(-1,12,0,LEAVES:1)
Block(-1,13,0,LOG:1)
Block(-1,14,0,LEAVES:1)
Block(-1,26,0,LEAVES:1)
Block(-2,10,5,LEAVES:1)
Block(-5,13,3,LEAVES:1)
Block(-1,28,0,LEAVES:1)
Block(-5,12,3,LEAVES:1)
Block(-5,7,-1,LEAVES:1)
Block(-3,15,-4,LEAVES:1)
Block(-3,12,-4,LEAVES:1)
Block(-1,20,0,LEAVES:1)
Block(-1,21,0,LEAVES:1)
Block(-3,18,-4,LEAVES:1)
Block(-1,22,0,LEAVES:1)
Block(-3,19,-4,LEAVES:1)
Block(-1,23,0,LEAVES:1)
Block(-5,8,-1,LEAVES:1)
Block(-3,16,-4,LEAVES:1)
Block(-1,24,0,LOG:1)
Block(-5,9,-1,LOG:1)
Block(-3,17,-4,LEAVES:1)
Block(-1,25,0,LEAVES:1)
Block(-1,6,1,LEAVES:1)
Block(-1,5,1,LEAVES:1)
Block(-3,-1,0,LOG:1)
Block(-1,8,1,LEAVES:1)
Block(-3,-2,0,LOG:1)
Block(-1,7,1,LEAVES:1)
Block(-3,-3,0,LOG:1)
Block(0,15,4,LEAVES:1)
Block(0,16,4,LOG:1)
Block(0,17,4,LEAVES:1)
Block(-1,0,1,LOG:1)
Block(0,10,4,LEAVES:1)
Block(-4,11,-4,LOG:1)
Block(-4,12,-4,LEAVES:1)
Block(-3,0,0,LOG:1)
Block(-3,11,-5,LEAVES:1)
Block(-1,10,4,LOG:1)
Block(-4,17,-4,LEAVES:1)
Block(-3,10,-5,LEAVES:1)
Block(-4,18,-4,LOG:1)
Block(-4,19,-4,LEAVES:1)
Block(1,17,-3,LEAVES:1)
Block(2,18,-2,LEAVES:1)
Block(2,16,-2,LEAVES:1)
Block(2,17,-2,LOG:1)
Block(-3,9,0,LEAVES:1)
Block(-3,8,0,LEAVES:1)
Block(-2,9,2,LEAVES:1)
Block(-2,8,2,LOG:1)
Block(-1,9,4,LEAVES:1)
Block(-7,21,0,LEAVES:1)
Block(-2,7,2,LEAVES:1)
Block(-1,8,4,LEAVES:1)
Block(-7,16,0,LEAVES:1)
Block(-7,15,0,LEAVES:1)
Block(0,14,6,LEAVES:1)
Block(-3,15,-5,LEAVES:1)
Block(0,13,6,LEAVES:1)
Block(-3,16,-5,LEAVES:1)
Block(-1,11,4,LEAVES:1)
Block(0,21,-4,LEAVES:1)
Block(-1,17,4,LEAVES:1)
Block(-1,18,4,LEAVES:1)
Block(0,12,6,LEAVES:1)
Block(-1,15,4,LEAVES:1)
Block(-1,16,4,LEAVES:1)
Block(-3,18,-5,LEAVES:1)
Block(0,4,1,LEAVES:1)
Block(0,6,1,LEAVES:1)
Block(0,5,1,LEAVES:1)
Block(-6,9,-1,LEAVES:1)
Block(-6,8,-1,LEAVES:1)
Block(-6,7,-1,LEAVES:1)
Block(-6,6,-1,LEAVES:1)
Block(3,17,-2,LEAVES:1)
Block(3,15,-2,LEAVES:1)
Block(3,16,-2,LEAVES:1)
Block(0,22,-3,LEAVES:1)
Block(0,20,-3,LEAVES:1)
Block(0,21,-3,LEAVES:1)
Block(-4,11,-5,LEAVES:1)
Block(-4,10,-5,LEAVES:1)
Block(-3,11,0,LEAVES:1)
Block(-4,12,-5,LEAVES:1)
Block(-3,10,0,LOG:1)
Block(-1,10,5,LEAVES:1)
Block(-4,17,-5,LEAVES:1)
Block(-1,8,3,LEAVES:1)
Block(-3,14,0,LEAVES:1)
Block(-4,18,-5,LEAVES:1)
Block(-2,9,1,LEAVES:1)
Block(-3,19,0,LEAVES:1)
Block(-2,8,1,LEAVES:1)
Block(-1,9,3,LEAVES:1)
Block(-2,7,1,LOG:1)
Block(-3,17,0,LEAVES:1)
Block(-2,6,1,LEAVES:1)
Block(-3,18,0,LOG:1)
Block(2,17,-3,LEAVES:1)
Block(2,18,-3,LEAVES:1)
Block(2,16,-3,LEAVES:1)
Block(1,20,-3,LEAVES:1)
Block(1,21,-3,LEAVES:1)
Block(1,6,0,LEAVES:1)
Block(1,5,0,LEAVES:1)
Block(3,11,0,LEAVES:1)
Block(-6,11,3,LEAVES:1)
Block(-6,12,3,LEAVES:1)
Block(-3,22,0,LOG:1)
Block(-3,23,0,LEAVES:1)
Block(-3,20,0,LEAVES:1)
Block(-4,9,0,LOG:1)
Block(-3,21,0,LEAVES:1)
Block(-3,26,0,LEAVES:1)
Block(-3,27,0,LEAVES:1)
Block(-3,24,0,LEAVES:1)
Block(-3,25,0,LEAVES:1)
Block(-3,29,0,LEAVES:1)
Block(-4,8,0,LEAVES:1)
Block(-5,9,-4,LEAVES:1)
Block(-3,9,2,LEAVES:1)
Block(-3,8,2,LEAVES:1)
Block(-1,21,2,LEAVES:1)
Block(-3,7,2,LEAVES:1)
Block(-1,22,2,LEAVES:1)
Block(-1,7,-1,LEAVES:1)
Block(-1,6,-1,LEAVES:1)
Block(1,18,0,LEAVES:1)
Block(-1,5,-1,LEAVES:1)
Block(1,15,0,LEAVES:1)
Block(-2,9,4,LEAVES:1)
Block(1,14,0,LEAVES:1)
Block(1,13,0,LOG:1)
Block(1,12,0,LEAVES:1)
Block(2,18,-1,LEAVES:1)
Block(2,17,-1,LEAVES:1)
Block(-5,24,0,LEAVES:1)
Block(-1,9,6,LEAVES:1)
Block(-5,23,0,LOG:1)
Block(-1,8,6,LEAVES:1)
Block(-5,22,0,LEAVES:1)
Block(-1,9,-1,LEAVES:1)
Block(2,16,-1,LEAVES:1)
Block(-1,8,-1,LEAVES:1)
Block(1,5,1,LEAVES:1)
Block(1,4,1,LEAVES:1)
Block(1,3,1,LEAVES:1)
Block(1,21,-1,LEAVES:1)
Block(-4,10,-6,LEAVES:1)
Block(0,17,-2,LEAVES:1)
Block(-3,13,1,LEAVES:1)
Block(-3,10,1,LEAVES:1)
Block(-4,16,-6,LEAVES:1)
Block(0,19,-2,LEAVES:1)
Block(-3,11,1,LEAVES:1)
Block(0,18,-2,LEAVES:1)
Block(-4,17,-6,LEAVES:1)
Block(-3,14,1,LEAVES:1)
Block(-3,15,1,LOG:1)
Block(1,23,0,LEAVES:1)
Block(1,22,0,LEAVES:1)
Block(-3,18,1,LEAVES:1)
Block(-5,18,0,LEAVES:1)
Block(-5,17,0,LEAVES:1)
Block(-1,19,3,LEAVES:1)
Block(-1,18,3,LOG:1)
Block(1,20,-2,LEAVES:1)
Block(-5,9,-5,LEAVES:1)
Block(-5,21,0,LEAVES:1)
Block(-3,9,1,LEAVES:1)
Block(-1,11,3,LEAVES:1)
Block(-1,10,3,LEAVES:1)
Block(-3,8,1,LEAVES:1)
Block(0,10,-2,LEAVES:1)
Block(-1,17,3,LOG:1)
Block(-1,16,3,LEAVES:1)
Block(-3,23,1,LEAVES:1)
Block(-3,24,1,LEAVES:1)
Block(-3,22,1,LEAVES:1)
Block(-2,9,3,LOG:1)
Block(-2,8,3,LEAVES:1)
Block(-3,26,1,LEAVES:1)
Block(-2,7,3,LEAVES:1)
Block(1,16,-2,LEAVES:1)
Block(1,17,-2,LEAVES:1)
Block(-1,9,5,LEAVES:1)
Block(1,18,-2,LEAVES:1)
Block(-5,10,0,LEAVES:1)
Block(-3,6,-3,LEAVES:1)
Block(0,20,-2,LEAVES:1)
Block(0,7,4,LEAVES:1)
Block(0,22,-2,LEAVES:1)
Block(0,21,-2,LOG:1)
Block(0,9,4,LEAVES:1)
Block(0,8,4,LEAVES:1)

#######################################################################
# +-----------------------------------------------------------------+ #
# |                            BO3 checks                           | #
# +-----------------------------------------------------------------+ #
#######################################################################

BlockCheck(0,-1,0,GRASS,DIRT:0,DIRT:1,DIRT:2,biomesoplenty:grass:0,biomesoplenty:grass:1,biomesoplenty:grass:2,biomesoplenty:grass:3,biomesoplenty:grass:4,biomesoplenty:grass:5,biomesoplenty:grass:6,biomesoplenty:grass:7,biomesoplenty:dirt:0,biomesoplenty:dirt:1,biomesoplenty:dirt:2,biomesoplenty:dirt:3,biomesoplenty:dirt:4,biomesoplenty:dirt:5,biomesoplenty:dirt:6,biomesoplenty:dirt:7,biomesoplenty:dirt:8,biomesoplenty:dirt:9,biomesoplenty:dirt:10,biomesoplenty:dried_sand:0,biomesoplenty:hard_ice:0,biomesoplenty:white_sand:0,biomesoplenty:white_sandstone:0,biomesoplenty:mud:0,biomesoplenty:ash_block:0)

#######################################################################
# +-----------------------------------------------------------------+ #
# |                             Branches                            | #
# +-----------------------------------------------------------------+ #
#######################################################################


#######################################################################
# +-----------------------------------------------------------------+ #
# |                             Entities                            | #
# +-----------------------------------------------------------------+ #
#######################################################################


#######################################################################
# +-----------------------------------------------------------------+ #
# |                            Particles                            | #
# +-----------------------------------------------------------------+ #
#######################################################################


#######################################################################
# +-----------------------------------------------------------------+ #
# |                             Spawners                            | #
# +-----------------------------------------------------------------+ #
#######################################################################


#######################################################################
# +-----------------------------------------------------------------+ #
# |                             ModData                             | #
# +-----------------------------------------------------------------+ #
#######################################################################

