
#######################################################################
# +-----------------------------------------------------------------+ #
# |                            BO3 object                           | #
# +-----------------------------------------------------------------+ #
#######################################################################

Author: LordSmellyPants

Description: No description given

Version: 3

SettingsMode: WriteWithoutComments


#######################################################################
# +-----------------------------------------------------------------+ #
# |                          Main settings                          | #
# +-----------------------------------------------------------------+ #
#######################################################################

Tree: true

Frequency: 1

Rarity: 100.0

RotateRandomly: true

SpawnHeight: highestSolidBlock

SpawnHeightOffset: 0

SpawnHeightVariance: 0

##############################
# Height Limits for the BO3. #
##############################

MinHeight: 63

MaxHeight: 70

######################
# Extrusion settings #
######################

ExtrudeMode: None

ExtrudeThroughBlocks: AIR

MaxBranchDepth: 10

ExcludedBiomes: All


#######################################################################
# +-----------------------------------------------------------------+ #
# |                      Source block settings                      | #
# +-----------------------------------------------------------------+ #
#######################################################################

SourceBlocks: AIR

MaxPercentageOutsideSourceBlock: 0

OutsideSourceBlock: placeAnyway

DoReplaceBlocks: true

IsOTGPlus: false


#######################################################################
# +-----------------------------------------------------------------+ #
# |                              Blocks                             | #
# +-----------------------------------------------------------------+ #
#######################################################################

Block(-7,10,1,LEAVES:1)
Block(-7,14,-3,LOG:13)
Block(-7,15,-1,LEAVES:1)
Block(-7,19,3,LEAVES:1)
Block(-6,7,4,LEAVES:1)
Block(-6,10,1,LOG:13)
Block(-6,10,2,LEAVES:1)
Block(-6,12,5,LEAVES:1)
Block(-6,14,-3,LEAVES:1)
Block(-6,15,-4,LEAVES:1)
Block(-6,15,-3,LEAVES:1)
Block(-6,15,-2,LOG:13)
Block(-6,15,-1,LEAVES:1)
Block(-6,16,-1,LEAVES:1)
Block(-6,18,2,LEAVES:1)
Block(-6,18,3,LOG:13)
Block(-6,18,4,LEAVES:1)
Block(-6,19,3,LEAVES:1)
Block(-5,4,-4,LEAVES:1)
Block(-5,4,-3,LEAVES:1)
Block(-5,5,-4,LEAVES:1)
Block(-5,7,4,LOG:13)
Block(-5,7,5,LEAVES:1)
Block(-5,7,6,LEAVES:1)
Block(-5,8,3,LEAVES:1)
Block(-5,10,-6,LEAVES:1)
Block(-5,11,-1,LEAVES:1)
Block(-5,11,0,LEAVES:1)
Block(-5,11,1,LOG:13)
Block(-5,11,6,LOG:13)
Block(-5,11,7,LEAVES:1)
Block(-5,12,0,LEAVES:1)
Block(-5,12,5,LOG:13)
Block(-5,14,3,LEAVES:1)
Block(-5,16,-2,LOG:13)
Block(-5,19,-4,LEAVES:1)
Block(-5,19,-2,LEAVES:1)
Block(-5,19,2,LEAVES:1)
Block(-5,19,3,LOG:13)
Block(-5,23,3,LEAVES:1)
Block(-5,24,-2,LEAVES:1)
Block(-5,24,-1,LEAVES:1)
Block(-4,4,-4,LOG:13)
Block(-4,7,5,LEAVES:1)
Block(-4,8,3,LOG:13)
Block(-4,9,1,LEAVES:1)
Block(-4,9,2,LEAVES:1)
Block(-4,10,-7,LEAVES:1)
Block(-4,10,-6,LEAVES:1)
Block(-4,10,-5,LOG:13)
Block(-4,10,-4,LEAVES:1)
Block(-4,10,2,LEAVES:1)
Block(-4,11,-5,LEAVES:1)
Block(-4,12,0,LOG:13)
Block(-4,12,5,LEAVES:1)
Block(-4,12,6,LEAVES:1)
Block(-4,13,4,LOG:13)
Block(-4,13,5,LEAVES:1)
Block(-4,14,3,LOG:13)
Block(-4,16,-2,LEAVES:1)
Block(-4,16,-1,LOG:13)
Block(-4,19,-5,LEAVES:1)
Block(-4,19,-4,LEAVES:1)
Block(-4,19,-3,LOG:13)
Block(-4,19,-2,LEAVES:1)
Block(-4,19,2,LOG:13)
Block(-4,19,3,LEAVES:1)
Block(-4,19,4,LEAVES:1)
Block(-4,20,-2,LEAVES:1)
Block(-4,20,1,LEAVES:1)
Block(-4,23,3,LOG:13)
Block(-4,23,4,LOG:13)
Block(-4,23,5,LEAVES:1)
Block(-4,24,-1,LOG:13)
Block(-4,25,0,LEAVES:1)
Block(-3,4,-5,LEAVES:1)
Block(-3,4,-4,LEAVES:1)
Block(-3,5,-3,LOG:13)
Block(-3,5,-2,LEAVES:1)
Block(-3,8,3,LEAVES:1)
Block(-3,9,2,LOG:13)
Block(-3,10,-4,LOG:13)
Block(-3,12,-1,LEAVES:1)
Block(-3,12,0,LOG:13)
Block(-3,12,5,LEAVES:1)
Block(-3,14,2,LOG:13)
Block(-3,14,3,LEAVES:1)
Block(-3,14,4,LEAVES:1)
Block(-3,15,6,LEAVES:1)
Block(-3,16,-1,LEAVES:1)
Block(-3,17,-1,LEAVES:1)
Block(-3,17,0,LOG:13)
Block(-3,18,0,LEAVES:1)
Block(-3,19,3,LEAVES:1)
Block(-3,20,-3,LEAVES:1)
Block(-3,20,-2,LOG:13)
Block(-3,20,1,LOG:13)
Block(-3,23,3,LEAVES:1)
Block(-3,24,2,LOG:13)
Block(-3,25,0,LOG:13)
Block(-3,25,2,LEAVES:1)
Block(-3,26,1,LEAVES:1)
Block(-2,1,1,LEAVES:1)
Block(-2,2,0,LEAVES:1)
Block(-2,2,1,LEAVES:1)
Block(-2,5,-2,LOG:13)
Block(-2,6,-1,LEAVES:1)
Block(-2,8,0,LEAVES:1)
Block(-2,9,-1,LEAVES:1)
Block(-2,9,0,LEAVES:1)
Block(-2,9,1,LOG:13)
Block(-2,10,-4,LEAVES:1)
Block(-2,11,-5,LEAVES:1)
Block(-2,11,-4,LEAVES:1)
Block(-2,11,-3,LOG:13)
Block(-2,12,-2,LEAVES:1)
Block(-2,13,0,LOG:13)
Block(-2,14,-2,LEAVES:1)
Block(-2,14,0,LEAVES:1)
Block(-2,14,3,LEAVES:1)
Block(-2,15,1,LOG:13)
Block(-2,15,5,LEAVES:1)
Block(-2,15,6,LEAVES:1)
Block(-2,16,1,LOG:13)
Block(-2,16,6,LEAVES:1)
Block(-2,17,-1,LEAVES:1)
Block(-2,17,1,LOG:13)
Block(-2,17,3,LOG:13)
Block(-2,17,4,LOG:13)
Block(-2,18,1,LOG:13)
Block(-2,18,2,LOG:13)
Block(-2,19,1,LOG:13)
Block(-2,19,2,LEAVES:1)
Block(-2,20,-1,LOG:13)
Block(-2,20,1,LOG:13)
Block(-2,21,-1,LEAVES:1)
Block(-2,21,0,LOG:13)
Block(-2,21,1,LOG:13)
Block(-2,22,-1,LEAVES:1)
Block(-2,22,1,LOG:13)
Block(-2,23,1,LOG:13)
Block(-2,24,1,LOG:13)
Block(-2,25,1,LOG:13)
Block(-2,26,0,LEAVES:1)
Block(-2,26,1,LOG:13)
Block(-2,27,0,LEAVES:1)
Block(-2,27,1,LOG:13)
Block(-2,28,0,LEAVES:1)
Block(-2,28,1,LEAVES:1)
Block(-2,29,1,LEAVES:1)
Block(-2,30,1,LEAVES:1)
Block(-2,31,0,LEAVES:1)
Block(-2,31,1,LEAVES:1)
Block(-2,32,1,LEAVES:1)
Block(-1,-5,-2,LOG:13)
Block(-1,-5,0,LOG:13)
Block(-1,-5,2,LOG:13)
Block(-1,2,0,LEAVES:1)
Block(-1,3,0,LOG:13)
Block(-1,3,1,LEAVES:1)
Block(-1,4,0,LOG:13)
Block(-1,5,-2,LEAVES:1)
Block(-1,5,-1,LEAVES:1)
Block(-1,5,0,LOG:13)
Block(-1,6,-1,LOG:13)
Block(-1,6,0,LOG:13)
Block(-1,7,0,LOG:13)
Block(-1,8,0,LOG:13)
Block(-1,8,1,LEAVES:1)
Block(-1,9,0,LOG:13)
Block(-1,9,1,LEAVES:1)
Block(-1,9,2,LEAVES:1)
Block(-1,10,0,LOG:13)
Block(-1,10,1,LOG:13)
Block(-1,11,0,LOG:13)
Block(-1,11,1,LOG:13)
Block(-1,12,-2,LOG:13)
Block(-1,12,-1,LOG:13)
Block(-1,12,0,LOG:13)
Block(-1,12,1,LOG:13)
Block(-1,13,0,LOG:13)
Block(-1,13,1,LOG:13)
Block(-1,14,-3,LEAVES:1)
Block(-1,14,-2,LEAVES:1)
Block(-1,14,0,LOG:13)
Block(-1,14,1,LOG:13)
Block(-1,15,0,LOG:13)
Block(-1,15,1,LOG:13)
Block(-1,15,6,LOG:13)
Block(-1,15,7,LEAVES:1)
Block(-1,16,0,LEAVES:1)
Block(-1,16,1,LOG:13)
Block(-1,16,5,LOG:13)
Block(-1,17,1,LOG:13)
Block(-1,17,4,LEAVES:1)
Block(-1,17,5,LEAVES:1)
Block(-1,18,1,LOG:13)
Block(-1,19,0,LOG:13)
Block(-1,19,1,LOG:13)
Block(-1,20,0,LEAVES:1)
Block(-1,23,1,LEAVES:1)
Block(-1,23,2,LOG:13)
Block(-1,24,2,LEAVES:1)
Block(-1,30,1,LEAVES:1)
Block(0,-5,-1,LOG:13)
Block(0,-5,0,LOG:13)
Block(0,-5,1,LOG:13)
Block(0,-5,2,LOG:13)
Block(0,-5,3,LOG:13)
Block(0,-4,-1,LOG:13)
Block(0,-4,0,LOG:13)
Block(0,-4,1,LOG:13)
Block(0,-4,2,LOG:1)
Block(0,-3,-1,LOG:1)
Block(0,-3,0,LOG:13)
Block(0,-2,0,LOG:13)
Block(0,-1,-1,LOG:13)
Block(0,-1,0,LOG:13)
Block(0,0,-1,LOG:13)
Block(0,0,0,LOG:13)
Block(0,1,-1,LOG:13)
Block(0,1,0,LOG:13)
Block(0,2,-2,LOG:13)
Block(0,2,-1,LOG:13)
Block(0,2,0,LOG:13)
Block(0,3,-1,LOG:13)
Block(0,3,0,LOG:13)
Block(0,4,-1,LOG:13)
Block(0,4,0,LOG:13)
Block(0,5,-1,LOG:13)
Block(0,5,0,LOG:13)
Block(0,6,-1,LOG:13)
Block(0,6,0,LOG:13)
Block(0,7,-1,LOG:13)
Block(0,7,0,LOG:13)
Block(0,8,-1,LOG:13)
Block(0,8,0,LOG:13)
Block(0,9,0,LOG:13)
Block(0,10,-2,LEAVES:1)
Block(0,10,-1,LOG:13)
Block(0,10,0,LOG:13)
Block(0,13,1,LOG:13)
Block(0,13,2,LOG:13)
Block(0,13,3,LEAVES:1)
Block(0,14,-2,LOG:13)
Block(0,14,1,LEAVES:1)
Block(0,15,-1,LOG:13)
Block(0,16,1,LOG:13)
Block(0,16,2,LEAVES:1)
Block(0,17,4,LEAVES:1)
Block(0,18,-2,LEAVES:1)
Block(0,19,-1,LOG:13)
Block(0,22,2,LOG:13)
Block(0,22,3,LEAVES:1)
Block(1,-5,-1,LOG:13)
Block(1,-5,0,LOG:13)
Block(1,-5,1,LOG:13)
Block(1,-5,2,LOG:13)
Block(1,-4,-1,LOG:13)
Block(1,-4,0,LOG:13)
Block(1,-4,1,LOG:13)
Block(1,-4,2,LOG:13)
Block(1,-3,-1,LOG:13)
Block(1,-3,0,LOG:13)
Block(1,-3,1,LOG:13)
Block(1,-3,2,LOG:1)
Block(1,-2,-1,LOG:1)
Block(1,-2,0,LOG:13)
Block(1,-2,1,LOG:13)
Block(1,-1,0,LOG:13)
Block(1,-1,1,LOG:13)
Block(1,0,0,LOG:1)
Block(1,0,1,LOG:13)
Block(1,1,0,LOG:13)
Block(1,1,1,LEAVES:1)
Block(1,2,-2,LEAVES:1)
Block(1,2,0,LOG:13)
Block(1,5,-1,LEAVES:1)
Block(1,5,0,LOG:13)
Block(1,5,1,LEAVES:1)
Block(1,6,-2,LEAVES:1)
Block(1,6,-1,LEAVES:1)
Block(1,8,-1,LEAVES:1)
Block(1,8,0,LEAVES:1)
Block(1,9,-4,LEAVES:1)
Block(1,10,-2,LOG:13)
Block(1,12,3,LOG:13)
Block(1,12,5,LEAVES:1)
Block(1,13,3,LEAVES:1)
Block(1,14,-4,LEAVES:1)
Block(1,14,-3,LOG:13)
Block(1,15,-1,LEAVES:1)
Block(1,15,0,LEAVES:1)
Block(1,15,1,LOG:13)
Block(1,15,2,LEAVES:1)
Block(1,16,0,LEAVES:1)
Block(1,17,-4,LEAVES:1)
Block(1,18,-2,LOG:13)
Block(1,19,-2,LEAVES:1)
Block(1,22,2,LEAVES:1)
Block(1,22,3,LOG:13)
Block(2,-5,-3,LOG:13)
Block(2,-5,-2,LOG:13)
Block(2,-5,-1,LOG:13)
Block(2,-5,0,LOG:13)
Block(2,-5,2,LOG:13)
Block(2,-4,-2,LOG:13)
Block(2,-4,-1,LOG:1)
Block(2,-4,0,LOG:13)
Block(2,-3,0,LOG:1)
Block(2,1,1,LEAVES:1)
Block(2,1,2,LEAVES:1)
Block(2,4,0,LEAVES:1)
Block(2,4,1,LOG:13)
Block(2,6,-1,LEAVES:1)
Block(2,8,0,LEAVES:1)
Block(2,8,1,LEAVES:1)
Block(2,9,-5,LEAVES:1)
Block(2,9,-4,LEAVES:1)
Block(2,9,-3,LOG:13)
Block(2,9,1,LEAVES:1)
Block(2,10,-2,LEAVES:1)
Block(2,12,4,LOG:13)
Block(2,12,5,LEAVES:1)
Block(2,12,6,LEAVES:1)
Block(2,13,-4,LOG:13)
Block(2,14,-3,LEAVES:1)
Block(2,15,0,LEAVES:1)
Block(2,15,1,LOG:13)
Block(2,17,-5,LEAVES:1)
Block(2,17,-4,LEAVES:1)
Block(2,17,-3,LOG:13)
Block(2,18,-2,LEAVES:1)
Block(2,18,-1,LEAVES:1)
Block(2,22,3,LEAVES:1)
Block(3,-5,0,LOG:13)
Block(3,-5,1,LOG:13)
Block(3,-4,1,LOG:13)
Block(3,3,2,LEAVES:1)
Block(3,4,1,LOG:13)
Block(3,4,2,LEAVES:1)
Block(3,4,3,LEAVES:1)
Block(3,8,-5,LOG:13)
Block(3,8,1,LEAVES:1)
Block(3,9,-4,LOG:13)
Block(3,10,6,LEAVES:1)
Block(3,11,5,LOG:13)
Block(3,13,-6,LEAVES:1)
Block(3,13,-5,LOG:13)
Block(3,13,-4,LEAVES:1)
Block(3,14,-4,LEAVES:1)
Block(3,14,-1,LEAVES:1)
Block(3,14,0,LOG:13)
Block(3,14,1,LEAVES:1)
Block(3,14,2,LEAVES:1)
Block(3,17,-3,LEAVES:1)
Block(4,-5,1,LOG:13)
Block(4,3,1,LEAVES:1)
Block(4,3,2,LOG:13)
Block(4,8,-6,LEAVES:1)
Block(4,8,-5,LEAVES:1)
Block(4,10,6,LOG:13)
Block(4,11,5,LEAVES:1)
Block(4,14,0,LOG:13)
Block(4,14,1,LEAVES:1)
Block(5,3,1,LEAVES:1)
Block(5,3,3,LOG:13)
Block(5,3,4,LEAVES:1)
Block(5,10,6,LEAVES:1)
Block(5,10,7,LEAVES:1)
Block(5,11,7,LEAVES:1)
Block(5,13,-1,LEAVES:1)
Block(5,13,0,LOG:13)
Block(6,3,3,LEAVES:1)
Block(6,10,7,LEAVES:1)
Block(6,13,0,LEAVES:1)

#######################################################################
# +-----------------------------------------------------------------+ #
# |                            BO3 checks                           | #
# +-----------------------------------------------------------------+ #
#######################################################################

BlockCheck(0,-1,0,GRASS,DIRT,biomesoplenty:grass:0,biomesoplenty:grass:1,biomesoplenty:grass,biomesoplenty:grass:3,biomesoplenty:grass:4,biomesoplenty:grass:5,biomesoplenty:grass:6,biomesoplenty:grass:7,UNKNOWN_BLOCK:0,UNKNOWN_BLOCK:1,UNKNOWN_BLOCK:2,UNKNOWN_BLOCK:8,UNKNOWN_BLOCK:9,UNKNOWN_BLOCK:10,biomesoplenty:dried_sand,biomesoplenty:hard_ice,biomesoplenty:white_sand,biomesoplenty:white_sandstone,biomesoplenty:mud,biomesoplenty:ash_block)

#######################################################################
# +-----------------------------------------------------------------+ #
# |                             Branches                            | #
# +-----------------------------------------------------------------+ #
#######################################################################


#######################################################################
# +-----------------------------------------------------------------+ #
# |                             Entities                            | #
# +-----------------------------------------------------------------+ #
#######################################################################


#######################################################################
# +-----------------------------------------------------------------+ #
# |                            Particles                            | #
# +-----------------------------------------------------------------+ #
#######################################################################


#######################################################################
# +-----------------------------------------------------------------+ #
# |                             Spawners                            | #
# +-----------------------------------------------------------------+ #
#######################################################################


#######################################################################
# +-----------------------------------------------------------------+ #
# |                             ModData                             | #
# +-----------------------------------------------------------------+ #
#######################################################################

