
#######################################################################
# +-----------------------------------------------------------------+ #
# |                            BO3 object                           | #
# +-----------------------------------------------------------------+ #
#######################################################################

Author: LordSmellyPants

Description: No description given

Version: 3

SettingsMode: WriteWithoutComments


#######################################################################
# +-----------------------------------------------------------------+ #
# |                          Main settings                          | #
# +-----------------------------------------------------------------+ #
#######################################################################

Tree: true

Frequency: 1

Rarity: 100.0

RotateRandomly: true

SpawnHeight: highestSolidBlock

SpawnHeightOffset: 0

SpawnHeightVariance: 0

##############################
# Height Limits for the BO3. #
##############################

MinHeight: 63

MaxHeight: 70

######################
# Extrusion settings #
######################

ExtrudeMode: None

ExtrudeThroughBlocks: AIR

MaxBranchDepth: 10

ExcludedBiomes: All


#######################################################################
# +-----------------------------------------------------------------+ #
# |                      Source block settings                      | #
# +-----------------------------------------------------------------+ #
#######################################################################

SourceBlocks: AIR

MaxPercentageOutsideSourceBlock: 0

OutsideSourceBlock: placeAnyway

DoReplaceBlocks: true

IsOTGPlus: false


#######################################################################
# +-----------------------------------------------------------------+ #
# |                              Blocks                             | #
# +-----------------------------------------------------------------+ #
#######################################################################

Block(-9,10,-2,LOG:13)
Block(-8,10,-2,LOG:13)
Block(-7,11,-2,LOG:13)
Block(-6,11,-1,LOG:13)
Block(-5,-4,0,LOG:1)
Block(-5,-3,0,LOG:13)
Block(-5,-2,0,LOG:13)
Block(-5,-1,0,LOG:1)
Block(-5,12,0,LOG:13)
Block(-5,24,0,LOG:13)
Block(-4,-4,-3,LOG:1)
Block(-4,-4,-2,LOG:1)
Block(-4,-4,-1,LOG:1)
Block(-4,-4,0,LOG:1)
Block(-4,-4,2,LOG:1)
Block(-4,-3,-3,LOG:13)
Block(-4,-3,-1,LOG:13)
Block(-4,-3,0,LOG:1)
Block(-4,-3,2,LOG:13)
Block(-4,-2,-3,LOG:13)
Block(-4,-2,-1,LOG:13)
Block(-4,-2,2,LOG:13)
Block(-4,-1,-1,LOG:13)
Block(-4,0,-1,LOG:1)
Block(-4,12,0,LOG:13)
Block(-4,24,-5,LOG:13)
Block(-4,25,0,LOG:13)
Block(-3,-4,-2,LOG:1)
Block(-3,-4,1,LOG:1)
Block(-3,-4,2,LOG:1)
Block(-3,-3,-2,LOG:13)
Block(-3,-3,1,LOG:13)
Block(-3,-3,2,LOG:13)
Block(-3,-2,-2,LOG:13)
Block(-3,-2,-1,LOG:13)
Block(-3,-2,0,LOG:9)
Block(-3,-2,1,LOG:13)
Block(-3,-2,2,LOG:13)
Block(-3,-1,-2,LOG:13)
Block(-3,-1,-1,LOG:13)
Block(-3,-1,1,LOG:13)
Block(-3,-1,2,LOG:13)
Block(-3,0,-1,LOG:13)
Block(-3,0,1,LOG:13)
Block(-3,1,-1,LOG:13)
Block(-3,1,1,LOG:1)
Block(-3,2,-1,LOG:1)
Block(-3,13,0,LOG:13)
Block(-3,21,4,LOG:13)
Block(-3,25,-4,LOG:13)
Block(-3,25,-1,LOG:13)
Block(-3,29,1,LOG:13)
Block(-3,31,-3,LOG:13)
Block(-2,-4,-2,LOG:1)
Block(-2,-4,1,LOG:1)
Block(-2,-3,-2,LOG:13)
Block(-2,-3,0,LOG:13)
Block(-2,-3,1,LOG:13)
Block(-2,-2,-2,LOG:13)
Block(-2,-2,-1,LOG:13)
Block(-2,-2,0,LOG:13)
Block(-2,-2,1,LOG:13)
Block(-2,-1,-2,LOG:13)
Block(-2,-1,-1,LOG:13)
Block(-2,-1,0,LOG:13)
Block(-2,-1,1,LOG:1)
Block(-2,0,-2,LOG:13)
Block(-2,0,-1,LOG:13)
Block(-2,0,0,LOG:13)
Block(-2,1,-2,LOG:1)
Block(-2,1,-1,LOG:13)
Block(-2,1,0,LOG:13)
Block(-2,2,-1,LOG:13)
Block(-2,2,0,LOG:13)
Block(-2,3,-1,LOG:13)
Block(-2,3,0,LOG:13)
Block(-2,4,-1,LOG:13)
Block(-2,4,0,LOG:13)
Block(-2,5,-1,LOG:13)
Block(-2,5,0,LOG:13)
Block(-2,6,-1,LOG:13)
Block(-2,7,-1,LOG:13)
Block(-2,8,-1,LOG:13)
Block(-2,13,0,LOG:13)
Block(-2,14,0,LOG:1)
Block(-2,22,3,LOG:13)
Block(-2,25,-3,LOG:13)
Block(-2,26,-2,LOG:13)
Block(-2,26,-1,LOG:13)
Block(-2,30,0,LOG:13)
Block(-2,32,-2,LOG:13)
Block(-2,36,0,LOG:13)
Block(-1,-4,-3,LOG:1)
Block(-1,-4,-2,LOG:1)
Block(-1,-4,2,LOG:1)
Block(-1,-4,3,LOG:9)
Block(-1,-3,-3,LOG:13)
Block(-1,-3,-2,LOG:13)
Block(-1,-3,1,LOG:13)
Block(-1,-3,2,LOG:13)
Block(-1,-3,3,LOG:1)
Block(-1,-2,-3,LOG:13)
Block(-1,-2,-2,LOG:13)
Block(-1,-2,-1,LOG:13)
Block(-1,-2,1,LOG:13)
Block(-1,-1,-3,LOG:13)
Block(-1,-1,-2,LOG:13)
Block(-1,-1,-1,LOG:13)
Block(-1,-1,1,LOG:13)
Block(-1,0,-3,LOG:13)
Block(-1,0,-2,LOG:13)
Block(-1,0,-1,LOG:13)
Block(-1,0,0,LOG:13)
Block(-1,0,1,LOG:13)
Block(-1,1,-3,LOG:1)
Block(-1,1,-2,LOG:13)
Block(-1,1,-1,LOG:13)
Block(-1,1,0,LOG:13)
Block(-1,1,1,LOG:13)
Block(-1,2,-2,LOG:13)
Block(-1,2,-1,LOG:13)
Block(-1,2,0,LOG:13)
Block(-1,2,1,LOG:13)
Block(-1,3,-2,LOG:13)
Block(-1,3,-1,LOG:13)
Block(-1,3,0,LOG:13)
Block(-1,3,1,LOG:13)
Block(-1,4,-2,LOG:13)
Block(-1,4,-1,LOG:13)
Block(-1,4,0,LOG:13)
Block(-1,5,-2,LOG:13)
Block(-1,5,-1,LOG:13)
Block(-1,5,0,LOG:13)
Block(-1,6,-2,LOG:13)
Block(-1,6,-1,LOG:13)
Block(-1,6,0,LOG:13)
Block(-1,7,-2,LOG:13)
Block(-1,7,-1,LOG:13)
Block(-1,7,0,LOG:13)
Block(-1,8,-2,LOG:13)
Block(-1,8,-1,LOG:13)
Block(-1,8,0,LOG:13)
Block(-1,9,-2,LOG:13)
Block(-1,9,-1,LOG:13)
Block(-1,9,0,LOG:13)
Block(-1,10,-2,LOG:13)
Block(-1,10,-1,LOG:13)
Block(-1,10,0,LOG:13)
Block(-1,11,-2,LOG:13)
Block(-1,11,-1,LOG:13)
Block(-1,11,0,LOG:13)
Block(-1,12,-2,LOG:13)
Block(-1,12,-1,LOG:13)
Block(-1,12,0,LOG:13)
Block(-1,13,-2,LOG:13)
Block(-1,13,-1,LOG:13)
Block(-1,13,0,LOG:13)
Block(-1,14,-2,LOG:13)
Block(-1,14,-1,LOG:13)
Block(-1,14,0,LOG:13)
Block(-1,15,-5,LOG:13)
Block(-1,15,-4,LOG:13)
Block(-1,15,-1,LOG:13)
Block(-1,15,0,LOG:13)
Block(-1,16,-3,LOG:13)
Block(-1,16,-2,LOG:13)
Block(-1,16,-1,LOG:13)
Block(-1,16,0,LOG:13)
Block(-1,17,-1,LOG:13)
Block(-1,17,0,LOG:13)
Block(-1,18,-1,LOG:13)
Block(-1,18,0,LOG:13)
Block(-1,19,-1,LOG:13)
Block(-1,19,0,LOG:13)
Block(-1,20,-1,LOG:13)
Block(-1,20,0,LOG:13)
Block(-1,21,-1,LOG:13)
Block(-1,21,0,LOG:13)
Block(-1,22,-1,LOG:13)
Block(-1,22,0,LOG:13)
Block(-1,22,2,LOG:13)
Block(-1,23,-1,LOG:13)
Block(-1,23,0,LOG:13)
Block(-1,23,1,LOG:13)
Block(-1,24,-1,LOG:13)
Block(-1,25,-1,LOG:13)
Block(-1,26,-1,LOG:13)
Block(-1,27,-1,LOG:13)
Block(-1,28,-1,LOG:1)
Block(-1,30,-1,LOG:13)
Block(-1,32,-1,LOG:13)
Block(-1,37,-3,LOG:13)
Block(-1,37,-1,LOG:13)
Block(0,-4,-5,LOG:1)
Block(0,-4,-4,LOG:1)
Block(0,-4,-3,LOG:5)
Block(0,-4,-2,LOG:5)
Block(0,-4,2,LOG:1)
Block(0,-3,-5,LOG:13)
Block(0,-3,-4,LOG:13)
Block(0,-3,-3,LOG:1)
Block(0,-3,-2,LOG:13)
Block(0,-3,2,LOG:13)
Block(0,-2,-4,LOG:13)
Block(0,-2,-2,LOG:13)
Block(0,-2,1,LOG:13)
Block(0,-2,2,LOG:13)
Block(0,-1,-2,LOG:13)
Block(0,-1,1,LOG:13)
Block(0,-1,2,LOG:13)
Block(0,0,-2,LOG:13)
Block(0,0,-1,LOG:13)
Block(0,0,0,LOG:13)
Block(0,0,1,LOG:13)
Block(0,0,2,LOG:13)
Block(0,1,-2,LOG:13)
Block(0,1,-1,LOG:13)
Block(0,1,0,LOG:13)
Block(0,1,1,LOG:13)
Block(0,1,2,LOG:1)
Block(0,2,-2,LOG:1)
Block(0,2,-1,LOG:13)
Block(0,2,0,LOG:13)
Block(0,2,1,LOG:13)
Block(0,3,-1,LOG:13)
Block(0,3,0,LOG:13)
Block(0,3,1,LOG:13)
Block(0,4,-1,LOG:13)
Block(0,4,0,LOG:13)
Block(0,4,1,LOG:13)
Block(0,5,-1,LOG:13)
Block(0,5,0,LOG:13)
Block(0,5,1,LOG:13)
Block(0,6,-1,LOG:13)
Block(0,6,0,LOG:13)
Block(0,6,1,LOG:13)
Block(0,7,-1,LOG:13)
Block(0,7,0,LOG:13)
Block(0,7,1,LOG:13)
Block(0,8,-1,LOG:13)
Block(0,8,0,LOG:13)
Block(0,8,1,LOG:13)
Block(0,9,-1,LOG:13)
Block(0,9,0,LOG:13)
Block(0,9,1,LOG:13)
Block(0,10,-1,LOG:13)
Block(0,10,0,LOG:13)
Block(0,10,1,LOG:1)
Block(0,11,-1,LOG:13)
Block(0,11,0,LOG:13)
Block(0,12,-1,LOG:13)
Block(0,12,0,LOG:13)
Block(0,13,-1,LOG:13)
Block(0,13,0,LOG:13)
Block(0,14,-6,LOG:13)
Block(0,14,-1,LOG:13)
Block(0,14,0,LOG:13)
Block(0,15,-1,LOG:13)
Block(0,15,0,LOG:13)
Block(0,15,1,LOG:13)
Block(0,15,2,LOG:13)
Block(0,15,3,LOG:13)
Block(0,16,-1,LOG:13)
Block(0,16,0,LOG:13)
Block(0,17,-1,LOG:13)
Block(0,18,-1,LOG:13)
Block(0,19,-1,LOG:13)
Block(0,20,-1,LOG:13)
Block(0,20,6,LOG:13)
Block(0,21,-1,LOG:13)
Block(0,21,5,LOG:13)
Block(0,22,-1,LOG:13)
Block(0,22,3,LOG:13)
Block(0,22,4,LOG:13)
Block(0,23,-1,LOG:13)
Block(0,24,-1,LOG:13)
Block(0,25,-1,LOG:13)
Block(0,26,-1,LOG:13)
Block(0,27,-1,LOG:13)
Block(0,28,-1,LOG:13)
Block(0,29,-1,LOG:13)
Block(0,30,-1,LOG:13)
Block(0,31,-1,LOG:13)
Block(0,32,-4,LOG:13)
Block(0,32,-1,LOG:13)
Block(0,33,-3,LOG:13)
Block(0,33,-1,LOG:13)
Block(0,33,0,LOG:13)
Block(0,34,-2,LOG:13)
Block(0,34,-1,LOG:13)
Block(0,35,-1,LOG:13)
Block(0,36,-1,LOG:13)
Block(0,37,-1,LOG:13)
Block(0,38,-2,LOG:13)
Block(0,38,-1,LOG:13)
Block(0,39,-1,LOG:13)
Block(0,40,-1,LOG:13)
Block(0,40,0,LOG:13)
Block(0,41,-1,LOG:13)
Block(0,42,-1,LOG:13)
Block(0,43,-1,LOG:13)
Block(0,44,-1,LOG:13)
Block(0,45,-1,LOG:13)
Block(0,46,-1,LOG:13)
Block(0,47,-1,LOG:1)
Block(1,-4,-2,LOG:1)
Block(1,-4,0,LOG:1)
Block(1,-4,1,LOG:1)
Block(1,-4,2,LOG:1)
Block(1,-4,3,LOG:1)
Block(1,-3,-2,LOG:13)
Block(1,-3,-1,LOG:13)
Block(1,-3,0,LOG:13)
Block(1,-3,1,LOG:13)
Block(1,-3,2,LOG:13)
Block(1,-3,3,LOG:13)
Block(1,-2,-2,LOG:13)
Block(1,-2,-1,LOG:13)
Block(1,-2,0,LOG:13)
Block(1,-2,1,LOG:13)
Block(1,-2,2,LOG:13)
Block(1,-2,3,LOG:13)
Block(1,-1,-2,LOG:1)
Block(1,-1,-1,LOG:13)
Block(1,-1,0,LOG:13)
Block(1,-1,1,LOG:13)
Block(1,-1,2,LOG:13)
Block(1,0,-1,LOG:13)
Block(1,0,0,LOG:13)
Block(1,0,1,LOG:13)
Block(1,1,-1,LOG:13)
Block(1,1,0,LOG:13)
Block(1,1,1,LOG:13)
Block(1,2,-1,LOG:13)
Block(1,2,0,LOG:13)
Block(1,2,1,LOG:13)
Block(1,3,-1,LOG:13)
Block(1,3,0,LOG:13)
Block(1,4,-1,LOG:13)
Block(1,4,0,LOG:13)
Block(1,5,-1,LOG:13)
Block(1,5,0,LOG:13)
Block(1,6,-1,LOG:13)
Block(1,6,0,LOG:13)
Block(1,7,-1,LOG:13)
Block(1,8,-1,LOG:13)
Block(1,9,-1,LOG:13)
Block(1,10,-1,LOG:13)
Block(1,11,-1,LOG:1)
Block(1,12,8,LOG:13)
Block(1,13,-9,LOG:13)
Block(1,13,-8,LOG:13)
Block(1,13,6,LOG:13)
Block(1,13,7,LOG:13)
Block(1,14,-7,LOG:13)
Block(1,14,4,LOG:13)
Block(1,14,5,LOG:13)
Block(1,19,-1,LOG:13)
Block(1,27,-1,LOG:13)
Block(1,31,-1,LOG:13)
Block(1,31,3,LOG:13)
Block(1,32,1,LOG:13)
Block(1,32,2,LOG:13)
Block(1,36,-1,LOG:13)
Block(1,43,-1,LOG:13)
Block(2,-4,-2,LOG:1)
Block(2,-4,-1,LOG:1)
Block(2,-4,0,LOG:1)
Block(2,-4,1,LOG:1)
Block(2,-4,2,LOG:1)
Block(2,-4,3,LOG:1)
Block(2,-3,-1,LOG:13)
Block(2,-3,0,LOG:1)
Block(2,-3,2,LOG:13)
Block(2,-3,3,LOG:1)
Block(2,-2,-1,LOG:13)
Block(2,-2,0,LOG:1)
Block(2,-2,2,LOG:13)
Block(2,-1,-1,LOG:13)
Block(2,-1,2,LOG:1)
Block(2,0,-1,LOG:13)
Block(2,1,-1,LOG:1)
Block(2,19,-1,LOG:13)
Block(2,26,-2,LOG:13)
Block(2,30,0,LOG:13)
Block(2,35,-1,LOG:13)
Block(3,-4,-2,LOG:1)
Block(3,-4,2,LOG:5)
Block(3,-3,-2,LOG:13)
Block(3,-2,-2,LOG:13)
Block(3,18,-1,LOG:13)
Block(3,26,-2,LOG:13)
Block(3,30,0,LOG:13)
Block(4,17,-2,LOG:13)
Block(4,18,0,LOG:13)
Block(4,25,-3,LOG:13)
Block(5,17,-3,LOG:13)
Block(5,17,1,LOG:13)
Block(5,24,-4,LOG:13)

#######################################################################
# +-----------------------------------------------------------------+ #
# |                            BO3 checks                           | #
# +-----------------------------------------------------------------+ #
#######################################################################

BlockCheck(0,-1,0,GRASS,DIRT,biomesoplenty:grass:0,biomesoplenty:grass:1,biomesoplenty:grass,biomesoplenty:grass:3,biomesoplenty:grass:4,biomesoplenty:grass:5,biomesoplenty:grass:6,biomesoplenty:grass:7,UNKNOWN_BLOCK:0,UNKNOWN_BLOCK:1,UNKNOWN_BLOCK:2,UNKNOWN_BLOCK:8,UNKNOWN_BLOCK:9,UNKNOWN_BLOCK:10,biomesoplenty:dried_sand,biomesoplenty:hard_ice,biomesoplenty:white_sand,biomesoplenty:white_sandstone,biomesoplenty:mud,biomesoplenty:ash_block)

#######################################################################
# +-----------------------------------------------------------------+ #
# |                             Branches                            | #
# +-----------------------------------------------------------------+ #
#######################################################################


#######################################################################
# +-----------------------------------------------------------------+ #
# |                             Entities                            | #
# +-----------------------------------------------------------------+ #
#######################################################################


#######################################################################
# +-----------------------------------------------------------------+ #
# |                            Particles                            | #
# +-----------------------------------------------------------------+ #
#######################################################################


#######################################################################
# +-----------------------------------------------------------------+ #
# |                             Spawners                            | #
# +-----------------------------------------------------------------+ #
#######################################################################


#######################################################################
# +-----------------------------------------------------------------+ #
# |                             ModData                             | #
# +-----------------------------------------------------------------+ #
#######################################################################

