
#######################################################################
# +-----------------------------------------------------------------+ #
# |                            BO3 object                           | #
# +-----------------------------------------------------------------+ #
#######################################################################

Author: MC_Pitman

Description: No description given

Version: 3

SettingsMode: WriteWithoutComments


#######################################################################
# +-----------------------------------------------------------------+ #
# |                          Main settings                          | #
# +-----------------------------------------------------------------+ #
#######################################################################

Tree: true

Frequency: 1

Rarity: 100.0

RotateRandomly: true

SpawnHeight: highestSolidBlock

SpawnHeightOffset: 0

SpawnHeightVariance: 0

##############################
# Height Limits for the BO3. #
##############################

MinHeight: 63

MaxHeight: 130

######################
# Extrusion settings #
######################

ExtrudeMode: None

ExtrudeThroughBlocks: AIR

MaxBranchDepth: 10

ExcludedBiomes: All


#######################################################################
# +-----------------------------------------------------------------+ #
# |                      Source block settings                      | #
# +-----------------------------------------------------------------+ #
#######################################################################

SourceBlocks: STONE:1,STONE:3,STONE:5,DIRT:1,DIRT,SAND,GRASS,DIRT:2,STATIONARY_WATER,HARD_CLAY,STAINED_CLAY,CLAY,SANDSTONE,SAND:1,AIR,STONE,GRAVEL,LONG_GRASS,LONG_GRASS:1,LONG_GRASS:2,DEAD_BUSH,YELLOW_FLOWER,RED_ROSE,BROWN_MUSHROOM,RED_MUSHROOM,biomesoplenty:plant_0:1,biomesoplenty:plant_0:2,biomesoplenty:plant_0:3,biomesoplenty:plant_0:4,biomesoplenty:plant_0:5,biomesoplenty:plant_0:6,biomesoplenty:plant_0:7,biomesoplenty:plant_0:8,biomesoplenty:plant_0:9,biomesoplenty:plant_0:10,biomesoplenty:plant_0:11,biomesoplenty:plant_0:12,biomesoplenty:plant_0:13,biomesoplenty:plant_0:14,biomesoplenty:flower_0:1,biomesoplenty:flower_0:2,biomesoplenty:flower_0:3,biomesoplenty:flower_0:4,biomesoplenty:flower_0:5,biomesoplenty:flower_0:6,biomesoplenty:flower_0:7,biomesoplenty:flower_0:8,biomesoplenty:flower_0:9,biomesoplenty:flower_0:10,biomesoplenty:flower_0:11,biomesoplenty:flower_0:12,biomesoplenty:flower_0:13,biomesoplenty:flower_0:14,biomesoplenty:plant_1,biomesoplenty:grass:0,biomesoplenty:grass:1,biomesoplenty:grass,biomesoplenty:grass:3,biomesoplenty:grass:4,biomesoplenty:grass:5,biomesoplenty:grass:6,biomesoplenty:grass:7,UNKNOWN_BLOCK:0,UNKNOWN_BLOCK:1,UNKNOWN_BLOCK:2,UNKNOWN_BLOCK:8,UNKNOWN_BLOCK:9,UNKNOWN_BLOCK:10,biomesoplenty:dried_sand,biomesoplenty:hard_ice,biomesoplenty:white_sand,biomesoplenty:white_sandstone,biomesoplenty:mud,biomesoplenty:ash_block

MaxPercentageOutsideSourceBlock: 0

OutsideSourceBlock: placeAnyway

DoReplaceBlocks: true

IsOTGPlus: false


#######################################################################
# +-----------------------------------------------------------------+ #
# |                              Blocks                             | #
# +-----------------------------------------------------------------+ #
#######################################################################

Block(-5,5,-1,LEAVES:13)
Block(-5,5,0,LEAVES:13)
Block(-5,6,-1,LEAVES:13)
Block(-4,5,-2,LEAVES:13)
Block(-4,5,-1,LEAVES:13)
Block(-4,5,0,LEAVES:13)
Block(-4,5,1,LEAVES:13)
Block(-4,5,2,LEAVES:13)
Block(-4,6,0,LEAVES:13)
Block(-4,7,-2,LEAVES:13)
Block(-4,7,-1,LEAVES:13)
Block(-4,7,1,LEAVES:13)
Block(-4,8,-3,LEAVES:13)
Block(-4,8,-2,LEAVES:13)
Block(-4,14,0,LEAVES:13)
Block(-3,4,0,LEAVES:13)
Block(-3,5,-3,LEAVES:13)
Block(-3,5,-2,LEAVES:13)
Block(-3,5,-1,LEAVES:13)
Block(-3,5,0,LEAVES:13)
Block(-3,5,1,LEAVES:13)
Block(-3,5,3,LEAVES:13)
Block(-3,6,-4,LEAVES:13)
Block(-3,6,-3,LEAVES:13)
Block(-3,6,-2,LEAVES:13)
Block(-3,6,-1,LEAVES:13)
Block(-3,6,0,LEAVES:13)
Block(-3,6,1,LEAVES:13)
Block(-3,6,4,LEAVES:13)
Block(-3,7,-3,LEAVES:13)
Block(-3,7,-2,LEAVES:13)
Block(-3,7,-1,LEAVES:13)
Block(-3,7,0,LEAVES:13)
Block(-3,7,1,LEAVES:13)
Block(-3,7,2,LEAVES:13)
Block(-3,8,-3,LEAVES:13)
Block(-3,8,-2,LEAVES:13)
Block(-3,8,-1,LEAVES:13)
Block(-3,8,0,LEAVES:13)
Block(-3,8,1,LEAVES:13)
Block(-3,9,-2,LEAVES:13)
Block(-3,9,0,LEAVES:13)
Block(-3,9,2,LEAVES:13)
Block(-3,10,-1,LEAVES:13)
Block(-3,10,0,LEAVES:13)
Block(-3,10,1,LEAVES:13)
Block(-3,11,-2,LEAVES:13)
Block(-3,12,-1,LEAVES:13)
Block(-3,12,1,LEAVES:13)
Block(-3,15,0,LEAVES:13)
Block(-3,15,1,LEAVES:13)
Block(-3,16,0,LEAVES:13)
Block(-3,18,0,LEAVES:13)
Block(-2,3,0,LEAVES:13)
Block(-2,4,1,LEAVES:13)
Block(-2,4,3,LEAVES:13)
Block(-2,5,-4,LEAVES:13)
Block(-2,5,-3,LEAVES:13)
Block(-2,5,-2,LEAVES:13)
Block(-2,5,0,LEAVES:13)
Block(-2,5,1,LEAVES:13)
Block(-2,5,2,LEAVES:13)
Block(-2,5,3,LEAVES:13)
Block(-2,5,4,LEAVES:13)
Block(-2,6,-4,LEAVES:13)
Block(-2,6,-3,LEAVES:13)
Block(-2,6,-2,LEAVES:13)
Block(-2,6,-1,LOG:13)
Block(-2,6,0,LEAVES:13)
Block(-2,6,1,LEAVES:13)
Block(-2,6,2,LEAVES:13)
Block(-2,6,4,LEAVES:13)
Block(-2,7,-4,LEAVES:13)
Block(-2,7,-3,LEAVES:13)
Block(-2,7,-2,LEAVES:13)
Block(-2,7,-1,LEAVES:13)
Block(-2,7,0,LOG:13)
Block(-2,7,1,LEAVES:13)
Block(-2,7,2,LEAVES:13)
Block(-2,8,-4,LEAVES:13)
Block(-2,8,-3,LEAVES:13)
Block(-2,8,-2,LEAVES:13)
Block(-2,8,-1,LEAVES:13)
Block(-2,8,0,LEAVES:13)
Block(-2,8,1,LEAVES:13)
Block(-2,8,3,LEAVES:13)
Block(-2,9,-3,LEAVES:13)
Block(-2,9,-1,LEAVES:13)
Block(-2,9,0,LEAVES:13)
Block(-2,9,1,LEAVES:13)
Block(-2,9,2,LEAVES:13)
Block(-2,9,3,LEAVES:13)
Block(-2,10,-2,LEAVES:13)
Block(-2,10,-1,LEAVES:13)
Block(-2,10,0,LEAVES:13)
Block(-2,10,1,LEAVES:13)
Block(-2,10,2,LEAVES:13)
Block(-2,11,-1,LEAVES:13)
Block(-2,11,0,LEAVES:13)
Block(-2,11,1,LEAVES:13)
Block(-2,12,-2,LEAVES:13)
Block(-2,12,0,LEAVES:13)
Block(-2,12,1,LEAVES:13)
Block(-2,12,2,LEAVES:13)
Block(-2,13,-1,LEAVES:13)
Block(-2,13,0,LEAVES:13)
Block(-2,13,1,LEAVES:13)
Block(-2,14,0,LEAVES:13)
Block(-2,14,1,LEAVES:13)
Block(-2,14,3,LEAVES:13)
Block(-2,15,-2,LEAVES:13)
Block(-2,15,-1,LEAVES:13)
Block(-2,15,0,LEAVES:13)
Block(-2,15,2,LEAVES:13)
Block(-2,16,-1,LEAVES:13)
Block(-2,16,0,LEAVES:13)
Block(-2,16,1,LEAVES:13)
Block(-2,17,0,LEAVES:13)
Block(-2,17,1,LEAVES:13)
Block(-2,17,2,LEAVES:13)
Block(-2,18,-2,LEAVES:13)
Block(-2,18,-1,LEAVES:13)
Block(-2,19,1,LEAVES:13)
Block(-2,20,0,LEAVES:13)
Block(-2,22,-1,LEAVES:13)
Block(-2,23,0,LEAVES:13)
Block(-1,3,-1,LEAVES:13)
Block(-1,3,0,LEAVES:13)
Block(-1,3,1,LEAVES:13)
Block(-1,4,-4,LEAVES:13)
Block(-1,4,-2,LEAVES:13)
Block(-1,4,-1,LEAVES:13)
Block(-1,4,0,LEAVES:13)
Block(-1,4,1,LEAVES:13)
Block(-1,4,2,LEAVES:13)
Block(-1,5,-5,LEAVES:13)
Block(-1,5,-4,LEAVES:13)
Block(-1,5,-3,LEAVES:13)
Block(-1,5,-2,LEAVES:13)
Block(-1,5,-1,LEAVES:13)
Block(-1,5,0,LEAVES:13)
Block(-1,5,1,LEAVES:13)
Block(-1,5,2,LEAVES:13)
Block(-1,5,3,LEAVES:13)
Block(-1,5,4,LEAVES:13)
Block(-1,5,5,LEAVES:13)
Block(-1,6,-5,LEAVES:13)
Block(-1,6,-4,LEAVES:13)
Block(-1,6,-3,LEAVES:13)
Block(-1,6,-1,LEAVES:13)
Block(-1,6,0,LEAVES:13)
Block(-1,6,1,LEAVES:13)
Block(-1,6,2,LEAVES:13)
Block(-1,6,3,LEAVES:13)
Block(-1,6,4,LEAVES:13)
Block(-1,7,-3,LEAVES:13)
Block(-1,7,-2,LEAVES:13)
Block(-1,7,-1,LEAVES:13)
Block(-1,7,0,LEAVES:13)
Block(-1,7,1,LEAVES:13)
Block(-1,7,2,LEAVES:13)
Block(-1,7,3,LEAVES:13)
Block(-1,7,4,LEAVES:13)
Block(-1,8,-5,LEAVES:13)
Block(-1,8,-4,LEAVES:13)
Block(-1,8,-3,LEAVES:13)
Block(-1,8,-2,LEAVES:13)
Block(-1,8,-1,LEAVES:13)
Block(-1,8,0,LOG:13)
Block(-1,8,1,LEAVES:13)
Block(-1,8,2,LEAVES:13)
Block(-1,8,3,LEAVES:13)
Block(-1,9,-4,LEAVES:13)
Block(-1,9,-1,LEAVES:13)
Block(-1,9,0,LEAVES:13)
Block(-1,9,1,LEAVES:13)
Block(-1,9,2,LEAVES:13)
Block(-1,10,-3,LEAVES:13)
Block(-1,10,-2,LEAVES:13)
Block(-1,10,-1,LEAVES:13)
Block(-1,10,0,LEAVES:13)
Block(-1,10,1,LEAVES:13)
Block(-1,10,2,LEAVES:13)
Block(-1,10,3,LEAVES:13)
Block(-1,11,-2,LEAVES:13)
Block(-1,11,-1,LEAVES:13)
Block(-1,11,0,LEAVES:13)
Block(-1,11,1,LEAVES:13)
Block(-1,11,2,LEAVES:13)
Block(-1,12,-3,LEAVES:13)
Block(-1,12,-2,LEAVES:13)
Block(-1,12,-1,LEAVES:13)
Block(-1,12,0,LEAVES:13)
Block(-1,12,1,LEAVES:13)
Block(-1,12,2,LEAVES:13)
Block(-1,13,-2,LEAVES:13)
Block(-1,13,-1,LEAVES:13)
Block(-1,13,0,LOG:13)
Block(-1,13,1,LEAVES:13)
Block(-1,13,2,LEAVES:13)
Block(-1,14,-1,LEAVES:13)
Block(-1,14,0,LEAVES:13)
Block(-1,14,1,LEAVES:13)
Block(-1,14,2,LEAVES:13)
Block(-1,15,-1,LEAVES:13)
Block(-1,15,0,LEAVES:13)
Block(-1,15,1,LEAVES:13)
Block(-1,15,2,LEAVES:13)
Block(-1,15,3,LEAVES:13)
Block(-1,16,-2,LEAVES:13)
Block(-1,16,-1,LEAVES:13)
Block(-1,16,0,LEAVES:13)
Block(-1,16,1,LEAVES:13)
Block(-1,16,2,LEAVES:13)
Block(-1,17,-3,LEAVES:13)
Block(-1,17,-2,LEAVES:13)
Block(-1,17,-1,LEAVES:13)
Block(-1,17,0,LOG:13)
Block(-1,17,1,LEAVES:13)
Block(-1,18,-3,LEAVES:13)
Block(-1,18,-2,LOG:13)
Block(-1,18,-1,LEAVES:13)
Block(-1,18,0,LEAVES:13)
Block(-1,18,1,LEAVES:13)
Block(-1,19,-2,LEAVES:13)
Block(-1,19,-1,LEAVES:13)
Block(-1,19,0,LEAVES:13)
Block(-1,19,1,LEAVES:13)
Block(-1,19,2,LEAVES:13)
Block(-1,20,-1,LEAVES:13)
Block(-1,20,0,LEAVES:13)
Block(-1,20,1,LEAVES:13)
Block(-1,21,-1,LEAVES:13)
Block(-1,21,0,LEAVES:13)
Block(-1,21,1,LEAVES:13)
Block(-1,21,2,LEAVES:13)
Block(-1,22,-1,LEAVES:13)
Block(-1,22,0,LEAVES:13)
Block(-1,22,1,LEAVES:13)
Block(-1,23,-1,LEAVES:13)
Block(-1,23,0,LEAVES:13)
Block(-1,23,1,LEAVES:13)
Block(-1,24,0,LEAVES:13)
Block(-1,25,1,LEAVES:13)
Block(-1,26,0,LEAVES:13)
Block(0,0,0,LOG:13)
Block(0,1,0,LOG:13)
Block(0,2,0,LOG:13)
Block(0,3,-2,LEAVES:13)
Block(0,3,-1,LEAVES:13)
Block(0,3,0,LOG:13)
Block(0,3,1,LEAVES:13)
Block(0,3,2,LEAVES:13)
Block(0,4,-3,LEAVES:13)
Block(0,4,-2,LOG:13)
Block(0,4,-1,LEAVES:13)
Block(0,4,0,LOG:13)
Block(0,4,1,LEAVES:13)
Block(0,4,3,LEAVES:13)
Block(0,5,-4,LEAVES:13)
Block(0,5,-3,LEAVES:13)
Block(0,5,-1,LOG:13)
Block(0,5,0,LOG:13)
Block(0,5,1,LEAVES:13)
Block(0,5,2,LEAVES:13)
Block(0,5,4,LEAVES:13)
Block(0,6,-4,LEAVES:13)
Block(0,6,-3,LEAVES:13)
Block(0,6,-1,LEAVES:13)
Block(0,6,0,LOG:13)
Block(0,6,1,LEAVES:13)
Block(0,6,2,LEAVES:13)
Block(0,6,3,LEAVES:13)
Block(0,6,4,LEAVES:13)
Block(0,7,-4,LEAVES:13)
Block(0,7,-3,LEAVES:13)
Block(0,7,-2,LEAVES:13)
Block(0,7,-1,LEAVES:13)
Block(0,7,0,LOG:13)
Block(0,7,1,LEAVES:13)
Block(0,7,2,LEAVES:13)
Block(0,7,3,LEAVES:13)
Block(0,7,4,LEAVES:13)
Block(0,8,-4,LEAVES:13)
Block(0,8,-3,LEAVES:13)
Block(0,8,-2,LEAVES:13)
Block(0,8,-1,LEAVES:13)
Block(0,8,0,LOG:13)
Block(0,8,1,LEAVES:13)
Block(0,8,2,LEAVES:13)
Block(0,8,3,LEAVES:13)
Block(0,8,4,LEAVES:13)
Block(0,9,-3,LEAVES:13)
Block(0,9,-1,LEAVES:13)
Block(0,9,0,LOG:13)
Block(0,9,1,LEAVES:13)
Block(0,9,2,LEAVES:13)
Block(0,9,3,LEAVES:13)
Block(0,10,-4,LEAVES:13)
Block(0,10,-3,LEAVES:13)
Block(0,10,-2,LEAVES:13)
Block(0,10,-1,LEAVES:13)
Block(0,10,0,LOG:13)
Block(0,10,1,LEAVES:13)
Block(0,10,2,LOG:13)
Block(0,10,3,LEAVES:13)
Block(0,10,4,LEAVES:13)
Block(0,11,-3,LEAVES:13)
Block(0,11,-2,LEAVES:13)
Block(0,11,-1,LEAVES:13)
Block(0,11,0,LOG:13)
Block(0,11,1,LOG:13)
Block(0,11,2,LEAVES:13)
Block(0,12,-3,LEAVES:13)
Block(0,12,-2,LEAVES:13)
Block(0,12,-1,LEAVES:13)
Block(0,12,0,LOG:13)
Block(0,12,1,LEAVES:13)
Block(0,12,2,LEAVES:13)
Block(0,12,3,LEAVES:13)
Block(0,13,-4,LEAVES:13)
Block(0,13,-3,LEAVES:13)
Block(0,13,-2,LEAVES:13)
Block(0,13,-1,LEAVES:13)
Block(0,13,0,LOG:13)
Block(0,13,1,LEAVES:13)
Block(0,13,2,LEAVES:13)
Block(0,13,3,LEAVES:13)
Block(0,13,4,LEAVES:13)
Block(0,14,-3,LEAVES:13)
Block(0,14,-2,LEAVES:13)
Block(0,14,-1,LEAVES:13)
Block(0,14,0,LOG:13)
Block(0,14,1,LEAVES:13)
Block(0,14,2,LEAVES:13)
Block(0,14,3,LEAVES:13)
Block(0,15,-2,LEAVES:13)
Block(0,15,-1,LEAVES:13)
Block(0,15,0,LOG:13)
Block(0,15,1,LEAVES:13)
Block(0,16,-3,LEAVES:13)
Block(0,16,-2,LEAVES:13)
Block(0,16,-1,LEAVES:13)
Block(0,16,0,LOG:13)
Block(0,16,1,LEAVES:13)
Block(0,16,2,LEAVES:13)
Block(0,16,3,LEAVES:13)
Block(0,17,-2,LEAVES:13)
Block(0,17,-1,LEAVES:13)
Block(0,17,0,LOG:13)
Block(0,17,1,LEAVES:13)
Block(0,18,-1,LEAVES:13)
Block(0,18,0,LOG:13)
Block(0,18,1,LEAVES:13)
Block(0,18,2,LEAVES:13)
Block(0,19,-2,LEAVES:13)
Block(0,19,-1,LOG:13)
Block(0,19,0,LOG:13)
Block(0,19,1,LEAVES:13)
Block(0,19,2,LEAVES:13)
Block(0,19,3,LEAVES:13)
Block(0,20,-2,LEAVES:13)
Block(0,20,-1,LEAVES:13)
Block(0,20,0,LOG:13)
Block(0,20,1,LEAVES:13)
Block(0,20,2,LEAVES:13)
Block(0,21,-1,LEAVES:13)
Block(0,21,0,LOG:13)
Block(0,21,1,LEAVES:13)
Block(0,21,2,LEAVES:13)
Block(0,22,-2,LEAVES:13)
Block(0,22,-1,LEAVES:13)
Block(0,22,0,LOG:13)
Block(0,22,1,LOG:13)
Block(0,23,-1,LEAVES:13)
Block(0,23,0,LOG:13)
Block(0,23,1,LEAVES:13)
Block(0,23,2,LEAVES:13)
Block(0,24,-2,LEAVES:13)
Block(0,24,-1,LEAVES:13)
Block(0,24,0,LOG:13)
Block(0,24,1,LEAVES:13)
Block(0,25,-1,LEAVES:13)
Block(0,25,0,LOG:13)
Block(0,26,-1,LEAVES:13)
Block(0,26,0,LOG:13)
Block(0,26,1,LEAVES:13)
Block(0,27,0,LEAVES:13)
Block(0,28,0,LEAVES:13)
Block(1,3,-1,LEAVES:13)
Block(1,3,0,LEAVES:13)
Block(1,3,1,LEAVES:13)
Block(1,4,-3,LEAVES:13)
Block(1,4,-2,LEAVES:13)
Block(1,4,-1,LEAVES:13)
Block(1,4,0,LEAVES:13)
Block(1,4,1,LEAVES:13)
Block(1,5,-5,LEAVES:13)
Block(1,5,-4,LEAVES:13)
Block(1,5,-3,LEAVES:13)
Block(1,5,-2,LEAVES:13)
Block(1,5,-1,LEAVES:13)
Block(1,5,0,LEAVES:13)
Block(1,5,1,LEAVES:13)
Block(1,5,3,LEAVES:13)
Block(1,5,4,LEAVES:13)
Block(1,5,5,LEAVES:13)
Block(1,6,-3,LEAVES:13)
Block(1,6,-2,LEAVES:13)
Block(1,6,-1,LEAVES:13)
Block(1,6,0,LOG:13)
Block(1,6,1,LEAVES:13)
Block(1,6,2,LEAVES:13)
Block(1,6,3,LEAVES:13)
Block(1,7,-2,LEAVES:13)
Block(1,7,-1,LEAVES:13)
Block(1,7,0,LEAVES:13)
Block(1,7,1,LEAVES:13)
Block(1,7,2,LEAVES:13)
Block(1,7,4,LEAVES:13)
Block(1,8,-3,LEAVES:13)
Block(1,8,-2,LEAVES:13)
Block(1,8,-1,LEAVES:13)
Block(1,8,0,LEAVES:13)
Block(1,8,1,LEAVES:13)
Block(1,8,2,LEAVES:13)
Block(1,8,3,LEAVES:13)
Block(1,9,-2,LEAVES:13)
Block(1,9,-1,LEAVES:13)
Block(1,9,0,LEAVES:13)
Block(1,9,1,LEAVES:13)
Block(1,9,2,LEAVES:13)
Block(1,9,3,LEAVES:13)
Block(1,9,4,LEAVES:13)
Block(1,10,-3,LEAVES:13)
Block(1,10,-2,LEAVES:13)
Block(1,10,-1,LEAVES:13)
Block(1,10,0,LEAVES:13)
Block(1,10,1,LEAVES:13)
Block(1,10,2,LEAVES:13)
Block(1,10,3,LEAVES:13)
Block(1,11,-2,LEAVES:13)
Block(1,11,-1,LEAVES:13)
Block(1,11,0,LEAVES:13)
Block(1,11,1,LEAVES:13)
Block(1,11,2,LEAVES:13)
Block(1,11,3,LEAVES:13)
Block(1,12,-2,LEAVES:13)
Block(1,12,-1,LEAVES:13)
Block(1,12,0,LEAVES:13)
Block(1,12,1,LEAVES:13)
Block(1,12,2,LEAVES:13)
Block(1,12,3,LEAVES:13)
Block(1,13,-2,LEAVES:13)
Block(1,13,-1,LEAVES:13)
Block(1,13,0,LEAVES:13)
Block(1,13,1,LEAVES:13)
Block(1,13,2,LEAVES:13)
Block(1,14,-3,LEAVES:13)
Block(1,14,-2,LEAVES:13)
Block(1,14,-1,LEAVES:13)
Block(1,14,0,LEAVES:13)
Block(1,14,1,LEAVES:13)
Block(1,14,2,LEAVES:13)
Block(1,15,-1,LEAVES:13)
Block(1,15,0,LOG:13)
Block(1,15,1,LEAVES:13)
Block(1,15,2,LEAVES:13)
Block(1,16,-2,LEAVES:13)
Block(1,16,-1,LEAVES:13)
Block(1,16,0,LEAVES:13)
Block(1,16,1,LEAVES:13)
Block(1,16,2,LEAVES:13)
Block(1,17,-1,LEAVES:13)
Block(1,17,0,LEAVES:13)
Block(1,17,1,LEAVES:13)
Block(1,17,3,LEAVES:13)
Block(1,18,-2,LEAVES:13)
Block(1,18,-1,LEAVES:13)
Block(1,18,0,LEAVES:13)
Block(1,18,1,LEAVES:13)
Block(1,19,-2,LEAVES:13)
Block(1,19,-1,LEAVES:13)
Block(1,19,0,LEAVES:13)
Block(1,19,1,LEAVES:13)
Block(1,20,-1,LEAVES:13)
Block(1,20,0,LEAVES:13)
Block(1,20,1,LEAVES:13)
Block(1,20,3,LEAVES:13)
Block(1,21,-1,LEAVES:13)
Block(1,21,0,LEAVES:13)
Block(1,21,1,LEAVES:13)
Block(1,21,2,LEAVES:13)
Block(1,22,-1,LEAVES:13)
Block(1,22,0,LEAVES:13)
Block(1,22,1,LEAVES:13)
Block(1,23,-1,LEAVES:13)
Block(1,23,0,LEAVES:13)
Block(1,23,1,LEAVES:13)
Block(1,24,0,LEAVES:13)
Block(1,25,-1,LEAVES:13)
Block(1,26,0,LEAVES:13)
Block(2,3,0,LEAVES:13)
Block(2,4,-2,LEAVES:13)
Block(2,4,-1,LOG:13)
Block(2,4,0,LEAVES:13)
Block(2,4,2,LEAVES:13)
Block(2,5,-3,LEAVES:13)
Block(2,5,-2,LEAVES:13)
Block(2,5,-1,LEAVES:13)
Block(2,5,0,LOG:13)
Block(2,5,1,LEAVES:13)
Block(2,5,2,LEAVES:13)
Block(2,5,4,LEAVES:13)
Block(2,6,-4,LEAVES:13)
Block(2,6,-3,LEAVES:13)
Block(2,6,-1,LEAVES:13)
Block(2,6,1,LEAVES:13)
Block(2,6,2,LEAVES:13)
Block(2,6,3,LEAVES:13)
Block(2,7,-3,LEAVES:13)
Block(2,7,-2,LEAVES:13)
Block(2,7,-1,LEAVES:13)
Block(2,7,0,LEAVES:13)
Block(2,7,1,LEAVES:13)
Block(2,7,2,LEAVES:13)
Block(2,7,3,LEAVES:13)
Block(2,8,-2,LEAVES:13)
Block(2,8,-1,LEAVES:13)
Block(2,8,0,LEAVES:13)
Block(2,8,1,LEAVES:13)
Block(2,8,2,LEAVES:13)
Block(2,8,3,LEAVES:13)
Block(2,9,-2,LEAVES:13)
Block(2,9,-1,LEAVES:13)
Block(2,9,0,LEAVES:13)
Block(2,9,1,LEAVES:13)
Block(2,9,2,LEAVES:13)
Block(2,9,3,LEAVES:13)
Block(2,10,-2,LEAVES:13)
Block(2,10,-1,LEAVES:13)
Block(2,10,0,LEAVES:13)
Block(2,10,1,LEAVES:13)
Block(2,10,2,LEAVES:13)
Block(2,10,3,LEAVES:13)
Block(2,11,-1,LEAVES:13)
Block(2,11,0,LEAVES:13)
Block(2,11,1,LEAVES:13)
Block(2,12,-2,LEAVES:13)
Block(2,12,0,LEAVES:13)
Block(2,12,1,LEAVES:13)
Block(2,12,2,LEAVES:13)
Block(2,13,-1,LEAVES:13)
Block(2,13,0,LEAVES:13)
Block(2,13,1,LEAVES:13)
Block(2,14,-2,LEAVES:13)
Block(2,14,-1,LEAVES:13)
Block(2,14,0,LOG:13)
Block(2,14,1,LEAVES:13)
Block(2,14,2,LEAVES:13)
Block(2,15,-2,LEAVES:13)
Block(2,15,-1,LEAVES:13)
Block(2,15,0,LEAVES:13)
Block(2,15,1,LEAVES:13)
Block(2,16,-1,LEAVES:13)
Block(2,16,0,LEAVES:13)
Block(2,16,1,LEAVES:13)
Block(2,17,-1,LEAVES:13)
Block(2,17,1,LEAVES:13)
Block(2,18,-2,LEAVES:13)
Block(2,19,0,LEAVES:13)
Block(2,19,2,LEAVES:13)
Block(2,20,2,LEAVES:13)
Block(2,21,-2,LEAVES:13)
Block(2,21,0,LEAVES:13)
Block(2,21,1,LEAVES:13)
Block(2,22,-1,LEAVES:13)
Block(2,22,0,LEAVES:13)
Block(2,22,1,LEAVES:13)
Block(2,23,0,LEAVES:13)
Block(3,4,-1,LEAVES:13)
Block(3,4,0,LEAVES:13)
Block(3,5,-3,LEAVES:13)
Block(3,5,-1,LEAVES:13)
Block(3,5,0,LEAVES:13)
Block(3,5,1,LEAVES:13)
Block(3,5,2,LEAVES:13)
Block(3,5,3,LEAVES:13)
Block(3,6,-2,LEAVES:13)
Block(3,6,-1,LEAVES:13)
Block(3,6,0,LEAVES:13)
Block(3,6,1,LEAVES:13)
Block(3,6,2,LEAVES:13)
Block(3,6,3,LEAVES:13)
Block(3,6,4,LEAVES:13)
Block(3,7,-2,LEAVES:13)
Block(3,7,-1,LEAVES:13)
Block(3,7,0,LEAVES:13)
Block(3,7,1,LEAVES:13)
Block(3,7,2,LEAVES:13)
Block(3,7,3,LEAVES:13)
Block(3,8,-1,LEAVES:13)
Block(3,8,0,LEAVES:13)
Block(3,8,1,LEAVES:13)
Block(3,8,3,LEAVES:13)
Block(3,9,0,LEAVES:13)
Block(3,9,2,LEAVES:13)
Block(3,10,-1,LEAVES:13)
Block(3,10,1,LEAVES:13)
Block(3,11,-2,LEAVES:13)
Block(3,11,0,LEAVES:13)
Block(3,11,2,LEAVES:13)
Block(3,12,0,LEAVES:13)
Block(3,12,1,LEAVES:13)
Block(3,13,1,LEAVES:13)
Block(3,14,-1,LEAVES:13)
Block(3,14,0,LEAVES:13)
Block(3,15,1,LEAVES:13)
Block(3,16,0,LEAVES:13)
Block(4,5,-2,LEAVES:13)
Block(4,5,-1,LEAVES:13)
Block(4,5,0,LEAVES:13)
Block(4,5,2,LEAVES:13)
Block(4,6,-1,LEAVES:13)
Block(4,6,0,LEAVES:13)
Block(4,7,-1,LEAVES:13)
Block(4,7,0,LEAVES:13)
Block(4,7,2,LEAVES:13)
Block(4,8,-2,LEAVES:13)
Block(4,8,-1,LEAVES:13)
Block(4,8,0,LEAVES:13)
Block(4,8,2,LEAVES:13)
Block(4,9,-1,LEAVES:13)
Block(4,9,0,LEAVES:13)
Block(4,10,0,LEAVES:13)
Block(5,5,-1,LEAVES:13)
Block(5,5,0,LEAVES:13)
Block(5,5,1,LEAVES:13)
Block(5,6,-2,LEAVES:13)
Block(5,6,1,LEAVES:13)
Block(5,7,0,LEAVES:13)

#######################################################################
# +-----------------------------------------------------------------+ #
# |                            BO3 checks                           | #
# +-----------------------------------------------------------------+ #
#######################################################################

BlockCheck(0,-1,0,GRASS,DIRT,biomesoplenty:grass:0,biomesoplenty:grass:1,biomesoplenty:grass,biomesoplenty:grass:3,biomesoplenty:grass:4,biomesoplenty:grass:5,biomesoplenty:grass:6,biomesoplenty:grass:7,UNKNOWN_BLOCK:0,UNKNOWN_BLOCK:1,UNKNOWN_BLOCK:2,UNKNOWN_BLOCK:8,UNKNOWN_BLOCK:9,UNKNOWN_BLOCK:10,biomesoplenty:dried_sand,biomesoplenty:hard_ice,biomesoplenty:white_sand,biomesoplenty:white_sandstone,biomesoplenty:mud,biomesoplenty:ash_block)

#######################################################################
# +-----------------------------------------------------------------+ #
# |                             Branches                            | #
# +-----------------------------------------------------------------+ #
#######################################################################


#######################################################################
# +-----------------------------------------------------------------+ #
# |                             Entities                            | #
# +-----------------------------------------------------------------+ #
#######################################################################


#######################################################################
# +-----------------------------------------------------------------+ #
# |                            Particles                            | #
# +-----------------------------------------------------------------+ #
#######################################################################


#######################################################################
# +-----------------------------------------------------------------+ #
# |                             Spawners                            | #
# +-----------------------------------------------------------------+ #
#######################################################################


#######################################################################
# +-----------------------------------------------------------------+ #
# |                             ModData                             | #
# +-----------------------------------------------------------------+ #
#######################################################################

