
#######################################################################
# +-----------------------------------------------------------------+ #
# |                            BO3 object                           | #
# +-----------------------------------------------------------------+ #
#######################################################################

Author: LordSmellyPants

Description: No description given

Version: 3

SettingsMode: WriteWithoutComments


#######################################################################
# +-----------------------------------------------------------------+ #
# |                          Main settings                          | #
# +-----------------------------------------------------------------+ #
#######################################################################

Tree: true

Frequency: 1

Rarity: 25.0

RotateRandomly: true

SpawnHeight: highestSolidBlock

SpawnHeightOffset: 0

SpawnHeightVariance: 0

##############################
# Height Limits for the BO3. #
##############################

MinHeight: 61

MaxHeight: 111

######################
# Extrusion settings #
######################

ExtrudeMode: None

ExtrudeThroughBlocks: AIR

MaxBranchDepth: 10

ExcludedBiomes: All


#######################################################################
# +-----------------------------------------------------------------+ #
# |                      Source block settings                      | #
# +-----------------------------------------------------------------+ #
#######################################################################

SourceBlocks: STONE:1,STONE:3,STONE:5,DIRT:1,DIRT,SAND,GRASS,DIRT:2,STATIONARY_WATER,HARD_CLAY,STAINED_CLAY,CLAY,SANDSTONE,SAND:1,AIR,STONE,GRAVEL,LONG_GRASS,LONG_GRASS:1,LONG_GRASS:2,DEAD_BUSH,YELLOW_FLOWER,RED_ROSE,BROWN_MUSHROOM,RED_MUSHROOM,biomesoplenty:plant_0:1,biomesoplenty:plant_0:2,biomesoplenty:plant_0:3,biomesoplenty:plant_0:4,biomesoplenty:plant_0:5,biomesoplenty:plant_0:6,biomesoplenty:plant_0:7,biomesoplenty:plant_0:8,biomesoplenty:plant_0:9,biomesoplenty:plant_0:10,biomesoplenty:plant_0:11,biomesoplenty:plant_0:12,biomesoplenty:plant_0:13,biomesoplenty:plant_0:14,biomesoplenty:flower_0:1,biomesoplenty:flower_0:2,biomesoplenty:flower_0:3,biomesoplenty:flower_0:4,biomesoplenty:flower_0:5,biomesoplenty:flower_0:6,biomesoplenty:flower_0:7,biomesoplenty:flower_0:8,biomesoplenty:flower_0:9,biomesoplenty:flower_0:10,biomesoplenty:flower_0:11,biomesoplenty:flower_0:12,biomesoplenty:flower_0:13,biomesoplenty:flower_0:14,biomesoplenty:plant_1:0,biomesoplenty:grass:0,biomesoplenty:grass:1,biomesoplenty:grass:2,biomesoplenty:grass:3,biomesoplenty:grass:4,biomesoplenty:grass:5,biomesoplenty:grass:6,biomesoplenty:grass:7,biomesoplenty:dirt:0,biomesoplenty:dirt:1,biomesoplenty:dirt:2,biomesoplenty:dirt:3,biomesoplenty:dirt:4,biomesoplenty:dirt:5,biomesoplenty:dirt:6,biomesoplenty:dirt:7,biomesoplenty:dirt:8,biomesoplenty:dirt:9,biomesoplenty:dirt:10,biomesoplenty:dried_sand:0,biomesoplenty:hard_ice:0,biomesoplenty:white_sand:0,biomesoplenty:white_sandstone:0,biomesoplenty:mud:0,biomesoplenty:ash_block:0
MaxPercentageOutsideSourceBlock: 0

OutsideSourceBlock: placeAnyway

IsOTGPlus: false


#######################################################################
# +-----------------------------------------------------------------+ #
# |                              Blocks                             | #
# +-----------------------------------------------------------------+ #
#######################################################################

Block(-24,17,4,biomesoplenty:leaves_0:3)
Block(-24,17,5,biomesoplenty:leaves_0:3)
Block(-24,18,3,biomesoplenty:leaves_0:3)
Block(-24,18,4,biomesoplenty:leaves_0:3)
Block(-24,19,4,biomesoplenty:leaves_0:3)
Block(-24,19,5,biomesoplenty:leaves_0:3)
Block(-23,16,6,biomesoplenty:leaves_0:3)
Block(-23,16,7,biomesoplenty:leaves_0:3)
Block(-23,16,8,biomesoplenty:leaves_0:3)
Block(-23,17,4,biomesoplenty:leaves_0:3)
Block(-23,17,5,biomesoplenty:leaves_0:3)
Block(-23,17,6,biomesoplenty:leaves_0:3)
Block(-23,17,8,biomesoplenty:leaves_0:3)
Block(-23,17,9,biomesoplenty:leaves_0:3)
Block(-23,18,3,biomesoplenty:leaves_0:3)
Block(-23,18,4,biomesoplenty:leaves_0:3)
Block(-23,18,5,biomesoplenty:leaves_0:3)
Block(-23,18,6,biomesoplenty:leaves_0:3)
Block(-23,19,2,biomesoplenty:leaves_0:3)
Block(-23,19,5,biomesoplenty:leaves_0:3)
Block(-23,19,6,biomesoplenty:leaves_0:3)
Block(-23,20,3,biomesoplenty:leaves_0:3)
Block(-23,20,4,biomesoplenty:leaves_0:3)
Block(-23,20,5,biomesoplenty:leaves_0:3)
Block(-23,21,1,biomesoplenty:leaves_0:3)
Block(-23,21,2,biomesoplenty:leaves_0:3)
Block(-23,21,3,biomesoplenty:leaves_0:3)
Block(-22,12,2,biomesoplenty:leaves_0:3)
Block(-22,12,3,biomesoplenty:leaves_0:3)
Block(-22,13,1,biomesoplenty:leaves_0:3)
Block(-22,13,2,biomesoplenty:leaves_0:3)
Block(-22,14,1,biomesoplenty:leaves_0:3)
Block(-22,14,3,biomesoplenty:leaves_0:3)
Block(-22,14,8,biomesoplenty:leaves_0:3)
Block(-22,15,2,biomesoplenty:leaves_0:3)
Block(-22,15,3,biomesoplenty:leaves_0:3)
Block(-22,15,6,biomesoplenty:leaves_0:3)
Block(-22,15,7,biomesoplenty:leaves_0:3)
Block(-22,15,8,biomesoplenty:leaves_0:3)
Block(-22,15,9,biomesoplenty:leaves_0:3)
Block(-22,16,3,biomesoplenty:leaves_0:3)
Block(-22,16,6,biomesoplenty:leaves_0:3)
Block(-22,16,7,biomesoplenty:leaves_0:3)
Block(-22,16,8,biomesoplenty:leaves_0:3)
Block(-22,16,9,biomesoplenty:leaves_0:3)
Block(-22,16,10,biomesoplenty:leaves_0:3)
Block(-22,17,2,biomesoplenty:leaves_0:3)
Block(-22,17,4,biomesoplenty:leaves_0:3)
Block(-22,17,5,biomesoplenty:leaves_0:3)
Block(-22,17,6,biomesoplenty:leaves_0:3)
Block(-22,17,7,biomesoplenty:leaves_0:3)
Block(-22,17,8,biomesoplenty:leaves_0:3)
Block(-22,17,9,biomesoplenty:leaves_0:3)
Block(-22,17,10,biomesoplenty:leaves_0:3)
Block(-22,18,2,biomesoplenty:leaves_0:3)
Block(-22,18,5,biomesoplenty:leaves_0:3)
Block(-22,18,6,biomesoplenty:leaves_0:3)
Block(-22,18,7,biomesoplenty:leaves_0:3)
Block(-22,18,9,biomesoplenty:leaves_0:3)
Block(-22,19,1,biomesoplenty:leaves_0:3)
Block(-22,19,2,biomesoplenty:leaves_0:3)
Block(-22,19,3,biomesoplenty:leaves_0:3)
Block(-22,19,4,biomesoplenty:leaves_0:3)
Block(-22,19,5,biomesoplenty:leaves_0:3)
Block(-22,19,6,biomesoplenty:leaves_0:3)
Block(-22,19,7,biomesoplenty:leaves_0:3)
Block(-22,19,8,biomesoplenty:leaves_0:3)
Block(-22,20,2,biomesoplenty:leaves_0:3)
Block(-22,20,3,biomesoplenty:leaves_0:3)
Block(-22,20,5,biomesoplenty:leaves_0:3)
Block(-22,20,6,biomesoplenty:leaves_0:3)
Block(-22,20,7,biomesoplenty:leaves_0:3)
Block(-22,21,1,biomesoplenty:leaves_0:3)
Block(-22,21,2,biomesoplenty:leaves_0:3)
Block(-22,21,3,biomesoplenty:leaves_0:3)
Block(-22,21,4,biomesoplenty:leaves_0:3)
Block(-22,21,5,biomesoplenty:leaves_0:3)
Block(-22,22,2,biomesoplenty:leaves_0:3)
Block(-22,22,5,biomesoplenty:leaves_0:3)
Block(-21,12,1,biomesoplenty:leaves_0:3)
Block(-21,12,2,biomesoplenty:leaves_0:3)
Block(-21,12,3,biomesoplenty:leaves_0:3)
Block(-21,13,0,biomesoplenty:leaves_0:3)
Block(-21,13,1,biomesoplenty:leaves_0:3)
Block(-21,13,2,biomesoplenty:leaves_0:3)
Block(-21,13,8,biomesoplenty:leaves_0:3)
Block(-21,14,0,biomesoplenty:leaves_0:3)
Block(-21,14,1,biomesoplenty:log_1:5)
Block(-21,14,2,biomesoplenty:log_1:5)
Block(-21,14,8,biomesoplenty:leaves_0:3)
Block(-21,15,1,biomesoplenty:leaves_0:3)
Block(-21,15,2,biomesoplenty:leaves_0:3)
Block(-21,15,7,biomesoplenty:leaves_0:3)
Block(-21,15,8,biomesoplenty:leaves_0:3)
Block(-21,16,1,biomesoplenty:leaves_0:3)
Block(-21,16,2,biomesoplenty:leaves_0:3)
Block(-21,16,3,biomesoplenty:leaves_0:3)
Block(-21,16,6,biomesoplenty:leaves_0:3)
Block(-21,16,7,biomesoplenty:leaves_0:3)
Block(-21,16,8,biomesoplenty:leaves_0:3)
Block(-21,16,9,biomesoplenty:leaves_0:3)
Block(-21,17,1,biomesoplenty:leaves_0:3)
Block(-21,17,2,biomesoplenty:leaves_0:3)
Block(-21,17,3,biomesoplenty:leaves_0:3)
Block(-21,17,4,biomesoplenty:leaves_0:3)
Block(-21,17,5,biomesoplenty:leaves_0:3)
Block(-21,17,6,biomesoplenty:leaves_0:3)
Block(-21,17,7,biomesoplenty:leaves_0:3)
Block(-21,17,8,biomesoplenty:leaves_0:3)
Block(-21,17,9,biomesoplenty:leaves_0:3)
Block(-21,17,10,biomesoplenty:leaves_0:3)
Block(-21,17,11,biomesoplenty:leaves_0:3)
Block(-21,17,12,biomesoplenty:leaves_0:3)
Block(-21,18,0,biomesoplenty:leaves_0:3)
Block(-21,18,2,biomesoplenty:leaves_0:3)
Block(-21,18,3,biomesoplenty:leaves_0:3)
Block(-21,18,4,biomesoplenty:leaves_0:3)
Block(-21,18,6,biomesoplenty:leaves_0:3)
Block(-21,18,7,biomesoplenty:leaves_0:3)
Block(-21,18,8,biomesoplenty:leaves_0:3)
Block(-21,18,10,biomesoplenty:leaves_0:3)
Block(-21,18,11,biomesoplenty:leaves_0:3)
Block(-21,18,12,biomesoplenty:leaves_0:3)
Block(-21,19,1,biomesoplenty:leaves_0:3)
Block(-21,19,2,biomesoplenty:leaves_0:3)
Block(-21,19,3,biomesoplenty:leaves_0:3)
Block(-21,19,5,biomesoplenty:leaves_0:3)
Block(-21,19,6,biomesoplenty:leaves_0:3)
Block(-21,19,8,biomesoplenty:leaves_0:3)
Block(-21,19,9,biomesoplenty:leaves_0:3)
Block(-21,19,10,biomesoplenty:leaves_0:3)
Block(-21,20,1,biomesoplenty:leaves_0:3)
Block(-21,20,5,biomesoplenty:leaves_0:3)
Block(-21,20,6,biomesoplenty:leaves_0:3)
Block(-21,20,7,biomesoplenty:leaves_0:3)
Block(-21,20,8,biomesoplenty:leaves_0:3)
Block(-21,21,1,biomesoplenty:leaves_0:3)
Block(-21,21,2,biomesoplenty:leaves_0:3)
Block(-21,21,5,biomesoplenty:leaves_0:3)
Block(-21,21,6,biomesoplenty:leaves_0:3)
Block(-21,21,11,biomesoplenty:leaves_0:3)
Block(-21,21,12,biomesoplenty:leaves_0:3)
Block(-21,22,1,biomesoplenty:leaves_0:3)
Block(-21,22,2,biomesoplenty:leaves_0:3)
Block(-21,22,3,biomesoplenty:leaves_0:3)
Block(-21,22,4,biomesoplenty:leaves_0:3)
Block(-20,12,0,biomesoplenty:leaves_0:3)
Block(-20,12,1,biomesoplenty:leaves_0:3)
Block(-20,12,2,biomesoplenty:leaves_0:3)
Block(-20,13,-1,biomesoplenty:leaves_0:3)
Block(-20,13,0,biomesoplenty:leaves_0:3)
Block(-20,13,1,biomesoplenty:leaves_0:3)
Block(-20,13,2,biomesoplenty:leaves_0:3)
Block(-20,13,3,biomesoplenty:leaves_0:3)
Block(-20,14,0,biomesoplenty:leaves_0:3)
Block(-20,14,1,biomesoplenty:leaves_0:3)
Block(-20,14,2,biomesoplenty:log_1:5)
Block(-20,14,3,biomesoplenty:log_1:5)
Block(-20,14,4,biomesoplenty:leaves_0:3)
Block(-20,14,8,biomesoplenty:leaves_0:3)
Block(-20,15,1,biomesoplenty:leaves_0:3)
Block(-20,15,2,biomesoplenty:leaves_0:3)
Block(-20,15,5,biomesoplenty:log_1:5)
Block(-20,15,6,biomesoplenty:leaves_0:3)
Block(-20,15,7,biomesoplenty:leaves_0:3)
Block(-20,15,8,biomesoplenty:leaves_0:3)
Block(-20,15,9,biomesoplenty:leaves_0:3)
Block(-20,16,2,biomesoplenty:leaves_0:3)
Block(-20,16,4,biomesoplenty:leaves_0:3)
Block(-20,16,6,biomesoplenty:log_1:5)
Block(-20,16,7,biomesoplenty:leaves_0:3)
Block(-20,16,8,biomesoplenty:leaves_0:3)
Block(-20,16,9,biomesoplenty:leaves_0:3)
Block(-20,16,10,biomesoplenty:leaves_0:3)
Block(-20,16,11,biomesoplenty:leaves_0:3)
Block(-20,16,12,biomesoplenty:leaves_0:3)
Block(-20,16,14,biomesoplenty:leaves_0:3)
Block(-20,16,15,biomesoplenty:leaves_0:3)
Block(-20,17,0,biomesoplenty:leaves_0:3)
Block(-20,17,2,biomesoplenty:leaves_0:3)
Block(-20,17,4,biomesoplenty:leaves_0:3)
Block(-20,17,7,biomesoplenty:log_1:5)
Block(-20,17,9,biomesoplenty:leaves_0:3)
Block(-20,17,10,biomesoplenty:leaves_0:3)
Block(-20,17,11,biomesoplenty:leaves_0:3)
Block(-20,17,12,biomesoplenty:leaves_0:3)
Block(-20,17,13,biomesoplenty:leaves_0:3)
Block(-20,17,14,biomesoplenty:leaves_0:3)
Block(-20,17,15,biomesoplenty:leaves_0:3)
Block(-20,18,0,biomesoplenty:leaves_0:3)
Block(-20,18,1,biomesoplenty:leaves_0:3)
Block(-20,18,2,biomesoplenty:leaves_0:3)
Block(-20,18,3,biomesoplenty:leaves_0:3)
Block(-20,18,4,biomesoplenty:leaves_0:3)
Block(-20,18,5,biomesoplenty:leaves_0:3)
Block(-20,18,6,biomesoplenty:leaves_0:3)
Block(-20,18,7,biomesoplenty:leaves_0:3)
Block(-20,18,8,biomesoplenty:leaves_0:3)
Block(-20,18,9,biomesoplenty:leaves_0:3)
Block(-20,18,10,biomesoplenty:leaves_0:3)
Block(-20,18,11,biomesoplenty:leaves_0:3)
Block(-20,18,12,biomesoplenty:leaves_0:3)
Block(-20,18,13,biomesoplenty:leaves_0:3)
Block(-20,18,15,biomesoplenty:leaves_0:3)
Block(-20,19,0,biomesoplenty:leaves_0:3)
Block(-20,19,1,biomesoplenty:leaves_0:3)
Block(-20,19,2,biomesoplenty:leaves_0:3)
Block(-20,19,4,biomesoplenty:leaves_0:3)
Block(-20,19,5,biomesoplenty:leaves_0:3)
Block(-20,19,7,biomesoplenty:leaves_0:3)
Block(-20,19,8,biomesoplenty:leaves_0:3)
Block(-20,19,10,biomesoplenty:leaves_0:3)
Block(-20,19,11,biomesoplenty:leaves_0:3)
Block(-20,19,12,biomesoplenty:leaves_0:3)
Block(-20,20,1,biomesoplenty:leaves_0:3)
Block(-20,20,2,biomesoplenty:leaves_0:3)
Block(-20,20,4,biomesoplenty:leaves_0:3)
Block(-20,20,5,biomesoplenty:leaves_0:3)
Block(-20,20,7,biomesoplenty:leaves_0:3)
Block(-20,20,8,biomesoplenty:leaves_0:3)
Block(-20,20,9,biomesoplenty:leaves_0:3)
Block(-20,20,10,biomesoplenty:leaves_0:3)
Block(-20,20,12,biomesoplenty:leaves_0:3)
Block(-20,21,0,biomesoplenty:leaves_0:3)
Block(-20,21,1,biomesoplenty:leaves_0:3)
Block(-20,21,2,biomesoplenty:leaves_0:3)
Block(-20,21,6,biomesoplenty:leaves_0:3)
Block(-20,21,8,biomesoplenty:leaves_0:3)
Block(-20,21,9,biomesoplenty:leaves_0:3)
Block(-20,21,10,biomesoplenty:leaves_0:3)
Block(-20,21,11,biomesoplenty:leaves_0:3)
Block(-20,21,12,biomesoplenty:leaves_0:3)
Block(-20,21,13,biomesoplenty:leaves_0:3)
Block(-20,22,2,biomesoplenty:leaves_0:3)
Block(-20,22,9,biomesoplenty:leaves_0:3)
Block(-20,22,11,biomesoplenty:leaves_0:3)
Block(-20,23,2,biomesoplenty:leaves_0:3)
Block(-20,24,3,biomesoplenty:leaves_0:3)
Block(-20,24,4,biomesoplenty:leaves_0:3)
Block(-20,25,4,biomesoplenty:leaves_0:3)
Block(-19,11,11,biomesoplenty:leaves_0:3)
Block(-19,11,12,biomesoplenty:leaves_0:3)
Block(-19,12,1,biomesoplenty:leaves_0:3)
Block(-19,12,3,biomesoplenty:leaves_0:3)
Block(-19,12,11,biomesoplenty:leaves_0:3)
Block(-19,13,1,biomesoplenty:leaves_0:3)
Block(-19,13,2,biomesoplenty:leaves_0:3)
Block(-19,13,3,biomesoplenty:leaves_0:3)
Block(-19,13,4,biomesoplenty:leaves_0:3)
Block(-19,13,6,biomesoplenty:leaves_0:3)
Block(-19,14,1,biomesoplenty:leaves_0:3)
Block(-19,14,3,biomesoplenty:log_1:5)
Block(-19,14,4,biomesoplenty:leaves_0:3)
Block(-19,14,5,biomesoplenty:leaves_0:3)
Block(-19,14,6,biomesoplenty:leaves_0:3)
Block(-19,14,7,biomesoplenty:leaves_0:3)
Block(-19,14,8,biomesoplenty:leaves_0:3)
Block(-19,15,1,biomesoplenty:leaves_0:3)
Block(-19,15,2,biomesoplenty:leaves_0:3)
Block(-19,15,3,biomesoplenty:log_1:5)
Block(-19,15,4,biomesoplenty:log_1:5)
Block(-19,15,5,biomesoplenty:log_1:5)
Block(-19,15,6,biomesoplenty:leaves_0:3)
Block(-19,15,7,biomesoplenty:leaves_0:3)
Block(-19,15,8,biomesoplenty:leaves_0:3)
Block(-19,15,9,biomesoplenty:leaves_0:3)
Block(-19,15,13,biomesoplenty:leaves_0:3)
Block(-19,15,14,biomesoplenty:leaves_0:3)
Block(-19,15,15,biomesoplenty:leaves_0:3)
Block(-19,15,16,biomesoplenty:leaves_0:3)
Block(-19,16,0,biomesoplenty:leaves_0:3)
Block(-19,16,1,biomesoplenty:leaves_0:3)
Block(-19,16,2,biomesoplenty:leaves_0:3)
Block(-19,16,3,biomesoplenty:leaves_0:3)
Block(-19,16,7,biomesoplenty:leaves_0:3)
Block(-19,16,8,biomesoplenty:leaves_0:3)
Block(-19,16,13,biomesoplenty:leaves_0:3)
Block(-19,16,14,biomesoplenty:leaves_0:3)
Block(-19,16,15,biomesoplenty:leaves_0:3)
Block(-19,16,16,biomesoplenty:leaves_0:3)
Block(-19,17,1,biomesoplenty:leaves_0:3)
Block(-19,17,2,biomesoplenty:leaves_0:3)
Block(-19,17,3,biomesoplenty:leaves_0:3)
Block(-19,17,8,biomesoplenty:leaves_0:3)
Block(-19,17,9,biomesoplenty:leaves_0:3)
Block(-19,17,11,biomesoplenty:leaves_0:3)
Block(-19,17,12,biomesoplenty:leaves_0:3)
Block(-19,17,13,biomesoplenty:leaves_0:3)
Block(-19,17,15,biomesoplenty:leaves_0:3)
Block(-19,17,16,biomesoplenty:leaves_0:3)
Block(-19,18,0,biomesoplenty:leaves_0:3)
Block(-19,18,1,biomesoplenty:leaves_0:3)
Block(-19,18,2,biomesoplenty:leaves_0:3)
Block(-19,18,3,biomesoplenty:leaves_0:3)
Block(-19,18,4,biomesoplenty:leaves_0:3)
Block(-19,18,7,biomesoplenty:leaves_0:3)
Block(-19,18,9,biomesoplenty:leaves_0:3)
Block(-19,18,10,biomesoplenty:leaves_0:3)
Block(-19,18,11,biomesoplenty:leaves_0:3)
Block(-19,18,13,biomesoplenty:leaves_0:3)
Block(-19,18,15,biomesoplenty:leaves_0:3)
Block(-19,19,0,biomesoplenty:leaves_0:3)
Block(-19,19,1,biomesoplenty:leaves_0:3)
Block(-19,19,2,biomesoplenty:leaves_0:3)
Block(-19,19,3,biomesoplenty:leaves_0:3)
Block(-19,19,7,biomesoplenty:leaves_0:3)
Block(-19,19,9,biomesoplenty:leaves_0:3)
Block(-19,19,10,biomesoplenty:leaves_0:3)
Block(-19,20,1,biomesoplenty:leaves_0:3)
Block(-19,20,2,biomesoplenty:leaves_0:3)
Block(-19,20,8,biomesoplenty:leaves_0:3)
Block(-19,20,10,biomesoplenty:leaves_0:3)
Block(-19,20,13,biomesoplenty:leaves_0:3)
Block(-19,21,0,biomesoplenty:leaves_0:3)
Block(-19,21,1,biomesoplenty:leaves_0:3)
Block(-19,21,6,biomesoplenty:leaves_0:3)
Block(-19,21,7,biomesoplenty:leaves_0:3)
Block(-19,21,8,biomesoplenty:leaves_0:3)
Block(-19,21,10,biomesoplenty:leaves_0:3)
Block(-19,21,12,biomesoplenty:leaves_0:3)
Block(-19,21,13,biomesoplenty:leaves_0:3)
Block(-19,22,1,biomesoplenty:leaves_0:3)
Block(-19,22,2,biomesoplenty:leaves_0:3)
Block(-19,22,9,biomesoplenty:leaves_0:3)
Block(-19,22,11,biomesoplenty:leaves_0:3)
Block(-19,22,12,biomesoplenty:leaves_0:3)
Block(-19,22,13,biomesoplenty:leaves_0:3)
Block(-19,23,0,biomesoplenty:leaves_0:3)
Block(-19,23,2,biomesoplenty:leaves_0:3)
Block(-19,23,3,biomesoplenty:leaves_0:3)
Block(-19,23,10,biomesoplenty:leaves_0:3)
Block(-19,23,11,biomesoplenty:leaves_0:3)
Block(-19,23,13,biomesoplenty:leaves_0:3)
Block(-19,24,-1,biomesoplenty:leaves_0:3)
Block(-19,24,0,biomesoplenty:leaves_0:3)
Block(-19,24,3,biomesoplenty:leaves_0:3)
Block(-19,24,4,biomesoplenty:leaves_0:3)
Block(-19,24,5,biomesoplenty:leaves_0:3)
Block(-19,25,0,biomesoplenty:leaves_0:3)
Block(-19,25,1,biomesoplenty:leaves_0:3)
Block(-19,25,2,biomesoplenty:leaves_0:3)
Block(-19,25,3,biomesoplenty:leaves_0:3)
Block(-19,25,4,biomesoplenty:leaves_0:3)
Block(-19,26,0,biomesoplenty:leaves_0:3)
Block(-18,11,10,biomesoplenty:leaves_0:3)
Block(-18,11,12,biomesoplenty:leaves_0:3)
Block(-18,12,9,biomesoplenty:leaves_0:3)
Block(-18,12,10,biomesoplenty:leaves_0:3)
Block(-18,12,11,biomesoplenty:leaves_0:3)
Block(-18,12,12,biomesoplenty:leaves_0:3)
Block(-18,13,3,biomesoplenty:leaves_0:3)
Block(-18,13,13,biomesoplenty:leaves_0:3)
Block(-18,14,2,biomesoplenty:leaves_0:3)
Block(-18,14,4,biomesoplenty:leaves_0:3)
Block(-18,15,1,biomesoplenty:leaves_0:3)
Block(-18,15,2,biomesoplenty:leaves_0:3)
Block(-18,15,3,biomesoplenty:leaves_0:3)
Block(-18,15,4,biomesoplenty:log_1:5)
Block(-18,15,5,biomesoplenty:leaves_0:3)
Block(-18,15,6,biomesoplenty:leaves_0:3)
Block(-18,15,7,biomesoplenty:leaves_0:3)
Block(-18,15,8,biomesoplenty:leaves_0:3)
Block(-18,15,13,biomesoplenty:leaves_0:3)
Block(-18,15,14,biomesoplenty:leaves_0:3)
Block(-18,16,1,biomesoplenty:leaves_0:3)
Block(-18,16,2,biomesoplenty:leaves_0:3)
Block(-18,16,3,biomesoplenty:leaves_0:3)
Block(-18,16,4,biomesoplenty:log_1:5)
Block(-18,16,5,biomesoplenty:leaves_0:3)
Block(-18,16,6,biomesoplenty:leaves_0:3)
Block(-18,16,11,biomesoplenty:leaves_0:3)
Block(-18,16,13,biomesoplenty:leaves_0:3)
Block(-18,16,14,biomesoplenty:leaves_0:3)
Block(-18,16,16,biomesoplenty:leaves_0:3)
Block(-18,16,17,biomesoplenty:leaves_0:3)
Block(-18,17,-7,biomesoplenty:leaves_0:3)
Block(-18,17,1,biomesoplenty:leaves_0:3)
Block(-18,17,2,biomesoplenty:leaves_0:3)
Block(-18,17,3,biomesoplenty:leaves_0:3)
Block(-18,17,4,biomesoplenty:leaves_0:3)
Block(-18,17,5,biomesoplenty:leaves_0:3)
Block(-18,17,7,biomesoplenty:leaves_0:3)
Block(-18,17,10,biomesoplenty:leaves_0:3)
Block(-18,17,12,biomesoplenty:leaves_0:3)
Block(-18,17,15,biomesoplenty:leaves_0:3)
Block(-18,17,16,biomesoplenty:leaves_0:3)
Block(-18,18,-8,biomesoplenty:leaves_0:3)
Block(-18,18,-7,biomesoplenty:leaves_0:3)
Block(-18,18,1,biomesoplenty:leaves_0:3)
Block(-18,18,2,biomesoplenty:leaves_0:3)
Block(-18,18,3,biomesoplenty:leaves_0:3)
Block(-18,18,4,biomesoplenty:leaves_0:3)
Block(-18,18,5,biomesoplenty:leaves_0:3)
Block(-18,18,7,biomesoplenty:leaves_0:3)
Block(-18,18,10,biomesoplenty:leaves_0:3)
Block(-18,18,11,biomesoplenty:leaves_0:3)
Block(-18,18,12,biomesoplenty:leaves_0:3)
Block(-18,18,13,biomesoplenty:log_1:5)
Block(-18,18,14,biomesoplenty:leaves_0:3)
Block(-18,18,15,biomesoplenty:leaves_0:3)
Block(-18,19,-7,biomesoplenty:leaves_0:3)
Block(-18,19,-5,biomesoplenty:leaves_0:3)
Block(-18,19,-4,biomesoplenty:leaves_0:3)
Block(-18,19,0,biomesoplenty:leaves_0:3)
Block(-18,19,1,biomesoplenty:leaves_0:3)
Block(-18,19,2,biomesoplenty:leaves_0:3)
Block(-18,19,4,biomesoplenty:leaves_0:3)
Block(-18,19,7,biomesoplenty:leaves_0:3)
Block(-18,19,9,biomesoplenty:leaves_0:3)
Block(-18,19,10,biomesoplenty:leaves_0:3)
Block(-18,19,15,biomesoplenty:leaves_0:3)
Block(-18,20,-4,biomesoplenty:leaves_0:3)
Block(-18,20,5,biomesoplenty:leaves_0:3)
Block(-18,20,7,biomesoplenty:leaves_0:3)
Block(-18,20,8,biomesoplenty:leaves_0:3)
Block(-18,20,9,biomesoplenty:leaves_0:3)
Block(-18,20,11,biomesoplenty:leaves_0:3)
Block(-18,20,12,biomesoplenty:leaves_0:3)
Block(-18,20,13,biomesoplenty:leaves_0:3)
Block(-18,20,14,biomesoplenty:leaves_0:3)
Block(-18,20,15,biomesoplenty:leaves_0:3)
Block(-18,21,0,biomesoplenty:leaves_0:3)
Block(-18,21,1,biomesoplenty:leaves_0:3)
Block(-18,21,2,biomesoplenty:leaves_0:3)
Block(-18,21,4,biomesoplenty:leaves_0:3)
Block(-18,21,7,biomesoplenty:leaves_0:3)
Block(-18,21,9,biomesoplenty:leaves_0:3)
Block(-18,21,10,biomesoplenty:leaves_0:3)
Block(-18,21,11,biomesoplenty:leaves_0:3)
Block(-18,21,12,biomesoplenty:leaves_0:3)
Block(-18,21,13,biomesoplenty:leaves_0:3)
Block(-18,22,-1,biomesoplenty:leaves_0:3)
Block(-18,22,0,biomesoplenty:leaves_0:3)
Block(-18,22,1,biomesoplenty:leaves_0:3)
Block(-18,22,2,biomesoplenty:log_1:5)
Block(-18,22,4,biomesoplenty:leaves_0:3)
Block(-18,22,5,biomesoplenty:leaves_0:3)
Block(-18,22,9,biomesoplenty:leaves_0:3)
Block(-18,22,10,biomesoplenty:leaves_0:3)
Block(-18,22,11,biomesoplenty:leaves_0:3)
Block(-18,22,12,biomesoplenty:leaves_0:3)
Block(-18,22,14,biomesoplenty:leaves_0:3)
Block(-18,23,1,biomesoplenty:leaves_0:3)
Block(-18,23,2,biomesoplenty:log_1:5)
Block(-18,23,3,biomesoplenty:leaves_0:3)
Block(-18,23,4,biomesoplenty:leaves_0:3)
Block(-18,23,5,biomesoplenty:leaves_0:3)
Block(-18,23,9,biomesoplenty:leaves_0:3)
Block(-18,23,10,biomesoplenty:leaves_0:3)
Block(-18,23,11,biomesoplenty:leaves_0:3)
Block(-18,23,12,biomesoplenty:leaves_0:3)
Block(-18,23,13,biomesoplenty:leaves_0:3)
Block(-18,23,14,biomesoplenty:leaves_0:3)
Block(-18,24,1,biomesoplenty:log_1:5)
Block(-18,24,2,biomesoplenty:leaves_0:3)
Block(-18,24,3,biomesoplenty:leaves_0:3)
Block(-18,24,4,biomesoplenty:leaves_0:3)
Block(-18,24,5,biomesoplenty:leaves_0:3)
Block(-18,24,6,biomesoplenty:leaves_0:3)
Block(-18,24,8,biomesoplenty:leaves_0:3)
Block(-18,24,11,biomesoplenty:leaves_0:3)
Block(-18,25,-2,biomesoplenty:leaves_0:3)
Block(-18,25,-1,biomesoplenty:leaves_0:3)
Block(-18,25,0,biomesoplenty:leaves_0:3)
Block(-18,25,1,biomesoplenty:leaves_0:3)
Block(-18,25,2,biomesoplenty:leaves_0:3)
Block(-18,25,3,biomesoplenty:leaves_0:3)
Block(-18,25,4,biomesoplenty:leaves_0:3)
Block(-18,25,11,biomesoplenty:leaves_0:3)
Block(-18,26,-4,biomesoplenty:leaves_0:3)
Block(-18,26,-2,biomesoplenty:leaves_0:3)
Block(-18,26,0,biomesoplenty:leaves_0:3)
Block(-18,26,1,biomesoplenty:leaves_0:3)
Block(-18,26,3,biomesoplenty:leaves_0:3)
Block(-18,27,0,biomesoplenty:leaves_0:3)
Block(-17,9,11,biomesoplenty:leaves_0:3)
Block(-17,10,10,biomesoplenty:leaves_0:3)
Block(-17,10,11,biomesoplenty:leaves_0:3)
Block(-17,10,12,biomesoplenty:leaves_0:3)
Block(-17,11,9,biomesoplenty:leaves_0:3)
Block(-17,11,10,biomesoplenty:log_1:5)
Block(-17,11,11,biomesoplenty:leaves_0:3)
Block(-17,11,12,biomesoplenty:leaves_0:3)
Block(-17,11,13,biomesoplenty:leaves_0:3)
Block(-17,11,14,biomesoplenty:leaves_0:3)
Block(-17,12,7,biomesoplenty:leaves_0:3)
Block(-17,12,8,biomesoplenty:leaves_0:3)
Block(-17,12,11,biomesoplenty:leaves_0:3)
Block(-17,12,12,biomesoplenty:leaves_0:3)
Block(-17,13,8,biomesoplenty:leaves_0:3)
Block(-17,13,9,biomesoplenty:leaves_0:3)
Block(-17,13,12,biomesoplenty:leaves_0:3)
Block(-17,13,14,biomesoplenty:leaves_0:3)
Block(-17,14,6,biomesoplenty:leaves_0:3)
Block(-17,15,5,biomesoplenty:leaves_0:3)
Block(-17,15,6,biomesoplenty:leaves_0:3)
Block(-17,15,7,biomesoplenty:leaves_0:3)
Block(-17,15,17,biomesoplenty:leaves_0:3)
Block(-17,16,-7,biomesoplenty:leaves_0:3)
Block(-17,16,-6,biomesoplenty:leaves_0:3)
Block(-17,16,-5,biomesoplenty:leaves_0:3)
Block(-17,16,2,biomesoplenty:leaves_0:3)
Block(-17,16,3,biomesoplenty:leaves_0:3)
Block(-17,16,4,biomesoplenty:log_1:5)
Block(-17,16,6,biomesoplenty:leaves_0:3)
Block(-17,16,7,biomesoplenty:leaves_0:3)
Block(-17,16,12,biomesoplenty:leaves_0:3)
Block(-17,16,13,biomesoplenty:leaves_0:3)
Block(-17,16,14,biomesoplenty:leaves_0:3)
Block(-17,16,15,biomesoplenty:leaves_0:3)
Block(-17,16,16,biomesoplenty:leaves_0:3)
Block(-17,17,-8,biomesoplenty:leaves_0:3)
Block(-17,17,-6,biomesoplenty:leaves_0:3)
Block(-17,17,-5,biomesoplenty:leaves_0:3)
Block(-17,17,-4,biomesoplenty:leaves_0:3)
Block(-17,17,3,biomesoplenty:leaves_0:3)
Block(-17,17,4,biomesoplenty:log_1:5)
Block(-17,17,5,biomesoplenty:leaves_0:3)
Block(-17,17,6,biomesoplenty:leaves_0:3)
Block(-17,17,10,biomesoplenty:leaves_0:3)
Block(-17,17,14,biomesoplenty:log_1:5)
Block(-17,17,15,biomesoplenty:leaves_0:3)
Block(-17,17,16,biomesoplenty:leaves_0:3)
Block(-17,18,-9,biomesoplenty:leaves_0:3)
Block(-17,18,-8,biomesoplenty:leaves_0:3)
Block(-17,18,-7,biomesoplenty:leaves_0:3)
Block(-17,18,-5,biomesoplenty:leaves_0:3)
Block(-17,18,3,biomesoplenty:leaves_0:3)
Block(-17,18,4,biomesoplenty:leaves_0:3)
Block(-17,18,5,biomesoplenty:leaves_0:3)
Block(-17,18,7,biomesoplenty:leaves_0:3)
Block(-17,18,16,biomesoplenty:leaves_0:3)
Block(-17,19,-8,biomesoplenty:leaves_0:3)
Block(-17,19,-7,biomesoplenty:leaves_0:3)
Block(-17,19,-6,biomesoplenty:leaves_0:3)
Block(-17,19,-5,biomesoplenty:leaves_0:3)
Block(-17,19,-4,biomesoplenty:leaves_0:3)
Block(-17,19,-3,biomesoplenty:leaves_0:3)
Block(-17,19,6,biomesoplenty:leaves_0:3)
Block(-17,19,12,biomesoplenty:leaves_0:3)
Block(-17,19,13,biomesoplenty:leaves_0:3)
Block(-17,20,-6,biomesoplenty:leaves_0:3)
Block(-17,20,-5,biomesoplenty:leaves_0:3)
Block(-17,20,-3,biomesoplenty:leaves_0:3)
Block(-17,20,-2,biomesoplenty:leaves_0:3)
Block(-17,20,1,biomesoplenty:leaves_0:3)
Block(-17,20,2,biomesoplenty:leaves_0:3)
Block(-17,20,3,biomesoplenty:log_1:5)
Block(-17,20,4,biomesoplenty:log_1:5)
Block(-17,20,5,biomesoplenty:leaves_0:3)
Block(-17,20,7,biomesoplenty:leaves_0:3)
Block(-17,20,8,biomesoplenty:leaves_0:3)
Block(-17,20,11,biomesoplenty:leaves_0:3)
Block(-17,20,12,biomesoplenty:leaves_0:3)
Block(-17,20,13,biomesoplenty:leaves_0:3)
Block(-17,20,15,biomesoplenty:leaves_0:3)
Block(-17,21,-5,biomesoplenty:leaves_0:3)
Block(-17,21,-4,biomesoplenty:leaves_0:3)
Block(-17,21,-3,biomesoplenty:leaves_0:3)
Block(-17,21,0,biomesoplenty:leaves_0:3)
Block(-17,21,1,biomesoplenty:leaves_0:3)
Block(-17,21,2,biomesoplenty:log_1:5)
Block(-17,21,3,biomesoplenty:log_1:5)
Block(-17,21,4,biomesoplenty:log_1:5)
Block(-17,21,6,biomesoplenty:leaves_0:3)
Block(-17,21,12,biomesoplenty:leaves_0:3)
Block(-17,21,13,biomesoplenty:leaves_0:3)
Block(-17,21,14,biomesoplenty:leaves_0:3)
Block(-17,21,15,biomesoplenty:leaves_0:3)
Block(-17,22,-4,biomesoplenty:leaves_0:3)
Block(-17,22,-1,biomesoplenty:leaves_0:3)
Block(-17,22,0,biomesoplenty:leaves_0:3)
Block(-17,22,1,biomesoplenty:leaves_0:3)
Block(-17,22,2,biomesoplenty:log_1:5)
Block(-17,22,3,biomesoplenty:log_1:5)
Block(-17,22,6,biomesoplenty:leaves_0:3)
Block(-17,22,7,biomesoplenty:leaves_0:3)
Block(-17,22,8,biomesoplenty:leaves_0:3)
Block(-17,22,10,biomesoplenty:leaves_0:3)
Block(-17,22,11,biomesoplenty:leaves_0:3)
Block(-17,22,12,biomesoplenty:leaves_0:3)
Block(-17,22,13,biomesoplenty:leaves_0:3)
Block(-17,22,14,biomesoplenty:leaves_0:3)
Block(-17,23,0,biomesoplenty:leaves_0:3)
Block(-17,23,1,biomesoplenty:leaves_0:3)
Block(-17,23,2,biomesoplenty:leaves_0:3)
Block(-17,23,3,biomesoplenty:leaves_0:3)
Block(-17,23,4,biomesoplenty:leaves_0:3)
Block(-17,23,5,biomesoplenty:leaves_0:3)
Block(-17,23,10,biomesoplenty:leaves_0:3)
Block(-17,23,11,biomesoplenty:leaves_0:3)
Block(-17,23,12,biomesoplenty:leaves_0:3)
Block(-17,23,13,biomesoplenty:leaves_0:3)
Block(-17,23,14,biomesoplenty:leaves_0:3)
Block(-17,23,15,biomesoplenty:leaves_0:3)
Block(-17,24,-1,biomesoplenty:leaves_0:3)
Block(-17,24,0,biomesoplenty:log_1:5)
Block(-17,24,3,biomesoplenty:leaves_0:3)
Block(-17,24,4,biomesoplenty:leaves_0:3)
Block(-17,24,5,biomesoplenty:leaves_0:3)
Block(-17,24,6,biomesoplenty:leaves_0:3)
Block(-17,24,7,biomesoplenty:leaves_0:3)
Block(-17,24,8,biomesoplenty:leaves_0:3)
Block(-17,24,10,biomesoplenty:leaves_0:3)
Block(-17,24,11,biomesoplenty:leaves_0:3)
Block(-17,24,12,biomesoplenty:leaves_0:3)
Block(-17,24,13,biomesoplenty:leaves_0:3)
Block(-17,25,-5,biomesoplenty:leaves_0:3)
Block(-17,25,-4,biomesoplenty:leaves_0:3)
Block(-17,25,-3,biomesoplenty:leaves_0:3)
Block(-17,25,1,biomesoplenty:leaves_0:3)
Block(-17,25,2,biomesoplenty:leaves_0:3)
Block(-17,25,5,biomesoplenty:leaves_0:3)
Block(-17,25,6,biomesoplenty:leaves_0:3)
Block(-17,25,8,biomesoplenty:leaves_0:3)
Block(-17,25,11,biomesoplenty:leaves_0:3)
Block(-17,25,12,biomesoplenty:leaves_0:3)
Block(-17,26,-4,biomesoplenty:leaves_0:3)
Block(-17,26,-3,biomesoplenty:leaves_0:3)
Block(-17,26,-2,biomesoplenty:leaves_0:3)
Block(-17,26,-1,biomesoplenty:leaves_0:3)
Block(-17,26,1,biomesoplenty:leaves_0:3)
Block(-17,26,2,biomesoplenty:leaves_0:3)
Block(-17,27,-6,biomesoplenty:leaves_0:3)
Block(-17,27,-4,biomesoplenty:leaves_0:3)
Block(-17,27,-2,biomesoplenty:leaves_0:3)
Block(-17,27,-1,biomesoplenty:leaves_0:3)
Block(-17,27,0,biomesoplenty:leaves_0:3)
Block(-17,28,0,biomesoplenty:leaves_0:3)
Block(-16,10,13,biomesoplenty:leaves_0:3)
Block(-16,11,9,biomesoplenty:leaves_0:3)
Block(-16,11,10,biomesoplenty:leaves_0:3)
Block(-16,11,11,biomesoplenty:leaves_0:3)
Block(-16,12,8,biomesoplenty:leaves_0:3)
Block(-16,12,9,biomesoplenty:leaves_0:3)
Block(-16,12,10,biomesoplenty:leaves_0:3)
Block(-16,12,11,biomesoplenty:log_1:5)
Block(-16,12,12,biomesoplenty:log_1:5)
Block(-16,12,13,biomesoplenty:leaves_0:3)
Block(-16,12,14,biomesoplenty:leaves_0:3)
Block(-16,13,8,biomesoplenty:leaves_0:3)
Block(-16,13,9,biomesoplenty:leaves_0:3)
Block(-16,13,10,biomesoplenty:leaves_0:3)
Block(-16,13,11,biomesoplenty:leaves_0:3)
Block(-16,13,12,biomesoplenty:leaves_0:3)
Block(-16,13,13,biomesoplenty:leaves_0:3)
Block(-16,13,14,biomesoplenty:leaves_0:3)
Block(-16,13,15,biomesoplenty:leaves_0:3)
Block(-16,14,9,biomesoplenty:leaves_0:3)
Block(-16,14,10,biomesoplenty:leaves_0:3)
Block(-16,14,11,biomesoplenty:leaves_0:3)
Block(-16,14,13,biomesoplenty:leaves_0:3)
Block(-16,14,15,biomesoplenty:leaves_0:3)
Block(-16,14,16,biomesoplenty:leaves_0:3)
Block(-16,15,5,biomesoplenty:leaves_0:3)
Block(-16,15,6,biomesoplenty:leaves_0:3)
Block(-16,15,13,biomesoplenty:log_1:5)
Block(-16,15,14,biomesoplenty:log_1:5)
Block(-16,15,16,biomesoplenty:leaves_0:3)
Block(-16,16,-6,biomesoplenty:leaves_0:3)
Block(-16,16,-4,biomesoplenty:leaves_0:3)
Block(-16,16,-3,biomesoplenty:leaves_0:3)
Block(-16,16,3,biomesoplenty:leaves_0:3)
Block(-16,16,6,biomesoplenty:leaves_0:3)
Block(-16,16,12,biomesoplenty:leaves_0:3)
Block(-16,16,14,biomesoplenty:log_1:5)
Block(-16,16,15,biomesoplenty:log_1:5)
Block(-16,16,16,biomesoplenty:leaves_0:3)
Block(-16,17,-10,biomesoplenty:leaves_0:3)
Block(-16,17,-8,biomesoplenty:leaves_0:3)
Block(-16,17,-6,biomesoplenty:leaves_0:3)
Block(-16,17,-5,biomesoplenty:leaves_0:3)
Block(-16,17,-4,biomesoplenty:leaves_0:3)
Block(-16,17,-3,biomesoplenty:leaves_0:3)
Block(-16,17,-2,biomesoplenty:leaves_0:3)
Block(-16,17,4,biomesoplenty:log_1:5)
Block(-16,17,5,biomesoplenty:leaves_0:3)
Block(-16,17,13,biomesoplenty:leaves_0:3)
Block(-16,17,14,biomesoplenty:leaves_0:3)
Block(-16,17,15,biomesoplenty:leaves_0:3)
Block(-16,17,16,biomesoplenty:leaves_0:3)
Block(-16,17,17,biomesoplenty:leaves_0:3)
Block(-16,18,-9,biomesoplenty:leaves_0:3)
Block(-16,18,-8,biomesoplenty:leaves_0:3)
Block(-16,18,-7,biomesoplenty:leaves_0:3)
Block(-16,18,-6,biomesoplenty:leaves_0:3)
Block(-16,18,-4,biomesoplenty:leaves_0:3)
Block(-16,18,5,biomesoplenty:leaves_0:3)
Block(-16,18,13,biomesoplenty:leaves_0:3)
Block(-16,19,-10,biomesoplenty:leaves_0:3)
Block(-16,19,-9,biomesoplenty:leaves_0:3)
Block(-16,19,-8,biomesoplenty:leaves_0:3)
Block(-16,19,-6,biomesoplenty:leaves_0:3)
Block(-16,19,-5,biomesoplenty:leaves_0:3)
Block(-16,19,-4,biomesoplenty:leaves_0:3)
Block(-16,19,-3,biomesoplenty:leaves_0:3)
Block(-16,19,2,biomesoplenty:leaves_0:3)
Block(-16,19,3,biomesoplenty:leaves_0:3)
Block(-16,19,4,biomesoplenty:log_1:5)
Block(-16,19,6,biomesoplenty:leaves_0:3)
Block(-16,19,10,biomesoplenty:leaves_0:3)
Block(-16,19,11,biomesoplenty:leaves_0:3)
Block(-16,19,12,biomesoplenty:leaves_0:3)
Block(-16,19,14,biomesoplenty:leaves_0:3)
Block(-16,19,15,biomesoplenty:leaves_0:3)
Block(-16,19,16,biomesoplenty:leaves_0:3)
Block(-16,20,-9,biomesoplenty:leaves_0:3)
Block(-16,20,-8,biomesoplenty:leaves_0:3)
Block(-16,20,-7,biomesoplenty:leaves_0:3)
Block(-16,20,-6,biomesoplenty:leaves_0:3)
Block(-16,20,-5,biomesoplenty:leaves_0:3)
Block(-16,20,-4,biomesoplenty:leaves_0:3)
Block(-16,20,-3,biomesoplenty:leaves_0:3)
Block(-16,20,-2,biomesoplenty:leaves_0:3)
Block(-16,20,-1,biomesoplenty:leaves_0:3)
Block(-16,20,1,biomesoplenty:leaves_0:3)
Block(-16,20,2,biomesoplenty:leaves_0:3)
Block(-16,20,3,biomesoplenty:leaves_0:3)
Block(-16,20,4,biomesoplenty:log_1:5)
Block(-16,20,5,biomesoplenty:leaves_0:3)
Block(-16,20,7,biomesoplenty:leaves_0:3)
Block(-16,20,9,biomesoplenty:leaves_0:3)
Block(-16,20,10,biomesoplenty:leaves_0:3)
Block(-16,20,11,biomesoplenty:leaves_0:3)
Block(-16,20,12,biomesoplenty:leaves_0:3)
Block(-16,20,13,biomesoplenty:leaves_0:3)
Block(-16,20,14,biomesoplenty:leaves_0:3)
Block(-16,21,-7,biomesoplenty:leaves_0:3)
Block(-16,21,-5,biomesoplenty:leaves_0:3)
Block(-16,21,-4,biomesoplenty:leaves_0:3)
Block(-16,21,-3,biomesoplenty:leaves_0:3)
Block(-16,21,3,biomesoplenty:leaves_0:3)
Block(-16,21,4,biomesoplenty:leaves_0:3)
Block(-16,21,5,biomesoplenty:leaves_0:3)
Block(-16,21,7,biomesoplenty:leaves_0:3)
Block(-16,21,10,biomesoplenty:leaves_0:3)
Block(-16,21,12,biomesoplenty:leaves_0:3)
Block(-16,21,13,biomesoplenty:leaves_0:3)
Block(-16,21,14,biomesoplenty:leaves_0:3)
Block(-16,21,15,biomesoplenty:leaves_0:3)
Block(-16,22,-4,biomesoplenty:leaves_0:3)
Block(-16,22,0,biomesoplenty:leaves_0:3)
Block(-16,22,1,biomesoplenty:leaves_0:3)
Block(-16,22,2,biomesoplenty:leaves_0:3)
Block(-16,22,3,biomesoplenty:leaves_0:3)
Block(-16,22,8,biomesoplenty:leaves_0:3)
Block(-16,22,10,biomesoplenty:leaves_0:3)
Block(-16,22,11,biomesoplenty:leaves_0:3)
Block(-16,22,12,biomesoplenty:leaves_0:3)
Block(-16,22,14,biomesoplenty:leaves_0:3)
Block(-16,23,-4,biomesoplenty:leaves_0:3)
Block(-16,23,2,biomesoplenty:leaves_0:3)
Block(-16,23,3,biomesoplenty:leaves_0:3)
Block(-16,23,8,biomesoplenty:leaves_0:3)
Block(-16,23,9,biomesoplenty:leaves_0:3)
Block(-16,23,10,biomesoplenty:leaves_0:3)
Block(-16,23,12,biomesoplenty:leaves_0:3)
Block(-16,24,-4,biomesoplenty:leaves_0:3)
Block(-16,24,-3,biomesoplenty:leaves_0:3)
Block(-16,24,3,biomesoplenty:leaves_0:3)
Block(-16,24,4,biomesoplenty:leaves_0:3)
Block(-16,24,5,biomesoplenty:leaves_0:3)
Block(-16,24,6,biomesoplenty:leaves_0:3)
Block(-16,24,7,biomesoplenty:leaves_0:3)
Block(-16,24,8,biomesoplenty:leaves_0:3)
Block(-16,24,9,biomesoplenty:leaves_0:3)
Block(-16,24,10,biomesoplenty:leaves_0:3)
Block(-16,24,11,biomesoplenty:leaves_0:3)
Block(-16,24,12,biomesoplenty:leaves_0:3)
Block(-16,24,13,biomesoplenty:leaves_0:3)
Block(-16,24,14,biomesoplenty:leaves_0:3)
Block(-16,24,15,biomesoplenty:leaves_0:3)
Block(-16,25,-5,biomesoplenty:leaves_0:3)
Block(-16,25,-4,biomesoplenty:leaves_0:3)
Block(-16,25,-3,biomesoplenty:leaves_0:3)
Block(-16,25,-2,biomesoplenty:leaves_0:3)
Block(-16,25,-1,biomesoplenty:log_1:5)
Block(-16,25,3,biomesoplenty:leaves_0:3)
Block(-16,25,4,biomesoplenty:leaves_0:3)
Block(-16,25,5,biomesoplenty:leaves_0:3)
Block(-16,25,6,biomesoplenty:leaves_0:3)
Block(-16,25,7,biomesoplenty:leaves_0:3)
Block(-16,25,8,biomesoplenty:leaves_0:3)
Block(-16,25,10,biomesoplenty:leaves_0:3)
Block(-16,25,12,biomesoplenty:leaves_0:3)
Block(-16,26,-7,biomesoplenty:leaves_0:3)
Block(-16,26,-6,biomesoplenty:leaves_0:3)
Block(-16,26,-5,biomesoplenty:leaves_0:3)
Block(-16,26,-4,biomesoplenty:leaves_0:3)
Block(-16,26,-3,biomesoplenty:leaves_0:3)
Block(-16,26,-2,biomesoplenty:leaves_0:3)
Block(-16,26,5,biomesoplenty:leaves_0:3)
Block(-16,26,11,biomesoplenty:leaves_0:3)
Block(-16,26,13,biomesoplenty:leaves_0:3)
Block(-16,27,-6,biomesoplenty:leaves_0:3)
Block(-16,27,-5,biomesoplenty:leaves_0:3)
Block(-16,27,-4,biomesoplenty:leaves_0:3)
Block(-16,27,-3,biomesoplenty:leaves_0:3)
Block(-16,27,-2,biomesoplenty:leaves_0:3)
Block(-16,27,1,biomesoplenty:leaves_0:3)
Block(-16,28,-6,biomesoplenty:leaves_0:3)
Block(-16,28,-1,biomesoplenty:leaves_0:3)
Block(-16,28,0,biomesoplenty:leaves_0:3)
Block(-15,9,12,biomesoplenty:leaves_0:3)
Block(-15,10,13,biomesoplenty:leaves_0:3)
Block(-15,10,14,biomesoplenty:leaves_0:3)
Block(-15,11,12,biomesoplenty:leaves_0:3)
Block(-15,12,8,biomesoplenty:leaves_0:3)
Block(-15,12,9,biomesoplenty:leaves_0:3)
Block(-15,12,10,biomesoplenty:leaves_0:3)
Block(-15,12,11,biomesoplenty:leaves_0:3)
Block(-15,12,12,biomesoplenty:log_1:5)
Block(-15,12,13,biomesoplenty:leaves_0:3)
Block(-15,12,14,biomesoplenty:leaves_0:3)
Block(-15,12,15,biomesoplenty:leaves_0:3)
Block(-15,13,9,biomesoplenty:leaves_0:3)
Block(-15,13,10,biomesoplenty:leaves_0:3)
Block(-15,13,11,biomesoplenty:leaves_0:3)
Block(-15,13,12,biomesoplenty:log_1:5)
Block(-15,13,15,biomesoplenty:leaves_0:3)
Block(-15,14,10,biomesoplenty:leaves_0:3)
Block(-15,14,11,biomesoplenty:leaves_0:3)
Block(-15,14,12,biomesoplenty:log_1:5)
Block(-15,14,13,biomesoplenty:log_1:5)
Block(-15,14,14,biomesoplenty:leaves_0:3)
Block(-15,14,15,biomesoplenty:leaves_0:3)
Block(-15,14,17,biomesoplenty:leaves_0:3)
Block(-15,15,11,biomesoplenty:leaves_0:3)
Block(-15,15,12,biomesoplenty:leaves_0:3)
Block(-15,15,13,biomesoplenty:log_1:5)
Block(-15,15,15,biomesoplenty:leaves_0:3)
Block(-15,15,17,biomesoplenty:leaves_0:3)
Block(-15,16,-7,biomesoplenty:leaves_0:3)
Block(-15,16,-6,biomesoplenty:leaves_0:3)
Block(-15,16,-4,biomesoplenty:leaves_0:3)
Block(-15,16,14,biomesoplenty:leaves_0:3)
Block(-15,16,15,biomesoplenty:leaves_0:3)
Block(-15,17,-9,biomesoplenty:leaves_0:3)
Block(-15,17,-6,biomesoplenty:leaves_0:3)
Block(-15,17,-5,biomesoplenty:leaves_0:3)
Block(-15,17,-4,biomesoplenty:leaves_0:3)
Block(-15,17,-2,biomesoplenty:leaves_0:3)
Block(-15,17,-1,biomesoplenty:leaves_0:3)
Block(-15,17,4,biomesoplenty:log_1:5)
Block(-15,17,13,biomesoplenty:leaves_0:3)
Block(-15,17,14,biomesoplenty:leaves_0:3)
Block(-15,17,15,biomesoplenty:leaves_0:3)
Block(-15,17,16,biomesoplenty:leaves_0:3)
Block(-15,17,17,biomesoplenty:leaves_0:3)
Block(-15,18,-11,biomesoplenty:leaves_0:3)
Block(-15,18,-10,biomesoplenty:leaves_0:3)
Block(-15,18,-9,biomesoplenty:leaves_0:3)
Block(-15,18,-8,biomesoplenty:leaves_0:3)
Block(-15,18,-7,biomesoplenty:leaves_0:3)
Block(-15,18,-4,biomesoplenty:log_1:5)
Block(-15,18,2,biomesoplenty:log_1:5)
Block(-15,18,3,biomesoplenty:log_1:5)
Block(-15,18,4,biomesoplenty:log_1:5)
Block(-15,18,5,biomesoplenty:leaves_0:3)
Block(-15,18,13,biomesoplenty:leaves_0:3)
Block(-15,18,15,biomesoplenty:leaves_0:3)
Block(-15,19,-10,biomesoplenty:leaves_0:3)
Block(-15,19,-9,biomesoplenty:leaves_0:3)
Block(-15,19,-8,biomesoplenty:leaves_0:3)
Block(-15,19,-5,biomesoplenty:leaves_0:3)
Block(-15,19,-4,biomesoplenty:log_1:5)
Block(-15,19,-3,biomesoplenty:leaves_0:3)
Block(-15,19,2,biomesoplenty:leaves_0:3)
Block(-15,19,3,biomesoplenty:leaves_0:3)
Block(-15,19,4,biomesoplenty:log_1:5)
Block(-15,19,13,biomesoplenty:leaves_0:3)
Block(-15,19,14,biomesoplenty:leaves_0:3)
Block(-15,19,15,biomesoplenty:leaves_0:3)
Block(-15,20,-11,biomesoplenty:leaves_0:3)
Block(-15,20,-10,biomesoplenty:leaves_0:3)
Block(-15,20,-9,biomesoplenty:leaves_0:3)
Block(-15,20,-8,biomesoplenty:leaves_0:3)
Block(-15,20,-7,biomesoplenty:leaves_0:3)
Block(-15,20,-6,biomesoplenty:leaves_0:3)
Block(-15,20,-5,biomesoplenty:leaves_0:3)
Block(-15,20,-4,biomesoplenty:leaves_0:3)
Block(-15,20,-3,biomesoplenty:leaves_0:3)
Block(-15,20,-2,biomesoplenty:leaves_0:3)
Block(-15,20,3,biomesoplenty:leaves_0:3)
Block(-15,20,4,biomesoplenty:leaves_0:3)
Block(-15,20,5,biomesoplenty:leaves_0:3)
Block(-15,20,6,biomesoplenty:leaves_0:3)
Block(-15,20,8,biomesoplenty:leaves_0:3)
Block(-15,20,9,biomesoplenty:leaves_0:3)
Block(-15,20,12,biomesoplenty:leaves_0:3)
Block(-15,20,13,biomesoplenty:leaves_0:3)
Block(-15,20,14,biomesoplenty:leaves_0:3)
Block(-15,20,15,biomesoplenty:leaves_0:3)
Block(-15,21,-8,biomesoplenty:leaves_0:3)
Block(-15,21,-7,biomesoplenty:leaves_0:3)
Block(-15,21,-6,biomesoplenty:leaves_0:3)
Block(-15,21,-4,biomesoplenty:leaves_0:3)
Block(-15,21,-3,biomesoplenty:leaves_0:3)
Block(-15,21,-2,biomesoplenty:leaves_0:3)
Block(-15,21,3,biomesoplenty:leaves_0:3)
Block(-15,21,5,biomesoplenty:leaves_0:3)
Block(-15,21,7,biomesoplenty:leaves_0:3)
Block(-15,21,8,biomesoplenty:leaves_0:3)
Block(-15,21,9,biomesoplenty:leaves_0:3)
Block(-15,21,10,biomesoplenty:leaves_0:3)
Block(-15,21,11,biomesoplenty:leaves_0:3)
Block(-15,21,13,biomesoplenty:leaves_0:3)
Block(-15,22,-6,biomesoplenty:leaves_0:3)
Block(-15,22,-3,biomesoplenty:leaves_0:3)
Block(-15,22,4,biomesoplenty:leaves_0:3)
Block(-15,22,5,biomesoplenty:leaves_0:3)
Block(-15,22,6,biomesoplenty:leaves_0:3)
Block(-15,22,8,biomesoplenty:log_1:5)
Block(-15,22,9,biomesoplenty:log_1:5)
Block(-15,22,12,biomesoplenty:leaves_0:3)
Block(-15,23,-4,biomesoplenty:leaves_0:3)
Block(-15,23,-3,biomesoplenty:leaves_0:3)
Block(-15,23,-2,biomesoplenty:leaves_0:3)
Block(-15,23,2,biomesoplenty:leaves_0:3)
Block(-15,23,4,biomesoplenty:leaves_0:3)
Block(-15,23,5,biomesoplenty:leaves_0:3)
Block(-15,23,6,biomesoplenty:leaves_0:3)
Block(-15,23,8,biomesoplenty:leaves_0:3)
Block(-15,23,13,biomesoplenty:leaves_0:3)
Block(-15,23,14,biomesoplenty:leaves_0:3)
Block(-15,23,15,biomesoplenty:leaves_0:3)
Block(-15,24,-2,biomesoplenty:leaves_0:3)
Block(-15,24,-1,biomesoplenty:leaves_0:3)
Block(-15,24,3,biomesoplenty:leaves_0:3)
Block(-15,24,4,biomesoplenty:leaves_0:3)
Block(-15,24,5,biomesoplenty:leaves_0:3)
Block(-15,24,7,biomesoplenty:leaves_0:3)
Block(-15,24,10,biomesoplenty:leaves_0:3)
Block(-15,24,11,biomesoplenty:leaves_0:3)
Block(-15,24,12,biomesoplenty:leaves_0:3)
Block(-15,24,14,biomesoplenty:leaves_0:3)
Block(-15,25,-7,biomesoplenty:leaves_0:3)
Block(-15,25,-6,biomesoplenty:leaves_0:3)
Block(-15,25,-5,biomesoplenty:leaves_0:3)
Block(-15,25,-4,biomesoplenty:leaves_0:3)
Block(-15,25,-3,biomesoplenty:leaves_0:3)
Block(-15,25,-1,biomesoplenty:leaves_0:3)
Block(-15,25,0,biomesoplenty:leaves_0:3)
Block(-15,25,3,biomesoplenty:leaves_0:3)
Block(-15,25,4,biomesoplenty:leaves_0:3)
Block(-15,25,5,biomesoplenty:leaves_0:3)
Block(-15,25,7,biomesoplenty:leaves_0:3)
Block(-15,25,8,biomesoplenty:leaves_0:3)
Block(-15,25,9,biomesoplenty:leaves_0:3)
Block(-15,25,10,biomesoplenty:leaves_0:3)
Block(-15,25,11,biomesoplenty:leaves_0:3)
Block(-15,25,12,biomesoplenty:leaves_0:3)
Block(-15,25,14,biomesoplenty:leaves_0:3)
Block(-15,26,-5,biomesoplenty:leaves_0:3)
Block(-15,26,-4,biomesoplenty:leaves_0:3)
Block(-15,26,-3,biomesoplenty:leaves_0:3)
Block(-15,26,-2,biomesoplenty:leaves_0:3)
Block(-15,26,-1,biomesoplenty:leaves_0:3)
Block(-15,26,0,biomesoplenty:leaves_0:3)
Block(-15,26,4,biomesoplenty:leaves_0:3)
Block(-15,26,5,biomesoplenty:leaves_0:3)
Block(-15,26,6,biomesoplenty:leaves_0:3)
Block(-15,26,8,biomesoplenty:leaves_0:3)
Block(-15,26,10,biomesoplenty:leaves_0:3)
Block(-15,26,11,biomesoplenty:leaves_0:3)
Block(-15,26,13,biomesoplenty:leaves_0:3)
Block(-15,26,14,biomesoplenty:leaves_0:3)
Block(-15,27,-5,biomesoplenty:leaves_0:3)
Block(-15,27,-4,biomesoplenty:leaves_0:3)
Block(-15,27,-2,biomesoplenty:leaves_0:3)
Block(-15,27,-1,biomesoplenty:leaves_0:3)
Block(-15,27,11,biomesoplenty:leaves_0:3)
Block(-15,28,-5,biomesoplenty:leaves_0:3)
Block(-15,28,0,biomesoplenty:leaves_0:3)
Block(-14,9,13,biomesoplenty:leaves_0:3)
Block(-14,10,11,biomesoplenty:leaves_0:3)
Block(-14,10,12,biomesoplenty:leaves_0:3)
Block(-14,10,13,biomesoplenty:leaves_0:3)
Block(-14,10,14,biomesoplenty:leaves_0:3)
Block(-14,10,15,biomesoplenty:leaves_0:3)
Block(-14,11,10,biomesoplenty:leaves_0:3)
Block(-14,11,12,biomesoplenty:leaves_0:3)
Block(-14,11,13,biomesoplenty:leaves_0:3)
Block(-14,11,14,biomesoplenty:leaves_0:3)
Block(-14,11,15,biomesoplenty:leaves_0:3)
Block(-14,12,11,biomesoplenty:leaves_0:3)
Block(-14,12,12,biomesoplenty:leaves_0:3)
Block(-14,12,14,biomesoplenty:leaves_0:3)
Block(-14,12,15,biomesoplenty:leaves_0:3)
Block(-14,13,10,biomesoplenty:leaves_0:3)
Block(-14,13,11,biomesoplenty:leaves_0:3)
Block(-14,13,12,biomesoplenty:leaves_0:3)
Block(-14,13,14,biomesoplenty:leaves_0:3)
Block(-14,13,15,biomesoplenty:leaves_0:3)
Block(-14,13,16,biomesoplenty:leaves_0:3)
Block(-14,14,11,biomesoplenty:leaves_0:3)
Block(-14,14,12,biomesoplenty:leaves_0:3)
Block(-14,14,13,biomesoplenty:log_1:5)
Block(-14,14,14,biomesoplenty:leaves_0:3)
Block(-14,14,15,biomesoplenty:leaves_0:3)
Block(-14,14,16,biomesoplenty:leaves_0:3)
Block(-14,15,-9,biomesoplenty:leaves_0:3)
Block(-14,15,-8,biomesoplenty:leaves_0:3)
Block(-14,15,-7,biomesoplenty:leaves_0:3)
Block(-14,15,-5,biomesoplenty:leaves_0:3)
Block(-14,15,12,biomesoplenty:leaves_0:3)
Block(-14,15,13,biomesoplenty:leaves_0:3)
Block(-14,15,15,biomesoplenty:leaves_0:3)
Block(-14,16,-10,biomesoplenty:leaves_0:3)
Block(-14,16,-8,biomesoplenty:leaves_0:3)
Block(-14,16,-7,biomesoplenty:leaves_0:3)
Block(-14,16,-6,biomesoplenty:leaves_0:3)
Block(-14,16,-5,biomesoplenty:leaves_0:3)
Block(-14,16,15,biomesoplenty:leaves_0:3)
Block(-14,16,16,biomesoplenty:leaves_0:3)
Block(-14,16,17,biomesoplenty:leaves_0:3)
Block(-14,17,-11,biomesoplenty:leaves_0:3)
Block(-14,17,-10,biomesoplenty:leaves_0:3)
Block(-14,17,-5,biomesoplenty:leaves_0:3)
Block(-14,17,-4,biomesoplenty:log_1:5)
Block(-14,17,-2,biomesoplenty:leaves_0:3)
Block(-14,17,0,biomesoplenty:log_1:5)
Block(-14,17,1,biomesoplenty:log_1:5)
Block(-14,17,15,biomesoplenty:leaves_0:3)
Block(-14,18,-10,biomesoplenty:leaves_0:3)
Block(-14,18,-9,biomesoplenty:leaves_0:3)
Block(-14,18,-8,biomesoplenty:leaves_0:3)
Block(-14,18,-5,biomesoplenty:log_1:5)
Block(-14,18,-4,biomesoplenty:log_1:5)
Block(-14,18,-3,biomesoplenty:leaves_0:3)
Block(-14,18,-2,biomesoplenty:leaves_0:3)
Block(-14,18,-1,biomesoplenty:leaves_0:3)
Block(-14,18,1,biomesoplenty:log_1:5)
Block(-14,18,2,biomesoplenty:log_1:5)
Block(-14,18,3,biomesoplenty:log_1:5)
Block(-14,18,4,biomesoplenty:log_1:5)
Block(-14,19,-11,biomesoplenty:leaves_0:3)
Block(-14,19,-9,biomesoplenty:leaves_0:3)
Block(-14,19,-3,biomesoplenty:leaves_0:3)
Block(-14,19,3,biomesoplenty:log_1:5)
Block(-14,19,4,biomesoplenty:log_1:5)
Block(-14,19,5,biomesoplenty:leaves_0:3)
Block(-14,20,-10,biomesoplenty:leaves_0:3)
Block(-14,20,-9,biomesoplenty:leaves_0:3)
Block(-14,20,-8,biomesoplenty:leaves_0:3)
Block(-14,20,-5,biomesoplenty:leaves_0:3)
Block(-14,20,-4,biomesoplenty:leaves_0:3)
Block(-14,20,-3,biomesoplenty:leaves_0:3)
Block(-14,20,3,biomesoplenty:leaves_0:3)
Block(-14,20,4,biomesoplenty:leaves_0:3)
Block(-14,20,5,biomesoplenty:leaves_0:3)
Block(-14,20,6,biomesoplenty:leaves_0:3)
Block(-14,20,8,biomesoplenty:leaves_0:3)
Block(-14,20,10,biomesoplenty:leaves_0:3)
Block(-14,20,12,biomesoplenty:leaves_0:3)
Block(-14,20,13,biomesoplenty:leaves_0:3)
Block(-14,21,-9,biomesoplenty:leaves_0:3)
Block(-14,21,-8,biomesoplenty:leaves_0:3)
Block(-14,21,-6,biomesoplenty:leaves_0:3)
Block(-14,21,-3,biomesoplenty:leaves_0:3)
Block(-14,21,-2,biomesoplenty:leaves_0:3)
Block(-14,21,3,biomesoplenty:leaves_0:3)
Block(-14,21,4,biomesoplenty:leaves_0:3)
Block(-14,21,5,biomesoplenty:leaves_0:3)
Block(-14,21,6,biomesoplenty:leaves_0:3)
Block(-14,21,7,biomesoplenty:leaves_0:3)
Block(-14,21,9,biomesoplenty:log_1:5)
Block(-14,21,10,biomesoplenty:log_1:5)
Block(-14,21,11,biomesoplenty:leaves_0:3)
Block(-14,21,12,biomesoplenty:leaves_0:3)
Block(-14,22,-8,biomesoplenty:leaves_0:3)
Block(-14,22,-7,biomesoplenty:leaves_0:3)
Block(-14,22,-6,biomesoplenty:leaves_0:3)
Block(-14,22,-5,biomesoplenty:leaves_0:3)
Block(-14,22,5,biomesoplenty:leaves_0:3)
Block(-14,22,9,biomesoplenty:log_1:5)
Block(-14,22,10,biomesoplenty:leaves_0:3)
Block(-14,22,11,biomesoplenty:leaves_0:3)
Block(-14,22,12,biomesoplenty:leaves_0:3)
Block(-14,23,-7,biomesoplenty:leaves_0:3)
Block(-14,23,-6,biomesoplenty:leaves_0:3)
Block(-14,23,-4,biomesoplenty:leaves_0:3)
Block(-14,23,-3,biomesoplenty:leaves_0:3)
Block(-14,23,-2,biomesoplenty:leaves_0:3)
Block(-14,23,6,biomesoplenty:leaves_0:3)
Block(-14,23,8,biomesoplenty:leaves_0:3)
Block(-14,23,9,biomesoplenty:leaves_0:3)
Block(-14,23,10,biomesoplenty:leaves_0:3)
Block(-14,23,13,biomesoplenty:leaves_0:3)
Block(-14,23,14,biomesoplenty:leaves_0:3)
Block(-14,23,15,biomesoplenty:leaves_0:3)
Block(-14,24,-8,biomesoplenty:leaves_0:3)
Block(-14,24,-7,biomesoplenty:leaves_0:3)
Block(-14,24,-5,biomesoplenty:leaves_0:3)
Block(-14,24,-3,biomesoplenty:leaves_0:3)
Block(-14,24,-1,biomesoplenty:leaves_0:3)
Block(-14,24,8,biomesoplenty:leaves_0:3)
Block(-14,24,10,biomesoplenty:leaves_0:3)
Block(-14,24,14,biomesoplenty:leaves_0:3)
Block(-14,24,15,biomesoplenty:leaves_0:3)
Block(-14,24,16,biomesoplenty:leaves_0:3)
Block(-14,25,-7,biomesoplenty:leaves_0:3)
Block(-14,25,-6,biomesoplenty:leaves_0:3)
Block(-14,25,-5,biomesoplenty:leaves_0:3)
Block(-14,25,-1,biomesoplenty:leaves_0:3)
Block(-14,25,7,biomesoplenty:leaves_0:3)
Block(-14,25,8,biomesoplenty:leaves_0:3)
Block(-14,25,10,biomesoplenty:leaves_0:3)
Block(-14,25,13,biomesoplenty:leaves_0:3)
Block(-14,25,14,biomesoplenty:leaves_0:3)
Block(-14,26,-7,biomesoplenty:leaves_0:3)
Block(-14,26,-6,biomesoplenty:leaves_0:3)
Block(-14,26,-5,biomesoplenty:leaves_0:3)
Block(-14,26,-3,biomesoplenty:leaves_0:3)
Block(-14,26,-2,biomesoplenty:leaves_0:3)
Block(-14,26,-1,biomesoplenty:leaves_0:3)
Block(-14,26,3,biomesoplenty:leaves_0:3)
Block(-14,26,4,biomesoplenty:leaves_0:3)
Block(-14,26,5,biomesoplenty:leaves_0:3)
Block(-14,26,6,biomesoplenty:leaves_0:3)
Block(-14,26,7,biomesoplenty:leaves_0:3)
Block(-14,26,8,biomesoplenty:leaves_0:3)
Block(-14,26,9,biomesoplenty:leaves_0:3)
Block(-14,26,11,biomesoplenty:leaves_0:3)
Block(-14,26,12,biomesoplenty:leaves_0:3)
Block(-14,26,13,biomesoplenty:leaves_0:3)
Block(-14,26,15,biomesoplenty:leaves_0:3)
Block(-14,26,16,biomesoplenty:leaves_0:3)
Block(-14,27,-6,biomesoplenty:leaves_0:3)
Block(-14,27,-4,biomesoplenty:leaves_0:3)
Block(-14,27,-3,biomesoplenty:leaves_0:3)
Block(-14,27,-1,biomesoplenty:leaves_0:3)
Block(-14,27,6,biomesoplenty:leaves_0:3)
Block(-14,27,7,biomesoplenty:leaves_0:3)
Block(-14,27,8,biomesoplenty:leaves_0:3)
Block(-14,27,11,biomesoplenty:leaves_0:3)
Block(-14,27,13,biomesoplenty:leaves_0:3)
Block(-14,27,14,biomesoplenty:leaves_0:3)
Block(-14,27,15,biomesoplenty:leaves_0:3)
Block(-14,27,16,biomesoplenty:leaves_0:3)
Block(-14,27,17,biomesoplenty:leaves_0:3)
Block(-14,28,-6,biomesoplenty:leaves_0:3)
Block(-14,28,-5,biomesoplenty:leaves_0:3)
Block(-14,28,-4,biomesoplenty:leaves_0:3)
Block(-14,28,15,biomesoplenty:leaves_0:3)
Block(-14,28,16,biomesoplenty:leaves_0:3)
Block(-13,10,10,biomesoplenty:leaves_0:3)
Block(-13,10,11,biomesoplenty:leaves_0:3)
Block(-13,10,12,biomesoplenty:leaves_0:3)
Block(-13,10,14,biomesoplenty:leaves_0:3)
Block(-13,10,16,biomesoplenty:leaves_0:3)
Block(-13,11,11,biomesoplenty:leaves_0:3)
Block(-13,11,12,biomesoplenty:leaves_0:3)
Block(-13,11,13,biomesoplenty:leaves_0:3)
Block(-13,11,14,biomesoplenty:leaves_0:3)
Block(-13,11,16,biomesoplenty:leaves_0:3)
Block(-13,11,17,biomesoplenty:leaves_0:3)
Block(-13,12,10,biomesoplenty:leaves_0:3)
Block(-13,12,11,biomesoplenty:leaves_0:3)
Block(-13,12,12,biomesoplenty:leaves_0:3)
Block(-13,12,15,biomesoplenty:leaves_0:3)
Block(-13,12,16,biomesoplenty:leaves_0:3)
Block(-13,13,10,biomesoplenty:leaves_0:3)
Block(-13,13,11,biomesoplenty:leaves_0:3)
Block(-13,13,12,biomesoplenty:leaves_0:3)
Block(-13,13,13,biomesoplenty:leaves_0:3)
Block(-13,14,-10,biomesoplenty:leaves_0:3)
Block(-13,14,-9,biomesoplenty:leaves_0:3)
Block(-13,14,-6,biomesoplenty:leaves_0:3)
Block(-13,14,10,biomesoplenty:leaves_0:3)
Block(-13,14,11,biomesoplenty:leaves_0:3)
Block(-13,14,12,biomesoplenty:log_1:5)
Block(-13,14,13,biomesoplenty:log_1:5)
Block(-13,14,14,biomesoplenty:leaves_0:3)
Block(-13,14,16,biomesoplenty:leaves_0:3)
Block(-13,14,17,biomesoplenty:leaves_0:3)
Block(-13,15,-9,biomesoplenty:leaves_0:3)
Block(-13,15,-5,biomesoplenty:leaves_0:3)
Block(-13,15,16,biomesoplenty:leaves_0:3)
Block(-13,16,-11,biomesoplenty:leaves_0:3)
Block(-13,16,-10,biomesoplenty:leaves_0:3)
Block(-13,16,-9,biomesoplenty:leaves_0:3)
Block(-13,16,-8,biomesoplenty:leaves_0:3)
Block(-13,16,-7,biomesoplenty:leaves_0:3)
Block(-13,16,-4,biomesoplenty:log_1:5)
Block(-13,16,-3,biomesoplenty:log_1:5)
Block(-13,16,-2,biomesoplenty:log_1:5)
Block(-13,16,0,biomesoplenty:log_1:5)
Block(-13,16,16,biomesoplenty:leaves_0:3)
Block(-13,16,17,biomesoplenty:leaves_0:3)
Block(-13,17,-11,biomesoplenty:leaves_0:3)
Block(-13,17,-8,biomesoplenty:leaves_0:3)
Block(-13,17,-7,biomesoplenty:leaves_0:3)
Block(-13,17,-4,biomesoplenty:log_1:5)
Block(-13,17,0,biomesoplenty:log_1:5)
Block(-13,17,1,biomesoplenty:log_1:5)
Block(-13,18,-13,biomesoplenty:leaves_0:3)
Block(-13,18,-12,biomesoplenty:leaves_0:3)
Block(-13,18,-11,biomesoplenty:leaves_0:3)
Block(-13,18,-10,biomesoplenty:leaves_0:3)
Block(-13,18,-9,biomesoplenty:leaves_0:3)
Block(-13,18,-8,biomesoplenty:leaves_0:3)
Block(-13,18,-7,biomesoplenty:leaves_0:3)
Block(-13,18,-6,biomesoplenty:leaves_0:3)
Block(-13,18,-4,biomesoplenty:log_1:5)
Block(-13,19,-12,biomesoplenty:leaves_0:3)
Block(-13,19,-11,biomesoplenty:leaves_0:3)
Block(-13,19,-10,biomesoplenty:leaves_0:3)
Block(-13,19,-9,biomesoplenty:leaves_0:3)
Block(-13,19,-8,biomesoplenty:leaves_0:3)
Block(-13,19,-7,biomesoplenty:leaves_0:3)
Block(-13,19,-4,biomesoplenty:leaves_0:3)
Block(-13,19,4,biomesoplenty:log_1:5)
Block(-13,20,-11,biomesoplenty:leaves_0:3)
Block(-13,20,-10,biomesoplenty:leaves_0:3)
Block(-13,20,-8,biomesoplenty:leaves_0:3)
Block(-13,20,-6,biomesoplenty:leaves_0:3)
Block(-13,20,-3,biomesoplenty:leaves_0:3)
Block(-13,20,3,biomesoplenty:log_1:5)
Block(-13,20,4,biomesoplenty:log_1:5)
Block(-13,20,7,biomesoplenty:leaves_0:3)
Block(-13,20,8,biomesoplenty:leaves_0:3)
Block(-13,20,10,biomesoplenty:leaves_0:3)
Block(-13,20,11,biomesoplenty:leaves_0:3)
Block(-13,21,-10,biomesoplenty:leaves_0:3)
Block(-13,21,-9,biomesoplenty:leaves_0:3)
Block(-13,21,-6,biomesoplenty:leaves_0:3)
Block(-13,21,-4,biomesoplenty:leaves_0:3)
Block(-13,21,3,biomesoplenty:log_1:5)
Block(-13,21,5,biomesoplenty:leaves_0:3)
Block(-13,21,6,biomesoplenty:leaves_0:3)
Block(-13,21,9,biomesoplenty:log_1:5)
Block(-13,21,10,biomesoplenty:log_1:5)
Block(-13,21,11,biomesoplenty:log_1:5)
Block(-13,21,12,biomesoplenty:leaves_0:3)
Block(-13,22,-8,biomesoplenty:leaves_0:3)
Block(-13,22,-7,biomesoplenty:leaves_0:3)
Block(-13,22,-6,biomesoplenty:leaves_0:3)
Block(-13,22,6,biomesoplenty:leaves_0:3)
Block(-13,22,8,biomesoplenty:leaves_0:3)
Block(-13,22,9,biomesoplenty:leaves_0:3)
Block(-13,22,10,biomesoplenty:leaves_0:3)
Block(-13,22,11,biomesoplenty:leaves_0:3)
Block(-13,23,-6,biomesoplenty:leaves_0:3)
Block(-13,23,-4,biomesoplenty:leaves_0:3)
Block(-13,23,12,biomesoplenty:leaves_0:3)
Block(-13,23,13,biomesoplenty:leaves_0:3)
Block(-13,23,14,biomesoplenty:leaves_0:3)
Block(-13,23,15,biomesoplenty:leaves_0:3)
Block(-13,24,-6,biomesoplenty:leaves_0:3)
Block(-13,24,-5,biomesoplenty:leaves_0:3)
Block(-13,24,-4,biomesoplenty:leaves_0:3)
Block(-13,24,-3,biomesoplenty:leaves_0:3)
Block(-13,24,13,biomesoplenty:leaves_0:3)
Block(-13,24,15,biomesoplenty:leaves_0:3)
Block(-13,25,-7,biomesoplenty:leaves_0:3)
Block(-13,25,-5,biomesoplenty:leaves_0:3)
Block(-13,25,4,biomesoplenty:leaves_0:3)
Block(-13,25,5,biomesoplenty:leaves_0:3)
Block(-13,25,6,biomesoplenty:leaves_0:3)
Block(-13,25,7,biomesoplenty:leaves_0:3)
Block(-13,25,8,biomesoplenty:leaves_0:3)
Block(-13,25,11,biomesoplenty:leaves_0:3)
Block(-13,25,13,biomesoplenty:leaves_0:3)
Block(-13,25,15,biomesoplenty:leaves_0:3)
Block(-13,25,16,biomesoplenty:leaves_0:3)
Block(-13,25,17,biomesoplenty:leaves_0:3)
Block(-13,26,-7,biomesoplenty:leaves_0:3)
Block(-13,26,-5,biomesoplenty:leaves_0:3)
Block(-13,26,-4,biomesoplenty:leaves_0:3)
Block(-13,26,-2,biomesoplenty:leaves_0:3)
Block(-13,26,3,biomesoplenty:leaves_0:3)
Block(-13,26,4,biomesoplenty:leaves_0:3)
Block(-13,26,7,biomesoplenty:leaves_0:3)
Block(-13,26,8,biomesoplenty:leaves_0:3)
Block(-13,26,9,biomesoplenty:leaves_0:3)
Block(-13,26,14,biomesoplenty:log_1:5)
Block(-13,26,17,biomesoplenty:leaves_0:3)
Block(-13,27,-6,biomesoplenty:leaves_0:3)
Block(-13,27,-5,biomesoplenty:leaves_0:3)
Block(-13,27,-3,biomesoplenty:leaves_0:3)
Block(-13,27,-2,biomesoplenty:leaves_0:3)
Block(-13,27,3,biomesoplenty:leaves_0:3)
Block(-13,27,4,biomesoplenty:leaves_0:3)
Block(-13,27,12,biomesoplenty:leaves_0:3)
Block(-13,27,13,biomesoplenty:leaves_0:3)
Block(-13,27,14,biomesoplenty:leaves_0:3)
Block(-13,27,15,biomesoplenty:leaves_0:3)
Block(-13,27,16,biomesoplenty:leaves_0:3)
Block(-13,27,17,biomesoplenty:leaves_0:3)
Block(-13,28,-5,biomesoplenty:leaves_0:3)
Block(-13,28,13,biomesoplenty:leaves_0:3)
Block(-13,28,14,biomesoplenty:leaves_0:3)
Block(-13,28,15,biomesoplenty:leaves_0:3)
Block(-13,28,17,biomesoplenty:leaves_0:3)
Block(-13,29,15,biomesoplenty:leaves_0:3)
Block(-13,29,16,biomesoplenty:leaves_0:3)
Block(-12,10,12,biomesoplenty:leaves_0:3)
Block(-12,10,14,biomesoplenty:leaves_0:3)
Block(-12,11,11,biomesoplenty:leaves_0:3)
Block(-12,11,12,biomesoplenty:leaves_0:3)
Block(-12,12,11,biomesoplenty:leaves_0:3)
Block(-12,12,12,biomesoplenty:leaves_0:3)
Block(-12,12,14,biomesoplenty:leaves_0:3)
Block(-12,12,15,biomesoplenty:leaves_0:3)
Block(-12,12,16,biomesoplenty:leaves_0:3)
Block(-12,12,17,biomesoplenty:leaves_0:3)
Block(-12,13,-6,biomesoplenty:log_1:5)
Block(-12,13,-5,biomesoplenty:log_1:5)
Block(-12,13,10,biomesoplenty:leaves_0:3)
Block(-12,13,11,biomesoplenty:leaves_0:3)
Block(-12,13,12,biomesoplenty:leaves_0:3)
Block(-12,13,15,biomesoplenty:leaves_0:3)
Block(-12,13,16,biomesoplenty:leaves_0:3)
Block(-12,13,17,biomesoplenty:leaves_0:3)
Block(-12,14,-10,biomesoplenty:leaves_0:3)
Block(-12,14,-9,biomesoplenty:leaves_0:3)
Block(-12,14,-8,biomesoplenty:leaves_0:3)
Block(-12,14,-7,biomesoplenty:leaves_0:3)
Block(-12,14,-6,biomesoplenty:leaves_0:3)
Block(-12,14,-5,biomesoplenty:log_1:5)
Block(-12,14,-4,biomesoplenty:log_1:5)
Block(-12,14,11,biomesoplenty:leaves_0:3)
Block(-12,14,12,biomesoplenty:log_1:5)
Block(-12,14,13,biomesoplenty:leaves_0:3)
Block(-12,14,14,biomesoplenty:log_1:5)
Block(-12,14,15,biomesoplenty:leaves_0:3)
Block(-12,15,-11,biomesoplenty:leaves_0:3)
Block(-12,15,-10,biomesoplenty:leaves_0:3)
Block(-12,15,-9,biomesoplenty:leaves_0:3)
Block(-12,15,-7,biomesoplenty:leaves_0:3)
Block(-12,15,-6,biomesoplenty:leaves_0:3)
Block(-12,15,-5,biomesoplenty:leaves_0:3)
Block(-12,15,-4,biomesoplenty:log_1:5)
Block(-12,15,-3,biomesoplenty:log_1:5)
Block(-12,15,-2,biomesoplenty:log_1:5)
Block(-12,15,-1,biomesoplenty:log_1:5)
Block(-12,15,16,biomesoplenty:leaves_0:3)
Block(-12,16,-11,biomesoplenty:leaves_0:3)
Block(-12,16,-10,biomesoplenty:leaves_0:3)
Block(-12,16,-9,biomesoplenty:leaves_0:3)
Block(-12,16,-8,biomesoplenty:leaves_0:3)
Block(-12,16,-7,biomesoplenty:leaves_0:3)
Block(-12,16,-3,biomesoplenty:log_1:5)
Block(-12,16,-2,biomesoplenty:log_1:5)
Block(-12,16,-1,biomesoplenty:log_1:5)
Block(-12,16,0,biomesoplenty:log_1:5)
Block(-12,17,-13,biomesoplenty:leaves_0:3)
Block(-12,17,-8,biomesoplenty:leaves_0:3)
Block(-12,17,0,biomesoplenty:log_1:5)
Block(-12,18,-13,biomesoplenty:leaves_0:3)
Block(-12,18,-12,biomesoplenty:leaves_0:3)
Block(-12,18,-9,biomesoplenty:leaves_0:3)
Block(-12,18,-7,biomesoplenty:leaves_0:3)
Block(-12,18,-6,biomesoplenty:leaves_0:3)
Block(-12,19,-11,biomesoplenty:leaves_0:3)
Block(-12,19,-10,biomesoplenty:leaves_0:3)
Block(-12,19,-9,biomesoplenty:leaves_0:3)
Block(-12,19,-4,biomesoplenty:leaves_0:3)
Block(-12,20,-12,biomesoplenty:leaves_0:3)
Block(-12,20,-11,biomesoplenty:leaves_0:3)
Block(-12,20,-10,biomesoplenty:leaves_0:3)
Block(-12,20,-8,biomesoplenty:leaves_0:3)
Block(-12,20,-7,biomesoplenty:leaves_0:3)
Block(-12,20,-5,biomesoplenty:leaves_0:3)
Block(-12,20,3,biomesoplenty:log_1:5)
Block(-12,20,10,biomesoplenty:log_1:5)
Block(-12,20,11,biomesoplenty:log_1:5)
Block(-12,21,-10,biomesoplenty:leaves_0:3)
Block(-12,21,2,biomesoplenty:log_1:5)
Block(-12,21,3,biomesoplenty:log_1:5)
Block(-12,21,10,biomesoplenty:log_1:5)
Block(-12,21,11,biomesoplenty:log_1:5)
Block(-12,21,12,biomesoplenty:leaves_0:3)
Block(-12,21,13,biomesoplenty:leaves_0:3)
Block(-12,22,-10,biomesoplenty:leaves_0:3)
Block(-12,22,14,biomesoplenty:leaves_0:3)
Block(-12,23,14,biomesoplenty:leaves_0:3)
Block(-12,23,15,biomesoplenty:leaves_0:3)
Block(-12,23,16,biomesoplenty:leaves_0:3)
Block(-12,24,-4,biomesoplenty:leaves_0:3)
Block(-12,24,13,biomesoplenty:log_1:5)
Block(-12,24,14,biomesoplenty:log_1:5)
Block(-12,24,15,biomesoplenty:leaves_0:3)
Block(-12,24,16,biomesoplenty:leaves_0:3)
Block(-12,25,-8,biomesoplenty:leaves_0:3)
Block(-12,25,-7,biomesoplenty:leaves_0:3)
Block(-12,25,-6,biomesoplenty:leaves_0:3)
Block(-12,25,3,biomesoplenty:leaves_0:3)
Block(-12,25,4,biomesoplenty:log_1:5)
Block(-12,25,11,biomesoplenty:leaves_0:3)
Block(-12,25,12,biomesoplenty:leaves_0:3)
Block(-12,25,13,biomesoplenty:leaves_0:3)
Block(-12,25,14,biomesoplenty:log_1:5)
Block(-12,25,15,biomesoplenty:leaves_0:3)
Block(-12,25,16,biomesoplenty:leaves_0:3)
Block(-12,25,17,biomesoplenty:leaves_0:3)
Block(-12,25,18,biomesoplenty:leaves_0:3)
Block(-12,26,-8,biomesoplenty:leaves_0:3)
Block(-12,26,-5,biomesoplenty:leaves_0:3)
Block(-12,26,-4,biomesoplenty:leaves_0:3)
Block(-12,26,-3,biomesoplenty:leaves_0:3)
Block(-12,26,2,biomesoplenty:leaves_0:3)
Block(-12,26,3,biomesoplenty:leaves_0:3)
Block(-12,26,4,biomesoplenty:leaves_0:3)
Block(-12,26,5,biomesoplenty:log_1:5)
Block(-12,26,8,biomesoplenty:leaves_0:3)
Block(-12,26,11,biomesoplenty:leaves_0:3)
Block(-12,26,12,biomesoplenty:leaves_0:3)
Block(-12,26,13,biomesoplenty:leaves_0:3)
Block(-12,26,14,biomesoplenty:leaves_0:3)
Block(-12,26,15,biomesoplenty:leaves_0:3)
Block(-12,26,16,biomesoplenty:leaves_0:3)
Block(-12,26,17,biomesoplenty:leaves_0:3)
Block(-12,26,18,biomesoplenty:leaves_0:3)
Block(-12,27,-7,biomesoplenty:leaves_0:3)
Block(-12,27,-6,biomesoplenty:leaves_0:3)
Block(-12,27,-5,biomesoplenty:leaves_0:3)
Block(-12,27,2,biomesoplenty:leaves_0:3)
Block(-12,27,3,biomesoplenty:leaves_0:3)
Block(-12,27,4,biomesoplenty:leaves_0:3)
Block(-12,27,5,biomesoplenty:leaves_0:3)
Block(-12,27,12,biomesoplenty:leaves_0:3)
Block(-12,27,14,biomesoplenty:leaves_0:3)
Block(-12,27,15,biomesoplenty:log_1:5)
Block(-12,27,16,biomesoplenty:leaves_0:3)
Block(-12,27,17,biomesoplenty:leaves_0:3)
Block(-12,27,18,biomesoplenty:leaves_0:3)
Block(-12,28,-6,biomesoplenty:leaves_0:3)
Block(-12,28,-5,biomesoplenty:leaves_0:3)
Block(-12,28,-4,biomesoplenty:leaves_0:3)
Block(-12,28,5,biomesoplenty:leaves_0:3)
Block(-12,28,7,biomesoplenty:leaves_0:3)
Block(-12,28,13,biomesoplenty:leaves_0:3)
Block(-12,28,14,biomesoplenty:leaves_0:3)
Block(-12,28,15,biomesoplenty:leaves_0:3)
Block(-12,28,18,biomesoplenty:leaves_0:3)
Block(-12,29,15,biomesoplenty:leaves_0:3)
Block(-12,29,17,biomesoplenty:leaves_0:3)
Block(-11,10,14,biomesoplenty:leaves_0:3)
Block(-11,10,15,biomesoplenty:leaves_0:3)
Block(-11,11,12,biomesoplenty:leaves_0:3)
Block(-11,11,14,biomesoplenty:leaves_0:3)
Block(-11,11,15,biomesoplenty:leaves_0:3)
Block(-11,11,16,biomesoplenty:leaves_0:3)
Block(-11,12,12,biomesoplenty:leaves_0:3)
Block(-11,12,13,biomesoplenty:leaves_0:3)
Block(-11,12,14,biomesoplenty:log_1:5)
Block(-11,12,16,biomesoplenty:leaves_0:3)
Block(-11,13,-7,biomesoplenty:log_1:5)
Block(-11,13,-6,biomesoplenty:log_1:5)
Block(-11,13,12,biomesoplenty:leaves_0:3)
Block(-11,13,13,biomesoplenty:leaves_0:3)
Block(-11,13,14,biomesoplenty:log_1:5)
Block(-11,13,15,biomesoplenty:leaves_0:3)
Block(-11,14,-11,biomesoplenty:leaves_0:3)
Block(-11,14,-10,biomesoplenty:leaves_0:3)
Block(-11,14,-9,biomesoplenty:leaves_0:3)
Block(-11,14,-8,biomesoplenty:leaves_0:3)
Block(-11,14,-7,biomesoplenty:log_1:5)
Block(-11,14,-2,biomesoplenty:log_1:5)
Block(-11,14,-1,biomesoplenty:log_1:5)
Block(-11,14,0,biomesoplenty:log_1:5)
Block(-11,14,1,biomesoplenty:log_1:5)
Block(-11,14,11,biomesoplenty:log_1:5)
Block(-11,14,12,biomesoplenty:log_1:5)
Block(-11,14,14,biomesoplenty:leaves_0:3)
Block(-11,14,15,biomesoplenty:leaves_0:3)
Block(-11,14,16,biomesoplenty:leaves_0:3)
Block(-11,15,-12,biomesoplenty:leaves_0:3)
Block(-11,15,-11,biomesoplenty:leaves_0:3)
Block(-11,15,-10,biomesoplenty:leaves_0:3)
Block(-11,15,-8,biomesoplenty:leaves_0:3)
Block(-11,15,-7,biomesoplenty:leaves_0:3)
Block(-11,15,-2,biomesoplenty:log_1:5)
Block(-11,15,-1,biomesoplenty:log_1:5)
Block(-11,15,0,biomesoplenty:log_1:5)
Block(-11,15,13,biomesoplenty:leaves_0:3)
Block(-11,15,14,biomesoplenty:leaves_0:3)
Block(-11,15,15,biomesoplenty:leaves_0:3)
Block(-11,15,16,biomesoplenty:leaves_0:3)
Block(-11,16,-13,biomesoplenty:leaves_0:3)
Block(-11,16,-12,biomesoplenty:leaves_0:3)
Block(-11,16,-11,biomesoplenty:log_1:5)
Block(-11,16,-10,biomesoplenty:log_1:5)
Block(-11,16,-8,biomesoplenty:leaves_0:3)
Block(-11,16,-7,biomesoplenty:leaves_0:3)
Block(-11,16,-1,biomesoplenty:log_1:5)
Block(-11,17,-13,biomesoplenty:leaves_0:3)
Block(-11,17,-12,biomesoplenty:leaves_0:3)
Block(-11,17,-11,biomesoplenty:leaves_0:3)
Block(-11,17,-10,biomesoplenty:leaves_0:3)
Block(-11,17,9,biomesoplenty:log_1:5)
Block(-11,18,-13,biomesoplenty:leaves_0:3)
Block(-11,18,-9,biomesoplenty:leaves_0:3)
Block(-11,18,9,biomesoplenty:log_1:5)
Block(-11,18,10,biomesoplenty:log_1:5)
Block(-11,19,-13,biomesoplenty:leaves_0:3)
Block(-11,19,-12,biomesoplenty:leaves_0:3)
Block(-11,19,-11,biomesoplenty:leaves_0:3)
Block(-11,19,-10,biomesoplenty:leaves_0:3)
Block(-11,19,10,biomesoplenty:log_1:5)
Block(-11,20,-11,biomesoplenty:leaves_0:3)
Block(-11,20,-10,biomesoplenty:leaves_0:3)
Block(-11,20,10,biomesoplenty:log_1:5)
Block(-11,20,14,biomesoplenty:leaves_0:3)
Block(-11,21,-11,biomesoplenty:leaves_0:3)
Block(-11,21,-10,biomesoplenty:leaves_0:3)
Block(-11,21,-9,biomesoplenty:leaves_0:3)
Block(-11,21,1,biomesoplenty:log_1:5)
Block(-11,21,2,biomesoplenty:log_1:5)
Block(-11,21,11,biomesoplenty:log_1:5)
Block(-11,21,12,biomesoplenty:leaves_0:3)
Block(-11,21,14,biomesoplenty:leaves_0:3)
Block(-11,21,15,biomesoplenty:leaves_0:3)
Block(-11,22,-11,biomesoplenty:leaves_0:3)
Block(-11,22,-10,biomesoplenty:leaves_0:3)
Block(-11,22,-9,biomesoplenty:leaves_0:3)
Block(-11,22,1,biomesoplenty:log_1:5)
Block(-11,22,11,biomesoplenty:log_1:5)
Block(-11,22,12,biomesoplenty:log_1:5)
Block(-11,22,13,biomesoplenty:log_1:5)
Block(-11,22,14,biomesoplenty:leaves_0:3)
Block(-11,22,15,biomesoplenty:leaves_0:3)
Block(-11,22,16,biomesoplenty:leaves_0:3)
Block(-11,23,13,biomesoplenty:log_1:5)
Block(-11,23,14,biomesoplenty:leaves_0:3)
Block(-11,24,3,biomesoplenty:log_1:5)
Block(-11,24,11,biomesoplenty:leaves_0:3)
Block(-11,24,12,biomesoplenty:leaves_0:3)
Block(-11,24,13,biomesoplenty:log_1:5)
Block(-11,24,15,biomesoplenty:leaves_0:3)
Block(-11,24,16,biomesoplenty:leaves_0:3)
Block(-11,24,17,biomesoplenty:leaves_0:3)
Block(-11,24,18,biomesoplenty:leaves_0:3)
Block(-11,25,-5,biomesoplenty:leaves_0:3)
Block(-11,25,-4,biomesoplenty:leaves_0:3)
Block(-11,25,-2,biomesoplenty:leaves_0:3)
Block(-11,25,2,biomesoplenty:leaves_0:3)
Block(-11,25,3,biomesoplenty:log_1:5)
Block(-11,25,4,biomesoplenty:log_1:5)
Block(-11,25,7,biomesoplenty:leaves_0:3)
Block(-11,25,12,biomesoplenty:leaves_0:3)
Block(-11,25,13,biomesoplenty:leaves_0:3)
Block(-11,25,14,biomesoplenty:leaves_0:3)
Block(-11,25,15,biomesoplenty:leaves_0:3)
Block(-11,25,16,biomesoplenty:leaves_0:3)
Block(-11,25,18,biomesoplenty:leaves_0:3)
Block(-11,25,19,biomesoplenty:leaves_0:3)
Block(-11,26,-7,biomesoplenty:leaves_0:3)
Block(-11,26,-6,biomesoplenty:leaves_0:3)
Block(-11,26,-4,biomesoplenty:leaves_0:3)
Block(-11,26,-2,biomesoplenty:leaves_0:3)
Block(-11,26,2,biomesoplenty:leaves_0:3)
Block(-11,26,3,biomesoplenty:leaves_0:3)
Block(-11,26,8,biomesoplenty:leaves_0:3)
Block(-11,26,9,biomesoplenty:leaves_0:3)
Block(-11,26,12,biomesoplenty:leaves_0:3)
Block(-11,26,13,biomesoplenty:leaves_0:3)
Block(-11,26,15,biomesoplenty:leaves_0:3)
Block(-11,26,16,biomesoplenty:leaves_0:3)
Block(-11,26,17,biomesoplenty:leaves_0:3)
Block(-11,26,18,biomesoplenty:leaves_0:3)
Block(-11,26,19,biomesoplenty:leaves_0:3)
Block(-11,27,-6,biomesoplenty:leaves_0:3)
Block(-11,27,-5,biomesoplenty:leaves_0:3)
Block(-11,27,-4,biomesoplenty:leaves_0:3)
Block(-11,27,3,biomesoplenty:leaves_0:3)
Block(-11,27,4,biomesoplenty:leaves_0:3)
Block(-11,27,5,biomesoplenty:leaves_0:3)
Block(-11,27,6,biomesoplenty:log_1:5)
Block(-11,27,8,biomesoplenty:leaves_0:3)
Block(-11,27,13,biomesoplenty:leaves_0:3)
Block(-11,27,16,biomesoplenty:leaves_0:3)
Block(-11,27,18,biomesoplenty:leaves_0:3)
Block(-11,28,-5,biomesoplenty:leaves_0:3)
Block(-11,28,4,biomesoplenty:leaves_0:3)
Block(-11,28,5,biomesoplenty:leaves_0:3)
Block(-11,28,8,biomesoplenty:leaves_0:3)
Block(-11,28,16,biomesoplenty:leaves_0:3)
Block(-11,28,18,biomesoplenty:leaves_0:3)
Block(-11,29,6,biomesoplenty:leaves_0:3)
Block(-11,29,8,biomesoplenty:leaves_0:3)
Block(-11,29,16,biomesoplenty:leaves_0:3)
Block(-10,10,14,biomesoplenty:leaves_0:3)
Block(-10,11,12,biomesoplenty:leaves_0:3)
Block(-10,11,13,biomesoplenty:leaves_0:3)
Block(-10,11,14,biomesoplenty:leaves_0:3)
Block(-10,12,11,biomesoplenty:leaves_0:3)
Block(-10,12,12,biomesoplenty:leaves_0:3)
Block(-10,12,13,biomesoplenty:leaves_0:3)
Block(-10,12,14,biomesoplenty:leaves_0:3)
Block(-10,12,15,biomesoplenty:leaves_0:3)
Block(-10,13,2,biomesoplenty:log_1:5)
Block(-10,13,11,biomesoplenty:leaves_0:3)
Block(-10,13,13,biomesoplenty:leaves_0:3)
Block(-10,13,14,biomesoplenty:leaves_0:3)
Block(-10,13,15,biomesoplenty:leaves_0:3)
Block(-10,13,16,biomesoplenty:leaves_0:3)
Block(-10,14,-12,biomesoplenty:leaves_0:3)
Block(-10,14,-11,biomesoplenty:leaves_0:3)
Block(-10,14,-10,biomesoplenty:leaves_0:3)
Block(-10,14,-9,biomesoplenty:leaves_0:3)
Block(-10,14,-7,biomesoplenty:log_1:5)
Block(-10,14,-1,biomesoplenty:log_1:5)
Block(-10,14,0,biomesoplenty:log_1:5)
Block(-10,14,1,biomesoplenty:log_1:5)
Block(-10,14,11,biomesoplenty:log_1:5)
Block(-10,14,16,biomesoplenty:leaves_0:3)
Block(-10,15,-13,biomesoplenty:leaves_0:3)
Block(-10,15,-12,biomesoplenty:leaves_0:3)
Block(-10,15,-11,biomesoplenty:leaves_0:3)
Block(-10,15,-9,biomesoplenty:log_1:5)
Block(-10,15,0,biomesoplenty:log_1:5)
Block(-10,15,1,biomesoplenty:log_1:5)
Block(-10,15,8,biomesoplenty:log_1:5)
Block(-10,15,11,biomesoplenty:log_1:5)
Block(-10,15,14,biomesoplenty:leaves_0:3)
Block(-10,15,15,biomesoplenty:leaves_0:3)
Block(-10,16,-12,biomesoplenty:leaves_0:3)
Block(-10,16,-11,biomesoplenty:leaves_0:3)
Block(-10,16,-10,biomesoplenty:log_1:5)
Block(-10,16,-9,biomesoplenty:log_1:5)
Block(-10,16,-7,biomesoplenty:leaves_0:3)
Block(-10,16,8,biomesoplenty:log_1:5)
Block(-10,16,9,biomesoplenty:log_1:5)
Block(-10,16,14,biomesoplenty:leaves_0:3)
Block(-10,17,-13,biomesoplenty:leaves_0:3)
Block(-10,17,-12,biomesoplenty:leaves_0:3)
Block(-10,17,-11,biomesoplenty:leaves_0:3)
Block(-10,17,-9,biomesoplenty:leaves_0:3)
Block(-10,17,-5,biomesoplenty:leaves_0:3)
Block(-10,17,8,biomesoplenty:log_1:5)
Block(-10,17,9,biomesoplenty:log_1:5)
Block(-10,18,-11,biomesoplenty:leaves_0:3)
Block(-10,18,-10,biomesoplenty:leaves_0:3)
Block(-10,18,-9,biomesoplenty:leaves_0:3)
Block(-10,18,-6,biomesoplenty:leaves_0:3)
Block(-10,18,9,biomesoplenty:log_1:5)
Block(-10,19,-12,biomesoplenty:leaves_0:3)
Block(-10,19,-11,biomesoplenty:leaves_0:3)
Block(-10,19,-10,biomesoplenty:leaves_0:3)
Block(-10,19,-9,biomesoplenty:leaves_0:3)
Block(-10,20,-11,biomesoplenty:leaves_0:3)
Block(-10,20,-10,biomesoplenty:leaves_0:3)
Block(-10,20,-9,biomesoplenty:leaves_0:3)
Block(-10,20,-7,biomesoplenty:leaves_0:3)
Block(-10,20,13,biomesoplenty:leaves_0:3)
Block(-10,21,-11,biomesoplenty:leaves_0:3)
Block(-10,21,-10,biomesoplenty:leaves_0:3)
Block(-10,21,-9,biomesoplenty:leaves_0:3)
Block(-10,21,13,biomesoplenty:leaves_0:3)
Block(-10,21,14,biomesoplenty:leaves_0:3)
Block(-10,21,15,biomesoplenty:leaves_0:3)
Block(-10,21,16,biomesoplenty:leaves_0:3)
Block(-10,22,-10,biomesoplenty:leaves_0:3)
Block(-10,22,-9,biomesoplenty:leaves_0:3)
Block(-10,22,-8,biomesoplenty:leaves_0:3)
Block(-10,22,0,biomesoplenty:log_1:5)
Block(-10,22,1,biomesoplenty:log_1:5)
Block(-10,22,2,biomesoplenty:leaves_0:3)
Block(-10,22,15,biomesoplenty:leaves_0:3)
Block(-10,23,-10,biomesoplenty:leaves_0:3)
Block(-10,23,-9,biomesoplenty:leaves_0:3)
Block(-10,23,-8,biomesoplenty:leaves_0:3)
Block(-10,23,-7,biomesoplenty:leaves_0:3)
Block(-10,23,-6,biomesoplenty:leaves_0:3)
Block(-10,23,0,biomesoplenty:log_1:5)
Block(-10,23,1,biomesoplenty:log_1:5)
Block(-10,23,2,biomesoplenty:log_1:5)
Block(-10,23,11,biomesoplenty:log_1:5)
Block(-10,23,15,biomesoplenty:leaves_0:3)
Block(-10,23,16,biomesoplenty:leaves_0:3)
Block(-10,24,-3,biomesoplenty:leaves_0:3)
Block(-10,24,2,biomesoplenty:log_1:5)
Block(-10,24,3,biomesoplenty:log_1:5)
Block(-10,24,8,biomesoplenty:leaves_0:3)
Block(-10,24,11,biomesoplenty:leaves_0:3)
Block(-10,24,12,biomesoplenty:leaves_0:3)
Block(-10,24,15,biomesoplenty:leaves_0:3)
Block(-10,24,18,biomesoplenty:leaves_0:3)
Block(-10,25,-4,biomesoplenty:leaves_0:3)
Block(-10,25,-3,biomesoplenty:leaves_0:3)
Block(-10,25,-1,biomesoplenty:leaves_0:3)
Block(-10,25,2,biomesoplenty:leaves_0:3)
Block(-10,25,3,biomesoplenty:leaves_0:3)
Block(-10,25,4,biomesoplenty:leaves_0:3)
Block(-10,25,7,biomesoplenty:leaves_0:3)
Block(-10,25,8,biomesoplenty:leaves_0:3)
Block(-10,25,15,biomesoplenty:leaves_0:3)
Block(-10,25,16,biomesoplenty:leaves_0:3)
Block(-10,25,17,biomesoplenty:leaves_0:3)
Block(-10,25,18,biomesoplenty:leaves_0:3)
Block(-10,25,19,biomesoplenty:leaves_0:3)
Block(-10,26,-4,biomesoplenty:leaves_0:3)
Block(-10,26,-3,biomesoplenty:leaves_0:3)
Block(-10,26,2,biomesoplenty:leaves_0:3)
Block(-10,26,3,biomesoplenty:leaves_0:3)
Block(-10,26,7,biomesoplenty:leaves_0:3)
Block(-10,26,16,biomesoplenty:leaves_0:3)
Block(-10,26,17,biomesoplenty:leaves_0:3)
Block(-10,26,18,biomesoplenty:leaves_0:3)
Block(-10,26,19,biomesoplenty:leaves_0:3)
Block(-10,27,-7,biomesoplenty:leaves_0:3)
Block(-10,27,-6,biomesoplenty:leaves_0:3)
Block(-10,27,-5,biomesoplenty:leaves_0:3)
Block(-10,27,-4,biomesoplenty:leaves_0:3)
Block(-10,27,-3,biomesoplenty:leaves_0:3)
Block(-10,27,-2,biomesoplenty:leaves_0:3)
Block(-10,27,0,biomesoplenty:leaves_0:3)
Block(-10,27,2,biomesoplenty:leaves_0:3)
Block(-10,27,3,biomesoplenty:leaves_0:3)
Block(-10,27,7,biomesoplenty:leaves_0:3)
Block(-10,27,8,biomesoplenty:leaves_0:3)
Block(-10,27,9,biomesoplenty:leaves_0:3)
Block(-10,27,13,biomesoplenty:leaves_0:3)
Block(-10,27,14,biomesoplenty:leaves_0:3)
Block(-10,27,15,biomesoplenty:leaves_0:3)
Block(-10,27,17,biomesoplenty:leaves_0:3)
Block(-10,27,18,biomesoplenty:leaves_0:3)
Block(-10,28,-5,biomesoplenty:leaves_0:3)
Block(-10,28,-4,biomesoplenty:leaves_0:3)
Block(-10,28,3,biomesoplenty:leaves_0:3)
Block(-10,28,4,biomesoplenty:leaves_0:3)
Block(-10,28,5,biomesoplenty:leaves_0:3)
Block(-10,28,6,biomesoplenty:leaves_0:3)
Block(-10,28,7,biomesoplenty:leaves_0:3)
Block(-10,29,4,biomesoplenty:leaves_0:3)
Block(-10,29,5,biomesoplenty:leaves_0:3)
Block(-10,29,6,biomesoplenty:leaves_0:3)
Block(-9,10,14,biomesoplenty:leaves_0:3)
Block(-9,11,14,biomesoplenty:leaves_0:3)
Block(-9,12,2,biomesoplenty:log_1:5)
Block(-9,12,3,biomesoplenty:log_1:5)
Block(-9,12,12,biomesoplenty:leaves_0:3)
Block(-9,12,13,biomesoplenty:leaves_0:3)
Block(-9,12,14,biomesoplenty:leaves_0:3)
Block(-9,12,15,biomesoplenty:leaves_0:3)
Block(-9,13,0,biomesoplenty:log_1:5)
Block(-9,13,1,biomesoplenty:log_1:5)
Block(-9,13,2,biomesoplenty:log_1:5)
Block(-9,13,13,biomesoplenty:leaves_0:3)
Block(-9,13,14,biomesoplenty:leaves_0:3)
Block(-9,13,15,biomesoplenty:leaves_0:3)
Block(-9,14,-13,biomesoplenty:leaves_0:3)
Block(-9,14,-12,biomesoplenty:leaves_0:3)
Block(-9,14,-11,biomesoplenty:leaves_0:3)
Block(-9,14,-10,biomesoplenty:leaves_0:3)
Block(-9,14,-9,biomesoplenty:leaves_0:3)
Block(-9,14,-7,biomesoplenty:log_1:5)
Block(-9,14,-6,biomesoplenty:leaves_0:3)
Block(-9,14,0,biomesoplenty:log_1:5)
Block(-9,14,1,biomesoplenty:log_1:5)
Block(-9,14,2,biomesoplenty:log_1:5)
Block(-9,14,7,biomesoplenty:log_1:5)
Block(-9,14,10,biomesoplenty:log_1:5)
Block(-9,14,16,biomesoplenty:leaves_0:3)
Block(-9,15,-12,biomesoplenty:leaves_0:3)
Block(-9,15,-9,biomesoplenty:log_1:5)
Block(-9,15,-8,biomesoplenty:log_1:5)
Block(-9,15,-7,biomesoplenty:log_1:5)
Block(-9,15,-6,biomesoplenty:leaves_0:3)
Block(-9,15,-5,biomesoplenty:leaves_0:3)
Block(-9,15,7,biomesoplenty:log_1:5)
Block(-9,15,8,biomesoplenty:log_1:5)
Block(-9,15,9,biomesoplenty:log_1:5)
Block(-9,15,10,biomesoplenty:log_1:5)
Block(-9,15,11,biomesoplenty:log_1:5)
Block(-9,15,14,biomesoplenty:leaves_0:3)
Block(-9,15,16,biomesoplenty:leaves_0:3)
Block(-9,15,17,biomesoplenty:leaves_0:3)
Block(-9,16,-13,biomesoplenty:leaves_0:3)
Block(-9,16,-12,biomesoplenty:leaves_0:3)
Block(-9,16,-11,biomesoplenty:leaves_0:3)
Block(-9,16,-10,biomesoplenty:leaves_0:3)
Block(-9,16,-6,biomesoplenty:leaves_0:3)
Block(-9,16,-5,biomesoplenty:leaves_0:3)
Block(-9,16,9,biomesoplenty:log_1:5)
Block(-9,16,14,biomesoplenty:leaves_0:3)
Block(-9,16,15,biomesoplenty:leaves_0:3)
Block(-9,16,17,biomesoplenty:leaves_0:3)
Block(-9,17,-12,biomesoplenty:leaves_0:3)
Block(-9,17,-11,biomesoplenty:leaves_0:3)
Block(-9,17,-10,biomesoplenty:leaves_0:3)
Block(-9,17,-9,biomesoplenty:leaves_0:3)
Block(-9,17,-8,biomesoplenty:leaves_0:3)
Block(-9,17,-5,biomesoplenty:leaves_0:3)
Block(-9,17,-4,biomesoplenty:leaves_0:3)
Block(-9,18,-12,biomesoplenty:leaves_0:3)
Block(-9,18,-11,biomesoplenty:leaves_0:3)
Block(-9,18,-8,biomesoplenty:leaves_0:3)
Block(-9,18,-6,biomesoplenty:leaves_0:3)
Block(-9,18,-5,biomesoplenty:leaves_0:3)
Block(-9,19,-12,biomesoplenty:leaves_0:3)
Block(-9,19,-11,biomesoplenty:leaves_0:3)
Block(-9,19,-9,biomesoplenty:leaves_0:3)
Block(-9,19,-5,biomesoplenty:leaves_0:3)
Block(-9,20,-11,biomesoplenty:leaves_0:3)
Block(-9,20,-10,biomesoplenty:leaves_0:3)
Block(-9,20,-9,biomesoplenty:leaves_0:3)
Block(-9,20,-8,biomesoplenty:leaves_0:3)
Block(-9,20,-7,biomesoplenty:leaves_0:3)
Block(-9,20,15,biomesoplenty:leaves_0:3)
Block(-9,20,16,biomesoplenty:leaves_0:3)
Block(-9,20,17,biomesoplenty:leaves_0:3)
Block(-9,21,-11,biomesoplenty:leaves_0:3)
Block(-9,21,-10,biomesoplenty:leaves_0:3)
Block(-9,21,-9,biomesoplenty:leaves_0:3)
Block(-9,21,-8,biomesoplenty:leaves_0:3)
Block(-9,21,-7,biomesoplenty:leaves_0:3)
Block(-9,21,-6,biomesoplenty:leaves_0:3)
Block(-9,21,15,biomesoplenty:leaves_0:3)
Block(-9,22,-10,biomesoplenty:leaves_0:3)
Block(-9,22,-9,biomesoplenty:leaves_0:3)
Block(-9,22,-8,biomesoplenty:leaves_0:3)
Block(-9,22,-5,biomesoplenty:leaves_0:3)
Block(-9,22,-4,biomesoplenty:leaves_0:3)
Block(-9,22,2,biomesoplenty:leaves_0:3)
Block(-9,22,3,biomesoplenty:leaves_0:3)
Block(-9,22,15,biomesoplenty:leaves_0:3)
Block(-9,22,16,biomesoplenty:leaves_0:3)
Block(-9,22,18,biomesoplenty:leaves_0:3)
Block(-9,23,-9,biomesoplenty:leaves_0:3)
Block(-9,23,-8,biomesoplenty:leaves_0:3)
Block(-9,23,-1,biomesoplenty:log_1:5)
Block(-9,23,0,biomesoplenty:log_1:5)
Block(-9,23,2,biomesoplenty:leaves_0:3)
Block(-9,23,6,biomesoplenty:leaves_0:3)
Block(-9,23,7,biomesoplenty:leaves_0:3)
Block(-9,23,8,biomesoplenty:leaves_0:3)
Block(-9,23,11,biomesoplenty:log_1:5)
Block(-9,23,16,biomesoplenty:leaves_0:3)
Block(-9,23,17,biomesoplenty:leaves_0:3)
Block(-9,23,18,biomesoplenty:leaves_0:3)
Block(-9,24,-9,biomesoplenty:leaves_0:3)
Block(-9,24,-8,biomesoplenty:leaves_0:3)
Block(-9,24,-2,biomesoplenty:log_1:5)
Block(-9,24,-1,biomesoplenty:log_1:5)
Block(-9,24,7,biomesoplenty:leaves_0:3)
Block(-9,24,8,biomesoplenty:leaves_0:3)
Block(-9,24,9,biomesoplenty:leaves_0:3)
Block(-9,24,11,biomesoplenty:leaves_0:3)
Block(-9,24,15,biomesoplenty:leaves_0:3)
Block(-9,24,17,biomesoplenty:leaves_0:3)
Block(-9,24,18,biomesoplenty:leaves_0:3)
Block(-9,25,-7,biomesoplenty:leaves_0:3)
Block(-9,25,-5,biomesoplenty:leaves_0:3)
Block(-9,25,-4,biomesoplenty:leaves_0:3)
Block(-9,25,-3,biomesoplenty:log_1:5)
Block(-9,25,-2,biomesoplenty:log_1:5)
Block(-9,25,6,biomesoplenty:leaves_0:3)
Block(-9,25,7,biomesoplenty:leaves_0:3)
Block(-9,25,8,biomesoplenty:leaves_0:3)
Block(-9,25,9,biomesoplenty:leaves_0:3)
Block(-9,25,14,biomesoplenty:leaves_0:3)
Block(-9,26,-6,biomesoplenty:leaves_0:3)
Block(-9,26,-5,biomesoplenty:leaves_0:3)
Block(-9,26,-4,biomesoplenty:leaves_0:3)
Block(-9,26,-3,biomesoplenty:leaves_0:3)
Block(-9,26,-2,biomesoplenty:leaves_0:3)
Block(-9,26,3,biomesoplenty:leaves_0:3)
Block(-9,26,6,biomesoplenty:leaves_0:3)
Block(-9,26,9,biomesoplenty:leaves_0:3)
Block(-9,26,14,biomesoplenty:leaves_0:3)
Block(-9,26,17,biomesoplenty:leaves_0:3)
Block(-9,26,18,biomesoplenty:leaves_0:3)
Block(-9,26,19,biomesoplenty:leaves_0:3)
Block(-9,27,-6,biomesoplenty:leaves_0:3)
Block(-9,27,-5,biomesoplenty:leaves_0:3)
Block(-9,27,-4,biomesoplenty:leaves_0:3)
Block(-9,27,-3,biomesoplenty:leaves_0:3)
Block(-9,27,-2,biomesoplenty:leaves_0:3)
Block(-9,27,-1,biomesoplenty:leaves_0:3)
Block(-9,27,0,biomesoplenty:leaves_0:3)
Block(-9,27,1,biomesoplenty:leaves_0:3)
Block(-9,27,2,biomesoplenty:leaves_0:3)
Block(-9,27,3,biomesoplenty:leaves_0:3)
Block(-9,27,8,biomesoplenty:leaves_0:3)
Block(-9,27,15,biomesoplenty:leaves_0:3)
Block(-9,27,17,biomesoplenty:leaves_0:3)
Block(-9,28,-5,biomesoplenty:leaves_0:3)
Block(-9,28,2,biomesoplenty:leaves_0:3)
Block(-9,28,3,biomesoplenty:leaves_0:3)
Block(-9,28,4,biomesoplenty:leaves_0:3)
Block(-9,28,5,biomesoplenty:leaves_0:3)
Block(-9,28,6,biomesoplenty:leaves_0:3)
Block(-9,28,7,biomesoplenty:leaves_0:3)
Block(-9,28,8,biomesoplenty:leaves_0:3)
Block(-9,28,15,biomesoplenty:leaves_0:3)
Block(-9,29,7,biomesoplenty:leaves_0:3)
Block(-8,11,2,biomesoplenty:log_1:5)
Block(-8,11,3,biomesoplenty:log_1:5)
Block(-8,11,4,biomesoplenty:log_1:5)
Block(-8,11,5,biomesoplenty:log_1:5)
Block(-8,11,14,biomesoplenty:leaves_0:3)
Block(-8,12,2,biomesoplenty:log_1:5)
Block(-8,12,3,biomesoplenty:log_1:5)
Block(-8,12,5,biomesoplenty:log_1:5)
Block(-8,12,6,biomesoplenty:log_1:5)
Block(-8,12,14,biomesoplenty:leaves_0:3)
Block(-8,12,15,biomesoplenty:leaves_0:3)
Block(-8,13,1,biomesoplenty:log_1:5)
Block(-8,13,2,biomesoplenty:log_1:5)
Block(-8,13,3,biomesoplenty:log_1:5)
Block(-8,13,6,biomesoplenty:log_1:5)
Block(-8,13,14,biomesoplenty:leaves_0:3)
Block(-8,14,-9,biomesoplenty:leaves_0:3)
Block(-8,14,-6,biomesoplenty:leaves_0:3)
Block(-8,14,7,biomesoplenty:log_1:5)
Block(-8,14,13,biomesoplenty:leaves_0:3)
Block(-8,14,15,biomesoplenty:leaves_0:3)
Block(-8,14,16,biomesoplenty:leaves_0:3)
Block(-8,14,17,biomesoplenty:leaves_0:3)
Block(-8,15,-12,biomesoplenty:leaves_0:3)
Block(-8,15,-11,biomesoplenty:leaves_0:3)
Block(-8,15,-10,biomesoplenty:leaves_0:3)
Block(-8,15,-9,biomesoplenty:leaves_0:3)
Block(-8,15,-7,biomesoplenty:log_1:5)
Block(-8,15,-6,biomesoplenty:leaves_0:3)
Block(-8,15,-5,biomesoplenty:leaves_0:3)
Block(-8,15,14,biomesoplenty:leaves_0:3)
Block(-8,15,15,biomesoplenty:leaves_0:3)
Block(-8,15,16,biomesoplenty:leaves_0:3)
Block(-8,15,17,biomesoplenty:leaves_0:3)
Block(-8,16,-12,biomesoplenty:leaves_0:3)
Block(-8,16,-11,biomesoplenty:leaves_0:3)
Block(-8,16,-10,biomesoplenty:leaves_0:3)
Block(-8,16,-9,biomesoplenty:leaves_0:3)
Block(-8,16,-7,biomesoplenty:log_1:5)
Block(-8,16,-6,biomesoplenty:log_1:5)
Block(-8,16,-5,biomesoplenty:leaves_0:3)
Block(-8,16,-4,biomesoplenty:leaves_0:3)
Block(-8,16,15,biomesoplenty:leaves_0:3)
Block(-8,16,16,biomesoplenty:leaves_0:3)
Block(-8,16,17,biomesoplenty:leaves_0:3)
Block(-8,17,-12,biomesoplenty:leaves_0:3)
Block(-8,17,-11,biomesoplenty:leaves_0:3)
Block(-8,17,-10,biomesoplenty:leaves_0:3)
Block(-8,17,-6,biomesoplenty:leaves_0:3)
Block(-8,17,-4,biomesoplenty:leaves_0:3)
Block(-8,17,13,biomesoplenty:leaves_0:3)
Block(-8,17,15,biomesoplenty:leaves_0:3)
Block(-8,17,16,biomesoplenty:leaves_0:3)
Block(-8,17,17,biomesoplenty:leaves_0:3)
Block(-8,18,-12,biomesoplenty:leaves_0:3)
Block(-8,18,-11,biomesoplenty:leaves_0:3)
Block(-8,18,-10,biomesoplenty:leaves_0:3)
Block(-8,18,-9,biomesoplenty:leaves_0:3)
Block(-8,18,-8,biomesoplenty:leaves_0:3)
Block(-8,18,-5,biomesoplenty:leaves_0:3)
Block(-8,19,-11,biomesoplenty:leaves_0:3)
Block(-8,19,-8,biomesoplenty:leaves_0:3)
Block(-8,19,-7,biomesoplenty:leaves_0:3)
Block(-8,19,15,biomesoplenty:leaves_0:3)
Block(-8,19,16,biomesoplenty:leaves_0:3)
Block(-8,19,17,biomesoplenty:leaves_0:3)
Block(-8,20,-11,biomesoplenty:leaves_0:3)
Block(-8,20,-10,biomesoplenty:leaves_0:3)
Block(-8,20,-9,biomesoplenty:leaves_0:3)
Block(-8,20,-8,biomesoplenty:leaves_0:3)
Block(-8,20,-6,biomesoplenty:leaves_0:3)
Block(-8,20,17,biomesoplenty:leaves_0:3)
Block(-8,20,18,biomesoplenty:leaves_0:3)
Block(-8,21,-10,biomesoplenty:leaves_0:3)
Block(-8,21,-9,biomesoplenty:leaves_0:3)
Block(-8,21,-4,biomesoplenty:leaves_0:3)
Block(-8,21,2,biomesoplenty:leaves_0:3)
Block(-8,21,14,biomesoplenty:leaves_0:3)
Block(-8,21,15,biomesoplenty:leaves_0:3)
Block(-8,21,17,biomesoplenty:leaves_0:3)
Block(-8,22,-10,biomesoplenty:leaves_0:3)
Block(-8,22,-9,biomesoplenty:leaves_0:3)
Block(-8,22,-8,biomesoplenty:leaves_0:3)
Block(-8,22,-5,biomesoplenty:leaves_0:3)
Block(-8,22,-4,biomesoplenty:leaves_0:3)
Block(-8,22,0,biomesoplenty:leaves_0:3)
Block(-8,22,2,biomesoplenty:leaves_0:3)
Block(-8,22,6,biomesoplenty:leaves_0:3)
Block(-8,22,7,biomesoplenty:leaves_0:3)
Block(-8,22,9,biomesoplenty:leaves_0:3)
Block(-8,22,10,biomesoplenty:leaves_0:3)
Block(-8,22,11,biomesoplenty:log_1:5)
Block(-8,22,13,biomesoplenty:leaves_0:3)
Block(-8,22,14,biomesoplenty:leaves_0:3)
Block(-8,22,15,biomesoplenty:leaves_0:3)
Block(-8,22,16,biomesoplenty:leaves_0:3)
Block(-8,22,18,biomesoplenty:leaves_0:3)
Block(-8,23,-10,biomesoplenty:leaves_0:3)
Block(-8,23,-9,biomesoplenty:leaves_0:3)
Block(-8,23,-5,biomesoplenty:leaves_0:3)
Block(-8,23,2,biomesoplenty:leaves_0:3)
Block(-8,23,3,biomesoplenty:leaves_0:3)
Block(-8,23,6,biomesoplenty:leaves_0:3)
Block(-8,23,7,biomesoplenty:leaves_0:3)
Block(-8,23,8,biomesoplenty:leaves_0:3)
Block(-8,23,9,biomesoplenty:leaves_0:3)
Block(-8,23,10,biomesoplenty:leaves_0:3)
Block(-8,23,11,biomesoplenty:leaves_0:3)
Block(-8,23,12,biomesoplenty:leaves_0:3)
Block(-8,23,14,biomesoplenty:leaves_0:3)
Block(-8,23,15,biomesoplenty:leaves_0:3)
Block(-8,23,16,biomesoplenty:leaves_0:3)
Block(-8,23,17,biomesoplenty:leaves_0:3)
Block(-8,24,-9,biomesoplenty:leaves_0:3)
Block(-8,24,-8,biomesoplenty:leaves_0:3)
Block(-8,24,-7,biomesoplenty:leaves_0:3)
Block(-8,24,-2,biomesoplenty:leaves_0:3)
Block(-8,24,-1,biomesoplenty:leaves_0:3)
Block(-8,24,2,biomesoplenty:leaves_0:3)
Block(-8,24,3,biomesoplenty:leaves_0:3)
Block(-8,24,7,biomesoplenty:leaves_0:3)
Block(-8,24,8,biomesoplenty:leaves_0:3)
Block(-8,24,9,biomesoplenty:leaves_0:3)
Block(-8,24,11,biomesoplenty:leaves_0:3)
Block(-8,24,15,biomesoplenty:leaves_0:3)
Block(-8,24,16,biomesoplenty:leaves_0:3)
Block(-8,24,17,biomesoplenty:leaves_0:3)
Block(-8,24,18,biomesoplenty:leaves_0:3)
Block(-8,25,-8,biomesoplenty:leaves_0:3)
Block(-8,25,-7,biomesoplenty:leaves_0:3)
Block(-8,25,-5,biomesoplenty:log_1:5)
Block(-8,25,-4,biomesoplenty:log_1:5)
Block(-8,25,-3,biomesoplenty:log_1:5)
Block(-8,25,-2,biomesoplenty:leaves_0:3)
Block(-8,25,3,biomesoplenty:leaves_0:3)
Block(-8,25,7,biomesoplenty:leaves_0:3)
Block(-8,25,8,biomesoplenty:leaves_0:3)
Block(-8,25,11,biomesoplenty:leaves_0:3)
Block(-8,25,14,biomesoplenty:leaves_0:3)
Block(-8,25,15,biomesoplenty:leaves_0:3)
Block(-8,25,17,biomesoplenty:leaves_0:3)
Block(-8,25,18,biomesoplenty:leaves_0:3)
Block(-8,26,-4,biomesoplenty:leaves_0:3)
Block(-8,26,-3,biomesoplenty:leaves_0:3)
Block(-8,26,-2,biomesoplenty:leaves_0:3)
Block(-8,26,7,biomesoplenty:leaves_0:3)
Block(-8,26,8,biomesoplenty:leaves_0:3)
Block(-8,26,13,biomesoplenty:leaves_0:3)
Block(-8,26,14,biomesoplenty:leaves_0:3)
Block(-8,26,15,biomesoplenty:leaves_0:3)
Block(-8,26,16,biomesoplenty:leaves_0:3)
Block(-8,27,-2,biomesoplenty:leaves_0:3)
Block(-8,27,-1,biomesoplenty:leaves_0:3)
Block(-8,27,0,biomesoplenty:leaves_0:3)
Block(-8,27,1,biomesoplenty:leaves_0:3)
Block(-8,27,6,biomesoplenty:leaves_0:3)
Block(-8,27,7,biomesoplenty:leaves_0:3)
Block(-8,27,8,biomesoplenty:leaves_0:3)
Block(-8,27,9,biomesoplenty:leaves_0:3)
Block(-8,27,15,biomesoplenty:leaves_0:3)
Block(-8,27,16,biomesoplenty:leaves_0:3)
Block(-8,28,-6,biomesoplenty:leaves_0:3)
Block(-8,28,-5,biomesoplenty:leaves_0:3)
Block(-8,28,-2,biomesoplenty:leaves_0:3)
Block(-8,28,0,biomesoplenty:leaves_0:3)
Block(-8,28,4,biomesoplenty:leaves_0:3)
Block(-8,28,5,biomesoplenty:leaves_0:3)
Block(-8,28,6,biomesoplenty:leaves_0:3)
Block(-8,28,7,biomesoplenty:leaves_0:3)
Block(-8,28,16,biomesoplenty:leaves_0:3)
Block(-8,29,-1,biomesoplenty:leaves_0:3)
Block(-8,29,4,biomesoplenty:leaves_0:3)
Block(-8,29,5,biomesoplenty:leaves_0:3)
Block(-7,9,3,biomesoplenty:log_1:5)
Block(-7,10,2,biomesoplenty:log_1:5)
Block(-7,10,3,biomesoplenty:log_1:5)
Block(-7,10,4,biomesoplenty:log_1:5)
Block(-7,10,5,biomesoplenty:log_1:5)
Block(-7,11,1,biomesoplenty:log_1:5)
Block(-7,11,2,biomesoplenty:log_1:5)
Block(-7,11,4,biomesoplenty:log_1:5)
Block(-7,11,5,biomesoplenty:log_1:5)
Block(-7,11,6,biomesoplenty:log_1:5)
Block(-7,12,2,biomesoplenty:log_1:5)
Block(-7,12,3,biomesoplenty:log_1:5)
Block(-7,12,4,biomesoplenty:log_1:5)
Block(-7,12,5,biomesoplenty:log_1:5)
Block(-7,12,6,biomesoplenty:log_1:5)
Block(-7,12,7,biomesoplenty:log_1:5)
Block(-7,12,13,biomesoplenty:leaves_0:3)
Block(-7,12,14,biomesoplenty:leaves_0:3)
Block(-7,12,16,biomesoplenty:leaves_0:3)
Block(-7,13,3,biomesoplenty:log_1:5)
Block(-7,13,6,biomesoplenty:log_1:5)
Block(-7,13,7,biomesoplenty:log_1:5)
Block(-7,13,14,biomesoplenty:leaves_0:3)
Block(-7,13,15,biomesoplenty:leaves_0:3)
Block(-7,13,16,biomesoplenty:leaves_0:3)
Block(-7,14,-5,biomesoplenty:leaves_0:3)
Block(-7,14,7,biomesoplenty:log_1:5)
Block(-7,14,16,biomesoplenty:leaves_0:3)
Block(-7,14,17,biomesoplenty:leaves_0:3)
Block(-7,15,-12,biomesoplenty:leaves_0:3)
Block(-7,15,-9,biomesoplenty:leaves_0:3)
Block(-7,15,-6,biomesoplenty:leaves_0:3)
Block(-7,15,-5,biomesoplenty:leaves_0:3)
Block(-7,15,13,biomesoplenty:leaves_0:3)
Block(-7,15,15,biomesoplenty:leaves_0:3)
Block(-7,15,17,biomesoplenty:leaves_0:3)
Block(-7,16,-11,biomesoplenty:leaves_0:3)
Block(-7,16,-10,biomesoplenty:leaves_0:3)
Block(-7,16,-8,biomesoplenty:leaves_0:3)
Block(-7,16,-6,biomesoplenty:log_1:5)
Block(-7,16,-5,biomesoplenty:log_1:5)
Block(-7,16,-4,biomesoplenty:leaves_0:3)
Block(-7,16,-3,biomesoplenty:leaves_0:3)
Block(-7,16,14,biomesoplenty:leaves_0:3)
Block(-7,16,15,biomesoplenty:leaves_0:3)
Block(-7,16,17,biomesoplenty:leaves_0:3)
Block(-7,16,18,biomesoplenty:leaves_0:3)
Block(-7,17,-11,biomesoplenty:leaves_0:3)
Block(-7,17,-10,biomesoplenty:leaves_0:3)
Block(-7,17,-9,biomesoplenty:leaves_0:3)
Block(-7,17,-8,biomesoplenty:leaves_0:3)
Block(-7,17,-7,biomesoplenty:leaves_0:3)
Block(-7,17,-5,biomesoplenty:leaves_0:3)
Block(-7,17,-4,biomesoplenty:leaves_0:3)
Block(-7,17,13,biomesoplenty:leaves_0:3)
Block(-7,17,14,biomesoplenty:leaves_0:3)
Block(-7,17,16,biomesoplenty:leaves_0:3)
Block(-7,18,-11,biomesoplenty:leaves_0:3)
Block(-7,18,-10,biomesoplenty:leaves_0:3)
Block(-7,18,-9,biomesoplenty:leaves_0:3)
Block(-7,18,-8,biomesoplenty:leaves_0:3)
Block(-7,18,-7,biomesoplenty:leaves_0:3)
Block(-7,18,-6,biomesoplenty:leaves_0:3)
Block(-7,18,15,biomesoplenty:leaves_0:3)
Block(-7,18,16,biomesoplenty:leaves_0:3)
Block(-7,19,-10,biomesoplenty:leaves_0:3)
Block(-7,19,-9,biomesoplenty:leaves_0:3)
Block(-7,19,-8,biomesoplenty:leaves_0:3)
Block(-7,19,-7,biomesoplenty:leaves_0:3)
Block(-7,19,-6,biomesoplenty:leaves_0:3)
Block(-7,19,13,biomesoplenty:leaves_0:3)
Block(-7,19,16,biomesoplenty:leaves_0:3)
Block(-7,19,17,biomesoplenty:leaves_0:3)
Block(-7,19,18,biomesoplenty:leaves_0:3)
Block(-7,20,-10,biomesoplenty:leaves_0:3)
Block(-7,20,-8,biomesoplenty:leaves_0:3)
Block(-7,20,-7,biomesoplenty:leaves_0:3)
Block(-7,20,-6,biomesoplenty:leaves_0:3)
Block(-7,20,17,biomesoplenty:leaves_0:3)
Block(-7,20,18,biomesoplenty:leaves_0:3)
Block(-7,21,-11,biomesoplenty:leaves_0:3)
Block(-7,21,-10,biomesoplenty:leaves_0:3)
Block(-7,21,-9,biomesoplenty:leaves_0:3)
Block(-7,21,-8,biomesoplenty:leaves_0:3)
Block(-7,21,-7,biomesoplenty:leaves_0:3)
Block(-7,21,-6,biomesoplenty:leaves_0:3)
Block(-7,21,-4,biomesoplenty:leaves_0:3)
Block(-7,21,1,biomesoplenty:leaves_0:3)
Block(-7,21,2,biomesoplenty:leaves_0:3)
Block(-7,21,10,biomesoplenty:leaves_0:3)
Block(-7,21,11,biomesoplenty:leaves_0:3)
Block(-7,21,12,biomesoplenty:log_1:5)
Block(-7,21,13,biomesoplenty:leaves_0:3)
Block(-7,21,14,biomesoplenty:leaves_0:3)
Block(-7,21,15,biomesoplenty:leaves_0:3)
Block(-7,21,16,biomesoplenty:leaves_0:3)
Block(-7,21,17,biomesoplenty:leaves_0:3)
Block(-7,21,18,biomesoplenty:leaves_0:3)
Block(-7,22,-10,biomesoplenty:leaves_0:3)
Block(-7,22,-9,biomesoplenty:leaves_0:3)
Block(-7,22,-8,biomesoplenty:leaves_0:3)
Block(-7,22,-7,biomesoplenty:leaves_0:3)
Block(-7,22,0,biomesoplenty:leaves_0:3)
Block(-7,22,1,biomesoplenty:leaves_0:3)
Block(-7,22,2,biomesoplenty:leaves_0:3)
Block(-7,22,3,biomesoplenty:leaves_0:3)
Block(-7,22,7,biomesoplenty:leaves_0:3)
Block(-7,22,8,biomesoplenty:leaves_0:3)
Block(-7,22,10,biomesoplenty:leaves_0:3)
Block(-7,22,11,biomesoplenty:leaves_0:3)
Block(-7,22,13,biomesoplenty:leaves_0:3)
Block(-7,22,15,biomesoplenty:leaves_0:3)
Block(-7,22,16,biomesoplenty:leaves_0:3)
Block(-7,22,17,biomesoplenty:leaves_0:3)
Block(-7,23,-9,biomesoplenty:leaves_0:3)
Block(-7,23,-8,biomesoplenty:leaves_0:3)
Block(-7,23,-5,biomesoplenty:leaves_0:3)
Block(-7,23,-4,biomesoplenty:leaves_0:3)
Block(-7,23,-3,biomesoplenty:leaves_0:3)
Block(-7,23,-2,biomesoplenty:leaves_0:3)
Block(-7,23,-1,biomesoplenty:leaves_0:3)
Block(-7,23,0,biomesoplenty:leaves_0:3)
Block(-7,23,1,biomesoplenty:leaves_0:3)
Block(-7,23,2,biomesoplenty:leaves_0:3)
Block(-7,23,3,biomesoplenty:leaves_0:3)
Block(-7,23,6,biomesoplenty:leaves_0:3)
Block(-7,23,9,biomesoplenty:leaves_0:3)
Block(-7,23,10,biomesoplenty:leaves_0:3)
Block(-7,23,11,biomesoplenty:leaves_0:3)
Block(-7,23,12,biomesoplenty:leaves_0:3)
Block(-7,23,15,biomesoplenty:leaves_0:3)
Block(-7,23,16,biomesoplenty:leaves_0:3)
Block(-7,23,17,biomesoplenty:leaves_0:3)
Block(-7,24,-9,biomesoplenty:leaves_0:3)
Block(-7,24,-8,biomesoplenty:leaves_0:3)
Block(-7,24,-6,biomesoplenty:leaves_0:3)
Block(-7,24,-5,biomesoplenty:leaves_0:3)
Block(-7,24,-2,biomesoplenty:leaves_0:3)
Block(-7,24,1,biomesoplenty:leaves_0:3)
Block(-7,24,8,biomesoplenty:leaves_0:3)
Block(-7,24,9,biomesoplenty:leaves_0:3)
Block(-7,24,11,biomesoplenty:leaves_0:3)
Block(-7,24,12,biomesoplenty:leaves_0:3)
Block(-7,24,16,biomesoplenty:leaves_0:3)
Block(-7,25,-8,biomesoplenty:leaves_0:3)
Block(-7,25,-7,biomesoplenty:leaves_0:3)
Block(-7,25,-6,biomesoplenty:leaves_0:3)
Block(-7,25,-5,biomesoplenty:log_1:5)
Block(-7,25,-4,biomesoplenty:leaves_0:3)
Block(-7,25,7,biomesoplenty:leaves_0:3)
Block(-7,25,8,biomesoplenty:log_1:5)
Block(-7,25,12,biomesoplenty:leaves_0:3)
Block(-7,25,14,biomesoplenty:leaves_0:3)
Block(-7,25,17,biomesoplenty:leaves_0:3)
Block(-7,26,-6,biomesoplenty:leaves_0:3)
Block(-7,26,-5,biomesoplenty:leaves_0:3)
Block(-7,26,-4,biomesoplenty:leaves_0:3)
Block(-7,26,-3,biomesoplenty:log_1:5)
Block(-7,26,-2,biomesoplenty:log_1:5)
Block(-7,26,7,biomesoplenty:leaves_0:3)
Block(-7,26,13,biomesoplenty:leaves_0:3)
Block(-7,26,14,biomesoplenty:leaves_0:3)
Block(-7,26,15,biomesoplenty:leaves_0:3)
Block(-7,27,-5,biomesoplenty:leaves_0:3)
Block(-7,27,-4,biomesoplenty:leaves_0:3)
Block(-7,27,-3,biomesoplenty:leaves_0:3)
Block(-7,27,-1,biomesoplenty:leaves_0:3)
Block(-7,27,0,biomesoplenty:leaves_0:3)
Block(-7,27,1,biomesoplenty:leaves_0:3)
Block(-7,27,2,biomesoplenty:leaves_0:3)
Block(-7,27,5,biomesoplenty:leaves_0:3)
Block(-7,27,6,biomesoplenty:leaves_0:3)
Block(-7,27,7,biomesoplenty:leaves_0:3)
Block(-7,28,-4,biomesoplenty:leaves_0:3)
Block(-7,28,-3,biomesoplenty:leaves_0:3)
Block(-7,28,-2,biomesoplenty:leaves_0:3)
Block(-7,28,-1,biomesoplenty:leaves_0:3)
Block(-7,28,0,biomesoplenty:leaves_0:3)
Block(-7,28,1,biomesoplenty:leaves_0:3)
Block(-7,28,3,biomesoplenty:leaves_0:3)
Block(-7,28,4,biomesoplenty:leaves_0:3)
Block(-7,28,5,biomesoplenty:leaves_0:3)
Block(-7,28,6,biomesoplenty:leaves_0:3)
Block(-7,28,7,biomesoplenty:leaves_0:3)
Block(-7,28,8,biomesoplenty:leaves_0:3)
Block(-7,29,-2,biomesoplenty:leaves_0:3)
Block(-7,29,-1,biomesoplenty:leaves_0:3)
Block(-7,29,0,biomesoplenty:leaves_0:3)
Block(-6,-4,-5,biomesoplenty:log_1:5)
Block(-6,-4,-4,biomesoplenty:log_1:5)
Block(-6,-2,3,biomesoplenty:log_1:5)
Block(-6,6,3,biomesoplenty:log_1:5)
Block(-6,7,4,biomesoplenty:log_1:5)
Block(-6,8,3,biomesoplenty:log_1:5)
Block(-6,8,4,biomesoplenty:log_1:5)
Block(-6,9,3,biomesoplenty:log_1:5)
Block(-6,9,4,biomesoplenty:log_1:5)
Block(-6,9,5,biomesoplenty:log_1:5)
Block(-6,10,3,biomesoplenty:log_1:5)
Block(-6,10,4,biomesoplenty:log_1:5)
Block(-6,10,5,biomesoplenty:log_1:5)
Block(-6,11,3,biomesoplenty:log_1:5)
Block(-6,11,4,biomesoplenty:log_1:5)
Block(-6,11,5,biomesoplenty:log_1:5)
Block(-6,12,3,biomesoplenty:log_1:5)
Block(-6,12,4,biomesoplenty:log_1:5)
Block(-6,12,5,biomesoplenty:log_1:5)
Block(-6,12,6,biomesoplenty:log_1:5)
Block(-6,12,7,biomesoplenty:log_1:5)
Block(-6,12,14,biomesoplenty:leaves_0:3)
Block(-6,12,15,biomesoplenty:leaves_0:3)
Block(-6,13,6,biomesoplenty:log_1:5)
Block(-6,13,7,biomesoplenty:log_1:5)
Block(-6,13,14,biomesoplenty:leaves_0:3)
Block(-6,13,15,biomesoplenty:leaves_0:3)
Block(-6,13,16,biomesoplenty:leaves_0:3)
Block(-6,14,-5,biomesoplenty:leaves_0:3)
Block(-6,14,7,biomesoplenty:log_1:5)
Block(-6,14,8,biomesoplenty:log_1:5)
Block(-6,14,13,biomesoplenty:leaves_0:3)
Block(-6,14,16,biomesoplenty:leaves_0:3)
Block(-6,15,-5,biomesoplenty:leaves_0:3)
Block(-6,15,-4,biomesoplenty:leaves_0:3)
Block(-6,15,15,biomesoplenty:leaves_0:3)
Block(-6,15,16,biomesoplenty:leaves_0:3)
Block(-6,15,17,biomesoplenty:leaves_0:3)
Block(-6,15,18,biomesoplenty:leaves_0:3)
Block(-6,16,-10,biomesoplenty:leaves_0:3)
Block(-6,16,-8,biomesoplenty:leaves_0:3)
Block(-6,16,-7,biomesoplenty:leaves_0:3)
Block(-6,16,-5,biomesoplenty:leaves_0:3)
Block(-6,16,-4,biomesoplenty:leaves_0:3)
Block(-6,16,13,biomesoplenty:leaves_0:3)
Block(-6,16,14,biomesoplenty:leaves_0:3)
Block(-6,16,15,biomesoplenty:log_1:5)
Block(-6,16,16,biomesoplenty:log_1:5)
Block(-6,16,17,biomesoplenty:leaves_0:3)
Block(-6,16,18,biomesoplenty:leaves_0:3)
Block(-6,17,-10,biomesoplenty:leaves_0:3)
Block(-6,17,-9,biomesoplenty:leaves_0:3)
Block(-6,17,-8,biomesoplenty:leaves_0:3)
Block(-6,17,-7,biomesoplenty:leaves_0:3)
Block(-6,17,-6,biomesoplenty:leaves_0:3)
Block(-6,17,-5,biomesoplenty:leaves_0:3)
Block(-6,17,-4,biomesoplenty:leaves_0:3)
Block(-6,17,13,biomesoplenty:leaves_0:3)
Block(-6,17,16,biomesoplenty:leaves_0:3)
Block(-6,17,17,biomesoplenty:leaves_0:3)
Block(-6,17,18,biomesoplenty:leaves_0:3)
Block(-6,18,-9,biomesoplenty:leaves_0:3)
Block(-6,18,-7,biomesoplenty:leaves_0:3)
Block(-6,18,-6,biomesoplenty:leaves_0:3)
Block(-6,18,-5,biomesoplenty:leaves_0:3)
Block(-6,18,12,biomesoplenty:leaves_0:3)
Block(-6,18,16,biomesoplenty:leaves_0:3)
Block(-6,18,17,biomesoplenty:leaves_0:3)
Block(-6,18,18,biomesoplenty:leaves_0:3)
Block(-6,19,-9,biomesoplenty:leaves_0:3)
Block(-6,19,-8,biomesoplenty:leaves_0:3)
Block(-6,19,-5,biomesoplenty:leaves_0:3)
Block(-6,19,11,biomesoplenty:leaves_0:3)
Block(-6,19,14,biomesoplenty:leaves_0:3)
Block(-6,19,16,biomesoplenty:leaves_0:3)
Block(-6,20,-10,biomesoplenty:leaves_0:3)
Block(-6,20,-9,biomesoplenty:leaves_0:3)
Block(-6,20,-8,biomesoplenty:leaves_0:3)
Block(-6,20,-7,biomesoplenty:leaves_0:3)
Block(-6,20,-6,biomesoplenty:leaves_0:3)
Block(-6,20,-5,biomesoplenty:leaves_0:3)
Block(-6,20,7,biomesoplenty:log_1:5)
Block(-6,20,8,biomesoplenty:log_1:5)
Block(-6,20,17,biomesoplenty:leaves_0:3)
Block(-6,20,18,biomesoplenty:leaves_0:3)
Block(-6,21,-9,biomesoplenty:leaves_0:3)
Block(-6,21,-8,biomesoplenty:leaves_0:3)
Block(-6,21,-6,biomesoplenty:leaves_0:3)
Block(-6,21,-5,biomesoplenty:leaves_0:3)
Block(-6,21,6,biomesoplenty:log_1:5)
Block(-6,21,7,biomesoplenty:log_1:5)
Block(-6,21,10,biomesoplenty:leaves_0:3)
Block(-6,21,12,biomesoplenty:log_1:5)
Block(-6,21,13,biomesoplenty:leaves_0:3)
Block(-6,21,15,biomesoplenty:leaves_0:3)
