
#######################################################################
# +-----------------------------------------------------------------+ #
# |                            BO3 object                           | #
# +-----------------------------------------------------------------+ #
#######################################################################

Author: LordSmellyPants

Description: No description given

Version: 3

SettingsMode: WriteWithoutComments


#######################################################################
# +-----------------------------------------------------------------+ #
# |                          Main settings                          | #
# +-----------------------------------------------------------------+ #
#######################################################################

Tree: true

Frequency: 1

Rarity: 50.0

RotateRandomly: true

SpawnHeight: highestSolidBlock

SpawnHeightOffset: 0

SpawnHeightVariance: 0

##############################
# Height Limits for the BO3. #
##############################

MinHeight: 60

MaxHeight: 69

######################
# Extrusion settings #
######################

ExtrudeMode: None

ExtrudeThroughBlocks: AIR

MaxBranchDepth: 10

ExcludedBiomes: All


#######################################################################
# +-----------------------------------------------------------------+ #
# |                      Source block settings                      | #
# +-----------------------------------------------------------------+ #
#######################################################################

SourceBlocks: STONE:1,STONE:3,STONE:5,DIRT:1,DIRT,SAND,GRASS,DIRT:2,STATIONARY_WATER,HARD_CLAY,STAINED_CLAY,CLAY,SANDSTONE,SAND:1,AIR,STONE,GRAVEL,LONG_GRASS,LONG_GRASS:1,LONG_GRASS:2,DEAD_BUSH,YELLOW_FLOWER,RED_ROSE,BROWN_MUSHROOM,RED_MUSHROOM,biomesoplenty:plant_0:1,biomesoplenty:plant_0:2,biomesoplenty:plant_0:3,biomesoplenty:plant_0:4,biomesoplenty:plant_0:5,biomesoplenty:plant_0:6,biomesoplenty:plant_0:7,biomesoplenty:plant_0:8,biomesoplenty:plant_0:9,biomesoplenty:plant_0:10,biomesoplenty:plant_0:11,biomesoplenty:plant_0:12,biomesoplenty:plant_0:13,biomesoplenty:plant_0:14,biomesoplenty:flower_0:1,biomesoplenty:flower_0:2,biomesoplenty:flower_0:3,biomesoplenty:flower_0:4,biomesoplenty:flower_0:5,biomesoplenty:flower_0:6,biomesoplenty:flower_0:7,biomesoplenty:flower_0:8,biomesoplenty:flower_0:9,biomesoplenty:flower_0:10,biomesoplenty:flower_0:11,biomesoplenty:flower_0:12,biomesoplenty:flower_0:13,biomesoplenty:flower_0:14,biomesoplenty:plant_1,biomesoplenty:grass:0,biomesoplenty:grass:1,biomesoplenty:grass,biomesoplenty:grass:3,biomesoplenty:grass:4,biomesoplenty:grass:5,biomesoplenty:grass:6,biomesoplenty:grass:7,UNKNOWN_BLOCK:0,UNKNOWN_BLOCK:1,UNKNOWN_BLOCK:2,UNKNOWN_BLOCK:8,UNKNOWN_BLOCK:9,UNKNOWN_BLOCK:10,biomesoplenty:dried_sand,biomesoplenty:hard_ice,biomesoplenty:white_sand,biomesoplenty:white_sandstone,biomesoplenty:mud,biomesoplenty:ash_block

MaxPercentageOutsideSourceBlock: 0

OutsideSourceBlock: placeAnyway

DoReplaceBlocks: true

IsOTGPlus: false


#######################################################################
# +-----------------------------------------------------------------+ #
# |                              Blocks                             | #
# +-----------------------------------------------------------------+ #
#######################################################################

Block(-4,3,-2,VINE:8)
Block(-4,4,-2,VINE:8)
Block(-4,4,0,VINE:8)
Block(-4,5,-2,VINE:8)
Block(-4,5,0,VINE:8)
Block(-3,2,-1,biomesoplenty:leaves_4:3)
Block(-3,2,1,VINE:4)
Block(-3,3,-1,biomesoplenty:leaves_4:3)
Block(-3,3,1,VINE:4)
Block(-3,4,-1,biomesoplenty:leaves_4:3)
Block(-3,4,0,biomesoplenty:leaves_4:3)
Block(-3,4,1,VINE:4)
Block(-3,5,-2,biomesoplenty:leaves_4:3)
Block(-3,5,-1,biomesoplenty:leaves_4:3)
Block(-3,5,0,biomesoplenty:leaves_4:3)
Block(-3,5,1,VINE:4)
Block(-3,6,-2,VINE:8)
Block(-3,6,-1,biomesoplenty:leaves_4:3)
Block(-2,3,-3,biomesoplenty:leaves_4:3)
Block(-2,3,1,biomesoplenty:leaves_4:3)
Block(-2,4,-4,VINE:1)
Block(-2,4,-3,biomesoplenty:leaves_4:3)
Block(-2,4,1,biomesoplenty:leaves_4:3)
Block(-2,4,3,VINE:8)
Block(-2,5,-4,VINE:1)
Block(-2,5,-3,biomesoplenty:leaves_4:3)
Block(-2,5,-2,biomesoplenty:leaves_4:3)
Block(-2,5,-1,biomesoplenty:leaves_4:3)
Block(-2,5,0,biomesoplenty:leaves_4:3)
Block(-2,5,1,biomesoplenty:leaves_4:3)
Block(-2,5,3,VINE:8)
Block(-2,6,-2,biomesoplenty:leaves_4:3)
Block(-2,6,-1,biomesoplenty:leaves_4:3)
Block(-2,6,0,biomesoplenty:leaves_4:3)
Block(-1,2,-3,biomesoplenty:leaves_4:3)
Block(-1,2,3,biomesoplenty:leaves_4:3)
Block(-1,3,-3,biomesoplenty:leaves_4:3)
Block(-1,3,3,biomesoplenty:leaves_4:3)
Block(-1,4,-3,biomesoplenty:leaves_4:3)
Block(-1,4,3,biomesoplenty:leaves_4:3)
Block(-1,4,4,VINE:4)
Block(-1,5,-4,VINE:1)
Block(-1,5,-3,biomesoplenty:leaves_4:3)
Block(-1,5,-2,biomesoplenty:log_2:1)
Block(-1,5,-1,biomesoplenty:log_2:1)
Block(-1,5,0,biomesoplenty:log_2:1)
Block(-1,5,1,biomesoplenty:leaves_4:3)
Block(-1,5,2,biomesoplenty:leaves_4:3)
Block(-1,5,3,biomesoplenty:leaves_4:3)
Block(-1,5,4,VINE:4)
Block(-1,6,-4,VINE:1)
Block(-1,6,-3,biomesoplenty:leaves_4:3)
Block(-1,6,-2,biomesoplenty:leaves_4:3)
Block(-1,6,-1,biomesoplenty:leaves_4:3)
Block(-1,6,0,biomesoplenty:leaves_4:3)
Block(0,-1,0,biomesoplenty:log_2:5)
Block(0,0,0,biomesoplenty:log_2:5)
Block(0,1,0,biomesoplenty:log_2:5)
Block(0,2,0,biomesoplenty:log_2:5)
Block(0,2,4,VINE:8)
Block(0,3,0,biomesoplenty:log_2:5)
Block(0,4,-3,biomesoplenty:leaves_4:3)
Block(0,4,0,biomesoplenty:log_2:5)
Block(0,4,4,biomesoplenty:leaves_4:3)
Block(0,5,-3,biomesoplenty:leaves_4:3)
Block(0,5,-2,biomesoplenty:leaves_4:3)
Block(0,5,-1,biomesoplenty:leaves_4:3)
Block(0,5,0,biomesoplenty:log_2:5)
Block(0,5,1,biomesoplenty:log_2:1)
Block(0,5,2,biomesoplenty:log_2:1)
Block(0,5,3,biomesoplenty:leaves_4:3)
Block(0,5,4,biomesoplenty:leaves_4:3)
Block(0,6,-2,biomesoplenty:leaves_4:3)
Block(0,6,-1,biomesoplenty:leaves_4:3)
Block(0,6,0,biomesoplenty:leaves_4:3)
Block(0,6,1,biomesoplenty:leaves_4:3)
Block(0,6,2,biomesoplenty:leaves_4:3)
Block(0,6,3,biomesoplenty:leaves_4:3)
Block(0,6,4,biomesoplenty:leaves_4:3)
Block(0,6,5,VINE:4)
Block(1,2,-2,biomesoplenty:leaves_4:3)
Block(1,2,4,biomesoplenty:leaves_4:3)
Block(1,2,5,VINE:4)
Block(1,3,-2,biomesoplenty:leaves_4:3)
Block(1,3,4,biomesoplenty:leaves_4:3)
Block(1,3,5,VINE:4)
Block(1,4,-2,biomesoplenty:leaves_4:3)
Block(1,4,3,biomesoplenty:leaves_4:3)
Block(1,4,4,biomesoplenty:leaves_4:3)
Block(1,4,5,VINE:4)
Block(1,5,-2,biomesoplenty:leaves_4:3)
Block(1,5,-1,biomesoplenty:leaves_4:3)
Block(1,5,0,biomesoplenty:log_2:9)
Block(1,5,1,biomesoplenty:leaves_4:3)
Block(1,5,2,biomesoplenty:leaves_4:3)
Block(1,5,3,biomesoplenty:leaves_4:3)
Block(1,5,4,biomesoplenty:leaves_4:3)
Block(1,5,5,VINE:4)
Block(1,6,-2,VINE:2)
Block(1,6,-1,biomesoplenty:leaves_4:3)
Block(1,6,0,biomesoplenty:leaves_4:3)
Block(1,6,1,biomesoplenty:leaves_4:3)
Block(1,6,2,biomesoplenty:leaves_4:3)
Block(1,6,3,biomesoplenty:leaves_4:3)
Block(2,2,2,biomesoplenty:leaves_4:3)
Block(2,3,2,biomesoplenty:leaves_4:3)
Block(2,4,2,biomesoplenty:leaves_4:3)
Block(2,5,-1,biomesoplenty:leaves_4:3)
Block(2,5,0,biomesoplenty:log_2:9)
Block(2,5,1,biomesoplenty:leaves_4:3)
Block(2,5,2,biomesoplenty:leaves_4:3)
Block(2,6,-1,biomesoplenty:leaves_4:3)
Block(2,6,0,biomesoplenty:leaves_4:3)
Block(2,6,1,biomesoplenty:leaves_4:3)
Block(3,3,-1,biomesoplenty:leaves_4:3)
Block(3,3,2,biomesoplenty:leaves_4:3)
Block(3,4,-1,biomesoplenty:leaves_4:3)
Block(3,4,2,biomesoplenty:leaves_4:3)
Block(3,5,-1,biomesoplenty:leaves_4:3)
Block(3,5,0,biomesoplenty:log_2:9)
Block(3,5,1,biomesoplenty:leaves_4:3)
Block(3,5,2,biomesoplenty:leaves_4:3)
Block(3,6,-1,VINE:2)
Block(3,6,0,biomesoplenty:leaves_4:3)
Block(3,6,1,VINE:4)
Block(4,2,0,biomesoplenty:leaves_4:3)
Block(4,2,1,VINE:4)
Block(4,3,0,biomesoplenty:leaves_4:3)
Block(4,4,0,biomesoplenty:leaves_4:3)
Block(4,4,1,biomesoplenty:leaves_4:3)
Block(4,5,0,biomesoplenty:leaves_4:3)
Block(4,5,1,biomesoplenty:leaves_4:3)
Block(4,6,0,VINE:2)
Block(5,1,0,VINE:2)
Block(5,2,0,VINE:2)
Block(5,3,0,VINE:2)
Block(5,4,0,VINE:2)
Block(5,5,0,VINE:2)

#######################################################################
# +-----------------------------------------------------------------+ #
# |                            BO3 checks                           | #
# +-----------------------------------------------------------------+ #
#######################################################################

BlockCheck(0,-1,0,GRASS,DIRT,DIRT:2,DIRT:1)

#######################################################################
# +-----------------------------------------------------------------+ #
# |                             Branches                            | #
# +-----------------------------------------------------------------+ #
#######################################################################


#######################################################################
# +-----------------------------------------------------------------+ #
# |                             Entities                            | #
# +-----------------------------------------------------------------+ #
#######################################################################


#######################################################################
# +-----------------------------------------------------------------+ #
# |                            Particles                            | #
# +-----------------------------------------------------------------+ #
#######################################################################


#######################################################################
# +-----------------------------------------------------------------+ #
# |                             Spawners                            | #
# +-----------------------------------------------------------------+ #
#######################################################################


#######################################################################
# +-----------------------------------------------------------------+ #
# |                             ModData                             | #
# +-----------------------------------------------------------------+ #
#######################################################################

