
#######################################################################
# +-----------------------------------------------------------------+ #
# |                            BO3 object                           | #
# +-----------------------------------------------------------------+ #
#######################################################################

Author: MC_Pitman

Description: No description given

Version: 3

SettingsMode: WriteWithoutComments


#######################################################################
# +-----------------------------------------------------------------+ #
# |                          Main settings                          | #
# +-----------------------------------------------------------------+ #
#######################################################################

Tree: true

Frequency: 1

Rarity: 3.0

RotateRandomly: true

SpawnHeight: highestSolidBlock

SpawnHeightOffset: -3

SpawnHeightVariance: 0

##############################
# Height Limits for the BO3. #
##############################

MinHeight: 61

MaxHeight: 71

######################
# Extrusion settings #
######################

ExtrudeMode: None

ExtrudeThroughBlocks: AIR

MaxBranchDepth: 10

ExcludedBiomes: All


#######################################################################
# +-----------------------------------------------------------------+ #
# |                      Source block settings                      | #
# +-----------------------------------------------------------------+ #
#######################################################################

SourceBlocks: STONE:1,STONE:3,STONE:5,DIRT:1,DIRT,SAND,GRASS,DIRT:2,STATIONARY_WATER,HARD_CLAY,STAINED_CLAY,CLAY,SANDSTONE,SAND:1,AIR,STONE,GRAVEL,LONG_GRASS,LONG_GRASS:1,LONG_GRASS:2,DEAD_BUSH,YELLOW_FLOWER,RED_ROSE,BROWN_MUSHROOM,RED_MUSHROOM,biomesoplenty:plant_0:1,biomesoplenty:plant_0:2,biomesoplenty:plant_0:3,biomesoplenty:plant_0:4,biomesoplenty:plant_0:5,biomesoplenty:plant_0:6,biomesoplenty:plant_0:7,biomesoplenty:plant_0:8,biomesoplenty:plant_0:9,biomesoplenty:plant_0:10,biomesoplenty:plant_0:11,biomesoplenty:plant_0:12,biomesoplenty:plant_0:13,biomesoplenty:plant_0:14,biomesoplenty:flower_0:1,biomesoplenty:flower_0:2,biomesoplenty:flower_0:3,biomesoplenty:flower_0:4,biomesoplenty:flower_0:5,biomesoplenty:flower_0:6,biomesoplenty:flower_0:7,biomesoplenty:flower_0:8,biomesoplenty:flower_0:9,biomesoplenty:flower_0:10,biomesoplenty:flower_0:11,biomesoplenty:flower_0:12,biomesoplenty:flower_0:13,biomesoplenty:flower_0:14,biomesoplenty:plant_1,biomesoplenty:grass:0,biomesoplenty:grass:1,biomesoplenty:grass,biomesoplenty:grass:3,biomesoplenty:grass:4,biomesoplenty:grass:5,biomesoplenty:grass:6,biomesoplenty:grass:7,UNKNOWN_BLOCK:0,UNKNOWN_BLOCK:1,UNKNOWN_BLOCK:2,UNKNOWN_BLOCK:8,UNKNOWN_BLOCK:9,UNKNOWN_BLOCK:10,biomesoplenty:dried_sand,biomesoplenty:hard_ice,biomesoplenty:white_sand,biomesoplenty:white_sandstone,biomesoplenty:mud,biomesoplenty:ash_block

MaxPercentageOutsideSourceBlock: 0

OutsideSourceBlock: placeAnyway

DoReplaceBlocks: true

IsOTGPlus: false


#######################################################################
# +-----------------------------------------------------------------+ #
# |                              Blocks                             | #
# +-----------------------------------------------------------------+ #
#######################################################################

Block(-9,5,2,HUGE_MUSHROOM_1:0)
Block(-9,5,3,HUGE_MUSHROOM_1:0)
Block(-8,0,1,LOG:12)
Block(-8,1,1,LOG:12)
Block(-8,1,2,LOG:12)
Block(-8,1,4,LOG:12)
Block(-8,2,1,LOG:12)
Block(-8,2,2,LOG:12)
Block(-8,2,4,LOG:12)
Block(-8,5,1,HUGE_MUSHROOM_1:0)
Block(-8,5,2,HUGE_MUSHROOM_1:0)
Block(-8,5,3,HUGE_MUSHROOM_1:0)
Block(-8,5,4,HUGE_MUSHROOM_1:0)
Block(-7,0,3,LOG:12)
Block(-7,0,6,LOG:12)
Block(-7,1,0,LOG:12)
Block(-7,1,3,LOG:12)
Block(-7,1,5,LOG:12)
Block(-7,1,6,LOG:12)
Block(-7,2,0,LOG:12)
Block(-7,2,1,LOG:12)
Block(-7,2,2,LOG:12)
Block(-7,2,3,LOG:12)
Block(-7,2,4,LOG:12)
Block(-7,2,5,LOG:12)
Block(-7,2,6,LOG:12)
Block(-7,3,1,LOG:12)
Block(-7,3,2,LOG:12)
Block(-7,3,3,LOG:12)
Block(-7,3,5,LOG:12)
Block(-7,4,2,LOG:12)
Block(-7,5,0,HUGE_MUSHROOM_1:0)
Block(-7,5,1,HUGE_MUSHROOM_1:0)
Block(-7,5,2,HUGE_MUSHROOM_1:0)
Block(-7,5,3,HUGE_MUSHROOM_1:0)
Block(-7,5,4,HUGE_MUSHROOM_1:0)
Block(-7,5,5,HUGE_MUSHROOM_1:0)
Block(-7,6,2,HUGE_MUSHROOM_1:0)
Block(-7,6,3,HUGE_MUSHROOM_1:0)
Block(-6,0,-1,LOG:12)
Block(-6,1,-1,LOG:12)
Block(-6,1,6,LOG:12)
Block(-6,2,-1,LOG:12)
Block(-6,2,0,LOG:12)
Block(-6,2,1,LOG:12)
Block(-6,2,2,LOG:12)
Block(-6,2,3,LOG:12)
Block(-6,2,4,LOG:12)
Block(-6,2,5,LOG:12)
Block(-6,2,6,LOG:12)
Block(-6,3,0,LOG:12)
Block(-6,3,1,LOG:12)
Block(-6,3,2,LOG:12)
Block(-6,3,3,LOG:12)
Block(-6,3,4,LOG:12)
Block(-6,3,5,LOG:12)
Block(-6,3,6,LOG:12)
Block(-6,4,0,LOG:12)
Block(-6,4,1,LOG:12)
Block(-6,4,2,LOG:12)
Block(-6,4,3,LOG:12)
Block(-6,4,4,LOG:12)
Block(-6,4,5,LOG:12)
Block(-6,4,6,WEB)
Block(-6,5,0,HUGE_MUSHROOM_1:0)
Block(-6,5,1,LOG:12)
Block(-6,5,2,LOG:12)
Block(-6,5,3,LOG:12)
Block(-6,5,4,LOG:12)
Block(-6,5,5,HUGE_MUSHROOM_1:0)
Block(-6,6,1,HUGE_MUSHROOM_1:0)
Block(-6,6,2,HUGE_MUSHROOM_1:0)
Block(-6,6,3,HUGE_MUSHROOM_1:0)
Block(-6,6,4,HUGE_MUSHROOM_1:0)
Block(-5,0,6,LOG:12)
Block(-5,1,-1,LOG:12)
Block(-5,1,6,LOG:12)
Block(-5,1,7,LOG:12)
Block(-5,2,-1,LOG:12)
Block(-5,2,0,LOG:12)
Block(-5,2,5,LOG:12)
Block(-5,2,6,LOG:12)
Block(-5,2,7,LOG:12)
Block(-5,3,1,LOG:12)
Block(-5,3,2,LOG:12)
Block(-5,3,3,LOG:12)
Block(-5,3,4,LOG:12)
Block(-5,3,5,LOG:12)
Block(-5,3,6,LOG:12)
Block(-5,4,1,LOG:12)
Block(-5,4,2,LOG:12)
Block(-5,4,3,LOG:12)
Block(-5,4,4,LOG:12)
Block(-5,4,5,LOG:12)
Block(-5,4,6,LOG:12)
Block(-5,5,1,LOG:12)
Block(-5,5,2,LOG:12)
Block(-5,5,3,LOG:12)
Block(-5,5,4,LOG:12)
Block(-5,5,5,LOG:12)
Block(-5,6,1,LOG:12)
Block(-5,6,2,LOG:12)
Block(-5,6,3,HUGE_MUSHROOM_1:0)
Block(-5,6,4,HUGE_MUSHROOM_1:0)
Block(-5,7,1,LOG:12)
Block(-5,7,2,LOG:12)
Block(-5,8,1,LOG:12)
Block(-4,0,-1,LOG:12)
Block(-4,0,8,LOG:12)
Block(-4,1,-1,LOG:12)
Block(-4,1,7,LOG:12)
Block(-4,1,8,LOG:12)
Block(-4,2,-1,LOG:12)
Block(-4,2,0,LOG:12)
Block(-4,2,6,LOG:12)
Block(-4,2,7,LOG:12)
Block(-4,2,8,LOG:12)
Block(-4,3,-1,BROWN_MUSHROOM)
Block(-4,3,0,LOG:12)
Block(-4,3,1,LOG:12)
Block(-4,3,2,LOG:12)
Block(-4,3,5,LOG:12)
Block(-4,3,6,LOG:12)
Block(-4,3,7,LOG:12)
Block(-4,4,0,LOG:12)
Block(-4,4,1,LOG:12)
Block(-4,4,2,LOG:12)
Block(-4,4,3,LOG:12)
Block(-4,4,4,LOG:12)
Block(-4,4,5,LOG:12)
Block(-4,4,6,LOG:12)
Block(-4,5,1,LOG:12)
Block(-4,5,2,LOG:12)
Block(-4,5,3,LOG:12)
Block(-4,5,4,LOG:12)
Block(-4,5,5,LOG:12)
Block(-4,5,6,LOG:12)
Block(-4,6,1,LOG:12)
Block(-4,6,2,LOG:12)
Block(-4,6,3,LOG:12)
Block(-4,6,4,LOG:12)
Block(-4,6,5,LOG:12)
Block(-4,6,6,LOG:12)
Block(-4,7,1,LOG:12)
Block(-4,7,2,LOG:12)
Block(-4,7,3,LOG:12)
Block(-4,7,4,LOG:12)
Block(-4,7,5,LOG:12)
Block(-4,8,1,LOG:12)
Block(-4,8,2,LOG:12)
Block(-4,8,3,LOG:12)
Block(-4,9,1,LOG:12)
Block(-4,9,2,LOG:12)
Block(-4,10,2,BROWN_MUSHROOM)
Block(-3,0,-5,LOG:12)
Block(-3,1,-5,LOG:12)
Block(-3,1,0,LOG:12)
Block(-3,1,8,LOG:12)
Block(-3,2,-5,LOG:12)
Block(-3,2,0,LOG:12)
Block(-3,2,1,LOG:12)
Block(-3,2,7,LOG:12)
Block(-3,2,8,LOG:12)
Block(-3,3,1,LOG:12)
Block(-3,3,2,LOG:12)
Block(-3,3,6,LOG:12)
Block(-3,3,7,LOG:12)
Block(-3,3,8,BROWN_MUSHROOM)
Block(-3,4,1,LOG:12)
Block(-3,4,2,LOG:12)
Block(-3,4,6,LOG:12)
Block(-3,4,7,LOG:12)
Block(-3,5,1,LOG:12)
Block(-3,5,2,LOG:12)
Block(-3,5,3,LOG:12)
Block(-3,5,5,LOG:12)
Block(-3,5,6,LOG:12)
Block(-3,6,1,LOG:12)
Block(-3,6,2,LOG:12)
Block(-3,6,3,LOG:12)
Block(-3,6,5,LOG:12)
Block(-3,6,6,LOG:12)
Block(-3,7,2,LOG:12)
Block(-3,7,3,LOG:12)
Block(-3,7,5,LOG:12)
Block(-3,7,6,LOG:12)
Block(-3,8,2,LOG:12)
Block(-3,8,3,LOG:12)
Block(-3,8,5,LOG:12)
Block(-3,8,6,BROWN_MUSHROOM)
Block(-3,9,2,LOG:12)
Block(-3,9,3,LOG:12)
Block(-3,9,5,LOG:12)
Block(-3,10,2,LOG:12)
Block(-3,10,3,LOG:12)
Block(-3,10,5,LOG:12)
Block(-3,11,2,LOG:12)
Block(-3,11,3,LOG:12)
Block(-3,12,2,LOG:12)
Block(-3,13,2,LOG:12)
Block(-2,0,-6,LOG:12)
Block(-2,0,1,LOG:12)
Block(-2,0,9,LOG:12)
Block(-2,1,-6,LOG:12)
Block(-2,1,-5,LOG:12)
Block(-2,1,-4,LOG:12)
Block(-2,1,1,LOG:12)
Block(-2,1,9,LOG:12)
Block(-2,2,-6,LOG:12)
Block(-2,2,-5,LOG:12)
Block(-2,2,-4,LOG:12)
Block(-2,2,1,LOG:12)
Block(-2,2,2,LOG:12)
Block(-2,2,7,LOG:12)
Block(-2,2,8,LOG:12)
Block(-2,2,9,LOG:12)
Block(-2,3,-5,LOG:12)
Block(-2,3,-4,LOG:12)
Block(-2,3,2,LOG:12)
Block(-2,3,7,LOG:12)
Block(-2,3,8,LOG:12)
Block(-2,4,-5,LOG:12)
Block(-2,4,-4,LOG:12)
Block(-2,4,2,LOG:12)
Block(-2,4,7,LOG:12)
Block(-2,5,-5,LOG:12)
Block(-2,5,-4,LOG:12)
Block(-2,5,2,LOG:12)
Block(-2,5,3,LOG:12)
Block(-2,5,6,LOG:12)
Block(-2,5,7,LOG:12)
Block(-2,6,-4,BROWN_MUSHROOM)
Block(-2,6,2,LOG:12)
Block(-2,6,3,LOG:12)
Block(-2,6,6,LOG:12)
Block(-2,7,3,LOG:12)
Block(-2,7,5,LOG:12)
Block(-2,7,6,LOG:12)
Block(-2,8,3,LOG:12)
Block(-2,8,5,LOG:12)
Block(-2,8,6,LOG:12)
Block(-2,9,3,LOG:12)
Block(-2,9,4,WEB)
Block(-2,9,5,LOG:12)
Block(-2,9,6,LOG:12)
Block(-2,10,5,LOG:12)
Block(-2,11,5,LOG:12)
Block(-2,12,5,LOG:12)
Block(-2,13,5,LOG:12)
Block(-2,14,5,LOG:12)
Block(-2,15,5,LOG:12)
Block(-1,0,-4,LOG:12)
Block(-1,1,-6,LOG:12)
Block(-1,1,-4,LOG:12)
Block(-1,1,2,LOG:12)
Block(-1,1,9,LOG:12)
Block(-1,2,-6,LOG:12)
Block(-1,2,-5,LOG:12)
Block(-1,2,-4,LOG:12)
Block(-1,2,2,LOG:12)
Block(-1,2,8,LOG:12)
Block(-1,2,9,LOG:12)
Block(-1,3,-5,LOG:12)
Block(-1,3,-4,LOG:12)
Block(-1,3,2,LOG:12)
Block(-1,3,7,LOG:12)
Block(-1,3,8,LOG:12)
Block(-1,3,9,LOG:12)
Block(-1,4,-5,LOG:12)
Block(-1,4,-4,LOG:12)
Block(-1,4,2,LOG:12)
Block(-1,4,7,LOG:12)
Block(-1,4,8,LOG:12)
Block(-1,4,9,LOG:12)
Block(-1,5,-5,LOG:12)
Block(-1,5,-4,LOG:12)
Block(-1,5,3,LOG:12)
Block(-1,5,6,LOG:12)
Block(-1,5,7,LOG:12)
Block(-1,5,8,LOG:12)
Block(-1,6,-5,LOG:12)
Block(-1,6,-4,LOG:12)
Block(-1,6,3,LOG:12)
Block(-1,6,6,LOG:12)
Block(-1,6,7,LOG:12)
Block(-1,7,-4,LOG:12)
Block(-1,7,4,LOG:12)
Block(-1,7,5,LOG:12)
Block(-1,7,6,LOG:12)
Block(-1,7,7,LOG:12)
Block(-1,8,4,LOG:12)
Block(-1,8,5,LOG:12)
Block(-1,8,6,LOG:12)
Block(-1,9,5,LOG:12)
Block(-1,9,6,LOG:12)
Block(-1,10,5,LOG:12)
Block(-1,10,6,LOG:12)
Block(-1,11,5,LOG:12)
Block(-1,11,6,LOG:12)
Block(-1,12,5,LOG:12)
Block(-1,12,6,LOG:12)
Block(-1,13,5,RED_MUSHROOM)
Block(-1,13,6,LOG:12)
Block(-1,14,6,LOG:12)
Block(0,0,2,LOG:12)
Block(0,1,-7,LOG:12)
Block(0,1,2,LOG:12)
Block(0,1,10,LOG:12)
Block(0,2,-7,LOG:12)
Block(0,2,-6,LOG:12)
Block(0,2,-4,LOG:12)
Block(0,2,-3,LOG:12)
Block(0,2,2,LOG:12)
Block(0,2,8,LOG:12)
Block(0,2,9,LOG:12)
Block(0,2,10,LOG:12)
Block(0,3,-6,LOG:12)
Block(0,3,-5,LOG:12)
Block(0,3,-4,LOG:12)
Block(0,3,3,LOG:12)
Block(0,3,7,LOG:12)
Block(0,3,8,LOG:12)
Block(0,3,9,LOG:12)
Block(0,4,-6,LOG:12)
Block(0,4,-5,LOG:12)
Block(0,4,-4,LOG:12)
Block(0,4,3,LOG:12)
Block(0,4,6,LOG:12)
Block(0,4,7,LOG:12)
Block(0,4,8,LOG:12)
Block(0,4,9,BROWN_MUSHROOM)
Block(0,5,-6,WEB)
Block(0,5,-5,LOG:12)
Block(0,5,-4,LOG:12)
Block(0,5,3,LOG:12)
Block(0,5,4,LOG:12)
Block(0,5,6,LOG:12)
Block(0,5,7,LOG:12)
Block(0,5,8,LOG:12)
Block(0,6,-5,LOG:12)
Block(0,6,-4,LOG:12)
Block(0,6,4,LOG:12)
Block(0,6,5,LOG:12)
Block(0,6,6,LOG:12)
Block(0,6,7,LOG:12)
Block(0,6,8,LOG:12)
Block(0,7,-4,LOG:12)
Block(0,7,4,LOG:12)
Block(0,7,5,LOG:12)
Block(0,7,6,LOG:12)
Block(0,7,7,LOG:12)
Block(0,8,-5,HUGE_MUSHROOM_1:0)
Block(0,8,-4,HUGE_MUSHROOM_1:0)
Block(0,8,-3,HUGE_MUSHROOM_1:0)
Block(0,8,5,LOG:12)
Block(0,8,6,LOG:12)
Block(0,8,7,LOG:12)
Block(0,9,5,LOG:12)
Block(0,9,6,LOG:12)
Block(0,9,7,LOG:12)
Block(0,10,6,LOG:12)
Block(0,10,7,LOG:12)
Block(0,11,6,LOG:12)
Block(0,12,6,LOG:12)
Block(0,13,6,LOG:12)
Block(1,0,-8,LOG:12)
Block(1,0,10,LOG:12)
Block(1,1,-9,LOG:12)
Block(1,1,-8,LOG:12)
Block(1,1,-3,LOG:12)
Block(1,1,3,LOG:12)
Block(1,1,9,LOG:12)
Block(1,1,10,LOG:12)
Block(1,2,-9,LOG:12)
Block(1,2,-8,LOG:12)
Block(1,2,-7,LOG:12)
Block(1,2,-6,LOG:12)
Block(1,2,-3,LOG:12)
Block(1,2,3,LOG:12)
Block(1,2,4,LOG:12)
Block(1,2,5,LOG:12)
Block(1,2,6,LOG:12)
Block(1,2,9,LOG:12)
Block(1,2,10,LOG:12)
Block(1,3,-7,LOG:12)
Block(1,3,-6,LOG:12)
Block(1,3,-5,LOG:12)
Block(1,3,-4,LOG:12)
Block(1,3,-3,LOG:12)
Block(1,3,4,LOG:12)
Block(1,3,5,LOG:12)
Block(1,3,6,LOG:12)
Block(1,3,7,LOG:12)
Block(1,3,8,LOG:12)
Block(1,3,9,LOG:12)
Block(1,3,10,LOG:12)
Block(1,4,-7,RED_MUSHROOM)
Block(1,4,-6,LOG:12)
Block(1,4,-5,LOG:12)
Block(1,4,-4,LOG:12)
Block(1,4,-3,LOG:12)
Block(1,4,4,LOG:12)
Block(1,4,5,LOG:12)
Block(1,4,6,LOG:12)
Block(1,4,7,LOG:12)
Block(1,4,8,LOG:12)
Block(1,4,9,LOG:12)
Block(1,5,-6,LOG:12)
Block(1,5,-5,LOG:12)
Block(1,5,-4,LOG:12)
Block(1,5,-3,RED_MUSHROOM)
Block(1,5,4,WEB)
Block(1,5,5,LOG:12)
Block(1,5,6,LOG:12)
Block(1,5,7,LOG:12)
Block(1,5,8,LOG:12)
Block(1,6,-5,LOG:12)
Block(1,6,-4,LOG:12)
Block(1,6,4,HUGE_MUSHROOM_1:0)
Block(1,6,5,LOG:12)
Block(1,6,6,LOG:12)
Block(1,6,7,LOG:12)
Block(1,6,8,LOG:12)
Block(1,7,-5,LOG:12)
Block(1,7,-4,LOG:12)
Block(1,7,5,LOG:12)
Block(1,7,6,LOG:12)
Block(1,7,7,LOG:12)
Block(1,7,8,LOG:12)
Block(1,8,-5,HUGE_MUSHROOM_1:0)
Block(1,8,-4,LOG:12)
Block(1,8,-3,HUGE_MUSHROOM_1:0)
Block(1,8,-2,HUGE_MUSHROOM_1:0)
Block(1,8,5,LOG:12)
Block(1,8,6,LOG:12)
Block(1,8,7,LOG:12)
Block(1,8,8,LOG:12)
Block(1,9,-4,HUGE_MUSHROOM_1:0)
Block(1,9,-3,HUGE_MUSHROOM_1:0)
Block(1,9,6,LOG:12)
Block(1,9,7,LOG:12)
Block(1,10,6,LOG:12)
Block(1,10,7,LOG:12)
Block(1,11,7,LOG:12)
Block(2,0,6,LOG:12)
Block(2,1,-8,LOG:12)
Block(2,1,-7,LOG:12)
Block(2,1,-6,LOG:12)
Block(2,1,-2,LOG:12)
Block(2,1,4,LOG:12)
Block(2,1,6,LOG:12)
Block(2,2,-8,LOG:12)
Block(2,2,-7,LOG:12)
Block(2,2,-6,LOG:12)
Block(2,2,-5,LOG:12)
Block(2,2,-3,LOG:12)
Block(2,2,-2,LOG:12)
Block(2,2,4,LOG:12)
Block(2,2,5,LOG:12)
Block(2,2,6,LOG:12)
Block(2,2,8,LOG:12)
Block(2,2,9,LOG:12)
Block(2,3,-6,LOG:12)
Block(2,3,-5,LOG:12)
Block(2,3,-3,LOG:12)
Block(2,3,-2,LOG:12)
Block(2,3,5,LOG:12)
Block(2,3,6,LOG:12)
Block(2,3,7,LOG:12)
Block(2,3,8,LOG:12)
Block(2,3,9,LOG:12)
Block(2,4,-6,LOG:12)
Block(2,4,-5,LOG:12)
Block(2,4,-3,LOG:12)
Block(2,4,-2,LOG:12)
Block(2,4,-1,LOG:12)
Block(2,4,5,LOG:12)
Block(2,4,6,LOG:12)
Block(2,4,7,LOG:12)
Block(2,4,8,LOG:12)
Block(2,4,9,LOG:12)
Block(2,5,-5,LOG:12)
Block(2,5,-4,LOG:12)
Block(2,5,-3,LOG:12)
Block(2,5,-1,LOG:12)
Block(2,5,5,LOG:12)
Block(2,5,6,LOG:12)
Block(2,5,7,LOG:12)
Block(2,5,8,LOG:12)
Block(2,5,9,LOG:12)
Block(2,6,-5,LOG:12)
Block(2,6,-4,LOG:12)
Block(2,6,-3,LOG:12)
Block(2,6,-1,LOG:12)
Block(2,6,4,HUGE_MUSHROOM_1:0)
Block(2,6,6,LOG:12)
Block(2,6,8,LOG:12)
Block(2,6,9,LOG:12)
Block(2,7,-4,LOG:12)
Block(2,7,-3,LOG:12)
Block(2,7,-1,LOG:12)
Block(2,7,5,HUGE_MUSHROOM_1:0)
Block(2,7,6,HUGE_MUSHROOM_1:0)
Block(2,7,7,HUGE_MUSHROOM_1:0)
Block(2,8,-5,HUGE_MUSHROOM_1:0)
Block(2,8,-4,LOG:12)
Block(2,8,-3,LOG:12)
Block(2,8,-2,HUGE_MUSHROOM_1:0)
Block(2,8,-1,LOG:12)
Block(2,9,-4,HUGE_MUSHROOM_1:0)
Block(2,9,-3,LOG:12)
Block(2,9,-1,LOG:12)
Block(2,10,-3,RED_MUSHROOM)
Block(3,0,5,LOG:12)
Block(3,0,8,LOG:12)
Block(3,1,-6,LOG:12)
Block(3,1,-1,LOG:12)
Block(3,1,0,LOG:12)
Block(3,1,1,LOG:12)
Block(3,1,5,LOG:12)
Block(3,1,6,LOG:12)
Block(3,1,7,LOG:12)
Block(3,1,8,LOG:12)
Block(3,2,-6,LOG:12)
Block(3,2,-5,LOG:12)
Block(3,2,-1,LOG:12)
Block(3,2,0,LOG:12)
Block(3,2,1,LOG:12)
Block(3,2,5,LOG:12)
Block(3,2,6,LOG:12)
Block(3,2,7,LOG:12)
Block(3,2,8,LOG:12)
Block(3,3,-6,LOG:12)
Block(3,3,-5,LOG:12)
Block(3,3,-1,LOG:12)
Block(3,3,0,LOG:12)
Block(3,3,5,LOG:12)
Block(3,3,7,LOG:12)
Block(3,3,8,BROWN_MUSHROOM)
Block(3,4,-5,LOG:12)
Block(3,4,-1,LOG:12)
Block(3,4,7,LOG:12)
Block(3,5,-5,LOG:12)
Block(3,5,-3,LOG:12)
Block(3,5,-2,LOG:12)
Block(3,5,-1,LOG:12)
Block(3,6,-5,BROWN_MUSHROOM)
Block(3,6,-4,LOG:12)
Block(3,6,-3,LOG:12)
Block(3,6,-2,LOG:12)
Block(3,6,-1,LOG:12)
Block(3,6,0,LOG:12)
Block(3,6,4,HUGE_MUSHROOM_1:0)
Block(3,6,8,HUGE_MUSHROOM_1:0)
Block(3,7,-4,LOG:12)
Block(3,7,-3,LOG:12)
Block(3,7,-2,LOG:12)
Block(3,7,-1,LOG:12)
Block(3,7,0,LOG:12)
Block(3,7,5,HUGE_MUSHROOM_1:0)
Block(3,7,6,HUGE_MUSHROOM_1:0)
Block(3,7,7,HUGE_MUSHROOM_1:0)
Block(3,8,-4,HUGE_MUSHROOM_1:0)
Block(3,8,-3,LOG:12)
Block(3,8,-2,LOG:12)
Block(3,8,-1,LOG:12)
Block(3,8,0,LOG:12)
Block(3,8,1,LOG:12)
Block(3,9,-1,LOG:12)
Block(3,9,0,LOG:12)
Block(3,10,-1,LOG:12)
Block(3,10,0,LOG:12)
Block(3,11,0,LOG:12)
Block(3,12,0,LOG:12)
Block(3,13,0,LOG:12)
Block(3,14,0,LOG:12)
Block(4,0,2,LOG:12)
Block(4,1,-5,LOG:12)
Block(4,1,2,LOG:12)
Block(4,1,3,LOG:12)
Block(4,2,-5,LOG:12)
Block(4,2,0,LOG:12)
Block(4,2,1,LOG:12)
Block(4,2,2,LOG:12)
Block(4,2,3,LOG:12)
Block(4,3,-5,LOG:12)
Block(4,3,0,LOG:12)
Block(4,3,1,LOG:12)
Block(4,3,2,LOG:12)
Block(4,4,-5,LOG:12)
Block(4,4,0,LOG:12)
Block(4,4,1,LOG:12)
Block(4,5,-4,LOG:12)
Block(4,5,-1,LOG:12)
Block(4,5,0,LOG:12)
Block(4,5,1,LOG:12)
Block(4,6,-4,LOG:12)
Block(4,6,-3,LOG:12)
Block(4,6,-1,LOG:12)
Block(4,6,0,LOG:12)
Block(4,6,1,LOG:12)
Block(4,6,5,HUGE_MUSHROOM_1:0)
Block(4,6,6,HUGE_MUSHROOM_1:0)
Block(4,6,7,HUGE_MUSHROOM_1:0)
Block(4,7,-3,LOG:12)
Block(4,7,-2,LOG:12)
Block(4,7,-1,LOG:12)
Block(4,7,0,LOG:12)
Block(4,7,1,LOG:12)
Block(4,8,-2,LOG:12)
Block(4,8,-1,LOG:12)
Block(4,8,0,LOG:12)
Block(4,8,1,LOG:12)
Block(4,9,-2,LOG:12)
Block(4,9,-1,LOG:12)
Block(4,9,0,LOG:12)
Block(4,9,1,LOG:12)
Block(4,10,0,LOG:12)
Block(4,10,1,LOG:12)
Block(5,0,-7,LOG:12)
Block(5,1,-7,LOG:12)
Block(5,1,-6,LOG:12)
Block(5,1,3,LOG:12)
Block(5,2,-7,LOG:12)
Block(5,2,-6,LOG:12)
Block(5,2,-5,LOG:12)
Block(5,2,-4,LOG:12)
Block(5,2,2,LOG:12)
Block(5,2,3,LOG:12)
Block(5,3,-5,LOG:12)
Block(5,3,-4,LOG:12)
Block(5,3,1,LOG:12)
Block(5,3,2,LOG:12)
Block(5,3,3,LOG:12)
Block(5,4,-5,LOG:12)
Block(5,4,-4,LOG:12)
Block(5,4,1,LOG:12)
Block(5,4,2,LOG:12)
Block(5,5,-4,LOG:12)
Block(5,5,-3,LOG:12)
Block(5,5,1,LOG:12)
Block(5,5,2,LOG:12)
Block(5,6,-3,LOG:12)
Block(5,6,-2,LOG:12)
Block(5,6,1,LOG:12)
Block(5,6,2,LOG:12)
Block(5,7,-2,LOG:12)
Block(5,7,1,LOG:12)
Block(5,7,2,LOG:12)
Block(5,8,-2,LOG:12)
Block(5,8,1,LOG:12)
Block(5,9,-1,WEB)
Block(6,0,4,LOG:12)
Block(6,1,-5,LOG:12)
Block(6,1,4,LOG:12)
Block(6,2,-5,LOG:12)
Block(6,2,-4,LOG:12)
Block(6,2,-3,LOG:12)
Block(6,2,2,LOG:12)
Block(6,2,3,LOG:12)
Block(6,2,4,LOG:12)
Block(6,3,-4,LOG:12)
Block(6,3,-3,LOG:12)
Block(6,3,-2,LOG:12)
Block(6,3,1,LOG:12)
Block(6,3,3,LOG:12)
Block(6,3,4,RED_MUSHROOM)
Block(6,4,-3,LOG:12)
Block(6,4,-2,LOG:12)
Block(6,4,1,LOG:12)
Block(6,4,2,LOG:12)
Block(6,4,3,LOG:12)
Block(6,5,-3,LOG:12)
Block(6,5,-2,LOG:12)
Block(6,5,1,LOG:12)
Block(6,5,2,LOG:12)
Block(6,5,3,LOG:12)
Block(6,6,-2,LOG:12)
Block(6,6,-1,LOG:12)
Block(6,6,0,LOG:12)
Block(6,6,1,LOG:12)
Block(6,6,2,LOG:12)
Block(6,6,3,LOG:12)
Block(6,7,-2,LOG:12)
Block(6,7,-1,LOG:12)
Block(6,7,1,LOG:12)
Block(6,7,2,LOG:12)
Block(6,7,3,LOG:12)
Block(6,8,-2,BROWN_MUSHROOM)
Block(6,8,-1,LOG:12)
Block(6,8,3,LOG:12)
Block(7,0,-4,LOG:12)
Block(7,1,-4,LOG:12)
Block(7,1,-3,LOG:12)
Block(7,1,4,LOG:12)
Block(7,2,-4,LOG:12)
Block(7,2,-3,LOG:12)
Block(7,2,-2,LOG:12)
Block(7,2,-1,LOG:12)
Block(7,2,0,LOG:12)
Block(7,2,3,LOG:12)
Block(7,2,4,LOG:12)
Block(7,3,-3,LOG:12)
Block(7,3,-2,LOG:12)
Block(7,3,-1,LOG:12)
Block(7,3,0,LOG:12)
Block(7,3,1,LOG:12)
Block(7,3,2,LOG:12)
Block(7,3,3,LOG:12)
Block(7,4,-2,LOG:12)
Block(7,4,-1,LOG:12)
Block(7,4,0,LOG:12)
Block(7,4,1,LOG:12)
Block(7,4,2,LOG:12)
Block(7,4,3,LOG:12)
Block(7,5,-1,LOG:12)
Block(7,5,0,LOG:12)
Block(7,5,1,LOG:12)
Block(7,5,2,LOG:12)
Block(7,5,3,LOG:12)
Block(7,6,-1,LOG:12)
Block(7,6,1,LOG:12)
Block(7,6,2,LOG:12)
Block(7,6,3,LOG:12)
Block(7,7,-1,LOG:12)
Block(7,7,1,LOG:12)
Block(7,7,2,LOG:12)
Block(7,8,-1,LOG:12)
Block(7,8,1,LOG:12)
Block(7,9,1,LOG:12)
Block(7,10,1,RED_MUSHROOM)
Block(8,0,2,LOG:12)
Block(8,1,-2,LOG:12)
Block(8,1,-1,LOG:12)
Block(8,1,2,LOG:12)
Block(8,1,3,LOG:12)
Block(8,2,-2,LOG:12)
Block(8,2,-1,LOG:12)
Block(8,2,0,LOG:12)
Block(8,2,1,LOG:12)
Block(8,2,2,LOG:12)
Block(8,2,3,LOG:12)
Block(8,3,-1,BROWN_MUSHROOM)
Block(8,3,0,LOG:12)
Block(8,3,1,LOG:12)
Block(8,3,2,LOG:12)
Block(8,3,3,LOG:12)
Block(8,4,1,LOG:12)
Block(8,4,2,LOG:12)
Block(8,4,3,BROWN_MUSHROOM)
Block(8,5,1,LOG:12)
Block(8,5,2,LOG:12)
Block(8,6,1,LOG:12)
Block(9,0,-3,LOG:12)
Block(9,0,1,LOG:12)
Block(9,1,-3,LOG:12)
Block(9,1,-2,LOG:12)
Block(9,1,0,LOG:12)
Block(9,1,1,LOG:12)
Block(9,1,2,LOG:12)
Block(9,2,-3,LOG:12)
Block(9,2,-2,LOG:12)
Block(9,2,0,LOG:12)
Block(9,2,1,LOG:12)
Block(9,2,2,LOG:12)
Block(9,3,1,LOG:12)
Block(9,4,1,LOG:12)
Block(10,0,0,LOG:12)
Block(10,1,0,LOG:12)
Block(10,2,0,LOG:12)

#######################################################################
# +-----------------------------------------------------------------+ #
# |                            BO3 checks                           | #
# +-----------------------------------------------------------------+ #
#######################################################################


#######################################################################
# +-----------------------------------------------------------------+ #
# |                             Branches                            | #
# +-----------------------------------------------------------------+ #
#######################################################################


#######################################################################
# +-----------------------------------------------------------------+ #
# |                             Entities                            | #
# +-----------------------------------------------------------------+ #
#######################################################################


#######################################################################
# +-----------------------------------------------------------------+ #
# |                            Particles                            | #
# +-----------------------------------------------------------------+ #
#######################################################################


#######################################################################
# +-----------------------------------------------------------------+ #
# |                             Spawners                            | #
# +-----------------------------------------------------------------+ #
#######################################################################


#######################################################################
# +-----------------------------------------------------------------+ #
# |                             ModData                             | #
# +-----------------------------------------------------------------+ #
#######################################################################

